Workbook
Name beta_observed: Valuation!$D$93
Name last_close: Valuation!$G$7
Name ticker: Valuation!$D$7
Name Useful_Life_of_Depreciable_PP_E: "PPElife"
Name beta_observed: #REF!
Name ticker: #REF!
Name costdebtfirm: Valuation!$D$86
Name costequity: Valuation!$D$94
Name debt: Valuation!$G$88
Name debt_weight: Valuation!$J$88
Name g: Valuation!$D$63
Name market_equity: Valuation!$G$89
Name noplat_t1: Valuation!$D$65
Name relevered_beta: Valuation!$M$102
Name risk_free_rate: Valuation!$D$91
Name risk_premium: Valuation!$D$92
Name ronic: Valuation!$D$64
Name stub_year_fraction: Valuation!$D$11
Name totalcap: Valuation!$G$90
Name wacc: Valuation!$D$12

Sheet Inputs
A1: Base histórica normalizada (R$ mil) — convertida da máscara anterior; linhas de origem auditáveis
A2: Fonte / conta original | B2: Código | C2: Conta padronizada | D2: 1Q21 | E2: 2Q21 | F2: 3Q21 | G2: 4Q21 | H2: 2021 | I2: 1Q22 | J2: 2Q22 | K2: 3Q22 | L2: 4Q22 | M2: 2022 | N2: 1Q23 | O2: 2Q23 | P2: 3Q23 | Q2: 4Q23 | R2: 2023 | S2: 1Q24 | T2: 2Q24 | U2: 3Q24 | V2: 4Q24 | W2: 2024 | X2: 1Q25 | Y2: 2Q25 | Z2: 3Q25 | AA2: 4Q25 | AB2: 2025 | AC2: 1Q26 | AD2: 2Q26 | AE2: 3Q26 | AF2: 4Q26 | AG2: 2026
A3: Fonte: ver coluna A de cada linha | C3: Unidade: R$ mil (monetário); demais unidades × 1.000
A4: DRE - TRIMESTRE ISOLADO (aba IS | DRE (w | com IFRS16), bloco Reportado, consolidado l.101-128; R$ milhoes). 1T23+ = CVM; 2020-22 = base pro forma da Cia | C4: [linha bruta, sem código; lançada nas linhas abaixo]
A5: Receita Líquida (DRE l.103) · fonte · unid. moeda | B5: 1 | C5: Net Revenues | D5: 757552 | E5: 1165345 | F5: 1521076 | G5: 1689065 | I5: 1905657 | J5: 2230992 | K5: 2536864 | L5: 2626633 | N5: 2703206 | O5: 2479144 | P5: 2666220 | Q5: 2493444 | S5: 3021646 | T5: 3435604 | U5: 3775864 | V5: 3248157 | X5: 3568231 | Y5: 3679006 | Z5: 3765843 | AA5: 3658975.2 | AC5: 3780645 | AD5: 3765830.2
A6: Custo Ex-depreciação (DRE l.106) · fonte · unid. moeda | B6: 2 | C6: COGS (cash) | D6: -296444 | E6: -605183 | F6: -729162 | G6: -699450 | I6: -822587 | J6: -1085046 | K6: -1337890 | L6: -1440095 | N6: -1511480 | O6: -1276679 | P6: -1479884 | Q6: -1260799 | S6: -1641800 | T6: -1943531 | U6: -2167358 | V6: -1632259 | X6: -1850291 | Y6: -1930489 | Z6: -1923128 | AA6: -1775877.8 | AC6: -1792954.8 | AD6: -1658145
A7: Depreciação (DRE l.107) (depreciacao frota + outros + direito de uso; devolvida abaixo via D&A) · fonte · unid. moeda | B7: 2 | C7: COGS (cash) | D7: -62178 | E7: -72936 | F7: -110706 | G7: -170431 | I7: -212836 | J7: -240909 | K7: -300524 | L7: -380942 | N7: -390033 | O7: -388955 | P7: -412766 | Q7: -906810 | S7: -447805 | T7: -522064 | U7: -551278 | V7: -559350 | X7: -572374 | Y7: -593733 | Z7: -624564 | AA7: -639359.24 | AC7: -650585.92 | AD7: -671563.62
A8: Despesa Ex-depreciação (DRE l.114) · fonte · unid. moeda | B8: 3 | C8: SG&A and Other (cash) | D8: -156605 | E8: -171698 | F8: -178506 | G8: -213003 | I8: -234631 | J8: -257540 | K8: -292522 | L8: -344544 | N8: -332775 | O8: -329942 | P8: -338551 | Q8: -366571 | S8: -320432 | T8: -315813 | U8: -356334 | V8: -371618 | X8: -379610 | Y8: -369393 | Z8: -364059 | AA8: -393047.09 | AC8: -419025.55 | AD8: -420941.57
A9: Depreciação Mais Valia (DRE l.115) (depreciacao de mais-valia) · fonte · unid. moeda | B9: 3 | C9: SG&A and Other (cash) | D9: 0 | E9: 0 | F9: 0 | G9: 0 | I9: 0 | J9: 0 | K9: 0 | L9: 0 | N9: 0 | O9: 0 | P9: 0 | Q9: -139114 | S9: 0 | T9: 0 | U9: 0 | V9: 0 | X9: 0 | Y9: 0 | Z9: 0 | AA9: 0 | AC9: 0 | AD9: 0
A10: Impairment de Depreciação (DRE l.116) (impairment de depreciacao) · fonte · unid. moeda | B10: 3 | C10: SG&A and Other (cash) | D10: 0 | E10: 0 | F10: 0 | G10: 0 | I10: 0 | J10: 0 | K10: 0 | L10: 0 | N10: 0 | O10: 0 | P10: 0 | Q10: 0 | S10: 0 | T10: -26900 | U10: -4696 | V10: 0 | X10: 0 | Y10: 0 | Z10: 0 | AA10: 0 | AC10: 0 | AD10: 0
A11: Despesas Financeiras (DRE l.124) · fonte · unid. moeda | B11: 5 | C11: Interest Expense | D11: -265184 | E11: 239899 | F11: -342257 | G11: -591177 | I11: -394958 | J11: -515803 | K11: -637391 | L11: -662277 | N11: -615278 | O11: -551559 | P11: -590177 | Q11: -614436 | S11: -627625 | T11: -662137 | U11: -707297 | V11: -691837 | X11: -745217 | Y11: -792778 | Z11: -895889 | AA11: -1154513.7 | AC11: -902577.86 | AD11: -1000770.5
A12: Receitas Financeiras (DRE l.125) · fonte · unid. moeda | B12: 6 | C12: Nonoperating Income / (Loss) | D12: 188526 | E12: -307323 | F12: 209511 | G12: 383039 | I12: 107671 | J12: 116444 | K12: 123724 | L12: 161251 | N12: 140596 | O12: 25985 | P12: 47438 | Q12: 59055 | S12: 88865 | T12: 91414 | U12: 112895 | V12: 85172 | X12: 90007 | Y12: 98699 | Z12: 100571 | AA12: 390591.91 | AC12: 148795.41 | AD12: 155135.69
A13: Receita Bruta (DRE l.101) - memoria · memoria · unid. moeda | C13: [linha bruta, sem código; lançada nas linhas abaixo] | D13: 824150 | E13: 1234303 | F13: 1605965 | G13: 1797894 | I13: 2023882 | J13: 2354247 | K13: 2680451 | L13: 2779739 | N13: 2871596 | O13: 2647105 | P13: 2846875 | Q13: 2686001 | S13: 3219943 | T13: 3657546 | U13: 4016702 | V13: 3493321 | X13: 3804719 | Y13: 3930928 | Z13: 4032922 | AA13: 3935855.8 | AC13: 4069234.1 | AD13: 4057515.4
A14: Deduções (DRE l.102) - memoria · memoria · unid. moeda | C14: [linha bruta, sem código; lançada nas linhas abaixo] | D14: -66598 | E14: -68958 | F14: -84889 | G14: -108829 | I14: -118225 | J14: -123255 | K14: -143587 | L14: -153106 | N14: -168390 | O14: -167961 | P14: -180655 | Q14: -192557 | S14: -198297 | T14: -221943 | U14: -240838 | V14: -245164 | X14: -236488 | Y14: -251923 | Z14: -267080 | AA14: -276880.61 | AC14: -288589.17 | AD14: -291685.23
A15: Receita Líquida de Serviços (DRE l.104) - memoria · memoria · unid. moeda | C15: [linha bruta, sem código; lançada nas linhas abaixo] | D15: 483011 | E15: 491865 | F15: 676455 | G15: 879950 | I15: 931895 | J15: 1002358 | K15: 1126436 | L15: 1222226 | N15: 1239742 | O15: 1233781 | P15: 1297318 | Q15: 1339621 | S15: 1495198 | T15: 1608087 | U15: 1744697 | V15: 1791057 | X15: 1878904 | Y15: 1892632 | Z15: 2010812 | AA15: 2096394.1 | AC15: 2205616.5 | AD15: 2295334.6
A16: Custo (DRE l.105) - memoria · memoria · unid. moeda | C16: [linha bruta, sem código; lançada nas linhas abaixo] | D16: -358623 | E16: -678119 | F16: -839868 | G16: -869881 | I16: -1020767 | J16: -1309105 | K16: -1619529 | L16: -1804787 | N16: -1885122 | O16: -1648165 | P16: -1872509 | Q16: -2167697 | S16: -2089568 | T16: -2465595 | U16: -2718636 | V16: -2191609 | X16: -2422665 | Y16: -2524222 | Z16: -2547692 | AA16: -2415237.1 | AC16: -2443540.8 | AD16: -2329708.7
A17: Lucro Bruto (DRE l.111) - memoria · memoria · unid. moeda | C17: [linha bruta, sem código; lançada nas linhas abaixo] | D17: 398929 | E17: 487226 | F17: 681208 | G17: 819185 | I17: 884890 | J17: 921888 | K17: 917335 | L17: 821846 | N17: 818084 | O17: 830979 | P17: 793711 | Q17: 325747 | S17: 932078 | T17: 970009 | U17: 1057228 | V17: 1056548 | X17: 1145565 | Y17: 1154784 | Z17: 1218150 | AA17: 1243738.1 | AC17: 1337104.2 | AD17: 1436121.5
A18: Despesas Administrativas (DRE l.113) - memoria · memoria · unid. moeda | C18: [linha bruta, sem código; lançada nas linhas abaixo] | D18: -156605 | E18: -171698 | F18: -178506 | G18: -213003 | I18: -234631 | J18: -257540 | K18: -292522 | L18: -344544 | N18: -332775 | O18: -329942 | P18: -338551 | Q18: -505686 | S18: -320432 | T18: -342713 | U18: -361030 | V18: -371618 | X18: -379610 | Y18: -369393 | Z18: -364059 | AA18: -393047.09 | AC18: -419025.55 | AD18: -420941.57
A19: EBITDA (DRE l.117) - memoria · memoria · unid. moeda | C19: [linha bruta, sem código; lançada nas linhas abaixo] | D19: 304502 | E19: 388464 | F19: 613408 | G19: 776612 | I19: 863095 | J19: 905256 | K19: 925337 | L19: 858243 | N19: 875342 | O19: 889992 | P19: 867926 | Q19: 866073 | S19: 1059500 | T19: 1149360 | U19: 1247476 | V19: 1244280 | X19: 1338329 | Y19: 1379123 | Z19: 1478656 | AA19: 1490050.3 | AC19: 1568664.6 | AD19: 1686743.6
A20: EBITDA de Serviços (DRE l.118) - memoria · memoria · unid. moeda | C20: [linha bruta, sem código; lançada nas linhas abaixo] | D20: 268221 | E20: 268356 | F20: 426207 | G20: 595052 | I20: 658624 | J20: 700022 | K20: 789148 | L20: 752650 | N20: 788955 | O20: 793534 | P20: 826475 | Q20: 829453 | S20: 1020779 | T20: 1124660 | U20: 1225769 | V20: 1227273 | X20: 1320160 | Y20: 1359482 | Z20: 1460057 | AA20: 1474816.2 | AC20: 1551287.2 | AD20: 1671048.1
A21: EBIT (DRE l.121) - memoria · memoria · unid. moeda | C21: [linha bruta, sem código; lançada nas linhas abaixo] | D21: 242324 | E21: 315528 | F21: 502702 | G21: 606181 | I21: 650259 | J21: 664347 | K21: 624813 | L21: 477301 | N21: 485309 | O21: 501037 | P21: 455160 | Q21: -179939 | S21: 611645 | T21: 627326 | U21: 696198 | V21: 684929 | X21: 765955 | Y21: 785390 | Z21: 854091 | AA21: 850691.02 | AC21: 918078.64 | AD21: 1015180
A22: Resultado Financeiro³ (DRE l.123) - memoria · memoria · unid. moeda | C22: [linha bruta, sem código; lançada nas linhas abaixo] | D22: -76658 | E22: -67424 | F22: -132746 | G22: -208138 | I22: -287287 | J22: -399359 | K22: -513667 | L22: -501027 | N22: -474682 | O22: -525574 | P22: -542739 | Q22: -555381 | S22: -538760 | T22: -570722 | U22: -594402 | V22: -606664 | X22: -655210 | Y22: -694079 | Z22: -795318 | AA22: -763921.74 | AC22: -753782.45 | AD22: -845634.83
A23: EBT (DRE l.126) - memoria · memoria · unid. moeda | C23: [linha bruta, sem código; lançada nas linhas abaixo] | D23: 165666 | E23: 248104 | F23: 369956 | G23: 398043 | I23: 362972 | J23: 264989 | K23: 111146 | L23: -23725 | N23: 10627 | O23: -24537 | P23: -87579 | Q23: -735320 | S23: 72886 | T23: 56604 | U23: 101796 | V23: 78265 | X23: 110745 | Y23: 91311 | Z23: 58774 | AA23: 86769.274 | AC23: 164296.19 | AD23: 169545.13
A24: Lucro Líquido (DRE l.128) - memoria · memoria · unid. moeda | C24: [linha bruta, sem código; lançada nas linhas abaixo] | D24: 109481 | E24: 173921 | F24: 259381 | G24: 276656 | I24: 258068 | J24: 186761 | K24: 93718 | L24: 17831 | N24: 21044 | O24: -17864 | P24: -65721 | Q24: -588309 | S24: 48599 | T24: 42548 | U24: 78194 | V24: 62171 | X24: 78468 | Y24: 67595 | Z24: 69955 | AA24: 102344.11 | AC24: 124513.19 | AD24: 135649.66
A25: DERIVADAS (formula nesta aba) | C25: [linha bruta, sem código; lançada nas linhas abaixo]
A26: Residuo do custo: EBT - (receita + custo ex-dep + depreciacao + despesas + desp. e rec. financeiras). Fecha o lucro bruto/EBT divulgados (1T22-3T23 ~15-20 = outros custos; 1T20 +195,4 e 4T20 -50,1 = base pro forma; demais = arredondamento) · derivada · unid. moeda | B26: 2 | C26: COGS (cash) | D26: =D23-D5-D6-D7-D8-D9-D10-D11-D12 -> -1 | E26: =E23-E5-E6-E7-E8-E9-E10-E11-E12 -> 0 | F26: =F23-F5-F6-F7-F8-F9-F10-F11-F12 -> 0 | G26: =G23-G5-G6-G7-G8-G9-G10-G11-G12 -> 0 | I26: =I23-I5-I6-I7-I8-I9-I10-I11-I12 -> 14656 | J26: =J23-J5-J6-J7-J8-J9-J10-J11-J12 -> 16851 | K26: =K23-K5-K6-K7-K8-K9-K10-K11-K12 -> 18885 | L26: =L23-L5-L6-L7-L8-L9-L10-L11-L12 -> 16249 | N26: =N23-N5-N6-N7-N8-N9-N10-N11-N12 -> 16391 | O26: =O23-O5-O6-O7-O8-O9-O10-O11-O12 -> 17469 | P26: =P23-P5-P6-P7-P8-P9-P10-P11-P12 -> 20141 | Q26: =Q23-Q5-Q6-Q7-Q8-Q9-Q10-Q11-Q12 -> -89 | S26: =S23-S5-S6-S7-S8-S9-S10-S11-S12 -> 37 | T26: =T23-T5-T6-T7-T8-T9-T10-T11-T12 -> 31 | U26: =U23-U5-U6-U7-U8-U9-U10-U11-U12 -> 0 | V26: =V23-V5-V6-V7-V8-V9-V10-V11-V12 -> 0 | X26: =X23-X5-X6-X7-X8-X9-X10-X11-X12 -> -1 | Y26: =Y23-Y5-Y6-Y7-Y8-Y9-Y10-Y11-Y12 -> -1 | Z26: =Z23-Z5-Z6-Z7-Z8-Z9-Z10-Z11-Z12 -> 0 | AA26: =AA23-AA5-AA6-AA7-AA8-AA9-AA10-AA11-AA12 -> 0 | AC26: =AC23-AC5-AC6-AC7-AC8-AC9-AC10-AC11-AC12 -> 0 | AD26: =AD23-AD5-AD6-AD7-AD8-AD9-AD10-AD11-AD12 -> 0
A27: IR/CS = lucro liquido - EBT (a planilha nao abre a linha de IR) · derivada · unid. moeda | B27: 7 | C27: Taxes | D27: =D24-D23 -> -56185 | E27: =E24-E23 -> -74183 | F27: =F24-F23 -> -110575 | G27: =G24-G23 -> -121387 | I27: =I24-I23 -> -104904 | J27: =J24-J23 -> -78228 | K27: =K24-K23 -> -17428 | L27: =L24-L23 -> 41556 | N27: =N24-N23 -> 10417 | O27: =O24-O23 -> 6673 | P27: =P24-P23 -> 21858 | Q27: =Q24-Q23 -> 147011 | S27: =S24-S23 -> -24287 | T27: =T24-T23 -> -14056 | U27: =U24-U23 -> -23602 | V27: =V24-V23 -> -16094 | X27: =X24-X23 -> -32277 | Y27: =Y24-Y23 -> -23716 | Z27: =Z24-Z23 -> 11181 | AA27: =AA24-AA23 -> 15574.833 | AC27: =AC24-AC23 -> -39782.999 | AD27: =AD24-AD23 -> -33895.472
A28: D&A = EBIT - EBITDA (negativo): COD1=4 lanca; COD2=2 devolve ao custo (quase toda depreciacao e de frota). EBITDA do Model = EBITDA divulgado · derivada · unid. moeda | C28: [linha bruta, sem código; lançada nas linhas abaixo] | D28: =D21-D19 -> -62178 | E28: =E21-E19 -> -72936 | F28: =F21-F19 -> -110706 | G28: =G21-G19 -> -170431 | I28: =I21-I19 -> -212836 | J28: =J21-J19 -> -240909 | K28: =K21-K19 -> -300524 | L28: =L21-L19 -> -380942 | N28: =N21-N19 -> -390033 | O28: =O21-O19 -> -388955 | P28: =P21-P19 -> -412766 | Q28: =Q21-Q19 -> -1046012 | S28: =S21-S19 -> -447855 | T28: =T21-T19 -> -522034 | U28: =U21-U19 -> -551278 | V28: =V21-V19 -> -559351 | X28: =X21-X19 -> -572374 | Y28: =Y21-Y19 -> -593733 | Z28: =Z21-Z19 -> -624565 | AA28: =AA21-AA19 -> -639359.24 | AC28: =AC21-AC19 -> -650585.92 | AD28: =AD21-AD19 -> -671563.62
A29: (lançamento) código 4, sinal +1 sobre a linha bruta 28: D&A = EBIT - EBITDA (negativo): COD1=4 lanca; COD2=2 devolve ao custo (quase toda deprecia | B29: 4 | C29: D&A | D29: =IF(D28="","",D28) -> -62178 | E29: =IF(E28="","",E28) -> -72936 | F29: =IF(F28="","",F28) -> -110706 | G29: =IF(G28="","",G28) -> -170431 | I29: =IF(I28="","",I28) -> -212836 | J29: =IF(J28="","",J28) -> -240909 | K29: =IF(K28="","",K28) -> -300524 | L29: =IF(L28="","",L28) -> -380942 | N29: =IF(N28="","",N28) -> -390033 | O29: =IF(O28="","",O28) -> -388955 | P29: =IF(P28="","",P28) -> -412766 | Q29: =IF(Q28="","",Q28) -> -1046012 | S29: =IF(S28="","",S28) -> -447855 | T29: =IF(T28="","",T28) -> -522034 | U29: =IF(U28="","",U28) -> -551278 | V29: =IF(V28="","",V28) -> -559351 | X29: =IF(X28="","",X28) -> -572374 | Y29: =IF(Y28="","",Y28) -> -593733 | Z29: =IF(Z28="","",Z28) -> -624565 | AA29: =IF(AA28="","",AA28) -> -639359.24 | AC29: =IF(AC28="","",AC28) -> -650585.92 | AD29: =IF(AD28="","",AD28) -> -671563.62
A30: (lançamento) código 2, sinal -1 sobre a linha bruta 28: D&A = EBIT - EBITDA (negativo): COD1=4 lanca; COD2=2 devolve ao custo (quase toda deprecia | B30: 2 | C30: COGS (cash) | D30: =IF(D28="","",-1*D28) -> 62178 | E30: =IF(E28="","",-1*E28) -> 72936 | F30: =IF(F28="","",-1*F28) -> 110706 | G30: =IF(G28="","",-1*G28) -> 170431 | I30: =IF(I28="","",-1*I28) -> 212836 | J30: =IF(J28="","",-1*J28) -> 240909 | K30: =IF(K28="","",-1*K28) -> 300524 | L30: =IF(L28="","",-1*L28) -> 380942 | N30: =IF(N28="","",-1*N28) -> 390033 | O30: =IF(O28="","",-1*O28) -> 388955 | P30: =IF(P28="","",-1*P28) -> 412766 | Q30: =IF(Q28="","",-1*Q28) -> 1046012 | S30: =IF(S28="","",-1*S28) -> 447855 | T30: =IF(T28="","",-1*T28) -> 522034 | U30: =IF(U28="","",-1*U28) -> 551278 | V30: =IF(V28="","",-1*V28) -> 559351 | X30: =IF(X28="","",-1*X28) -> 572374 | Y30: =IF(Y28="","",-1*Y28) -> 593733 | Z30: =IF(Z28="","",-1*Z28) -> 624565 | AA30: =IF(AA28="","",-1*AA28) -> 639359.24 | AC30: =IF(AC28="","",-1*AC28) -> 650585.92 | AD30: =IF(AD28="","",-1*AD28) -> 671563.62
A31: Lucro liquido (l.128; sem minoritarios) - COD 44 alimenta o check IS do Model · derivada · unid. moeda | B31: 44 | C31: Lucro liquido (l.128; sem minoritarios) - COD 44 alimenta o | D31: =D24 -> 109481 | E31: =E24 -> 173921 | F31: =F24 -> 259381 | G31: =G24 -> 276656 | I31: =I24 -> 258068 | J31: =J24 -> 186761 | K31: =K24 -> 93718 | L31: =L24 -> 17831 | N31: =N24 -> 21044 | O31: =O24 -> -17864 | P31: =P24 -> -65721 | Q31: =Q24 -> -588309 | S31: =S24 -> 48599 | T31: =T24 -> 42548 | U31: =U24 -> 78194 | V31: =V24 -> 62171 | X31: =X24 -> 78468 | Y31: =Y24 -> 67595 | Z31: =Z24 -> 69955 | AA31: =AA24 -> 102344.11 | AC31: =AC24 -> 124513.19 | AD31: =AD24 -> 135649.66
A32: DFC - ACUMULADO NO ANO (R$ milhoes): Dividendos e JCP pagos, DFC consolidada dos ITR/DFP na CVM (contas 6.03.xx "Dividendos..."). A planilha da Cia nao traz DFC | C32: [linha bruta, sem código; lançada nas linhas abaixo]
A33: Dividendos e JCP pagos - acumulado no ano (CVM; soma das contas 6.03 de dividendos/JCP) · memoria · unid. moeda | C33: [linha bruta, sem código; lançada nas linhas abaixo] | D33: 0 | E33: 0 | F33: -64133 | G33: -106614 | I33: -39311 | J33: -348658 | K33: -395507 | L33: -447638 | N33: -47512 | O33: -138201 | P33: -138200 | Q33: -138200 | S33: 0 | T33: 0 | U33: 0 | V33: 0 | X33: 0 | Y33: -55050 | Z33: -55050 | AA33: -55050 | AC33: 0 | AD33: 0
A34: Dividendos e JCP pagos (trimestralizado) · derivada · unid. moeda | B34: 10 | C34: Common Dividends | D34: =N(D33) -> 0 | E34: =N(E33)-N(D33) -> 0 | F34: =N(F33)-N(E33) -> -64133 | G34: =N(G33)-N(F33) -> -42481 | I34: =N(I33) -> -39311 | J34: =N(J33)-N(I33) -> -309347 | K34: =N(K33)-N(J33) -> -46849 | L34: =N(L33)-N(K33) -> -52131 | N34: =N(N33) -> -47512 | O34: =N(O33)-N(N33) -> -90689 | P34: =N(P33)-N(O33) -> 1 | Q34: =N(Q33)-N(P33) -> 0 | S34: =N(S33) -> 0 | T34: =N(T33)-N(S33) -> 0 | U34: =N(U33)-N(T33) -> 0 | V34: =N(V33)-N(U33) -> 0 | X34: =N(X33) -> 0 | Y34: =N(Y33)-N(X33) -> -55050 | Z34: =N(Z33)-N(Y33) -> 0 | AA34: =N(AA33)-N(Z33) -> 0 | AC34: =N(AC33) -> 0 | AD34: =N(AD33)-N(AC33) -> 0
A35: BALANCO (aba BS | BP (Proforma); R$ milhoes). TVM de longo prazo vai para caixa (cod 11), como no calculo de divida liquida da Cia | C35: [linha bruta, sem código; lançada nas linhas abaixo]
A36: A: Caixa e equivalentes de caixa (BP l.6) · fonte · unid. moeda | B36: 11 | C36: Cash and equivalents (inc. investment securities) | D36: 886551 | E36: 2816548 | F36: 4643996 | G36: 146030 | I36: 903521 | J36: 950708 | K36: 401837 | L36: 551764 | N36: 486982 | O36: 487375 | P36: 356841 | Q36: 133394 | S36: 475274 | T36: 674841 | U36: 568043 | V36: 677895 | X36: 847108 | Y36: 1002896 | Z36: 1671176 | AA36: 1322044 | AC36: 1830668 | AD36: 1648914
A37: A: Títulos, valores mobiliários e aplicações financeiras (BP l.7) -> caixa · fonte · unid. moeda | B37: 11 | C37: Cash and equivalents (inc. investment securities) | D37: 2095684 | E37: 2740207 | F37: 3630317 | G37: 7640423 | I37: 4747063 | J37: 4771989 | K37: 7393620 | L37: 6275771 | N37: 3436117 | O37: 2090491 | P37: 1654286 | Q37: 2865358 | S37: 2736012 | T37: 3010162 | U37: 3407676 | V37: 3613468 | X37: 2190087 | Y37: 2436181 | Z37: 1645729 | AA37: 2799536 | AC37: 3650208 | AD37: 1815879
A38: A: Títulos, valores mobiliários e aplicações financeiras (BP l.19) (LP) -> caixa · fonte · unid. moeda | B38: 11 | C38: Cash and equivalents (inc. investment securities) | D38: 2529645 | E38: 0 | F38: 0 | G38: 0 | I38: 0 | J38: 0 | K38: 0 | L38: 0 | N38: 0 | O38: 0 | P38: 0 | Q38: 0 | S38: 0 | T38: 0 | U38: 0 | V38: 0 | X38: 0 | Y38: 2563 | Z38: 2584 | AA38: 2753815 | AC38: 2612312 | AD38: 4014504
A39: A: Instrumentos financeiros derivativos (BP l.8) · fonte · unid. moeda | B39: 22 | C39: Other non-current assets | D39: 0 | E39: 0 | F39: 0 | G39: 0 | I39: 0 | J39: 0 | K39: 0 | L39: 0 | N39: 0 | O39: 0 | P39: 0 | Q39: 0 | S39: 0 | T39: 0 | U39: 0 | V39: 0 | X39: 0 | Y39: 0 | Z39: 0 | AA39: 0 | AC39: 0 | AD39: 31224
A40: A: Contas a receber (BP l.9) · fonte · unid. moeda | B40: 12 | C40: Accounts receivable | D40: 447114 | E40: 550855 | F40: 631554 | G40: 879885 | I40: 1075725 | J40: 1284046 | K40: 1044110 | L40: 1173855 | N40: 1024973 | O40: 1099135 | P40: 1309929 | Q40: 1343672 | S40: 1541190 | T40: 1684002 | U40: 1736952 | V40: 1441650 | X40: 2183360 | Y40: 2175461 | Z40: 2216498 | AA40: 1989613 | AC40: 2172228 | AD40: 2293273
...

Sheet Inputs (2)
A1: =IF(Control!B3="","EMPRESA",Control!B3) -> Movida | B1: Código | C1: Conta padronizada | D1: 2021 | E1: 2021 | F1: 2021 | G1: 2021 | H1: 2021 | I1: 2022 | J1: 2022 | K1: 2022 | L1: 2022 | M1: 2022 | N1: 2023 | O1: 2023 | P1: 2023 | Q1: 2023 | R1: 2023 | S1: 2024 | T1: 2024 | U1: 2024 | V1: 2024 | W1: 2024 | X1: 2025 | Y1: 2025 | Z1: 2025 | AA1: 2025 | AB1: 2025 | AC1: 2026 | AD1: 2026 | AE1: 2026 | AF1: 2026 | AG1: 2026
A2: R$ milhões | C2: Período | D2: 1Q21 | E2: 2Q21 | F2: 3Q21 | G2: 4Q21 | H2: 2021 | I2: 1Q22 | J2: 2Q22 | K2: 3Q22 | L2: 4Q22 | M2: 2022 | N2: 1Q23 | O2: 2Q23 | P2: 3Q23 | Q2: 4Q23 | R2: 2023 | S2: 1Q24 | T2: 2Q24 | U2: 3Q24 | V2: 4Q24 | W2: 2024 | X2: 1Q25 | Y2: 2Q25 | Z2: 3Q25 | AA2: 4Q25 | AB2: 2025 | AC2: 1Q26 | AD2: 2Q26 | AE2: 3Q26 | AF2: 4Q26 | AG2: 2026
A3: Actual flag | C3: 0 = sem dados / 1 = realizado | D3: 1 | E3: 1 | F3: 1 | G3: 1 | H3: 1 | I3: 1 | J3: 1 | K3: 1 | L3: 1 | M3: 1 | N3: 1 | O3: 1 | P3: 1 | Q3: 1 | R3: 1 | S3: 1 | T3: 1 | U3: 1 | V3: 1 | W3: 1 | X3: 1 | Y3: 1 | Z3: 1 | AA3: 1 | AB3: 1 | AC3: 1 | AD3: 1 | AE3: 0 | AF3: 0 | AG3: 0
B4: 1 | C4: Net Revenues | D4: =IF(D$3=0,"",SUMIFS(INDEX(Inputs!$D$4:$AG$200,0,MATCH(D$2,Inputs!$D$2:$AG$2,0)),Inputs!$B$4:$B$200,$B4)/1000) -> 757.552 | E4: =IF(E$3=0,"",SUMIFS(INDEX(Inputs!$D$4:$AG$200,0,MATCH(E$2,Inputs!$D$2:$AG$2,0)),Inputs!$B$4:$B$200,$B4)/1000) -> 1165.345 | F4: =IF(F$3=0,"",SUMIFS(INDEX(Inputs!$D$4:$AG$200,0,MATCH(F$2,Inputs!$D$2:$AG$2,0)),Inputs!$B$4:$B$200,$B4)/1000) -> 1521.076 | G4: =IF(G$3=0,"",SUMIFS(INDEX(Inputs!$D$4:$AG$200,0,MATCH(G$2,Inputs!$D$2:$AG$2,0)),Inputs!$B$4:$B$200,$B4)/1000) -> 1689.065 | H4: =IF(COUNT(D4:G4)=4,SUM(D4:G4),"") -> 5133.038 | I4: =IF(I$3=0,"",SUMIFS(INDEX(Inputs!$D$4:$AG$200,0,MATCH(I$2,Inputs!$D$2:$AG$2,0)),Inputs!$B$4:$B$200,$B4)/1000) -> 1905.657 | J4: =IF(J$3=0,"",SUMIFS(INDEX(Inputs!$D$4:$AG$200,0,MATCH(J$2,Inputs!$D$2:$AG$2,0)),Inputs!$B$4:$B$200,$B4)/1000) -> 2230.992 | K4: =IF(K$3=0,"",SUMIFS(INDEX(Inputs!$D$4:$AG$200,0,MATCH(K$2,Inputs!$D$2:$AG$2,0)),Inputs!$B$4:$B$200,$B4)/1000) -> 2536.864 | L4: =IF(L$3=0,"",SUMIFS(INDEX(Inputs!$D$4:$AG$200,0,MATCH(L$2,Inputs!$D$2:$AG$2,0)),Inputs!$B$4:$B$200,$B4)/1000) -> 2626.633 | M4: =IF(COUNT(I4:L4)=4,SUM(I4:L4),"") -> 9300.146 | N4: =IF(N$3=0,"",SUMIFS(INDEX(Inputs!$D$4:$AG$200,0,MATCH(N$2,Inputs!$D$2:$AG$2,0)),Inputs!$B$4:$B$200,$B4)/1000) -> 2703.206 | O4: =IF(O$3=0,"",SUMIFS(INDEX(Inputs!$D$4:$AG$200,0,MATCH(O$2,Inputs!$D$2:$AG$2,0)),Inputs!$B$4:$B$200,$B4)/1000) -> 2479.144 | P4: =IF(P$3=0,"",SUMIFS(INDEX(Inputs!$D$4:$AG$200,0,MATCH(P$2,Inputs!$D$2:$AG$2,0)),Inputs!$B$4:$B$200,$B4)/1000) -> 2666.22 | Q4: =IF(Q$3=0,"",SUMIFS(INDEX(Inputs!$D$4:$AG$200,0,MATCH(Q$2,Inputs!$D$2:$AG$2,0)),Inputs!$B$4:$B$200,$B4)/1000) -> 2493.444 | R4: =IF(COUNT(N4:Q4)=4,SUM(N4:Q4),"") -> 10342.014 | S4: =IF(S$3=0,"",SUMIFS(INDEX(Inputs!$D$4:$AG$200,0,MATCH(S$2,Inputs!$D$2:$AG$2,0)),Inputs!$B$4:$B$200,$B4)/1000) -> 3021.646 | T4: =IF(T$3=0,"",SUMIFS(INDEX(Inputs!$D$4:$AG$200,0,MATCH(T$2,Inputs!$D$2:$AG$2,0)),Inputs!$B$4:$B$200,$B4)/1000) -> 3435.604 | U4: =IF(U$3=0,"",SUMIFS(INDEX(Inputs!$D$4:$AG$200,0,MATCH(U$2,Inputs!$D$2:$AG$2,0)),Inputs!$B$4:$B$200,$B4)/1000) -> 3775.864 | V4: =IF(V$3=0,"",SUMIFS(INDEX(Inputs!$D$4:$AG$200,0,MATCH(V$2,Inputs!$D$2:$AG$2,0)),Inputs!$B$4:$B$200,$B4)/1000) -> 3248.157 | W4: =IF(COUNT(S4:V4)=4,SUM(S4:V4),"") -> 13481.271 | X4: =IF(X$3=0,"",SUMIFS(INDEX(Inputs!$D$4:$AG$200,0,MATCH(X$2,Inputs!$D$2:$AG$2,0)),Inputs!$B$4:$B$200,$B4)/1000) -> 3568.231 | Y4: =IF(Y$3=0,"",SUMIFS(INDEX(Inputs!$D$4:$AG$200,0,MATCH(Y$2,Inputs!$D$2:$AG$2,0)),Inputs!$B$4:$B$200,$B4)/1000) -> 3679.006 | Z4: =IF(Z$3=0,"",SUMIFS(INDEX(Inputs!$D$4:$AG$200,0,MATCH(Z$2,Inputs!$D$2:$AG$2,0)),Inputs!$B$4:$B$200,$B4)/1000) -> 3765.843 | AA4: =IF(AA$3=0,"",SUMIFS(INDEX(Inputs!$D$4:$AG$200,0,MATCH(AA$2,Inputs!$D$2:$AG$2,0)),Inputs!$B$4:$B$200,$B4)/1000) -> 3658.9752 | AB4: =IF(COUNT(X4:AA4)=4,SUM(X4:AA4),"") -> 14672.055 | AC4: =IF(AC$3=0,"",SUMIFS(INDEX(Inputs!$D$4:$AG$200,0,MATCH(AC$2,Inputs!$D$2:$AG$2,0)),Inputs!$B$4:$B$200,$B4)/1000) -> 3780.645 | AD4: =IF(AD$3=0,"",SUMIFS(INDEX(Inputs!$D$4:$AG$200,0,MATCH(AD$2,Inputs!$D$2:$AG$2,0)),Inputs!$B$4:$B$200,$B4)/1000) -> 3765.8302 | AE4: =IF(AE$3=0,"",SUMIFS(INDEX(Inputs!$D$4:$AG$200,0,MATCH(AE$2,Inputs!$D$2:$AG$2,0)),Inputs!$B$4:$B$200,$B4)/1000) | AF4: =IF(AF$3=0,"",SUMIFS(INDEX(Inputs!$D$4:$AG$200,0,MATCH(AF$2,Inputs!$D$2:$AG$2,0)),Inputs!$B$4:$B$200,$B4)/1000) | AG4: =IF(COUNT(AC4:AF4)=4,SUM(AC4:AF4),"")
B5: 2 | C5: COGS (cash) | D5: =IF(D$3=0,"",SUMIFS(INDEX(Inputs!$D$4:$AG$200,0,MATCH(D$2,Inputs!$D$2:$AG$2,0)),Inputs!$B$4:$B$200,$B5)/1000) -> -296.445 | E5: =IF(E$3=0,"",SUMIFS(INDEX(Inputs!$D$4:$AG$200,0,MATCH(E$2,Inputs!$D$2:$AG$2,0)),Inputs!$B$4:$B$200,$B5)/1000) -> -605.183 | F5: =IF(F$3=0,"",SUMIFS(INDEX(Inputs!$D$4:$AG$200,0,MATCH(F$2,Inputs!$D$2:$AG$2,0)),Inputs!$B$4:$B$200,$B5)/1000) -> -729.162 | G5: =IF(G$3=0,"",SUMIFS(INDEX(Inputs!$D$4:$AG$200,0,MATCH(G$2,Inputs!$D$2:$AG$2,0)),Inputs!$B$4:$B$200,$B5)/1000) -> -699.45 | H5: =IF(COUNT(D5:G5)=4,SUM(D5:G5),"") -> -2330.24 | I5: =IF(I$3=0,"",SUMIFS(INDEX(Inputs!$D$4:$AG$200,0,MATCH(I$2,Inputs!$D$2:$AG$2,0)),Inputs!$B$4:$B$200,$B5)/1000) -> -807.931 | J5: =IF(J$3=0,"",SUMIFS(INDEX(Inputs!$D$4:$AG$200,0,MATCH(J$2,Inputs!$D$2:$AG$2,0)),Inputs!$B$4:$B$200,$B5)/1000) -> -1068.195 | K5: =IF(K$3=0,"",SUMIFS(INDEX(Inputs!$D$4:$AG$200,0,MATCH(K$2,Inputs!$D$2:$AG$2,0)),Inputs!$B$4:$B$200,$B5)/1000) -> -1319.005 | L5: =IF(L$3=0,"",SUMIFS(INDEX(Inputs!$D$4:$AG$200,0,MATCH(L$2,Inputs!$D$2:$AG$2,0)),Inputs!$B$4:$B$200,$B5)/1000) -> -1423.846 | M5: =IF(COUNT(I5:L5)=4,SUM(I5:L5),"") -> -4618.977 | N5: =IF(N$3=0,"",SUMIFS(INDEX(Inputs!$D$4:$AG$200,0,MATCH(N$2,Inputs!$D$2:$AG$2,0)),Inputs!$B$4:$B$200,$B5)/1000) -> -1495.089 | O5: =IF(O$3=0,"",SUMIFS(INDEX(Inputs!$D$4:$AG$200,0,MATCH(O$2,Inputs!$D$2:$AG$2,0)),Inputs!$B$4:$B$200,$B5)/1000) -> -1259.21 | P5: =IF(P$3=0,"",SUMIFS(INDEX(Inputs!$D$4:$AG$200,0,MATCH(P$2,Inputs!$D$2:$AG$2,0)),Inputs!$B$4:$B$200,$B5)/1000) -> -1459.743 | Q5: =IF(Q$3=0,"",SUMIFS(INDEX(Inputs!$D$4:$AG$200,0,MATCH(Q$2,Inputs!$D$2:$AG$2,0)),Inputs!$B$4:$B$200,$B5)/1000) -> -1121.686 | R5: =IF(COUNT(N5:Q5)=4,SUM(N5:Q5),"") -> -5335.728 | S5: =IF(S$3=0,"",SUMIFS(INDEX(Inputs!$D$4:$AG$200,0,MATCH(S$2,Inputs!$D$2:$AG$2,0)),Inputs!$B$4:$B$200,$B5)/1000) -> -1641.713 | T5: =IF(T$3=0,"",SUMIFS(INDEX(Inputs!$D$4:$AG$200,0,MATCH(T$2,Inputs!$D$2:$AG$2,0)),Inputs!$B$4:$B$200,$B5)/1000) -> -1943.53 | U5: =IF(U$3=0,"",SUMIFS(INDEX(Inputs!$D$4:$AG$200,0,MATCH(U$2,Inputs!$D$2:$AG$2,0)),Inputs!$B$4:$B$200,$B5)/1000) -> -2167.358 | V5: =IF(V$3=0,"",SUMIFS(INDEX(Inputs!$D$4:$AG$200,0,MATCH(V$2,Inputs!$D$2:$AG$2,0)),Inputs!$B$4:$B$200,$B5)/1000) -> -1632.258 | W5: =IF(COUNT(S5:V5)=4,SUM(S5:V5),"") -> -7384.859 | X5: =IF(X$3=0,"",SUMIFS(INDEX(Inputs!$D$4:$AG$200,0,MATCH(X$2,Inputs!$D$2:$AG$2,0)),Inputs!$B$4:$B$200,$B5)/1000) -> -1850.292 | Y5: =IF(Y$3=0,"",SUMIFS(INDEX(Inputs!$D$4:$AG$200,0,MATCH(Y$2,Inputs!$D$2:$AG$2,0)),Inputs!$B$4:$B$200,$B5)/1000) -> -1930.49 | Z5: =IF(Z$3=0,"",SUMIFS(INDEX(Inputs!$D$4:$AG$200,0,MATCH(Z$2,Inputs!$D$2:$AG$2,0)),Inputs!$B$4:$B$200,$B5)/1000) -> -1923.127 | AA5: =IF(AA$3=0,"",SUMIFS(INDEX(Inputs!$D$4:$AG$200,0,MATCH(AA$2,Inputs!$D$2:$AG$2,0)),Inputs!$B$4:$B$200,$B5)/1000) -> -1775.8778 | AB5: =IF(COUNT(X5:AA5)=4,SUM(X5:AA5),"") -> -7479.7868 | AC5: =IF(AC$3=0,"",SUMIFS(INDEX(Inputs!$D$4:$AG$200,0,MATCH(AC$2,Inputs!$D$2:$AG$2,0)),Inputs!$B$4:$B$200,$B5)/1000) -> -1792.9548 | AD5: =IF(AD$3=0,"",SUMIFS(INDEX(Inputs!$D$4:$AG$200,0,MATCH(AD$2,Inputs!$D$2:$AG$2,0)),Inputs!$B$4:$B$200,$B5)/1000) -> -1658.145 | AE5: =IF(AE$3=0,"",SUMIFS(INDEX(Inputs!$D$4:$AG$200,0,MATCH(AE$2,Inputs!$D$2:$AG$2,0)),Inputs!$B$4:$B$200,$B5)/1000) | AF5: =IF(AF$3=0,"",SUMIFS(INDEX(Inputs!$D$4:$AG$200,0,MATCH(AF$2,Inputs!$D$2:$AG$2,0)),Inputs!$B$4:$B$200,$B5)/1000) | AG5: =IF(COUNT(AC5:AF5)=4,SUM(AC5:AF5),"")
B6: 3 | C6: SG&A and Other (cash) | D6: =IF(D$3=0,"",SUMIFS(INDEX(Inputs!$D$4:$AG$200,0,MATCH(D$2,Inputs!$D$2:$AG$2,0)),Inputs!$B$4:$B$200,$B6)/1000) -> -156.605 | E6: =IF(E$3=0,"",SUMIFS(INDEX(Inputs!$D$4:$AG$200,0,MATCH(E$2,Inputs!$D$2:$AG$2,0)),Inputs!$B$4:$B$200,$B6)/1000) -> -171.698 | F6: =IF(F$3=0,"",SUMIFS(INDEX(Inputs!$D$4:$AG$200,0,MATCH(F$2,Inputs!$D$2:$AG$2,0)),Inputs!$B$4:$B$200,$B6)/1000) -> -178.506 | G6: =IF(G$3=0,"",SUMIFS(INDEX(Inputs!$D$4:$AG$200,0,MATCH(G$2,Inputs!$D$2:$AG$2,0)),Inputs!$B$4:$B$200,$B6)/1000) -> -213.003 | H6: =IF(COUNT(D6:G6)=4,SUM(D6:G6),"") -> -719.812 | I6: =IF(I$3=0,"",SUMIFS(INDEX(Inputs!$D$4:$AG$200,0,MATCH(I$2,Inputs!$D$2:$AG$2,0)),Inputs!$B$4:$B$200,$B6)/1000) -> -234.631 | J6: =IF(J$3=0,"",SUMIFS(INDEX(Inputs!$D$4:$AG$200,0,MATCH(J$2,Inputs!$D$2:$AG$2,0)),Inputs!$B$4:$B$200,$B6)/1000) -> -257.54 | K6: =IF(K$3=0,"",SUMIFS(INDEX(Inputs!$D$4:$AG$200,0,MATCH(K$2,Inputs!$D$2:$AG$2,0)),Inputs!$B$4:$B$200,$B6)/1000) -> -292.522 | L6: =IF(L$3=0,"",SUMIFS(INDEX(Inputs!$D$4:$AG$200,0,MATCH(L$2,Inputs!$D$2:$AG$2,0)),Inputs!$B$4:$B$200,$B6)/1000) -> -344.544 | M6: =IF(COUNT(I6:L6)=4,SUM(I6:L6),"") -> -1129.237 | N6: =IF(N$3=0,"",SUMIFS(INDEX(Inputs!$D$4:$AG$200,0,MATCH(N$2,Inputs!$D$2:$AG$2,0)),Inputs!$B$4:$B$200,$B6)/1000) -> -332.775 | O6: =IF(O$3=0,"",SUMIFS(INDEX(Inputs!$D$4:$AG$200,0,MATCH(O$2,Inputs!$D$2:$AG$2,0)),Inputs!$B$4:$B$200,$B6)/1000) -> -329.942 | P6: =IF(P$3=0,"",SUMIFS(INDEX(Inputs!$D$4:$AG$200,0,MATCH(P$2,Inputs!$D$2:$AG$2,0)),Inputs!$B$4:$B$200,$B6)/1000) -> -338.551 | Q6: =IF(Q$3=0,"",SUMIFS(INDEX(Inputs!$D$4:$AG$200,0,MATCH(Q$2,Inputs!$D$2:$AG$2,0)),Inputs!$B$4:$B$200,$B6)/1000) -> -505.685 | R6: =IF(COUNT(N6:Q6)=4,SUM(N6:Q6),"") -> -1506.953 | S6: =IF(S$3=0,"",SUMIFS(INDEX(Inputs!$D$4:$AG$200,0,MATCH(S$2,Inputs!$D$2:$AG$2,0)),Inputs!$B$4:$B$200,$B6)/1000) -> -320.432 | T6: =IF(T$3=0,"",SUMIFS(INDEX(Inputs!$D$4:$AG$200,0,MATCH(T$2,Inputs!$D$2:$AG$2,0)),Inputs!$B$4:$B$200,$B6)/1000) -> -342.713 | U6: =IF(U$3=0,"",SUMIFS(INDEX(Inputs!$D$4:$AG$200,0,MATCH(U$2,Inputs!$D$2:$AG$2,0)),Inputs!$B$4:$B$200,$B6)/1000) -> -361.03 | V6: =IF(V$3=0,"",SUMIFS(INDEX(Inputs!$D$4:$AG$200,0,MATCH(V$2,Inputs!$D$2:$AG$2,0)),Inputs!$B$4:$B$200,$B6)/1000) -> -371.618 | W6: =IF(COUNT(S6:V6)=4,SUM(S6:V6),"") -> -1395.793 | X6: =IF(X$3=0,"",SUMIFS(INDEX(Inputs!$D$4:$AG$200,0,MATCH(X$2,Inputs!$D$2:$AG$2,0)),Inputs!$B$4:$B$200,$B6)/1000) -> -379.61 | Y6: =IF(Y$3=0,"",SUMIFS(INDEX(Inputs!$D$4:$AG$200,0,MATCH(Y$2,Inputs!$D$2:$AG$2,0)),Inputs!$B$4:$B$200,$B6)/1000) -> -369.393 | Z6: =IF(Z$3=0,"",SUMIFS(INDEX(Inputs!$D$4:$AG$200,0,MATCH(Z$2,Inputs!$D$2:$AG$2,0)),Inputs!$B$4:$B$200,$B6)/1000) -> -364.059 | AA6: =IF(AA$3=0,"",SUMIFS(INDEX(Inputs!$D$4:$AG$200,0,MATCH(AA$2,Inputs!$D$2:$AG$2,0)),Inputs!$B$4:$B$200,$B6)/1000) -> -393.04709 | AB6: =IF(COUNT(X6:AA6)=4,SUM(X6:AA6),"") -> -1506.1091 | AC6: =IF(AC$3=0,"",SUMIFS(INDEX(Inputs!$D$4:$AG$200,0,MATCH(AC$2,Inputs!$D$2:$AG$2,0)),Inputs!$B$4:$B$200,$B6)/1000) -> -419.02555 | AD6: =IF(AD$3=0,"",SUMIFS(INDEX(Inputs!$D$4:$AG$200,0,MATCH(AD$2,Inputs!$D$2:$AG$2,0)),Inputs!$B$4:$B$200,$B6)/1000) -> -420.94157 | AE6: =IF(AE$3=0,"",SUMIFS(INDEX(Inputs!$D$4:$AG$200,0,MATCH(AE$2,Inputs!$D$2:$AG$2,0)),Inputs!$B$4:$B$200,$B6)/1000) | AF6: =IF(AF$3=0,"",SUMIFS(INDEX(Inputs!$D$4:$AG$200,0,MATCH(AF$2,Inputs!$D$2:$AG$2,0)),Inputs!$B$4:$B$200,$B6)/1000) | AG6: =IF(COUNT(AC6:AF6)=4,SUM(AC6:AF6),"")
B7: 4 | C7: D&A | D7: =IF(D$3=0,"",SUMIFS(INDEX(Inputs!$D$4:$AG$200,0,MATCH(D$2,Inputs!$D$2:$AG$2,0)),Inputs!$B$4:$B$200,$B7)/1000) -> -62.178 | E7: =IF(E$3=0,"",SUMIFS(INDEX(Inputs!$D$4:$AG$200,0,MATCH(E$2,Inputs!$D$2:$AG$2,0)),Inputs!$B$4:$B$200,$B7)/1000) -> -72.936 | F7: =IF(F$3=0,"",SUMIFS(INDEX(Inputs!$D$4:$AG$200,0,MATCH(F$2,Inputs!$D$2:$AG$2,0)),Inputs!$B$4:$B$200,$B7)/1000) -> -110.706 | G7: =IF(G$3=0,"",SUMIFS(INDEX(Inputs!$D$4:$AG$200,0,MATCH(G$2,Inputs!$D$2:$AG$2,0)),Inputs!$B$4:$B$200,$B7)/1000) -> -170.431 | H7: =IF(COUNT(D7:G7)=4,SUM(D7:G7),"") -> -416.251 | I7: =IF(I$3=0,"",SUMIFS(INDEX(Inputs!$D$4:$AG$200,0,MATCH(I$2,Inputs!$D$2:$AG$2,0)),Inputs!$B$4:$B$200,$B7)/1000) -> -212.836 | J7: =IF(J$3=0,"",SUMIFS(INDEX(Inputs!$D$4:$AG$200,0,MATCH(J$2,Inputs!$D$2:$AG$2,0)),Inputs!$B$4:$B$200,$B7)/1000) -> -240.909 | K7: =IF(K$3=0,"",SUMIFS(INDEX(Inputs!$D$4:$AG$200,0,MATCH(K$2,Inputs!$D$2:$AG$2,0)),Inputs!$B$4:$B$200,$B7)/1000) -> -300.524 | L7: =IF(L$3=0,"",SUMIFS(INDEX(Inputs!$D$4:$AG$200,0,MATCH(L$2,Inputs!$D$2:$AG$2,0)),Inputs!$B$4:$B$200,$B7)/1000) -> -380.942 | M7: =IF(COUNT(I7:L7)=4,SUM(I7:L7),"") -> -1135.211 | N7: =IF(N$3=0,"",SUMIFS(INDEX(Inputs!$D$4:$AG$200,0,MATCH(N$2,Inputs!$D$2:$AG$2,0)),Inputs!$B$4:$B$200,$B7)/1000) -> -390.033 | O7: =IF(O$3=0,"",SUMIFS(INDEX(Inputs!$D$4:$AG$200,0,MATCH(O$2,Inputs!$D$2:$AG$2,0)),Inputs!$B$4:$B$200,$B7)/1000) -> -388.955 | P7: =IF(P$3=0,"",SUMIFS(INDEX(Inputs!$D$4:$AG$200,0,MATCH(P$2,Inputs!$D$2:$AG$2,0)),Inputs!$B$4:$B$200,$B7)/1000) -> -412.766 | Q7: =IF(Q$3=0,"",SUMIFS(INDEX(Inputs!$D$4:$AG$200,0,MATCH(Q$2,Inputs!$D$2:$AG$2,0)),Inputs!$B$4:$B$200,$B7)/1000) -> -1046.012 | R7: =IF(COUNT(N7:Q7)=4,SUM(N7:Q7),"") -> -2237.766 | S7: =IF(S$3=0,"",SUMIFS(INDEX(Inputs!$D$4:$AG$200,0,MATCH(S$2,Inputs!$D$2:$AG$2,0)),Inputs!$B$4:$B$200,$B7)/1000) -> -447.855 | T7: =IF(T$3=0,"",SUMIFS(INDEX(Inputs!$D$4:$AG$200,0,MATCH(T$2,Inputs!$D$2:$AG$2,0)),Inputs!$B$4:$B$200,$B7)/1000) -> -522.034 | U7: =IF(U$3=0,"",SUMIFS(INDEX(Inputs!$D$4:$AG$200,0,MATCH(U$2,Inputs!$D$2:$AG$2,0)),Inputs!$B$4:$B$200,$B7)/1000) -> -551.278 | V7: =IF(V$3=0,"",SUMIFS(INDEX(Inputs!$D$4:$AG$200,0,MATCH(V$2,Inputs!$D$2:$AG$2,0)),Inputs!$B$4:$B$200,$B7)/1000) -> -559.351 | W7: =IF(COUNT(S7:V7)=4,SUM(S7:V7),"") -> -2080.518 | X7: =IF(X$3=0,"",SUMIFS(INDEX(Inputs!$D$4:$AG$200,0,MATCH(X$2,Inputs!$D$2:$AG$2,0)),Inputs!$B$4:$B$200,$B7)/1000) -> -572.374 | Y7: =IF(Y$3=0,"",SUMIFS(INDEX(Inputs!$D$4:$AG$200,0,MATCH(Y$2,Inputs!$D$2:$AG$2,0)),Inputs!$B$4:$B$200,$B7)/1000) -> -593.733 | Z7: =IF(Z$3=0,"",SUMIFS(INDEX(Inputs!$D$4:$AG$200,0,MATCH(Z$2,Inputs!$D$2:$AG$2,0)),Inputs!$B$4:$B$200,$B7)/1000) -> -624.565 | AA7: =IF(AA$3=0,"",SUMIFS(INDEX(Inputs!$D$4:$AG$200,0,MATCH(AA$2,Inputs!$D$2:$AG$2,0)),Inputs!$B$4:$B$200,$B7)/1000) -> -639.35924 | AB7: =IF(COUNT(X7:AA7)=4,SUM(X7:AA7),"") -> -2430.0312 | AC7: =IF(AC$3=0,"",SUMIFS(INDEX(Inputs!$D$4:$AG$200,0,MATCH(AC$2,Inputs!$D$2:$AG$2,0)),Inputs!$B$4:$B$200,$B7)/1000) -> -650.58592 | AD7: =IF(AD$3=0,"",SUMIFS(INDEX(Inputs!$D$4:$AG$200,0,MATCH(AD$2,Inputs!$D$2:$AG$2,0)),Inputs!$B$4:$B$200,$B7)/1000) -> -671.56362 | AE7: =IF(AE$3=0,"",SUMIFS(INDEX(Inputs!$D$4:$AG$200,0,MATCH(AE$2,Inputs!$D$2:$AG$2,0)),Inputs!$B$4:$B$200,$B7)/1000) | AF7: =IF(AF$3=0,"",SUMIFS(INDEX(Inputs!$D$4:$AG$200,0,MATCH(AF$2,Inputs!$D$2:$AG$2,0)),Inputs!$B$4:$B$200,$B7)/1000) | AG7: =IF(COUNT(AC7:AF7)=4,SUM(AC7:AF7),"")
B8: 5 | C8: Interest Expense | D8: =IF(D$3=0,"",SUMIFS(INDEX(Inputs!$D$4:$AG$200,0,MATCH(D$2,Inputs!$D$2:$AG$2,0)),Inputs!$B$4:$B$200,$B8)/1000) -> -265.184 | E8: =IF(E$3=0,"",SUMIFS(INDEX(Inputs!$D$4:$AG$200,0,MATCH(E$2,Inputs!$D$2:$AG$2,0)),Inputs!$B$4:$B$200,$B8)/1000) -> 239.899 | F8: =IF(F$3=0,"",SUMIFS(INDEX(Inputs!$D$4:$AG$200,0,MATCH(F$2,Inputs!$D$2:$AG$2,0)),Inputs!$B$4:$B$200,$B8)/1000) -> -342.257 | G8: =IF(G$3=0,"",SUMIFS(INDEX(Inputs!$D$4:$AG$200,0,MATCH(G$2,Inputs!$D$2:$AG$2,0)),Inputs!$B$4:$B$200,$B8)/1000) -> -591.177 | H8: =IF(COUNT(D8:G8)=4,SUM(D8:G8),"") -> -958.719 | I8: =IF(I$3=0,"",SUMIFS(INDEX(Inputs!$D$4:$AG$200,0,MATCH(I$2,Inputs!$D$2:$AG$2,0)),Inputs!$B$4:$B$200,$B8)/1000) -> -394.958 | J8: =IF(J$3=0,"",SUMIFS(INDEX(Inputs!$D$4:$AG$200,0,MATCH(J$2,Inputs!$D$2:$AG$2,0)),Inputs!$B$4:$B$200,$B8)/1000) -> -515.803 | K8: =IF(K$3=0,"",SUMIFS(INDEX(Inputs!$D$4:$AG$200,0,MATCH(K$2,Inputs!$D$2:$AG$2,0)),Inputs!$B$4:$B$200,$B8)/1000) -> -637.391 | L8: =IF(L$3=0,"",SUMIFS(INDEX(Inputs!$D$4:$AG$200,0,MATCH(L$2,Inputs!$D$2:$AG$2,0)),Inputs!$B$4:$B$200,$B8)/1000) -> -662.277 | M8: =IF(COUNT(I8:L8)=4,SUM(I8:L8),"") -> -2210.429 | N8: =IF(N$3=0,"",SUMIFS(INDEX(Inputs!$D$4:$AG$200,0,MATCH(N$2,Inputs!$D$2:$AG$2,0)),Inputs!$B$4:$B$200,$B8)/1000) -> -615.278 | O8: =IF(O$3=0,"",SUMIFS(INDEX(Inputs!$D$4:$AG$200,0,MATCH(O$2,Inputs!$D$2:$AG$2,0)),Inputs!$B$4:$B$200,$B8)/1000) -> -551.559 | P8: =IF(P$3=0,"",SUMIFS(INDEX(Inputs!$D$4:$AG$200,0,MATCH(P$2,Inputs!$D$2:$AG$2,0)),Inputs!$B$4:$B$200,$B8)/1000) -> -590.177 | Q8: =IF(Q$3=0,"",SUMIFS(INDEX(Inputs!$D$4:$AG$200,0,MATCH(Q$2,Inputs!$D$2:$AG$2,0)),Inputs!$B$4:$B$200,$B8)/1000) -> -614.436 | R8: =IF(COUNT(N8:Q8)=4,SUM(N8:Q8),"") -> -2371.45 | S8: =IF(S$3=0,"",SUMIFS(INDEX(Inputs!$D$4:$AG$200,0,MATCH(S$2,Inputs!$D$2:$AG$2,0)),Inputs!$B$4:$B$200,$B8)/1000) -> -627.625 | T8: =IF(T$3=0,"",SUMIFS(INDEX(Inputs!$D$4:$AG$200,0,MATCH(T$2,Inputs!$D$2:$AG$2,0)),Inputs!$B$4:$B$200,$B8)/1000) -> -662.137 | U8: =IF(U$3=0,"",SUMIFS(INDEX(Inputs!$D$4:$AG$200,0,MATCH(U$2,Inputs!$D$2:$AG$2,0)),Inputs!$B$4:$B$200,$B8)/1000) -> -707.297 | V8: =IF(V$3=0,"",SUMIFS(INDEX(Inputs!$D$4:$AG$200,0,MATCH(V$2,Inputs!$D$2:$AG$2,0)),Inputs!$B$4:$B$200,$B8)/1000) -> -691.837 | W8: =IF(COUNT(S8:V8)=4,SUM(S8:V8),"") -> -2688.896 | X8: =IF(X$3=0,"",SUMIFS(INDEX(Inputs!$D$4:$AG$200,0,MATCH(X$2,Inputs!$D$2:$AG$2,0)),Inputs!$B$4:$B$200,$B8)/1000) -> -745.217 | Y8: =IF(Y$3=0,"",SUMIFS(INDEX(Inputs!$D$4:$AG$200,0,MATCH(Y$2,Inputs!$D$2:$AG$2,0)),Inputs!$B$4:$B$200,$B8)/1000) -> -792.778 | Z8: =IF(Z$3=0,"",SUMIFS(INDEX(Inputs!$D$4:$AG$200,0,MATCH(Z$2,Inputs!$D$2:$AG$2,0)),Inputs!$B$4:$B$200,$B8)/1000) -> -895.889 | AA8: =IF(AA$3=0,"",SUMIFS(INDEX(Inputs!$D$4:$AG$200,0,MATCH(AA$2,Inputs!$D$2:$AG$2,0)),Inputs!$B$4:$B$200,$B8)/1000) -> -1154.5137 | AB8: =IF(COUNT(X8:AA8)=4,SUM(X8:AA8),"") -> -3588.3977 | AC8: =IF(AC$3=0,"",SUMIFS(INDEX(Inputs!$D$4:$AG$200,0,MATCH(AC$2,Inputs!$D$2:$AG$2,0)),Inputs!$B$4:$B$200,$B8)/1000) -> -902.57786 | AD8: =IF(AD$3=0,"",SUMIFS(INDEX(Inputs!$D$4:$AG$200,0,MATCH(AD$2,Inputs!$D$2:$AG$2,0)),Inputs!$B$4:$B$200,$B8)/1000) -> -1000.7705 | AE8: =IF(AE$3=0,"",SUMIFS(INDEX(Inputs!$D$4:$AG$200,0,MATCH(AE$2,Inputs!$D$2:$AG$2,0)),Inputs!$B$4:$B$200,$B8)/1000) | AF8: =IF(AF$3=0,"",SUMIFS(INDEX(Inputs!$D$4:$AG$200,0,MATCH(AF$2,Inputs!$D$2:$AG$2,0)),Inputs!$B$4:$B$200,$B8)/1000) | AG8: =IF(COUNT(AC8:AF8)=4,SUM(AC8:AF8),"")
B9: 6 | C9: Nonoperating Income / (Loss) | D9: =IF(D$3=0,"",SUMIFS(INDEX(Inputs!$D$4:$AG$200,0,MATCH(D$2,Inputs!$D$2:$AG$2,0)),Inputs!$B$4:$B$200,$B9)/1000) -> 188.526 | E9: =IF(E$3=0,"",SUMIFS(INDEX(Inputs!$D$4:$AG$200,0,MATCH(E$2,Inputs!$D$2:$AG$2,0)),Inputs!$B$4:$B$200,$B9)/1000) -> -307.323 | F9: =IF(F$3=0,"",SUMIFS(INDEX(Inputs!$D$4:$AG$200,0,MATCH(F$2,Inputs!$D$2:$AG$2,0)),Inputs!$B$4:$B$200,$B9)/1000) -> 209.511 | G9: =IF(G$3=0,"",SUMIFS(INDEX(Inputs!$D$4:$AG$200,0,MATCH(G$2,Inputs!$D$2:$AG$2,0)),Inputs!$B$4:$B$200,$B9)/1000) -> 383.039 | H9: =IF(COUNT(D9:G9)=4,SUM(D9:G9),"") -> 473.753 | I9: =IF(I$3=0,"",SUMIFS(INDEX(Inputs!$D$4:$AG$200,0,MATCH(I$2,Inputs!$D$2:$AG$2,0)),Inputs!$B$4:$B$200,$B9)/1000) -> 107.671 | J9: =IF(J$3=0,"",SUMIFS(INDEX(Inputs!$D$4:$AG$200,0,MATCH(J$2,Inputs!$D$2:$AG$2,0)),Inputs!$B$4:$B$200,$B9)/1000) -> 116.444 | K9: =IF(K$3=0,"",SUMIFS(INDEX(Inputs!$D$4:$AG$200,0,MATCH(K$2,Inputs!$D$2:$AG$2,0)),Inputs!$B$4:$B$200,$B9)/1000) -> 123.724 | L9: =IF(L$3=0,"",SUMIFS(INDEX(Inputs!$D$4:$AG$200,0,MATCH(L$2,Inputs!$D$2:$AG$2,0)),Inputs!$B$4:$B$200,$B9)/1000) -> 161.251 | M9: =IF(COUNT(I9:L9)=4,SUM(I9:L9),"") -> 509.09 | N9: =IF(N$3=0,"",SUMIFS(INDEX(Inputs!$D$4:$AG$200,0,MATCH(N$2,Inputs!$D$2:$AG$2,0)),Inputs!$B$4:$B$200,$B9)/1000) -> 140.596 | O9: =IF(O$3=0,"",SUMIFS(INDEX(Inputs!$D$4:$AG$200,0,MATCH(O$2,Inputs!$D$2:$AG$2,0)),Inputs!$B$4:$B$200,$B9)/1000) -> 25.985 | P9: =IF(P$3=0,"",SUMIFS(INDEX(Inputs!$D$4:$AG$200,0,MATCH(P$2,Inputs!$D$2:$AG$2,0)),Inputs!$B$4:$B$200,$B9)/1000) -> 47.438 | Q9: =IF(Q$3=0,"",SUMIFS(INDEX(Inputs!$D$4:$AG$200,0,MATCH(Q$2,Inputs!$D$2:$AG$2,0)),Inputs!$B$4:$B$200,$B9)/1000) -> 59.055 | R9: =IF(COUNT(N9:Q9)=4,SUM(N9:Q9),"") -> 273.074 | S9: =IF(S$3=0,"",SUMIFS(INDEX(Inputs!$D$4:$AG$200,0,MATCH(S$2,Inputs!$D$2:$AG$2,0)),Inputs!$B$4:$B$200,$B9)/1000) -> 88.865 | T9: =IF(T$3=0,"",SUMIFS(INDEX(Inputs!$D$4:$AG$200,0,MATCH(T$2,Inputs!$D$2:$AG$2,0)),Inputs!$B$4:$B$200,$B9)/1000) -> 91.414 | U9: =IF(U$3=0,"",SUMIFS(INDEX(Inputs!$D$4:$AG$200,0,MATCH(U$2,Inputs!$D$2:$AG$2,0)),Inputs!$B$4:$B$200,$B9)/1000) -> 112.895 | V9: =IF(V$3=0,"",SUMIFS(INDEX(Inputs!$D$4:$AG$200,0,MATCH(V$2,Inputs!$D$2:$AG$2,0)),Inputs!$B$4:$B$200,$B9)/1000) -> 85.172 | W9: =IF(COUNT(S9:V9)=4,SUM(S9:V9),"") -> 378.346 | X9: =IF(X$3=0,"",SUMIFS(INDEX(Inputs!$D$4:$AG$200,0,MATCH(X$2,Inputs!$D$2:$AG$2,0)),Inputs!$B$4:$B$200,$B9)/1000) -> 90.007 | Y9: =IF(Y$3=0,"",SUMIFS(INDEX(Inputs!$D$4:$AG$200,0,MATCH(Y$2,Inputs!$D$2:$AG$2,0)),Inputs!$B$4:$B$200,$B9)/1000) -> 98.699 | Z9: =IF(Z$3=0,"",SUMIFS(INDEX(Inputs!$D$4:$AG$200,0,MATCH(Z$2,Inputs!$D$2:$AG$2,0)),Inputs!$B$4:$B$200,$B9)/1000) -> 100.571 | AA9: =IF(AA$3=0,"",SUMIFS(INDEX(Inputs!$D$4:$AG$200,0,MATCH(AA$2,Inputs!$D$2:$AG$2,0)),Inputs!$B$4:$B$200,$B9)/1000) -> 390.59191 | AB9: =IF(COUNT(X9:AA9)=4,SUM(X9:AA9),"") -> 679.86891 | AC9: =IF(AC$3=0,"",SUMIFS(INDEX(Inputs!$D$4:$AG$200,0,MATCH(AC$2,Inputs!$D$2:$AG$2,0)),Inputs!$B$4:$B$200,$B9)/1000) -> 148.79541 | AD9: =IF(AD$3=0,"",SUMIFS(INDEX(Inputs!$D$4:$AG$200,0,MATCH(AD$2,Inputs!$D$2:$AG$2,0)),Inputs!$B$4:$B$200,$B9)/1000) -> 155.13569 | AE9: =IF(AE$3=0,"",SUMIFS(INDEX(Inputs!$D$4:$AG$200,0,MATCH(AE$2,Inputs!$D$2:$AG$2,0)),Inputs!$B$4:$B$200,$B9)/1000) | AF9: =IF(AF$3=0,"",SUMIFS(INDEX(Inputs!$D$4:$AG$200,0,MATCH(AF$2,Inputs!$D$2:$AG$2,0)),Inputs!$B$4:$B$200,$B9)/1000) | AG9: =IF(COUNT(AC9:AF9)=4,SUM(AC9:AF9),"")
B10: 7 | C10: Taxes | D10: =IF(D$3=0,"",SUMIFS(INDEX(Inputs!$D$4:$AG$200,0,MATCH(D$2,Inputs!$D$2:$AG$2,0)),Inputs!$B$4:$B$200,$B10)/1000) -> -56.185 | E10: =IF(E$3=0,"",SUMIFS(INDEX(Inputs!$D$4:$AG$200,0,MATCH(E$2,Inputs!$D$2:$AG$2,0)),Inputs!$B$4:$B$200,$B10)/1000) -> -74.183 | F10: =IF(F$3=0,"",SUMIFS(INDEX(Inputs!$D$4:$AG$200,0,MATCH(F$2,Inputs!$D$2:$AG$2,0)),Inputs!$B$4:$B$200,$B10)/1000) -> -110.575 | G10: =IF(G$3=0,"",SUMIFS(INDEX(Inputs!$D$4:$AG$200,0,MATCH(G$2,Inputs!$D$2:$AG$2,0)),Inputs!$B$4:$B$200,$B10)/1000) -> -121.387 | H10: =IF(COUNT(D10:G10)=4,SUM(D10:G10),"") -> -362.33 | I10: =IF(I$3=0,"",SUMIFS(INDEX(Inputs!$D$4:$AG$200,0,MATCH(I$2,Inputs!$D$2:$AG$2,0)),Inputs!$B$4:$B$200,$B10)/1000) -> -104.904 | J10: =IF(J$3=0,"",SUMIFS(INDEX(Inputs!$D$4:$AG$200,0,MATCH(J$2,Inputs!$D$2:$AG$2,0)),Inputs!$B$4:$B$200,$B10)/1000) -> -78.228 | K10: =IF(K$3=0,"",SUMIFS(INDEX(Inputs!$D$4:$AG$200,0,MATCH(K$2,Inputs!$D$2:$AG$2,0)),Inputs!$B$4:$B$200,$B10)/1000) -> -17.428 | L10: =IF(L$3=0,"",SUMIFS(INDEX(Inputs!$D$4:$AG$200,0,MATCH(L$2,Inputs!$D$2:$AG$2,0)),Inputs!$B$4:$B$200,$B10)/1000) -> 41.556 | M10: =IF(COUNT(I10:L10)=4,SUM(I10:L10),"") -> -159.004 | N10: =IF(N$3=0,"",SUMIFS(INDEX(Inputs!$D$4:$AG$200,0,MATCH(N$2,Inputs!$D$2:$AG$2,0)),Inputs!$B$4:$B$200,$B10)/1000) -> 10.417 | O10: =IF(O$3=0,"",SUMIFS(INDEX(Inputs!$D$4:$AG$200,0,MATCH(O$2,Inputs!$D$2:$AG$2,0)),Inputs!$B$4:$B$200,$B10)/1000) -> 6.673 | P10: =IF(P$3=0,"",SUMIFS(INDEX(Inputs!$D$4:$AG$200,0,MATCH(P$2,Inputs!$D$2:$AG$2,0)),Inputs!$B$4:$B$200,$B10)/1000) -> 21.858 | Q10: =IF(Q$3=0,"",SUMIFS(INDEX(Inputs!$D$4:$AG$200,0,MATCH(Q$2,Inputs!$D$2:$AG$2,0)),Inputs!$B$4:$B$200,$B10)/1000) -> 147.011 | R10: =IF(COUNT(N10:Q10)=4,SUM(N10:Q10),"") -> 185.959 | S10: =IF(S$3=0,"",SUMIFS(INDEX(Inputs!$D$4:$AG$200,0,MATCH(S$2,Inputs!$D$2:$AG$2,0)),Inputs!$B$4:$B$200,$B10)/1000) -> -24.287 | T10: =IF(T$3=0,"",SUMIFS(INDEX(Inputs!$D$4:$AG$200,0,MATCH(T$2,Inputs!$D$2:$AG$2,0)),Inputs!$B$4:$B$200,$B10)/1000) -> -14.056 | U10: =IF(U$3=0,"",SUMIFS(INDEX(Inputs!$D$4:$AG$200,0,MATCH(U$2,Inputs!$D$2:$AG$2,0)),Inputs!$B$4:$B$200,$B10)/1000) -> -23.602 | V10: =IF(V$3=0,"",SUMIFS(INDEX(Inputs!$D$4:$AG$200,0,MATCH(V$2,Inputs!$D$2:$AG$2,0)),Inputs!$B$4:$B$200,$B10)/1000) -> -16.094 | W10: =IF(COUNT(S10:V10)=4,SUM(S10:V10),"") -> -78.039 | X10: =IF(X$3=0,"",SUMIFS(INDEX(Inputs!$D$4:$AG$200,0,MATCH(X$2,Inputs!$D$2:$AG$2,0)),Inputs!$B$4:$B$200,$B10)/1000) -> -32.277 | Y10: =IF(Y$3=0,"",SUMIFS(INDEX(Inputs!$D$4:$AG$200,0,MATCH(Y$2,Inputs!$D$2:$AG$2,0)),Inputs!$B$4:$B$200,$B10)/1000) -> -23.716 | Z10: =IF(Z$3=0,"",SUMIFS(INDEX(Inputs!$D$4:$AG$200,0,MATCH(Z$2,Inputs!$D$2:$AG$2,0)),Inputs!$B$4:$B$200,$B10)/1000) -> 11.181 | AA10: =IF(AA$3=0,"",SUMIFS(INDEX(Inputs!$D$4:$AG$200,0,MATCH(AA$2,Inputs!$D$2:$AG$2,0)),Inputs!$B$4:$B$200,$B10)/1000) -> 15.574833 | AB10: =IF(COUNT(X10:AA10)=4,SUM(X10:AA10),"") -> -29.237167 | AC10: =IF(AC$3=0,"",SUMIFS(INDEX(Inputs!$D$4:$AG$200,0,MATCH(AC$2,Inputs!$D$2:$AG$2,0)),Inputs!$B$4:$B$200,$B10)/1000) -> -39.782999 | AD10: =IF(AD$3=0,"",SUMIFS(INDEX(Inputs!$D$4:$AG$200,0,MATCH(AD$2,Inputs!$D$2:$AG$2,0)),Inputs!$B$4:$B$200,$B10)/1000) -> -33.895472 | AE10: =IF(AE$3=0,"",SUMIFS(INDEX(Inputs!$D$4:$AG$200,0,MATCH(AE$2,Inputs!$D$2:$AG$2,0)),Inputs!$B$4:$B$200,$B10)/1000) | AF10: =IF(AF$3=0,"",SUMIFS(INDEX(Inputs!$D$4:$AG$200,0,MATCH(AF$2,Inputs!$D$2:$AG$2,0)),Inputs!$B$4:$B$200,$B10)/1000) | AG10: =IF(COUNT(AC10:AF10)=4,SUM(AC10:AF10),"")
B11: 8 | C11: Equity in Income of Affiliates, after tax (enter as +) | D11: =IF(D$3=0,"",SUMIFS(INDEX(Inputs!$D$4:$AG$200,0,MATCH(D$2,Inputs!$D$2:$AG$2,0)),Inputs!$B$4:$B$200,$B11)/1000) -> 0 | E11: =IF(E$3=0,"",SUMIFS(INDEX(Inputs!$D$4:$AG$200,0,MATCH(E$2,Inputs!$D$2:$AG$2,0)),Inputs!$B$4:$B$200,$B11)/1000) -> 0 | F11: =IF(F$3=0,"",SUMIFS(INDEX(Inputs!$D$4:$AG$200,0,MATCH(F$2,Inputs!$D$2:$AG$2,0)),Inputs!$B$4:$B$200,$B11)/1000) -> 0 | G11: =IF(G$3=0,"",SUMIFS(INDEX(Inputs!$D$4:$AG$200,0,MATCH(G$2,Inputs!$D$2:$AG$2,0)),Inputs!$B$4:$B$200,$B11)/1000) -> 0 | H11: =IF(COUNT(D11:G11)=4,SUM(D11:G11),"") -> 0 | I11: =IF(I$3=0,"",SUMIFS(INDEX(Inputs!$D$4:$AG$200,0,MATCH(I$2,Inputs!$D$2:$AG$2,0)),Inputs!$B$4:$B$200,$B11)/1000) -> 0 | J11: =IF(J$3=0,"",SUMIFS(INDEX(Inputs!$D$4:$AG$200,0,MATCH(J$2,Inputs!$D$2:$AG$2,0)),Inputs!$B$4:$B$200,$B11)/1000) -> 0 | K11: =IF(K$3=0,"",SUMIFS(INDEX(Inputs!$D$4:$AG$200,0,MATCH(K$2,Inputs!$D$2:$AG$2,0)),Inputs!$B$4:$B$200,$B11)/1000) -> 0 | L11: =IF(L$3=0,"",SUMIFS(INDEX(Inputs!$D$4:$AG$200,0,MATCH(L$2,Inputs!$D$2:$AG$2,0)),Inputs!$B$4:$B$200,$B11)/1000) -> 0 | M11: =IF(COUNT(I11:L11)=4,SUM(I11:L11),"") -> 0 | N11: =IF(N$3=0,"",SUMIFS(INDEX(Inputs!$D$4:$AG$200,0,MATCH(N$2,Inputs!$D$2:$AG$2,0)),Inputs!$B$4:$B$200,$B11)/1000) -> 0 | O11: =IF(O$3=0,"",SUMIFS(INDEX(Inputs!$D$4:$AG$200,0,MATCH(O$2,Inputs!$D$2:$AG$2,0)),Inputs!$B$4:$B$200,$B11)/1000) -> 0 | P11: =IF(P$3=0,"",SUMIFS(INDEX(Inputs!$D$4:$AG$200,0,MATCH(P$2,Inputs!$D$2:$AG$2,0)),Inputs!$B$4:$B$200,$B11)/1000) -> 0 | Q11: =IF(Q$3=0,"",SUMIFS(INDEX(Inputs!$D$4:$AG$200,0,MATCH(Q$2,Inputs!$D$2:$AG$2,0)),Inputs!$B$4:$B$200,$B11)/1000) -> 0 | R11: =IF(COUNT(N11:Q11)=4,SUM(N11:Q11),"") -> 0 | S11: =IF(S$3=0,"",SUMIFS(INDEX(Inputs!$D$4:$AG$200,0,MATCH(S$2,Inputs!$D$2:$AG$2,0)),Inputs!$B$4:$B$200,$B11)/1000) -> 0 | T11: =IF(T$3=0,"",SUMIFS(INDEX(Inputs!$D$4:$AG$200,0,MATCH(T$2,Inputs!$D$2:$AG$2,0)),Inputs!$B$4:$B$200,$B11)/1000) -> 0 | U11: =IF(U$3=0,"",SUMIFS(INDEX(Inputs!$D$4:$AG$200,0,MATCH(U$2,Inputs!$D$2:$AG$2,0)),Inputs!$B$4:$B$200,$B11)/1000) -> 0 | V11: =IF(V$3=0,"",SUMIFS(INDEX(Inputs!$D$4:$AG$200,0,MATCH(V$2,Inputs!$D$2:$AG$2,0)),Inputs!$B$4:$B$200,$B11)/1000) -> 0 | W11: =IF(COUNT(S11:V11)=4,SUM(S11:V11),"") -> 0 | X11: =IF(X$3=0,"",SUMIFS(INDEX(Inputs!$D$4:$AG$200,0,MATCH(X$2,Inputs!$D$2:$AG$2,0)),Inputs!$B$4:$B$200,$B11)/1000) -> 0 | Y11: =IF(Y$3=0,"",SUMIFS(INDEX(Inputs!$D$4:$AG$200,0,MATCH(Y$2,Inputs!$D$2:$AG$2,0)),Inputs!$B$4:$B$200,$B11)/1000) -> 0 | Z11: =IF(Z$3=0,"",SUMIFS(INDEX(Inputs!$D$4:$AG$200,0,MATCH(Z$2,Inputs!$D$2:$AG$2,0)),Inputs!$B$4:$B$200,$B11)/1000) -> 0 | AA11: =IF(AA$3=0,"",SUMIFS(INDEX(Inputs!$D$4:$AG$200,0,MATCH(AA$2,Inputs!$D$2:$AG$2,0)),Inputs!$B$4:$B$200,$B11)/1000) -> 0 | AB11: =IF(COUNT(X11:AA11)=4,SUM(X11:AA11),"") -> 0 | AC11: =IF(AC$3=0,"",SUMIFS(INDEX(Inputs!$D$4:$AG$200,0,MATCH(AC$2,Inputs!$D$2:$AG$2,0)),Inputs!$B$4:$B$200,$B11)/1000) -> 0 | AD11: =IF(AD$3=0,"",SUMIFS(INDEX(Inputs!$D$4:$AG$200,0,MATCH(AD$2,Inputs!$D$2:$AG$2,0)),Inputs!$B$4:$B$200,$B11)/1000) -> 0 | AE11: =IF(AE$3=0,"",SUMIFS(INDEX(Inputs!$D$4:$AG$200,0,MATCH(AE$2,Inputs!$D$2:$AG$2,0)),Inputs!$B$4:$B$200,$B11)/1000) | AF11: =IF(AF$3=0,"",SUMIFS(INDEX(Inputs!$D$4:$AG$200,0,MATCH(AF$2,Inputs!$D$2:$AG$2,0)),Inputs!$B$4:$B$200,$B11)/1000) | AG11: =IF(COUNT(AC11:AF11)=4,SUM(AC11:AF11),"")
B12: 9 | C12: Minority Interest Expense, after tax (enter as - ) | D12: =IF(D$3=0,"",SUMIFS(INDEX(Inputs!$D$4:$AG$200,0,MATCH(D$2,Inputs!$D$2:$AG$2,0)),Inputs!$B$4:$B$200,$B12)/1000) -> 0 | E12: =IF(E$3=0,"",SUMIFS(INDEX(Inputs!$D$4:$AG$200,0,MATCH(E$2,Inputs!$D$2:$AG$2,0)),Inputs!$B$4:$B$200,$B12)/1000) -> 0 | F12: =IF(F$3=0,"",SUMIFS(INDEX(Inputs!$D$4:$AG$200,0,MATCH(F$2,Inputs!$D$2:$AG$2,0)),Inputs!$B$4:$B$200,$B12)/1000) -> 0 | G12: =IF(G$3=0,"",SUMIFS(INDEX(Inputs!$D$4:$AG$200,0,MATCH(G$2,Inputs!$D$2:$AG$2,0)),Inputs!$B$4:$B$200,$B12)/1000) -> 0 | H12: =IF(COUNT(D12:G12)=4,SUM(D12:G12),"") -> 0 | I12: =IF(I$3=0,"",SUMIFS(INDEX(Inputs!$D$4:$AG$200,0,MATCH(I$2,Inputs!$D$2:$AG$2,0)),Inputs!$B$4:$B$200,$B12)/1000) -> 0 | J12: =IF(J$3=0,"",SUMIFS(INDEX(Inputs!$D$4:$AG$200,0,MATCH(J$2,Inputs!$D$2:$AG$2,0)),Inputs!$B$4:$B$200,$B12)/1000) -> 0 | K12: =IF(K$3=0,"",SUMIFS(INDEX(Inputs!$D$4:$AG$200,0,MATCH(K$2,Inputs!$D$2:$AG$2,0)),Inputs!$B$4:$B$200,$B12)/1000) -> 0 | L12: =IF(L$3=0,"",SUMIFS(INDEX(Inputs!$D$4:$AG$200,0,MATCH(L$2,Inputs!$D$2:$AG$2,0)),Inputs!$B$4:$B$200,$B12)/1000) -> 0 | M12: =IF(COUNT(I12:L12)=4,SUM(I12:L12),"") -> 0 | N12: =IF(N$3=0,"",SUMIFS(INDEX(Inputs!$D$4:$AG$200,0,MATCH(N$2,Inputs!$D$2:$AG$2,0)),Inputs!$B$4:$B$200,$B12)/1000) -> 0 | O12: =IF(O$3=0,"",SUMIFS(INDEX(Inputs!$D$4:$AG$200,0,MATCH(O$2,Inputs!$D$2:$AG$2,0)),Inputs!$B$4:$B$200,$B12)/1000) -> 0 | P12: =IF(P$3=0,"",SUMIFS(INDEX(Inputs!$D$4:$AG$200,0,MATCH(P$2,Inputs!$D$2:$AG$2,0)),Inputs!$B$4:$B$200,$B12)/1000) -> 0 | Q12: =IF(Q$3=0,"",SUMIFS(INDEX(Inputs!$D$4:$AG$200,0,MATCH(Q$2,Inputs!$D$2:$AG$2,0)),Inputs!$B$4:$B$200,$B12)/1000) -> 0 | R12: =IF(COUNT(N12:Q12)=4,SUM(N12:Q12),"") -> 0 | S12: =IF(S$3=0,"",SUMIFS(INDEX(Inputs!$D$4:$AG$200,0,MATCH(S$2,Inputs!$D$2:$AG$2,0)),Inputs!$B$4:$B$200,$B12)/1000) -> 0 | T12: =IF(T$3=0,"",SUMIFS(INDEX(Inputs!$D$4:$AG$200,0,MATCH(T$2,Inputs!$D$2:$AG$2,0)),Inputs!$B$4:$B$200,$B12)/1000) -> 0 | U12: =IF(U$3=0,"",SUMIFS(INDEX(Inputs!$D$4:$AG$200,0,MATCH(U$2,Inputs!$D$2:$AG$2,0)),Inputs!$B$4:$B$200,$B12)/1000) -> 0 | V12: =IF(V$3=0,"",SUMIFS(INDEX(Inputs!$D$4:$AG$200,0,MATCH(V$2,Inputs!$D$2:$AG$2,0)),Inputs!$B$4:$B$200,$B12)/1000) -> 0 | W12: =IF(COUNT(S12:V12)=4,SUM(S12:V12),"") -> 0 | X12: =IF(X$3=0,"",SUMIFS(INDEX(Inputs!$D$4:$AG$200,0,MATCH(X$2,Inputs!$D$2:$AG$2,0)),Inputs!$B$4:$B$200,$B12)/1000) -> 0 | Y12: =IF(Y$3=0,"",SUMIFS(INDEX(Inputs!$D$4:$AG$200,0,MATCH(Y$2,Inputs!$D$2:$AG$2,0)),Inputs!$B$4:$B$200,$B12)/1000) -> 0 | Z12: =IF(Z$3=0,"",SUMIFS(INDEX(Inputs!$D$4:$AG$200,0,MATCH(Z$2,Inputs!$D$2:$AG$2,0)),Inputs!$B$4:$B$200,$B12)/1000) -> 0 | AA12: =IF(AA$3=0,"",SUMIFS(INDEX(Inputs!$D$4:$AG$200,0,MATCH(AA$2,Inputs!$D$2:$AG$2,0)),Inputs!$B$4:$B$200,$B12)/1000) -> 0 | AB12: =IF(COUNT(X12:AA12)=4,SUM(X12:AA12),"") -> 0 | AC12: =IF(AC$3=0,"",SUMIFS(INDEX(Inputs!$D$4:$AG$200,0,MATCH(AC$2,Inputs!$D$2:$AG$2,0)),Inputs!$B$4:$B$200,$B12)/1000) -> 0 | AD12: =IF(AD$3=0,"",SUMIFS(INDEX(Inputs!$D$4:$AG$200,0,MATCH(AD$2,Inputs!$D$2:$AG$2,0)),Inputs!$B$4:$B$200,$B12)/1000) -> 0 | AE12: =IF(AE$3=0,"",SUMIFS(INDEX(Inputs!$D$4:$AG$200,0,MATCH(AE$2,Inputs!$D$2:$AG$2,0)),Inputs!$B$4:$B$200,$B12)/1000) | AF12: =IF(AF$3=0,"",SUMIFS(INDEX(Inputs!$D$4:$AG$200,0,MATCH(AF$2,Inputs!$D$2:$AG$2,0)),Inputs!$B$4:$B$200,$B12)/1000) | AG12: =IF(COUNT(AC12:AF12)=4,SUM(AC12:AF12),"")
B13: 10 | C13: Common Dividends | D13: =IF(D$3=0,"",SUMIFS(INDEX(Inputs!$D$4:$AG$200,0,MATCH(D$2,Inputs!$D$2:$AG$2,0)),Inputs!$B$4:$B$200,$B13)/1000) -> 0 | E13: =IF(E$3=0,"",SUMIFS(INDEX(Inputs!$D$4:$AG$200,0,MATCH(E$2,Inputs!$D$2:$AG$2,0)),Inputs!$B$4:$B$200,$B13)/1000) -> 0 | F13: =IF(F$3=0,"",SUMIFS(INDEX(Inputs!$D$4:$AG$200,0,MATCH(F$2,Inputs!$D$2:$AG$2,0)),Inputs!$B$4:$B$200,$B13)/1000) -> -64.133 | G13: =IF(G$3=0,"",SUMIFS(INDEX(Inputs!$D$4:$AG$200,0,MATCH(G$2,Inputs!$D$2:$AG$2,0)),Inputs!$B$4:$B$200,$B13)/1000) -> -42.481 | H13: =IF(COUNT(D13:G13)=4,SUM(D13:G13),"") -> -106.614 | I13: =IF(I$3=0,"",SUMIFS(INDEX(Inputs!$D$4:$AG$200,0,MATCH(I$2,Inputs!$D$2:$AG$2,0)),Inputs!$B$4:$B$200,$B13)/1000) -> -39.311 | J13: =IF(J$3=0,"",SUMIFS(INDEX(Inputs!$D$4:$AG$200,0,MATCH(J$2,Inputs!$D$2:$AG$2,0)),Inputs!$B$4:$B$200,$B13)/1000) -> -309.347 | K13: =IF(K$3=0,"",SUMIFS(INDEX(Inputs!$D$4:$AG$200,0,MATCH(K$2,Inputs!$D$2:$AG$2,0)),Inputs!$B$4:$B$200,$B13)/1000) -> -46.849 | L13: =IF(L$3=0,"",SUMIFS(INDEX(Inputs!$D$4:$AG$200,0,MATCH(L$2,Inputs!$D$2:$AG$2,0)),Inputs!$B$4:$B$200,$B13)/1000) -> -52.131 | M13: =IF(COUNT(I13:L13)=4,SUM(I13:L13),"") -> -447.638 | N13: =IF(N$3=0,"",SUMIFS(INDEX(Inputs!$D$4:$AG$200,0,MATCH(N$2,Inputs!$D$2:$AG$2,0)),Inputs!$B$4:$B$200,$B13)/1000) -> -47.512 | O13: =IF(O$3=0,"",SUMIFS(INDEX(Inputs!$D$4:$AG$200,0,MATCH(O$2,Inputs!$D$2:$AG$2,0)),Inputs!$B$4:$B$200,$B13)/1000) -> -90.689 | P13: =IF(P$3=0,"",SUMIFS(INDEX(Inputs!$D$4:$AG$200,0,MATCH(P$2,Inputs!$D$2:$AG$2,0)),Inputs!$B$4:$B$200,$B13)/1000) -> 0.001 | Q13: =IF(Q$3=0,"",SUMIFS(INDEX(Inputs!$D$4:$AG$200,0,MATCH(Q$2,Inputs!$D$2:$AG$2,0)),Inputs!$B$4:$B$200,$B13)/1000) -> 0 | R13: =IF(COUNT(N13:Q13)=4,SUM(N13:Q13),"") -> -138.2 | S13: =IF(S$3=0,"",SUMIFS(INDEX(Inputs!$D$4:$AG$200,0,MATCH(S$2,Inputs!$D$2:$AG$2,0)),Inputs!$B$4:$B$200,$B13)/1000) -> 0 | T13: =IF(T$3=0,"",SUMIFS(INDEX(Inputs!$D$4:$AG$200,0,MATCH(T$2,Inputs!$D$2:$AG$2,0)),Inputs!$B$4:$B$200,$B13)/1000) -> 0 | U13: =IF(U$3=0,"",SUMIFS(INDEX(Inputs!$D$4:$AG$200,0,MATCH(U$2,Inputs!$D$2:$AG$2,0)),Inputs!$B$4:$B$200,$B13)/1000) -> 0 | V13: =IF(V$3=0,"",SUMIFS(INDEX(Inputs!$D$4:$AG$200,0,MATCH(V$2,Inputs!$D$2:$AG$2,0)),Inputs!$B$4:$B$200,$B13)/1000) -> 0 | W13: =IF(COUNT(S13:V13)=4,SUM(S13:V13),"") -> 0 | X13: =IF(X$3=0,"",SUMIFS(INDEX(Inputs!$D$4:$AG$200,0,MATCH(X$2,Inputs!$D$2:$AG$2,0)),Inputs!$B$4:$B$200,$B13)/1000) -> 0 | Y13: =IF(Y$3=0,"",SUMIFS(INDEX(Inputs!$D$4:$AG$200,0,MATCH(Y$2,Inputs!$D$2:$AG$2,0)),Inputs!$B$4:$B$200,$B13)/1000) -> -55.05 | Z13: =IF(Z$3=0,"",SUMIFS(INDEX(Inputs!$D$4:$AG$200,0,MATCH(Z$2,Inputs!$D$2:$AG$2,0)),Inputs!$B$4:$B$200,$B13)/1000) -> 0 | AA13: =IF(AA$3=0,"",SUMIFS(INDEX(Inputs!$D$4:$AG$200,0,MATCH(AA$2,Inputs!$D$2:$AG$2,0)),Inputs!$B$4:$B$200,$B13)/1000) -> 0 | AB13: =IF(COUNT(X13:AA13)=4,SUM(X13:AA13),"") -> -55.05 | AC13: =IF(AC$3=0,"",SUMIFS(INDEX(Inputs!$D$4:$AG$200,0,MATCH(AC$2,Inputs!$D$2:$AG$2,0)),Inputs!$B$4:$B$200,$B13)/1000) -> 0 | AD13: =IF(AD$3=0,"",SUMIFS(INDEX(Inputs!$D$4:$AG$200,0,MATCH(AD$2,Inputs!$D$2:$AG$2,0)),Inputs!$B$4:$B$200,$B13)/1000) -> 0 | AE13: =IF(AE$3=0,"",SUMIFS(INDEX(Inputs!$D$4:$AG$200,0,MATCH(AE$2,Inputs!$D$2:$AG$2,0)),Inputs!$B$4:$B$200,$B13)/1000) | AF13: =IF(AF$3=0,"",SUMIFS(INDEX(Inputs!$D$4:$AG$200,0,MATCH(AF$2,Inputs!$D$2:$AG$2,0)),Inputs!$B$4:$B$200,$B13)/1000) | AG13: =IF(COUNT(AC13:AF13)=4,SUM(AC13:AF13),"")
B15: 11 | C15: Cash and equivalents (inc. investment securities) | D15: =IF(D$3=0,"",SUMIFS(INDEX(Inputs!$D$4:$AG$200,0,MATCH(D$2,Inputs!$D$2:$AG$2,0)),Inputs!$B$4:$B$200,$B15)/1000) -> 5511.88 | E15: =IF(E$3=0,"",SUMIFS(INDEX(Inputs!$D$4:$AG$200,0,MATCH(E$2,Inputs!$D$2:$AG$2,0)),Inputs!$B$4:$B$200,$B15)/1000) -> 5556.755 | F15: =IF(F$3=0,"",SUMIFS(INDEX(Inputs!$D$4:$AG$200,0,MATCH(F$2,Inputs!$D$2:$AG$2,0)),Inputs!$B$4:$B$200,$B15)/1000) -> 8274.313 | G15: =IF(G$3=0,"",SUMIFS(INDEX(Inputs!$D$4:$AG$200,0,MATCH(G$2,Inputs!$D$2:$AG$2,0)),Inputs!$B$4:$B$200,$B15)/1000) -> 7786.453 | H15: =IF(G15="","",G15) -> 7786.453 | I15: =IF(I$3=0,"",SUMIFS(INDEX(Inputs!$D$4:$AG$200,0,MATCH(I$2,Inputs!$D$2:$AG$2,0)),Inputs!$B$4:$B$200,$B15)/1000) -> 5650.584 | J15: =IF(J$3=0,"",SUMIFS(INDEX(Inputs!$D$4:$AG$200,0,MATCH(J$2,Inputs!$D$2:$AG$2,0)),Inputs!$B$4:$B$200,$B15)/1000) -> 5722.697 | K15: =IF(K$3=0,"",SUMIFS(INDEX(Inputs!$D$4:$AG$200,0,MATCH(K$2,Inputs!$D$2:$AG$2,0)),Inputs!$B$4:$B$200,$B15)/1000) -> 7795.457 | L15: =IF(L$3=0,"",SUMIFS(INDEX(Inputs!$D$4:$AG$200,0,MATCH(L$2,Inputs!$D$2:$AG$2,0)),Inputs!$B$4:$B$200,$B15)/1000) -> 6827.535 | M15: =IF(L15="","",L15) -> 6827.535 | N15: =IF(N$3=0,"",SUMIFS(INDEX(Inputs!$D$4:$AG$200,0,MATCH(N$2,Inputs!$D$2:$AG$2,0)),Inputs!$B$4:$B$200,$B15)/1000) -> 3923.099 | O15: =IF(O$3=0,"",SUMIFS(INDEX(Inputs!$D$4:$AG$200,0,MATCH(O$2,Inputs!$D$2:$AG$2,0)),Inputs!$B$4:$B$200,$B15)/1000) -> 2577.866 | P15: =IF(P$3=0,"",SUMIFS(INDEX(Inputs!$D$4:$AG$200,0,MATCH(P$2,Inputs!$D$2:$AG$2,0)),Inputs!$B$4:$B$200,$B15)/1000) -> 2011.127 | Q15: =IF(Q$3=0,"",SUMIFS(INDEX(Inputs!$D$4:$AG$200,0,MATCH(Q$2,Inputs!$D$2:$AG$2,0)),Inputs!$B$4:$B$200,$B15)/1000) -> 2998.752 | R15: =IF(Q15="","",Q15) -> 2998.752 | S15: =IF(S$3=0,"",SUMIFS(INDEX(Inputs!$D$4:$AG$200,0,MATCH(S$2,Inputs!$D$2:$AG$2,0)),Inputs!$B$4:$B$200,$B15)/1000) -> 3211.286 | T15: =IF(T$3=0,"",SUMIFS(INDEX(Inputs!$D$4:$AG$200,0,MATCH(T$2,Inputs!$D$2:$AG$2,0)),Inputs!$B$4:$B$200,$B15)/1000) -> 3685.003 | U15: =IF(U$3=0,"",SUMIFS(INDEX(Inputs!$D$4:$AG$200,0,MATCH(U$2,Inputs!$D$2:$AG$2,0)),Inputs!$B$4:$B$200,$B15)/1000) -> 3975.719 | V15: =IF(V$3=0,"",SUMIFS(INDEX(Inputs!$D$4:$AG$200,0,MATCH(V$2,Inputs!$D$2:$AG$2,0)),Inputs!$B$4:$B$200,$B15)/1000) -> 4291.363 | W15: =IF(V15="","",V15) -> 4291.363 | X15: =IF(X$3=0,"",SUMIFS(INDEX(Inputs!$D$4:$AG$200,0,MATCH(X$2,Inputs!$D$2:$AG$2,0)),Inputs!$B$4:$B$200,$B15)/1000) -> 3037.195 | Y15: =IF(Y$3=0,"",SUMIFS(INDEX(Inputs!$D$4:$AG$200,0,MATCH(Y$2,Inputs!$D$2:$AG$2,0)),Inputs!$B$4:$B$200,$B15)/1000) -> 3441.64 | Z15: =IF(Z$3=0,"",SUMIFS(INDEX(Inputs!$D$4:$AG$200,0,MATCH(Z$2,Inputs!$D$2:$AG$2,0)),Inputs!$B$4:$B$200,$B15)/1000) -> 3319.489 | AA15: =IF(AA$3=0,"",SUMIFS(INDEX(Inputs!$D$4:$AG$200,0,MATCH(AA$2,Inputs!$D$2:$AG$2,0)),Inputs!$B$4:$B$200,$B15)/1000) -> 6875.395 | AB15: =IF(AA15="","",AA15) -> 6875.395 | AC15: =IF(AC$3=0,"",SUMIFS(INDEX(Inputs!$D$4:$AG$200,0,MATCH(AC$2,Inputs!$D$2:$AG$2,0)),Inputs!$B$4:$B$200,$B15)/1000) -> 8093.188 | AD15: =IF(AD$3=0,"",SUMIFS(INDEX(Inputs!$D$4:$AG$200,0,MATCH(AD$2,Inputs!$D$2:$AG$2,0)),Inputs!$B$4:$B$200,$B15)/1000) -> 7479.297 | AE15: =IF(AE$3=0,"",SUMIFS(INDEX(Inputs!$D$4:$AG$200,0,MATCH(AE$2,Inputs!$D$2:$AG$2,0)),Inputs!$B$4:$B$200,$B15)/1000) | AF15: =IF(AF$3=0,"",SUMIFS(INDEX(Inputs!$D$4:$AG$200,0,MATCH(AF$2,Inputs!$D$2:$AG$2,0)),Inputs!$B$4:$B$200,$B15)/1000) | AG15: =IF(AF15="","",AF15)
