Workbook
Name beta_observed: #REF!
Name beta_observed: Valuation!$D$93
Name costdebtfirm: Valuation!$D$86
Name costequity: Valuation!$D$94
Name debt: Valuation!$G$88
Name debt_weight: Valuation!$J$88
Name g: Valuation!$D$63
Name last_close: Valuation!$G$7
Name market_equity: Valuation!$G$89
Name noplat_t1: Valuation!$D$65
Name relevered_beta: Valuation!$M$102
Name risk_free_rate: Valuation!$D$91
Name risk_premium: Valuation!$D$92
Name ronic: Valuation!$D$64
Name stub_year_fraction: Valuation!$D$11
Name ticker: #REF!
Name ticker: Valuation!$D$7
Name totalcap: Valuation!$G$90
Name Useful_Life_of_Depreciable_PP_E: "PPElife"
Name wacc: Valuation!$D$12

Sheet Inputs
A1: Base histórica normalizada (R$ mil)
A2: Fonte / conta original | B2: Código | C2: Conta padronizada | D2: 1Q21 | E2: 2Q21 | F2: 3Q21 | G2: 4Q21 | H2: 2021 | I2: 1Q22 | J2: 2Q22 | K2: 3Q22 | L2: 4Q22 | M2: 2022 | N2: 1Q23 | O2: 2Q23 | P2: 3Q23 | Q2: 4Q23 | R2: 2023 | S2: 1Q24 | T2: 2Q24 | U2: 3Q24 | V2: 4Q24 | W2: 2024 | X2: 1Q25 | Y2: 2Q25 | Z2: 3Q25 | AA2: 4Q25 | AB2: 2025 | AC2: 1Q26 | AD2: 2Q26 | AE2: 3Q26 | AF2: 4Q26 | AG2: 2026
A3: Fonte: preencher com planilha de fundamentos e/ou RI | C3: Unidade original: R$ mil
B4: 1 | C4: Net Revenues
B5: 2 | C5: COGS (cash)
B6: 3 | C6: SG&A and Other (cash)
B7: 4 | C7: D&A
B8: 5 | C8: Interest Expense
B9: 6 | C9: Nonoperating Income / (Loss)
B10: 7 | C10: Taxes
B11: 8 | C11: Equity in Income of Affiliates, after tax (enter as +)
B12: 9 | C12: Minority Interest Expense, after tax (enter as - )
B13: 10 | C13: Common Dividends
B14: 11 | C14: Cash and equivalents (inc. investment securities)
B15: 12 | C15: Accounts receivable
... B44: 41 | C44: Retained earnings

Sheet Inputs (2)
A1: =IF(Control!B3="","EMPRESA",Control!B3) -> EMPRESA | B1: Código | C1: Conta padronizada | D1: 2021 | E1: 2021 | F1: 2021 | G1: 2021 | H1: 2021 | I1: 2022 | J1: 2022 | K1: 2022 | L1: 2022 | M1: 2022 | N1: 2023 | O1: 2023 | P1: 2023 | Q1: 2023 | R1: 2023 | S1: 2024 | T1: 2024 | U1: 2024 | V1: 2024 | W1: 2024 | X1: 2025 | Y1: 2025 | Z1: 2025 | AA1: 2025 | AB1: 2025 | AC1: 2026 | AD1: 2026 | AE1: 2026 | AF1: 2026 | AG1: 2026
A2: R$ milhões | C2: Período | D2: 1Q21 | E2: 2Q21 | F2: 3Q21 | G2: 4Q21 | H2: 2021 | I2: 1Q22 | J2: 2Q22 | K2: 3Q22 | L2: 4Q22 | M2: 2022 | N2: 1Q23 | O2: 2Q23 | P2: 3Q23 | Q2: 4Q23 | R2: 2023 | S2: 1Q24 | T2: 2Q24 | U2: 3Q24 | V2: 4Q24 | W2: 2024 | X2: 1Q25 | Y2: 2Q25 | Z2: 3Q25 | AA2: 4Q25 | AB2: 2025 | AC2: 1Q26 | AD2: 2Q26 | AE2: 3Q26 | AF2: 4Q26 | AG2: 2026
A3: Actual flag | C3: 0 = sem dados / 1 = realizado | D3: 0 | E3: 0 | F3: 0 | G3: 0 | H3: 0 | I3: 0 | J3: 0 | K3: 0 | L3: 0 | M3: 0 | N3: 0 | O3: 0 | P3: 0 | Q3: 0 | R3: 0 | S3: 0 | T3: 0 | U3: 0 | V3: 0 | W3: 0 | X3: 0 | Y3: 0 | Z3: 0 | AA3: 0 | AB3: 0 | AC3: 0 | AD3: 0 | AE3: 0 | AF3: 0 | AG3: 0
B4: 1 | C4: Net Revenues | D4: =IF(D$3=0,"",SUMIFS(INDEX(Inputs!$D$4:$AG$100,0,MATCH(D$2,Inputs!$D$2:$AG$2,0)),Inputs!$B$4:$B$100,$B4)/1000) | E4: =IF(E$3=0,"",SUMIFS(INDEX(Inputs!$D$4:$AG$100,0,MATCH(E$2,Inputs!$D$2:$AG$2,0)),Inputs!$B$4:$B$100,$B4)/1000) | F4: =IF(F$3=0,"",SUMIFS(INDEX(Inputs!$D$4:$AG$100,0,MATCH(F$2,Inputs!$D$2:$AG$2,0)),Inputs!$B$4:$B$100,$B4)/1000) | G4: =IF(G$3=0,"",SUMIFS(INDEX(Inputs!$D$4:$AG$100,0,MATCH(G$2,Inputs!$D$2:$AG$2,0)),Inputs!$B$4:$B$100,$B4)/1000) | H4: =IF(COUNT(D4:G4)=4,SUM(D4:G4),"") | I4: =IF(I$3=0,"",SUMIFS(INDEX(Inputs!$D$4:$AG$100,0,MATCH(I$2,Inputs!$D$2:$AG$2,0)),Inputs!$B$4:$B$100,$B4)/1000) | J4: =IF(J$3=0,"",SUMIFS(INDEX(Inputs!$D$4:$AG$100,0,MATCH(J$2,Inputs!$D$2:$AG$2,0)),Inputs!$B$4:$B$100,$B4)/1000) | K4: =IF(K$3=0,"",SUMIFS(INDEX(Inputs!$D$4:$AG$100,0,MATCH(K$2,Inputs!$D$2:$AG$2,0)),Inputs!$B$4:$B$100,$B4)/1000) | L4: =IF(L$3=0,"",SUMIFS(INDEX(Inputs!$D$4:$AG$100,0,MATCH(L$2,Inputs!$D$2:$AG$2,0)),Inputs!$B$4:$B$100,$B4)/1000) | M4: =IF(COUNT(I4:L4)=4,SUM(I4:L4),"") | N4: =IF(N$3=0,"",SUMIFS(INDEX(Inputs!$D$4:$AG$100,0,MATCH(N$2,Inputs!$D$2:$AG$2,0)),Inputs!$B$4:$B$100,$B4)/1000) | O4: =IF(O$3=0,"",SUMIFS(INDEX(Inputs!$D$4:$AG$100,0,MATCH(O$2,Inputs!$D$2:$AG$2,0)),Inputs!$B$4:$B$100,$B4)/1000) | P4: =IF(P$3=0,"",SUMIFS(INDEX(Inputs!$D$4:$AG$100,0,MATCH(P$2,Inputs!$D$2:$AG$2,0)),Inputs!$B$4:$B$100,$B4)/1000) | Q4: =IF(Q$3=0,"",SUMIFS(INDEX(Inputs!$D$4:$AG$100,0,MATCH(Q$2,Inputs!$D$2:$AG$2,0)),Inputs!$B$4:$B$100,$B4)/1000) | R4: =IF(COUNT(N4:Q4)=4,SUM(N4:Q4),"") | S4: =IF(S$3=0,"",SUMIFS(INDEX(Inputs!$D$4:$AG$100,0,MATCH(S$2,Inputs!$D$2:$AG$2,0)),Inputs!$B$4:$B$100,$B4)/1000) | T4: =IF(T$3=0,"",SUMIFS(INDEX(Inputs!$D$4:$AG$100,0,MATCH(T$2,Inputs!$D$2:$AG$2,0)),Inputs!$B$4:$B$100,$B4)/1000) | U4: =IF(U$3=0,"",SUMIFS(INDEX(Inputs!$D$4:$AG$100,0,MATCH(U$2,Inputs!$D$2:$AG$2,0)),Inputs!$B$4:$B$100,$B4)/1000) | V4: =IF(V$3=0,"",SUMIFS(INDEX(Inputs!$D$4:$AG$100,0,MATCH(V$2,Inputs!$D$2:$AG$2,0)),Inputs!$B$4:$B$100,$B4)/1000) | W4: =IF(COUNT(S4:V4)=4,SUM(S4:V4),"") | X4: =IF(X$3=0,"",SUMIFS(INDEX(Inputs!$D$4:$AG$100,0,MATCH(X$2,Inputs!$D$2:$AG$2,0)),Inputs!$B$4:$B$100,$B4)/1000) | Y4: =IF(Y$3=0,"",SUMIFS(INDEX(Inputs!$D$4:$AG$100,0,MATCH(Y$2,Inputs!$D$2:$AG$2,0)),Inputs!$B$4:$B$100,$B4)/1000) | Z4: =IF(Z$3=0,"",SUMIFS(INDEX(Inputs!$D$4:$AG$100,0,MATCH(Z$2,Inputs!$D$2:$AG$2,0)),Inputs!$B$4:$B$100,$B4)/1000) | AA4: =IF(AA$3=0,"",SUMIFS(INDEX(Inputs!$D$4:$AG$100,0,MATCH(AA$2,Inputs!$D$2:$AG$2,0)),Inputs!$B$4:$B$100,$B4)/1000) | AB4: =IF(COUNT(X4:AA4)=4,SUM(X4:AA4),"") | AC4: =IF(AC$3=0,"",SUMIFS(INDEX(Inputs!$D$4:$AG$100,0,MATCH(AC$2,Inputs!$D$2:$AG$2,0)),Inputs!$B$4:$B$100,$B4)/1000) | AD4: =IF(AD$3=0,"",SUMIFS(INDEX(Inputs!$D$4:$AG$100,0,MATCH(AD$2,Inputs!$D$2:$AG$2,0)),Inputs!$B$4:$B$100,$B4)/1000) | AE4: =IF(AE$3=0,"",SUMIFS(INDEX(Inputs!$D$4:$AG$100,0,MATCH(AE$2,Inputs!$D$2:$AG$2,0)),Inputs!$B$4:$B$100,$B4)/1000) | AF4: =IF(AF$3=0,"",SUMIFS(INDEX(Inputs!$D$4:$AG$100,0,MATCH(AF$2,Inputs!$D$2:$AG$2,0)),Inputs!$B$4:$B$100,$B4)/1000) | AG4: =IF(COUNT(AC4:AF4)=4,SUM(AC4:AF4),"")
B5: 2 | C5: COGS (cash) | D5: =IF(D$3=0,"",SUMIFS(INDEX(Inputs!$D$4:$AG$100,0,MATCH(D$2,Inputs!$D$2:$AG$2,0)),Inputs!$B$4:$B$100,$B5)/1000) | E5: =IF(E$3=0,"",SUMIFS(INDEX(Inputs!$D$4:$AG$100,0,MATCH(E$2,Inputs!$D$2:$AG$2,0)),Inputs!$B$4:$B$100,$B5)/1000) | F5: =IF(F$3=0,"",SUMIFS(INDEX(Inputs!$D$4:$AG$100,0,MATCH(F$2,Inputs!$D$2:$AG$2,0)),Inputs!$B$4:$B$100,$B5)/1000) | G5: =IF(G$3=0,"",SUMIFS(INDEX(Inputs!$D$4:$AG$100,0,MATCH(G$2,Inputs!$D$2:$AG$2,0)),Inputs!$B$4:$B$100,$B5)/1000) | H5: =IF(COUNT(D5:G5)=4,SUM(D5:G5),"") | I5: =IF(I$3=0,"",SUMIFS(INDEX(Inputs!$D$4:$AG$100,0,MATCH(I$2,Inputs!$D$2:$AG$2,0)),Inputs!$B$4:$B$100,$B5)/1000) | J5: =IF(J$3=0,"",SUMIFS(INDEX(Inputs!$D$4:$AG$100,0,MATCH(J$2,Inputs!$D$2:$AG$2,0)),Inputs!$B$4:$B$100,$B5)/1000) | K5: =IF(K$3=0,"",SUMIFS(INDEX(Inputs!$D$4:$AG$100,0,MATCH(K$2,Inputs!$D$2:$AG$2,0)),Inputs!$B$4:$B$100,$B5)/1000) | L5: =IF(L$3=0,"",SUMIFS(INDEX(Inputs!$D$4:$AG$100,0,MATCH(L$2,Inputs!$D$2:$AG$2,0)),Inputs!$B$4:$B$100,$B5)/1000) | M5: =IF(COUNT(I5:L5)=4,SUM(I5:L5),"") | N5: =IF(N$3=0,"",SUMIFS(INDEX(Inputs!$D$4:$AG$100,0,MATCH(N$2,Inputs!$D$2:$AG$2,0)),Inputs!$B$4:$B$100,$B5)/1000) | O5: =IF(O$3=0,"",SUMIFS(INDEX(Inputs!$D$4:$AG$100,0,MATCH(O$2,Inputs!$D$2:$AG$2,0)),Inputs!$B$4:$B$100,$B5)/1000) | P5: =IF(P$3=0,"",SUMIFS(INDEX(Inputs!$D$4:$AG$100,0,MATCH(P$2,Inputs!$D$2:$AG$2,0)),Inputs!$B$4:$B$100,$B5)/1000) | Q5: =IF(Q$3=0,"",SUMIFS(INDEX(Inputs!$D$4:$AG$100,0,MATCH(Q$2,Inputs!$D$2:$AG$2,0)),Inputs!$B$4:$B$100,$B5)/1000) | R5: =IF(COUNT(N5:Q5)=4,SUM(N5:Q5),"") | S5: =IF(S$3=0,"",SUMIFS(INDEX(Inputs!$D$4:$AG$100,0,MATCH(S$2,Inputs!$D$2:$AG$2,0)),Inputs!$B$4:$B$100,$B5)/1000) | T5: =IF(T$3=0,"",SUMIFS(INDEX(Inputs!$D$4:$AG$100,0,MATCH(T$2,Inputs!$D$2:$AG$2,0)),Inputs!$B$4:$B$100,$B5)/1000) | U5: =IF(U$3=0,"",SUMIFS(INDEX(Inputs!$D$4:$AG$100,0,MATCH(U$2,Inputs!$D$2:$AG$2,0)),Inputs!$B$4:$B$100,$B5)/1000) | V5: =IF(V$3=0,"",SUMIFS(INDEX(Inputs!$D$4:$AG$100,0,MATCH(V$2,Inputs!$D$2:$AG$2,0)),Inputs!$B$4:$B$100,$B5)/1000) | W5: =IF(COUNT(S5:V5)=4,SUM(S5:V5),"") | X5: =IF(X$3=0,"",SUMIFS(INDEX(Inputs!$D$4:$AG$100,0,MATCH(X$2,Inputs!$D$2:$AG$2,0)),Inputs!$B$4:$B$100,$B5)/1000) | Y5: =IF(Y$3=0,"",SUMIFS(INDEX(Inputs!$D$4:$AG$100,0,MATCH(Y$2,Inputs!$D$2:$AG$2,0)),Inputs!$B$4:$B$100,$B5)/1000) | Z5: =IF(Z$3=0,"",SUMIFS(INDEX(Inputs!$D$4:$AG$100,0,MATCH(Z$2,Inputs!$D$2:$AG$2,0)),Inputs!$B$4:$B$100,$B5)/1000) | AA5: =IF(AA$3=0,"",SUMIFS(INDEX(Inputs!$D$4:$AG$100,0,MATCH(AA$2,Inputs!$D$2:$AG$2,0)),Inputs!$B$4:$B$100,$B5)/1000) | AB5: =IF(COUNT(X5:AA5)=4,SUM(X5:AA5),"") | AC5: =IF(AC$3=0,"",SUMIFS(INDEX(Inputs!$D$4:$AG$100,0,MATCH(AC$2,Inputs!$D$2:$AG$2,0)),Inputs!$B$4:$B$100,$B5)/1000) | AD5: =IF(AD$3=0,"",SUMIFS(INDEX(Inputs!$D$4:$AG$100,0,MATCH(AD$2,Inputs!$D$2:$AG$2,0)),Inputs!$B$4:$B$100,$B5)/1000) | AE5: =IF(AE$3=0,"",SUMIFS(INDEX(Inputs!$D$4:$AG$100,0,MATCH(AE$2,Inputs!$D$2:$AG$2,0)),Inputs!$B$4:$B$100,$B5)/1000) | AF5: =IF(AF$3=0,"",SUMIFS(INDEX(Inputs!$D$4:$AG$100,0,MATCH(AF$2,Inputs!$D$2:$AG$2,0)),Inputs!$B$4:$B$100,$B5)/1000) | AG5: =IF(COUNT(AC5:AF5)=4,SUM(AC5:AF5),"")
B6: 3 | C6: SG&A and Other (cash) | D6: =IF(D$3=0,"",SUMIFS(INDEX(Inputs!$D$4:$AG$100,0,MATCH(D$2,Inputs!$D$2:$AG$2,0)),Inputs!$B$4:$B$100,$B6)/1000) | E6: =IF(E$3=0,"",SUMIFS(INDEX(Inputs!$D$4:$AG$100,0,MATCH(E$2,Inputs!$D$2:$AG$2,0)),Inputs!$B$4:$B$100,$B6)/1000) | F6: =IF(F$3=0,"",SUMIFS(INDEX(Inputs!$D$4:$AG$100,0,MATCH(F$2,Inputs!$D$2:$AG$2,0)),Inputs!$B$4:$B$100,$B6)/1000) | G6: =IF(G$3=0,"",SUMIFS(INDEX(Inputs!$D$4:$AG$100,0,MATCH(G$2,Inputs!$D$2:$AG$2,0)),Inputs!$B$4:$B$100,$B6)/1000) | H6: =IF(COUNT(D6:G6)=4,SUM(D6:G6),"") | I6: =IF(I$3=0,"",SUMIFS(INDEX(Inputs!$D$4:$AG$100,0,MATCH(I$2,Inputs!$D$2:$AG$2,0)),Inputs!$B$4:$B$100,$B6)/1000) | J6: =IF(J$3=0,"",SUMIFS(INDEX(Inputs!$D$4:$AG$100,0,MATCH(J$2,Inputs!$D$2:$AG$2,0)),Inputs!$B$4:$B$100,$B6)/1000) | K6: =IF(K$3=0,"",SUMIFS(INDEX(Inputs!$D$4:$AG$100,0,MATCH(K$2,Inputs!$D$2:$AG$2,0)),Inputs!$B$4:$B$100,$B6)/1000) | L6: =IF(L$3=0,"",SUMIFS(INDEX(Inputs!$D$4:$AG$100,0,MATCH(L$2,Inputs!$D$2:$AG$2,0)),Inputs!$B$4:$B$100,$B6)/1000) | M6: =IF(COUNT(I6:L6)=4,SUM(I6:L6),"") | N6: =IF(N$3=0,"",SUMIFS(INDEX(Inputs!$D$4:$AG$100,0,MATCH(N$2,Inputs!$D$2:$AG$2,0)),Inputs!$B$4:$B$100,$B6)/1000) | O6: =IF(O$3=0,"",SUMIFS(INDEX(Inputs!$D$4:$AG$100,0,MATCH(O$2,Inputs!$D$2:$AG$2,0)),Inputs!$B$4:$B$100,$B6)/1000) | P6: =IF(P$3=0,"",SUMIFS(INDEX(Inputs!$D$4:$AG$100,0,MATCH(P$2,Inputs!$D$2:$AG$2,0)),Inputs!$B$4:$B$100,$B6)/1000) | Q6: =IF(Q$3=0,"",SUMIFS(INDEX(Inputs!$D$4:$AG$100,0,MATCH(Q$2,Inputs!$D$2:$AG$2,0)),Inputs!$B$4:$B$100,$B6)/1000) | R6: =IF(COUNT(N6:Q6)=4,SUM(N6:Q6),"") | S6: =IF(S$3=0,"",SUMIFS(INDEX(Inputs!$D$4:$AG$100,0,MATCH(S$2,Inputs!$D$2:$AG$2,0)),Inputs!$B$4:$B$100,$B6)/1000) | T6: =IF(T$3=0,"",SUMIFS(INDEX(Inputs!$D$4:$AG$100,0,MATCH(T$2,Inputs!$D$2:$AG$2,0)),Inputs!$B$4:$B$100,$B6)/1000) | U6: =IF(U$3=0,"",SUMIFS(INDEX(Inputs!$D$4:$AG$100,0,MATCH(U$2,Inputs!$D$2:$AG$2,0)),Inputs!$B$4:$B$100,$B6)/1000) | V6: =IF(V$3=0,"",SUMIFS(INDEX(Inputs!$D$4:$AG$100,0,MATCH(V$2,Inputs!$D$2:$AG$2,0)),Inputs!$B$4:$B$100,$B6)/1000) | W6: =IF(COUNT(S6:V6)=4,SUM(S6:V6),"") | X6: =IF(X$3=0,"",SUMIFS(INDEX(Inputs!$D$4:$AG$100,0,MATCH(X$2,Inputs!$D$2:$AG$2,0)),Inputs!$B$4:$B$100,$B6)/1000) | Y6: =IF(Y$3=0,"",SUMIFS(INDEX(Inputs!$D$4:$AG$100,0,MATCH(Y$2,Inputs!$D$2:$AG$2,0)),Inputs!$B$4:$B$100,$B6)/1000) | Z6: =IF(Z$3=0,"",SUMIFS(INDEX(Inputs!$D$4:$AG$100,0,MATCH(Z$2,Inputs!$D$2:$AG$2,0)),Inputs!$B$4:$B$100,$B6)/1000) | AA6: =IF(AA$3=0,"",SUMIFS(INDEX(Inputs!$D$4:$AG$100,0,MATCH(AA$2,Inputs!$D$2:$AG$2,0)),Inputs!$B$4:$B$100,$B6)/1000) | AB6: =IF(COUNT(X6:AA6)=4,SUM(X6:AA6),"") | AC6: =IF(AC$3=0,"",SUMIFS(INDEX(Inputs!$D$4:$AG$100,0,MATCH(AC$2,Inputs!$D$2:$AG$2,0)),Inputs!$B$4:$B$100,$B6)/1000) | AD6: =IF(AD$3=0,"",SUMIFS(INDEX(Inputs!$D$4:$AG$100,0,MATCH(AD$2,Inputs!$D$2:$AG$2,0)),Inputs!$B$4:$B$100,$B6)/1000) | AE6: =IF(AE$3=0,"",SUMIFS(INDEX(Inputs!$D$4:$AG$100,0,MATCH(AE$2,Inputs!$D$2:$AG$2,0)),Inputs!$B$4:$B$100,$B6)/1000) | AF6: =IF(AF$3=0,"",SUMIFS(INDEX(Inputs!$D$4:$AG$100,0,MATCH(AF$2,Inputs!$D$2:$AG$2,0)),Inputs!$B$4:$B$100,$B6)/1000) | AG6: =IF(COUNT(AC6:AF6)=4,SUM(AC6:AF6),"")
B7: 4 | C7: D&A | D7: =IF(D$3=0,"",SUMIFS(INDEX(Inputs!$D$4:$AG$100,0,MATCH(D$2,Inputs!$D$2:$AG$2,0)),Inputs!$B$4:$B$100,$B7)/1000) | E7: =IF(E$3=0,"",SUMIFS(INDEX(Inputs!$D$4:$AG$100,0,MATCH(E$2,Inputs!$D$2:$AG$2,0)),Inputs!$B$4:$B$100,$B7)/1000) | F7: =IF(F$3=0,"",SUMIFS(INDEX(Inputs!$D$4:$AG$100,0,MATCH(F$2,Inputs!$D$2:$AG$2,0)),Inputs!$B$4:$B$100,$B7)/1000) | G7: =IF(G$3=0,"",SUMIFS(INDEX(Inputs!$D$4:$AG$100,0,MATCH(G$2,Inputs!$D$2:$AG$2,0)),Inputs!$B$4:$B$100,$B7)/1000) | H7: =IF(COUNT(D7:G7)=4,SUM(D7:G7),"") | I7: =IF(I$3=0,"",SUMIFS(INDEX(Inputs!$D$4:$AG$100,0,MATCH(I$2,Inputs!$D$2:$AG$2,0)),Inputs!$B$4:$B$100,$B7)/1000) | J7: =IF(J$3=0,"",SUMIFS(INDEX(Inputs!$D$4:$AG$100,0,MATCH(J$2,Inputs!$D$2:$AG$2,0)),Inputs!$B$4:$B$100,$B7)/1000) | K7: =IF(K$3=0,"",SUMIFS(INDEX(Inputs!$D$4:$AG$100,0,MATCH(K$2,Inputs!$D$2:$AG$2,0)),Inputs!$B$4:$B$100,$B7)/1000) | L7: =IF(L$3=0,"",SUMIFS(INDEX(Inputs!$D$4:$AG$100,0,MATCH(L$2,Inputs!$D$2:$AG$2,0)),Inputs!$B$4:$B$100,$B7)/1000) | M7: =IF(COUNT(I7:L7)=4,SUM(I7:L7),"") | N7: =IF(N$3=0,"",SUMIFS(INDEX(Inputs!$D$4:$AG$100,0,MATCH(N$2,Inputs!$D$2:$AG$2,0)),Inputs!$B$4:$B$100,$B7)/1000) | O7: =IF(O$3=0,"",SUMIFS(INDEX(Inputs!$D$4:$AG$100,0,MATCH(O$2,Inputs!$D$2:$AG$2,0)),Inputs!$B$4:$B$100,$B7)/1000) | P7: =IF(P$3=0,"",SUMIFS(INDEX(Inputs!$D$4:$AG$100,0,MATCH(P$2,Inputs!$D$2:$AG$2,0)),Inputs!$B$4:$B$100,$B7)/1000) | Q7: =IF(Q$3=0,"",SUMIFS(INDEX(Inputs!$D$4:$AG$100,0,MATCH(Q$2,Inputs!$D$2:$AG$2,0)),Inputs!$B$4:$B$100,$B7)/1000) | R7: =IF(COUNT(N7:Q7)=4,SUM(N7:Q7),"") | S7: =IF(S$3=0,"",SUMIFS(INDEX(Inputs!$D$4:$AG$100,0,MATCH(S$2,Inputs!$D$2:$AG$2,0)),Inputs!$B$4:$B$100,$B7)/1000) | T7: =IF(T$3=0,"",SUMIFS(INDEX(Inputs!$D$4:$AG$100,0,MATCH(T$2,Inputs!$D$2:$AG$2,0)),Inputs!$B$4:$B$100,$B7)/1000) | U7: =IF(U$3=0,"",SUMIFS(INDEX(Inputs!$D$4:$AG$100,0,MATCH(U$2,Inputs!$D$2:$AG$2,0)),Inputs!$B$4:$B$100,$B7)/1000) | V7: =IF(V$3=0,"",SUMIFS(INDEX(Inputs!$D$4:$AG$100,0,MATCH(V$2,Inputs!$D$2:$AG$2,0)),Inputs!$B$4:$B$100,$B7)/1000) | W7: =IF(COUNT(S7:V7)=4,SUM(S7:V7),"") | X7: =IF(X$3=0,"",SUMIFS(INDEX(Inputs!$D$4:$AG$100,0,MATCH(X$2,Inputs!$D$2:$AG$2,0)),Inputs!$B$4:$B$100,$B7)/1000) | Y7: =IF(Y$3=0,"",SUMIFS(INDEX(Inputs!$D$4:$AG$100,0,MATCH(Y$2,Inputs!$D$2:$AG$2,0)),Inputs!$B$4:$B$100,$B7)/1000) | Z7: =IF(Z$3=0,"",SUMIFS(INDEX(Inputs!$D$4:$AG$100,0,MATCH(Z$2,Inputs!$D$2:$AG$2,0)),Inputs!$B$4:$B$100,$B7)/1000) | AA7: =IF(AA$3=0,"",SUMIFS(INDEX(Inputs!$D$4:$AG$100,0,MATCH(AA$2,Inputs!$D$2:$AG$2,0)),Inputs!$B$4:$B$100,$B7)/1000) | AB7: =IF(COUNT(X7:AA7)=4,SUM(X7:AA7),"") | AC7: =IF(AC$3=0,"",SUMIFS(INDEX(Inputs!$D$4:$AG$100,0,MATCH(AC$2,Inputs!$D$2:$AG$2,0)),Inputs!$B$4:$B$100,$B7)/1000) | AD7: =IF(AD$3=0,"",SUMIFS(INDEX(Inputs!$D$4:$AG$100,0,MATCH(AD$2,Inputs!$D$2:$AG$2,0)),Inputs!$B$4:$B$100,$B7)/1000) | AE7: =IF(AE$3=0,"",SUMIFS(INDEX(Inputs!$D$4:$AG$100,0,MATCH(AE$2,Inputs!$D$2:$AG$2,0)),Inputs!$B$4:$B$100,$B7)/1000) | AF7: =IF(AF$3=0,"",SUMIFS(INDEX(Inputs!$D$4:$AG$100,0,MATCH(AF$2,Inputs!$D$2:$AG$2,0)),Inputs!$B$4:$B$100,$B7)/1000) | AG7: =IF(COUNT(AC7:AF7)=4,SUM(AC7:AF7),"")
B8: 5 | C8: Interest Expense | D8: =IF(D$3=0,"",SUMIFS(INDEX(Inputs!$D$4:$AG$100,0,MATCH(D$2,Inputs!$D$2:$AG$2,0)),Inputs!$B$4:$B$100,$B8)/1000) | E8: =IF(E$3=0,"",SUMIFS(INDEX(Inputs!$D$4:$AG$100,0,MATCH(E$2,Inputs!$D$2:$AG$2,0)),Inputs!$B$4:$B$100,$B8)/1000) | F8: =IF(F$3=0,"",SUMIFS(INDEX(Inputs!$D$4:$AG$100,0,MATCH(F$2,Inputs!$D$2:$AG$2,0)),Inputs!$B$4:$B$100,$B8)/1000) | G8: =IF(G$3=0,"",SUMIFS(INDEX(Inputs!$D$4:$AG$100,0,MATCH(G$2,Inputs!$D$2:$AG$2,0)),Inputs!$B$4:$B$100,$B8)/1000) | H8: =IF(COUNT(D8:G8)=4,SUM(D8:G8),"") | I8: =IF(I$3=0,"",SUMIFS(INDEX(Inputs!$D$4:$AG$100,0,MATCH(I$2,Inputs!$D$2:$AG$2,0)),Inputs!$B$4:$B$100,$B8)/1000) | J8: =IF(J$3=0,"",SUMIFS(INDEX(Inputs!$D$4:$AG$100,0,MATCH(J$2,Inputs!$D$2:$AG$2,0)),Inputs!$B$4:$B$100,$B8)/1000) | K8: =IF(K$3=0,"",SUMIFS(INDEX(Inputs!$D$4:$AG$100,0,MATCH(K$2,Inputs!$D$2:$AG$2,0)),Inputs!$B$4:$B$100,$B8)/1000) | L8: =IF(L$3=0,"",SUMIFS(INDEX(Inputs!$D$4:$AG$100,0,MATCH(L$2,Inputs!$D$2:$AG$2,0)),Inputs!$B$4:$B$100,$B8)/1000) | M8: =IF(COUNT(I8:L8)=4,SUM(I8:L8),"") | N8: =IF(N$3=0,"",SUMIFS(INDEX(Inputs!$D$4:$AG$100,0,MATCH(N$2,Inputs!$D$2:$AG$2,0)),Inputs!$B$4:$B$100,$B8)/1000) | O8: =IF(O$3=0,"",SUMIFS(INDEX(Inputs!$D$4:$AG$100,0,MATCH(O$2,Inputs!$D$2:$AG$2,0)),Inputs!$B$4:$B$100,$B8)/1000) | P8: =IF(P$3=0,"",SUMIFS(INDEX(Inputs!$D$4:$AG$100,0,MATCH(P$2,Inputs!$D$2:$AG$2,0)),Inputs!$B$4:$B$100,$B8)/1000) | Q8: =IF(Q$3=0,"",SUMIFS(INDEX(Inputs!$D$4:$AG$100,0,MATCH(Q$2,Inputs!$D$2:$AG$2,0)),Inputs!$B$4:$B$100,$B8)/1000) | R8: =IF(COUNT(N8:Q8)=4,SUM(N8:Q8),"") | S8: =IF(S$3=0,"",SUMIFS(INDEX(Inputs!$D$4:$AG$100,0,MATCH(S$2,Inputs!$D$2:$AG$2,0)),Inputs!$B$4:$B$100,$B8)/1000) | T8: =IF(T$3=0,"",SUMIFS(INDEX(Inputs!$D$4:$AG$100,0,MATCH(T$2,Inputs!$D$2:$AG$2,0)),Inputs!$B$4:$B$100,$B8)/1000) | U8: =IF(U$3=0,"",SUMIFS(INDEX(Inputs!$D$4:$AG$100,0,MATCH(U$2,Inputs!$D$2:$AG$2,0)),Inputs!$B$4:$B$100,$B8)/1000) | V8: =IF(V$3=0,"",SUMIFS(INDEX(Inputs!$D$4:$AG$100,0,MATCH(V$2,Inputs!$D$2:$AG$2,0)),Inputs!$B$4:$B$100,$B8)/1000) | W8: =IF(COUNT(S8:V8)=4,SUM(S8:V8),"") | X8: =IF(X$3=0,"",SUMIFS(INDEX(Inputs!$D$4:$AG$100,0,MATCH(X$2,Inputs!$D$2:$AG$2,0)),Inputs!$B$4:$B$100,$B8)/1000) | Y8: =IF(Y$3=0,"",SUMIFS(INDEX(Inputs!$D$4:$AG$100,0,MATCH(Y$2,Inputs!$D$2:$AG$2,0)),Inputs!$B$4:$B$100,$B8)/1000) | Z8: =IF(Z$3=0,"",SUMIFS(INDEX(Inputs!$D$4:$AG$100,0,MATCH(Z$2,Inputs!$D$2:$AG$2,0)),Inputs!$B$4:$B$100,$B8)/1000) | AA8: =IF(AA$3=0,"",SUMIFS(INDEX(Inputs!$D$4:$AG$100,0,MATCH(AA$2,Inputs!$D$2:$AG$2,0)),Inputs!$B$4:$B$100,$B8)/1000) | AB8: =IF(COUNT(X8:AA8)=4,SUM(X8:AA8),"") | AC8: =IF(AC$3=0,"",SUMIFS(INDEX(Inputs!$D$4:$AG$100,0,MATCH(AC$2,Inputs!$D$2:$AG$2,0)),Inputs!$B$4:$B$100,$B8)/1000) | AD8: =IF(AD$3=0,"",SUMIFS(INDEX(Inputs!$D$4:$AG$100,0,MATCH(AD$2,Inputs!$D$2:$AG$2,0)),Inputs!$B$4:$B$100,$B8)/1000) | AE8: =IF(AE$3=0,"",SUMIFS(INDEX(Inputs!$D$4:$AG$100,0,MATCH(AE$2,Inputs!$D$2:$AG$2,0)),Inputs!$B$4:$B$100,$B8)/1000) | AF8: =IF(AF$3=0,"",SUMIFS(INDEX(Inputs!$D$4:$AG$100,0,MATCH(AF$2,Inputs!$D$2:$AG$2,0)),Inputs!$B$4:$B$100,$B8)/1000) | AG8: =IF(COUNT(AC8:AF8)=4,SUM(AC8:AF8),"")
B9: 6 | C9: Nonoperating Income / (Loss) | D9: =IF(D$3=0,"",SUMIFS(INDEX(Inputs!$D$4:$AG$100,0,MATCH(D$2,Inputs!$D$2:$AG$2,0)),Inputs!$B$4:$B$100,$B9)/1000) | E9: =IF(E$3=0,"",SUMIFS(INDEX(Inputs!$D$4:$AG$100,0,MATCH(E$2,Inputs!$D$2:$AG$2,0)),Inputs!$B$4:$B$100,$B9)/1000) | F9: =IF(F$3=0,"",SUMIFS(INDEX(Inputs!$D$4:$AG$100,0,MATCH(F$2,Inputs!$D$2:$AG$2,0)),Inputs!$B$4:$B$100,$B9)/1000) | G9: =IF(G$3=0,"",SUMIFS(INDEX(Inputs!$D$4:$AG$100,0,MATCH(G$2,Inputs!$D$2:$AG$2,0)),Inputs!$B$4:$B$100,$B9)/1000) | H9: =IF(COUNT(D9:G9)=4,SUM(D9:G9),"") | I9: =IF(I$3=0,"",SUMIFS(INDEX(Inputs!$D$4:$AG$100,0,MATCH(I$2,Inputs!$D$2:$AG$2,0)),Inputs!$B$4:$B$100,$B9)/1000) | J9: =IF(J$3=0,"",SUMIFS(INDEX(Inputs!$D$4:$AG$100,0,MATCH(J$2,Inputs!$D$2:$AG$2,0)),Inputs!$B$4:$B$100,$B9)/1000) | K9: =IF(K$3=0,"",SUMIFS(INDEX(Inputs!$D$4:$AG$100,0,MATCH(K$2,Inputs!$D$2:$AG$2,0)),Inputs!$B$4:$B$100,$B9)/1000) | L9: =IF(L$3=0,"",SUMIFS(INDEX(Inputs!$D$4:$AG$100,0,MATCH(L$2,Inputs!$D$2:$AG$2,0)),Inputs!$B$4:$B$100,$B9)/1000) | M9: =IF(COUNT(I9:L9)=4,SUM(I9:L9),"") | N9: =IF(N$3=0,"",SUMIFS(INDEX(Inputs!$D$4:$AG$100,0,MATCH(N$2,Inputs!$D$2:$AG$2,0)),Inputs!$B$4:$B$100,$B9)/1000) | O9: =IF(O$3=0,"",SUMIFS(INDEX(Inputs!$D$4:$AG$100,0,MATCH(O$2,Inputs!$D$2:$AG$2,0)),Inputs!$B$4:$B$100,$B9)/1000) | P9: =IF(P$3=0,"",SUMIFS(INDEX(Inputs!$D$4:$AG$100,0,MATCH(P$2,Inputs!$D$2:$AG$2,0)),Inputs!$B$4:$B$100,$B9)/1000) | Q9: =IF(Q$3=0,"",SUMIFS(INDEX(Inputs!$D$4:$AG$100,0,MATCH(Q$2,Inputs!$D$2:$AG$2,0)),Inputs!$B$4:$B$100,$B9)/1000) | R9: =IF(COUNT(N9:Q9)=4,SUM(N9:Q9),"") | S9: =IF(S$3=0,"",SUMIFS(INDEX(Inputs!$D$4:$AG$100,0,MATCH(S$2,Inputs!$D$2:$AG$2,0)),Inputs!$B$4:$B$100,$B9)/1000) | T9: =IF(T$3=0,"",SUMIFS(INDEX(Inputs!$D$4:$AG$100,0,MATCH(T$2,Inputs!$D$2:$AG$2,0)),Inputs!$B$4:$B$100,$B9)/1000) | U9: =IF(U$3=0,"",SUMIFS(INDEX(Inputs!$D$4:$AG$100,0,MATCH(U$2,Inputs!$D$2:$AG$2,0)),Inputs!$B$4:$B$100,$B9)/1000) | V9: =IF(V$3=0,"",SUMIFS(INDEX(Inputs!$D$4:$AG$100,0,MATCH(V$2,Inputs!$D$2:$AG$2,0)),Inputs!$B$4:$B$100,$B9)/1000) | W9: =IF(COUNT(S9:V9)=4,SUM(S9:V9),"") | X9: =IF(X$3=0,"",SUMIFS(INDEX(Inputs!$D$4:$AG$100,0,MATCH(X$2,Inputs!$D$2:$AG$2,0)),Inputs!$B$4:$B$100,$B9)/1000) | Y9: =IF(Y$3=0,"",SUMIFS(INDEX(Inputs!$D$4:$AG$100,0,MATCH(Y$2,Inputs!$D$2:$AG$2,0)),Inputs!$B$4:$B$100,$B9)/1000) | Z9: =IF(Z$3=0,"",SUMIFS(INDEX(Inputs!$D$4:$AG$100,0,MATCH(Z$2,Inputs!$D$2:$AG$2,0)),Inputs!$B$4:$B$100,$B9)/1000) | AA9: =IF(AA$3=0,"",SUMIFS(INDEX(Inputs!$D$4:$AG$100,0,MATCH(AA$2,Inputs!$D$2:$AG$2,0)),Inputs!$B$4:$B$100,$B9)/1000) | AB9: =IF(COUNT(X9:AA9)=4,SUM(X9:AA9),"") | AC9: =IF(AC$3=0,"",SUMIFS(INDEX(Inputs!$D$4:$AG$100,0,MATCH(AC$2,Inputs!$D$2:$AG$2,0)),Inputs!$B$4:$B$100,$B9)/1000) | AD9: =IF(AD$3=0,"",SUMIFS(INDEX(Inputs!$D$4:$AG$100,0,MATCH(AD$2,Inputs!$D$2:$AG$2,0)),Inputs!$B$4:$B$100,$B9)/1000) | AE9: =IF(AE$3=0,"",SUMIFS(INDEX(Inputs!$D$4:$AG$100,0,MATCH(AE$2,Inputs!$D$2:$AG$2,0)),Inputs!$B$4:$B$100,$B9)/1000) | AF9: =IF(AF$3=0,"",SUMIFS(INDEX(Inputs!$D$4:$AG$100,0,MATCH(AF$2,Inputs!$D$2:$AG$2,0)),Inputs!$B$4:$B$100,$B9)/1000) | AG9: =IF(COUNT(AC9:AF9)=4,SUM(AC9:AF9),"")
B10: 7 | C10: Taxes | D10: =IF(D$3=0,"",SUMIFS(INDEX(Inputs!$D$4:$AG$100,0,MATCH(D$2,Inputs!$D$2:$AG$2,0)),Inputs!$B$4:$B$100,$B10)/1000) | E10: =IF(E$3=0,"",SUMIFS(INDEX(Inputs!$D$4:$AG$100,0,MATCH(E$2,Inputs!$D$2:$AG$2,0)),Inputs!$B$4:$B$100,$B10)/1000) | F10: =IF(F$3=0,"",SUMIFS(INDEX(Inputs!$D$4:$AG$100,0,MATCH(F$2,Inputs!$D$2:$AG$2,0)),Inputs!$B$4:$B$100,$B10)/1000) | G10: =IF(G$3=0,"",SUMIFS(INDEX(Inputs!$D$4:$AG$100,0,MATCH(G$2,Inputs!$D$2:$AG$2,0)),Inputs!$B$4:$B$100,$B10)/1000) | H10: =IF(COUNT(D10:G10)=4,SUM(D10:G10),"") | I10: =IF(I$3=0,"",SUMIFS(INDEX(Inputs!$D$4:$AG$100,0,MATCH(I$2,Inputs!$D$2:$AG$2,0)),Inputs!$B$4:$B$100,$B10)/1000) | J10: =IF(J$3=0,"",SUMIFS(INDEX(Inputs!$D$4:$AG$100,0,MATCH(J$2,Inputs!$D$2:$AG$2,0)),Inputs!$B$4:$B$100,$B10)/1000) | K10: =IF(K$3=0,"",SUMIFS(INDEX(Inputs!$D$4:$AG$100,0,MATCH(K$2,Inputs!$D$2:$AG$2,0)),Inputs!$B$4:$B$100,$B10)/1000) | L10: =IF(L$3=0,"",SUMIFS(INDEX(Inputs!$D$4:$AG$100,0,MATCH(L$2,Inputs!$D$2:$AG$2,0)),Inputs!$B$4:$B$100,$B10)/1000) | M10: =IF(COUNT(I10:L10)=4,SUM(I10:L10),"") | N10: =IF(N$3=0,"",SUMIFS(INDEX(Inputs!$D$4:$AG$100,0,MATCH(N$2,Inputs!$D$2:$AG$2,0)),Inputs!$B$4:$B$100,$B10)/1000) | O10: =IF(O$3=0,"",SUMIFS(INDEX(Inputs!$D$4:$AG$100,0,MATCH(O$2,Inputs!$D$2:$AG$2,0)),Inputs!$B$4:$B$100,$B10)/1000) | P10: =IF(P$3=0,"",SUMIFS(INDEX(Inputs!$D$4:$AG$100,0,MATCH(P$2,Inputs!$D$2:$AG$2,0)),Inputs!$B$4:$B$100,$B10)/1000) | Q10: =IF(Q$3=0,"",SUMIFS(INDEX(Inputs!$D$4:$AG$100,0,MATCH(Q$2,Inputs!$D$2:$AG$2,0)),Inputs!$B$4:$B$100,$B10)/1000) | R10: =IF(COUNT(N10:Q10)=4,SUM(N10:Q10),"") | S10: =IF(S$3=0,"",SUMIFS(INDEX(Inputs!$D$4:$AG$100,0,MATCH(S$2,Inputs!$D$2:$AG$2,0)),Inputs!$B$4:$B$100,$B10)/1000) | T10: =IF(T$3=0,"",SUMIFS(INDEX(Inputs!$D$4:$AG$100,0,MATCH(T$2,Inputs!$D$2:$AG$2,0)),Inputs!$B$4:$B$100,$B10)/1000) | U10: =IF(U$3=0,"",SUMIFS(INDEX(Inputs!$D$4:$AG$100,0,MATCH(U$2,Inputs!$D$2:$AG$2,0)),Inputs!$B$4:$B$100,$B10)/1000) | V10: =IF(V$3=0,"",SUMIFS(INDEX(Inputs!$D$4:$AG$100,0,MATCH(V$2,Inputs!$D$2:$AG$2,0)),Inputs!$B$4:$B$100,$B10)/1000) | W10: =IF(COUNT(S10:V10)=4,SUM(S10:V10),"") | X10: =IF(X$3=0,"",SUMIFS(INDEX(Inputs!$D$4:$AG$100,0,MATCH(X$2,Inputs!$D$2:$AG$2,0)),Inputs!$B$4:$B$100,$B10)/1000) | Y10: =IF(Y$3=0,"",SUMIFS(INDEX(Inputs!$D$4:$AG$100,0,MATCH(Y$2,Inputs!$D$2:$AG$2,0)),Inputs!$B$4:$B$100,$B10)/1000) | Z10: =IF(Z$3=0,"",SUMIFS(INDEX(Inputs!$D$4:$AG$100,0,MATCH(Z$2,Inputs!$D$2:$AG$2,0)),Inputs!$B$4:$B$100,$B10)/1000) | AA10: =IF(AA$3=0,"",SUMIFS(INDEX(Inputs!$D$4:$AG$100,0,MATCH(AA$2,Inputs!$D$2:$AG$2,0)),Inputs!$B$4:$B$100,$B10)/1000) | AB10: =IF(COUNT(X10:AA10)=4,SUM(X10:AA10),"") | AC10: =IF(AC$3=0,"",SUMIFS(INDEX(Inputs!$D$4:$AG$100,0,MATCH(AC$2,Inputs!$D$2:$AG$2,0)),Inputs!$B$4:$B$100,$B10)/1000) | AD10: =IF(AD$3=0,"",SUMIFS(INDEX(Inputs!$D$4:$AG$100,0,MATCH(AD$2,Inputs!$D$2:$AG$2,0)),Inputs!$B$4:$B$100,$B10)/1000) | AE10: =IF(AE$3=0,"",SUMIFS(INDEX(Inputs!$D$4:$AG$100,0,MATCH(AE$2,Inputs!$D$2:$AG$2,0)),Inputs!$B$4:$B$100,$B10)/1000) | AF10: =IF(AF$3=0,"",SUMIFS(INDEX(Inputs!$D$4:$AG$100,0,MATCH(AF$2,Inputs!$D$2:$AG$2,0)),Inputs!$B$4:$B$100,$B10)/1000) | AG10: =IF(COUNT(AC10:AF10)=4,SUM(AC10:AF10),"")
B11: 8 | C11: Equity in Income of Affiliates, after tax (enter as +) | D11: =IF(D$3=0,"",SUMIFS(INDEX(Inputs!$D$4:$AG$100,0,MATCH(D$2,Inputs!$D$2:$AG$2,0)),Inputs!$B$4:$B$100,$B11)/1000) | E11: =IF(E$3=0,"",SUMIFS(INDEX(Inputs!$D$4:$AG$100,0,MATCH(E$2,Inputs!$D$2:$AG$2,0)),Inputs!$B$4:$B$100,$B11)/1000) | F11: =IF(F$3=0,"",SUMIFS(INDEX(Inputs!$D$4:$AG$100,0,MATCH(F$2,Inputs!$D$2:$AG$2,0)),Inputs!$B$4:$B$100,$B11)/1000) | G11: =IF(G$3=0,"",SUMIFS(INDEX(Inputs!$D$4:$AG$100,0,MATCH(G$2,Inputs!$D$2:$AG$2,0)),Inputs!$B$4:$B$100,$B11)/1000) | H11: =IF(COUNT(D11:G11)=4,SUM(D11:G11),"") | I11: =IF(I$3=0,"",SUMIFS(INDEX(Inputs!$D$4:$AG$100,0,MATCH(I$2,Inputs!$D$2:$AG$2,0)),Inputs!$B$4:$B$100,$B11)/1000) | J11: =IF(J$3=0,"",SUMIFS(INDEX(Inputs!$D$4:$AG$100,0,MATCH(J$2,Inputs!$D$2:$AG$2,0)),Inputs!$B$4:$B$100,$B11)/1000) | K11: =IF(K$3=0,"",SUMIFS(INDEX(Inputs!$D$4:$AG$100,0,MATCH(K$2,Inputs!$D$2:$AG$2,0)),Inputs!$B$4:$B$100,$B11)/1000) | L11: =IF(L$3=0,"",SUMIFS(INDEX(Inputs!$D$4:$AG$100,0,MATCH(L$2,Inputs!$D$2:$AG$2,0)),Inputs!$B$4:$B$100,$B11)/1000) | M11: =IF(COUNT(I11:L11)=4,SUM(I11:L11),"") | N11: =IF(N$3=0,"",SUMIFS(INDEX(Inputs!$D$4:$AG$100,0,MATCH(N$2,Inputs!$D$2:$AG$2,0)),Inputs!$B$4:$B$100,$B11)/1000) | O11: =IF(O$3=0,"",SUMIFS(INDEX(Inputs!$D$4:$AG$100,0,MATCH(O$2,Inputs!$D$2:$AG$2,0)),Inputs!$B$4:$B$100,$B11)/1000) | P11: =IF(P$3=0,"",SUMIFS(INDEX(Inputs!$D$4:$AG$100,0,MATCH(P$2,Inputs!$D$2:$AG$2,0)),Inputs!$B$4:$B$100,$B11)/1000) | Q11: =IF(Q$3=0,"",SUMIFS(INDEX(Inputs!$D$4:$AG$100,0,MATCH(Q$2,Inputs!$D$2:$AG$2,0)),Inputs!$B$4:$B$100,$B11)/1000) | R11: =IF(COUNT(N11:Q11)=4,SUM(N11:Q11),"") | S11: =IF(S$3=0,"",SUMIFS(INDEX(Inputs!$D$4:$AG$100,0,MATCH(S$2,Inputs!$D$2:$AG$2,0)),Inputs!$B$4:$B$100,$B11)/1000) | T11: =IF(T$3=0,"",SUMIFS(INDEX(Inputs!$D$4:$AG$100,0,MATCH(T$2,Inputs!$D$2:$AG$2,0)),Inputs!$B$4:$B$100,$B11)/1000) | U11: =IF(U$3=0,"",SUMIFS(INDEX(Inputs!$D$4:$AG$100,0,MATCH(U$2,Inputs!$D$2:$AG$2,0)),Inputs!$B$4:$B$100,$B11)/1000) | V11: =IF(V$3=0,"",SUMIFS(INDEX(Inputs!$D$4:$AG$100,0,MATCH(V$2,Inputs!$D$2:$AG$2,0)),Inputs!$B$4:$B$100,$B11)/1000) | W11: =IF(COUNT(S11:V11)=4,SUM(S11:V11),"") | X11: =IF(X$3=0,"",SUMIFS(INDEX(Inputs!$D$4:$AG$100,0,MATCH(X$2,Inputs!$D$2:$AG$2,0)),Inputs!$B$4:$B$100,$B11)/1000) | Y11: =IF(Y$3=0,"",SUMIFS(INDEX(Inputs!$D$4:$AG$100,0,MATCH(Y$2,Inputs!$D$2:$AG$2,0)),Inputs!$B$4:$B$100,$B11)/1000) | Z11: =IF(Z$3=0,"",SUMIFS(INDEX(Inputs!$D$4:$AG$100,0,MATCH(Z$2,Inputs!$D$2:$AG$2,0)),Inputs!$B$4:$B$100,$B11)/1000) | AA11: =IF(AA$3=0,"",SUMIFS(INDEX(Inputs!$D$4:$AG$100,0,MATCH(AA$2,Inputs!$D$2:$AG$2,0)),Inputs!$B$4:$B$100,$B11)/1000) | AB11: =IF(COUNT(X11:AA11)=4,SUM(X11:AA11),"") | AC11: =IF(AC$3=0,"",SUMIFS(INDEX(Inputs!$D$4:$AG$100,0,MATCH(AC$2,Inputs!$D$2:$AG$2,0)),Inputs!$B$4:$B$100,$B11)/1000) | AD11: =IF(AD$3=0,"",SUMIFS(INDEX(Inputs!$D$4:$AG$100,0,MATCH(AD$2,Inputs!$D$2:$AG$2,0)),Inputs!$B$4:$B$100,$B11)/1000) | AE11: =IF(AE$3=0,"",SUMIFS(INDEX(Inputs!$D$4:$AG$100,0,MATCH(AE$2,Inputs!$D$2:$AG$2,0)),Inputs!$B$4:$B$100,$B11)/1000) | AF11: =IF(AF$3=0,"",SUMIFS(INDEX(Inputs!$D$4:$AG$100,0,MATCH(AF$2,Inputs!$D$2:$AG$2,0)),Inputs!$B$4:$B$100,$B11)/1000) | AG11: =IF(COUNT(AC11:AF11)=4,SUM(AC11:AF11),"")
B12: 9 | C12: Minority Interest Expense, after tax (enter as - ) | D12: =IF(D$3=0,"",SUMIFS(INDEX(Inputs!$D$4:$AG$100,0,MATCH(D$2,Inputs!$D$2:$AG$2,0)),Inputs!$B$4:$B$100,$B12)/1000) | E12: =IF(E$3=0,"",SUMIFS(INDEX(Inputs!$D$4:$AG$100,0,MATCH(E$2,Inputs!$D$2:$AG$2,0)),Inputs!$B$4:$B$100,$B12)/1000) | F12: =IF(F$3=0,"",SUMIFS(INDEX(Inputs!$D$4:$AG$100,0,MATCH(F$2,Inputs!$D$2:$AG$2,0)),Inputs!$B$4:$B$100,$B12)/1000) | G12: =IF(G$3=0,"",SUMIFS(INDEX(Inputs!$D$4:$AG$100,0,MATCH(G$2,Inputs!$D$2:$AG$2,0)),Inputs!$B$4:$B$100,$B12)/1000) | H12: =IF(COUNT(D12:G12)=4,SUM(D12:G12),"") | I12: =IF(I$3=0,"",SUMIFS(INDEX(Inputs!$D$4:$AG$100,0,MATCH(I$2,Inputs!$D$2:$AG$2,0)),Inputs!$B$4:$B$100,$B12)/1000) | J12: =IF(J$3=0,"",SUMIFS(INDEX(Inputs!$D$4:$AG$100,0,MATCH(J$2,Inputs!$D$2:$AG$2,0)),Inputs!$B$4:$B$100,$B12)/1000) | K12: =IF(K$3=0,"",SUMIFS(INDEX(Inputs!$D$4:$AG$100,0,MATCH(K$2,Inputs!$D$2:$AG$2,0)),Inputs!$B$4:$B$100,$B12)/1000) | L12: =IF(L$3=0,"",SUMIFS(INDEX(Inputs!$D$4:$AG$100,0,MATCH(L$2,Inputs!$D$2:$AG$2,0)),Inputs!$B$4:$B$100,$B12)/1000) | M12: =IF(COUNT(I12:L12)=4,SUM(I12:L12),"") | N12: =IF(N$3=0,"",SUMIFS(INDEX(Inputs!$D$4:$AG$100,0,MATCH(N$2,Inputs!$D$2:$AG$2,0)),Inputs!$B$4:$B$100,$B12)/1000) | O12: =IF(O$3=0,"",SUMIFS(INDEX(Inputs!$D$4:$AG$100,0,MATCH(O$2,Inputs!$D$2:$AG$2,0)),Inputs!$B$4:$B$100,$B12)/1000) | P12: =IF(P$3=0,"",SUMIFS(INDEX(Inputs!$D$4:$AG$100,0,MATCH(P$2,Inputs!$D$2:$AG$2,0)),Inputs!$B$4:$B$100,$B12)/1000) | Q12: =IF(Q$3=0,"",SUMIFS(INDEX(Inputs!$D$4:$AG$100,0,MATCH(Q$2,Inputs!$D$2:$AG$2,0)),Inputs!$B$4:$B$100,$B12)/1000) | R12: =IF(COUNT(N12:Q12)=4,SUM(N12:Q12),"") | S12: =IF(S$3=0,"",SUMIFS(INDEX(Inputs!$D$4:$AG$100,0,MATCH(S$2,Inputs!$D$2:$AG$2,0)),Inputs!$B$4:$B$100,$B12)/1000) | T12: =IF(T$3=0,"",SUMIFS(INDEX(Inputs!$D$4:$AG$100,0,MATCH(T$2,Inputs!$D$2:$AG$2,0)),Inputs!$B$4:$B$100,$B12)/1000) | U12: =IF(U$3=0,"",SUMIFS(INDEX(Inputs!$D$4:$AG$100,0,MATCH(U$2,Inputs!$D$2:$AG$2,0)),Inputs!$B$4:$B$100,$B12)/1000) | V12: =IF(V$3=0,"",SUMIFS(INDEX(Inputs!$D$4:$AG$100,0,MATCH(V$2,Inputs!$D$2:$AG$2,0)),Inputs!$B$4:$B$100,$B12)/1000) | W12: =IF(COUNT(S12:V12)=4,SUM(S12:V12),"") | X12: =IF(X$3=0,"",SUMIFS(INDEX(Inputs!$D$4:$AG$100,0,MATCH(X$2,Inputs!$D$2:$AG$2,0)),Inputs!$B$4:$B$100,$B12)/1000) | Y12: =IF(Y$3=0,"",SUMIFS(INDEX(Inputs!$D$4:$AG$100,0,MATCH(Y$2,Inputs!$D$2:$AG$2,0)),Inputs!$B$4:$B$100,$B12)/1000) | Z12: =IF(Z$3=0,"",SUMIFS(INDEX(Inputs!$D$4:$AG$100,0,MATCH(Z$2,Inputs!$D$2:$AG$2,0)),Inputs!$B$4:$B$100,$B12)/1000) | AA12: =IF(AA$3=0,"",SUMIFS(INDEX(Inputs!$D$4:$AG$100,0,MATCH(AA$2,Inputs!$D$2:$AG$2,0)),Inputs!$B$4:$B$100,$B12)/1000) | AB12: =IF(COUNT(X12:AA12)=4,SUM(X12:AA12),"") | AC12: =IF(AC$3=0,"",SUMIFS(INDEX(Inputs!$D$4:$AG$100,0,MATCH(AC$2,Inputs!$D$2:$AG$2,0)),Inputs!$B$4:$B$100,$B12)/1000) | AD12: =IF(AD$3=0,"",SUMIFS(INDEX(Inputs!$D$4:$AG$100,0,MATCH(AD$2,Inputs!$D$2:$AG$2,0)),Inputs!$B$4:$B$100,$B12)/1000) | AE12: =IF(AE$3=0,"",SUMIFS(INDEX(Inputs!$D$4:$AG$100,0,MATCH(AE$2,Inputs!$D$2:$AG$2,0)),Inputs!$B$4:$B$100,$B12)/1000) | AF12: =IF(AF$3=0,"",SUMIFS(INDEX(Inputs!$D$4:$AG$100,0,MATCH(AF$2,Inputs!$D$2:$AG$2,0)),Inputs!$B$4:$B$100,$B12)/1000) | AG12: =IF(COUNT(AC12:AF12)=4,SUM(AC12:AF12),"")
B13: 10 | C13: Common Dividends | D13: =IF(D$3=0,"",SUMIFS(INDEX(Inputs!$D$4:$AG$100,0,MATCH(D$2,Inputs!$D$2:$AG$2,0)),Inputs!$B$4:$B$100,$B13)/1000) | E13: =IF(E$3=0,"",SUMIFS(INDEX(Inputs!$D$4:$AG$100,0,MATCH(E$2,Inputs!$D$2:$AG$2,0)),Inputs!$B$4:$B$100,$B13)/1000) | F13: =IF(F$3=0,"",SUMIFS(INDEX(Inputs!$D$4:$AG$100,0,MATCH(F$2,Inputs!$D$2:$AG$2,0)),Inputs!$B$4:$B$100,$B13)/1000) | G13: =IF(G$3=0,"",SUMIFS(INDEX(Inputs!$D$4:$AG$100,0,MATCH(G$2,Inputs!$D$2:$AG$2,0)),Inputs!$B$4:$B$100,$B13)/1000) | H13: =IF(COUNT(D13:G13)=4,SUM(D13:G13),"") | I13: =IF(I$3=0,"",SUMIFS(INDEX(Inputs!$D$4:$AG$100,0,MATCH(I$2,Inputs!$D$2:$AG$2,0)),Inputs!$B$4:$B$100,$B13)/1000) | J13: =IF(J$3=0,"",SUMIFS(INDEX(Inputs!$D$4:$AG$100,0,MATCH(J$2,Inputs!$D$2:$AG$2,0)),Inputs!$B$4:$B$100,$B13)/1000) | K13: =IF(K$3=0,"",SUMIFS(INDEX(Inputs!$D$4:$AG$100,0,MATCH(K$2,Inputs!$D$2:$AG$2,0)),Inputs!$B$4:$B$100,$B13)/1000) | L13: =IF(L$3=0,"",SUMIFS(INDEX(Inputs!$D$4:$AG$100,0,MATCH(L$2,Inputs!$D$2:$AG$2,0)),Inputs!$B$4:$B$100,$B13)/1000) | M13: =IF(COUNT(I13:L13)=4,SUM(I13:L13),"") | N13: =IF(N$3=0,"",SUMIFS(INDEX(Inputs!$D$4:$AG$100,0,MATCH(N$2,Inputs!$D$2:$AG$2,0)),Inputs!$B$4:$B$100,$B13)/1000) | O13: =IF(O$3=0,"",SUMIFS(INDEX(Inputs!$D$4:$AG$100,0,MATCH(O$2,Inputs!$D$2:$AG$2,0)),Inputs!$B$4:$B$100,$B13)/1000) | P13: =IF(P$3=0,"",SUMIFS(INDEX(Inputs!$D$4:$AG$100,0,MATCH(P$2,Inputs!$D$2:$AG$2,0)),Inputs!$B$4:$B$100,$B13)/1000) | Q13: =IF(Q$3=0,"",SUMIFS(INDEX(Inputs!$D$4:$AG$100,0,MATCH(Q$2,Inputs!$D$2:$AG$2,0)),Inputs!$B$4:$B$100,$B13)/1000) | R13: =IF(COUNT(N13:Q13)=4,SUM(N13:Q13),"") | S13: =IF(S$3=0,"",SUMIFS(INDEX(Inputs!$D$4:$AG$100,0,MATCH(S$2,Inputs!$D$2:$AG$2,0)),Inputs!$B$4:$B$100,$B13)/1000) | T13: =IF(T$3=0,"",SUMIFS(INDEX(Inputs!$D$4:$AG$100,0,MATCH(T$2,Inputs!$D$2:$AG$2,0)),Inputs!$B$4:$B$100,$B13)/1000) | U13: =IF(U$3=0,"",SUMIFS(INDEX(Inputs!$D$4:$AG$100,0,MATCH(U$2,Inputs!$D$2:$AG$2,0)),Inputs!$B$4:$B$100,$B13)/1000) | V13: =IF(V$3=0,"",SUMIFS(INDEX(Inputs!$D$4:$AG$100,0,MATCH(V$2,Inputs!$D$2:$AG$2,0)),Inputs!$B$4:$B$100,$B13)/1000) | W13: =IF(COUNT(S13:V13)=4,SUM(S13:V13),"") | X13: =IF(X$3=0,"",SUMIFS(INDEX(Inputs!$D$4:$AG$100,0,MATCH(X$2,Inputs!$D$2:$AG$2,0)),Inputs!$B$4:$B$100,$B13)/1000) | Y13: =IF(Y$3=0,"",SUMIFS(INDEX(Inputs!$D$4:$AG$100,0,MATCH(Y$2,Inputs!$D$2:$AG$2,0)),Inputs!$B$4:$B$100,$B13)/1000) | Z13: =IF(Z$3=0,"",SUMIFS(INDEX(Inputs!$D$4:$AG$100,0,MATCH(Z$2,Inputs!$D$2:$AG$2,0)),Inputs!$B$4:$B$100,$B13)/1000) | AA13: =IF(AA$3=0,"",SUMIFS(INDEX(Inputs!$D$4:$AG$100,0,MATCH(AA$2,Inputs!$D$2:$AG$2,0)),Inputs!$B$4:$B$100,$B13)/1000) | AB13: =IF(COUNT(X13:AA13)=4,SUM(X13:AA13),"") | AC13: =IF(AC$3=0,"",SUMIFS(INDEX(Inputs!$D$4:$AG$100,0,MATCH(AC$2,Inputs!$D$2:$AG$2,0)),Inputs!$B$4:$B$100,$B13)/1000) | AD13: =IF(AD$3=0,"",SUMIFS(INDEX(Inputs!$D$4:$AG$100,0,MATCH(AD$2,Inputs!$D$2:$AG$2,0)),Inputs!$B$4:$B$100,$B13)/1000) | AE13: =IF(AE$3=0,"",SUMIFS(INDEX(Inputs!$D$4:$AG$100,0,MATCH(AE$2,Inputs!$D$2:$AG$2,0)),Inputs!$B$4:$B$100,$B13)/1000) | AF13: =IF(AF$3=0,"",SUMIFS(INDEX(Inputs!$D$4:$AG$100,0,MATCH(AF$2,Inputs!$D$2:$AG$2,0)),Inputs!$B$4:$B$100,$B13)/1000) | AG13: =IF(COUNT(AC13:AF13)=4,SUM(AC13:AF13),"")
B15: 11 | C15: Cash and equivalents (inc. investment securities) | D15: =IF(D$3=0,"",SUMIFS(INDEX(Inputs!$D$4:$AG$100,0,MATCH(D$2,Inputs!$D$2:$AG$2,0)),Inputs!$B$4:$B$100,$B15)/1000) | E15: =IF(E$3=0,"",SUMIFS(INDEX(Inputs!$D$4:$AG$100,0,MATCH(E$2,Inputs!$D$2:$AG$2,0)),Inputs!$B$4:$B$100,$B15)/1000) | F15: =IF(F$3=0,"",SUMIFS(INDEX(Inputs!$D$4:$AG$100,0,MATCH(F$2,Inputs!$D$2:$AG$2,0)),Inputs!$B$4:$B$100,$B15)/1000) | G15: =IF(G$3=0,"",SUMIFS(INDEX(Inputs!$D$4:$AG$100,0,MATCH(G$2,Inputs!$D$2:$AG$2,0)),Inputs!$B$4:$B$100,$B15)/1000) | H15: =IF(G15="","",G15) | I15: =IF(I$3=0,"",SUMIFS(INDEX(Inputs!$D$4:$AG$100,0,MATCH(I$2,Inputs!$D$2:$AG$2,0)),Inputs!$B$4:$B$100,$B15)/1000) | J15: =IF(J$3=0,"",SUMIFS(INDEX(Inputs!$D$4:$AG$100,0,MATCH(J$2,Inputs!$D$2:$AG$2,0)),Inputs!$B$4:$B$100,$B15)/1000) | K15: =IF(K$3=0,"",SUMIFS(INDEX(Inputs!$D$4:$AG$100,0,MATCH(K$2,Inputs!$D$2:$AG$2,0)),Inputs!$B$4:$B$100,$B15)/1000) | L15: =IF(L$3=0,"",SUMIFS(INDEX(Inputs!$D$4:$AG$100,0,MATCH(L$2,Inputs!$D$2:$AG$2,0)),Inputs!$B$4:$B$100,$B15)/1000) | M15: =IF(L15="","",L15) | N15: =IF(N$3=0,"",SUMIFS(INDEX(Inputs!$D$4:$AG$100,0,MATCH(N$2,Inputs!$D$2:$AG$2,0)),Inputs!$B$4:$B$100,$B15)/1000) | O15: =IF(O$3=0,"",SUMIFS(INDEX(Inputs!$D$4:$AG$100,0,MATCH(O$2,Inputs!$D$2:$AG$2,0)),Inputs!$B$4:$B$100,$B15)/1000) | P15: =IF(P$3=0,"",SUMIFS(INDEX(Inputs!$D$4:$AG$100,0,MATCH(P$2,Inputs!$D$2:$AG$2,0)),Inputs!$B$4:$B$100,$B15)/1000) | Q15: =IF(Q$3=0,"",SUMIFS(INDEX(Inputs!$D$4:$AG$100,0,MATCH(Q$2,Inputs!$D$2:$AG$2,0)),Inputs!$B$4:$B$100,$B15)/1000) | R15: =IF(Q15="","",Q15) | S15: =IF(S$3=0,"",SUMIFS(INDEX(Inputs!$D$4:$AG$100,0,MATCH(S$2,Inputs!$D$2:$AG$2,0)),Inputs!$B$4:$B$100,$B15)/1000) | T15: =IF(T$3=0,"",SUMIFS(INDEX(Inputs!$D$4:$AG$100,0,MATCH(T$2,Inputs!$D$2:$AG$2,0)),Inputs!$B$4:$B$100,$B15)/1000) | U15: =IF(U$3=0,"",SUMIFS(INDEX(Inputs!$D$4:$AG$100,0,MATCH(U$2,Inputs!$D$2:$AG$2,0)),Inputs!$B$4:$B$100,$B15)/1000) | V15: =IF(V$3=0,"",SUMIFS(INDEX(Inputs!$D$4:$AG$100,0,MATCH(V$2,Inputs!$D$2:$AG$2,0)),Inputs!$B$4:$B$100,$B15)/1000) | W15: =IF(V15="","",V15) | X15: =IF(X$3=0,"",SUMIFS(INDEX(Inputs!$D$4:$AG$100,0,MATCH(X$2,Inputs!$D$2:$AG$2,0)),Inputs!$B$4:$B$100,$B15)/1000) | Y15: =IF(Y$3=0,"",SUMIFS(INDEX(Inputs!$D$4:$AG$100,0,MATCH(Y$2,Inputs!$D$2:$AG$2,0)),Inputs!$B$4:$B$100,$B15)/1000) | Z15: =IF(Z$3=0,"",SUMIFS(INDEX(Inputs!$D$4:$AG$100,0,MATCH(Z$2,Inputs!$D$2:$AG$2,0)),Inputs!$B$4:$B$100,$B15)/1000) | AA15: =IF(AA$3=0,"",SUMIFS(INDEX(Inputs!$D$4:$AG$100,0,MATCH(AA$2,Inputs!$D$2:$AG$2,0)),Inputs!$B$4:$B$100,$B15)/1000) | AB15: =IF(AA15="","",AA15) | AC15: =IF(AC$3=0,"",SUMIFS(INDEX(Inputs!$D$4:$AG$100,0,MATCH(AC$2,Inputs!$D$2:$AG$2,0)),Inputs!$B$4:$B$100,$B15)/1000) | AD15: =IF(AD$3=0,"",SUMIFS(INDEX(Inputs!$D$4:$AG$100,0,MATCH(AD$2,Inputs!$D$2:$AG$2,0)),Inputs!$B$4:$B$100,$B15)/1000) | AE15: =IF(AE$3=0,"",SUMIFS(INDEX(Inputs!$D$4:$AG$100,0,MATCH(AE$2,Inputs!$D$2:$AG$2,0)),Inputs!$B$4:$B$100,$B15)/1000) | AF15: =IF(AF$3=0,"",SUMIFS(INDEX(Inputs!$D$4:$AG$100,0,MATCH(AF$2,Inputs!$D$2:$AG$2,0)),Inputs!$B$4:$B$100,$B15)/1000) | AG15: =IF(AF15="","",AF15)
B16: 12 | C16: Accounts receivable | D16: =IF(D$3=0,"",SUMIFS(INDEX(Inputs!$D$4:$AG$100,0,MATCH(D$2,Inputs!$D$2:$AG$2,0)),Inputs!$B$4:$B$100,$B16)/1000) | E16: =IF(E$3=0,"",SUMIFS(INDEX(Inputs!$D$4:$AG$100,0,MATCH(E$2,Inputs!$D$2:$AG$2,0)),Inputs!$B$4:$B$100,$B16)/1000) | F16: =IF(F$3=0,"",SUMIFS(INDEX(Inputs!$D$4:$AG$100,0,MATCH(F$2,Inputs!$D$2:$AG$2,0)),Inputs!$B$4:$B$100,$B16)/1000) | G16: =IF(G$3=0,"",SUMIFS(INDEX(Inputs!$D$4:$AG$100,0,MATCH(G$2,Inputs!$D$2:$AG$2,0)),Inputs!$B$4:$B$100,$B16)/1000) | H16: =IF(G16="","",G16) | I16: =IF(I$3=0,"",SUMIFS(INDEX(Inputs!$D$4:$AG$100,0,MATCH(I$2,Inputs!$D$2:$AG$2,0)),Inputs!$B$4:$B$100,$B16)/1000) | J16: =IF(J$3=0,"",SUMIFS(INDEX(Inputs!$D$4:$AG$100,0,MATCH(J$2,Inputs!$D$2:$AG$2,0)),Inputs!$B$4:$B$100,$B16)/1000) | K16: =IF(K$3=0,"",SUMIFS(INDEX(Inputs!$D$4:$AG$100,0,MATCH(K$2,Inputs!$D$2:$AG$2,0)),Inputs!$B$4:$B$100,$B16)/1000) | L16: =IF(L$3=0,"",SUMIFS(INDEX(Inputs!$D$4:$AG$100,0,MATCH(L$2,Inputs!$D$2:$AG$2,0)),Inputs!$B$4:$B$100,$B16)/1000) | M16: =IF(L16="","",L16) | N16: =IF(N$3=0,"",SUMIFS(INDEX(Inputs!$D$4:$AG$100,0,MATCH(N$2,Inputs!$D$2:$AG$2,0)),Inputs!$B$4:$B$100,$B16)/1000) | O16: =IF(O$3=0,"",SUMIFS(INDEX(Inputs!$D$4:$AG$100,0,MATCH(O$2,Inputs!$D$2:$AG$2,0)),Inputs!$B$4:$B$100,$B16)/1000) | P16: =IF(P$3=0,"",SUMIFS(INDEX(Inputs!$D$4:$AG$100,0,MATCH(P$2,Inputs!$D$2:$AG$2,0)),Inputs!$B$4:$B$100,$B16)/1000) | Q16: =IF(Q$3=0,"",SUMIFS(INDEX(Inputs!$D$4:$AG$100,0,MATCH(Q$2,Inputs!$D$2:$AG$2,0)),Inputs!$B$4:$B$100,$B16)/1000) | R16: =IF(Q16="","",Q16) | S16: =IF(S$3=0,"",SUMIFS(INDEX(Inputs!$D$4:$AG$100,0,MATCH(S$2,Inputs!$D$2:$AG$2,0)),Inputs!$B$4:$B$100,$B16)/1000) | T16: =IF(T$3=0,"",SUMIFS(INDEX(Inputs!$D$4:$AG$100,0,MATCH(T$2,Inputs!$D$2:$AG$2,0)),Inputs!$B$4:$B$100,$B16)/1000) | U16: =IF(U$3=0,"",SUMIFS(INDEX(Inputs!$D$4:$AG$100,0,MATCH(U$2,Inputs!$D$2:$AG$2,0)),Inputs!$B$4:$B$100,$B16)/1000) | V16: =IF(V$3=0,"",SUMIFS(INDEX(Inputs!$D$4:$AG$100,0,MATCH(V$2,Inputs!$D$2:$AG$2,0)),Inputs!$B$4:$B$100,$B16)/1000) | W16: =IF(V16="","",V16) | X16: =IF(X$3=0,"",SUMIFS(INDEX(Inputs!$D$4:$AG$100,0,MATCH(X$2,Inputs!$D$2:$AG$2,0)),Inputs!$B$4:$B$100,$B16)/1000) | Y16: =IF(Y$3=0,"",SUMIFS(INDEX(Inputs!$D$4:$AG$100,0,MATCH(Y$2,Inputs!$D$2:$AG$2,0)),Inputs!$B$4:$B$100,$B16)/1000) | Z16: =IF(Z$3=0,"",SUMIFS(INDEX(Inputs!$D$4:$AG$100,0,MATCH(Z$2,Inputs!$D$2:$AG$2,0)),Inputs!$B$4:$B$100,$B16)/1000) | AA16: =IF(AA$3=0,"",SUMIFS(INDEX(Inputs!$D$4:$AG$100,0,MATCH(AA$2,Inputs!$D$2:$AG$2,0)),Inputs!$B$4:$B$100,$B16)/1000) | AB16: =IF(AA16="","",AA16) | AC16: =IF(AC$3=0,"",SUMIFS(INDEX(Inputs!$D$4:$AG$100,0,MATCH(AC$2,Inputs!$D$2:$AG$2,0)),Inputs!$B$4:$B$100,$B16)/1000) | AD16: =IF(AD$3=0,"",SUMIFS(INDEX(Inputs!$D$4:$AG$100,0,MATCH(AD$2,Inputs!$D$2:$AG$2,0)),Inputs!$B$4:$B$100,$B16)/1000) | AE16: =IF(AE$3=0,"",SUMIFS(INDEX(Inputs!$D$4:$AG$100,0,MATCH(AE$2,Inputs!$D$2:$AG$2,0)),Inputs!$B$4:$B$100,$B16)/1000) | AF16: =IF(AF$3=0,"",SUMIFS(INDEX(Inputs!$D$4:$AG$100,0,MATCH(AF$2,Inputs!$D$2:$AG$2,0)),Inputs!$B$4:$B$100,$B16)/1000) | AG16: =IF(AF16="","",AF16)
B17: 13 | C17: Inventories | D17: =IF(D$3=0,"",SUMIFS(INDEX(Inputs!$D$4:$AG$100,0,MATCH(D$2,Inputs!$D$2:$AG$2,0)),Inputs!$B$4:$B$100,$B17)/1000) | E17: =IF(E$3=0,"",SUMIFS(INDEX(Inputs!$D$4:$AG$100,0,MATCH(E$2,Inputs!$D$2:$AG$2,0)),Inputs!$B$4:$B$100,$B17)/1000) | F17: =IF(F$3=0,"",SUMIFS(INDEX(Inputs!$D$4:$AG$100,0,MATCH(F$2,Inputs!$D$2:$AG$2,0)),Inputs!$B$4:$B$100,$B17)/1000) | G17: =IF(G$3=0,"",SUMIFS(INDEX(Inputs!$D$4:$AG$100,0,MATCH(G$2,Inputs!$D$2:$AG$2,0)),Inputs!$B$4:$B$100,$B17)/1000) | H17: =IF(G17="","",G17) | I17: =IF(I$3=0,"",SUMIFS(INDEX(Inputs!$D$4:$AG$100,0,MATCH(I$2,Inputs!$D$2:$AG$2,0)),Inputs!$B$4:$B$100,$B17)/1000) | J17: =IF(J$3=0,"",SUMIFS(INDEX(Inputs!$D$4:$AG$100,0,MATCH(J$2,Inputs!$D$2:$AG$2,0)),Inputs!$B$4:$B$100,$B17)/1000) | K17: =IF(K$3=0,"",SUMIFS(INDEX(Inputs!$D$4:$AG$100,0,MATCH(K$2,Inputs!$D$2:$AG$2,0)),Inputs!$B$4:$B$100,$B17)/1000) | L17: =IF(L$3=0,"",SUMIFS(INDEX(Inputs!$D$4:$AG$100,0,MATCH(L$2,Inputs!$D$2:$AG$2,0)),Inputs!$B$4:$B$100,$B17)/1000) | M17: =IF(L17="","",L17) | N17: =IF(N$3=0,"",SUMIFS(INDEX(Inputs!$D$4:$AG$100,0,MATCH(N$2,Inputs!$D$2:$AG$2,0)),Inputs!$B$4:$B$100,$B17)/1000) | O17: =IF(O$3=0,"",SUMIFS(INDEX(Inputs!$D$4:$AG$100,0,MATCH(O$2,Inputs!$D$2:$AG$2,0)),Inputs!$B$4:$B$100,$B17)/1000) | P17: =IF(P$3=0,"",SUMIFS(INDEX(Inputs!$D$4:$AG$100,0,MATCH(P$2,Inputs!$D$2:$AG$2,0)),Inputs!$B$4:$B$100,$B17)/1000) | Q17: =IF(Q$3=0,"",SUMIFS(INDEX(Inputs!$D$4:$AG$100,0,MATCH(Q$2,Inputs!$D$2:$AG$2,0)),Inputs!$B$4:$B$100,$B17)/1000) | R17: =IF(Q17="","",Q17) | S17: =IF(S$3=0,"",SUMIFS(INDEX(Inputs!$D$4:$AG$100,0,MATCH(S$2,Inputs!$D$2:$AG$2,0)),Inputs!$B$4:$B$100,$B17)/1000) | T17: =IF(T$3=0,"",SUMIFS(INDEX(Inputs!$D$4:$AG$100,0,MATCH(T$2,Inputs!$D$2:$AG$2,0)),Inputs!$B$4:$B$100,$B17)/1000) | U17: =IF(U$3=0,"",SUMIFS(INDEX(Inputs!$D$4:$AG$100,0,MATCH(U$2,Inputs!$D$2:$AG$2,0)),Inputs!$B$4:$B$100,$B17)/1000) | V17: =IF(V$3=0,"",SUMIFS(INDEX(Inputs!$D$4:$AG$100,0,MATCH(V$2,Inputs!$D$2:$AG$2,0)),Inputs!$B$4:$B$100,$B17)/1000) | W17: =IF(V17="","",V17) | X17: =IF(X$3=0,"",SUMIFS(INDEX(Inputs!$D$4:$AG$100,0,MATCH(X$2,Inputs!$D$2:$AG$2,0)),Inputs!$B$4:$B$100,$B17)/1000) | Y17: =IF(Y$3=0,"",SUMIFS(INDEX(Inputs!$D$4:$AG$100,0,MATCH(Y$2,Inputs!$D$2:$AG$2,0)),Inputs!$B$4:$B$100,$B17)/1000) | Z17: =IF(Z$3=0,"",SUMIFS(INDEX(Inputs!$D$4:$AG$100,0,MATCH(Z$2,Inputs!$D$2:$AG$2,0)),Inputs!$B$4:$B$100,$B17)/1000) | AA17: =IF(AA$3=0,"",SUMIFS(INDEX(Inputs!$D$4:$AG$100,0,MATCH(AA$2,Inputs!$D$2:$AG$2,0)),Inputs!$B$4:$B$100,$B17)/1000) | AB17: =IF(AA17="","",AA17) | AC17: =IF(AC$3=0,"",SUMIFS(INDEX(Inputs!$D$4:$AG$100,0,MATCH(AC$2,Inputs!$D$2:$AG$2,0)),Inputs!$B$4:$B$100,$B17)/1000) | AD17: =IF(AD$3=0,"",SUMIFS(INDEX(Inputs!$D$4:$AG$100,0,MATCH(AD$2,Inputs!$D$2:$AG$2,0)),Inputs!$B$4:$B$100,$B17)/1000) | AE17: =IF(AE$3=0,"",SUMIFS(INDEX(Inputs!$D$4:$AG$100,0,MATCH(AE$2,Inputs!$D$2:$AG$2,0)),Inputs!$B$4:$B$100,$B17)/1000) | AF17: =IF(AF$3=0,"",SUMIFS(INDEX(Inputs!$D$4:$AG$100,0,MATCH(AF$2,Inputs!$D$2:$AG$2,0)),Inputs!$B$4:$B$100,$B17)/1000) | AG17: =IF(AF17="","",AF17)
B18: 14 | C18: Deferred income taxes | D18: =IF(D$3=0,"",SUMIFS(INDEX(Inputs!$D$4:$AG$100,0,MATCH(D$2,Inputs!$D$2:$AG$2,0)),Inputs!$B$4:$B$100,$B18)/1000) | E18: =IF(E$3=0,"",SUMIFS(INDEX(Inputs!$D$4:$AG$100,0,MATCH(E$2,Inputs!$D$2:$AG$2,0)),Inputs!$B$4:$B$100,$B18)/1000) | F18: =IF(F$3=0,"",SUMIFS(INDEX(Inputs!$D$4:$AG$100,0,MATCH(F$2,Inputs!$D$2:$AG$2,0)),Inputs!$B$4:$B$100,$B18)/1000) | G18: =IF(G$3=0,"",SUMIFS(INDEX(Inputs!$D$4:$AG$100,0,MATCH(G$2,Inputs!$D$2:$AG$2,0)),Inputs!$B$4:$B$100,$B18)/1000) | H18: =IF(G18="","",G18) | I18: =IF(I$3=0,"",SUMIFS(INDEX(Inputs!$D$4:$AG$100,0,MATCH(I$2,Inputs!$D$2:$AG$2,0)),Inputs!$B$4:$B$100,$B18)/1000) | J18: =IF(J$3=0,"",SUMIFS(INDEX(Inputs!$D$4:$AG$100,0,MATCH(J$2,Inputs!$D$2:$AG$2,0)),Inputs!$B$4:$B$100,$B18)/1000) | K18: =IF(K$3=0,"",SUMIFS(INDEX(Inputs!$D$4:$AG$100,0,MATCH(K$2,Inputs!$D$2:$AG$2,0)),Inputs!$B$4:$B$100,$B18)/1000) | L18: =IF(L$3=0,"",SUMIFS(INDEX(Inputs!$D$4:$AG$100,0,MATCH(L$2,Inputs!$D$2:$AG$2,0)),Inputs!$B$4:$B$100,$B18)/1000) | M18: =IF(L18="","",L18) | N18: =IF(N$3=0,"",SUMIFS(INDEX(Inputs!$D$4:$AG$100,0,MATCH(N$2,Inputs!$D$2:$AG$2,0)),Inputs!$B$4:$B$100,$B18)/1000) | O18: =IF(O$3=0,"",SUMIFS(INDEX(Inputs!$D$4:$AG$100,0,MATCH(O$2,Inputs!$D$2:$AG$2,0)),Inputs!$B$4:$B$100,$B18)/1000) | P18: =IF(P$3=0,"",SUMIFS(INDEX(Inputs!$D$4:$AG$100,0,MATCH(P$2,Inputs!$D$2:$AG$2,0)),Inputs!$B$4:$B$100,$B18)/1000) | Q18: =IF(Q$3=0,"",SUMIFS(INDEX(Inputs!$D$4:$AG$100,0,MATCH(Q$2,Inputs!$D$2:$AG$2,0)),Inputs!$B$4:$B$100,$B18)/1000) | R18: =IF(Q18="","",Q18) | S18: =IF(S$3=0,"",SUMIFS(INDEX(Inputs!$D$4:$AG$100,0,MATCH(S$2,Inputs!$D$2:$AG$2,0)),Inputs!$B$4:$B$100,$B18)/1000) | T18: =IF(T$3=0,"",SUMIFS(INDEX(Inputs!$D$4:$AG$100,0,MATCH(T$2,Inputs!$D$2:$AG$2,0)),Inputs!$B$4:$B$100,$B18)/1000) | U18: =IF(U$3=0,"",SUMIFS(INDEX(Inputs!$D$4:$AG$100,0,MATCH(U$2,Inputs!$D$2:$AG$2,0)),Inputs!$B$4:$B$100,$B18)/1000) | V18: =IF(V$3=0,"",SUMIFS(INDEX(Inputs!$D$4:$AG$100,0,MATCH(V$2,Inputs!$D$2:$AG$2,0)),Inputs!$B$4:$B$100,$B18)/1000) | W18: =IF(V18="","",V18) | X18: =IF(X$3=0,"",SUMIFS(INDEX(Inputs!$D$4:$AG$100,0,MATCH(X$2,Inputs!$D$2:$AG$2,0)),Inputs!$B$4:$B$100,$B18)/1000) | Y18: =IF(Y$3=0,"",SUMIFS(INDEX(Inputs!$D$4:$AG$100,0,MATCH(Y$2,Inputs!$D$2:$AG$2,0)),Inputs!$B$4:$B$100,$B18)/1000) | Z18: =IF(Z$3=0,"",SUMIFS(INDEX(Inputs!$D$4:$AG$100,0,MATCH(Z$2,Inputs!$D$2:$AG$2,0)),Inputs!$B$4:$B$100,$B18)/1000) | AA18: =IF(AA$3=0,"",SUMIFS(INDEX(Inputs!$D$4:$AG$100,0,MATCH(AA$2,Inputs!$D$2:$AG$2,0)),Inputs!$B$4:$B$100,$B18)/1000) | AB18: =IF(AA18="","",AA18) | AC18: =IF(AC$3=0,"",SUMIFS(INDEX(Inputs!$D$4:$AG$100,0,MATCH(AC$2,Inputs!$D$2:$AG$2,0)),Inputs!$B$4:$B$100,$B18)/1000) | AD18: =IF(AD$3=0,"",SUMIFS(INDEX(Inputs!$D$4:$AG$100,0,MATCH(AD$2,Inputs!$D$2:$AG$2,0)),Inputs!$B$4:$B$100,$B18)/1000) | AE18: =IF(AE$3=0,"",SUMIFS(INDEX(Inputs!$D$4:$AG$100,0,MATCH(AE$2,Inputs!$D$2:$AG$2,0)),Inputs!$B$4:$B$100,$B18)/1000) | AF18: =IF(AF$3=0,"",SUMIFS(INDEX(Inputs!$D$4:$AG$100,0,MATCH(AF$2,Inputs!$D$2:$AG$2,0)),Inputs!$B$4:$B$100,$B18)/1000) | AG18: =IF(AF18="","",AF18)
B19: 15 | C19: Prepaid expenses | D19: =IF(D$3=0,"",SUMIFS(INDEX(Inputs!$D$4:$AG$100,0,MATCH(D$2,Inputs!$D$2:$AG$2,0)),Inputs!$B$4:$B$100,$B19)/1000) | E19: =IF(E$3=0,"",SUMIFS(INDEX(Inputs!$D$4:$AG$100,0,MATCH(E$2,Inputs!$D$2:$AG$2,0)),Inputs!$B$4:$B$100,$B19)/1000) | F19: =IF(F$3=0,"",SUMIFS(INDEX(Inputs!$D$4:$AG$100,0,MATCH(F$2,Inputs!$D$2:$AG$2,0)),Inputs!$B$4:$B$100,$B19)/1000) | G19: =IF(G$3=0,"",SUMIFS(INDEX(Inputs!$D$4:$AG$100,0,MATCH(G$2,Inputs!$D$2:$AG$2,0)),Inputs!$B$4:$B$100,$B19)/1000) | H19: =IF(G19="","",G19) | I19: =IF(I$3=0,"",SUMIFS(INDEX(Inputs!$D$4:$AG$100,0,MATCH(I$2,Inputs!$D$2:$AG$2,0)),Inputs!$B$4:$B$100,$B19)/1000) | J19: =IF(J$3=0,"",SUMIFS(INDEX(Inputs!$D$4:$AG$100,0,MATCH(J$2,Inputs!$D$2:$AG$2,0)),Inputs!$B$4:$B$100,$B19)/1000) | K19: =IF(K$3=0,"",SUMIFS(INDEX(Inputs!$D$4:$AG$100,0,MATCH(K$2,Inputs!$D$2:$AG$2,0)),Inputs!$B$4:$B$100,$B19)/1000) | L19: =IF(L$3=0,"",SUMIFS(INDEX(Inputs!$D$4:$AG$100,0,MATCH(L$2,Inputs!$D$2:$AG$2,0)),Inputs!$B$4:$B$100,$B19)/1000) | M19: =IF(L19="","",L19) | N19: =IF(N$3=0,"",SUMIFS(INDEX(Inputs!$D$4:$AG$100,0,MATCH(N$2,Inputs!$D$2:$AG$2,0)),Inputs!$B$4:$B$100,$B19)/1000) | O19: =IF(O$3=0,"",SUMIFS(INDEX(Inputs!$D$4:$AG$100,0,MATCH(O$2,Inputs!$D$2:$AG$2,0)),Inputs!$B$4:$B$100,$B19)/1000) | P19: =IF(P$3=0,"",SUMIFS(INDEX(Inputs!$D$4:$AG$100,0,MATCH(P$2,Inputs!$D$2:$AG$2,0)),Inputs!$B$4:$B$100,$B19)/1000) | Q19: =IF(Q$3=0,"",SUMIFS(INDEX(Inputs!$D$4:$AG$100,0,MATCH(Q$2,Inputs!$D$2:$AG$2,0)),Inputs!$B$4:$B$100,$B19)/1000) | R19: =IF(Q19="","",Q19) | S19: =IF(S$3=0,"",SUMIFS(INDEX(Inputs!$D$4:$AG$100,0,MATCH(S$2,Inputs!$D$2:$AG$2,0)),Inputs!$B$4:$B$100,$B19)/1000) | T19: =IF(T$3=0,"",SUMIFS(INDEX(Inputs!$D$4:$AG$100,0,MATCH(T$2,Inputs!$D$2:$AG$2,0)),Inputs!$B$4:$B$100,$B19)/1000) | U19: =IF(U$3=0,"",SUMIFS(INDEX(Inputs!$D$4:$AG$100,0,MATCH(U$2,Inputs!$D$2:$AG$2,0)),Inputs!$B$4:$B$100,$B19)/1000) | V19: =IF(V$3=0,"",SUMIFS(INDEX(Inputs!$D$4:$AG$100,0,MATCH(V$2,Inputs!$D$2:$AG$2,0)),Inputs!$B$4:$B$100,$B19)/1000) | W19: =IF(V19="","",V19) | X19: =IF(X$3=0,"",SUMIFS(INDEX(Inputs!$D$4:$AG$100,0,MATCH(X$2,Inputs!$D$2:$AG$2,0)),Inputs!$B$4:$B$100,$B19)/1000) | Y19: =IF(Y$3=0,"",SUMIFS(INDEX(Inputs!$D$4:$AG$100,0,MATCH(Y$2,Inputs!$D$2:$AG$2,0)),Inputs!$B$4:$B$100,$B19)/1000) | Z19: =IF(Z$3=0,"",SUMIFS(INDEX(Inputs!$D$4:$AG$100,0,MATCH(Z$2,Inputs!$D$2:$AG$2,0)),Inputs!$B$4:$B$100,$B19)/1000) | AA19: =IF(AA$3=0,"",SUMIFS(INDEX(Inputs!$D$4:$AG$100,0,MATCH(AA$2,Inputs!$D$2:$AG$2,0)),Inputs!$B$4:$B$100,$B19)/1000) | AB19: =IF(AA19="","",AA19) | AC19: =IF(AC$3=0,"",SUMIFS(INDEX(Inputs!$D$4:$AG$100,0,MATCH(AC$2,Inputs!$D$2:$AG$2,0)),Inputs!$B$4:$B$100,$B19)/1000) | AD19: =IF(AD$3=0,"",SUMIFS(INDEX(Inputs!$D$4:$AG$100,0,MATCH(AD$2,Inputs!$D$2:$AG$2,0)),Inputs!$B$4:$B$100,$B19)/1000) | AE19: =IF(AE$3=0,"",SUMIFS(INDEX(Inputs!$D$4:$AG$100,0,MATCH(AE$2,Inputs!$D$2:$AG$2,0)),Inputs!$B$4:$B$100,$B19)/1000) | AF19: =IF(AF$3=0,"",SUMIFS(INDEX(Inputs!$D$4:$AG$100,0,MATCH(AF$2,Inputs!$D$2:$AG$2,0)),Inputs!$B$4:$B$100,$B19)/1000) | AG19: =IF(AF19="","",AF19)
B20: 16 | C20: Other current assets | D20: =IF(D$3=0,"",SUMIFS(INDEX(Inputs!$D$4:$AG$100,0,MATCH(D$2,Inputs!$D$2:$AG$2,0)),Inputs!$B$4:$B$100,$B20)/1000) | E20: =IF(E$3=0,"",SUMIFS(INDEX(Inputs!$D$4:$AG$100,0,MATCH(E$2,Inputs!$D$2:$AG$2,0)),Inputs!$B$4:$B$100,$B20)/1000) | F20: =IF(F$3=0,"",SUMIFS(INDEX(Inputs!$D$4:$AG$100,0,MATCH(F$2,Inputs!$D$2:$AG$2,0)),Inputs!$B$4:$B$100,$B20)/1000) | G20: =IF(G$3=0,"",SUMIFS(INDEX(Inputs!$D$4:$AG$100,0,MATCH(G$2,Inputs!$D$2:$AG$2,0)),Inputs!$B$4:$B$100,$B20)/1000) | H20: =IF(G20="","",G20) | I20: =IF(I$3=0,"",SUMIFS(INDEX(Inputs!$D$4:$AG$100,0,MATCH(I$2,Inputs!$D$2:$AG$2,0)),Inputs!$B$4:$B$100,$B20)/1000) | J20: =IF(J$3=0,"",SUMIFS(INDEX(Inputs!$D$4:$AG$100,0,MATCH(J$2,Inputs!$D$2:$AG$2,0)),Inputs!$B$4:$B$100,$B20)/1000) | K20: =IF(K$3=0,"",SUMIFS(INDEX(Inputs!$D$4:$AG$100,0,MATCH(K$2,Inputs!$D$2:$AG$2,0)),Inputs!$B$4:$B$100,$B20)/1000) | L20: =IF(L$3=0,"",SUMIFS(INDEX(Inputs!$D$4:$AG$100,0,MATCH(L$2,Inputs!$D$2:$AG$2,0)),Inputs!$B$4:$B$100,$B20)/1000) | M20: =IF(L20="","",L20) | N20: =IF(N$3=0,"",SUMIFS(INDEX(Inputs!$D$4:$AG$100,0,MATCH(N$2,Inputs!$D$2:$AG$2,0)),Inputs!$B$4:$B$100,$B20)/1000) | O20: =IF(O$3=0,"",SUMIFS(INDEX(Inputs!$D$4:$AG$100,0,MATCH(O$2,Inputs!$D$2:$AG$2,0)),Inputs!$B$4:$B$100,$B20)/1000) | P20: =IF(P$3=0,"",SUMIFS(INDEX(Inputs!$D$4:$AG$100,0,MATCH(P$2,Inputs!$D$2:$AG$2,0)),Inputs!$B$4:$B$100,$B20)/1000) | Q20: =IF(Q$3=0,"",SUMIFS(INDEX(Inputs!$D$4:$AG$100,0,MATCH(Q$2,Inputs!$D$2:$AG$2,0)),Inputs!$B$4:$B$100,$B20)/1000) | R20: =IF(Q20="","",Q20) | S20: =IF(S$3=0,"",SUMIFS(INDEX(Inputs!$D$4:$AG$100,0,MATCH(S$2,Inputs!$D$2:$AG$2,0)),Inputs!$B$4:$B$100,$B20)/1000) | T20: =IF(T$3=0,"",SUMIFS(INDEX(Inputs!$D$4:$AG$100,0,MATCH(T$2,Inputs!$D$2:$AG$2,0)),Inputs!$B$4:$B$100,$B20)/1000) | U20: =IF(U$3=0,"",SUMIFS(INDEX(Inputs!$D$4:$AG$100,0,MATCH(U$2,Inputs!$D$2:$AG$2,0)),Inputs!$B$4:$B$100,$B20)/1000) | V20: =IF(V$3=0,"",SUMIFS(INDEX(Inputs!$D$4:$AG$100,0,MATCH(V$2,Inputs!$D$2:$AG$2,0)),Inputs!$B$4:$B$100,$B20)/1000) | W20: =IF(V20="","",V20) | X20: =IF(X$3=0,"",SUMIFS(INDEX(Inputs!$D$4:$AG$100,0,MATCH(X$2,Inputs!$D$2:$AG$2,0)),Inputs!$B$4:$B$100,$B20)/1000) | Y20: =IF(Y$3=0,"",SUMIFS(INDEX(Inputs!$D$4:$AG$100,0,MATCH(Y$2,Inputs!$D$2:$AG$2,0)),Inputs!$B$4:$B$100,$B20)/1000) | Z20: =IF(Z$3=0,"",SUMIFS(INDEX(Inputs!$D$4:$AG$100,0,MATCH(Z$2,Inputs!$D$2:$AG$2,0)),Inputs!$B$4:$B$100,$B20)/1000) | AA20: =IF(AA$3=0,"",SUMIFS(INDEX(Inputs!$D$4:$AG$100,0,MATCH(AA$2,Inputs!$D$2:$AG$2,0)),Inputs!$B$4:$B$100,$B20)/1000) | AB20: =IF(AA20="","",AA20) | AC20: =IF(AC$3=0,"",SUMIFS(INDEX(Inputs!$D$4:$AG$100,0,MATCH(AC$2,Inputs!$D$2:$AG$2,0)),Inputs!$B$4:$B$100,$B20)/1000) | AD20: =IF(AD$3=0,"",SUMIFS(INDEX(Inputs!$D$4:$AG$100,0,MATCH(AD$2,Inputs!$D$2:$AG$2,0)),Inputs!$B$4:$B$100,$B20)/1000) | AE20: =IF(AE$3=0,"",SUMIFS(INDEX(Inputs!$D$4:$AG$100,0,MATCH(AE$2,Inputs!$D$2:$AG$2,0)),Inputs!$B$4:$B$100,$B20)/1000) | AF20: =IF(AF$3=0,"",SUMIFS(INDEX(Inputs!$D$4:$AG$100,0,MATCH(AF$2,Inputs!$D$2:$AG$2,0)),Inputs!$B$4:$B$100,$B20)/1000) | AG20: =IF(AF20="","",AF20)
B21: 17 | C21: Equity in affiliates | D21: =IF(D$3=0,"",SUMIFS(INDEX(Inputs!$D$4:$AG$100,0,MATCH(D$2,Inputs!$D$2:$AG$2,0)),Inputs!$B$4:$B$100,$B21)/1000) | E21: =IF(E$3=0,"",SUMIFS(INDEX(Inputs!$D$4:$AG$100,0,MATCH(E$2,Inputs!$D$2:$AG$2,0)),Inputs!$B$4:$B$100,$B21)/1000) | F21: =IF(F$3=0,"",SUMIFS(INDEX(Inputs!$D$4:$AG$100,0,MATCH(F$2,Inputs!$D$2:$AG$2,0)),Inputs!$B$4:$B$100,$B21)/1000) | G21: =IF(G$3=0,"",SUMIFS(INDEX(Inputs!$D$4:$AG$100,0,MATCH(G$2,Inputs!$D$2:$AG$2,0)),Inputs!$B$4:$B$100,$B21)/1000) | H21: =IF(G21="","",G21) | I21: =IF(I$3=0,"",SUMIFS(INDEX(Inputs!$D$4:$AG$100,0,MATCH(I$2,Inputs!$D$2:$AG$2,0)),Inputs!$B$4:$B$100,$B21)/1000) | J21: =IF(J$3=0,"",SUMIFS(INDEX(Inputs!$D$4:$AG$100,0,MATCH(J$2,Inputs!$D$2:$AG$2,0)),Inputs!$B$4:$B$100,$B21)/1000) | K21: =IF(K$3=0,"",SUMIFS(INDEX(Inputs!$D$4:$AG$100,0,MATCH(K$2,Inputs!$D$2:$AG$2,0)),Inputs!$B$4:$B$100,$B21)/1000) | L21: =IF(L$3=0,"",SUMIFS(INDEX(Inputs!$D$4:$AG$100,0,MATCH(L$2,Inputs!$D$2:$AG$2,0)),Inputs!$B$4:$B$100,$B21)/1000) | M21: =IF(L21="","",L21) | N21: =IF(N$3=0,"",SUMIFS(INDEX(Inputs!$D$4:$AG$100,0,MATCH(N$2,Inputs!$D$2:$AG$2,0)),Inputs!$B$4:$B$100,$B21)/1000) | O21: =IF(O$3=0,"",SUMIFS(INDEX(Inputs!$D$4:$AG$100,0,MATCH(O$2,Inputs!$D$2:$AG$2,0)),Inputs!$B$4:$B$100,$B21)/1000) | P21: =IF(P$3=0,"",SUMIFS(INDEX(Inputs!$D$4:$AG$100,0,MATCH(P$2,Inputs!$D$2:$AG$2,0)),Inputs!$B$4:$B$100,$B21)/1000) | Q21: =IF(Q$3=0,"",SUMIFS(INDEX(Inputs!$D$4:$AG$100,0,MATCH(Q$2,Inputs!$D$2:$AG$2,0)),Inputs!$B$4:$B$100,$B21)/1000) | R21: =IF(Q21="","",Q21) | S21: =IF(S$3=0,"",SUMIFS(INDEX(Inputs!$D$4:$AG$100,0,MATCH(S$2,Inputs!$D$2:$AG$2,0)),Inputs!$B$4:$B$100,$B21)/1000) | T21: =IF(T$3=0,"",SUMIFS(INDEX(Inputs!$D$4:$AG$100,0,MATCH(T$2,Inputs!$D$2:$AG$2,0)),Inputs!$B$4:$B$100,$B21)/1000) | U21: =IF(U$3=0,"",SUMIFS(INDEX(Inputs!$D$4:$AG$100,0,MATCH(U$2,Inputs!$D$2:$AG$2,0)),Inputs!$B$4:$B$100,$B21)/1000) | V21: =IF(V$3=0,"",SUMIFS(INDEX(Inputs!$D$4:$AG$100,0,MATCH(V$2,Inputs!$D$2:$AG$2,0)),Inputs!$B$4:$B$100,$B21)/1000) | W21: =IF(V21="","",V21) | X21: =IF(X$3=0,"",SUMIFS(INDEX(Inputs!$D$4:$AG$100,0,MATCH(X$2,Inputs!$D$2:$AG$2,0)),Inputs!$B$4:$B$100,$B21)/1000) | Y21: =IF(Y$3=0,"",SUMIFS(INDEX(Inputs!$D$4:$AG$100,0,MATCH(Y$2,Inputs!$D$2:$AG$2,0)),Inputs!$B$4:$B$100,$B21)/1000) | Z21: =IF(Z$3=0,"",SUMIFS(INDEX(Inputs!$D$4:$AG$100,0,MATCH(Z$2,Inputs!$D$2:$AG$2,0)),Inputs!$B$4:$B$100,$B21)/1000) | AA21: =IF(AA$3=0,"",SUMIFS(INDEX(Inputs!$D$4:$AG$100,0,MATCH(AA$2,Inputs!$D$2:$AG$2,0)),Inputs!$B$4:$B$100,$B21)/1000) | AB21: =IF(AA21="","",AA21) | AC21: =IF(AC$3=0,"",SUMIFS(INDEX(Inputs!$D$4:$AG$100,0,MATCH(AC$2,Inputs!$D$2:$AG$2,0)),Inputs!$B$4:$B$100,$B21)/1000) | AD21: =IF(AD$3=0,"",SUMIFS(INDEX(Inputs!$D$4:$AG$100,0,MATCH(AD$2,Inputs!$D$2:$AG$2,0)),Inputs!$B$4:$B$100,$B21)/1000) | AE21: =IF(AE$3=0,"",SUMIFS(INDEX(Inputs!$D$4:$AG$100,0,MATCH(AE$2,Inputs!$D$2:$AG$2,0)),Inputs!$B$4:$B$100,$B21)/1000) | AF21: =IF(AF$3=0,"",SUMIFS(INDEX(Inputs!$D$4:$AG$100,0,MATCH(AF$2,Inputs!$D$2:$AG$2,0)),Inputs!$B$4:$B$100,$B21)/1000) | AG21: =IF(AF21="","",AF21)
B22: 18 | C22: PP&E | D22: =IF(D$3=0,"",SUMIFS(INDEX(Inputs!$D$4:$AG$100,0,MATCH(D$2,Inputs!$D$2:$AG$2,0)),Inputs!$B$4:$B$100,$B22)/1000) | E22: =IF(E$3=0,"",SUMIFS(INDEX(Inputs!$D$4:$AG$100,0,MATCH(E$2,Inputs!$D$2:$AG$2,0)),Inputs!$B$4:$B$100,$B22)/1000) | F22: =IF(F$3=0,"",SUMIFS(INDEX(Inputs!$D$4:$AG$100,0,MATCH(F$2,Inputs!$D$2:$AG$2,0)),Inputs!$B$4:$B$100,$B22)/1000) | G22: =IF(G$3=0,"",SUMIFS(INDEX(Inputs!$D$4:$AG$100,0,MATCH(G$2,Inputs!$D$2:$AG$2,0)),Inputs!$B$4:$B$100,$B22)/1000) | H22: =IF(G22="","",G22) | I22: =IF(I$3=0,"",SUMIFS(INDEX(Inputs!$D$4:$AG$100,0,MATCH(I$2,Inputs!$D$2:$AG$2,0)),Inputs!$B$4:$B$100,$B22)/1000) | J22: =IF(J$3=0,"",SUMIFS(INDEX(Inputs!$D$4:$AG$100,0,MATCH(J$2,Inputs!$D$2:$AG$2,0)),Inputs!$B$4:$B$100,$B22)/1000) | K22: =IF(K$3=0,"",SUMIFS(INDEX(Inputs!$D$4:$AG$100,0,MATCH(K$2,Inputs!$D$2:$AG$2,0)),Inputs!$B$4:$B$100,$B22)/1000) | L22: =IF(L$3=0,"",SUMIFS(INDEX(Inputs!$D$4:$AG$100,0,MATCH(L$2,Inputs!$D$2:$AG$2,0)),Inputs!$B$4:$B$100,$B22)/1000) | M22: =IF(L22="","",L22) | N22: =IF(N$3=0,"",SUMIFS(INDEX(Inputs!$D$4:$AG$100,0,MATCH(N$2,Inputs!$D$2:$AG$2,0)),Inputs!$B$4:$B$100,$B22)/1000) | O22: =IF(O$3=0,"",SUMIFS(INDEX(Inputs!$D$4:$AG$100,0,MATCH(O$2,Inputs!$D$2:$AG$2,0)),Inputs!$B$4:$B$100,$B22)/1000) | P22: =IF(P$3=0,"",SUMIFS(INDEX(Inputs!$D$4:$AG$100,0,MATCH(P$2,Inputs!$D$2:$AG$2,0)),Inputs!$B$4:$B$100,$B22)/1000) | Q22: =IF(Q$3=0,"",SUMIFS(INDEX(Inputs!$D$4:$AG$100,0,MATCH(Q$2,Inputs!$D$2:$AG$2,0)),Inputs!$B$4:$B$100,$B22)/1000) | R22: =IF(Q22="","",Q22) | S22: =IF(S$3=0,"",SUMIFS(INDEX(Inputs!$D$4:$AG$100,0,MATCH(S$2,Inputs!$D$2:$AG$2,0)),Inputs!$B$4:$B$100,$B22)/1000) | T22: =IF(T$3=0,"",SUMIFS(INDEX(Inputs!$D$4:$AG$100,0,MATCH(T$2,Inputs!$D$2:$AG$2,0)),Inputs!$B$4:$B$100,$B22)/1000) | U22: =IF(U$3=0,"",SUMIFS(INDEX(Inputs!$D$4:$AG$100,0,MATCH(U$2,Inputs!$D$2:$AG$2,0)),Inputs!$B$4:$B$100,$B22)/1000) | V22: =IF(V$3=0,"",SUMIFS(INDEX(Inputs!$D$4:$AG$100,0,MATCH(V$2,Inputs!$D$2:$AG$2,0)),Inputs!$B$4:$B$100,$B22)/1000) | W22: =IF(V22="","",V22) | X22: =IF(X$3=0,"",SUMIFS(INDEX(Inputs!$D$4:$AG$100,0,MATCH(X$2,Inputs!$D$2:$AG$2,0)),Inputs!$B$4:$B$100,$B22)/1000) | Y22: =IF(Y$3=0,"",SUMIFS(INDEX(Inputs!$D$4:$AG$100,0,MATCH(Y$2,Inputs!$D$2:$AG$2,0)),Inputs!$B$4:$B$100,$B22)/1000) | Z22: =IF(Z$3=0,"",SUMIFS(INDEX(Inputs!$D$4:$AG$100,0,MATCH(Z$2,Inputs!$D$2:$AG$2,0)),Inputs!$B$4:$B$100,$B22)/1000) | AA22: =IF(AA$3=0,"",SUMIFS(INDEX(Inputs!$D$4:$AG$100,0,MATCH(AA$2,Inputs!$D$2:$AG$2,0)),Inputs!$B$4:$B$100,$B22)/1000) | AB22: =IF(AA22="","",AA22) | AC22: =IF(AC$3=0,"",SUMIFS(INDEX(Inputs!$D$4:$AG$100,0,MATCH(AC$2,Inputs!$D$2:$AG$2,0)),Inputs!$B$4:$B$100,$B22)/1000) | AD22: =IF(AD$3=0,"",SUMIFS(INDEX(Inputs!$D$4:$AG$100,0,MATCH(AD$2,Inputs!$D$2:$AG$2,0)),Inputs!$B$4:$B$100,$B22)/1000) | AE22: =IF(AE$3=0,"",SUMIFS(INDEX(Inputs!$D$4:$AG$100,0,MATCH(AE$2,Inputs!$D$2:$AG$2,0)),Inputs!$B$4:$B$100,$B22)/1000) | AF22: =IF(AF$3=0,"",SUMIFS(INDEX(Inputs!$D$4:$AG$100,0,MATCH(AF$2,Inputs!$D$2:$AG$2,0)),Inputs!$B$4:$B$100,$B22)/1000) | AG22: =IF(AF22="","",AF22)
