Workbook
Name beta_observed: Valuation!$D$93
Name beta_observed_unlevered: #REF!
Name beta_unlev_comps: #REF!
Name cirkbreak: #REF!
Name costdebtfirm: #REF!
Name costequity: #REF!
Name Debt: #REF!
Name debt_weight: #REF!
Name last_close: Valuation!$G$7
Name Market_Equity: #REF!
Name midyear: #REF!
Name Net_Debt: #REF!
Name range: #REF!
Name Stub_year_fraction: #REF!
Name ticker: Valuation!$D$7
Name Useful_Life_of_Depreciable_PP_E: "PPElife"
Name beta_observed: #REF!
Name ticker: #REF!
Name costdebtfirm: Valuation!$D$86
Name costequity: Valuation!$D$94
Name debt: Valuation!$G$88
Name debt_weight: Valuation!$J$88
Name g: Valuation!$D$63
Name market_equity: Valuation!$G$89
Name noplat_t1: Valuation!$D$65
Name relevered_beta: Valuation!$M$102
Name risk_free_rate: Valuation!$D$91
Name risk_premium: Valuation!$D$92
Name ronic: Valuation!$D$64
Name stub_year_fraction: Valuation!$D$11
Name totalcap: Valuation!$G$90
Name wacc: Valuation!$D$12
Name scenario: Valuation!$E$8

Sheet Inputs
A1: Fator p/ milhões: | B1: 1e-06 | D1: Deere & Company (DE, CIK 315189) - fonte: SEC EDGAR XBRL (instâncias dos 10-Q/10-K). Moeda: USD. Brutos em USD unidades (fator 0,000001 -> milhões). Colunas = trimestres-CALENDÁRIO (cada fechamento vai para o fim de trimestre mais próximo); ano fiscal termina no trimestre-calendário de set. Trimestre fiscal 4 (e qualquer trimestre sem 3M publicado) = acumulado do ano menos o acumulado anterior, calculado na extração.
J2: Trimestre fiscal | K2: FQ2 | L2: FQ3 | M2: FQ4 | N2: FQ1 | O2: FQ2 | P2: FQ3 | Q2: FQ4 | R2: FQ1 | S2: FQ2 | T2: FQ3 | U2: FQ4 | V2: FQ1 | W2: FQ2 | X2: FQ3 | Y2: FQ4 | Z2: FQ1 | AA2: FQ2 | AB2: FQ3 | AC2: FQ4 | AD2: FQ1 | AE2: FQ2 | AF2: FQ3 | AG2: FQ4 | AH2: FQ1 | AI2: FQ2 | AJ2: FQ3
A4: COD1 | B4: SINAL1 | C4: COD2 | D4: SINAL2 | E4: COD3 | F4: SINAL3 | G4: UNID | H4: Conta (PT) / origem | I4: Account (EN) | J4: ORIGEM | K4: 1Q20 | L4: 2Q20 | M4: 3Q20 | N4: 4Q20 | O4: 1Q21 | P4: 2Q21 | Q4: 3Q21 | R4: 4Q21 | S4: 1Q22 | T4: 2Q22 | U4: 3Q22 | V4: 4Q22 | W4: 1Q23 | X4: 2Q23 | Y4: 3Q23 | Z4: 4Q23 | AA4: 1Q24 | AB4: 2Q24 | AC4: 3Q24 | AD4: 4Q24 | AE4: 1Q25 | AF4: 2Q25 | AG4: 3Q25 | AH4: 4Q25 | AI4: 1Q26 | AJ4: 2Q26
H5: DRE - trimestre isolado (USD). Brutos SEC XBRL; linhas "derivada" são fórmulas nesta aba
A6: 1 | B6: 1 | G6: moeda | H6: Receita [us-gaap:Revenues/RevenueFromContractWithCustomerExcludingAssessedTax] | J6: fonte | K6: 9253000000 | L6: 8925000000 | M6: 9731000000 | N6: 9112000000 | O6: 12058000000 | P6: 11527000000 | Q6: 11327000000 | R6: 9569000000 | S6: 13370000000 | T6: 14102000000 | U6: 15536000000 | V6: 12652000000 | W6: 17387000000 | X6: 15801000000 | Y6: 15412000000 | Z6: 12185000000 | AA6: 15235000000 | AB6: 13152000000 | AC6: 11144000000 | AD6: 8508000000 | AE6: 12763000000 | AF6: 12018000000 | AG6: 12394000000 | AH6: 9611000000 | AI6: 13369000000 | AJ6: 12608000000
A7: 2 | B7: -1 | G7: moeda | H7: Custo da receita (divulgado positivo) [us-gaap:CostOfRevenue/CostOfGoodsAndServicesSold] | J7: fonte | K7: 0 | L7: 0 | M7: 0 | N7: 0 | O7: 0 | P7: 0 | Q7: 0 | R7: 0 | S7: 0 | T7: 0 | U7: 0 | V7: 0 | W7: 0 | X7: 0 | Y7: 0 | Z7: 0 | AA7: 0 | AB7: 0 | AC7: 0 | AD7: 0 | AE7: 0 | AF7: 0 | AG7: 0 | AH7: 0 | AI7: 0 | AJ7: 0
G8: moeda | H8: Lucro operacional [us-gaap:OperatingIncomeLoss] | J8: memoria | K8: 965000000 | L8: 1390000000 | M8: 1304000000 | N8: 1638000000 | O8: 2439000000 | P8: 2243000000 | Q8: 1692000000 | R8: 1235000000 | S8: 2670000000 | T8: 2646000000 | U8: 2956000000 | V8: 2518000000 | W8: 3898000000 | X8: 3516000000 | Y8: 3026000000
A9: 3 | B9: -1 | G9: moeda | H9: Despesas operacionais = receita - custo - lucro operacional (P&D + SG&A + outras operacionais) | J9: derivada | K9: =N(K6)-N(K7)-N(K8) -> 8288000000 | L9: =N(L6)-N(L7)-N(L8) -> 7535000000 | M9: =N(M6)-N(M7)-N(M8) -> 8427000000 | N9: =N(N6)-N(N7)-N(N8) -> 7474000000 | O9: =N(O6)-N(O7)-N(O8) -> 9619000000 | P9: =N(P6)-N(P7)-N(P8) -> 9284000000 | Q9: =N(Q6)-N(Q7)-N(Q8) -> 9635000000 | R9: =N(R6)-N(R7)-N(R8) -> 8334000000 | ... AJ9: =N(AJ6)-N(AJ7)-N(AJ8) -> 12608000000
G10: moeda | H10: Lucro antes do IR [us-gaap:IncomeLossFromContinuingOperationsBeforeIncomeTaxesExtraordi] | J10: memoria | K10: 928000000 | L10: 1270000000 | M10: 1115000000 | N10: 1528000000 | O10: 2312000000 | P10: 2150000000 | Q10: 1613000000 | R10: 1151000000 | S10: 2552000000 | T10: 2539000000 | U10: 2885000000 | V10: 2493000000 | W10: 3848000000 | X10: 3606000000 | Y10: 3073000000 | Z10: 2215000000 | AA10: 3117000000 | AB10: 2355000000 | AC10: 1519000000 | AD10: 895000000 | AE10: 2337000000 | AF10: 1600000000 | AG10: 1425000000 | AH10: 836000000 | AI10: 2293000000 | AJ10: 1882000000
A11: 6 | B11: 1 | G11: moeda | H11: Resultado não operacional total = lucro antes do IR - lucro operacional | J11: derivada | K11: =N(K10)-N(K8) -> -37000000 | L11: =N(L10)-N(L8) -> -120000000 | M11: =N(M10)-N(M8) -> -189000000 | N11: =N(N10)-N(N8) -> -110000000 | O11: =N(O10)-N(O8) -> -127000000 | P11: =N(P10)-N(P8) -> -93000000 | Q11: =N(Q10)-N(Q8) -> -79000000 | R11: =N(R10)-N(R8) -> -84000000 | ... AJ11: =N(AJ10)-N(AJ8) -> 1882000000
A12: 5 | B12: -1 | C12: 6 | D12: 1 | G12: moeda | H12: Despesa de juros (divulgado positivo): COD1=5 lança; COD2=6 devolve ao não operacional, que já a contém [us-gaap:InterestExpense/InterestExpenseNonoperating] | J12: fonte | K12: 342000000 | L12: 290000000 | M12: 278000000 | N12: 271000000 | O12: 268000000 | P12: 244000000 | Q12: 210000000 | R12: 229000000 | S12: 187000000 | T12: 296000000 | U12: 349000000 | V12: 479000000 | W12: 569000000 | X12: 623000000 | Y12: 782000000 | Z12: 802000000 | AA12: 836000000 | AB12: 840000000 | AC12: 870000000 | AD12: 829000000 | AE12: 784000000 | AF12: 794000000 | AG12: 762000000 | AH12: 719000000 | AI12: 712000000 | AJ12: 710000000
A13: 7 | B13: -1 | G13: moeda | H13: Imposto de renda (divulgado positivo) [us-gaap:IncomeTaxExpenseBenefit] | J13: fonte | K13: 245000000 | L13: 457000000 | M13: 330000000 | N13: 308000000 | O13: 530000000 | P13: 491000000 | Q13: 330000000 | R13: 250000000 | S13: 461000000 | T13: 654000000 | U13: 643000000 | V13: 537000000 | W13: 991000000 | X13: 636000000 | Y13: 707000000 | Z13: 469000000 | AA13: 751000000 | AB13: 625000000 | AC13: 249000000 | AD13: 27000000 | AE13: 539000000 | AF13: 339000000 | AG13: 354000000 | AH13: 196000000 | AI13: 518000000 | AJ13: 529000000
A14: 9 | B14: -1 | G14: moeda | H14: Lucro atribuído a não controladores (divulgado positivo) [us-gaap:NetIncomeLossAttributableToNoncontrollingInterest] | J14: fonte | K14: 0 | L14: 0 | M14: 0 | N14: 0 | O14: 1000000 | P14: 1000000 | Q14: 0 | R14: 1000000 | S14: -1000000 | T14: 1000000 | U14: -2000000 | V14: -2000000 | W14: -1000000 | X14: -6000000 | Y14: -1000000 | Z14: -3000000 | AA14: -2000000 | AB14: -3000000 | AC14: -3000000 | AD14: -2000000 | AE14: -3000000 | AF14: -18000000 | AG14: -5000000 | AH14: -1000000 | AI14: -3000000 | AJ14: -2000000
G15: moeda | H15: Lucro líquido atribuído à companhia [us-gaap:NetIncomeLoss] | J15: memoria | K15: 666000000 | L15: 811000000 | M15: 757000000 | N15: 1224000000 | O15: 1790000000 | P15: 1667000000 | Q15: 1283000000 | R15: 903000000 | S15: 2098000000 | T15: 1884000000 | U15: 2246000000 | V15: 1959000000 | W15: 2860000000 | X15: 2978000000 | Y15: 2369000000 | Z15: 1751000000 | AA15: 2370000000 | AB15: 1734000000 | AC15: 1245000000 | AD15: 869000000 | AE15: 1804000000 | AF15: 1289000000 | AG15: 1065000000 | AH15: 656000000 | AI15: 1773000000 | AJ15: 1379000000
A16: 8 | B16: 1 | G16: moeda | H16: Resultado após IR não classificado acima (equivalência patrimonial, operações descontinuadas): lucro - (LAIR - IR - minoritários); zero quando não há | J16: derivada | K16: =N(K15)-(N(K10)-N(K13)-N(K14)) -> -17000000 | L16: =N(L15)-(N(L10)-N(L13)-N(L14)) -> -2000000 | M16: =N(M15)-(N(M10)-N(M13)-N(M14)) -> -28000000 | N16: =N(N15)-(N(N10)-N(N13)-N(N14)) -> 4000000 | O16: =N(O15)-(N(O10)-N(O13)-N(O14)) -> 9000000 | P16: =N(P15)-(N(P10)-N(P13)-N(P14)) -> 9000000 | Q16: =N(Q15)-(N(Q10)-N(Q13)-N(Q14)) -> 0 | R16: =N(R15)-(N(R10)-N(R13)-N(R14)) -> 3000000 | ... AJ16: =N(AJ15)-(N(AJ10)-N(AJ13)-N(AJ14)) -> 24000000
A17: 44 | B17: 1 | G17: moeda | H17: Lucro líquido (check IS, código 44) | J17: derivada | K17: =N(K15) -> 666000000 | L17: =N(L15) -> 811000000 | M17: =N(M15) -> 757000000 | N17: =N(N15) -> 1224000000 | O17: =N(O15) -> 1790000000 | P17: =N(P15) -> 1667000000 | Q17: =N(Q15) -> 1283000000 | R17: =N(R15) -> 903000000 | ... AJ17: =N(AJ15) -> 1379000000
H18: DFC - trimestre isolado (desacumulado na extração)
A19: 4 | B19: -1 | C19: 3 | D19: 1 | G19: moeda | H19: D&A (fluxo de caixa). COD1=4 lança (positivo -> -1); COD2=3 devolve às despesas operacionais (a companhia não abre D&A entre custo e despesa) [us-gaap:DepreciationDepletionAndAmortization/DepreciationAmortizationAndImpairment] | J19: fonte | K19: 529000000 | L19: 547000000 | M19: 504000000 | N19: 538000000 | O19: 516000000 | P19: 515000000 | Q19: 481000000 | R19: 486000000 | S19: 447000000 | T19: 510000000 | U19: 452000000 | V19: 494000000 | W19: 501000000 | X19: 532000000 | Y19: 477000000 | Z19: 520000000 | AA19: 525000000 | AB19: 553000000 | AC19: 520000000 | AD19: 549000000 | AE19: 555000000 | AF19: 564000000 | AG19: 561000000 | AH19: 590000000 | AI19: 594000000 | AJ19: 603000000
A20: 10 | B20: -1 | G20: moeda | H20: Dividendos pagos [us-gaap:PaymentsOfDividends] | J20: fonte | K20: 239000000 | L20: 237000000 | M20: 238000000 | N20: 242000000 | O20: 238000000 | P20: 281000000 | Q20: 279000000 | R20: 327000000 | S20: 322000000 | T20: 322000000 | U20: 342000000 | V20: 341000000 | W20: 356000000 | X20: 368000000 | Y20: 362000000 | Z20: 386000000 | AA20: 410000000 | AB20: 406000000 | AC20: 403000000 | AD20: 403000000 | AE20: 440000000 | AF20: 439000000 | AG20: 438000000 | AH20: 441000000 | AI20: 437000000 | AJ20: 438000000
H21: BALANÇO DE FACE (USD, saldo no fim do trimestre; cada trimestre lido da instância do próprio 10-Q/10-K)
A22: 11 | B22: 1 | G22: moeda | H22: CashAndCashEquivalentsAtCarryingValue | J22: fonte | K22: 8900000000 | L22: 8190000000 | M22: 7066000000 | N22: 6962000000 | O22: 7182000000 | P22: 7519000000 | Q22: 8017000000 | R22: 4472000000 | S22: 3878000000 | T22: 4359000000 | U22: 4774000000 | V22: 3976000000 | W22: 5267000000 | X22: 6576000000 | Y22: 7458000000 | Z22: 5137000000 | AA22: 5553000000 | AB22: 7004000000 | AC22: 7324000000 | AD22: 6601000000 | AE22: 7991000000 | AF22: 8580000000 | AG22: 8276000000 | AH22: 6798000000 | AI22: 7905000000 | AJ22: 8928000000
A23: 13 | B23: 1 | G23: moeda | H23: InventoryNet | J23: fonte | K23: 6171000000 | L23: 5650000000 | M23: 4999000000 | N23: 5956000000 | O23: 6042000000 | P23: 6410000000 | Q23: 6781000000 | R23: 7935000000 | S23: 9030000000 | T23: 9121000000 | U23: 8495000000 | V23: 10056000000 | W23: 9713000000 | X23: 9350000000 | Y23: 8160000000 | Z23: 8937000000 | AA23: 8443000000 | AB23: 7696000000 | AC23: 7093000000 | AD23: 7744000000 | AE23: 7870000000 | AF23: 7713000000 | AG23: 7406000000 | AH23: 8286000000 | AI23: 8188000000 | AJ23: 7811000000
A24: 14 | B24: 1 | G24: moeda | H24: DeferredIncomeTaxAssetsNet | J24: fonte | K24: 1435000000 | L24: 1534000000 | M24: 1499000000 | N24: 1556000000 | O24: 1724000000 | P24: 1767000000 | Q24: 1037000000 | R24: 923000000 | S24: 1104000000 | T24: 1110000000 | U24: 824000000 | V24: 914000000 | W24: 1308000000 | X24: 1360000000 | Y24: 1814000000 | Z24: 1833000000 | AA24: 1936000000 | AB24: 1898000000 | AC24: 2086000000 | AD24: 1852000000 | AE24: 2088000000 | AF24: 2209000000 | AG24: 2284000000 | AH24: 2268000000 | AI24: 2361000000 | AJ24: 2343000000
A25: 16 | B25: 1 | G25: moeda | H25: MarketableSecurities | J25: fonte | K25: 626000000 | L25: 640000000 | M25: 641000000 | N25: 667000000 | O25: 668000000 | P25: 688000000 | Q25: 728000000 | R25: 735000000 | S25: 682000000 | T25: 719000000 | U25: 734000000 | V25: 852000000 | W25: 856000000 | X25: 841000000 | Y25: 946000000 | Z25: 1136000000 | AA25: 1094000000 | AB25: 1140000000 | AC25: 1154000000 | AD25: 1214000000 | AE25: 1272000000 | AF25: 1407000000 | AG25: 1411000000 | AH25: 1398000000 | AI25: 1430000000 | AJ25: 1350000000
A26: 16 | B26: 1 | G26: moeda | H26: DueFromRelatedParties | J26: fonte | K26: 32000000 | L26: 26000000 | M26: 31000000 | N26: 28000000 | O26: 31000000 | P26: 29000000 | Q26: 27000000 | R26: 33000000 | S26: 0 | T26: 0 | U26: 0 | V26: 0 | W26: 0 | X26: 0 | Y26: 0 | Z26: 0 | AA26: 0 | AB26: 0 | AC26: 0 | AD26: 0 | AE26: 0 | AF26: 0 | AG26: 0 | AH26: 0 | AI26: 0 | AJ26: 0
A27: 16 | B27: 1 | G27: moeda | H27: AccountsReceivableNet | J27: fonte | K27: 5986000000 | L27: 5473000000 | M27: 4171000000 | N27: 5037000000 | O27: 6158000000 | P27: 5268000000 | Q27: 4208000000 | R27: 4855000000 | S27: 6258000000 | T27: 6696000000 | U27: 6410000000 | V27: 7609000000 | W27: 9971000000 | X27: 9297000000 | Y27: 7739000000 | Z27: 7795000000 | AA27: 8880000000 | AB27: 7469000000 | AC27: 5326000000 | AD27: 4931000000 | AE27: 6748000000 | AF27: 6103000000 | AG27: 5317000000 | AH27: 5993000000 | AI27: 7571000000 | AJ27: 7723000000
A28: 16 | B28: 1 | G28: moeda | H28: LoansAndLeasesReceivableNetReportedAmount | J28: fonte | K28: 27256000000 | L28: 27814000000 | M28: 29750000000 | N28: 29438000000 | O28: 30994000000 | P28: 31449000000 | Q28: 33799000000 | R28: 33191000000 | S28: 34085000000 | T28: 0 | U28: 0 | V28: 0 | W28: 0 | X28: 0 | Y28: 0 | Z28: 0 | AA28: 0 | AB28: 0 | AC28: 0 | AD28: 0 | AE28: 0 | AF28: 0 | AG28: 0 | AH28: 0 | AI28: 0 | AJ28: 0
A29: 16 | B29: 1 | G29: moeda | H29: LoansPledgedAsCollateral | J29: fonte | K29: 4685000000 | L29: 5469000000 | M29: 4703000000 | N29: 3931000000 | O29: 4107000000 | P29: 5401000000 | Q29: 4659000000 | R29: 3516000000 | S29: 4073000000 | T29: 0 | U29: 0 | V29: 0 | W29: 0 | X29: 0 | Y29: 0 | Z29: 0 | AA29: 0 | AB29: 0 | AC29: 0 | AD29: 0 | AE29: 0 | AF29: 0 | AG29: 0 | AH29: 0 | AI29: 0 | AJ29: 0
A30: 16 | B30: 1 | G30: moeda | H30: OtherReceivables | J30: fonte | K30: 1212000000 | L30: 1217000000 | M30: 1220000000 | N30: 1141000000 | O30: 1473000000 | P30: 1673000000 | Q30: 1738000000 | R30: 1903000000 | S30: 2306000000 | T30: 1999000000 | U30: 2492000000 | V30: 1992000000 | W30: 2593000000 | X30: 3118000000 | Y30: 2623000000 | Z30: 2017000000 | AA30: 2535000000 | AB30: 2270000000 | AC30: 2545000000 | AD30: 2979000000 | AE30: 2975000000 | AF30: 2826000000 | AG30: 2403000000 | AH30: 2411000000 | AI30: 2582000000 | AJ30: 2466000000
A31: 16 | B31: 1 | G31: moeda | H31: EquipmentOnOperatingLeasesNet | J31: fonte | K31: 7245000000 | L31: 7158000000 | M31: 7298000000 | N31: 7030000000 | O31: 0 | P31: 0 | Q31: 0 | R31: 0 | S31: 0 | T31: 0 | U31: 0 | V31: 0 | W31: 0 | X31: 0 | Y31: 0 | Z31: 0 | AA31: 0 | AB31: 0 | AC31: 0 | AD31: 0 | AE31: 0 | AF31: 0 | AG31: 0 | AH31: 0 | AI31: 0 | AJ31: 0
A32: 16 | B32: 1 | G32: moeda | H32: InvestmentsInAffiliatesSubsidiariesAssociatesAndJointVentures | J32: fonte | K32: 192000000 | L32: 199000000 | M32: 193000000 | N32: 178000000 | O32: 182000000 | P32: 188000000 | Q32: 175000000 | R32: 176000000 | S32: 0 | T32: 0 | U32: 0 | V32: 0 | W32: 0 | X32: 0 | Y32: 0 | Z32: 0 | AA32: 0 | AB32: 0 | AC32: 0 | AD32: 0 | AE32: 0 | AF32: 0 | AG32: 0 | AH32: 0 | AI32: 0 | AJ32: 0
A33: 16 | B33: 1 | G33: moeda | H33: DefinedBenefitPlanAssetsForPlanBenefitsNoncurrent | J33: fonte | K33: 960000000 | L33: 1031000000 | M33: 863000000 | N33: 906000000 | O33: 951000000 | P33: 990000000 | Q33: 3601000000 | R33: 3158000000 | S33: 3059000000 | T33: 3125000000 | U33: 3730000000 | V33: 3793000000 | W33: 3519000000 | X33: 3573000000 | Y33: 3007000000 | Z33: 3087000000 | AA33: 3056000000 | AB33: 3126000000 | AC33: 2921000000 | AD33: 3018000000 | AE33: 3133000000 | AF33: 3182000000 | AG33: 3273000000 | AH33: 3378000000 | AI33: 3450000000 | AJ33: 3541000000
... A75: 22 | B75: 1 | G75: moeda | H75: Recebíveis de financiamento (John Deere Financial) e demais ativos de face etiquetados por dimensão = ativo total - linhas identificadas | J75: derivada | K75: 0 | L75: 0 | M75: 0 | N75: 0 | O75: 0 | P75: 0 | Q75: 0 | R75: 0 | S75: 0 | T75: 40197000000 | U75: 42570000000 | V75: 41971000000 | W75: 44613000000 | X75: 48303000000 | Y75: 51008000000 | Z75: 50108000000 | AA75: 52540000000 | AB75: 52170000000 | AC75: 53032000000 | AD75: 49653000000 | AE75: 50794000000 | AF75: 51878000000 | AG75: 51406000000 | AH75: 48592000000 | AI75: 49016000000 | AJ75: 49176000000
H76: BALANÇO - totais divulgados (memória)
G77: moeda | H77: Total do ativo [us-gaap:Assets] | J77: memoria | K77: 77326000000 | L77: 77264000000 | M77: 75091000000 | N77: 75480000000 | O77: 78979000000 | P77: 80688000000 | Q77: 84114000000 | R77: 79614000000 | S77: 84099000000 | T77: 86817000000 | U77: 90030000000 | V77: 91620000000 | W77: 98347000000 | X77: 103397000000 | Y77: 104087000000 | Z77: 101371000000 | AA77: 105628000000 | AB77: 107841000000 | AC77: 107320000000 | AD77: 103119000000 | AE77: 106303000000 | AF77: 107817000000 | AG77: 105996000000 | AH77: 103436000000 | AI77: 107001000000 | AJ77: 107607000000
G78: moeda | H78: Total do passivo + PL [us-gaap:LiabilitiesAndStockholdersEquity] | J78: memoria | K78: 77326000000 | L78: 77264000000 | M78: 75091000000 | N78: 75480000000 | O78: 78979000000 | P78: 80688000000 | Q78: 84114000000 | R78: 79614000000 | S78: 84099000000 | T78: 86817000000 | U78: 90030000000 | V78: 91620000000 | W78: 98347000000 | X78: 103397000000 | Y78: 104087000000 | Z78: 101371000000 | AA78: 105628000000 | AB78: 107841000000 | AC78: 107320000000 | AD78: 103119000000 | AE78: 106303000000 | AF78: 107817000000 | AG78: 105996000000 | AH78: 103436000000 | AI78: 107001000000 | AJ78: 107607000000
H79: CHECKS (devem ser 0)
G80: moeda | H80: CHECK: contas de ativo - ativo total (USD, arredondado a 100 mil) | J80: derivada | K80: =ROUND(N(K22)+N(K23)+N(K24)+N(K25)+N(K26)+N(K27)+N(K28)+N(K29)+N(K30)+N(K31)+N(K32)+N(K33)+N(K34)+N(K35)+N(K36)+N(K37)+N(K38)+N(K39)+N(K40)+N(K41)+N(K42)+N(K75)-N(K77),-5) -> 0 | L80: =ROUND(N(L22)+N(L23)+N(L24)+N(L25)+N(L26)+N(L27)+N(L28)+N(L29)+N(L30)+N(L31)+N(L32)+N(L33)+N(L34)+N(L35)+N(L36)+N(L37)+N(L38)+N(L39)+N(L40)+N(L41)+N(L42)+N(L75)-N(L77),-5) -> 0 | M80: =ROUND(N(M22)+N(M23)+N(M24)+N(M25)+N(M26)+N(M27)+N(M28)+N(M29)+N(M30)+N(M31)+N(M32)+N(M33)+N(M34)+N(M35)+N(M36)+N(M37)+N(M38)+N(M39)+N(M40)+N(M41)+N(M42)+N(M75)-N(M77),-5) -> 0 | N80: =ROUND(N(N22)+N(N23)+N(N24)+N(N25)+N(N26)+N(N27)+N(N28)+N(N29)+N(N30)+N(N31)+N(N32)+N(N33)+N(N34)+N(N35)+N(N36)+N(N37)+N(N38)+N(N39)+N(N40)+N(N41)+N(N42)+N(N75)-N(N77),-5) -> 0 | O80: =ROUND(N(O22)+N(O23)+N(O24)+N(O25)+N(O26)+N(O27)+N(O28)+N(O29)+N(O30)+N(O31)+N(O32)+N(O33)+N(O34)+N(O35)+N(O36)+N(O37)+N(O38)+N(O39)+N(O40)+N(O41)+N(O42)+N(O75)-N(O77),-5) -> 0 | P80: =ROUND(N(P22)+N(P23)+N(P24)+N(P25)+N(P26)+N(P27)+N(P28)+N(P29)+N(P30)+N(P31)+N(P32)+N(P33)+N(P34)+N(P35)+N(P36)+N(P37)+N(P38)+N(P39)+N(P40)+N(P41)+N(P42)+N(P75)-N(P77),-5) -> 0 | Q80: =ROUND(N(Q22)+N(Q23)+N(Q24)+N(Q25)+N(Q26)+N(Q27)+N(Q28)+N(Q29)+N(Q30)+N(Q31)+N(Q32)+N(Q33)+N(Q34)+N(Q35)+N(Q36)+N(Q37)+N(Q38)+N(Q39)+N(Q40)+N(Q41)+N(Q42)+N(Q75)-N(Q77),-5) -> 0 | R80: =ROUND(N(R22)+N(R23)+N(R24)+N(R25)+N(R26)+N(R27)+N(R28)+N(R29)+N(R30)+N(R31)+N(R32)+N(R33)+N(R34)+N(R35)+N(R36)+N(R37)+N(R38)+N(R39)+N(R40)+N(R41)+N(R42)+N(R75)-N(R77),-5) -> 0 | ... AJ80: =ROUND(N(AJ22)+N(AJ23)+N(AJ24)+N(AJ25)+N(AJ26)+N(AJ27)+N(AJ28)+N(AJ29)+N(AJ30)+N(AJ31)+N(AJ32)+N(AJ33)+N(AJ34)+N(AJ35)+N(AJ36)+N(AJ37)+N(AJ38)+N(AJ39)+N(AJ40)+N(AJ41)+N(AJ42)+N(AJ75)-N(AJ77),-5) -> 0
G81: moeda | H81: CHECK: passivo + PL (contas) - passivo + PL total | J81: derivada | K81: =ROUND(N(K43)+N(K44)+N(K45)+N(K46)+N(K47)+N(K48)+N(K49)+N(K50)+N(K51)+N(K52)+N(K53)+N(K54)+N(K55)+N(K56)+N(K57)+N(K58)+N(K59)-N(K78),-5) -> 0 | L81: =ROUND(N(L43)+N(L44)+N(L45)+N(L46)+N(L47)+N(L48)+N(L49)+N(L50)+N(L51)+N(L52)+N(L53)+N(L54)+N(L55)+N(L56)+N(L57)+N(L58)+N(L59)-N(L78),-5) -> 0 | M81: =ROUND(N(M43)+N(M44)+N(M45)+N(M46)+N(M47)+N(M48)+N(M49)+N(M50)+N(M51)+N(M52)+N(M53)+N(M54)+N(M55)+N(M56)+N(M57)+N(M58)+N(M59)-N(M78),-5) -> 0 | N81: =ROUND(N(N43)+N(N44)+N(N45)+N(N46)+N(N47)+N(N48)+N(N49)+N(N50)+N(N51)+N(N52)+N(N53)+N(N54)+N(N55)+N(N56)+N(N57)+N(N58)+N(N59)-N(N78),-5) -> 0 | O81: =ROUND(N(O43)+N(O44)+N(O45)+N(O46)+N(O47)+N(O48)+N(O49)+N(O50)+N(O51)+N(O52)+N(O53)+N(O54)+N(O55)+N(O56)+N(O57)+N(O58)+N(O59)-N(O78),-5) -> 0 | P81: =ROUND(N(P43)+N(P44)+N(P45)+N(P46)+N(P47)+N(P48)+N(P49)+N(P50)+N(P51)+N(P52)+N(P53)+N(P54)+N(P55)+N(P56)+N(P57)+N(P58)+N(P59)-N(P78),-5) -> 0 | Q81: =ROUND(N(Q43)+N(Q44)+N(Q45)+N(Q46)+N(Q47)+N(Q48)+N(Q49)+N(Q50)+N(Q51)+N(Q52)+N(Q53)+N(Q54)+N(Q55)+N(Q56)+N(Q57)+N(Q58)+N(Q59)-N(Q78),-5) -> 0 | R81: =ROUND(N(R43)+N(R44)+N(R45)+N(R46)+N(R47)+N(R48)+N(R49)+N(R50)+N(R51)+N(R52)+N(R53)+N(R54)+N(R55)+N(R56)+N(R57)+N(R58)+N(R59)-N(R78),-5) -> 0 | ... AJ81: =ROUND(N(AJ43)+N(AJ44)+N(AJ45)+N(AJ46)+N(AJ47)+N(AJ48)+N(AJ49)+N(AJ50)+N(AJ51)+N(AJ52)+N(AJ53)+N(AJ54)+N(AJ55)+N(AJ56)+N(AJ57)+N(AJ58)+N(AJ59)-N(AJ78),-5) -> 0
H82: CHECK: receita - custo - despesas + não operacional - IR - minoritários + outros após IR - lucro (deve ser 0) | J82: derivada | K82: =ROUND(N(K6)-N(K7)-N(K9)+N(K11)-N(K13)-N(K14)+N(K16)-N(K17),-5) -> 0 | L82: =ROUND(N(L6)-N(L7)-N(L9)+N(L11)-N(L13)-N(L14)+N(L16)-N(L17),-5) -> 0 | M82: =ROUND(N(M6)-N(M7)-N(M9)+N(M11)-N(M13)-N(M14)+N(M16)-N(M17),-5) -> 0 | N82: =ROUND(N(N6)-N(N7)-N(N9)+N(N11)-N(N13)-N(N14)+N(N16)-N(N17),-5) -> 0 | O82: =ROUND(N(O6)-N(O7)-N(O9)+N(O11)-N(O13)-N(O14)+N(O16)-N(O17),-5) -> 0 | P82: =ROUND(N(P6)-N(P7)-N(P9)+N(P11)-N(P13)-N(P14)+N(P16)-N(P17),-5) -> 0 | Q82: =ROUND(N(Q6)-N(Q7)-N(Q9)+N(Q11)-N(Q13)-N(Q14)+N(Q16)-N(Q17),-5) -> 0 | R82: =ROUND(N(R6)-N(R7)-N(R9)+N(R11)-N(R13)-N(R14)+N(R16)-N(R17),-5) -> 0 | ... AJ82: =ROUND(N(AJ6)-N(AJ7)-N(AJ9)+N(AJ11)-N(AJ13)-N(AJ14)+N(AJ16)-N(AJ17),-5) -> 0
...

Sheet Inputs (2)
A1: =COUNTIF($B$3:$B$1048576,$B$1) -> 1 | B1: =MAX($B$3:$B$1048576) -> 52
D2: 1Q21 | E2: 2Q21 | F2: 3Q21 | G2: 4Q21 | H2: 2021 | I2: 1Q22 | J2: 2Q22 | K2: 3Q22 | L2: 4Q22 | M2: 2022 | N2: 1Q23 | O2: 2Q23 | P2: 3Q23 | Q2: 4Q23 | R2: 2023 | S2: 1Q24 | T2: 2Q24 | U2: 3Q24 | V2: 4Q24 | W2: 2024 | X2: 1Q25 | Y2: 2Q25 | Z2: 3Q25 | AA2: 4Q25 | AB2: 2025 | AC2: 1Q26 | AD2: 2Q26 | AE2: 3Q26 | AF2: 4Q26 | AG2: 2026 | AH2: 1Q20 | AI2: 2Q20 | AJ2: 3Q20 | AK2: 4Q20 | AL2: 2020 | AN2: Sem dado na fonte: 3Q26, 4Q26 e 2026 (rotulo em cinza). 2020 fica nas colunas AH-AL.
B4: 1 | C4: Net Revenues | D4: =IF(ISNA(MATCH(D$2,Inputs!$K$4:$AJ$4,0)),NA(),IF(SUMPRODUCT((Inputs!$A$5:$A$130=$B4)*ISNUMBER(INDEX(Inputs!$K$5:$AJ$130,0,MATCH(D$2,Inputs!$K$4:$AJ$4,0))))+SUMPRODUCT((Inputs!$C$5:$C$130=$B4)*ISNUMBER(INDEX(Inputs!$K$5:$AJ$130,0,MATCH(D$2,Inputs!$K$4:$AJ$4,0))))+SUMPRODUCT((Inputs!$E$5:$E$130=$B4)*ISNUMBER(INDEX(Inputs!$K$5:$AJ$130,0,MATCH(D$2,Inputs!$K$4:$AJ$4,0))))=0,NA(),SUMPRODUCT((Inputs!$A$5:$A$130=$B4)*Inputs!$B$5:$B$130*(((Inputs!$G$5:$G$130="moeda")+(Inputs!$G$5:$G$130="acoes"))*Inputs!$B$1+((Inputs!$G$5:$G$130<>"moeda")*(Inputs!$G$5:$G$130<>"acoes")))*INDEX(Inputs!$K$5:$AJ$130,0,MATCH(D$2,Inputs!$K$4:$AJ$4,0)))+SUMPRODUCT((Inputs!$C$5:$C$130=$B4)*Inputs!$D$5:$D$130*(((Inputs!$G$5:$G$130="moeda")+(Inputs!$G$5:$G$130="acoes"))*Inputs!$B$1+((Inputs!$G$5:$G$130<>"moeda")*(Inputs!$G$5:$G$130<>"acoes")))*INDEX(Inputs!$K$5:$AJ$130,0,MATCH(D$2,Inputs!$K$4:$AJ$4,0)))+SUMPRODUCT((Inputs!$E$5:$E$130=$B4)*Inputs!$F$5:$F$130*(((Inputs!$G$5:$G$130="moeda")+(Inputs!$G$5:$G$130="acoes"))*Inputs!$B$1+((Inputs!$G$5:$G$130<>"moeda")*(Inputs!$G$5:$G$130<>"acoes")))*INDEX(Inputs!$K$5:$AJ$130,0,MATCH(D$2,Inputs!$K$4:$AJ$4,0))))) -> 12058 | E4: =IF(ISNA(MATCH(E$2,Inputs!$K$4:$AJ$4,0)),NA(),IF(SUMPRODUCT((Inputs!$A$5:$A$130=$B4)*ISNUMBER(INDEX(Inputs!$K$5:$AJ$130,0,MATCH(E$2,Inputs!$K$4:$AJ$4,0))))+SUMPRODUCT((Inputs!$C$5:$C$130=$B4)*ISNUMBER(INDEX(Inputs!$K$5:$AJ$130,0,MATCH(E$2,Inputs!$K$4:$AJ$4,0))))+SUMPRODUCT((Inputs!$E$5:$E$130=$B4)*ISNUMBER(INDEX(Inputs!$K$5:$AJ$130,0,MATCH(E$2,Inputs!$K$4:$AJ$4,0))))=0,NA(),SUMPRODUCT((Inputs!$A$5:$A$130=$B4)*Inputs!$B$5:$B$130*(((Inputs!$G$5:$G$130="moeda")+(Inputs!$G$5:$G$130="acoes"))*Inputs!$B$1+((Inputs!$G$5:$G$130<>"moeda")*(Inputs!$G$5:$G$130<>"acoes")))*INDEX(Inputs!$K$5:$AJ$130,0,MATCH(E$2,Inputs!$K$4:$AJ$4,0)))+SUMPRODUCT((Inputs!$C$5:$C$130=$B4)*Inputs!$D$5:$D$130*(((Inputs!$G$5:$G$130="moeda")+(Inputs!$G$5:$G$130="acoes"))*Inputs!$B$1+((Inputs!$G$5:$G$130<>"moeda")*(Inputs!$G$5:$G$130<>"acoes")))*INDEX(Inputs!$K$5:$AJ$130,0,MATCH(E$2,Inputs!$K$4:$AJ$4,0)))+SUMPRODUCT((Inputs!$E$5:$E$130=$B4)*Inputs!$F$5:$F$130*(((Inputs!$G$5:$G$130="moeda")+(Inputs!$G$5:$G$130="acoes"))*Inputs!$B$1+((Inputs!$G$5:$G$130<>"moeda")*(Inputs!$G$5:$G$130<>"acoes")))*INDEX(Inputs!$K$5:$AJ$130,0,MATCH(E$2,Inputs!$K$4:$AJ$4,0))))) -> 11527 | F4: =IF(ISNA(MATCH(F$2,Inputs!$K$4:$AJ$4,0)),NA(),IF(SUMPRODUCT((Inputs!$A$5:$A$130=$B4)*ISNUMBER(INDEX(Inputs!$K$5:$AJ$130,0,MATCH(F$2,Inputs!$K$4:$AJ$4,0))))+SUMPRODUCT((Inputs!$C$5:$C$130=$B4)*ISNUMBER(INDEX(Inputs!$K$5:$AJ$130,0,MATCH(F$2,Inputs!$K$4:$AJ$4,0))))+SUMPRODUCT((Inputs!$E$5:$E$130=$B4)*ISNUMBER(INDEX(Inputs!$K$5:$AJ$130,0,MATCH(F$2,Inputs!$K$4:$AJ$4,0))))=0,NA(),SUMPRODUCT((Inputs!$A$5:$A$130=$B4)*Inputs!$B$5:$B$130*(((Inputs!$G$5:$G$130="moeda")+(Inputs!$G$5:$G$130="acoes"))*Inputs!$B$1+((Inputs!$G$5:$G$130<>"moeda")*(Inputs!$G$5:$G$130<>"acoes")))*INDEX(Inputs!$K$5:$AJ$130,0,MATCH(F$2,Inputs!$K$4:$AJ$4,0)))+SUMPRODUCT((Inputs!$C$5:$C$130=$B4)*Inputs!$D$5:$D$130*(((Inputs!$G$5:$G$130="moeda")+(Inputs!$G$5:$G$130="acoes"))*Inputs!$B$1+((Inputs!$G$5:$G$130<>"moeda")*(Inputs!$G$5:$G$130<>"acoes")))*INDEX(Inputs!$K$5:$AJ$130,0,MATCH(F$2,Inputs!$K$4:$AJ$4,0)))+SUMPRODUCT((Inputs!$E$5:$E$130=$B4)*Inputs!$F$5:$F$130*(((Inputs!$G$5:$G$130="moeda")+(Inputs!$G$5:$G$130="acoes"))*Inputs!$B$1+((Inputs!$G$5:$G$130<>"moeda")*(Inputs!$G$5:$G$130<>"acoes")))*INDEX(Inputs!$K$5:$AJ$130,0,MATCH(F$2,Inputs!$K$4:$AJ$4,0))))) -> 11327 | G4: =IF(ISNA(MATCH(G$2,Inputs!$K$4:$AJ$4,0)),NA(),IF(SUMPRODUCT((Inputs!$A$5:$A$130=$B4)*ISNUMBER(INDEX(Inputs!$K$5:$AJ$130,0,MATCH(G$2,Inputs!$K$4:$AJ$4,0))))+SUMPRODUCT((Inputs!$C$5:$C$130=$B4)*ISNUMBER(INDEX(Inputs!$K$5:$AJ$130,0,MATCH(G$2,Inputs!$K$4:$AJ$4,0))))+SUMPRODUCT((Inputs!$E$5:$E$130=$B4)*ISNUMBER(INDEX(Inputs!$K$5:$AJ$130,0,MATCH(G$2,Inputs!$K$4:$AJ$4,0))))=0,NA(),SUMPRODUCT((Inputs!$A$5:$A$130=$B4)*Inputs!$B$5:$B$130*(((Inputs!$G$5:$G$130="moeda")+(Inputs!$G$5:$G$130="acoes"))*Inputs!$B$1+((Inputs!$G$5:$G$130<>"moeda")*(Inputs!$G$5:$G$130<>"acoes")))*INDEX(Inputs!$K$5:$AJ$130,0,MATCH(G$2,Inputs!$K$4:$AJ$4,0)))+SUMPRODUCT((Inputs!$C$5:$C$130=$B4)*Inputs!$D$5:$D$130*(((Inputs!$G$5:$G$130="moeda")+(Inputs!$G$5:$G$130="acoes"))*Inputs!$B$1+((Inputs!$G$5:$G$130<>"moeda")*(Inputs!$G$5:$G$130<>"acoes")))*INDEX(Inputs!$K$5:$AJ$130,0,MATCH(G$2,Inputs!$K$4:$AJ$4,0)))+SUMPRODUCT((Inputs!$E$5:$E$130=$B4)*Inputs!$F$5:$F$130*(((Inputs!$G$5:$G$130="moeda")+(Inputs!$G$5:$G$130="acoes"))*Inputs!$B$1+((Inputs!$G$5:$G$130<>"moeda")*(Inputs!$G$5:$G$130<>"acoes")))*INDEX(Inputs!$K$5:$AJ$130,0,MATCH(G$2,Inputs!$K$4:$AJ$4,0))))) -> 9569 | H4: =SUM(D4:G4) -> 44481 | I4: =IF(ISNA(MATCH(I$2,Inputs!$K$4:$AJ$4,0)),NA(),IF(SUMPRODUCT((Inputs!$A$5:$A$130=$B4)*ISNUMBER(INDEX(Inputs!$K$5:$AJ$130,0,MATCH(I$2,Inputs!$K$4:$AJ$4,0))))+SUMPRODUCT((Inputs!$C$5:$C$130=$B4)*ISNUMBER(INDEX(Inputs!$K$5:$AJ$130,0,MATCH(I$2,Inputs!$K$4:$AJ$4,0))))+SUMPRODUCT((Inputs!$E$5:$E$130=$B4)*ISNUMBER(INDEX(Inputs!$K$5:$AJ$130,0,MATCH(I$2,Inputs!$K$4:$AJ$4,0))))=0,NA(),SUMPRODUCT((Inputs!$A$5:$A$130=$B4)*Inputs!$B$5:$B$130*(((Inputs!$G$5:$G$130="moeda")+(Inputs!$G$5:$G$130="acoes"))*Inputs!$B$1+((Inputs!$G$5:$G$130<>"moeda")*(Inputs!$G$5:$G$130<>"acoes")))*INDEX(Inputs!$K$5:$AJ$130,0,MATCH(I$2,Inputs!$K$4:$AJ$4,0)))+SUMPRODUCT((Inputs!$C$5:$C$130=$B4)*Inputs!$D$5:$D$130*(((Inputs!$G$5:$G$130="moeda")+(Inputs!$G$5:$G$130="acoes"))*Inputs!$B$1+((Inputs!$G$5:$G$130<>"moeda")*(Inputs!$G$5:$G$130<>"acoes")))*INDEX(Inputs!$K$5:$AJ$130,0,MATCH(I$2,Inputs!$K$4:$AJ$4,0)))+SUMPRODUCT((Inputs!$E$5:$E$130=$B4)*Inputs!$F$5:$F$130*(((Inputs!$G$5:$G$130="moeda")+(Inputs!$G$5:$G$130="acoes"))*Inputs!$B$1+((Inputs!$G$5:$G$130<>"moeda")*(Inputs!$G$5:$G$130<>"acoes")))*INDEX(Inputs!$K$5:$AJ$130,0,MATCH(I$2,Inputs!$K$4:$AJ$4,0))))) -> 13370 | J4: =IF(ISNA(MATCH(J$2,Inputs!$K$4:$AJ$4,0)),NA(),IF(SUMPRODUCT((Inputs!$A$5:$A$130=$B4)*ISNUMBER(INDEX(Inputs!$K$5:$AJ$130,0,MATCH(J$2,Inputs!$K$4:$AJ$4,0))))+SUMPRODUCT((Inputs!$C$5:$C$130=$B4)*ISNUMBER(INDEX(Inputs!$K$5:$AJ$130,0,MATCH(J$2,Inputs!$K$4:$AJ$4,0))))+SUMPRODUCT((Inputs!$E$5:$E$130=$B4)*ISNUMBER(INDEX(Inputs!$K$5:$AJ$130,0,MATCH(J$2,Inputs!$K$4:$AJ$4,0))))=0,NA(),SUMPRODUCT((Inputs!$A$5:$A$130=$B4)*Inputs!$B$5:$B$130*(((Inputs!$G$5:$G$130="moeda")+(Inputs!$G$5:$G$130="acoes"))*Inputs!$B$1+((Inputs!$G$5:$G$130<>"moeda")*(Inputs!$G$5:$G$130<>"acoes")))*INDEX(Inputs!$K$5:$AJ$130,0,MATCH(J$2,Inputs!$K$4:$AJ$4,0)))+SUMPRODUCT((Inputs!$C$5:$C$130=$B4)*Inputs!$D$5:$D$130*(((Inputs!$G$5:$G$130="moeda")+(Inputs!$G$5:$G$130="acoes"))*Inputs!$B$1+((Inputs!$G$5:$G$130<>"moeda")*(Inputs!$G$5:$G$130<>"acoes")))*INDEX(Inputs!$K$5:$AJ$130,0,MATCH(J$2,Inputs!$K$4:$AJ$4,0)))+SUMPRODUCT((Inputs!$E$5:$E$130=$B4)*Inputs!$F$5:$F$130*(((Inputs!$G$5:$G$130="moeda")+(Inputs!$G$5:$G$130="acoes"))*Inputs!$B$1+((Inputs!$G$5:$G$130<>"moeda")*(Inputs!$G$5:$G$130<>"acoes")))*INDEX(Inputs!$K$5:$AJ$130,0,MATCH(J$2,Inputs!$K$4:$AJ$4,0))))) -> 14102 | K4: =IF(ISNA(MATCH(K$2,Inputs!$K$4:$AJ$4,0)),NA(),IF(SUMPRODUCT((Inputs!$A$5:$A$130=$B4)*ISNUMBER(INDEX(Inputs!$K$5:$AJ$130,0,MATCH(K$2,Inputs!$K$4:$AJ$4,0))))+SUMPRODUCT((Inputs!$C$5:$C$130=$B4)*ISNUMBER(INDEX(Inputs!$K$5:$AJ$130,0,MATCH(K$2,Inputs!$K$4:$AJ$4,0))))+SUMPRODUCT((Inputs!$E$5:$E$130=$B4)*ISNUMBER(INDEX(Inputs!$K$5:$AJ$130,0,MATCH(K$2,Inputs!$K$4:$AJ$4,0))))=0,NA(),SUMPRODUCT((Inputs!$A$5:$A$130=$B4)*Inputs!$B$5:$B$130*(((Inputs!$G$5:$G$130="moeda")+(Inputs!$G$5:$G$130="acoes"))*Inputs!$B$1+((Inputs!$G$5:$G$130<>"moeda")*(Inputs!$G$5:$G$130<>"acoes")))*INDEX(Inputs!$K$5:$AJ$130,0,MATCH(K$2,Inputs!$K$4:$AJ$4,0)))+SUMPRODUCT((Inputs!$C$5:$C$130=$B4)*Inputs!$D$5:$D$130*(((Inputs!$G$5:$G$130="moeda")+(Inputs!$G$5:$G$130="acoes"))*Inputs!$B$1+((Inputs!$G$5:$G$130<>"moeda")*(Inputs!$G$5:$G$130<>"acoes")))*INDEX(Inputs!$K$5:$AJ$130,0,MATCH(K$2,Inputs!$K$4:$AJ$4,0)))+SUMPRODUCT((Inputs!$E$5:$E$130=$B4)*Inputs!$F$5:$F$130*(((Inputs!$G$5:$G$130="moeda")+(Inputs!$G$5:$G$130="acoes"))*Inputs!$B$1+((Inputs!$G$5:$G$130<>"moeda")*(Inputs!$G$5:$G$130<>"acoes")))*INDEX(Inputs!$K$5:$AJ$130,0,MATCH(K$2,Inputs!$K$4:$AJ$4,0))))) -> 15536 | L4: =IF(ISNA(MATCH(L$2,Inputs!$K$4:$AJ$4,0)),NA(),IF(SUMPRODUCT((Inputs!$A$5:$A$130=$B4)*ISNUMBER(INDEX(Inputs!$K$5:$AJ$130,0,MATCH(L$2,Inputs!$K$4:$AJ$4,0))))+SUMPRODUCT((Inputs!$C$5:$C$130=$B4)*ISNUMBER(INDEX(Inputs!$K$5:$AJ$130,0,MATCH(L$2,Inputs!$K$4:$AJ$4,0))))+SUMPRODUCT((Inputs!$E$5:$E$130=$B4)*ISNUMBER(INDEX(Inputs!$K$5:$AJ$130,0,MATCH(L$2,Inputs!$K$4:$AJ$4,0))))=0,NA(),SUMPRODUCT((Inputs!$A$5:$A$130=$B4)*Inputs!$B$5:$B$130*(((Inputs!$G$5:$G$130="moeda")+(Inputs!$G$5:$G$130="acoes"))*Inputs!$B$1+((Inputs!$G$5:$G$130<>"moeda")*(Inputs!$G$5:$G$130<>"acoes")))*INDEX(Inputs!$K$5:$AJ$130,0,MATCH(L$2,Inputs!$K$4:$AJ$4,0)))+SUMPRODUCT((Inputs!$C$5:$C$130=$B4)*Inputs!$D$5:$D$130*(((Inputs!$G$5:$G$130="moeda")+(Inputs!$G$5:$G$130="acoes"))*Inputs!$B$1+((Inputs!$G$5:$G$130<>"moeda")*(Inputs!$G$5:$G$130<>"acoes")))*INDEX(Inputs!$K$5:$AJ$130,0,MATCH(L$2,Inputs!$K$4:$AJ$4,0)))+SUMPRODUCT((Inputs!$E$5:$E$130=$B4)*Inputs!$F$5:$F$130*(((Inputs!$G$5:$G$130="moeda")+(Inputs!$G$5:$G$130="acoes"))*Inputs!$B$1+((Inputs!$G$5:$G$130<>"moeda")*(Inputs!$G$5:$G$130<>"acoes")))*INDEX(Inputs!$K$5:$AJ$130,0,MATCH(L$2,Inputs!$K$4:$AJ$4,0))))) -> 12652 | M4: =SUM(I4:L4) -> 55660 | N4: =IF(ISNA(MATCH(N$2,Inputs!$K$4:$AJ$4,0)),NA(),IF(SUMPRODUCT((Inputs!$A$5:$A$130=$B4)*ISNUMBER(INDEX(Inputs!$K$5:$AJ$130,0,MATCH(N$2,Inputs!$K$4:$AJ$4,0))))+SUMPRODUCT((Inputs!$C$5:$C$130=$B4)*ISNUMBER(INDEX(Inputs!$K$5:$AJ$130,0,MATCH(N$2,Inputs!$K$4:$AJ$4,0))))+SUMPRODUCT((Inputs!$E$5:$E$130=$B4)*ISNUMBER(INDEX(Inputs!$K$5:$AJ$130,0,MATCH(N$2,Inputs!$K$4:$AJ$4,0))))=0,NA(),SUMPRODUCT((Inputs!$A$5:$A$130=$B4)*Inputs!$B$5:$B$130*(((Inputs!$G$5:$G$130="moeda")+(Inputs!$G$5:$G$130="acoes"))*Inputs!$B$1+((Inputs!$G$5:$G$130<>"moeda")*(Inputs!$G$5:$G$130<>"acoes")))*INDEX(Inputs!$K$5:$AJ$130,0,MATCH(N$2,Inputs!$K$4:$AJ$4,0)))+SUMPRODUCT((Inputs!$C$5:$C$130=$B4)*Inputs!$D$5:$D$130*(((Inputs!$G$5:$G$130="moeda")+(Inputs!$G$5:$G$130="acoes"))*Inputs!$B$1+((Inputs!$G$5:$G$130<>"moeda")*(Inputs!$G$5:$G$130<>"acoes")))*INDEX(Inputs!$K$5:$AJ$130,0,MATCH(N$2,Inputs!$K$4:$AJ$4,0)))+SUMPRODUCT((Inputs!$E$5:$E$130=$B4)*Inputs!$F$5:$F$130*(((Inputs!$G$5:$G$130="moeda")+(Inputs!$G$5:$G$130="acoes"))*Inputs!$B$1+((Inputs!$G$5:$G$130<>"moeda")*(Inputs!$G$5:$G$130<>"acoes")))*INDEX(Inputs!$K$5:$AJ$130,0,MATCH(N$2,Inputs!$K$4:$AJ$4,0))))) -> 17387 | O4: =IF(ISNA(MATCH(O$2,Inputs!$K$4:$AJ$4,0)),NA(),IF(SUMPRODUCT((Inputs!$A$5:$A$130=$B4)*ISNUMBER(INDEX(Inputs!$K$5:$AJ$130,0,MATCH(O$2,Inputs!$K$4:$AJ$4,0))))+SUMPRODUCT((Inputs!$C$5:$C$130=$B4)*ISNUMBER(INDEX(Inputs!$K$5:$AJ$130,0,MATCH(O$2,Inputs!$K$4:$AJ$4,0))))+SUMPRODUCT((Inputs!$E$5:$E$130=$B4)*ISNUMBER(INDEX(Inputs!$K$5:$AJ$130,0,MATCH(O$2,Inputs!$K$4:$AJ$4,0))))=0,NA(),SUMPRODUCT((Inputs!$A$5:$A$130=$B4)*Inputs!$B$5:$B$130*(((Inputs!$G$5:$G$130="moeda")+(Inputs!$G$5:$G$130="acoes"))*Inputs!$B$1+((Inputs!$G$5:$G$130<>"moeda")*(Inputs!$G$5:$G$130<>"acoes")))*INDEX(Inputs!$K$5:$AJ$130,0,MATCH(O$2,Inputs!$K$4:$AJ$4,0)))+SUMPRODUCT((Inputs!$C$5:$C$130=$B4)*Inputs!$D$5:$D$130*(((Inputs!$G$5:$G$130="moeda")+(Inputs!$G$5:$G$130="acoes"))*Inputs!$B$1+((Inputs!$G$5:$G$130<>"moeda")*(Inputs!$G$5:$G$130<>"acoes")))*INDEX(Inputs!$K$5:$AJ$130,0,MATCH(O$2,Inputs!$K$4:$AJ$4,0)))+SUMPRODUCT((Inputs!$E$5:$E$130=$B4)*Inputs!$F$5:$F$130*(((Inputs!$G$5:$G$130="moeda")+(Inputs!$G$5:$G$130="acoes"))*Inputs!$B$1+((Inputs!$G$5:$G$130<>"moeda")*(Inputs!$G$5:$G$130<>"acoes")))*INDEX(Inputs!$K$5:$AJ$130,0,MATCH(O$2,Inputs!$K$4:$AJ$4,0))))) -> 15801 | P4: =IF(ISNA(MATCH(P$2,Inputs!$K$4:$AJ$4,0)),NA(),IF(SUMPRODUCT((Inputs!$A$5:$A$130=$B4)*ISNUMBER(INDEX(Inputs!$K$5:$AJ$130,0,MATCH(P$2,Inputs!$K$4:$AJ$4,0))))+SUMPRODUCT((Inputs!$C$5:$C$130=$B4)*ISNUMBER(INDEX(Inputs!$K$5:$AJ$130,0,MATCH(P$2,Inputs!$K$4:$AJ$4,0))))+SUMPRODUCT((Inputs!$E$5:$E$130=$B4)*ISNUMBER(INDEX(Inputs!$K$5:$AJ$130,0,MATCH(P$2,Inputs!$K$4:$AJ$4,0))))=0,NA(),SUMPRODUCT((Inputs!$A$5:$A$130=$B4)*Inputs!$B$5:$B$130*(((Inputs!$G$5:$G$130="moeda")+(Inputs!$G$5:$G$130="acoes"))*Inputs!$B$1+((Inputs!$G$5:$G$130<>"moeda")*(Inputs!$G$5:$G$130<>"acoes")))*INDEX(Inputs!$K$5:$AJ$130,0,MATCH(P$2,Inputs!$K$4:$AJ$4,0)))+SUMPRODUCT((Inputs!$C$5:$C$130=$B4)*Inputs!$D$5:$D$130*(((Inputs!$G$5:$G$130="moeda")+(Inputs!$G$5:$G$130="acoes"))*Inputs!$B$1+((Inputs!$G$5:$G$130<>"moeda")*(Inputs!$G$5:$G$130<>"acoes")))*INDEX(Inputs!$K$5:$AJ$130,0,MATCH(P$2,Inputs!$K$4:$AJ$4,0)))+SUMPRODUCT((Inputs!$E$5:$E$130=$B4)*Inputs!$F$5:$F$130*(((Inputs!$G$5:$G$130="moeda")+(Inputs!$G$5:$G$130="acoes"))*Inputs!$B$1+((Inputs!$G$5:$G$130<>"moeda")*(Inputs!$G$5:$G$130<>"acoes")))*INDEX(Inputs!$K$5:$AJ$130,0,MATCH(P$2,Inputs!$K$4:$AJ$4,0))))) -> 15412 | Q4: =IF(ISNA(MATCH(Q$2,Inputs!$K$4:$AJ$4,0)),NA(),IF(SUMPRODUCT((Inputs!$A$5:$A$130=$B4)*ISNUMBER(INDEX(Inputs!$K$5:$AJ$130,0,MATCH(Q$2,Inputs!$K$4:$AJ$4,0))))+SUMPRODUCT((Inputs!$C$5:$C$130=$B4)*ISNUMBER(INDEX(Inputs!$K$5:$AJ$130,0,MATCH(Q$2,Inputs!$K$4:$AJ$4,0))))+SUMPRODUCT((Inputs!$E$5:$E$130=$B4)*ISNUMBER(INDEX(Inputs!$K$5:$AJ$130,0,MATCH(Q$2,Inputs!$K$4:$AJ$4,0))))=0,NA(),SUMPRODUCT((Inputs!$A$5:$A$130=$B4)*Inputs!$B$5:$B$130*(((Inputs!$G$5:$G$130="moeda")+(Inputs!$G$5:$G$130="acoes"))*Inputs!$B$1+((Inputs!$G$5:$G$130<>"moeda")*(Inputs!$G$5:$G$130<>"acoes")))*INDEX(Inputs!$K$5:$AJ$130,0,MATCH(Q$2,Inputs!$K$4:$AJ$4,0)))+SUMPRODUCT((Inputs!$C$5:$C$130=$B4)*Inputs!$D$5:$D$130*(((Inputs!$G$5:$G$130="moeda")+(Inputs!$G$5:$G$130="acoes"))*Inputs!$B$1+((Inputs!$G$5:$G$130<>"moeda")*(Inputs!$G$5:$G$130<>"acoes")))*INDEX(Inputs!$K$5:$AJ$130,0,MATCH(Q$2,Inputs!$K$4:$AJ$4,0)))+SUMPRODUCT((Inputs!$E$5:$E$130=$B4)*Inputs!$F$5:$F$130*(((Inputs!$G$5:$G$130="moeda")+(Inputs!$G$5:$G$130="acoes"))*Inputs!$B$1+((Inputs!$G$5:$G$130<>"moeda")*(Inputs!$G$5:$G$130<>"acoes")))*INDEX(Inputs!$K$5:$AJ$130,0,MATCH(Q$2,Inputs!$K$4:$AJ$4,0))))) -> 12185 | R4: =SUM(N4:Q4) -> 60785 | S4: =IF(ISNA(MATCH(S$2,Inputs!$K$4:$AJ$4,0)),NA(),IF(SUMPRODUCT((Inputs!$A$5:$A$130=$B4)*ISNUMBER(INDEX(Inputs!$K$5:$AJ$130,0,MATCH(S$2,Inputs!$K$4:$AJ$4,0))))+SUMPRODUCT((Inputs!$C$5:$C$130=$B4)*ISNUMBER(INDEX(Inputs!$K$5:$AJ$130,0,MATCH(S$2,Inputs!$K$4:$AJ$4,0))))+SUMPRODUCT((Inputs!$E$5:$E$130=$B4)*ISNUMBER(INDEX(Inputs!$K$5:$AJ$130,0,MATCH(S$2,Inputs!$K$4:$AJ$4,0))))=0,NA(),SUMPRODUCT((Inputs!$A$5:$A$130=$B4)*Inputs!$B$5:$B$130*(((Inputs!$G$5:$G$130="moeda")+(Inputs!$G$5:$G$130="acoes"))*Inputs!$B$1+((Inputs!$G$5:$G$130<>"moeda")*(Inputs!$G$5:$G$130<>"acoes")))*INDEX(Inputs!$K$5:$AJ$130,0,MATCH(S$2,Inputs!$K$4:$AJ$4,0)))+SUMPRODUCT((Inputs!$C$5:$C$130=$B4)*Inputs!$D$5:$D$130*(((Inputs!$G$5:$G$130="moeda")+(Inputs!$G$5:$G$130="acoes"))*Inputs!$B$1+((Inputs!$G$5:$G$130<>"moeda")*(Inputs!$G$5:$G$130<>"acoes")))*INDEX(Inputs!$K$5:$AJ$130,0,MATCH(S$2,Inputs!$K$4:$AJ$4,0)))+SUMPRODUCT((Inputs!$E$5:$E$130=$B4)*Inputs!$F$5:$F$130*(((Inputs!$G$5:$G$130="moeda")+(Inputs!$G$5:$G$130="acoes"))*Inputs!$B$1+((Inputs!$G$5:$G$130<>"moeda")*(Inputs!$G$5:$G$130<>"acoes")))*INDEX(Inputs!$K$5:$AJ$130,0,MATCH(S$2,Inputs!$K$4:$AJ$4,0))))) -> 15235 | T4: =IF(ISNA(MATCH(T$2,Inputs!$K$4:$AJ$4,0)),NA(),IF(SUMPRODUCT((Inputs!$A$5:$A$130=$B4)*ISNUMBER(INDEX(Inputs!$K$5:$AJ$130,0,MATCH(T$2,Inputs!$K$4:$AJ$4,0))))+SUMPRODUCT((Inputs!$C$5:$C$130=$B4)*ISNUMBER(INDEX(Inputs!$K$5:$AJ$130,0,MATCH(T$2,Inputs!$K$4:$AJ$4,0))))+SUMPRODUCT((Inputs!$E$5:$E$130=$B4)*ISNUMBER(INDEX(Inputs!$K$5:$AJ$130,0,MATCH(T$2,Inputs!$K$4:$AJ$4,0))))=0,NA(),SUMPRODUCT((Inputs!$A$5:$A$130=$B4)*Inputs!$B$5:$B$130*(((Inputs!$G$5:$G$130="moeda")+(Inputs!$G$5:$G$130="acoes"))*Inputs!$B$1+((Inputs!$G$5:$G$130<>"moeda")*(Inputs!$G$5:$G$130<>"acoes")))*INDEX(Inputs!$K$5:$AJ$130,0,MATCH(T$2,Inputs!$K$4:$AJ$4,0)))+SUMPRODUCT((Inputs!$C$5:$C$130=$B4)*Inputs!$D$5:$D$130*(((Inputs!$G$5:$G$130="moeda")+(Inputs!$G$5:$G$130="acoes"))*Inputs!$B$1+((Inputs!$G$5:$G$130<>"moeda")*(Inputs!$G$5:$G$130<>"acoes")))*INDEX(Inputs!$K$5:$AJ$130,0,MATCH(T$2,Inputs!$K$4:$AJ$4,0)))+SUMPRODUCT((Inputs!$E$5:$E$130=$B4)*Inputs!$F$5:$F$130*(((Inputs!$G$5:$G$130="moeda")+(Inputs!$G$5:$G$130="acoes"))*Inputs!$B$1+((Inputs!$G$5:$G$130<>"moeda")*(Inputs!$G$5:$G$130<>"acoes")))*INDEX(Inputs!$K$5:$AJ$130,0,MATCH(T$2,Inputs!$K$4:$AJ$4,0))))) -> 13152 | U4: =IF(ISNA(MATCH(U$2,Inputs!$K$4:$AJ$4,0)),NA(),IF(SUMPRODUCT((Inputs!$A$5:$A$130=$B4)*ISNUMBER(INDEX(Inputs!$K$5:$AJ$130,0,MATCH(U$2,Inputs!$K$4:$AJ$4,0))))+SUMPRODUCT((Inputs!$C$5:$C$130=$B4)*ISNUMBER(INDEX(Inputs!$K$5:$AJ$130,0,MATCH(U$2,Inputs!$K$4:$AJ$4,0))))+SUMPRODUCT((Inputs!$E$5:$E$130=$B4)*ISNUMBER(INDEX(Inputs!$K$5:$AJ$130,0,MATCH(U$2,Inputs!$K$4:$AJ$4,0))))=0,NA(),SUMPRODUCT((Inputs!$A$5:$A$130=$B4)*Inputs!$B$5:$B$130*(((Inputs!$G$5:$G$130="moeda")+(Inputs!$G$5:$G$130="acoes"))*Inputs!$B$1+((Inputs!$G$5:$G$130<>"moeda")*(Inputs!$G$5:$G$130<>"acoes")))*INDEX(Inputs!$K$5:$AJ$130,0,MATCH(U$2,Inputs!$K$4:$AJ$4,0)))+SUMPRODUCT((Inputs!$C$5:$C$130=$B4)*Inputs!$D$5:$D$130*(((Inputs!$G$5:$G$130="moeda")+(Inputs!$G$5:$G$130="acoes"))*Inputs!$B$1+((Inputs!$G$5:$G$130<>"moeda")*(Inputs!$G$5:$G$130<>"acoes")))*INDEX(Inputs!$K$5:$AJ$130,0,MATCH(U$2,Inputs!$K$4:$AJ$4,0)))+SUMPRODUCT((Inputs!$E$5:$E$130=$B4)*Inputs!$F$5:$F$130*(((Inputs!$G$5:$G$130="moeda")+(Inputs!$G$5:$G$130="acoes"))*Inputs!$B$1+((Inputs!$G$5:$G$130<>"moeda")*(Inputs!$G$5:$G$130<>"acoes")))*INDEX(Inputs!$K$5:$AJ$130,0,MATCH(U$2,Inputs!$K$4:$AJ$4,0))))) -> 11144 | V4: =IF(ISNA(MATCH(V$2,Inputs!$K$4:$AJ$4,0)),NA(),IF(SUMPRODUCT((Inputs!$A$5:$A$130=$B4)*ISNUMBER(INDEX(Inputs!$K$5:$AJ$130,0,MATCH(V$2,Inputs!$K$4:$AJ$4,0))))+SUMPRODUCT((Inputs!$C$5:$C$130=$B4)*ISNUMBER(INDEX(Inputs!$K$5:$AJ$130,0,MATCH(V$2,Inputs!$K$4:$AJ$4,0))))+SUMPRODUCT((Inputs!$E$5:$E$130=$B4)*ISNUMBER(INDEX(Inputs!$K$5:$AJ$130,0,MATCH(V$2,Inputs!$K$4:$AJ$4,0))))=0,NA(),SUMPRODUCT((Inputs!$A$5:$A$130=$B4)*Inputs!$B$5:$B$130*(((Inputs!$G$5:$G$130="moeda")+(Inputs!$G$5:$G$130="acoes"))*Inputs!$B$1+((Inputs!$G$5:$G$130<>"moeda")*(Inputs!$G$5:$G$130<>"acoes")))*INDEX(Inputs!$K$5:$AJ$130,0,MATCH(V$2,Inputs!$K$4:$AJ$4,0)))+SUMPRODUCT((Inputs!$C$5:$C$130=$B4)*Inputs!$D$5:$D$130*(((Inputs!$G$5:$G$130="moeda")+(Inputs!$G$5:$G$130="acoes"))*Inputs!$B$1+((Inputs!$G$5:$G$130<>"moeda")*(Inputs!$G$5:$G$130<>"acoes")))*INDEX(Inputs!$K$5:$AJ$130,0,MATCH(V$2,Inputs!$K$4:$AJ$4,0)))+SUMPRODUCT((Inputs!$E$5:$E$130=$B4)*Inputs!$F$5:$F$130*(((Inputs!$G$5:$G$130="moeda")+(Inputs!$G$5:$G$130="acoes"))*Inputs!$B$1+((Inputs!$G$5:$G$130<>"moeda")*(Inputs!$G$5:$G$130<>"acoes")))*INDEX(Inputs!$K$5:$AJ$130,0,MATCH(V$2,Inputs!$K$4:$AJ$4,0))))) -> 8508 | W4: =SUM(S4:V4) -> 48039 | X4: =IF(ISNA(MATCH(X$2,Inputs!$K$4:$AJ$4,0)),NA(),IF(SUMPRODUCT((Inputs!$A$5:$A$130=$B4)*ISNUMBER(INDEX(Inputs!$K$5:$AJ$130,0,MATCH(X$2,Inputs!$K$4:$AJ$4,0))))+SUMPRODUCT((Inputs!$C$5:$C$130=$B4)*ISNUMBER(INDEX(Inputs!$K$5:$AJ$130,0,MATCH(X$2,Inputs!$K$4:$AJ$4,0))))+SUMPRODUCT((Inputs!$E$5:$E$130=$B4)*ISNUMBER(INDEX(Inputs!$K$5:$AJ$130,0,MATCH(X$2,Inputs!$K$4:$AJ$4,0))))=0,NA(),SUMPRODUCT((Inputs!$A$5:$A$130=$B4)*Inputs!$B$5:$B$130*(((Inputs!$G$5:$G$130="moeda")+(Inputs!$G$5:$G$130="acoes"))*Inputs!$B$1+((Inputs!$G$5:$G$130<>"moeda")*(Inputs!$G$5:$G$130<>"acoes")))*INDEX(Inputs!$K$5:$AJ$130,0,MATCH(X$2,Inputs!$K$4:$AJ$4,0)))+SUMPRODUCT((Inputs!$C$5:$C$130=$B4)*Inputs!$D$5:$D$130*(((Inputs!$G$5:$G$130="moeda")+(Inputs!$G$5:$G$130="acoes"))*Inputs!$B$1+((Inputs!$G$5:$G$130<>"moeda")*(Inputs!$G$5:$G$130<>"acoes")))*INDEX(Inputs!$K$5:$AJ$130,0,MATCH(X$2,Inputs!$K$4:$AJ$4,0)))+SUMPRODUCT((Inputs!$E$5:$E$130=$B4)*Inputs!$F$5:$F$130*(((Inputs!$G$5:$G$130="moeda")+(Inputs!$G$5:$G$130="acoes"))*Inputs!$B$1+((Inputs!$G$5:$G$130<>"moeda")*(Inputs!$G$5:$G$130<>"acoes")))*INDEX(Inputs!$K$5:$AJ$130,0,MATCH(X$2,Inputs!$K$4:$AJ$4,0))))) -> 12763 | Y4: =IF(ISNA(MATCH(Y$2,Inputs!$K$4:$AJ$4,0)),NA(),IF(SUMPRODUCT((Inputs!$A$5:$A$130=$B4)*ISNUMBER(INDEX(Inputs!$K$5:$AJ$130,0,MATCH(Y$2,Inputs!$K$4:$AJ$4,0))))+SUMPRODUCT((Inputs!$C$5:$C$130=$B4)*ISNUMBER(INDEX(Inputs!$K$5:$AJ$130,0,MATCH(Y$2,Inputs!$K$4:$AJ$4,0))))+SUMPRODUCT((Inputs!$E$5:$E$130=$B4)*ISNUMBER(INDEX(Inputs!$K$5:$AJ$130,0,MATCH(Y$2,Inputs!$K$4:$AJ$4,0))))=0,NA(),SUMPRODUCT((Inputs!$A$5:$A$130=$B4)*Inputs!$B$5:$B$130*(((Inputs!$G$5:$G$130="moeda")+(Inputs!$G$5:$G$130="acoes"))*Inputs!$B$1+((Inputs!$G$5:$G$130<>"moeda")*(Inputs!$G$5:$G$130<>"acoes")))*INDEX(Inputs!$K$5:$AJ$130,0,MATCH(Y$2,Inputs!$K$4:$AJ$4,0)))+SUMPRODUCT((Inputs!$C$5:$C$130=$B4)*Inputs!$D$5:$D$130*(((Inputs!$G$5:$G$130="moeda")+(Inputs!$G$5:$G$130="acoes"))*Inputs!$B$1+((Inputs!$G$5:$G$130<>"moeda")*(Inputs!$G$5:$G$130<>"acoes")))*INDEX(Inputs!$K$5:$AJ$130,0,MATCH(Y$2,Inputs!$K$4:$AJ$4,0)))+SUMPRODUCT((Inputs!$E$5:$E$130=$B4)*Inputs!$F$5:$F$130*(((Inputs!$G$5:$G$130="moeda")+(Inputs!$G$5:$G$130="acoes"))*Inputs!$B$1+((Inputs!$G$5:$G$130<>"moeda")*(Inputs!$G$5:$G$130<>"acoes")))*INDEX(Inputs!$K$5:$AJ$130,0,MATCH(Y$2,Inputs!$K$4:$AJ$4,0))))) -> 12018 | Z4: =IF(ISNA(MATCH(Z$2,Inputs!$K$4:$AJ$4,0)),NA(),IF(SUMPRODUCT((Inputs!$A$5:$A$130=$B4)*ISNUMBER(INDEX(Inputs!$K$5:$AJ$130,0,MATCH(Z$2,Inputs!$K$4:$AJ$4,0))))+SUMPRODUCT((Inputs!$C$5:$C$130=$B4)*ISNUMBER(INDEX(Inputs!$K$5:$AJ$130,0,MATCH(Z$2,Inputs!$K$4:$AJ$4,0))))+SUMPRODUCT((Inputs!$E$5:$E$130=$B4)*ISNUMBER(INDEX(Inputs!$K$5:$AJ$130,0,MATCH(Z$2,Inputs!$K$4:$AJ$4,0))))=0,NA(),SUMPRODUCT((Inputs!$A$5:$A$130=$B4)*Inputs!$B$5:$B$130*(((Inputs!$G$5:$G$130="moeda")+(Inputs!$G$5:$G$130="acoes"))*Inputs!$B$1+((Inputs!$G$5:$G$130<>"moeda")*(Inputs!$G$5:$G$130<>"acoes")))*INDEX(Inputs!$K$5:$AJ$130,0,MATCH(Z$2,Inputs!$K$4:$AJ$4,0)))+SUMPRODUCT((Inputs!$C$5:$C$130=$B4)*Inputs!$D$5:$D$130*(((Inputs!$G$5:$G$130="moeda")+(Inputs!$G$5:$G$130="acoes"))*Inputs!$B$1+((Inputs!$G$5:$G$130<>"moeda")*(Inputs!$G$5:$G$130<>"acoes")))*INDEX(Inputs!$K$5:$AJ$130,0,MATCH(Z$2,Inputs!$K$4:$AJ$4,0)))+SUMPRODUCT((Inputs!$E$5:$E$130=$B4)*Inputs!$F$5:$F$130*(((Inputs!$G$5:$G$130="moeda")+(Inputs!$G$5:$G$130="acoes"))*Inputs!$B$1+((Inputs!$G$5:$G$130<>"moeda")*(Inputs!$G$5:$G$130<>"acoes")))*INDEX(Inputs!$K$5:$AJ$130,0,MATCH(Z$2,Inputs!$K$4:$AJ$4,0))))) -> 12394 | AA4: =IF(ISNA(MATCH(AA$2,Inputs!$K$4:$AJ$4,0)),NA(),IF(SUMPRODUCT((Inputs!$A$5:$A$130=$B4)*ISNUMBER(INDEX(Inputs!$K$5:$AJ$130,0,MATCH(AA$2,Inputs!$K$4:$AJ$4,0))))+SUMPRODUCT((Inputs!$C$5:$C$130=$B4)*ISNUMBER(INDEX(Inputs!$K$5:$AJ$130,0,MATCH(AA$2,Inputs!$K$4:$AJ$4,0))))+SUMPRODUCT((Inputs!$E$5:$E$130=$B4)*ISNUMBER(INDEX(Inputs!$K$5:$AJ$130,0,MATCH(AA$2,Inputs!$K$4:$AJ$4,0))))=0,NA(),SUMPRODUCT((Inputs!$A$5:$A$130=$B4)*Inputs!$B$5:$B$130*(((Inputs!$G$5:$G$130="moeda")+(Inputs!$G$5:$G$130="acoes"))*Inputs!$B$1+((Inputs!$G$5:$G$130<>"moeda")*(Inputs!$G$5:$G$130<>"acoes")))*INDEX(Inputs!$K$5:$AJ$130,0,MATCH(AA$2,Inputs!$K$4:$AJ$4,0)))+SUMPRODUCT((Inputs!$C$5:$C$130=$B4)*Inputs!$D$5:$D$130*(((Inputs!$G$5:$G$130="moeda")+(Inputs!$G$5:$G$130="acoes"))*Inputs!$B$1+((Inputs!$G$5:$G$130<>"moeda")*(Inputs!$G$5:$G$130<>"acoes")))*INDEX(Inputs!$K$5:$AJ$130,0,MATCH(AA$2,Inputs!$K$4:$AJ$4,0)))+SUMPRODUCT((Inputs!$E$5:$E$130=$B4)*Inputs!$F$5:$F$130*(((Inputs!$G$5:$G$130="moeda")+(Inputs!$G$5:$G$130="acoes"))*Inputs!$B$1+((Inputs!$G$5:$G$130<>"moeda")*(Inputs!$G$5:$G$130<>"acoes")))*INDEX(Inputs!$K$5:$AJ$130,0,MATCH(AA$2,Inputs!$K$4:$AJ$4,0))))) -> 9611 | AB4: =SUM(X4:AA4) -> 46786 | AC4: =IF(ISNA(MATCH(AC$2,Inputs!$K$4:$AJ$4,0)),NA(),IF(SUMPRODUCT((Inputs!$A$5:$A$130=$B4)*ISNUMBER(INDEX(Inputs!$K$5:$AJ$130,0,MATCH(AC$2,Inputs!$K$4:$AJ$4,0))))+SUMPRODUCT((Inputs!$C$5:$C$130=$B4)*ISNUMBER(INDEX(Inputs!$K$5:$AJ$130,0,MATCH(AC$2,Inputs!$K$4:$AJ$4,0))))+SUMPRODUCT((Inputs!$E$5:$E$130=$B4)*ISNUMBER(INDEX(Inputs!$K$5:$AJ$130,0,MATCH(AC$2,Inputs!$K$4:$AJ$4,0))))=0,NA(),SUMPRODUCT((Inputs!$A$5:$A$130=$B4)*Inputs!$B$5:$B$130*(((Inputs!$G$5:$G$130="moeda")+(Inputs!$G$5:$G$130="acoes"))*Inputs!$B$1+((Inputs!$G$5:$G$130<>"moeda")*(Inputs!$G$5:$G$130<>"acoes")))*INDEX(Inputs!$K$5:$AJ$130,0,MATCH(AC$2,Inputs!$K$4:$AJ$4,0)))+SUMPRODUCT((Inputs!$C$5:$C$130=$B4)*Inputs!$D$5:$D$130*(((Inputs!$G$5:$G$130="moeda")+(Inputs!$G$5:$G$130="acoes"))*Inputs!$B$1+((Inputs!$G$5:$G$130<>"moeda")*(Inputs!$G$5:$G$130<>"acoes")))*INDEX(Inputs!$K$5:$AJ$130,0,MATCH(AC$2,Inputs!$K$4:$AJ$4,0)))+SUMPRODUCT((Inputs!$E$5:$E$130=$B4)*Inputs!$F$5:$F$130*(((Inputs!$G$5:$G$130="moeda")+(Inputs!$G$5:$G$130="acoes"))*Inputs!$B$1+((Inputs!$G$5:$G$130<>"moeda")*(Inputs!$G$5:$G$130<>"acoes")))*INDEX(Inputs!$K$5:$AJ$130,0,MATCH(AC$2,Inputs!$K$4:$AJ$4,0))))) -> 13369 | AD4: =IF(ISNA(MATCH(AD$2,Inputs!$K$4:$AJ$4,0)),NA(),IF(SUMPRODUCT((Inputs!$A$5:$A$130=$B4)*ISNUMBER(INDEX(Inputs!$K$5:$AJ$130,0,MATCH(AD$2,Inputs!$K$4:$AJ$4,0))))+SUMPRODUCT((Inputs!$C$5:$C$130=$B4)*ISNUMBER(INDEX(Inputs!$K$5:$AJ$130,0,MATCH(AD$2,Inputs!$K$4:$AJ$4,0))))+SUMPRODUCT((Inputs!$E$5:$E$130=$B4)*ISNUMBER(INDEX(Inputs!$K$5:$AJ$130,0,MATCH(AD$2,Inputs!$K$4:$AJ$4,0))))=0,NA(),SUMPRODUCT((Inputs!$A$5:$A$130=$B4)*Inputs!$B$5:$B$130*(((Inputs!$G$5:$G$130="moeda")+(Inputs!$G$5:$G$130="acoes"))*Inputs!$B$1+((Inputs!$G$5:$G$130<>"moeda")*(Inputs!$G$5:$G$130<>"acoes")))*INDEX(Inputs!$K$5:$AJ$130,0,MATCH(AD$2,Inputs!$K$4:$AJ$4,0)))+SUMPRODUCT((Inputs!$C$5:$C$130=$B4)*Inputs!$D$5:$D$130*(((Inputs!$G$5:$G$130="moeda")+(Inputs!$G$5:$G$130="acoes"))*Inputs!$B$1+((Inputs!$G$5:$G$130<>"moeda")*(Inputs!$G$5:$G$130<>"acoes")))*INDEX(Inputs!$K$5:$AJ$130,0,MATCH(AD$2,Inputs!$K$4:$AJ$4,0)))+SUMPRODUCT((Inputs!$E$5:$E$130=$B4)*Inputs!$F$5:$F$130*(((Inputs!$G$5:$G$130="moeda")+(Inputs!$G$5:$G$130="acoes"))*Inputs!$B$1+((Inputs!$G$5:$G$130<>"moeda")*(Inputs!$G$5:$G$130<>"acoes")))*INDEX(Inputs!$K$5:$AJ$130,0,MATCH(AD$2,Inputs!$K$4:$AJ$4,0))))) -> 12608 | AE4: =IF(ISNA(MATCH(AE$2,Inputs!$K$4:$AJ$4,0)),NA(),IF(SUMPRODUCT((Inputs!$A$5:$A$130=$B4)*ISNUMBER(INDEX(Inputs!$K$5:$AJ$130,0,MATCH(AE$2,Inputs!$K$4:$AJ$4,0))))+SUMPRODUCT((Inputs!$C$5:$C$130=$B4)*ISNUMBER(INDEX(Inputs!$K$5:$AJ$130,0,MATCH(AE$2,Inputs!$K$4:$AJ$4,0))))+SUMPRODUCT((Inputs!$E$5:$E$130=$B4)*ISNUMBER(INDEX(Inputs!$K$5:$AJ$130,0,MATCH(AE$2,Inputs!$K$4:$AJ$4,0))))=0,NA(),SUMPRODUCT((Inputs!$A$5:$A$130=$B4)*Inputs!$B$5:$B$130*(((Inputs!$G$5:$G$130="moeda")+(Inputs!$G$5:$G$130="acoes"))*Inputs!$B$1+((Inputs!$G$5:$G$130<>"moeda")*(Inputs!$G$5:$G$130<>"acoes")))*INDEX(Inputs!$K$5:$AJ$130,0,MATCH(AE$2,Inputs!$K$4:$AJ$4,0)))+SUMPRODUCT((Inputs!$C$5:$C$130=$B4)*Inputs!$D$5:$D$130*(((Inputs!$G$5:$G$130="moeda")+(Inputs!$G$5:$G$130="acoes"))*Inputs!$B$1+((Inputs!$G$5:$G$130<>"moeda")*(Inputs!$G$5:$G$130<>"acoes")))*INDEX(Inputs!$K$5:$AJ$130,0,MATCH(AE$2,Inputs!$K$4:$AJ$4,0)))+SUMPRODUCT((Inputs!$E$5:$E$130=$B4)*Inputs!$F$5:$F$130*(((Inputs!$G$5:$G$130="moeda")+(Inputs!$G$5:$G$130="acoes"))*Inputs!$B$1+((Inputs!$G$5:$G$130<>"moeda")*(Inputs!$G$5:$G$130<>"acoes")))*INDEX(Inputs!$K$5:$AJ$130,0,MATCH(AE$2,Inputs!$K$4:$AJ$4,0))))) -> #N/A | AF4: =IF(ISNA(MATCH(AF$2,Inputs!$K$4:$AJ$4,0)),NA(),IF(SUMPRODUCT((Inputs!$A$5:$A$130=$B4)*ISNUMBER(INDEX(Inputs!$K$5:$AJ$130,0,MATCH(AF$2,Inputs!$K$4:$AJ$4,0))))+SUMPRODUCT((Inputs!$C$5:$C$130=$B4)*ISNUMBER(INDEX(Inputs!$K$5:$AJ$130,0,MATCH(AF$2,Inputs!$K$4:$AJ$4,0))))+SUMPRODUCT((Inputs!$E$5:$E$130=$B4)*ISNUMBER(INDEX(Inputs!$K$5:$AJ$130,0,MATCH(AF$2,Inputs!$K$4:$AJ$4,0))))=0,NA(),SUMPRODUCT((Inputs!$A$5:$A$130=$B4)*Inputs!$B$5:$B$130*(((Inputs!$G$5:$G$130="moeda")+(Inputs!$G$5:$G$130="acoes"))*Inputs!$B$1+((Inputs!$G$5:$G$130<>"moeda")*(Inputs!$G$5:$G$130<>"acoes")))*INDEX(Inputs!$K$5:$AJ$130,0,MATCH(AF$2,Inputs!$K$4:$AJ$4,0)))+SUMPRODUCT((Inputs!$C$5:$C$130=$B4)*Inputs!$D$5:$D$130*(((Inputs!$G$5:$G$130="moeda")+(Inputs!$G$5:$G$130="acoes"))*Inputs!$B$1+((Inputs!$G$5:$G$130<>"moeda")*(Inputs!$G$5:$G$130<>"acoes")))*INDEX(Inputs!$K$5:$AJ$130,0,MATCH(AF$2,Inputs!$K$4:$AJ$4,0)))+SUMPRODUCT((Inputs!$E$5:$E$130=$B4)*Inputs!$F$5:$F$130*(((Inputs!$G$5:$G$130="moeda")+(Inputs!$G$5:$G$130="acoes"))*Inputs!$B$1+((Inputs!$G$5:$G$130<>"moeda")*(Inputs!$G$5:$G$130<>"acoes")))*INDEX(Inputs!$K$5:$AJ$130,0,MATCH(AF$2,Inputs!$K$4:$AJ$4,0))))) -> #N/A | AG4: =SUM(AC4:AF4) -> #N/A | AH4: =IF(ISNA(MATCH(AH$2,Inputs!$K$4:$AJ$4,0)),NA(),IF(SUMPRODUCT((Inputs!$A$5:$A$130=$B4)*ISNUMBER(INDEX(Inputs!$K$5:$AJ$130,0,MATCH(AH$2,Inputs!$K$4:$AJ$4,0))))+SUMPRODUCT((Inputs!$C$5:$C$130=$B4)*ISNUMBER(INDEX(Inputs!$K$5:$AJ$130,0,MATCH(AH$2,Inputs!$K$4:$AJ$4,0))))+SUMPRODUCT((Inputs!$E$5:$E$130=$B4)*ISNUMBER(INDEX(Inputs!$K$5:$AJ$130,0,MATCH(AH$2,Inputs!$K$4:$AJ$4,0))))=0,NA(),SUMPRODUCT((Inputs!$A$5:$A$130=$B4)*Inputs!$B$5:$B$130*(((Inputs!$G$5:$G$130="moeda")+(Inputs!$G$5:$G$130="acoes"))*Inputs!$B$1+((Inputs!$G$5:$G$130<>"moeda")*(Inputs!$G$5:$G$130<>"acoes")))*INDEX(Inputs!$K$5:$AJ$130,0,MATCH(AH$2,Inputs!$K$4:$AJ$4,0)))+SUMPRODUCT((Inputs!$C$5:$C$130=$B4)*Inputs!$D$5:$D$130*(((Inputs!$G$5:$G$130="moeda")+(Inputs!$G$5:$G$130="acoes"))*Inputs!$B$1+((Inputs!$G$5:$G$130<>"moeda")*(Inputs!$G$5:$G$130<>"acoes")))*INDEX(Inputs!$K$5:$AJ$130,0,MATCH(AH$2,Inputs!$K$4:$AJ$4,0)))+SUMPRODUCT((Inputs!$E$5:$E$130=$B4)*Inputs!$F$5:$F$130*(((Inputs!$G$5:$G$130="moeda")+(Inputs!$G$5:$G$130="acoes"))*Inputs!$B$1+((Inputs!$G$5:$G$130<>"moeda")*(Inputs!$G$5:$G$130<>"acoes")))*INDEX(Inputs!$K$5:$AJ$130,0,MATCH(AH$2,Inputs!$K$4:$AJ$4,0))))) -> 9253 | AI4: =IF(ISNA(MATCH(AI$2,Inputs!$K$4:$AJ$4,0)),NA(),IF(SUMPRODUCT((Inputs!$A$5:$A$130=$B4)*ISNUMBER(INDEX(Inputs!$K$5:$AJ$130,0,MATCH(AI$2,Inputs!$K$4:$AJ$4,0))))+SUMPRODUCT((Inputs!$C$5:$C$130=$B4)*ISNUMBER(INDEX(Inputs!$K$5:$AJ$130,0,MATCH(AI$2,Inputs!$K$4:$AJ$4,0))))+SUMPRODUCT((Inputs!$E$5:$E$130=$B4)*ISNUMBER(INDEX(Inputs!$K$5:$AJ$130,0,MATCH(AI$2,Inputs!$K$4:$AJ$4,0))))=0,NA(),SUMPRODUCT((Inputs!$A$5:$A$130=$B4)*Inputs!$B$5:$B$130*(((Inputs!$G$5:$G$130="moeda")+(Inputs!$G$5:$G$130="acoes"))*Inputs!$B$1+((Inputs!$G$5:$G$130<>"moeda")*(Inputs!$G$5:$G$130<>"acoes")))*INDEX(Inputs!$K$5:$AJ$130,0,MATCH(AI$2,Inputs!$K$4:$AJ$4,0)))+SUMPRODUCT((Inputs!$C$5:$C$130=$B4)*Inputs!$D$5:$D$130*(((Inputs!$G$5:$G$130="moeda")+(Inputs!$G$5:$G$130="acoes"))*Inputs!$B$1+((Inputs!$G$5:$G$130<>"moeda")*(Inputs!$G$5:$G$130<>"acoes")))*INDEX(Inputs!$K$5:$AJ$130,0,MATCH(AI$2,Inputs!$K$4:$AJ$4,0)))+SUMPRODUCT((Inputs!$E$5:$E$130=$B4)*Inputs!$F$5:$F$130*(((Inputs!$G$5:$G$130="moeda")+(Inputs!$G$5:$G$130="acoes"))*Inputs!$B$1+((Inputs!$G$5:$G$130<>"moeda")*(Inputs!$G$5:$G$130<>"acoes")))*INDEX(Inputs!$K$5:$AJ$130,0,MATCH(AI$2,Inputs!$K$4:$AJ$4,0))))) -> 8925 | AJ4: =IF(ISNA(MATCH(AJ$2,Inputs!$K$4:$AJ$4,0)),NA(),IF(SUMPRODUCT((Inputs!$A$5:$A$130=$B4)*ISNUMBER(INDEX(Inputs!$K$5:$AJ$130,0,MATCH(AJ$2,Inputs!$K$4:$AJ$4,0))))+SUMPRODUCT((Inputs!$C$5:$C$130=$B4)*ISNUMBER(INDEX(Inputs!$K$5:$AJ$130,0,MATCH(AJ$2,Inputs!$K$4:$AJ$4,0))))+SUMPRODUCT((Inputs!$E$5:$E$130=$B4)*ISNUMBER(INDEX(Inputs!$K$5:$AJ$130,0,MATCH(AJ$2,Inputs!$K$4:$AJ$4,0))))=0,NA(),SUMPRODUCT((Inputs!$A$5:$A$130=$B4)*Inputs!$B$5:$B$130*(((Inputs!$G$5:$G$130="moeda")+(Inputs!$G$5:$G$130="acoes"))*Inputs!$B$1+((Inputs!$G$5:$G$130<>"moeda")*(Inputs!$G$5:$G$130<>"acoes")))*INDEX(Inputs!$K$5:$AJ$130,0,MATCH(AJ$2,Inputs!$K$4:$AJ$4,0)))+SUMPRODUCT((Inputs!$C$5:$C$130=$B4)*Inputs!$D$5:$D$130*(((Inputs!$G$5:$G$130="moeda")+(Inputs!$G$5:$G$130="acoes"))*Inputs!$B$1+((Inputs!$G$5:$G$130<>"moeda")*(Inputs!$G$5:$G$130<>"acoes")))*INDEX(Inputs!$K$5:$AJ$130,0,MATCH(AJ$2,Inputs!$K$4:$AJ$4,0)))+SUMPRODUCT((Inputs!$E$5:$E$130=$B4)*Inputs!$F$5:$F$130*(((Inputs!$G$5:$G$130="moeda")+(Inputs!$G$5:$G$130="acoes"))*Inputs!$B$1+((Inputs!$G$5:$G$130<>"moeda")*(Inputs!$G$5:$G$130<>"acoes")))*INDEX(Inputs!$K$5:$AJ$130,0,MATCH(AJ$2,Inputs!$K$4:$AJ$4,0))))) -> 9731 | AK4: =IF(ISNA(MATCH(AK$2,Inputs!$K$4:$AJ$4,0)),NA(),IF(SUMPRODUCT((Inputs!$A$5:$A$130=$B4)*ISNUMBER(INDEX(Inputs!$K$5:$AJ$130,0,MATCH(AK$2,Inputs!$K$4:$AJ$4,0))))+SUMPRODUCT((Inputs!$C$5:$C$130=$B4)*ISNUMBER(INDEX(Inputs!$K$5:$AJ$130,0,MATCH(AK$2,Inputs!$K$4:$AJ$4,0))))+SUMPRODUCT((Inputs!$E$5:$E$130=$B4)*ISNUMBER(INDEX(Inputs!$K$5:$AJ$130,0,MATCH(AK$2,Inputs!$K$4:$AJ$4,0))))=0,NA(),SUMPRODUCT((Inputs!$A$5:$A$130=$B4)*Inputs!$B$5:$B$130*(((Inputs!$G$5:$G$130="moeda")+(Inputs!$G$5:$G$130="acoes"))*Inputs!$B$1+((Inputs!$G$5:$G$130<>"moeda")*(Inputs!$G$5:$G$130<>"acoes")))*INDEX(Inputs!$K$5:$AJ$130,0,MATCH(AK$2,Inputs!$K$4:$AJ$4,0)))+SUMPRODUCT((Inputs!$C$5:$C$130=$B4)*Inputs!$D$5:$D$130*(((Inputs!$G$5:$G$130="moeda")+(Inputs!$G$5:$G$130="acoes"))*Inputs!$B$1+((Inputs!$G$5:$G$130<>"moeda")*(Inputs!$G$5:$G$130<>"acoes")))*INDEX(Inputs!$K$5:$AJ$130,0,MATCH(AK$2,Inputs!$K$4:$AJ$4,0)))+SUMPRODUCT((Inputs!$E$5:$E$130=$B4)*Inputs!$F$5:$F$130*(((Inputs!$G$5:$G$130="moeda")+(Inputs!$G$5:$G$130="acoes"))*Inputs!$B$1+((Inputs!$G$5:$G$130<>"moeda")*(Inputs!$G$5:$G$130<>"acoes")))*INDEX(Inputs!$K$5:$AJ$130,0,MATCH(AK$2,Inputs!$K$4:$AJ$4,0))))) -> 9112 | AL4: =SUM(AH4:AK4) -> 37021
