Workbook
Name beta_observed: Valuation!$D$93
Name last_close: Valuation!$G$7
Name ticker: Valuation!$D$7
Name Useful_Life_of_Depreciable_PP_E: "PPElife"
Name beta_observed: #REF!
Name ticker: #REF!
Name costdebtfirm: Valuation!$D$86
Name costequity: Valuation!$D$94
Name debt: Valuation!$G$88
Name debt_weight: Valuation!$J$88
Name g: Valuation!$D$63
Name market_equity: Valuation!$G$89
Name noplat_t1: Valuation!$D$65
Name relevered_beta: Valuation!$M$102
Name risk_free_rate: Valuation!$D$91
Name risk_premium: Valuation!$D$92
Name ronic: Valuation!$D$64
Name stub_year_fraction: Valuation!$D$11
Name totalcap: Valuation!$G$90
Name wacc: Valuation!$D$12

Sheet Inputs
A1: Base histórica (R$ mil) - AUREN ENERGIA S.A. (AURE3) - CVM ITR/DFP consolidado
A2: Fonte / conta original | B2: Código | C2: Conta padronizada | D2: 1Q21 | E2: 2Q21 | F2: 3Q21 | G2: 4Q21 | H2: 2021 | I2: 1Q22 | J2: 2Q22 | K2: 3Q22 | L2: 4Q22 | M2: 2022 | N2: 1Q23 | O2: 2Q23 | P2: 3Q23 | Q2: 4Q23 | R2: 2023 | S2: 1Q24 | T2: 2Q24 | U2: 3Q24 | V2: 4Q24 | W2: 2024 | X2: 1Q25 | Y2: 2Q25 | Z2: 3Q25 | AA2: 4Q25 | AB2: 2025 | AC2: 1Q26 | AD2: 2Q26 | AE2: 3Q26 | AF2: 4Q26 | AG2: 2026
A3: Fonte: CVM dados abertos (ITR/DFP consolidado, CVM 026620) - R$ mil, trimestre isolado | C3: Unidade original: R$ mil | a Inputs (2) divide por 1.000 -> R$ milhões
A4: DRE - CVM ITR/DFP consolidado (Auren Energia S.A., CVM 026620), R$ mil, trimestre isolado (4T = ano - 9M)
A5: CVM DRE 3.01 Receita de venda de bens e/ou serviços | B5: 1 | C5: Net Revenues | D5: 552151 | E5: 581104 | F5: 616194 | G5: 767313 | H5: =SUM(D5:G5) -> 2516762 | I5: 1145258 | J5: 1346655 | K5: 1538901 | L5: 1484892 | M5: =SUM(I5:L5) -> 5515706 | N5: 1414510 | O5: 1437088 | P5: 1626590 | Q5: 1703702 | R5: =SUM(N5:Q5) -> 6181890 | S5: 1397531 | T5: 1450045 | U5: 2046511 | V5: 3165864 | W5: =SUM(S5:V5) -> 8059951 | X5: 2952303 | Y5: 2885529 | Z5: 3537391 | AA5: 3801729 | AB5: =SUM(X5:AA5) -> 13176952 | AC5: 3074535 | AD5: 3055499
A6: CVM DRE 3.02 Custo dos bens e serviços vendidos (inclui D&A) | B6: 2 | C6: COGS (cash) | D6: -277630 | E6: -402476 | F6: 189049 | G6: -592360 | H6: =SUM(D6:G6) -> -1083417 | I6: -863207 | J6: -1046341 | K6: -1234077 | L6: -1228998 | M6: =SUM(I6:L6) -> -4372623 | N6: -1081144 | O6: -1095526 | P6: -1299153 | Q6: -1373123 | R6: =SUM(N6:Q6) -> -4848946 | S6: -1106505 | T6: -1128505 | U6: -1726989 | V6: -2668949 | W6: =SUM(S6:V6) -> -6630948 | X6: -2116034 | Y6: -2390092 | Z6: -3200700 | AA6: -3319390 | AB6: =SUM(X6:AA6) -> -11026216 | AC6: -2587081 | AD6: -2603261
A7: (+) estorno da D&A embutida no custo, relançada no código 4 (a CVM não separa D&A entre custo e despesa; toda a D&A sai do custo) | B7: 2 | C7: COGS (cash) | D7: 132593 | E7: 131573 | F7: 145397 | G7: 149432 | H7: =SUM(D7:G7) -> 558995 | I7: 157304 | J7: 161190 | K7: 161353 | L7: 117907 | M7: =SUM(I7:L7) -> 597754 | N7: 168327 | O7: 169666 | P7: 169643 | Q7: 169639 | R7: =SUM(N7:Q7) -> 677275 | S7: 166381 | T7: 175177 | U7: 182611 | V7: 189021 | W7: =SUM(S7:V7) -> 713190 | X7: 458196 | Y7: 521747 | Z7: 465553 | AA7: 477467 | AB7: =SUM(X7:AA7) -> 1922963 | AC7: 466831 | AD7: 465443
A8: CVM DRE 3.04 Despesas/receitas operacionais (G&A + outras receitas e despesas) | B8: 3 | C8: SG&A and Other (cash) | D8: -37007 | E8: -72009 | F8: -98542 | G8: -5338 | H8: =SUM(D8:G8) -> -212896 | I8: -105652 | J8: -117078 | K8: 89362 | L8: 381350 | M8: =SUM(I8:L8) -> 247982 | N8: -19582 | O8: -65205 | P8: -101973 | Q8: -72270 | R8: =SUM(N8:Q8) -> -259030 | S8: 208815 | T8: -45123 | U8: 189880 | V8: -490910 | W8: =SUM(S8:V8) -> -137338 | X8: 155190 | Y8: -485413 | Z8: -79727 | AA8: 575338 | AB8: =SUM(X8:AA8) -> 165388 | AC8: -582682 | AD8: -67320
A9: (-) estorno da equivalência patrimonial (3.04.06), lançada no código 8 | B9: 3 | C9: SG&A and Other (cash) | D9: 0 | E9: 0 | F9: 0 | G9: 0 | H9: =SUM(D9:G9) -> 0 | I9: -29051 | J9: -54940 | K9: -52300 | L9: 5632 | M9: =SUM(I9:L9) -> -130659 | N9: -30229 | O9: 11887 | P9: -45027 | Q9: -9943 | R9: =SUM(N9:Q9) -> -73312 | S9: -66578 | T9: -53524 | U9: -58434 | V9: 14152 | W9: =SUM(S9:V9) -> -164384 | X9: -72147 | Y9: -14758 | Z9: -58193 | AA9: -60249 | AB9: =SUM(X9:AA9) -> -205347 | AC9: -71487 | AD9: -39594
A10: D&A - DVA 7.04.01 até 2T22; DFC 6.01.01 (depreciação e amortização + amortização de mais-valia/ágio) a partir de 3T22 | B10: 4 | C10: D&A | D10: -132593 | E10: -131573 | F10: -145397 | G10: -149432 | H10: =SUM(D10:G10) -> -558995 | I10: -157304 | J10: -161190 | K10: -161353 | L10: -117907 | M10: =SUM(I10:L10) -> -597754 | N10: -168327 | O10: -169666 | P10: -169643 | Q10: -169639 | R10: =SUM(N10:Q10) -> -677275 | S10: -166381 | T10: -175177 | U10: -182611 | V10: -189021 | W10: =SUM(S10:V10) -> -713190 | X10: -458196 | Y10: -521747 | Z10: -465553 | AA10: -477467 | AB10: =SUM(X10:AA10) -> -1922963 | AC10: -466831 | AD10: -465443
A11: CVM DRE 3.06.02 Despesas financeiras | B11: 5 | C11: Interest Expense | D11: -164756 | E11: -211669 | F11: -193237 | G11: -238999 | H11: =SUM(D11:G11) -> -808661 | I11: -250510 | J11: -291340 | K11: -165812 | L11: -468975 | M11: =SUM(I11:L11) -> -1176637 | N11: -272035 | O11: -497689 | P11: -194621 | Q11: -215024 | R11: =SUM(N11:Q11) -> -1179369 | S11: -258839 | T11: -255757 | U11: -243887 | V11: -717696 | W11: =SUM(S11:V11) -> -1476179 | X11: -1008815 | Y11: -879279 | Z11: -869780 | AA11: -783788 | AB11: =SUM(X11:AA11) -> -3541662 | AC11: -867481 | AD11: -1018168
A12: CVM DRE 3.06.01 Receitas financeiras | B12: 6 | C12: Nonoperating Income / (Loss) | D12: 13753 | E12: 11716 | F12: 41663 | G12: 33412 | H12: =SUM(D12:G12) -> 100544 | I12: 86074 | J12: 103888 | K12: 112759 | L12: 2536191 | M12: =SUM(I12:L12) -> 2838912 | N12: 254848 | O12: 473238 | P12: 74493 | Q12: 138783 | R12: =SUM(N12:Q12) -> 941362 | S12: 149860 | T12: 119705 | U12: 141262 | V12: 304060 | W12: =SUM(S12:V12) -> 714887 | X12: 276738 | Y12: 234752 | Z12: 244490 | AA12: 351744 | AB12: =SUM(X12:AA12) -> 1107724 | AC12: 277650 | AD12: 286022
A13: CVM DRE 3.08 IR e CS sobre o lucro | B13: 7 | C13: Taxes | D13: -46947 | E13: 7108 | F13: -238601 | G13: 16235 | H13: =SUM(D13:G13) -> -262205 | I13: -14548 | J13: 2189 | K13: -111046 | L13: -251321 | M13: =SUM(I13:L13) -> -374726 | N13: -66645 | O13: -69024 | P13: -943452 | Q13: -74475 | R13: =SUM(N13:Q13) -> -1153596 | S13: -137244 | T13: -49276 | U13: -135947 | V13: 63963 | W13: =SUM(S13:V13) -> -258504 | X13: -205385 | Y13: 71650 | Z13: -35369 | AA13: -270957 | AB13: =SUM(X13:AA13) -> -440061 | AC13: 83453 | AD13: -31833
A14: CVM DRE 3.04.06 Resultado de equivalência patrimonial | B14: 8 | C14: Equity in Income of Affiliates, after tax (enter as +) | D14: 0 | E14: 0 | F14: 0 | G14: 0 | H14: =SUM(D14:G14) -> 0 | I14: 29051 | J14: 54940 | K14: 52300 | L14: -5632 | M14: =SUM(I14:L14) -> 130659 | N14: 30229 | O14: -11887 | P14: 45027 | Q14: 9943 | R14: =SUM(N14:Q14) -> 73312 | S14: 66578 | T14: 53524 | U14: 58434 | V14: -14152 | W14: =SUM(S14:V14) -> 164384 | X14: 72147 | Y14: 14758 | Z14: 58193 | AA14: 60249 | AB14: =SUM(X14:AA14) -> 205347 | AC14: 71487 | AD14: 39594
A15: CVM DRE 3.11.02 Lucro atribuído a não controladores (sinal invertido) | B15: 9 | C15: Minority Interest Expense, after tax (enter as - ) | D15: -29436 | E15: 15169 | F15: -234281 | G15: 34187 | H15: =SUM(D15:G15) -> -214361 | I15: -4214 | J15: 0 | K15: 0 | L15: 0 | M15: =SUM(I15:L15) -> -4214 | N15: 0 | O15: 0 | P15: 0 | Q15: 0 | R15: =SUM(N15:Q15) -> 0 | S15: 0 | T15: 0 | U15: 0 | V15: -20931 | W15: =SUM(S15:V15) -> -20931 | X15: -45501 | Y15: -52537 | Z15: 6661 | AA15: -14780 | AB15: =SUM(X15:AA15) -> -106157 | AC15: -19732 | AD15: -31886
A16: CVM DFC 6.03 Pagamento de dividendos e JCP (caixa) | B16: 10 | C16: Common Dividends | D16: -3475 | E16: -352302 | F16: -146582 | G16: -3 | H16: =SUM(D16:G16) -> -502362 | I16: 0 | J16: -99991 | K16: 0 | L16: -3 | M16: =SUM(I16:L16) -> -99994 | N16: 0 | O16: -1499809 | P16: 0 | Q16: -1499817 | R16: =SUM(N16:Q16) -> -2999626 | S16: -399948 | T16: -1 | U16: -1 | V16: 0 | W16: =SUM(S16:V16) -> -399950 | X16: -99648 | Y16: -61408 | Z16: -89327 | AA16: 8548 | AB16: =SUM(X16:AA16) -> -241835 | AC16: -42966 | AD16: 148
A17: CVM DRE 3.11.01 Lucro atribuído aos controladores (1T24-3T24: 3.11, pois a ITR não separou e não havia minoritários) | B17: 44 | C17: Net income reported (controladores) - memo p/ check | D17: 10128 | E17: -71057 | F17: 82245 | G17: 14450 | H17: =SUM(D17:G17) -> 35766 | I17: -6799 | J17: -2027 | K17: 230086 | L17: 2453140 | M17: =SUM(I17:L17) -> 2674400 | N17: 229952 | O17: 182882 | P17: -838116 | Q17: 107593 | R17: =SUM(N17:Q17) -> -317689 | S17: 253618 | T17: 91089 | U17: 270830 | V17: -364599 | W17: =SUM(S17:V17) -> 250938 | X17: 8496 | Y17: -615390 | Z17: -397034 | AA17: 339896 | AB17: =SUM(X17:AA17) -> -664032 | AC17: -621338 | AD17: -410947
A18: DRE - memória (sem código)
A19: CVM DRE 3.03 Resultado bruto | D19: 274521 | E19: 178628 | F19: 805243 | G19: 174953 | H19: =SUM(D19:G19) -> 1433345 | I19: 282051 | J19: 300314 | K19: 304824 | L19: 255894 | M19: =SUM(I19:L19) -> 1143083 | N19: 333366 | O19: 341562 | P19: 327437 | Q19: 330579 | R19: =SUM(N19:Q19) -> 1332944 | S19: 291026 | T19: 321540 | U19: 319522 | V19: 496915 | W19: =SUM(S19:V19) -> 1429003 | X19: 836269 | Y19: 495437 | Z19: 336691 | AA19: 482339 | AB19: =SUM(X19:AA19) -> 2150736 | AC19: 487454 | AD19: 452238
A20: CVM DRE 3.05 Resultado antes do resultado financeiro (EBIT) | D20: 237514 | E20: 106619 | F20: 706701 | G20: 169615 | H20: =SUM(D20:G20) -> 1220449 | I20: 176399 | J20: 183236 | K20: 394186 | L20: 637244 | M20: =SUM(I20:L20) -> 1391065 | N20: 313784 | O20: 276357 | P20: 225464 | Q20: 258309 | R20: =SUM(N20:Q20) -> 1073914 | S20: 499841 | T20: 276417 | U20: 509402 | V20: 6005 | W20: =SUM(S20:V20) -> 1291665 | X20: 991459 | Y20: 10024 | Z20: 256964 | AA20: 1057677 | AB20: =SUM(X20:AA20) -> 2316124 | AC20: -95228 | AD20: 384918
A21: CVM DRE 3.07 Resultado antes dos tributos | D21: 86511 | E21: -93334 | F21: 555127 | G21: -35972 | H21: =SUM(D21:G21) -> 512332 | I21: 11963 | J21: -4216 | K21: 341133 | L21: 2704460 | M21: =SUM(I21:L21) -> 3053340 | N21: 296597 | O21: 251906 | P21: 105336 | Q21: 182068 | R21: =SUM(N21:Q21) -> 835907 | S21: 390862 | T21: 140365 | U21: 406777 | V21: -407631 | W21: =SUM(S21:V21) -> 530373 | X21: 259382 | Y21: -634503 | Z21: -368326 | AA21: 625633 | AB21: =SUM(X21:AA21) -> -117814 | AC21: -685059 | AD21: -347228
A22: CVM DRE 3.11 Lucro consolidado do período | D22: 39564 | E22: -86226 | F22: 316526 | G22: -19737 | H22: =SUM(D22:G22) -> 250127 | I22: -2585 | J22: -2027 | K22: 230087 | L22: 2453139 | M22: =SUM(I22:L22) -> 2678614 | N22: 229952 | O22: 182882 | P22: -838116 | Q22: 107593 | R22: =SUM(N22:Q22) -> -317689 | S22: 253618 | T22: 91089 | U22: 270830 | V22: -343668 | W22: =SUM(S22:V22) -> 271869 | X22: 53997 | Y22: -562853 | Z22: -403695 | AA22: 354676 | AB22: =SUM(X22:AA22) -> -557875 | AC22: -601606 | AD22: -379061
A23: Receita líquida PRO FORMA (Auren + AES Brasil) - Planilha Interativa da RI; base antiga do modelo, só comparação | H23: =SUM(D23:G23) -> 0 | M23: =SUM(I23:L23) -> 0 | N23: 2180778.4 | O23: 2186623.6 | P23: 2523976.2 | Q23: 2666055.3 | R23: =SUM(N23:Q23) -> 9557433.5 | S23: 2209357.2 | T23: 2307884.5 | U23: 3134682.4 | V23: 3598925 | W23: =SUM(S23:V23) -> 11250849 | AB23: =SUM(X23:AA23) -> 0
A24: BALANÇO - CVM ITR/DFP consolidado, R$ mil, saldo no fim do trimestre
A25: CVM BPA 1.01.01 Caixa e Equivalentes de Caixa | B25: 11 | C25: Cash and equivalents (inc. investment securities) | D25: 1292369 | E25: 1189841 | F25: 1376313 | G25: 1595818 | H25: =G25 -> 1595818 | I25: 3049185 | J25: 3211067 | K25: 2881084 | L25: 3125959 | M25: =L25 -> 3125959 | N25: 3344668 | O25: 6225732 | P25: 4904741 | Q25: 3238394 | R25: =Q25 -> 3238394 | S25: 3094615 | T25: 4992046 | U25: 5281323 | V25: 7200549 | W25: =V25 -> 7200549 | X25: 6131027 | Y25: 4907414 | Z25: 4479368 | AA25: 3826127 | AB25: =AA25 -> 3826127 | AC25: 2959416 | AD25: 2949774
A26: CVM BPA 1.01.02 Aplicações Financeiras | B26: 11 | C26: Cash and equivalents (inc. investment securities) | D26: 0 | E26: 0 | F26: 0 | G26: 77751 | H26: =G26 -> 77751 | I26: 124662 | J26: 142899 | K26: 102612 | L26: 105347 | M26: =L26 -> 105347 | N26: 57999 | O26: 59610 | P26: 0 | Q26: 0 | R26: =Q26 -> 0 | S26: 0 | T26: 0 | U26: 14398 | V26: 2629 | W26: =V26 -> 2629 | X26: 31449 | Y26: 25754 | Z26: 596314 | AA26: 556295 | AB26: =AA26 -> 556295 | AC26: 612466 | AD26: 689034
A27: CVM BPA 1.01.03 Contas a Receber | B27: 12 | C27: Accounts receivable | D27: 382854 | E27: 325707 | F27: 330258 | G27: 328631 | H27: =G27 -> 328631 | I27: 556035 | J27: 549634 | K27: 625916 | L27: 617860 | M27: =L27 -> 617860 | N27: 577274 | O27: 569731 | P27: 656783 | Q27: 679476 | R27: =Q27 -> 679476 | S27: 569252 | T27: 575060 | U27: 919196 | V27: 1492867 | W27: =V27 -> 1492867 | X27: 1404559 | Y27: 1229784 | Z27: 1543172 | AA27: 1712414 | AB27: =AA27 -> 1712414 | AC27: 1637335 | AD27: 1408699
A28: CVM BPA 1.01.06 Tributos a Recuperar | B28: 16 | C28: Other current assets | D28: 75820 | E28: 83320 | F28: 80249 | G28: 36714 | H28: =G28 -> 36714 | I28: 72760 | J28: 92617 | K28: 111149 | L28: 105993 | M28: =L28 -> 105993 | N28: 129838 | O28: 175907 | P28: 225719 | Q28: 139249 | R28: =Q28 -> 139249 | S28: 162883 | T28: 176234 | U28: 220418 | V28: 261258 | W28: =V28 -> 261258 | X28: 255502 | Y28: 305604 | Z28: 331172 | AA28: 289189 | AB28: =AA28 -> 289189 | AC28: 304052 | AD28: 346199
A29: CVM BPA 1.01.08 Outros Ativos Circulantes | B29: 16 | C29: Other current assets | D29: 77884 | E29: 86212 | F29: 91761 | G29: 313085 | H29: =G29 -> 313085 | I29: 1663133 | J29: 1954073 | K29: 1779248 | L29: 2313337 | M29: =L29 -> 2313337 | N29: 2790493 | O29: 2161634 | P29: 2002402 | Q29: 1880742 | R29: =Q29 -> 1880742 | S29: 1521179 | T29: 1572587 | U29: 3241231 | V29: 2180491 | W29: =V29 -> 2180491 | X29: 3271444 | Y29: 2264697 | Z29: 1869303 | AA29: 2076082 | AB29: =AA29 -> 2076082 | AC29: 1896154 | AD29: 1735662
A30: CVM BPA 1.02.01 Ativo Realizável a Longo Prazo | B30: 22 | C30: Other non-current assets | D30: 5953955 | E30: 5970796 | F30: 5566187 | G30: 5858557 | H30: =G30 -> 5858557 | I30: 8838579 | J30: 8847640 | K30: 8821900 | L30: 10824096 | M30: =L30 -> 10824096 | N30: 11362362 | O30: 7910031 | P30: 6898457 | Q30: 6626900 | R30: =Q30 -> 6626900 | S30: 5996230 | T30: 5739551 | U30: 5553418 | V30: 5665802 | W30: =V30 -> 5665802 | X30: 5493592 | Y30: 5187745 | Z30: 4903780 | AA30: 5364266 | AB30: =AA30 -> 5364266 | AC30: 5437925 | AD30: 5429087
A31: (-) estorno IR e CS diferidos (1.02.01.07), lançado no código 14 | B31: 22 | C31: Other non-current assets | D31: -3908905 | E31: -3908192 | F31: -3444995 | G31: -3408893 | H31: =G31 -> -3408893 | I31: -3416808 | J31: -3430877 | K31: -3370826 | L31: -3000824 | M31: =L31 -> -3000824 | N31: -2992037 | O31: -2922766 | P31: -2601196 | Q31: -2698782 | R31: =Q31 -> -2698782 | S31: -2697332 | T31: -2660554 | U31: -2642872 | V31: -2172103 | W31: =V31 -> -2172103 | X31: -2129196 | Y31: -1964087 | Z31: -1995197 | AA31: -1942725 | AB31: =AA31 -> -1942725 | AC31: -1956126 | AD31: -1997881
A32: CVM BPA 1.02.01.07 Tributos Diferidos | B32: 14 | C32: Deferred income taxes | D32: 3908905 | E32: 3908192 | F32: 3444995 | G32: 3408893 | H32: =G32 -> 3408893 | I32: 3416808 | J32: 3430877 | K32: 3370826 | L32: 3000824 | M32: =L32 -> 3000824 | N32: 2992037 | O32: 2922766 | P32: 2601196 | Q32: 2698782 | R32: =Q32 -> 2698782 | S32: 2697332 | T32: 2660554 | U32: 2642872 | V32: 2172103 | W32: =V32 -> 2172103 | X32: 2129196 | Y32: 1964087 | Z32: 1995197 | AA32: 1942725 | AB32: =AA32 -> 1942725 | AC32: 1956126 | AD32: 1997881
A33: CVM BPA 1.02.02 Investimentos | B33: 17 | C33: Equity in affiliates | D33: 0 | E33: 0 | F33: 0 | G33: 0 | H33: =G33 -> 0 | I33: 1101829 | J33: 1015723 | K33: 1077880 | L33: 2161751 | M33: =L33 -> 2161751 | N33: 2192011 | O33: 2127074 | P33: 2111609 | Q33: 2057307 | R33: =Q33 -> 2057307 | S33: 2111899 | T33: 2047967 | U33: 2105551 | V33: 2261558 | W33: =V33 -> 2261558 | X33: 2299011 | Y33: 2216541 | Z33: 2133085 | AA33: 2131020 | AB33: =AA33 -> 2131020 | AC33: 2113512 | AD33: 2043198
A34: CVM BPA 1.02.03 Imobilizado | B34: 18 | C34: PP&E | D34: 8724325 | E34: 8631332 | F34: 8896198 | G34: 8985565 | H34: =G34 -> 8985565 | I34: 9177205 | J34: 9748982 | K34: 10149734 | L34: 10440742 | M34: =L34 -> 10440742 | N34: 10664521 | O34: 11223531 | P34: 11879298 | Q34: 11914036 | R34: =Q34 -> 11914036 | S34: 11795286 | T34: 11729447 | U34: 11641070 | V34: 26353080 | W34: =V34 -> 26353080 | X34: 26150092 | Y34: 25955934 | Z34: 25867570 | AA34: 25570358 | AB34: =AA34 -> 25570358 | AC34: 25348441 | AD34: 25157620
A35: (-) estorno direito de uso (1.02.03.02), lançado no código 19 | B35: 18 | C35: PP&E | D35: -6068 | E35: -6051 | F35: -5670 | G35: -5283 | H35: =G35 -> -5283 | I35: -6519 | J35: -5425 | K35: -80327 | L35: -43707 | M35: =L35 -> -43707 | N35: -44522 | O35: -45236 | P35: -65324 | Q35: -64689 | R35: =Q35 -> -64689 | S35: -62706 | T35: -60861 | U35: -69260 | V35: -149284 | W35: =V35 -> -149284 | X35: -149110 | Y35: -145660 | Z35: -142547 | AA35: -140111 | AB35: =AA35 -> -140111 | AC35: -141310 | AD35: -136850
A36: CVM BPA 1.02.03.02 Direito de Uso em Arrendamento | B36: 19 | C36: Right-of-use-assets | D36: 6068 | E36: 6051 | F36: 5670 | G36: 5283 | H36: =G36 -> 5283 | I36: 6519 | J36: 5425 | K36: 80327 | L36: 43707 | M36: =L36 -> 43707 | N36: 44522 | O36: 45236 | P36: 65324 | Q36: 64689 | R36: =Q36 -> 64689 | S36: 62706 | T36: 60861 | U36: 69260 | V36: 149284 | W36: =V36 -> 149284 | X36: 149110 | Y36: 145660 | Z36: 142547 | AA36: 140111 | AB36: =AA36 -> 140111 | AC36: 141310 | AD36: 136850
... A59: CVM BPP 2.03.09 Participação dos Acionistas Não Controladores | B59: 35 | C59: Minority interest | D59: 4277955 | E59: 4293710 | F59: 4768398 | G59: 4589112 | H59: =G59 -> 4589112 | I59: 0 | J59: 0 | K59: 0 | L59: 0 | M59: =L59 -> 0 | N59: 0 | O59: 0 | P59: 0 | Q59: 0 | R59: =Q59 -> 0 | S59: 0 | T59: 0 | U59: 0 | V59: 1281658 | W59: =V59 -> 1281658 | X59: 1327231 | Y59: 1379839 | Z59: 1288751 | AA59: 1266701 | AB59: =AA59 -> 1266701 | AC59: 1213632 | AD59: 1245517
A60: BALANÇO - totais divulgados (memória)
A61: CVM BPA 1 Ativo total | D61: 18260942 | E61: 18026959 | F61: 18525946 | G61: 19562553 | H61: =G61 -> 19562553 | I61: 28452306 | J61: 29391370 | K61: 29337895 | L61: 32282893 | M61: =L61 -> 32282893 | N61: 33694157 | O61: 33010352 | P61: 31219220 | Q61: 28994557 | R61: =Q61 -> 28994557 | S61: 27694357 | T61: 29259449 | U61: 31492257 | V61: 52754117 | W61: =V61 -> 52754117 | X61: 52266696 | Y61: 49202800 | Z61: 48833477 | AA61: 48727388 | AB61: =AA61 -> 48727388 | AC61: 47381486 | AD61: 46710105
A62: CVM BPP 2.01 + 2.02 Passivo circulante + não circulante (reconstruído pelas contas) | D62: 10078095 | E62: 9598964 | F62: 9380655 | G62: 10516038 | H62: =G62 -> 10516038 | I62: 15632029 | J62: 16659168 | K62: 16387368 | L62: 17029815 | M62: =L62 -> 17029815 | N62: 18210646 | O62: 18224390 | P62: 17256820 | Q62: 16625604 | R62: =Q62 -> 16625604 | S62: 15470892 | T62: 16943915 | U62: 18904972 | V62: 38270763 | W62: =V62 -> 38270763 | X62: 37687948 | Y62: 35139197 | Z62: 35269194 | AA62: 34951925 | AB62: =AA62 -> 34951925 | AC62: 34258293 | AD62: 33957255
...

Sheet Inputs (2)
A1: =IF(Control!B3="","EMPRESA",Control!B3) -> Auren Energia S.A. | B1: Código | C1: Conta padronizada | D1: 2021 | E1: 2021 | F1: 2021 | G1: 2021 | H1: 2021 | I1: 2022 | J1: 2022 | K1: 2022 | L1: 2022 | M1: 2022 | N1: 2023 | O1: 2023 | P1: 2023 | Q1: 2023 | R1: 2023 | S1: 2024 | T1: 2024 | U1: 2024 | V1: 2024 | W1: 2024 | X1: 2025 | Y1: 2025 | Z1: 2025 | AA1: 2025 | AB1: 2025 | AC1: 2026 | AD1: 2026 | AE1: 2026 | AF1: 2026 | AG1: 2026
A2: R$ milhões | C2: Período | D2: 1Q21 | E2: 2Q21 | F2: 3Q21 | G2: 4Q21 | H2: 2021 | I2: 1Q22 | J2: 2Q22 | K2: 3Q22 | L2: 4Q22 | M2: 2022 | N2: 1Q23 | O2: 2Q23 | P2: 3Q23 | Q2: 4Q23 | R2: 2023 | S2: 1Q24 | T2: 2Q24 | U2: 3Q24 | V2: 4Q24 | W2: 2024 | X2: 1Q25 | Y2: 2Q25 | Z2: 3Q25 | AA2: 4Q25 | AB2: 2025 | AC2: 1Q26 | AD2: 2Q26 | AE2: 3Q26 | AF2: 4Q26 | AG2: 2026
A3: Actual flag | C3: 0 = sem dados / 1 = realizado | D3: 1 | E3: 1 | F3: 1 | G3: 1 | H3: 1 | I3: 1 | J3: 1 | K3: 1 | L3: 1 | M3: 1 | N3: 1 | O3: 1 | P3: 1 | Q3: 1 | R3: 1 | S3: 1 | T3: 1 | U3: 1 | V3: 1 | W3: 1 | X3: 1 | Y3: 1 | Z3: 1 | AA3: 1 | AB3: 1 | AC3: 1 | AD3: 1 | AE3: 0 | AF3: 0 | AG3: 0
B4: 1 | C4: Net Revenues | D4: =IF(D$3=0,"",SUMIFS(INDEX(Inputs!$D$4:$AG$100,0,MATCH(D$2,Inputs!$D$2:$AG$2,0)),Inputs!$B$4:$B$100,$B4)/1000) -> 552.151 | E4: =IF(E$3=0,"",SUMIFS(INDEX(Inputs!$D$4:$AG$100,0,MATCH(E$2,Inputs!$D$2:$AG$2,0)),Inputs!$B$4:$B$100,$B4)/1000) -> 581.104 | F4: =IF(F$3=0,"",SUMIFS(INDEX(Inputs!$D$4:$AG$100,0,MATCH(F$2,Inputs!$D$2:$AG$2,0)),Inputs!$B$4:$B$100,$B4)/1000) -> 616.194 | G4: =IF(G$3=0,"",SUMIFS(INDEX(Inputs!$D$4:$AG$100,0,MATCH(G$2,Inputs!$D$2:$AG$2,0)),Inputs!$B$4:$B$100,$B4)/1000) -> 767.313 | H4: =IF(COUNT(D4:G4)=4,SUM(D4:G4),"") -> 2516.762 | I4: =IF(I$3=0,"",SUMIFS(INDEX(Inputs!$D$4:$AG$100,0,MATCH(I$2,Inputs!$D$2:$AG$2,0)),Inputs!$B$4:$B$100,$B4)/1000) -> 1145.258 | J4: =IF(J$3=0,"",SUMIFS(INDEX(Inputs!$D$4:$AG$100,0,MATCH(J$2,Inputs!$D$2:$AG$2,0)),Inputs!$B$4:$B$100,$B4)/1000) -> 1346.655 | K4: =IF(K$3=0,"",SUMIFS(INDEX(Inputs!$D$4:$AG$100,0,MATCH(K$2,Inputs!$D$2:$AG$2,0)),Inputs!$B$4:$B$100,$B4)/1000) -> 1538.901 | L4: =IF(L$3=0,"",SUMIFS(INDEX(Inputs!$D$4:$AG$100,0,MATCH(L$2,Inputs!$D$2:$AG$2,0)),Inputs!$B$4:$B$100,$B4)/1000) -> 1484.892 | M4: =IF(COUNT(I4:L4)=4,SUM(I4:L4),"") -> 5515.706 | N4: =IF(N$3=0,"",SUMIFS(INDEX(Inputs!$D$4:$AG$100,0,MATCH(N$2,Inputs!$D$2:$AG$2,0)),Inputs!$B$4:$B$100,$B4)/1000) -> 1414.51 | O4: =IF(O$3=0,"",SUMIFS(INDEX(Inputs!$D$4:$AG$100,0,MATCH(O$2,Inputs!$D$2:$AG$2,0)),Inputs!$B$4:$B$100,$B4)/1000) -> 1437.088 | P4: =IF(P$3=0,"",SUMIFS(INDEX(Inputs!$D$4:$AG$100,0,MATCH(P$2,Inputs!$D$2:$AG$2,0)),Inputs!$B$4:$B$100,$B4)/1000) -> 1626.59 | Q4: =IF(Q$3=0,"",SUMIFS(INDEX(Inputs!$D$4:$AG$100,0,MATCH(Q$2,Inputs!$D$2:$AG$2,0)),Inputs!$B$4:$B$100,$B4)/1000) -> 1703.702 | R4: =IF(COUNT(N4:Q4)=4,SUM(N4:Q4),"") -> 6181.89 | S4: =IF(S$3=0,"",SUMIFS(INDEX(Inputs!$D$4:$AG$100,0,MATCH(S$2,Inputs!$D$2:$AG$2,0)),Inputs!$B$4:$B$100,$B4)/1000) -> 1397.531 | T4: =IF(T$3=0,"",SUMIFS(INDEX(Inputs!$D$4:$AG$100,0,MATCH(T$2,Inputs!$D$2:$AG$2,0)),Inputs!$B$4:$B$100,$B4)/1000) -> 1450.045 | U4: =IF(U$3=0,"",SUMIFS(INDEX(Inputs!$D$4:$AG$100,0,MATCH(U$2,Inputs!$D$2:$AG$2,0)),Inputs!$B$4:$B$100,$B4)/1000) -> 2046.511 | V4: =IF(V$3=0,"",SUMIFS(INDEX(Inputs!$D$4:$AG$100,0,MATCH(V$2,Inputs!$D$2:$AG$2,0)),Inputs!$B$4:$B$100,$B4)/1000) -> 3165.864 | W4: =IF(COUNT(S4:V4)=4,SUM(S4:V4),"") -> 8059.951 | X4: =IF(X$3=0,"",SUMIFS(INDEX(Inputs!$D$4:$AG$100,0,MATCH(X$2,Inputs!$D$2:$AG$2,0)),Inputs!$B$4:$B$100,$B4)/1000) -> 2952.303 | Y4: =IF(Y$3=0,"",SUMIFS(INDEX(Inputs!$D$4:$AG$100,0,MATCH(Y$2,Inputs!$D$2:$AG$2,0)),Inputs!$B$4:$B$100,$B4)/1000) -> 2885.529 | Z4: =IF(Z$3=0,"",SUMIFS(INDEX(Inputs!$D$4:$AG$100,0,MATCH(Z$2,Inputs!$D$2:$AG$2,0)),Inputs!$B$4:$B$100,$B4)/1000) -> 3537.391 | AA4: =IF(AA$3=0,"",SUMIFS(INDEX(Inputs!$D$4:$AG$100,0,MATCH(AA$2,Inputs!$D$2:$AG$2,0)),Inputs!$B$4:$B$100,$B4)/1000) -> 3801.729 | AB4: =IF(COUNT(X4:AA4)=4,SUM(X4:AA4),"") -> 13176.952 | AC4: =IF(AC$3=0,"",SUMIFS(INDEX(Inputs!$D$4:$AG$100,0,MATCH(AC$2,Inputs!$D$2:$AG$2,0)),Inputs!$B$4:$B$100,$B4)/1000) -> 3074.535 | AD4: =IF(AD$3=0,"",SUMIFS(INDEX(Inputs!$D$4:$AG$100,0,MATCH(AD$2,Inputs!$D$2:$AG$2,0)),Inputs!$B$4:$B$100,$B4)/1000) -> 3055.499 | AE4: =IF(AE$3=0,"",SUMIFS(INDEX(Inputs!$D$4:$AG$100,0,MATCH(AE$2,Inputs!$D$2:$AG$2,0)),Inputs!$B$4:$B$100,$B4)/1000) | AF4: =IF(AF$3=0,"",SUMIFS(INDEX(Inputs!$D$4:$AG$100,0,MATCH(AF$2,Inputs!$D$2:$AG$2,0)),Inputs!$B$4:$B$100,$B4)/1000) | AG4: =IF(COUNT(AC4:AF4)=4,SUM(AC4:AF4),"")
B5: 2 | C5: COGS (cash) | D5: =IF(D$3=0,"",SUMIFS(INDEX(Inputs!$D$4:$AG$100,0,MATCH(D$2,Inputs!$D$2:$AG$2,0)),Inputs!$B$4:$B$100,$B5)/1000) -> -145.037 | E5: =IF(E$3=0,"",SUMIFS(INDEX(Inputs!$D$4:$AG$100,0,MATCH(E$2,Inputs!$D$2:$AG$2,0)),Inputs!$B$4:$B$100,$B5)/1000) -> -270.903 | F5: =IF(F$3=0,"",SUMIFS(INDEX(Inputs!$D$4:$AG$100,0,MATCH(F$2,Inputs!$D$2:$AG$2,0)),Inputs!$B$4:$B$100,$B5)/1000) -> 334.446 | G5: =IF(G$3=0,"",SUMIFS(INDEX(Inputs!$D$4:$AG$100,0,MATCH(G$2,Inputs!$D$2:$AG$2,0)),Inputs!$B$4:$B$100,$B5)/1000) -> -442.928 | H5: =IF(COUNT(D5:G5)=4,SUM(D5:G5),"") -> -524.422 | I5: =IF(I$3=0,"",SUMIFS(INDEX(Inputs!$D$4:$AG$100,0,MATCH(I$2,Inputs!$D$2:$AG$2,0)),Inputs!$B$4:$B$100,$B5)/1000) -> -705.903 | J5: =IF(J$3=0,"",SUMIFS(INDEX(Inputs!$D$4:$AG$100,0,MATCH(J$2,Inputs!$D$2:$AG$2,0)),Inputs!$B$4:$B$100,$B5)/1000) -> -885.151 | K5: =IF(K$3=0,"",SUMIFS(INDEX(Inputs!$D$4:$AG$100,0,MATCH(K$2,Inputs!$D$2:$AG$2,0)),Inputs!$B$4:$B$100,$B5)/1000) -> -1072.724 | L5: =IF(L$3=0,"",SUMIFS(INDEX(Inputs!$D$4:$AG$100,0,MATCH(L$2,Inputs!$D$2:$AG$2,0)),Inputs!$B$4:$B$100,$B5)/1000) -> -1111.091 | M5: =IF(COUNT(I5:L5)=4,SUM(I5:L5),"") -> -3774.869 | N5: =IF(N$3=0,"",SUMIFS(INDEX(Inputs!$D$4:$AG$100,0,MATCH(N$2,Inputs!$D$2:$AG$2,0)),Inputs!$B$4:$B$100,$B5)/1000) -> -912.817 | O5: =IF(O$3=0,"",SUMIFS(INDEX(Inputs!$D$4:$AG$100,0,MATCH(O$2,Inputs!$D$2:$AG$2,0)),Inputs!$B$4:$B$100,$B5)/1000) -> -925.86 | P5: =IF(P$3=0,"",SUMIFS(INDEX(Inputs!$D$4:$AG$100,0,MATCH(P$2,Inputs!$D$2:$AG$2,0)),Inputs!$B$4:$B$100,$B5)/1000) -> -1129.51 | Q5: =IF(Q$3=0,"",SUMIFS(INDEX(Inputs!$D$4:$AG$100,0,MATCH(Q$2,Inputs!$D$2:$AG$2,0)),Inputs!$B$4:$B$100,$B5)/1000) -> -1203.484 | R5: =IF(COUNT(N5:Q5)=4,SUM(N5:Q5),"") -> -4171.671 | S5: =IF(S$3=0,"",SUMIFS(INDEX(Inputs!$D$4:$AG$100,0,MATCH(S$2,Inputs!$D$2:$AG$2,0)),Inputs!$B$4:$B$100,$B5)/1000) -> -940.124 | T5: =IF(T$3=0,"",SUMIFS(INDEX(Inputs!$D$4:$AG$100,0,MATCH(T$2,Inputs!$D$2:$AG$2,0)),Inputs!$B$4:$B$100,$B5)/1000) -> -953.328 | U5: =IF(U$3=0,"",SUMIFS(INDEX(Inputs!$D$4:$AG$100,0,MATCH(U$2,Inputs!$D$2:$AG$2,0)),Inputs!$B$4:$B$100,$B5)/1000) -> -1544.378 | V5: =IF(V$3=0,"",SUMIFS(INDEX(Inputs!$D$4:$AG$100,0,MATCH(V$2,Inputs!$D$2:$AG$2,0)),Inputs!$B$4:$B$100,$B5)/1000) -> -2479.928 | W5: =IF(COUNT(S5:V5)=4,SUM(S5:V5),"") -> -5917.758 | X5: =IF(X$3=0,"",SUMIFS(INDEX(Inputs!$D$4:$AG$100,0,MATCH(X$2,Inputs!$D$2:$AG$2,0)),Inputs!$B$4:$B$100,$B5)/1000) -> -1657.838 | Y5: =IF(Y$3=0,"",SUMIFS(INDEX(Inputs!$D$4:$AG$100,0,MATCH(Y$2,Inputs!$D$2:$AG$2,0)),Inputs!$B$4:$B$100,$B5)/1000) -> -1868.345 | Z5: =IF(Z$3=0,"",SUMIFS(INDEX(Inputs!$D$4:$AG$100,0,MATCH(Z$2,Inputs!$D$2:$AG$2,0)),Inputs!$B$4:$B$100,$B5)/1000) -> -2735.147 | AA5: =IF(AA$3=0,"",SUMIFS(INDEX(Inputs!$D$4:$AG$100,0,MATCH(AA$2,Inputs!$D$2:$AG$2,0)),Inputs!$B$4:$B$100,$B5)/1000) -> -2841.923 | AB5: =IF(COUNT(X5:AA5)=4,SUM(X5:AA5),"") -> -9103.253 | AC5: =IF(AC$3=0,"",SUMIFS(INDEX(Inputs!$D$4:$AG$100,0,MATCH(AC$2,Inputs!$D$2:$AG$2,0)),Inputs!$B$4:$B$100,$B5)/1000) -> -2120.25 | AD5: =IF(AD$3=0,"",SUMIFS(INDEX(Inputs!$D$4:$AG$100,0,MATCH(AD$2,Inputs!$D$2:$AG$2,0)),Inputs!$B$4:$B$100,$B5)/1000) -> -2137.818 | AE5: =IF(AE$3=0,"",SUMIFS(INDEX(Inputs!$D$4:$AG$100,0,MATCH(AE$2,Inputs!$D$2:$AG$2,0)),Inputs!$B$4:$B$100,$B5)/1000) | AF5: =IF(AF$3=0,"",SUMIFS(INDEX(Inputs!$D$4:$AG$100,0,MATCH(AF$2,Inputs!$D$2:$AG$2,0)),Inputs!$B$4:$B$100,$B5)/1000) | AG5: =IF(COUNT(AC5:AF5)=4,SUM(AC5:AF5),"")
B6: 3 | C6: SG&A and Other (cash) | D6: =IF(D$3=0,"",SUMIFS(INDEX(Inputs!$D$4:$AG$100,0,MATCH(D$2,Inputs!$D$2:$AG$2,0)),Inputs!$B$4:$B$100,$B6)/1000) -> -37.007 | E6: =IF(E$3=0,"",SUMIFS(INDEX(Inputs!$D$4:$AG$100,0,MATCH(E$2,Inputs!$D$2:$AG$2,0)),Inputs!$B$4:$B$100,$B6)/1000) -> -72.009 | F6: =IF(F$3=0,"",SUMIFS(INDEX(Inputs!$D$4:$AG$100,0,MATCH(F$2,Inputs!$D$2:$AG$2,0)),Inputs!$B$4:$B$100,$B6)/1000) -> -98.542 | G6: =IF(G$3=0,"",SUMIFS(INDEX(Inputs!$D$4:$AG$100,0,MATCH(G$2,Inputs!$D$2:$AG$2,0)),Inputs!$B$4:$B$100,$B6)/1000) -> -5.338 | H6: =IF(COUNT(D6:G6)=4,SUM(D6:G6),"") -> -212.896 | I6: =IF(I$3=0,"",SUMIFS(INDEX(Inputs!$D$4:$AG$100,0,MATCH(I$2,Inputs!$D$2:$AG$2,0)),Inputs!$B$4:$B$100,$B6)/1000) -> -134.703 | J6: =IF(J$3=0,"",SUMIFS(INDEX(Inputs!$D$4:$AG$100,0,MATCH(J$2,Inputs!$D$2:$AG$2,0)),Inputs!$B$4:$B$100,$B6)/1000) -> -172.018 | K6: =IF(K$3=0,"",SUMIFS(INDEX(Inputs!$D$4:$AG$100,0,MATCH(K$2,Inputs!$D$2:$AG$2,0)),Inputs!$B$4:$B$100,$B6)/1000) -> 37.062 | L6: =IF(L$3=0,"",SUMIFS(INDEX(Inputs!$D$4:$AG$100,0,MATCH(L$2,Inputs!$D$2:$AG$2,0)),Inputs!$B$4:$B$100,$B6)/1000) -> 386.982 | M6: =IF(COUNT(I6:L6)=4,SUM(I6:L6),"") -> 117.323 | N6: =IF(N$3=0,"",SUMIFS(INDEX(Inputs!$D$4:$AG$100,0,MATCH(N$2,Inputs!$D$2:$AG$2,0)),Inputs!$B$4:$B$100,$B6)/1000) -> -49.811 | O6: =IF(O$3=0,"",SUMIFS(INDEX(Inputs!$D$4:$AG$100,0,MATCH(O$2,Inputs!$D$2:$AG$2,0)),Inputs!$B$4:$B$100,$B6)/1000) -> -53.318 | P6: =IF(P$3=0,"",SUMIFS(INDEX(Inputs!$D$4:$AG$100,0,MATCH(P$2,Inputs!$D$2:$AG$2,0)),Inputs!$B$4:$B$100,$B6)/1000) -> -147 | Q6: =IF(Q$3=0,"",SUMIFS(INDEX(Inputs!$D$4:$AG$100,0,MATCH(Q$2,Inputs!$D$2:$AG$2,0)),Inputs!$B$4:$B$100,$B6)/1000) -> -82.213 | R6: =IF(COUNT(N6:Q6)=4,SUM(N6:Q6),"") -> -332.342 | S6: =IF(S$3=0,"",SUMIFS(INDEX(Inputs!$D$4:$AG$100,0,MATCH(S$2,Inputs!$D$2:$AG$2,0)),Inputs!$B$4:$B$100,$B6)/1000) -> 142.237 | T6: =IF(T$3=0,"",SUMIFS(INDEX(Inputs!$D$4:$AG$100,0,MATCH(T$2,Inputs!$D$2:$AG$2,0)),Inputs!$B$4:$B$100,$B6)/1000) -> -98.647 | U6: =IF(U$3=0,"",SUMIFS(INDEX(Inputs!$D$4:$AG$100,0,MATCH(U$2,Inputs!$D$2:$AG$2,0)),Inputs!$B$4:$B$100,$B6)/1000) -> 131.446 | V6: =IF(V$3=0,"",SUMIFS(INDEX(Inputs!$D$4:$AG$100,0,MATCH(V$2,Inputs!$D$2:$AG$2,0)),Inputs!$B$4:$B$100,$B6)/1000) -> -476.758 | W6: =IF(COUNT(S6:V6)=4,SUM(S6:V6),"") -> -301.722 | X6: =IF(X$3=0,"",SUMIFS(INDEX(Inputs!$D$4:$AG$100,0,MATCH(X$2,Inputs!$D$2:$AG$2,0)),Inputs!$B$4:$B$100,$B6)/1000) -> 83.043 | Y6: =IF(Y$3=0,"",SUMIFS(INDEX(Inputs!$D$4:$AG$100,0,MATCH(Y$2,Inputs!$D$2:$AG$2,0)),Inputs!$B$4:$B$100,$B6)/1000) -> -500.171 | Z6: =IF(Z$3=0,"",SUMIFS(INDEX(Inputs!$D$4:$AG$100,0,MATCH(Z$2,Inputs!$D$2:$AG$2,0)),Inputs!$B$4:$B$100,$B6)/1000) -> -137.92 | AA6: =IF(AA$3=0,"",SUMIFS(INDEX(Inputs!$D$4:$AG$100,0,MATCH(AA$2,Inputs!$D$2:$AG$2,0)),Inputs!$B$4:$B$100,$B6)/1000) -> 515.089 | AB6: =IF(COUNT(X6:AA6)=4,SUM(X6:AA6),"") -> -39.959 | AC6: =IF(AC$3=0,"",SUMIFS(INDEX(Inputs!$D$4:$AG$100,0,MATCH(AC$2,Inputs!$D$2:$AG$2,0)),Inputs!$B$4:$B$100,$B6)/1000) -> -654.169 | AD6: =IF(AD$3=0,"",SUMIFS(INDEX(Inputs!$D$4:$AG$100,0,MATCH(AD$2,Inputs!$D$2:$AG$2,0)),Inputs!$B$4:$B$100,$B6)/1000) -> -106.914 | AE6: =IF(AE$3=0,"",SUMIFS(INDEX(Inputs!$D$4:$AG$100,0,MATCH(AE$2,Inputs!$D$2:$AG$2,0)),Inputs!$B$4:$B$100,$B6)/1000) | AF6: =IF(AF$3=0,"",SUMIFS(INDEX(Inputs!$D$4:$AG$100,0,MATCH(AF$2,Inputs!$D$2:$AG$2,0)),Inputs!$B$4:$B$100,$B6)/1000) | AG6: =IF(COUNT(AC6:AF6)=4,SUM(AC6:AF6),"")
B7: 4 | C7: D&A | D7: =IF(D$3=0,"",SUMIFS(INDEX(Inputs!$D$4:$AG$100,0,MATCH(D$2,Inputs!$D$2:$AG$2,0)),Inputs!$B$4:$B$100,$B7)/1000) -> -132.593 | E7: =IF(E$3=0,"",SUMIFS(INDEX(Inputs!$D$4:$AG$100,0,MATCH(E$2,Inputs!$D$2:$AG$2,0)),Inputs!$B$4:$B$100,$B7)/1000) -> -131.573 | F7: =IF(F$3=0,"",SUMIFS(INDEX(Inputs!$D$4:$AG$100,0,MATCH(F$2,Inputs!$D$2:$AG$2,0)),Inputs!$B$4:$B$100,$B7)/1000) -> -145.397 | G7: =IF(G$3=0,"",SUMIFS(INDEX(Inputs!$D$4:$AG$100,0,MATCH(G$2,Inputs!$D$2:$AG$2,0)),Inputs!$B$4:$B$100,$B7)/1000) -> -149.432 | H7: =IF(COUNT(D7:G7)=4,SUM(D7:G7),"") -> -558.995 | I7: =IF(I$3=0,"",SUMIFS(INDEX(Inputs!$D$4:$AG$100,0,MATCH(I$2,Inputs!$D$2:$AG$2,0)),Inputs!$B$4:$B$100,$B7)/1000) -> -157.304 | J7: =IF(J$3=0,"",SUMIFS(INDEX(Inputs!$D$4:$AG$100,0,MATCH(J$2,Inputs!$D$2:$AG$2,0)),Inputs!$B$4:$B$100,$B7)/1000) -> -161.19 | K7: =IF(K$3=0,"",SUMIFS(INDEX(Inputs!$D$4:$AG$100,0,MATCH(K$2,Inputs!$D$2:$AG$2,0)),Inputs!$B$4:$B$100,$B7)/1000) -> -161.353 | L7: =IF(L$3=0,"",SUMIFS(INDEX(Inputs!$D$4:$AG$100,0,MATCH(L$2,Inputs!$D$2:$AG$2,0)),Inputs!$B$4:$B$100,$B7)/1000) -> -117.907 | M7: =IF(COUNT(I7:L7)=4,SUM(I7:L7),"") -> -597.754 | N7: =IF(N$3=0,"",SUMIFS(INDEX(Inputs!$D$4:$AG$100,0,MATCH(N$2,Inputs!$D$2:$AG$2,0)),Inputs!$B$4:$B$100,$B7)/1000) -> -168.327 | O7: =IF(O$3=0,"",SUMIFS(INDEX(Inputs!$D$4:$AG$100,0,MATCH(O$2,Inputs!$D$2:$AG$2,0)),Inputs!$B$4:$B$100,$B7)/1000) -> -169.666 | P7: =IF(P$3=0,"",SUMIFS(INDEX(Inputs!$D$4:$AG$100,0,MATCH(P$2,Inputs!$D$2:$AG$2,0)),Inputs!$B$4:$B$100,$B7)/1000) -> -169.643 | Q7: =IF(Q$3=0,"",SUMIFS(INDEX(Inputs!$D$4:$AG$100,0,MATCH(Q$2,Inputs!$D$2:$AG$2,0)),Inputs!$B$4:$B$100,$B7)/1000) -> -169.639 | R7: =IF(COUNT(N7:Q7)=4,SUM(N7:Q7),"") -> -677.275 | S7: =IF(S$3=0,"",SUMIFS(INDEX(Inputs!$D$4:$AG$100,0,MATCH(S$2,Inputs!$D$2:$AG$2,0)),Inputs!$B$4:$B$100,$B7)/1000) -> -166.381 | T7: =IF(T$3=0,"",SUMIFS(INDEX(Inputs!$D$4:$AG$100,0,MATCH(T$2,Inputs!$D$2:$AG$2,0)),Inputs!$B$4:$B$100,$B7)/1000) -> -175.177 | U7: =IF(U$3=0,"",SUMIFS(INDEX(Inputs!$D$4:$AG$100,0,MATCH(U$2,Inputs!$D$2:$AG$2,0)),Inputs!$B$4:$B$100,$B7)/1000) -> -182.611 | V7: =IF(V$3=0,"",SUMIFS(INDEX(Inputs!$D$4:$AG$100,0,MATCH(V$2,Inputs!$D$2:$AG$2,0)),Inputs!$B$4:$B$100,$B7)/1000) -> -189.021 | W7: =IF(COUNT(S7:V7)=4,SUM(S7:V7),"") -> -713.19 | X7: =IF(X$3=0,"",SUMIFS(INDEX(Inputs!$D$4:$AG$100,0,MATCH(X$2,Inputs!$D$2:$AG$2,0)),Inputs!$B$4:$B$100,$B7)/1000) -> -458.196 | Y7: =IF(Y$3=0,"",SUMIFS(INDEX(Inputs!$D$4:$AG$100,0,MATCH(Y$2,Inputs!$D$2:$AG$2,0)),Inputs!$B$4:$B$100,$B7)/1000) -> -521.747 | Z7: =IF(Z$3=0,"",SUMIFS(INDEX(Inputs!$D$4:$AG$100,0,MATCH(Z$2,Inputs!$D$2:$AG$2,0)),Inputs!$B$4:$B$100,$B7)/1000) -> -465.553 | AA7: =IF(AA$3=0,"",SUMIFS(INDEX(Inputs!$D$4:$AG$100,0,MATCH(AA$2,Inputs!$D$2:$AG$2,0)),Inputs!$B$4:$B$100,$B7)/1000) -> -477.467 | AB7: =IF(COUNT(X7:AA7)=4,SUM(X7:AA7),"") -> -1922.963 | AC7: =IF(AC$3=0,"",SUMIFS(INDEX(Inputs!$D$4:$AG$100,0,MATCH(AC$2,Inputs!$D$2:$AG$2,0)),Inputs!$B$4:$B$100,$B7)/1000) -> -466.831 | AD7: =IF(AD$3=0,"",SUMIFS(INDEX(Inputs!$D$4:$AG$100,0,MATCH(AD$2,Inputs!$D$2:$AG$2,0)),Inputs!$B$4:$B$100,$B7)/1000) -> -465.443 | AE7: =IF(AE$3=0,"",SUMIFS(INDEX(Inputs!$D$4:$AG$100,0,MATCH(AE$2,Inputs!$D$2:$AG$2,0)),Inputs!$B$4:$B$100,$B7)/1000) | AF7: =IF(AF$3=0,"",SUMIFS(INDEX(Inputs!$D$4:$AG$100,0,MATCH(AF$2,Inputs!$D$2:$AG$2,0)),Inputs!$B$4:$B$100,$B7)/1000) | AG7: =IF(COUNT(AC7:AF7)=4,SUM(AC7:AF7),"")
B8: 5 | C8: Interest Expense | D8: =IF(D$3=0,"",SUMIFS(INDEX(Inputs!$D$4:$AG$100,0,MATCH(D$2,Inputs!$D$2:$AG$2,0)),Inputs!$B$4:$B$100,$B8)/1000) -> -164.756 | E8: =IF(E$3=0,"",SUMIFS(INDEX(Inputs!$D$4:$AG$100,0,MATCH(E$2,Inputs!$D$2:$AG$2,0)),Inputs!$B$4:$B$100,$B8)/1000) -> -211.669 | F8: =IF(F$3=0,"",SUMIFS(INDEX(Inputs!$D$4:$AG$100,0,MATCH(F$2,Inputs!$D$2:$AG$2,0)),Inputs!$B$4:$B$100,$B8)/1000) -> -193.237 | G8: =IF(G$3=0,"",SUMIFS(INDEX(Inputs!$D$4:$AG$100,0,MATCH(G$2,Inputs!$D$2:$AG$2,0)),Inputs!$B$4:$B$100,$B8)/1000) -> -238.999 | H8: =IF(COUNT(D8:G8)=4,SUM(D8:G8),"") -> -808.661 | I8: =IF(I$3=0,"",SUMIFS(INDEX(Inputs!$D$4:$AG$100,0,MATCH(I$2,Inputs!$D$2:$AG$2,0)),Inputs!$B$4:$B$100,$B8)/1000) -> -250.51 | J8: =IF(J$3=0,"",SUMIFS(INDEX(Inputs!$D$4:$AG$100,0,MATCH(J$2,Inputs!$D$2:$AG$2,0)),Inputs!$B$4:$B$100,$B8)/1000) -> -291.34 | K8: =IF(K$3=0,"",SUMIFS(INDEX(Inputs!$D$4:$AG$100,0,MATCH(K$2,Inputs!$D$2:$AG$2,0)),Inputs!$B$4:$B$100,$B8)/1000) -> -165.812 | L8: =IF(L$3=0,"",SUMIFS(INDEX(Inputs!$D$4:$AG$100,0,MATCH(L$2,Inputs!$D$2:$AG$2,0)),Inputs!$B$4:$B$100,$B8)/1000) -> -468.975 | M8: =IF(COUNT(I8:L8)=4,SUM(I8:L8),"") -> -1176.637 | N8: =IF(N$3=0,"",SUMIFS(INDEX(Inputs!$D$4:$AG$100,0,MATCH(N$2,Inputs!$D$2:$AG$2,0)),Inputs!$B$4:$B$100,$B8)/1000) -> -272.035 | O8: =IF(O$3=0,"",SUMIFS(INDEX(Inputs!$D$4:$AG$100,0,MATCH(O$2,Inputs!$D$2:$AG$2,0)),Inputs!$B$4:$B$100,$B8)/1000) -> -497.689 | P8: =IF(P$3=0,"",SUMIFS(INDEX(Inputs!$D$4:$AG$100,0,MATCH(P$2,Inputs!$D$2:$AG$2,0)),Inputs!$B$4:$B$100,$B8)/1000) -> -194.621 | Q8: =IF(Q$3=0,"",SUMIFS(INDEX(Inputs!$D$4:$AG$100,0,MATCH(Q$2,Inputs!$D$2:$AG$2,0)),Inputs!$B$4:$B$100,$B8)/1000) -> -215.024 | R8: =IF(COUNT(N8:Q8)=4,SUM(N8:Q8),"") -> -1179.369 | S8: =IF(S$3=0,"",SUMIFS(INDEX(Inputs!$D$4:$AG$100,0,MATCH(S$2,Inputs!$D$2:$AG$2,0)),Inputs!$B$4:$B$100,$B8)/1000) -> -258.839 | T8: =IF(T$3=0,"",SUMIFS(INDEX(Inputs!$D$4:$AG$100,0,MATCH(T$2,Inputs!$D$2:$AG$2,0)),Inputs!$B$4:$B$100,$B8)/1000) -> -255.757 | U8: =IF(U$3=0,"",SUMIFS(INDEX(Inputs!$D$4:$AG$100,0,MATCH(U$2,Inputs!$D$2:$AG$2,0)),Inputs!$B$4:$B$100,$B8)/1000) -> -243.887 | V8: =IF(V$3=0,"",SUMIFS(INDEX(Inputs!$D$4:$AG$100,0,MATCH(V$2,Inputs!$D$2:$AG$2,0)),Inputs!$B$4:$B$100,$B8)/1000) -> -717.696 | W8: =IF(COUNT(S8:V8)=4,SUM(S8:V8),"") -> -1476.179 | X8: =IF(X$3=0,"",SUMIFS(INDEX(Inputs!$D$4:$AG$100,0,MATCH(X$2,Inputs!$D$2:$AG$2,0)),Inputs!$B$4:$B$100,$B8)/1000) -> -1008.815 | Y8: =IF(Y$3=0,"",SUMIFS(INDEX(Inputs!$D$4:$AG$100,0,MATCH(Y$2,Inputs!$D$2:$AG$2,0)),Inputs!$B$4:$B$100,$B8)/1000) -> -879.279 | Z8: =IF(Z$3=0,"",SUMIFS(INDEX(Inputs!$D$4:$AG$100,0,MATCH(Z$2,Inputs!$D$2:$AG$2,0)),Inputs!$B$4:$B$100,$B8)/1000) -> -869.78 | AA8: =IF(AA$3=0,"",SUMIFS(INDEX(Inputs!$D$4:$AG$100,0,MATCH(AA$2,Inputs!$D$2:$AG$2,0)),Inputs!$B$4:$B$100,$B8)/1000) -> -783.788 | AB8: =IF(COUNT(X8:AA8)=4,SUM(X8:AA8),"") -> -3541.662 | AC8: =IF(AC$3=0,"",SUMIFS(INDEX(Inputs!$D$4:$AG$100,0,MATCH(AC$2,Inputs!$D$2:$AG$2,0)),Inputs!$B$4:$B$100,$B8)/1000) -> -867.481 | AD8: =IF(AD$3=0,"",SUMIFS(INDEX(Inputs!$D$4:$AG$100,0,MATCH(AD$2,Inputs!$D$2:$AG$2,0)),Inputs!$B$4:$B$100,$B8)/1000) -> -1018.168 | AE8: =IF(AE$3=0,"",SUMIFS(INDEX(Inputs!$D$4:$AG$100,0,MATCH(AE$2,Inputs!$D$2:$AG$2,0)),Inputs!$B$4:$B$100,$B8)/1000) | AF8: =IF(AF$3=0,"",SUMIFS(INDEX(Inputs!$D$4:$AG$100,0,MATCH(AF$2,Inputs!$D$2:$AG$2,0)),Inputs!$B$4:$B$100,$B8)/1000) | AG8: =IF(COUNT(AC8:AF8)=4,SUM(AC8:AF8),"")
B9: 6 | C9: Nonoperating Income / (Loss) | D9: =IF(D$3=0,"",SUMIFS(INDEX(Inputs!$D$4:$AG$100,0,MATCH(D$2,Inputs!$D$2:$AG$2,0)),Inputs!$B$4:$B$100,$B9)/1000) -> 13.753 | E9: =IF(E$3=0,"",SUMIFS(INDEX(Inputs!$D$4:$AG$100,0,MATCH(E$2,Inputs!$D$2:$AG$2,0)),Inputs!$B$4:$B$100,$B9)/1000) -> 11.716 | F9: =IF(F$3=0,"",SUMIFS(INDEX(Inputs!$D$4:$AG$100,0,MATCH(F$2,Inputs!$D$2:$AG$2,0)),Inputs!$B$4:$B$100,$B9)/1000) -> 41.663 | G9: =IF(G$3=0,"",SUMIFS(INDEX(Inputs!$D$4:$AG$100,0,MATCH(G$2,Inputs!$D$2:$AG$2,0)),Inputs!$B$4:$B$100,$B9)/1000) -> 33.412 | H9: =IF(COUNT(D9:G9)=4,SUM(D9:G9),"") -> 100.544 | I9: =IF(I$3=0,"",SUMIFS(INDEX(Inputs!$D$4:$AG$100,0,MATCH(I$2,Inputs!$D$2:$AG$2,0)),Inputs!$B$4:$B$100,$B9)/1000) -> 86.074 | J9: =IF(J$3=0,"",SUMIFS(INDEX(Inputs!$D$4:$AG$100,0,MATCH(J$2,Inputs!$D$2:$AG$2,0)),Inputs!$B$4:$B$100,$B9)/1000) -> 103.888 | K9: =IF(K$3=0,"",SUMIFS(INDEX(Inputs!$D$4:$AG$100,0,MATCH(K$2,Inputs!$D$2:$AG$2,0)),Inputs!$B$4:$B$100,$B9)/1000) -> 112.759 | L9: =IF(L$3=0,"",SUMIFS(INDEX(Inputs!$D$4:$AG$100,0,MATCH(L$2,Inputs!$D$2:$AG$2,0)),Inputs!$B$4:$B$100,$B9)/1000) -> 2536.191 | M9: =IF(COUNT(I9:L9)=4,SUM(I9:L9),"") -> 2838.912 | N9: =IF(N$3=0,"",SUMIFS(INDEX(Inputs!$D$4:$AG$100,0,MATCH(N$2,Inputs!$D$2:$AG$2,0)),Inputs!$B$4:$B$100,$B9)/1000) -> 254.848 | O9: =IF(O$3=0,"",SUMIFS(INDEX(Inputs!$D$4:$AG$100,0,MATCH(O$2,Inputs!$D$2:$AG$2,0)),Inputs!$B$4:$B$100,$B9)/1000) -> 473.238 | P9: =IF(P$3=0,"",SUMIFS(INDEX(Inputs!$D$4:$AG$100,0,MATCH(P$2,Inputs!$D$2:$AG$2,0)),Inputs!$B$4:$B$100,$B9)/1000) -> 74.493 | Q9: =IF(Q$3=0,"",SUMIFS(INDEX(Inputs!$D$4:$AG$100,0,MATCH(Q$2,Inputs!$D$2:$AG$2,0)),Inputs!$B$4:$B$100,$B9)/1000) -> 138.783 | R9: =IF(COUNT(N9:Q9)=4,SUM(N9:Q9),"") -> 941.362 | S9: =IF(S$3=0,"",SUMIFS(INDEX(Inputs!$D$4:$AG$100,0,MATCH(S$2,Inputs!$D$2:$AG$2,0)),Inputs!$B$4:$B$100,$B9)/1000) -> 149.86 | T9: =IF(T$3=0,"",SUMIFS(INDEX(Inputs!$D$4:$AG$100,0,MATCH(T$2,Inputs!$D$2:$AG$2,0)),Inputs!$B$4:$B$100,$B9)/1000) -> 119.705 | U9: =IF(U$3=0,"",SUMIFS(INDEX(Inputs!$D$4:$AG$100,0,MATCH(U$2,Inputs!$D$2:$AG$2,0)),Inputs!$B$4:$B$100,$B9)/1000) -> 141.262 | V9: =IF(V$3=0,"",SUMIFS(INDEX(Inputs!$D$4:$AG$100,0,MATCH(V$2,Inputs!$D$2:$AG$2,0)),Inputs!$B$4:$B$100,$B9)/1000) -> 304.06 | W9: =IF(COUNT(S9:V9)=4,SUM(S9:V9),"") -> 714.887 | X9: =IF(X$3=0,"",SUMIFS(INDEX(Inputs!$D$4:$AG$100,0,MATCH(X$2,Inputs!$D$2:$AG$2,0)),Inputs!$B$4:$B$100,$B9)/1000) -> 276.738 | Y9: =IF(Y$3=0,"",SUMIFS(INDEX(Inputs!$D$4:$AG$100,0,MATCH(Y$2,Inputs!$D$2:$AG$2,0)),Inputs!$B$4:$B$100,$B9)/1000) -> 234.752 | Z9: =IF(Z$3=0,"",SUMIFS(INDEX(Inputs!$D$4:$AG$100,0,MATCH(Z$2,Inputs!$D$2:$AG$2,0)),Inputs!$B$4:$B$100,$B9)/1000) -> 244.49 | AA9: =IF(AA$3=0,"",SUMIFS(INDEX(Inputs!$D$4:$AG$100,0,MATCH(AA$2,Inputs!$D$2:$AG$2,0)),Inputs!$B$4:$B$100,$B9)/1000) -> 351.744 | AB9: =IF(COUNT(X9:AA9)=4,SUM(X9:AA9),"") -> 1107.724 | AC9: =IF(AC$3=0,"",SUMIFS(INDEX(Inputs!$D$4:$AG$100,0,MATCH(AC$2,Inputs!$D$2:$AG$2,0)),Inputs!$B$4:$B$100,$B9)/1000) -> 277.65 | AD9: =IF(AD$3=0,"",SUMIFS(INDEX(Inputs!$D$4:$AG$100,0,MATCH(AD$2,Inputs!$D$2:$AG$2,0)),Inputs!$B$4:$B$100,$B9)/1000) -> 286.022 | AE9: =IF(AE$3=0,"",SUMIFS(INDEX(Inputs!$D$4:$AG$100,0,MATCH(AE$2,Inputs!$D$2:$AG$2,0)),Inputs!$B$4:$B$100,$B9)/1000) | AF9: =IF(AF$3=0,"",SUMIFS(INDEX(Inputs!$D$4:$AG$100,0,MATCH(AF$2,Inputs!$D$2:$AG$2,0)),Inputs!$B$4:$B$100,$B9)/1000) | AG9: =IF(COUNT(AC9:AF9)=4,SUM(AC9:AF9),"")
B10: 7 | C10: Taxes | D10: =IF(D$3=0,"",SUMIFS(INDEX(Inputs!$D$4:$AG$100,0,MATCH(D$2,Inputs!$D$2:$AG$2,0)),Inputs!$B$4:$B$100,$B10)/1000) -> -46.947 | E10: =IF(E$3=0,"",SUMIFS(INDEX(Inputs!$D$4:$AG$100,0,MATCH(E$2,Inputs!$D$2:$AG$2,0)),Inputs!$B$4:$B$100,$B10)/1000) -> 7.108 | F10: =IF(F$3=0,"",SUMIFS(INDEX(Inputs!$D$4:$AG$100,0,MATCH(F$2,Inputs!$D$2:$AG$2,0)),Inputs!$B$4:$B$100,$B10)/1000) -> -238.601 | G10: =IF(G$3=0,"",SUMIFS(INDEX(Inputs!$D$4:$AG$100,0,MATCH(G$2,Inputs!$D$2:$AG$2,0)),Inputs!$B$4:$B$100,$B10)/1000) -> 16.235 | H10: =IF(COUNT(D10:G10)=4,SUM(D10:G10),"") -> -262.205 | I10: =IF(I$3=0,"",SUMIFS(INDEX(Inputs!$D$4:$AG$100,0,MATCH(I$2,Inputs!$D$2:$AG$2,0)),Inputs!$B$4:$B$100,$B10)/1000) -> -14.548 | J10: =IF(J$3=0,"",SUMIFS(INDEX(Inputs!$D$4:$AG$100,0,MATCH(J$2,Inputs!$D$2:$AG$2,0)),Inputs!$B$4:$B$100,$B10)/1000) -> 2.189 | K10: =IF(K$3=0,"",SUMIFS(INDEX(Inputs!$D$4:$AG$100,0,MATCH(K$2,Inputs!$D$2:$AG$2,0)),Inputs!$B$4:$B$100,$B10)/1000) -> -111.046 | L10: =IF(L$3=0,"",SUMIFS(INDEX(Inputs!$D$4:$AG$100,0,MATCH(L$2,Inputs!$D$2:$AG$2,0)),Inputs!$B$4:$B$100,$B10)/1000) -> -251.321 | M10: =IF(COUNT(I10:L10)=4,SUM(I10:L10),"") -> -374.726 | N10: =IF(N$3=0,"",SUMIFS(INDEX(Inputs!$D$4:$AG$100,0,MATCH(N$2,Inputs!$D$2:$AG$2,0)),Inputs!$B$4:$B$100,$B10)/1000) -> -66.645 | O10: =IF(O$3=0,"",SUMIFS(INDEX(Inputs!$D$4:$AG$100,0,MATCH(O$2,Inputs!$D$2:$AG$2,0)),Inputs!$B$4:$B$100,$B10)/1000) -> -69.024 | P10: =IF(P$3=0,"",SUMIFS(INDEX(Inputs!$D$4:$AG$100,0,MATCH(P$2,Inputs!$D$2:$AG$2,0)),Inputs!$B$4:$B$100,$B10)/1000) -> -943.452 | Q10: =IF(Q$3=0,"",SUMIFS(INDEX(Inputs!$D$4:$AG$100,0,MATCH(Q$2,Inputs!$D$2:$AG$2,0)),Inputs!$B$4:$B$100,$B10)/1000) -> -74.475 | R10: =IF(COUNT(N10:Q10)=4,SUM(N10:Q10),"") -> -1153.596 | S10: =IF(S$3=0,"",SUMIFS(INDEX(Inputs!$D$4:$AG$100,0,MATCH(S$2,Inputs!$D$2:$AG$2,0)),Inputs!$B$4:$B$100,$B10)/1000) -> -137.244 | T10: =IF(T$3=0,"",SUMIFS(INDEX(Inputs!$D$4:$AG$100,0,MATCH(T$2,Inputs!$D$2:$AG$2,0)),Inputs!$B$4:$B$100,$B10)/1000) -> -49.276 | U10: =IF(U$3=0,"",SUMIFS(INDEX(Inputs!$D$4:$AG$100,0,MATCH(U$2,Inputs!$D$2:$AG$2,0)),Inputs!$B$4:$B$100,$B10)/1000) -> -135.947 | V10: =IF(V$3=0,"",SUMIFS(INDEX(Inputs!$D$4:$AG$100,0,MATCH(V$2,Inputs!$D$2:$AG$2,0)),Inputs!$B$4:$B$100,$B10)/1000) -> 63.963 | W10: =IF(COUNT(S10:V10)=4,SUM(S10:V10),"") -> -258.504 | X10: =IF(X$3=0,"",SUMIFS(INDEX(Inputs!$D$4:$AG$100,0,MATCH(X$2,Inputs!$D$2:$AG$2,0)),Inputs!$B$4:$B$100,$B10)/1000) -> -205.385 | Y10: =IF(Y$3=0,"",SUMIFS(INDEX(Inputs!$D$4:$AG$100,0,MATCH(Y$2,Inputs!$D$2:$AG$2,0)),Inputs!$B$4:$B$100,$B10)/1000) -> 71.65 | Z10: =IF(Z$3=0,"",SUMIFS(INDEX(Inputs!$D$4:$AG$100,0,MATCH(Z$2,Inputs!$D$2:$AG$2,0)),Inputs!$B$4:$B$100,$B10)/1000) -> -35.369 | AA10: =IF(AA$3=0,"",SUMIFS(INDEX(Inputs!$D$4:$AG$100,0,MATCH(AA$2,Inputs!$D$2:$AG$2,0)),Inputs!$B$4:$B$100,$B10)/1000) -> -270.957 | AB10: =IF(COUNT(X10:AA10)=4,SUM(X10:AA10),"") -> -440.061 | AC10: =IF(AC$3=0,"",SUMIFS(INDEX(Inputs!$D$4:$AG$100,0,MATCH(AC$2,Inputs!$D$2:$AG$2,0)),Inputs!$B$4:$B$100,$B10)/1000) -> 83.453 | AD10: =IF(AD$3=0,"",SUMIFS(INDEX(Inputs!$D$4:$AG$100,0,MATCH(AD$2,Inputs!$D$2:$AG$2,0)),Inputs!$B$4:$B$100,$B10)/1000) -> -31.833 | AE10: =IF(AE$3=0,"",SUMIFS(INDEX(Inputs!$D$4:$AG$100,0,MATCH(AE$2,Inputs!$D$2:$AG$2,0)),Inputs!$B$4:$B$100,$B10)/1000) | AF10: =IF(AF$3=0,"",SUMIFS(INDEX(Inputs!$D$4:$AG$100,0,MATCH(AF$2,Inputs!$D$2:$AG$2,0)),Inputs!$B$4:$B$100,$B10)/1000) | AG10: =IF(COUNT(AC10:AF10)=4,SUM(AC10:AF10),"")
B11: 8 | C11: Equity in Income of Affiliates, after tax (enter as +) | D11: =IF(D$3=0,"",SUMIFS(INDEX(Inputs!$D$4:$AG$100,0,MATCH(D$2,Inputs!$D$2:$AG$2,0)),Inputs!$B$4:$B$100,$B11)/1000) -> 0 | E11: =IF(E$3=0,"",SUMIFS(INDEX(Inputs!$D$4:$AG$100,0,MATCH(E$2,Inputs!$D$2:$AG$2,0)),Inputs!$B$4:$B$100,$B11)/1000) -> 0 | F11: =IF(F$3=0,"",SUMIFS(INDEX(Inputs!$D$4:$AG$100,0,MATCH(F$2,Inputs!$D$2:$AG$2,0)),Inputs!$B$4:$B$100,$B11)/1000) -> 0 | G11: =IF(G$3=0,"",SUMIFS(INDEX(Inputs!$D$4:$AG$100,0,MATCH(G$2,Inputs!$D$2:$AG$2,0)),Inputs!$B$4:$B$100,$B11)/1000) -> 0 | H11: =IF(COUNT(D11:G11)=4,SUM(D11:G11),"") -> 0 | I11: =IF(I$3=0,"",SUMIFS(INDEX(Inputs!$D$4:$AG$100,0,MATCH(I$2,Inputs!$D$2:$AG$2,0)),Inputs!$B$4:$B$100,$B11)/1000) -> 29.051 | J11: =IF(J$3=0,"",SUMIFS(INDEX(Inputs!$D$4:$AG$100,0,MATCH(J$2,Inputs!$D$2:$AG$2,0)),Inputs!$B$4:$B$100,$B11)/1000) -> 54.94 | K11: =IF(K$3=0,"",SUMIFS(INDEX(Inputs!$D$4:$AG$100,0,MATCH(K$2,Inputs!$D$2:$AG$2,0)),Inputs!$B$4:$B$100,$B11)/1000) -> 52.3 | L11: =IF(L$3=0,"",SUMIFS(INDEX(Inputs!$D$4:$AG$100,0,MATCH(L$2,Inputs!$D$2:$AG$2,0)),Inputs!$B$4:$B$100,$B11)/1000) -> -5.632 | M11: =IF(COUNT(I11:L11)=4,SUM(I11:L11),"") -> 130.659 | N11: =IF(N$3=0,"",SUMIFS(INDEX(Inputs!$D$4:$AG$100,0,MATCH(N$2,Inputs!$D$2:$AG$2,0)),Inputs!$B$4:$B$100,$B11)/1000) -> 30.229 | O11: =IF(O$3=0,"",SUMIFS(INDEX(Inputs!$D$4:$AG$100,0,MATCH(O$2,Inputs!$D$2:$AG$2,0)),Inputs!$B$4:$B$100,$B11)/1000) -> -11.887 | P11: =IF(P$3=0,"",SUMIFS(INDEX(Inputs!$D$4:$AG$100,0,MATCH(P$2,Inputs!$D$2:$AG$2,0)),Inputs!$B$4:$B$100,$B11)/1000) -> 45.027 | Q11: =IF(Q$3=0,"",SUMIFS(INDEX(Inputs!$D$4:$AG$100,0,MATCH(Q$2,Inputs!$D$2:$AG$2,0)),Inputs!$B$4:$B$100,$B11)/1000) -> 9.943 | R11: =IF(COUNT(N11:Q11)=4,SUM(N11:Q11),"") -> 73.312 | S11: =IF(S$3=0,"",SUMIFS(INDEX(Inputs!$D$4:$AG$100,0,MATCH(S$2,Inputs!$D$2:$AG$2,0)),Inputs!$B$4:$B$100,$B11)/1000) -> 66.578 | T11: =IF(T$3=0,"",SUMIFS(INDEX(Inputs!$D$4:$AG$100,0,MATCH(T$2,Inputs!$D$2:$AG$2,0)),Inputs!$B$4:$B$100,$B11)/1000) -> 53.524 | U11: =IF(U$3=0,"",SUMIFS(INDEX(Inputs!$D$4:$AG$100,0,MATCH(U$2,Inputs!$D$2:$AG$2,0)),Inputs!$B$4:$B$100,$B11)/1000) -> 58.434 | V11: =IF(V$3=0,"",SUMIFS(INDEX(Inputs!$D$4:$AG$100,0,MATCH(V$2,Inputs!$D$2:$AG$2,0)),Inputs!$B$4:$B$100,$B11)/1000) -> -14.152 | W11: =IF(COUNT(S11:V11)=4,SUM(S11:V11),"") -> 164.384 | X11: =IF(X$3=0,"",SUMIFS(INDEX(Inputs!$D$4:$AG$100,0,MATCH(X$2,Inputs!$D$2:$AG$2,0)),Inputs!$B$4:$B$100,$B11)/1000) -> 72.147 | Y11: =IF(Y$3=0,"",SUMIFS(INDEX(Inputs!$D$4:$AG$100,0,MATCH(Y$2,Inputs!$D$2:$AG$2,0)),Inputs!$B$4:$B$100,$B11)/1000) -> 14.758 | Z11: =IF(Z$3=0,"",SUMIFS(INDEX(Inputs!$D$4:$AG$100,0,MATCH(Z$2,Inputs!$D$2:$AG$2,0)),Inputs!$B$4:$B$100,$B11)/1000) -> 58.193 | AA11: =IF(AA$3=0,"",SUMIFS(INDEX(Inputs!$D$4:$AG$100,0,MATCH(AA$2,Inputs!$D$2:$AG$2,0)),Inputs!$B$4:$B$100,$B11)/1000) -> 60.249 | AB11: =IF(COUNT(X11:AA11)=4,SUM(X11:AA11),"") -> 205.347 | AC11: =IF(AC$3=0,"",SUMIFS(INDEX(Inputs!$D$4:$AG$100,0,MATCH(AC$2,Inputs!$D$2:$AG$2,0)),Inputs!$B$4:$B$100,$B11)/1000) -> 71.487 | AD11: =IF(AD$3=0,"",SUMIFS(INDEX(Inputs!$D$4:$AG$100,0,MATCH(AD$2,Inputs!$D$2:$AG$2,0)),Inputs!$B$4:$B$100,$B11)/1000) -> 39.594 | AE11: =IF(AE$3=0,"",SUMIFS(INDEX(Inputs!$D$4:$AG$100,0,MATCH(AE$2,Inputs!$D$2:$AG$2,0)),Inputs!$B$4:$B$100,$B11)/1000) | AF11: =IF(AF$3=0,"",SUMIFS(INDEX(Inputs!$D$4:$AG$100,0,MATCH(AF$2,Inputs!$D$2:$AG$2,0)),Inputs!$B$4:$B$100,$B11)/1000) | AG11: =IF(COUNT(AC11:AF11)=4,SUM(AC11:AF11),"")
B12: 9 | C12: Minority Interest Expense, after tax (enter as - ) | D12: =IF(D$3=0,"",SUMIFS(INDEX(Inputs!$D$4:$AG$100,0,MATCH(D$2,Inputs!$D$2:$AG$2,0)),Inputs!$B$4:$B$100,$B12)/1000) -> -29.436 | E12: =IF(E$3=0,"",SUMIFS(INDEX(Inputs!$D$4:$AG$100,0,MATCH(E$2,Inputs!$D$2:$AG$2,0)),Inputs!$B$4:$B$100,$B12)/1000) -> 15.169 | F12: =IF(F$3=0,"",SUMIFS(INDEX(Inputs!$D$4:$AG$100,0,MATCH(F$2,Inputs!$D$2:$AG$2,0)),Inputs!$B$4:$B$100,$B12)/1000) -> -234.281 | G12: =IF(G$3=0,"",SUMIFS(INDEX(Inputs!$D$4:$AG$100,0,MATCH(G$2,Inputs!$D$2:$AG$2,0)),Inputs!$B$4:$B$100,$B12)/1000) -> 34.187 | H12: =IF(COUNT(D12:G12)=4,SUM(D12:G12),"") -> -214.361 | I12: =IF(I$3=0,"",SUMIFS(INDEX(Inputs!$D$4:$AG$100,0,MATCH(I$2,Inputs!$D$2:$AG$2,0)),Inputs!$B$4:$B$100,$B12)/1000) -> -4.214 | J12: =IF(J$3=0,"",SUMIFS(INDEX(Inputs!$D$4:$AG$100,0,MATCH(J$2,Inputs!$D$2:$AG$2,0)),Inputs!$B$4:$B$100,$B12)/1000) -> 0 | K12: =IF(K$3=0,"",SUMIFS(INDEX(Inputs!$D$4:$AG$100,0,MATCH(K$2,Inputs!$D$2:$AG$2,0)),Inputs!$B$4:$B$100,$B12)/1000) -> 0 | L12: =IF(L$3=0,"",SUMIFS(INDEX(Inputs!$D$4:$AG$100,0,MATCH(L$2,Inputs!$D$2:$AG$2,0)),Inputs!$B$4:$B$100,$B12)/1000) -> 0 | M12: =IF(COUNT(I12:L12)=4,SUM(I12:L12),"") -> -4.214 | N12: =IF(N$3=0,"",SUMIFS(INDEX(Inputs!$D$4:$AG$100,0,MATCH(N$2,Inputs!$D$2:$AG$2,0)),Inputs!$B$4:$B$100,$B12)/1000) -> 0 | O12: =IF(O$3=0,"",SUMIFS(INDEX(Inputs!$D$4:$AG$100,0,MATCH(O$2,Inputs!$D$2:$AG$2,0)),Inputs!$B$4:$B$100,$B12)/1000) -> 0 | P12: =IF(P$3=0,"",SUMIFS(INDEX(Inputs!$D$4:$AG$100,0,MATCH(P$2,Inputs!$D$2:$AG$2,0)),Inputs!$B$4:$B$100,$B12)/1000) -> 0 | Q12: =IF(Q$3=0,"",SUMIFS(INDEX(Inputs!$D$4:$AG$100,0,MATCH(Q$2,Inputs!$D$2:$AG$2,0)),Inputs!$B$4:$B$100,$B12)/1000) -> 0 | R12: =IF(COUNT(N12:Q12)=4,SUM(N12:Q12),"") -> 0 | S12: =IF(S$3=0,"",SUMIFS(INDEX(Inputs!$D$4:$AG$100,0,MATCH(S$2,Inputs!$D$2:$AG$2,0)),Inputs!$B$4:$B$100,$B12)/1000) -> 0 | T12: =IF(T$3=0,"",SUMIFS(INDEX(Inputs!$D$4:$AG$100,0,MATCH(T$2,Inputs!$D$2:$AG$2,0)),Inputs!$B$4:$B$100,$B12)/1000) -> 0 | U12: =IF(U$3=0,"",SUMIFS(INDEX(Inputs!$D$4:$AG$100,0,MATCH(U$2,Inputs!$D$2:$AG$2,0)),Inputs!$B$4:$B$100,$B12)/1000) -> 0 | V12: =IF(V$3=0,"",SUMIFS(INDEX(Inputs!$D$4:$AG$100,0,MATCH(V$2,Inputs!$D$2:$AG$2,0)),Inputs!$B$4:$B$100,$B12)/1000) -> -20.931 | W12: =IF(COUNT(S12:V12)=4,SUM(S12:V12),"") -> -20.931 | X12: =IF(X$3=0,"",SUMIFS(INDEX(Inputs!$D$4:$AG$100,0,MATCH(X$2,Inputs!$D$2:$AG$2,0)),Inputs!$B$4:$B$100,$B12)/1000) -> -45.501 | Y12: =IF(Y$3=0,"",SUMIFS(INDEX(Inputs!$D$4:$AG$100,0,MATCH(Y$2,Inputs!$D$2:$AG$2,0)),Inputs!$B$4:$B$100,$B12)/1000) -> -52.537 | Z12: =IF(Z$3=0,"",SUMIFS(INDEX(Inputs!$D$4:$AG$100,0,MATCH(Z$2,Inputs!$D$2:$AG$2,0)),Inputs!$B$4:$B$100,$B12)/1000) -> 6.661 | AA12: =IF(AA$3=0,"",SUMIFS(INDEX(Inputs!$D$4:$AG$100,0,MATCH(AA$2,Inputs!$D$2:$AG$2,0)),Inputs!$B$4:$B$100,$B12)/1000) -> -14.78 | AB12: =IF(COUNT(X12:AA12)=4,SUM(X12:AA12),"") -> -106.157 | AC12: =IF(AC$3=0,"",SUMIFS(INDEX(Inputs!$D$4:$AG$100,0,MATCH(AC$2,Inputs!$D$2:$AG$2,0)),Inputs!$B$4:$B$100,$B12)/1000) -> -19.732 | AD12: =IF(AD$3=0,"",SUMIFS(INDEX(Inputs!$D$4:$AG$100,0,MATCH(AD$2,Inputs!$D$2:$AG$2,0)),Inputs!$B$4:$B$100,$B12)/1000) -> -31.886 | AE12: =IF(AE$3=0,"",SUMIFS(INDEX(Inputs!$D$4:$AG$100,0,MATCH(AE$2,Inputs!$D$2:$AG$2,0)),Inputs!$B$4:$B$100,$B12)/1000) | AF12: =IF(AF$3=0,"",SUMIFS(INDEX(Inputs!$D$4:$AG$100,0,MATCH(AF$2,Inputs!$D$2:$AG$2,0)),Inputs!$B$4:$B$100,$B12)/1000) | AG12: =IF(COUNT(AC12:AF12)=4,SUM(AC12:AF12),"")
B13: 10 | C13: Common Dividends | D13: =IF(D$3=0,"",SUMIFS(INDEX(Inputs!$D$4:$AG$100,0,MATCH(D$2,Inputs!$D$2:$AG$2,0)),Inputs!$B$4:$B$100,$B13)/1000) -> -3.475 | E13: =IF(E$3=0,"",SUMIFS(INDEX(Inputs!$D$4:$AG$100,0,MATCH(E$2,Inputs!$D$2:$AG$2,0)),Inputs!$B$4:$B$100,$B13)/1000) -> -352.302 | F13: =IF(F$3=0,"",SUMIFS(INDEX(Inputs!$D$4:$AG$100,0,MATCH(F$2,Inputs!$D$2:$AG$2,0)),Inputs!$B$4:$B$100,$B13)/1000) -> -146.582 | G13: =IF(G$3=0,"",SUMIFS(INDEX(Inputs!$D$4:$AG$100,0,MATCH(G$2,Inputs!$D$2:$AG$2,0)),Inputs!$B$4:$B$100,$B13)/1000) -> -0.003 | H13: =IF(COUNT(D13:G13)=4,SUM(D13:G13),"") -> -502.362 | I13: =IF(I$3=0,"",SUMIFS(INDEX(Inputs!$D$4:$AG$100,0,MATCH(I$2,Inputs!$D$2:$AG$2,0)),Inputs!$B$4:$B$100,$B13)/1000) -> 0 | J13: =IF(J$3=0,"",SUMIFS(INDEX(Inputs!$D$4:$AG$100,0,MATCH(J$2,Inputs!$D$2:$AG$2,0)),Inputs!$B$4:$B$100,$B13)/1000) -> -99.991 | K13: =IF(K$3=0,"",SUMIFS(INDEX(Inputs!$D$4:$AG$100,0,MATCH(K$2,Inputs!$D$2:$AG$2,0)),Inputs!$B$4:$B$100,$B13)/1000) -> 0 | L13: =IF(L$3=0,"",SUMIFS(INDEX(Inputs!$D$4:$AG$100,0,MATCH(L$2,Inputs!$D$2:$AG$2,0)),Inputs!$B$4:$B$100,$B13)/1000) -> -0.003 | M13: =IF(COUNT(I13:L13)=4,SUM(I13:L13),"") -> -99.994 | N13: =IF(N$3=0,"",SUMIFS(INDEX(Inputs!$D$4:$AG$100,0,MATCH(N$2,Inputs!$D$2:$AG$2,0)),Inputs!$B$4:$B$100,$B13)/1000) -> 0 | O13: =IF(O$3=0,"",SUMIFS(INDEX(Inputs!$D$4:$AG$100,0,MATCH(O$2,Inputs!$D$2:$AG$2,0)),Inputs!$B$4:$B$100,$B13)/1000) -> -1499.809 | P13: =IF(P$3=0,"",SUMIFS(INDEX(Inputs!$D$4:$AG$100,0,MATCH(P$2,Inputs!$D$2:$AG$2,0)),Inputs!$B$4:$B$100,$B13)/1000) -> 0 | Q13: =IF(Q$3=0,"",SUMIFS(INDEX(Inputs!$D$4:$AG$100,0,MATCH(Q$2,Inputs!$D$2:$AG$2,0)),Inputs!$B$4:$B$100,$B13)/1000) -> -1499.817 | R13: =IF(COUNT(N13:Q13)=4,SUM(N13:Q13),"") -> -2999.626 | S13: =IF(S$3=0,"",SUMIFS(INDEX(Inputs!$D$4:$AG$100,0,MATCH(S$2,Inputs!$D$2:$AG$2,0)),Inputs!$B$4:$B$100,$B13)/1000) -> -399.948 | T13: =IF(T$3=0,"",SUMIFS(INDEX(Inputs!$D$4:$AG$100,0,MATCH(T$2,Inputs!$D$2:$AG$2,0)),Inputs!$B$4:$B$100,$B13)/1000) -> -0.001 | U13: =IF(U$3=0,"",SUMIFS(INDEX(Inputs!$D$4:$AG$100,0,MATCH(U$2,Inputs!$D$2:$AG$2,0)),Inputs!$B$4:$B$100,$B13)/1000) -> -0.001 | V13: =IF(V$3=0,"",SUMIFS(INDEX(Inputs!$D$4:$AG$100,0,MATCH(V$2,Inputs!$D$2:$AG$2,0)),Inputs!$B$4:$B$100,$B13)/1000) -> 0 | W13: =IF(COUNT(S13:V13)=4,SUM(S13:V13),"") -> -399.95 | X13: =IF(X$3=0,"",SUMIFS(INDEX(Inputs!$D$4:$AG$100,0,MATCH(X$2,Inputs!$D$2:$AG$2,0)),Inputs!$B$4:$B$100,$B13)/1000) -> -99.648 | Y13: =IF(Y$3=0,"",SUMIFS(INDEX(Inputs!$D$4:$AG$100,0,MATCH(Y$2,Inputs!$D$2:$AG$2,0)),Inputs!$B$4:$B$100,$B13)/1000) -> -61.408 | Z13: =IF(Z$3=0,"",SUMIFS(INDEX(Inputs!$D$4:$AG$100,0,MATCH(Z$2,Inputs!$D$2:$AG$2,0)),Inputs!$B$4:$B$100,$B13)/1000) -> -89.327 | AA13: =IF(AA$3=0,"",SUMIFS(INDEX(Inputs!$D$4:$AG$100,0,MATCH(AA$2,Inputs!$D$2:$AG$2,0)),Inputs!$B$4:$B$100,$B13)/1000) -> 8.548 | AB13: =IF(COUNT(X13:AA13)=4,SUM(X13:AA13),"") -> -241.835 | AC13: =IF(AC$3=0,"",SUMIFS(INDEX(Inputs!$D$4:$AG$100,0,MATCH(AC$2,Inputs!$D$2:$AG$2,0)),Inputs!$B$4:$B$100,$B13)/1000) -> -42.966 | AD13: =IF(AD$3=0,"",SUMIFS(INDEX(Inputs!$D$4:$AG$100,0,MATCH(AD$2,Inputs!$D$2:$AG$2,0)),Inputs!$B$4:$B$100,$B13)/1000) -> 0.148 | AE13: =IF(AE$3=0,"",SUMIFS(INDEX(Inputs!$D$4:$AG$100,0,MATCH(AE$2,Inputs!$D$2:$AG$2,0)),Inputs!$B$4:$B$100,$B13)/1000) | AF13: =IF(AF$3=0,"",SUMIFS(INDEX(Inputs!$D$4:$AG$100,0,MATCH(AF$2,Inputs!$D$2:$AG$2,0)),Inputs!$B$4:$B$100,$B13)/1000) | AG13: =IF(COUNT(AC13:AF13)=4,SUM(AC13:AF13),"")
B15: 11 | C15: Cash and equivalents (inc. investment securities) | D15: =IF(D$3=0,"",SUMIFS(INDEX(Inputs!$D$4:$AG$100,0,MATCH(D$2,Inputs!$D$2:$AG$2,0)),Inputs!$B$4:$B$100,$B15)/1000) -> 1292.369 | E15: =IF(E$3=0,"",SUMIFS(INDEX(Inputs!$D$4:$AG$100,0,MATCH(E$2,Inputs!$D$2:$AG$2,0)),Inputs!$B$4:$B$100,$B15)/1000) -> 1189.841 | F15: =IF(F$3=0,"",SUMIFS(INDEX(Inputs!$D$4:$AG$100,0,MATCH(F$2,Inputs!$D$2:$AG$2,0)),Inputs!$B$4:$B$100,$B15)/1000) -> 1376.313 | G15: =IF(G$3=0,"",SUMIFS(INDEX(Inputs!$D$4:$AG$100,0,MATCH(G$2,Inputs!$D$2:$AG$2,0)),Inputs!$B$4:$B$100,$B15)/1000) -> 1673.569 | H15: =IF(G15="","",G15) -> 1673.569 | I15: =IF(I$3=0,"",SUMIFS(INDEX(Inputs!$D$4:$AG$100,0,MATCH(I$2,Inputs!$D$2:$AG$2,0)),Inputs!$B$4:$B$100,$B15)/1000) -> 3173.847 | J15: =IF(J$3=0,"",SUMIFS(INDEX(Inputs!$D$4:$AG$100,0,MATCH(J$2,Inputs!$D$2:$AG$2,0)),Inputs!$B$4:$B$100,$B15)/1000) -> 3353.966 | K15: =IF(K$3=0,"",SUMIFS(INDEX(Inputs!$D$4:$AG$100,0,MATCH(K$2,Inputs!$D$2:$AG$2,0)),Inputs!$B$4:$B$100,$B15)/1000) -> 2983.696 | L15: =IF(L$3=0,"",SUMIFS(INDEX(Inputs!$D$4:$AG$100,0,MATCH(L$2,Inputs!$D$2:$AG$2,0)),Inputs!$B$4:$B$100,$B15)/1000) -> 3231.306 | M15: =IF(L15="","",L15) -> 3231.306 | N15: =IF(N$3=0,"",SUMIFS(INDEX(Inputs!$D$4:$AG$100,0,MATCH(N$2,Inputs!$D$2:$AG$2,0)),Inputs!$B$4:$B$100,$B15)/1000) -> 3402.667 | O15: =IF(O$3=0,"",SUMIFS(INDEX(Inputs!$D$4:$AG$100,0,MATCH(O$2,Inputs!$D$2:$AG$2,0)),Inputs!$B$4:$B$100,$B15)/1000) -> 6285.342 | P15: =IF(P$3=0,"",SUMIFS(INDEX(Inputs!$D$4:$AG$100,0,MATCH(P$2,Inputs!$D$2:$AG$2,0)),Inputs!$B$4:$B$100,$B15)/1000) -> 4904.741 | Q15: =IF(Q$3=0,"",SUMIFS(INDEX(Inputs!$D$4:$AG$100,0,MATCH(Q$2,Inputs!$D$2:$AG$2,0)),Inputs!$B$4:$B$100,$B15)/1000) -> 3238.394 | R15: =IF(Q15="","",Q15) -> 3238.394 | S15: =IF(S$3=0,"",SUMIFS(INDEX(Inputs!$D$4:$AG$100,0,MATCH(S$2,Inputs!$D$2:$AG$2,0)),Inputs!$B$4:$B$100,$B15)/1000) -> 3094.615 | T15: =IF(T$3=0,"",SUMIFS(INDEX(Inputs!$D$4:$AG$100,0,MATCH(T$2,Inputs!$D$2:$AG$2,0)),Inputs!$B$4:$B$100,$B15)/1000) -> 4992.046 | U15: =IF(U$3=0,"",SUMIFS(INDEX(Inputs!$D$4:$AG$100,0,MATCH(U$2,Inputs!$D$2:$AG$2,0)),Inputs!$B$4:$B$100,$B15)/1000) -> 5295.721 | V15: =IF(V$3=0,"",SUMIFS(INDEX(Inputs!$D$4:$AG$100,0,MATCH(V$2,Inputs!$D$2:$AG$2,0)),Inputs!$B$4:$B$100,$B15)/1000) -> 7203.178 | W15: =IF(V15="","",V15) -> 7203.178 | X15: =IF(X$3=0,"",SUMIFS(INDEX(Inputs!$D$4:$AG$100,0,MATCH(X$2,Inputs!$D$2:$AG$2,0)),Inputs!$B$4:$B$100,$B15)/1000) -> 6162.476 | Y15: =IF(Y$3=0,"",SUMIFS(INDEX(Inputs!$D$4:$AG$100,0,MATCH(Y$2,Inputs!$D$2:$AG$2,0)),Inputs!$B$4:$B$100,$B15)/1000) -> 4933.168 | Z15: =IF(Z$3=0,"",SUMIFS(INDEX(Inputs!$D$4:$AG$100,0,MATCH(Z$2,Inputs!$D$2:$AG$2,0)),Inputs!$B$4:$B$100,$B15)/1000) -> 5075.682 | AA15: =IF(AA$3=0,"",SUMIFS(INDEX(Inputs!$D$4:$AG$100,0,MATCH(AA$2,Inputs!$D$2:$AG$2,0)),Inputs!$B$4:$B$100,$B15)/1000) -> 4382.422 | AB15: =IF(AA15="","",AA15) -> 4382.422 | AC15: =IF(AC$3=0,"",SUMIFS(INDEX(Inputs!$D$4:$AG$100,0,MATCH(AC$2,Inputs!$D$2:$AG$2,0)),Inputs!$B$4:$B$100,$B15)/1000) -> 3571.882 | AD15: =IF(AD$3=0,"",SUMIFS(INDEX(Inputs!$D$4:$AG$100,0,MATCH(AD$2,Inputs!$D$2:$AG$2,0)),Inputs!$B$4:$B$100,$B15)/1000) -> 3638.808 | AE15: =IF(AE$3=0,"",SUMIFS(INDEX(Inputs!$D$4:$AG$100,0,MATCH(AE$2,Inputs!$D$2:$AG$2,0)),Inputs!$B$4:$B$100,$B15)/1000) | AF15: =IF(AF$3=0,"",SUMIFS(INDEX(Inputs!$D$4:$AG$100,0,MATCH(AF$2,Inputs!$D$2:$AG$2,0)),Inputs!$B$4:$B$100,$B15)/1000) | AG15: =IF(AF15="","",AF15)
