Workbook
Name beta_observed: Valuation!$D$93
Name beta_observed_unlevered: #REF!
Name beta_unlev_comps: #REF!
Name cirkbreak: #REF!
Name costdebtfirm: #REF!
Name costequity: #REF!
Name Debt: #REF!
Name debt_weight: #REF!
Name last_close: Valuation!$G$7
Name Market_Equity: #REF!
Name midyear: #REF!
Name Net_Debt: #REF!
Name range: #REF!
Name Stub_year_fraction: #REF!
Name ticker: Valuation!$D$7
Name Useful_Life_of_Depreciable_PP_E: "PPElife"
Name beta_observed: #REF!
Name ticker: #REF!
Name costdebtfirm: Valuation!$D$86
Name costequity: Valuation!$D$94
Name debt: Valuation!$G$88
Name debt_weight: Valuation!$J$88
Name g: Valuation!$D$63
Name market_equity: Valuation!$G$89
Name noplat_t1: Valuation!$D$65
Name relevered_beta: Valuation!$M$102
Name risk_free_rate: Valuation!$D$91
Name risk_premium: Valuation!$D$92
Name ronic: Valuation!$D$64
Name stub_year_fraction: Valuation!$D$11
Name totalcap: Valuation!$G$90
Name wacc: Valuation!$D$12
Name scenario: Valuation!$E$8

Sheet Inputs
A1: Fator p/ milhões: | B1: 1 | D1: SIMPAR (SIMH3) - fonte: Planilha de Fundamentos 2T26 do RI (ri.simpar.com.br > Fundamentos e Planilhas): abas Consolidado (DRE e Balanco trimestrais), Fluxo de caixa (acumulado no ano) e abas das controladas. Moeda: BRL. Brutos JA EM R$ MILHOES (fator 1).
J2: Trimestre na fonte | K2: 1T20 | L2: 2T20 | M2: 3T20 | N2: 4T20 | O2: 1T21 | P2: 2T21 | Q2: 3T21 | R2: 4T21 | S2: 1T22 | T2: 2T22 | U2: 3T22 | V2: 4T22 | W2: 1T23 | X2: 2T23 | Y2: 3T23 | Z2: 4T23 | AA2: 1T24 | AB2: 2T24 | AC2: 3T24 | AD2: 4T24 | AE2: 1T25 | AF2: 2T25 | AG2: 3T25 | AH2: 4T25 | AI2: 1T26 | AJ2: 2T26
A4: COD1 | B4: SINAL1 | C4: COD2 | D4: SINAL2 | E4: COD3 | F4: SINAL3 | G4: UNID | H4: Conta (PT) / origem | I4: Account (EN) | J4: ORIGEM | K4: 1Q20 | L4: 2Q20 | M4: 3Q20 | N4: 4Q20 | O4: 1Q21 | P4: 2Q21 | Q4: 3Q21 | R4: 4Q21 | S4: 1Q22 | T4: 2Q22 | U4: 3Q22 | V4: 4Q22 | W4: 1Q23 | X4: 2Q23 | Y4: 3Q23 | Z4: 4Q23 | AA4: 1Q24 | AB4: 2Q24 | AC4: 3Q24 | AD4: 4Q24 | AE4: 1Q25 | AF4: 2Q25 | AG4: 3Q25 | AH4: 4Q25 | AI4: 1Q26 | AJ4: 2Q26
H5: DRE - TRIMESTRE ISOLADO (aba Consolidado, linhas 4-54; R$ milhoes). 1T20 e 4T20 = colunas "2" da planilha: desconsideram o impairment da Movida do 1T20 (nota 2)
A6: 1 | B6: 1 | G6: moeda | H6: (=) Receita Líquida (Consolidado l.10) | J6: fonte | K6: 2356.8923 | L6: 2197.2248 | M6: 2603.0449 | N6: 2649.895 | O6: 2620.1057 | P6: 3149.0663 | Q6: 3958.28 | R6: 4138.767 | S6: 4530.197 | T6: 5387.1474 | U6: 6823.3505 | V6: 7341.1863 | W6: 7440.0438 | X6: 7563.6362 | Y6: 8318.109 | Z6: 8521.824 | AA6: 9066.5964 | AB6: 10227.19 | AC6: 10790.491 | AD6: 10653.809 | AE6: 10244.635 | AF6: 10340.786 | AG6: 11100.933 | AH6: 11119.492 | AI6: 10924.298 | AJ6: 11248.662
A7: 2 | B7: 1 | G7: moeda | H7: Custo de Serviços (Consolidado l.16) (inclui D&A, devolvida abaixo) | J7: fonte | K7: -1038.6836 | L7: -1028.1092 | M7: -1326.0076 | N7: -1630.8336 | O7: -1481.367 | P7: -1652.8268 | Q7: -2035.8914 | R7: -2134.4488 | S7: -2223.278 | T7: -2629.6072 | U7: -3516.1967 | V7: -3955.4359 | W7: -3874.9459 | X7: -4188.9999 | Y7: -4564.5525 | Z7: -5529.0473 | AA7: -4888.5124 | AB7: -5508.3774 | AC7: -5804.7913 | AD7: -6204.2261 | AE7: -5624.734 | AF7: -5675.8107 | AG7: -6069.728 | AH7: -6291.5956 | AI7: -6029.2018 | AJ7: -6368.1225
A8: 2 | B8: 1 | G8: moeda | H8: Custo de Construção (Consolidado l.17) | J8: fonte | K8: 0 | L8: 0 | M8: 0 | N8: 0 | O8: 0 | P8: 0 | Q8: 0 | R8: 0 | S8: 0 | T8: 0 | U8: 0 | V8: 0 | W8: -14.312977 | X8: -10.787482 | Y8: -57.521267 | Z8: -92.885161 | AA8: -118.30826 | AB8: -223.03071 | AC8: -167.6488 | AD8: -209.1667 | AE8: -20.009113 | AF8: -15.237781 | AG8: -39.488761 | AH8: -61.195852 | AI8: -49.969726 | AJ8: -89.118339
A9: 2 | B9: 1 | G9: moeda | H9: Custo de Venda de Ativos (Consolidado l.18) (custo dos seminovos/ativos vendidos - valor contabil) | J9: fonte | K9: -606.92471 | L9: -775.58343 | M9: -736.84785 | N9: -498.74537 | O9: -311.05654 | P9: -519.4787 | Q9: -658.81809 | R9: -588.42666 | S9: -730.09 | T9: -958.129 | U9: -1234.134 | V9: -1243.8387 | W9: -1417.2688 | X9: -1213.5616 | Y9: -1473.4792 | Z9: -1262.398 | AA9: -1616.1813 | AB9: -1917.7287 | AC9: -2118.765 | AD9: -1533.9042 | AE9: -1905.2994 | AF9: -1872.9852 | AG9: -2103.3696 | AH9: -1814.6505 | AI9: -1897.7609 | AJ9: -1610.1056
A10: 3 | B10: 1 | G10: moeda | H10: Despesas Administrativas e Comerciais (Consolidado l.24) | J10: fonte | K10: -220.47711 | L10: -196.51759 | M10: -237.70136 | N10: -306.95917 | O10: -279.24788 | P10: -315.34856 | Q10: -414.17026 | R10: -429.99557 | S10: -459.752 | T10: -536.422 | U10: -641.04493 | V10: -772.00509 | W10: -711.21981 | X10: -723.50546 | Y10: -717.06489 | Z10: -1069.583 | AA10: -796.74091 | AB10: -861.08988 | AC10: -885.70228 | AD10: -907.57643 | AE10: -854.19454 | AF10: -925.89818 | AG10: -973.75871 | AH10: -992.8547 | AI10: -1000.3594 | AJ10: -1044.9958
A11: 3 | B11: 1 | G11: moeda | H11: Despesas Tributárias (Consolidado l.25) | J11: fonte | K11: -3.7134487 | L11: -1.4303652 | M11: -3.7997666 | N11: -4.7581916 | O11: -3.876756 | P11: -3.862527 | Q11: -5.4167488 | R11: -4.2346844 | S11: 0 | T11: 0 | U11: 0 | V11: 0 | W11: 0 | X11: 0 | Y11: -73.854294 | Z11: 13.099838 | AA11: -17.386277 | AB11: -16.999831 | AC11: -21.902204 | AD11: -24.58519 | AE11: -16.930686 | AF11: -16.821631 | AG11: -25.056971 | AH11: -20.919126 | AI11: -22.08476 | AJ11: -25.307738
A12: 3 | B12: 1 | G12: moeda | H12: Outras Receitas (Despesas) Operacionais (Consolidado l.26) (inclui equivalencia patrimonial) | J12: fonte | K12: -201.08978 | L12: 2.9401183 | M12: -1.4278036 | N12: 217.27628 | O12: -27.902485 | P12: 66.025884 | Q12: 45.698271 | R12: 18.977329 | S12: 18.474 | T12: 23.76 | U12: -3.9688666 | V12: -103.39559 | W12: -105.19163 | X12: 161.32539 | Y12: -63.773406 | Z12: 10.584691 | AA12: -90.301822 | AB12: -0.59738857 | AC12: -89.59461 | AD12: -133.70918 | AE12: -73.859858 | AF12: -30.33766 | AG12: -154.72258 | AH12: 929.81234 | AI12: -152.60911 | AJ12: -12.683275
A13: 6 | B13: 1 | G13: moeda | H13: Receitas Financeiras (Consolidado l.33) | J13: fonte | K13: 202.50764 | L13: 257.41068 | M13: 105.50668 | N13: 114.00069 | O13: 225.14892 | P13: 10.13128 | Q13: 210.23048 | R13: 290.85133 | S13: 345.152 | T13: 283.463 | U13: 246.492 | V13: 353.93468 | W13: 338.376 | X13: 183.206 | Y13: 316.416 | Z13: 299.504 | AA13: 367.50281 | AB13: 382.482 | AC13: 432.02735 | AD13: 484.81983 | AE13: 455.02286 | AF13: 516.74414 | AG13: 567.399 | AH13: 540.99036 | AI13: 611.519 | AJ13: 693.054
A14: 5 | B14: 1 | G14: moeda | H14: Despesa Financeiras (Consolidado l.34) | J14: fonte | K14: -372.69144 | L14: -154.39356 | M14: -261.248 | N14: -265.86925 | O14: -454.95787 | P14: -191.11211 | Q14: -526.93389 | R14: -780.95114 | S14: -1017.218 | T14: -1246.042 | U14: -1499.372 | V14: -1595.8405 | W14: -1648.827 | X14: -1664.541 | Y14: -1877.077 | Z14: -1840.783 | AA14: -1808.7842 | AB14: -1862.3567 | AC14: -1990.9005 | AD14: -2181.3582 | AE14: -2235.645 | AF14: -2445.21 | AG14: -2633.139 | AH14: -2646.005 | AI14: -2595.69 | AJ14: -2958.432
A15: 7 | B15: 1 | G15: moeda | H15: Impostos e contribuições sobre o lucro (Consolidado l.37) | J15: fonte | K15: -32.636457 | L15: -144.96427 | M15: -45.564212 | N15: -59.110733 | O15: -115.67799 | P15: -150.76209 | Q15: -173.62383 | R15: -143.94408 | S15: -134.962 | T15: -111.208 | U15: -64.128 | V15: 263.61971 | W15: 70.277896 | X15: -6.8864771 | Y15: 82.158321 | Z15: 231.65526 | AA15: -16.365505 | AB15: -79.027014 | AC15: -41.456355 | AD15: -178.77276 | AE15: 33.112948 | AF15: 76.221045 | AG15: 83.71827 | AH15: -239.26192 | AI15: 58.796699 | AJ15: 40.521435
A16: 6 | B16: 1 | G16: moeda | H16: (-) Prejuízo após os tributos de operações descontinuadas (Consolidado l.41) (operacoes descontinuadas -> cod 6, nao operacional) | J16: fonte | K16: 0 | L16: -19.787 | M16: -8.752 | N16: 0 | O16: 0 | P16: 0 | Q16: 0 | R16: 0 | S16: 0 | T16: 0 | U16: 0 | V16: 0 | W16: 0 | X16: 0 | Y16: 0 | Z16: 0 | AA16: -8.8055272 | AB16: 1.3839526 | AC16: 1.1765506 | AD16: 11.006811 | AE16: 9.5006091 | AF16: 5.6261114 | AG16: 8.7014613 | AH16: -40.983601 | AI16: -21.214936 | AJ16: -24.593788
G17: moeda | H17: (=) Lucro líquido do exercício (l.43) - memoria | J17: memoria | K17: 83.183425 | L17: 136.79017 | M17: 87.203023 | N17: 214.89566 | O17: 171.16807 | P17: 391.83268 | Q17: 399.3545 | R17: 366.59475 | S17: 328.523 | T17: 212.9622 | U17: 110.998 | V17: 288.22496 | W17: 76.931625 | X17: 99.885652 | Y17: -110.63922 | Z17: -718.02862 | AA17: 72.713039 | AB17: 141.84856 | AC17: 102.93343 | AD17: -223.66346 | AE17: 11.598454 | AF17: -42.923824 | AG17: -238.51153 | AH17: 482.82833 | AI17: -174.27665 | AJ17: -151.1218
G18: moeda | H18: (=) Lucro líquido do Controladores (l.46) - memoria | J18: memoria | K18: 54.4 | L18: 155.40027 | M18: 73.166 | N18: 138.96464 | O18: 94.243 | P18: 267.247 | Q18: 245.763 | R18: 215.002 | S18: 191.676 | T18: 101.977 | U18: 18.501 | V18: 169.929 | W18: 6.189 | X18: 12.329 | Y18: -136.515 | Z18: -377.224 | AA18: -13.055231 | AB18: 49.299835 | AC18: 10.84225 | AD18: -245.24247 | AE18: -50.953 | AF18: -96.291 | AG18: -246.193 | AH18: 432.908 | AI18: -179.59733 | AJ18: -189.46967
G19: moeda | H19: EBIT (l.28) - memoria | J19: memoria | K19: 286.00368 | L19: 198.52431 | M19: 297.26056 | N19: 425.87495 | O19: 516.65502 | P19: 723.57559 | Q19: 889.68174 | R19: 1000.6386 | S19: 1135.551 | T19: 1286.7492 | U19: 1428.006 | V19: 1266.5111 | W19: 1317.1047 | X19: 1588.1071 | Y19: 1367.8635 | Z19: 591.59512 | AA19: 1539.1654 | AB19: 1699.3663 | AC19: 1702.0863 | AD19: 1640.6408 | AE19: 1749.607 | AF19: 1803.6949 | AG19: 1734.8087 | AH19: 2868.0885 | AI19: 1772.3126 | AJ19: 2098.3286
G20: moeda | H20: EBITDA (l.49, como divulgado) - memoria | J20: memoria | K20: 561.68639 | L20: 470.43411 | M20: 587.5119 | N20: 699.98255 | O20: 733.70402 | P20: 965.00987 | Q20: 1165.5211 | R20: 1325.431 | S20: 1513.044 | T20: 1702.957 | U20: 1938.0713 | V20: 1849.022 | W20: 1963.8645 | X20: 2267.4931 | Y20: 2084.9445 | Z20: 1652.321 | AA20: 2361.1452 | AB20: 2597.0095 | AC20: 2699.2809 | AD20: 2614.9432 | AE20: 2802.0203 | AF20: 2922.6358 | AG20: 2906.8707 | AH20: 4066.0581 | AI20: 3012.2391 | AJ20: 3351.8827
G21: moeda | H21: EBITDA-A (l.53; EBITDA + custo de venda de ativos) - memoria | J21: memoria | K21: 1168.6111 | L21: 1246.0175 | M21: 1324.3598 | N21: 1198.7279 | O21: 1044.7606 | P21: 1484.4886 | Q21: 1824.3392 | R21: 1913.8577 | S21: 2243.134 | T21: 2661.086 | U21: 3172.2053 | V21: 3092.8606 | W21: 3381.1333 | X21: 3481.0547 | Y21: 3558.4237 | Z21: 2914.7189 | AA21: 3977.3265 | AB21: 4514.7382 | AC21: 4818.0459 | AD21: 4148.8474 | AE21: 4707.3197 | AF21: 4795.621 | AG21: 5010.2404 | AH21: 5880.7087 | AI21: 4910 | AJ21: 4961.9883
H22: DFC - ACUMULADO NO ANO (aba Fluxo de caixa; R$ milhoes). ATENCAO: colunas de periodos diferentes vem de documentos com reapresentacoes (ex.: 9M20 < 6M20 em dividendos)
G23: moeda | H23: Dividendos e JCP pagos (DFC l.59, acum.) | J23: memoria | K23: -41.585 | L23: -55.41 | M23: -33.956 | N23: -48.856 | O23: -23.249 | P23: -83.506 | Q23: -113.606 | R23: -226.573 | S23: -125.184 | T23: -546.665 | U23: -595.858 | V23: -415.184 | W23: -125.974 | X23: -235.098 | Y23: -257.782 | Z23: -481.563 | AA23: 0 | AB23: 0 | AC23: -112.087 | AD23: -157.178 | AE23: -40.884 | AF23: -230.635 | AG23: -236.437 | AH23: -229.051 | AI23: 0 | AJ23: -168.72
G24: moeda | H24: Depreciacao, amortizacao e impairment (DFC l.8, acum.) - memoria | J24: memoria | K24: 471.075 | L24: 742.986 | M24: 1033.238 | N24: 1257.202 | O24: 217.049 | P24: 458.483 | Q24: 734.322 | R24: 1059.114 | S24: 377.493 | T24: 793.699 | U24: 1303.765 | V24: 1895.775 | W24: 646.761 | X24: 1326.146 | Y24: 2043.227 | Z24: 3481.049 | AA24: 813.581 | AB24: 1858.994 | AC24: 2914.121 | AD24: 4010.493 | AE24: 1070.425 | AF24: 2322.567 | AG24: 3646.428 | AH24: 4882.131 | AI24: 1340.958 | AJ24: 1291.856
G25: moeda | H25: Compra de imobilizado operacional para locacao (DFC l.32, acum.) - memoria | J25: memoria | K25: -1245.249 | L25: -2036.648 | M25: -3175.716 | N25: -4460.52 | O25: -1766.086 | P25: -3980.548 | Q25: -7316.132 | R25: -10084.996 | S25: -3561.009 | T25: -7501.827 | U25: -12980.307 | V25: -15080.412 | W25: -3703.141 | X25: -6491.819 | Y25: -9095.136 | Z25: -10477.54 | AA25: -4241.138 | AB25: -8468.889 | AC25: -11831.202 | AD25: -14859.243 | AE25: -2614.813 | AF25: -6178.595 | AG25: -8977.631 | AH25: -12997.609 | AI25: -1809.101 | AJ25: -4642.176
H26: DERIVADAS (formula nesta aba)
A27: 4 | B27: -1 | C27: 2 | D27: 1 | G27: moeda | H27: D&A = EBITDA - EBIT divulgados (l.49 - l.28). COD1=4 lanca; COD2=2 devolve ao custo (depreciacao da frota esta no custo) | J27: derivada | K27: =K20-K19 -> 275.68271 | L27: =L20-L19 -> 271.9098 | M27: =M20-M19 -> 290.25134 | N27: =N20-N19 -> 274.10759 | O27: =O20-O19 -> 217.049 | P27: =P20-P19 -> 241.43428 | Q27: =Q20-Q19 -> 275.83937 | R27: =R20-R19 -> 324.79236 | ... AJ27: =AJ20-AJ19 -> 1253.5541
A28: 9 | B28: 1 | G28: moeda | H28: Participacao de nao controladores = lucro dos controladores - lucro total (l.46 - l.43; negativo quando os minoritarios tem lucro) | J28: derivada | K28: =K18-K17 -> -28.783425 | L28: =L18-L17 -> 18.610103 | M28: =M18-M17 -> -14.037023 | N28: =N18-N17 -> -75.931013 | O28: =O18-O17 -> -76.925074 | P28: =P18-P17 -> -124.58568 | Q28: =Q18-Q17 -> -153.5915 | R28: =R18-R17 -> -151.59275 | ... AJ28: =AJ18-AJ17 -> -38.347865
A29: 44 | B29: 1 | G29: moeda | H29: Lucro liquido dos controladores (l.46) - COD 44 alimenta o check IS do Model (linha 4) | J29: derivada | K29: =K18 -> 54.4 | L29: =L18 -> 155.40027 | M29: =M18 -> 73.166 | N29: =N18 -> 138.96464 | O29: =O18 -> 94.243 | P29: =P18 -> 267.247 | Q29: =Q18 -> 245.763 | R29: =R18 -> 215.002 | ... AJ29: =AJ18 -> -189.46967
A30: 10 | B30: 1 | G30: moeda | H30: Dividendos e JCP pagos (DFC trimestralizado; trimestres com reapresentacao podem sair positivos) | J30: derivada | K30: =N(K23) -> -41.585 | L30: =N(L23)-N(K23) -> -13.825 | M30: =N(M23)-N(L23) -> 21.454 | N30: =N(N23)-N(M23) -> -14.9 | O30: =N(O23) -> -23.249 | P30: =N(P23)-N(O23) -> -60.257 | Q30: =N(Q23)-N(P23) -> -30.1 | R30: =N(R23)-N(Q23) -> -112.967 | S30: =N(S23) -> -125.184 | T30: =N(T23)-N(S23) -> -421.481 | U30: =N(U23)-N(T23) -> -49.193 | V30: =N(V23)-N(U23) -> 180.674 | W30: =N(W23) -> -125.974 | X30: =N(X23)-N(W23) -> -109.124 | Y30: =N(Y23)-N(X23) -> -22.684 | Z30: =N(Z23)-N(Y23) -> -223.781 | AA30: =N(AA23) -> 0 | AB30: =N(AB23)-N(AA23) -> 0 | AC30: =N(AC23)-N(AB23) -> -112.087 | AD30: =N(AD23)-N(AC23) -> -45.091 | AE30: =N(AE23) -> -40.884 | AF30: =N(AF23)-N(AE23) -> -189.751 | AG30: =N(AG23)-N(AF23) -> -5.802 | AH30: =N(AH23)-N(AG23) -> 7.386 | AI30: =N(AI23) -> 0 | AJ30: =N(AJ23)-N(AI23) -> -168.72
G31: moeda | H31: Capex de frota (DFC trimestralizado) - memoria | J31: derivada | K31: =N(K25) -> -1245.249 | L31: =N(L25)-N(K25) -> -791.399 | M31: =N(M25)-N(L25) -> -1139.068 | N31: =N(N25)-N(M25) -> -1284.804 | O31: =N(O25) -> -1766.086 | P31: =N(P25)-N(O25) -> -2214.462 | Q31: =N(Q25)-N(P25) -> -3335.584 | R31: =N(R25)-N(Q25) -> -2768.864 | S31: =N(S25) -> -3561.009 | T31: =N(T25)-N(S25) -> -3940.818 | U31: =N(U25)-N(T25) -> -5478.48 | V31: =N(V25)-N(U25) -> -2100.105 | W31: =N(W25) -> -3703.141 | X31: =N(X25)-N(W25) -> -2788.678 | Y31: =N(Y25)-N(X25) -> -2603.317 | Z31: =N(Z25)-N(Y25) -> -1382.404 | AA31: =N(AA25) -> -4241.138 | AB31: =N(AB25)-N(AA25) -> -4227.751 | AC31: =N(AC25)-N(AB25) -> -3362.313 | AD31: =N(AD25)-N(AC25) -> -3028.041 | AE31: =N(AE25) -> -2614.813 | AF31: =N(AF25)-N(AE25) -> -3563.782 | AG31: =N(AG25)-N(AF25) -> -2799.036 | AH31: =N(AH25)-N(AG25) -> -4019.978 | AI31: =N(AI25) -> -1809.101 | AJ31: =N(AJ25)-N(AI25) -> -2833.075
H32: BALANCO (aba Consolidado, linhas 64-181; R$ milhoes, fim de trimestre)
A33: 11 | B33: 1 | G33: moeda | H33: A: Caixa e equivalentes de caixa (l.67) | J33: fonte | K33: 580.58739 | L33: 753.93436 | M33: 641.479 | N33: 409.60138 | O33: 1726.239 | P33: 3301.653 | Q33: 5168.084 | R33: 1029.384 | S33: 2552.381 | T33: 2530.055 | U33: 1884.29 | V33: 1718.025 | W33: 2623.6717 | X33: 1586.5072 | Y33: 1636.2833 | Z33: 1345.475 | AA33: 1553.012 | AB33: 2098.1617 | AC33: 1868.1544 | AD33: 1885.4154 | AE33: 1730.6384 | AF33: 2214.5866 | AG33: 3105.4519 | AH33: 2953.811 | AI33: 3477.9485 | AJ33: 3441.5673
A34: 11 | B34: 1 | G34: moeda | H34: A: Títulos e valores mobiliários (l.68) | J34: fonte | K34: 5935.2547 | L34: 7483.9905 | M34: 7128.441 | N34: 7918.78 | O34: 9102.152 | P34: 8800.845 | Q34: 11475.516 | R34: 17622.841 | S34: 12143.677 | T34: 12483.413 | U34: 13473.979 | V34: 11024.128 | W34: 7154.9991 | X34: 6184.3166 | Y34: 6324.0083 | Z34: 9600.8353 | AA34: 11216.067 | AB34: 9927.8475 | AC34: 12137.606 | AD34: 11288.479 | AE34: 11594.217 | AF34: 10123.046 | AG34: 9369.5804 | AH34: 11074.648 | AI34: 11703.556 | AJ34: 10442.73
A35: 16 | B35: 1 | G35: moeda | H35: A: Instrumentos financeiros derivativos (l.69) | J35: fonte | K35: 30.0589 | L35: 30.921311 | M35: 82.1 | N35: 80.38 | O35: 20.33803 | P35: 0.116 | Q35: 0.147 | R35: 0.147 | S35: 0.147 | T35: 0.079 | U35: 7.605 | V35: 0.086 | W35: 0.0820253 | X35: 0.04496455 | Y35: 2.7251504 | Z35: 29.180997 | AA35: 31.840035 | AB35: 248.27592 | AC35: 272.11148 | AD35: 1033.6062 | AE35: 521.73347 | AF35: 157.77192 | AG35: 156.77727 | AH35: 147.06728 | AI35: 116.73912 | AJ35: 84.271308
A36: 12 | B36: 1 | G36: moeda | H36: A: Contas a receber (l.70) | J36: fonte | K36: 1591.8635 | L36: 1627.089 | M36: 1741.4563 | N36: 1934.4459 | O36: 2151.3927 | P36: 2430.89 | Q36: 2779.127 | R36: 3260.329 | S36: 3702.988 | T36: 3976.906 | U36: 4223.848 | V36: 4433.345 | W36: 4794.6021 | X36: 5221.9683 | Y36: 5708.6408 | Z36: 5106.6802 | AA36: 5418.7127 | AB36: 5801.9812 | AC36: 6344.7848 | AD36: 6051.441 | AE36: 6817.3601 | AF36: 7493.7022 | AG36: 7771.081 | AH36: 7614.7977 | AI36: 7759.6153 | AJ36: 8715.7413
A37: 13 | B37: 1 | G37: moeda | H37: A: Estoques (l.71) | J37: fonte | K37: 308.24344 | L37: 292.12009 | M37: 235.56131 | N37: 213.01693 | O37: 255.36257 | P37: 378.575 | Q37: 378.18 | R37: 525.95 | S37: 596.625 | T37: 775.164 | U37: 1166.831 | V37: 1694.32 | W37: 1774.0662 | X37: 2010.4287 | Y37: 2549.5825 | Z37: 2890.5094 | AA37: 2876.0548 | AB37: 2973.7873 | AC37: 3204.8421 | AD37: 3180.4208 | AE37: 3017.7035 | AF37: 3009.3821 | AG37: 2814.7036 | AH37: 2827.6063 | AI37: 2524.4447 | AJ37: 2670.2405
A38: 16 | B38: 1 | G38: moeda | H38: A: Tributos a recuperar (l.72) | J38: fonte | K38: 122.99103 | L38: 97.706754 | M38: 115.61314 | N38: 160.48997 | O38: 150.9978 | P38: 114.452 | Q38: 162.229 | R38: 325.496 | S38: 377.863 | T38: 446.778 | U38: 496.207 | V38: 361.125 | W38: 325.88766 | X38: 388.85872 | Y38: 431.68915 | Z38: 499.76457 | AA38: 525.30188 | AB38: 538.20681 | AC38: 499.48772 | AD38: 461.80213 | AE38: 445.81045 | AF38: 606.92628 | AG38: 547.308 | AH38: 506.63815 | AI38: 585.23837 | AJ38: 446.31355
A39: 16 | B39: 1 | G39: moeda | H39: A: Imposto de renda e contribuição social a recuperar (l.73) | J39: fonte | K39: 217.93655 | L39: 372.23178 | M39: 372.73579 | N39: 298.45131 | O39: 214.99823 | P39: 268.861 | Q39: 283.454 | R39: 227.643 | S39: 277.368 | T39: 389.085 | U39: 508.702 | V39: 577.912 | W39: 563.13959 | X39: 623.51458 | Y39: 683.05489 | Z39: 855.07584 | AA39: 821.74362 | AB39: 854.26953 | AC39: 822.08008 | AD39: 937.23422 | AE39: 1086.4658 | AF39: 1227.8204 | AG39: 1224.878 | AH39: 1091.0048 | AI39: 1100.7377 | AJ39: 1189.6287
A40: 15 | B40: 1 | G40: moeda | H40: A: Despesas antecipadas (l.74) | J40: fonte | K40: 140.32446 | L40: 110.5702 | M40: 90.579392 | N40: 58.314227 | O40: 154.82687 | P40: 145.481 | Q40: 115.248 | R40: 67.977 | S40: 219.519 | T40: 189.826 | U40: 176.358 | V40: 98.457 | W40: 205.01664 | X40: 348.50864 | Y40: 264.29539 | Z40: 127.72711 | AA40: 393.75851 | AB40: 415.55977 | AC40: 320.16497 | AD40: 165.44256 | AE40: 537.14427 | AF40: 508.51692 | AG40: 346.88826 | AH40: 211.97374 | AI40: 581.06858 | AJ40: 475.81639
A41: 16 | B41: 1 | G41: moeda | H41: A: Dividendos a receber (l.75) | J41: fonte | K41: 0 | L41: 0 | M41: 0.02337902 | N41: 0 | O41: 0 | P41: 0 | Q41: 0 | R41: 0 | S41: 0 | T41: 0.28 | U41: 0.572 | V41: 0 | W41: 0.32206496 | X41: 1e-08 | Y41: -5e-08 | Z41: -5e-08 | AA41: 0.58519963 | AB41: 0.58519964 | AC41: 0.58519969 | AD41: 0.74816063 | AE41: 0.16296194 | AF41: 0.43468422 | AG41: 0.43464383 | AH41: 0.4346845 | AI41: 3.3446438 | AJ41: 0.58093421
...

Sheet Inputs (2)
A1: =COUNTIF($B$3:$B$1048576,$B$1) -> 1 | B1: =MAX($B$3:$B$1048576) -> 67
D2: 1Q21 | E2: 2Q21 | F2: 3Q21 | G2: 4Q21 | H2: 2021 | I2: 1Q22 | J2: 2Q22 | K2: 3Q22 | L2: 4Q22 | M2: 2022 | N2: 1Q23 | O2: 2Q23 | P2: 3Q23 | Q2: 4Q23 | R2: 2023 | S2: 1Q24 | T2: 2Q24 | U2: 3Q24 | V2: 4Q24 | W2: 2024 | X2: 1Q25 | Y2: 2Q25 | Z2: 3Q25 | AA2: 4Q25 | AB2: 2025 | AC2: 1Q26 | AD2: 2Q26 | AE2: 3Q26 | AF2: 4Q26 | AG2: 2026 | AH2: 1Q20 | AI2: 2Q20 | AJ2: 3Q20 | AK2: 4Q20 | AL2: 2020 | AN2: Sem dado na fonte: 3Q26, 4Q26 e 2026 (rotulo em cinza). 2020 fica nas colunas AH-AL.
B4: 1 | C4: Net Revenues | D4: =IF(ISNA(MATCH(D$2,Inputs!$K$4:$AJ$4,0)),NA(),IF(SUMPRODUCT((Inputs!$A$5:$A$190=$B4)*ISNUMBER(INDEX(Inputs!$K$5:$AJ$190,0,MATCH(D$2,Inputs!$K$4:$AJ$4,0))))+SUMPRODUCT((Inputs!$C$5:$C$190=$B4)*ISNUMBER(INDEX(Inputs!$K$5:$AJ$190,0,MATCH(D$2,Inputs!$K$4:$AJ$4,0))))+SUMPRODUCT((Inputs!$E$5:$E$190=$B4)*ISNUMBER(INDEX(Inputs!$K$5:$AJ$190,0,MATCH(D$2,Inputs!$K$4:$AJ$4,0))))=0,NA(),SUMPRODUCT((Inputs!$A$5:$A$190=$B4)*Inputs!$B$5:$B$190*(((Inputs!$G$5:$G$190="moeda")+(Inputs!$G$5:$G$190="acoes"))*Inputs!$B$1+((Inputs!$G$5:$G$190<>"moeda")*(Inputs!$G$5:$G$190<>"acoes")))*INDEX(Inputs!$K$5:$AJ$190,0,MATCH(D$2,Inputs!$K$4:$AJ$4,0)))+SUMPRODUCT((Inputs!$C$5:$C$190=$B4)*Inputs!$D$5:$D$190*(((Inputs!$G$5:$G$190="moeda")+(Inputs!$G$5:$G$190="acoes"))*Inputs!$B$1+((Inputs!$G$5:$G$190<>"moeda")*(Inputs!$G$5:$G$190<>"acoes")))*INDEX(Inputs!$K$5:$AJ$190,0,MATCH(D$2,Inputs!$K$4:$AJ$4,0)))+SUMPRODUCT((Inputs!$E$5:$E$190=$B4)*Inputs!$F$5:$F$190*(((Inputs!$G$5:$G$190="moeda")+(Inputs!$G$5:$G$190="acoes"))*Inputs!$B$1+((Inputs!$G$5:$G$190<>"moeda")*(Inputs!$G$5:$G$190<>"acoes")))*INDEX(Inputs!$K$5:$AJ$190,0,MATCH(D$2,Inputs!$K$4:$AJ$4,0))))) -> 2620.1057 | E4: =IF(ISNA(MATCH(E$2,Inputs!$K$4:$AJ$4,0)),NA(),IF(SUMPRODUCT((Inputs!$A$5:$A$190=$B4)*ISNUMBER(INDEX(Inputs!$K$5:$AJ$190,0,MATCH(E$2,Inputs!$K$4:$AJ$4,0))))+SUMPRODUCT((Inputs!$C$5:$C$190=$B4)*ISNUMBER(INDEX(Inputs!$K$5:$AJ$190,0,MATCH(E$2,Inputs!$K$4:$AJ$4,0))))+SUMPRODUCT((Inputs!$E$5:$E$190=$B4)*ISNUMBER(INDEX(Inputs!$K$5:$AJ$190,0,MATCH(E$2,Inputs!$K$4:$AJ$4,0))))=0,NA(),SUMPRODUCT((Inputs!$A$5:$A$190=$B4)*Inputs!$B$5:$B$190*(((Inputs!$G$5:$G$190="moeda")+(Inputs!$G$5:$G$190="acoes"))*Inputs!$B$1+((Inputs!$G$5:$G$190<>"moeda")*(Inputs!$G$5:$G$190<>"acoes")))*INDEX(Inputs!$K$5:$AJ$190,0,MATCH(E$2,Inputs!$K$4:$AJ$4,0)))+SUMPRODUCT((Inputs!$C$5:$C$190=$B4)*Inputs!$D$5:$D$190*(((Inputs!$G$5:$G$190="moeda")+(Inputs!$G$5:$G$190="acoes"))*Inputs!$B$1+((Inputs!$G$5:$G$190<>"moeda")*(Inputs!$G$5:$G$190<>"acoes")))*INDEX(Inputs!$K$5:$AJ$190,0,MATCH(E$2,Inputs!$K$4:$AJ$4,0)))+SUMPRODUCT((Inputs!$E$5:$E$190=$B4)*Inputs!$F$5:$F$190*(((Inputs!$G$5:$G$190="moeda")+(Inputs!$G$5:$G$190="acoes"))*Inputs!$B$1+((Inputs!$G$5:$G$190<>"moeda")*(Inputs!$G$5:$G$190<>"acoes")))*INDEX(Inputs!$K$5:$AJ$190,0,MATCH(E$2,Inputs!$K$4:$AJ$4,0))))) -> 3149.0663 | F4: =IF(ISNA(MATCH(F$2,Inputs!$K$4:$AJ$4,0)),NA(),IF(SUMPRODUCT((Inputs!$A$5:$A$190=$B4)*ISNUMBER(INDEX(Inputs!$K$5:$AJ$190,0,MATCH(F$2,Inputs!$K$4:$AJ$4,0))))+SUMPRODUCT((Inputs!$C$5:$C$190=$B4)*ISNUMBER(INDEX(Inputs!$K$5:$AJ$190,0,MATCH(F$2,Inputs!$K$4:$AJ$4,0))))+SUMPRODUCT((Inputs!$E$5:$E$190=$B4)*ISNUMBER(INDEX(Inputs!$K$5:$AJ$190,0,MATCH(F$2,Inputs!$K$4:$AJ$4,0))))=0,NA(),SUMPRODUCT((Inputs!$A$5:$A$190=$B4)*Inputs!$B$5:$B$190*(((Inputs!$G$5:$G$190="moeda")+(Inputs!$G$5:$G$190="acoes"))*Inputs!$B$1+((Inputs!$G$5:$G$190<>"moeda")*(Inputs!$G$5:$G$190<>"acoes")))*INDEX(Inputs!$K$5:$AJ$190,0,MATCH(F$2,Inputs!$K$4:$AJ$4,0)))+SUMPRODUCT((Inputs!$C$5:$C$190=$B4)*Inputs!$D$5:$D$190*(((Inputs!$G$5:$G$190="moeda")+(Inputs!$G$5:$G$190="acoes"))*Inputs!$B$1+((Inputs!$G$5:$G$190<>"moeda")*(Inputs!$G$5:$G$190<>"acoes")))*INDEX(Inputs!$K$5:$AJ$190,0,MATCH(F$2,Inputs!$K$4:$AJ$4,0)))+SUMPRODUCT((Inputs!$E$5:$E$190=$B4)*Inputs!$F$5:$F$190*(((Inputs!$G$5:$G$190="moeda")+(Inputs!$G$5:$G$190="acoes"))*Inputs!$B$1+((Inputs!$G$5:$G$190<>"moeda")*(Inputs!$G$5:$G$190<>"acoes")))*INDEX(Inputs!$K$5:$AJ$190,0,MATCH(F$2,Inputs!$K$4:$AJ$4,0))))) -> 3958.28 | G4: =IF(ISNA(MATCH(G$2,Inputs!$K$4:$AJ$4,0)),NA(),IF(SUMPRODUCT((Inputs!$A$5:$A$190=$B4)*ISNUMBER(INDEX(Inputs!$K$5:$AJ$190,0,MATCH(G$2,Inputs!$K$4:$AJ$4,0))))+SUMPRODUCT((Inputs!$C$5:$C$190=$B4)*ISNUMBER(INDEX(Inputs!$K$5:$AJ$190,0,MATCH(G$2,Inputs!$K$4:$AJ$4,0))))+SUMPRODUCT((Inputs!$E$5:$E$190=$B4)*ISNUMBER(INDEX(Inputs!$K$5:$AJ$190,0,MATCH(G$2,Inputs!$K$4:$AJ$4,0))))=0,NA(),SUMPRODUCT((Inputs!$A$5:$A$190=$B4)*Inputs!$B$5:$B$190*(((Inputs!$G$5:$G$190="moeda")+(Inputs!$G$5:$G$190="acoes"))*Inputs!$B$1+((Inputs!$G$5:$G$190<>"moeda")*(Inputs!$G$5:$G$190<>"acoes")))*INDEX(Inputs!$K$5:$AJ$190,0,MATCH(G$2,Inputs!$K$4:$AJ$4,0)))+SUMPRODUCT((Inputs!$C$5:$C$190=$B4)*Inputs!$D$5:$D$190*(((Inputs!$G$5:$G$190="moeda")+(Inputs!$G$5:$G$190="acoes"))*Inputs!$B$1+((Inputs!$G$5:$G$190<>"moeda")*(Inputs!$G$5:$G$190<>"acoes")))*INDEX(Inputs!$K$5:$AJ$190,0,MATCH(G$2,Inputs!$K$4:$AJ$4,0)))+SUMPRODUCT((Inputs!$E$5:$E$190=$B4)*Inputs!$F$5:$F$190*(((Inputs!$G$5:$G$190="moeda")+(Inputs!$G$5:$G$190="acoes"))*Inputs!$B$1+((Inputs!$G$5:$G$190<>"moeda")*(Inputs!$G$5:$G$190<>"acoes")))*INDEX(Inputs!$K$5:$AJ$190,0,MATCH(G$2,Inputs!$K$4:$AJ$4,0))))) -> 4138.767 | H4: =SUM(D4:G4) -> 13866.219 | I4: =IF(ISNA(MATCH(I$2,Inputs!$K$4:$AJ$4,0)),NA(),IF(SUMPRODUCT((Inputs!$A$5:$A$190=$B4)*ISNUMBER(INDEX(Inputs!$K$5:$AJ$190,0,MATCH(I$2,Inputs!$K$4:$AJ$4,0))))+SUMPRODUCT((Inputs!$C$5:$C$190=$B4)*ISNUMBER(INDEX(Inputs!$K$5:$AJ$190,0,MATCH(I$2,Inputs!$K$4:$AJ$4,0))))+SUMPRODUCT((Inputs!$E$5:$E$190=$B4)*ISNUMBER(INDEX(Inputs!$K$5:$AJ$190,0,MATCH(I$2,Inputs!$K$4:$AJ$4,0))))=0,NA(),SUMPRODUCT((Inputs!$A$5:$A$190=$B4)*Inputs!$B$5:$B$190*(((Inputs!$G$5:$G$190="moeda")+(Inputs!$G$5:$G$190="acoes"))*Inputs!$B$1+((Inputs!$G$5:$G$190<>"moeda")*(Inputs!$G$5:$G$190<>"acoes")))*INDEX(Inputs!$K$5:$AJ$190,0,MATCH(I$2,Inputs!$K$4:$AJ$4,0)))+SUMPRODUCT((Inputs!$C$5:$C$190=$B4)*Inputs!$D$5:$D$190*(((Inputs!$G$5:$G$190="moeda")+(Inputs!$G$5:$G$190="acoes"))*Inputs!$B$1+((Inputs!$G$5:$G$190<>"moeda")*(Inputs!$G$5:$G$190<>"acoes")))*INDEX(Inputs!$K$5:$AJ$190,0,MATCH(I$2,Inputs!$K$4:$AJ$4,0)))+SUMPRODUCT((Inputs!$E$5:$E$190=$B4)*Inputs!$F$5:$F$190*(((Inputs!$G$5:$G$190="moeda")+(Inputs!$G$5:$G$190="acoes"))*Inputs!$B$1+((Inputs!$G$5:$G$190<>"moeda")*(Inputs!$G$5:$G$190<>"acoes")))*INDEX(Inputs!$K$5:$AJ$190,0,MATCH(I$2,Inputs!$K$4:$AJ$4,0))))) -> 4530.197 | J4: =IF(ISNA(MATCH(J$2,Inputs!$K$4:$AJ$4,0)),NA(),IF(SUMPRODUCT((Inputs!$A$5:$A$190=$B4)*ISNUMBER(INDEX(Inputs!$K$5:$AJ$190,0,MATCH(J$2,Inputs!$K$4:$AJ$4,0))))+SUMPRODUCT((Inputs!$C$5:$C$190=$B4)*ISNUMBER(INDEX(Inputs!$K$5:$AJ$190,0,MATCH(J$2,Inputs!$K$4:$AJ$4,0))))+SUMPRODUCT((Inputs!$E$5:$E$190=$B4)*ISNUMBER(INDEX(Inputs!$K$5:$AJ$190,0,MATCH(J$2,Inputs!$K$4:$AJ$4,0))))=0,NA(),SUMPRODUCT((Inputs!$A$5:$A$190=$B4)*Inputs!$B$5:$B$190*(((Inputs!$G$5:$G$190="moeda")+(Inputs!$G$5:$G$190="acoes"))*Inputs!$B$1+((Inputs!$G$5:$G$190<>"moeda")*(Inputs!$G$5:$G$190<>"acoes")))*INDEX(Inputs!$K$5:$AJ$190,0,MATCH(J$2,Inputs!$K$4:$AJ$4,0)))+SUMPRODUCT((Inputs!$C$5:$C$190=$B4)*Inputs!$D$5:$D$190*(((Inputs!$G$5:$G$190="moeda")+(Inputs!$G$5:$G$190="acoes"))*Inputs!$B$1+((Inputs!$G$5:$G$190<>"moeda")*(Inputs!$G$5:$G$190<>"acoes")))*INDEX(Inputs!$K$5:$AJ$190,0,MATCH(J$2,Inputs!$K$4:$AJ$4,0)))+SUMPRODUCT((Inputs!$E$5:$E$190=$B4)*Inputs!$F$5:$F$190*(((Inputs!$G$5:$G$190="moeda")+(Inputs!$G$5:$G$190="acoes"))*Inputs!$B$1+((Inputs!$G$5:$G$190<>"moeda")*(Inputs!$G$5:$G$190<>"acoes")))*INDEX(Inputs!$K$5:$AJ$190,0,MATCH(J$2,Inputs!$K$4:$AJ$4,0))))) -> 5387.1474 | K4: =IF(ISNA(MATCH(K$2,Inputs!$K$4:$AJ$4,0)),NA(),IF(SUMPRODUCT((Inputs!$A$5:$A$190=$B4)*ISNUMBER(INDEX(Inputs!$K$5:$AJ$190,0,MATCH(K$2,Inputs!$K$4:$AJ$4,0))))+SUMPRODUCT((Inputs!$C$5:$C$190=$B4)*ISNUMBER(INDEX(Inputs!$K$5:$AJ$190,0,MATCH(K$2,Inputs!$K$4:$AJ$4,0))))+SUMPRODUCT((Inputs!$E$5:$E$190=$B4)*ISNUMBER(INDEX(Inputs!$K$5:$AJ$190,0,MATCH(K$2,Inputs!$K$4:$AJ$4,0))))=0,NA(),SUMPRODUCT((Inputs!$A$5:$A$190=$B4)*Inputs!$B$5:$B$190*(((Inputs!$G$5:$G$190="moeda")+(Inputs!$G$5:$G$190="acoes"))*Inputs!$B$1+((Inputs!$G$5:$G$190<>"moeda")*(Inputs!$G$5:$G$190<>"acoes")))*INDEX(Inputs!$K$5:$AJ$190,0,MATCH(K$2,Inputs!$K$4:$AJ$4,0)))+SUMPRODUCT((Inputs!$C$5:$C$190=$B4)*Inputs!$D$5:$D$190*(((Inputs!$G$5:$G$190="moeda")+(Inputs!$G$5:$G$190="acoes"))*Inputs!$B$1+((Inputs!$G$5:$G$190<>"moeda")*(Inputs!$G$5:$G$190<>"acoes")))*INDEX(Inputs!$K$5:$AJ$190,0,MATCH(K$2,Inputs!$K$4:$AJ$4,0)))+SUMPRODUCT((Inputs!$E$5:$E$190=$B4)*Inputs!$F$5:$F$190*(((Inputs!$G$5:$G$190="moeda")+(Inputs!$G$5:$G$190="acoes"))*Inputs!$B$1+((Inputs!$G$5:$G$190<>"moeda")*(Inputs!$G$5:$G$190<>"acoes")))*INDEX(Inputs!$K$5:$AJ$190,0,MATCH(K$2,Inputs!$K$4:$AJ$4,0))))) -> 6823.3505 | L4: =IF(ISNA(MATCH(L$2,Inputs!$K$4:$AJ$4,0)),NA(),IF(SUMPRODUCT((Inputs!$A$5:$A$190=$B4)*ISNUMBER(INDEX(Inputs!$K$5:$AJ$190,0,MATCH(L$2,Inputs!$K$4:$AJ$4,0))))+SUMPRODUCT((Inputs!$C$5:$C$190=$B4)*ISNUMBER(INDEX(Inputs!$K$5:$AJ$190,0,MATCH(L$2,Inputs!$K$4:$AJ$4,0))))+SUMPRODUCT((Inputs!$E$5:$E$190=$B4)*ISNUMBER(INDEX(Inputs!$K$5:$AJ$190,0,MATCH(L$2,Inputs!$K$4:$AJ$4,0))))=0,NA(),SUMPRODUCT((Inputs!$A$5:$A$190=$B4)*Inputs!$B$5:$B$190*(((Inputs!$G$5:$G$190="moeda")+(Inputs!$G$5:$G$190="acoes"))*Inputs!$B$1+((Inputs!$G$5:$G$190<>"moeda")*(Inputs!$G$5:$G$190<>"acoes")))*INDEX(Inputs!$K$5:$AJ$190,0,MATCH(L$2,Inputs!$K$4:$AJ$4,0)))+SUMPRODUCT((Inputs!$C$5:$C$190=$B4)*Inputs!$D$5:$D$190*(((Inputs!$G$5:$G$190="moeda")+(Inputs!$G$5:$G$190="acoes"))*Inputs!$B$1+((Inputs!$G$5:$G$190<>"moeda")*(Inputs!$G$5:$G$190<>"acoes")))*INDEX(Inputs!$K$5:$AJ$190,0,MATCH(L$2,Inputs!$K$4:$AJ$4,0)))+SUMPRODUCT((Inputs!$E$5:$E$190=$B4)*Inputs!$F$5:$F$190*(((Inputs!$G$5:$G$190="moeda")+(Inputs!$G$5:$G$190="acoes"))*Inputs!$B$1+((Inputs!$G$5:$G$190<>"moeda")*(Inputs!$G$5:$G$190<>"acoes")))*INDEX(Inputs!$K$5:$AJ$190,0,MATCH(L$2,Inputs!$K$4:$AJ$4,0))))) -> 7341.1863 | M4: =SUM(I4:L4) -> 24081.881 | N4: =IF(ISNA(MATCH(N$2,Inputs!$K$4:$AJ$4,0)),NA(),IF(SUMPRODUCT((Inputs!$A$5:$A$190=$B4)*ISNUMBER(INDEX(Inputs!$K$5:$AJ$190,0,MATCH(N$2,Inputs!$K$4:$AJ$4,0))))+SUMPRODUCT((Inputs!$C$5:$C$190=$B4)*ISNUMBER(INDEX(Inputs!$K$5:$AJ$190,0,MATCH(N$2,Inputs!$K$4:$AJ$4,0))))+SUMPRODUCT((Inputs!$E$5:$E$190=$B4)*ISNUMBER(INDEX(Inputs!$K$5:$AJ$190,0,MATCH(N$2,Inputs!$K$4:$AJ$4,0))))=0,NA(),SUMPRODUCT((Inputs!$A$5:$A$190=$B4)*Inputs!$B$5:$B$190*(((Inputs!$G$5:$G$190="moeda")+(Inputs!$G$5:$G$190="acoes"))*Inputs!$B$1+((Inputs!$G$5:$G$190<>"moeda")*(Inputs!$G$5:$G$190<>"acoes")))*INDEX(Inputs!$K$5:$AJ$190,0,MATCH(N$2,Inputs!$K$4:$AJ$4,0)))+SUMPRODUCT((Inputs!$C$5:$C$190=$B4)*Inputs!$D$5:$D$190*(((Inputs!$G$5:$G$190="moeda")+(Inputs!$G$5:$G$190="acoes"))*Inputs!$B$1+((Inputs!$G$5:$G$190<>"moeda")*(Inputs!$G$5:$G$190<>"acoes")))*INDEX(Inputs!$K$5:$AJ$190,0,MATCH(N$2,Inputs!$K$4:$AJ$4,0)))+SUMPRODUCT((Inputs!$E$5:$E$190=$B4)*Inputs!$F$5:$F$190*(((Inputs!$G$5:$G$190="moeda")+(Inputs!$G$5:$G$190="acoes"))*Inputs!$B$1+((Inputs!$G$5:$G$190<>"moeda")*(Inputs!$G$5:$G$190<>"acoes")))*INDEX(Inputs!$K$5:$AJ$190,0,MATCH(N$2,Inputs!$K$4:$AJ$4,0))))) -> 7440.0438 | O4: =IF(ISNA(MATCH(O$2,Inputs!$K$4:$AJ$4,0)),NA(),IF(SUMPRODUCT((Inputs!$A$5:$A$190=$B4)*ISNUMBER(INDEX(Inputs!$K$5:$AJ$190,0,MATCH(O$2,Inputs!$K$4:$AJ$4,0))))+SUMPRODUCT((Inputs!$C$5:$C$190=$B4)*ISNUMBER(INDEX(Inputs!$K$5:$AJ$190,0,MATCH(O$2,Inputs!$K$4:$AJ$4,0))))+SUMPRODUCT((Inputs!$E$5:$E$190=$B4)*ISNUMBER(INDEX(Inputs!$K$5:$AJ$190,0,MATCH(O$2,Inputs!$K$4:$AJ$4,0))))=0,NA(),SUMPRODUCT((Inputs!$A$5:$A$190=$B4)*Inputs!$B$5:$B$190*(((Inputs!$G$5:$G$190="moeda")+(Inputs!$G$5:$G$190="acoes"))*Inputs!$B$1+((Inputs!$G$5:$G$190<>"moeda")*(Inputs!$G$5:$G$190<>"acoes")))*INDEX(Inputs!$K$5:$AJ$190,0,MATCH(O$2,Inputs!$K$4:$AJ$4,0)))+SUMPRODUCT((Inputs!$C$5:$C$190=$B4)*Inputs!$D$5:$D$190*(((Inputs!$G$5:$G$190="moeda")+(Inputs!$G$5:$G$190="acoes"))*Inputs!$B$1+((Inputs!$G$5:$G$190<>"moeda")*(Inputs!$G$5:$G$190<>"acoes")))*INDEX(Inputs!$K$5:$AJ$190,0,MATCH(O$2,Inputs!$K$4:$AJ$4,0)))+SUMPRODUCT((Inputs!$E$5:$E$190=$B4)*Inputs!$F$5:$F$190*(((Inputs!$G$5:$G$190="moeda")+(Inputs!$G$5:$G$190="acoes"))*Inputs!$B$1+((Inputs!$G$5:$G$190<>"moeda")*(Inputs!$G$5:$G$190<>"acoes")))*INDEX(Inputs!$K$5:$AJ$190,0,MATCH(O$2,Inputs!$K$4:$AJ$4,0))))) -> 7563.6362 | P4: =IF(ISNA(MATCH(P$2,Inputs!$K$4:$AJ$4,0)),NA(),IF(SUMPRODUCT((Inputs!$A$5:$A$190=$B4)*ISNUMBER(INDEX(Inputs!$K$5:$AJ$190,0,MATCH(P$2,Inputs!$K$4:$AJ$4,0))))+SUMPRODUCT((Inputs!$C$5:$C$190=$B4)*ISNUMBER(INDEX(Inputs!$K$5:$AJ$190,0,MATCH(P$2,Inputs!$K$4:$AJ$4,0))))+SUMPRODUCT((Inputs!$E$5:$E$190=$B4)*ISNUMBER(INDEX(Inputs!$K$5:$AJ$190,0,MATCH(P$2,Inputs!$K$4:$AJ$4,0))))=0,NA(),SUMPRODUCT((Inputs!$A$5:$A$190=$B4)*Inputs!$B$5:$B$190*(((Inputs!$G$5:$G$190="moeda")+(Inputs!$G$5:$G$190="acoes"))*Inputs!$B$1+((Inputs!$G$5:$G$190<>"moeda")*(Inputs!$G$5:$G$190<>"acoes")))*INDEX(Inputs!$K$5:$AJ$190,0,MATCH(P$2,Inputs!$K$4:$AJ$4,0)))+SUMPRODUCT((Inputs!$C$5:$C$190=$B4)*Inputs!$D$5:$D$190*(((Inputs!$G$5:$G$190="moeda")+(Inputs!$G$5:$G$190="acoes"))*Inputs!$B$1+((Inputs!$G$5:$G$190<>"moeda")*(Inputs!$G$5:$G$190<>"acoes")))*INDEX(Inputs!$K$5:$AJ$190,0,MATCH(P$2,Inputs!$K$4:$AJ$4,0)))+SUMPRODUCT((Inputs!$E$5:$E$190=$B4)*Inputs!$F$5:$F$190*(((Inputs!$G$5:$G$190="moeda")+(Inputs!$G$5:$G$190="acoes"))*Inputs!$B$1+((Inputs!$G$5:$G$190<>"moeda")*(Inputs!$G$5:$G$190<>"acoes")))*INDEX(Inputs!$K$5:$AJ$190,0,MATCH(P$2,Inputs!$K$4:$AJ$4,0))))) -> 8318.109 | Q4: =IF(ISNA(MATCH(Q$2,Inputs!$K$4:$AJ$4,0)),NA(),IF(SUMPRODUCT((Inputs!$A$5:$A$190=$B4)*ISNUMBER(INDEX(Inputs!$K$5:$AJ$190,0,MATCH(Q$2,Inputs!$K$4:$AJ$4,0))))+SUMPRODUCT((Inputs!$C$5:$C$190=$B4)*ISNUMBER(INDEX(Inputs!$K$5:$AJ$190,0,MATCH(Q$2,Inputs!$K$4:$AJ$4,0))))+SUMPRODUCT((Inputs!$E$5:$E$190=$B4)*ISNUMBER(INDEX(Inputs!$K$5:$AJ$190,0,MATCH(Q$2,Inputs!$K$4:$AJ$4,0))))=0,NA(),SUMPRODUCT((Inputs!$A$5:$A$190=$B4)*Inputs!$B$5:$B$190*(((Inputs!$G$5:$G$190="moeda")+(Inputs!$G$5:$G$190="acoes"))*Inputs!$B$1+((Inputs!$G$5:$G$190<>"moeda")*(Inputs!$G$5:$G$190<>"acoes")))*INDEX(Inputs!$K$5:$AJ$190,0,MATCH(Q$2,Inputs!$K$4:$AJ$4,0)))+SUMPRODUCT((Inputs!$C$5:$C$190=$B4)*Inputs!$D$5:$D$190*(((Inputs!$G$5:$G$190="moeda")+(Inputs!$G$5:$G$190="acoes"))*Inputs!$B$1+((Inputs!$G$5:$G$190<>"moeda")*(Inputs!$G$5:$G$190<>"acoes")))*INDEX(Inputs!$K$5:$AJ$190,0,MATCH(Q$2,Inputs!$K$4:$AJ$4,0)))+SUMPRODUCT((Inputs!$E$5:$E$190=$B4)*Inputs!$F$5:$F$190*(((Inputs!$G$5:$G$190="moeda")+(Inputs!$G$5:$G$190="acoes"))*Inputs!$B$1+((Inputs!$G$5:$G$190<>"moeda")*(Inputs!$G$5:$G$190<>"acoes")))*INDEX(Inputs!$K$5:$AJ$190,0,MATCH(Q$2,Inputs!$K$4:$AJ$4,0))))) -> 8521.824 | R4: =SUM(N4:Q4) -> 31843.613 | S4: =IF(ISNA(MATCH(S$2,Inputs!$K$4:$AJ$4,0)),NA(),IF(SUMPRODUCT((Inputs!$A$5:$A$190=$B4)*ISNUMBER(INDEX(Inputs!$K$5:$AJ$190,0,MATCH(S$2,Inputs!$K$4:$AJ$4,0))))+SUMPRODUCT((Inputs!$C$5:$C$190=$B4)*ISNUMBER(INDEX(Inputs!$K$5:$AJ$190,0,MATCH(S$2,Inputs!$K$4:$AJ$4,0))))+SUMPRODUCT((Inputs!$E$5:$E$190=$B4)*ISNUMBER(INDEX(Inputs!$K$5:$AJ$190,0,MATCH(S$2,Inputs!$K$4:$AJ$4,0))))=0,NA(),SUMPRODUCT((Inputs!$A$5:$A$190=$B4)*Inputs!$B$5:$B$190*(((Inputs!$G$5:$G$190="moeda")+(Inputs!$G$5:$G$190="acoes"))*Inputs!$B$1+((Inputs!$G$5:$G$190<>"moeda")*(Inputs!$G$5:$G$190<>"acoes")))*INDEX(Inputs!$K$5:$AJ$190,0,MATCH(S$2,Inputs!$K$4:$AJ$4,0)))+SUMPRODUCT((Inputs!$C$5:$C$190=$B4)*Inputs!$D$5:$D$190*(((Inputs!$G$5:$G$190="moeda")+(Inputs!$G$5:$G$190="acoes"))*Inputs!$B$1+((Inputs!$G$5:$G$190<>"moeda")*(Inputs!$G$5:$G$190<>"acoes")))*INDEX(Inputs!$K$5:$AJ$190,0,MATCH(S$2,Inputs!$K$4:$AJ$4,0)))+SUMPRODUCT((Inputs!$E$5:$E$190=$B4)*Inputs!$F$5:$F$190*(((Inputs!$G$5:$G$190="moeda")+(Inputs!$G$5:$G$190="acoes"))*Inputs!$B$1+((Inputs!$G$5:$G$190<>"moeda")*(Inputs!$G$5:$G$190<>"acoes")))*INDEX(Inputs!$K$5:$AJ$190,0,MATCH(S$2,Inputs!$K$4:$AJ$4,0))))) -> 9066.5964 | T4: =IF(ISNA(MATCH(T$2,Inputs!$K$4:$AJ$4,0)),NA(),IF(SUMPRODUCT((Inputs!$A$5:$A$190=$B4)*ISNUMBER(INDEX(Inputs!$K$5:$AJ$190,0,MATCH(T$2,Inputs!$K$4:$AJ$4,0))))+SUMPRODUCT((Inputs!$C$5:$C$190=$B4)*ISNUMBER(INDEX(Inputs!$K$5:$AJ$190,0,MATCH(T$2,Inputs!$K$4:$AJ$4,0))))+SUMPRODUCT((Inputs!$E$5:$E$190=$B4)*ISNUMBER(INDEX(Inputs!$K$5:$AJ$190,0,MATCH(T$2,Inputs!$K$4:$AJ$4,0))))=0,NA(),SUMPRODUCT((Inputs!$A$5:$A$190=$B4)*Inputs!$B$5:$B$190*(((Inputs!$G$5:$G$190="moeda")+(Inputs!$G$5:$G$190="acoes"))*Inputs!$B$1+((Inputs!$G$5:$G$190<>"moeda")*(Inputs!$G$5:$G$190<>"acoes")))*INDEX(Inputs!$K$5:$AJ$190,0,MATCH(T$2,Inputs!$K$4:$AJ$4,0)))+SUMPRODUCT((Inputs!$C$5:$C$190=$B4)*Inputs!$D$5:$D$190*(((Inputs!$G$5:$G$190="moeda")+(Inputs!$G$5:$G$190="acoes"))*Inputs!$B$1+((Inputs!$G$5:$G$190<>"moeda")*(Inputs!$G$5:$G$190<>"acoes")))*INDEX(Inputs!$K$5:$AJ$190,0,MATCH(T$2,Inputs!$K$4:$AJ$4,0)))+SUMPRODUCT((Inputs!$E$5:$E$190=$B4)*Inputs!$F$5:$F$190*(((Inputs!$G$5:$G$190="moeda")+(Inputs!$G$5:$G$190="acoes"))*Inputs!$B$1+((Inputs!$G$5:$G$190<>"moeda")*(Inputs!$G$5:$G$190<>"acoes")))*INDEX(Inputs!$K$5:$AJ$190,0,MATCH(T$2,Inputs!$K$4:$AJ$4,0))))) -> 10227.19 | U4: =IF(ISNA(MATCH(U$2,Inputs!$K$4:$AJ$4,0)),NA(),IF(SUMPRODUCT((Inputs!$A$5:$A$190=$B4)*ISNUMBER(INDEX(Inputs!$K$5:$AJ$190,0,MATCH(U$2,Inputs!$K$4:$AJ$4,0))))+SUMPRODUCT((Inputs!$C$5:$C$190=$B4)*ISNUMBER(INDEX(Inputs!$K$5:$AJ$190,0,MATCH(U$2,Inputs!$K$4:$AJ$4,0))))+SUMPRODUCT((Inputs!$E$5:$E$190=$B4)*ISNUMBER(INDEX(Inputs!$K$5:$AJ$190,0,MATCH(U$2,Inputs!$K$4:$AJ$4,0))))=0,NA(),SUMPRODUCT((Inputs!$A$5:$A$190=$B4)*Inputs!$B$5:$B$190*(((Inputs!$G$5:$G$190="moeda")+(Inputs!$G$5:$G$190="acoes"))*Inputs!$B$1+((Inputs!$G$5:$G$190<>"moeda")*(Inputs!$G$5:$G$190<>"acoes")))*INDEX(Inputs!$K$5:$AJ$190,0,MATCH(U$2,Inputs!$K$4:$AJ$4,0)))+SUMPRODUCT((Inputs!$C$5:$C$190=$B4)*Inputs!$D$5:$D$190*(((Inputs!$G$5:$G$190="moeda")+(Inputs!$G$5:$G$190="acoes"))*Inputs!$B$1+((Inputs!$G$5:$G$190<>"moeda")*(Inputs!$G$5:$G$190<>"acoes")))*INDEX(Inputs!$K$5:$AJ$190,0,MATCH(U$2,Inputs!$K$4:$AJ$4,0)))+SUMPRODUCT((Inputs!$E$5:$E$190=$B4)*Inputs!$F$5:$F$190*(((Inputs!$G$5:$G$190="moeda")+(Inputs!$G$5:$G$190="acoes"))*Inputs!$B$1+((Inputs!$G$5:$G$190<>"moeda")*(Inputs!$G$5:$G$190<>"acoes")))*INDEX(Inputs!$K$5:$AJ$190,0,MATCH(U$2,Inputs!$K$4:$AJ$4,0))))) -> 10790.491 | V4: =IF(ISNA(MATCH(V$2,Inputs!$K$4:$AJ$4,0)),NA(),IF(SUMPRODUCT((Inputs!$A$5:$A$190=$B4)*ISNUMBER(INDEX(Inputs!$K$5:$AJ$190,0,MATCH(V$2,Inputs!$K$4:$AJ$4,0))))+SUMPRODUCT((Inputs!$C$5:$C$190=$B4)*ISNUMBER(INDEX(Inputs!$K$5:$AJ$190,0,MATCH(V$2,Inputs!$K$4:$AJ$4,0))))+SUMPRODUCT((Inputs!$E$5:$E$190=$B4)*ISNUMBER(INDEX(Inputs!$K$5:$AJ$190,0,MATCH(V$2,Inputs!$K$4:$AJ$4,0))))=0,NA(),SUMPRODUCT((Inputs!$A$5:$A$190=$B4)*Inputs!$B$5:$B$190*(((Inputs!$G$5:$G$190="moeda")+(Inputs!$G$5:$G$190="acoes"))*Inputs!$B$1+((Inputs!$G$5:$G$190<>"moeda")*(Inputs!$G$5:$G$190<>"acoes")))*INDEX(Inputs!$K$5:$AJ$190,0,MATCH(V$2,Inputs!$K$4:$AJ$4,0)))+SUMPRODUCT((Inputs!$C$5:$C$190=$B4)*Inputs!$D$5:$D$190*(((Inputs!$G$5:$G$190="moeda")+(Inputs!$G$5:$G$190="acoes"))*Inputs!$B$1+((Inputs!$G$5:$G$190<>"moeda")*(Inputs!$G$5:$G$190<>"acoes")))*INDEX(Inputs!$K$5:$AJ$190,0,MATCH(V$2,Inputs!$K$4:$AJ$4,0)))+SUMPRODUCT((Inputs!$E$5:$E$190=$B4)*Inputs!$F$5:$F$190*(((Inputs!$G$5:$G$190="moeda")+(Inputs!$G$5:$G$190="acoes"))*Inputs!$B$1+((Inputs!$G$5:$G$190<>"moeda")*(Inputs!$G$5:$G$190<>"acoes")))*INDEX(Inputs!$K$5:$AJ$190,0,MATCH(V$2,Inputs!$K$4:$AJ$4,0))))) -> 10653.809 | W4: =SUM(S4:V4) -> 40738.086 | X4: =IF(ISNA(MATCH(X$2,Inputs!$K$4:$AJ$4,0)),NA(),IF(SUMPRODUCT((Inputs!$A$5:$A$190=$B4)*ISNUMBER(INDEX(Inputs!$K$5:$AJ$190,0,MATCH(X$2,Inputs!$K$4:$AJ$4,0))))+SUMPRODUCT((Inputs!$C$5:$C$190=$B4)*ISNUMBER(INDEX(Inputs!$K$5:$AJ$190,0,MATCH(X$2,Inputs!$K$4:$AJ$4,0))))+SUMPRODUCT((Inputs!$E$5:$E$190=$B4)*ISNUMBER(INDEX(Inputs!$K$5:$AJ$190,0,MATCH(X$2,Inputs!$K$4:$AJ$4,0))))=0,NA(),SUMPRODUCT((Inputs!$A$5:$A$190=$B4)*Inputs!$B$5:$B$190*(((Inputs!$G$5:$G$190="moeda")+(Inputs!$G$5:$G$190="acoes"))*Inputs!$B$1+((Inputs!$G$5:$G$190<>"moeda")*(Inputs!$G$5:$G$190<>"acoes")))*INDEX(Inputs!$K$5:$AJ$190,0,MATCH(X$2,Inputs!$K$4:$AJ$4,0)))+SUMPRODUCT((Inputs!$C$5:$C$190=$B4)*Inputs!$D$5:$D$190*(((Inputs!$G$5:$G$190="moeda")+(Inputs!$G$5:$G$190="acoes"))*Inputs!$B$1+((Inputs!$G$5:$G$190<>"moeda")*(Inputs!$G$5:$G$190<>"acoes")))*INDEX(Inputs!$K$5:$AJ$190,0,MATCH(X$2,Inputs!$K$4:$AJ$4,0)))+SUMPRODUCT((Inputs!$E$5:$E$190=$B4)*Inputs!$F$5:$F$190*(((Inputs!$G$5:$G$190="moeda")+(Inputs!$G$5:$G$190="acoes"))*Inputs!$B$1+((Inputs!$G$5:$G$190<>"moeda")*(Inputs!$G$5:$G$190<>"acoes")))*INDEX(Inputs!$K$5:$AJ$190,0,MATCH(X$2,Inputs!$K$4:$AJ$4,0))))) -> 10244.635 | Y4: =IF(ISNA(MATCH(Y$2,Inputs!$K$4:$AJ$4,0)),NA(),IF(SUMPRODUCT((Inputs!$A$5:$A$190=$B4)*ISNUMBER(INDEX(Inputs!$K$5:$AJ$190,0,MATCH(Y$2,Inputs!$K$4:$AJ$4,0))))+SUMPRODUCT((Inputs!$C$5:$C$190=$B4)*ISNUMBER(INDEX(Inputs!$K$5:$AJ$190,0,MATCH(Y$2,Inputs!$K$4:$AJ$4,0))))+SUMPRODUCT((Inputs!$E$5:$E$190=$B4)*ISNUMBER(INDEX(Inputs!$K$5:$AJ$190,0,MATCH(Y$2,Inputs!$K$4:$AJ$4,0))))=0,NA(),SUMPRODUCT((Inputs!$A$5:$A$190=$B4)*Inputs!$B$5:$B$190*(((Inputs!$G$5:$G$190="moeda")+(Inputs!$G$5:$G$190="acoes"))*Inputs!$B$1+((Inputs!$G$5:$G$190<>"moeda")*(Inputs!$G$5:$G$190<>"acoes")))*INDEX(Inputs!$K$5:$AJ$190,0,MATCH(Y$2,Inputs!$K$4:$AJ$4,0)))+SUMPRODUCT((Inputs!$C$5:$C$190=$B4)*Inputs!$D$5:$D$190*(((Inputs!$G$5:$G$190="moeda")+(Inputs!$G$5:$G$190="acoes"))*Inputs!$B$1+((Inputs!$G$5:$G$190<>"moeda")*(Inputs!$G$5:$G$190<>"acoes")))*INDEX(Inputs!$K$5:$AJ$190,0,MATCH(Y$2,Inputs!$K$4:$AJ$4,0)))+SUMPRODUCT((Inputs!$E$5:$E$190=$B4)*Inputs!$F$5:$F$190*(((Inputs!$G$5:$G$190="moeda")+(Inputs!$G$5:$G$190="acoes"))*Inputs!$B$1+((Inputs!$G$5:$G$190<>"moeda")*(Inputs!$G$5:$G$190<>"acoes")))*INDEX(Inputs!$K$5:$AJ$190,0,MATCH(Y$2,Inputs!$K$4:$AJ$4,0))))) -> 10340.786 | Z4: =IF(ISNA(MATCH(Z$2,Inputs!$K$4:$AJ$4,0)),NA(),IF(SUMPRODUCT((Inputs!$A$5:$A$190=$B4)*ISNUMBER(INDEX(Inputs!$K$5:$AJ$190,0,MATCH(Z$2,Inputs!$K$4:$AJ$4,0))))+SUMPRODUCT((Inputs!$C$5:$C$190=$B4)*ISNUMBER(INDEX(Inputs!$K$5:$AJ$190,0,MATCH(Z$2,Inputs!$K$4:$AJ$4,0))))+SUMPRODUCT((Inputs!$E$5:$E$190=$B4)*ISNUMBER(INDEX(Inputs!$K$5:$AJ$190,0,MATCH(Z$2,Inputs!$K$4:$AJ$4,0))))=0,NA(),SUMPRODUCT((Inputs!$A$5:$A$190=$B4)*Inputs!$B$5:$B$190*(((Inputs!$G$5:$G$190="moeda")+(Inputs!$G$5:$G$190="acoes"))*Inputs!$B$1+((Inputs!$G$5:$G$190<>"moeda")*(Inputs!$G$5:$G$190<>"acoes")))*INDEX(Inputs!$K$5:$AJ$190,0,MATCH(Z$2,Inputs!$K$4:$AJ$4,0)))+SUMPRODUCT((Inputs!$C$5:$C$190=$B4)*Inputs!$D$5:$D$190*(((Inputs!$G$5:$G$190="moeda")+(Inputs!$G$5:$G$190="acoes"))*Inputs!$B$1+((Inputs!$G$5:$G$190<>"moeda")*(Inputs!$G$5:$G$190<>"acoes")))*INDEX(Inputs!$K$5:$AJ$190,0,MATCH(Z$2,Inputs!$K$4:$AJ$4,0)))+SUMPRODUCT((Inputs!$E$5:$E$190=$B4)*Inputs!$F$5:$F$190*(((Inputs!$G$5:$G$190="moeda")+(Inputs!$G$5:$G$190="acoes"))*Inputs!$B$1+((Inputs!$G$5:$G$190<>"moeda")*(Inputs!$G$5:$G$190<>"acoes")))*INDEX(Inputs!$K$5:$AJ$190,0,MATCH(Z$2,Inputs!$K$4:$AJ$4,0))))) -> 11100.933 | AA4: =IF(ISNA(MATCH(AA$2,Inputs!$K$4:$AJ$4,0)),NA(),IF(SUMPRODUCT((Inputs!$A$5:$A$190=$B4)*ISNUMBER(INDEX(Inputs!$K$5:$AJ$190,0,MATCH(AA$2,Inputs!$K$4:$AJ$4,0))))+SUMPRODUCT((Inputs!$C$5:$C$190=$B4)*ISNUMBER(INDEX(Inputs!$K$5:$AJ$190,0,MATCH(AA$2,Inputs!$K$4:$AJ$4,0))))+SUMPRODUCT((Inputs!$E$5:$E$190=$B4)*ISNUMBER(INDEX(Inputs!$K$5:$AJ$190,0,MATCH(AA$2,Inputs!$K$4:$AJ$4,0))))=0,NA(),SUMPRODUCT((Inputs!$A$5:$A$190=$B4)*Inputs!$B$5:$B$190*(((Inputs!$G$5:$G$190="moeda")+(Inputs!$G$5:$G$190="acoes"))*Inputs!$B$1+((Inputs!$G$5:$G$190<>"moeda")*(Inputs!$G$5:$G$190<>"acoes")))*INDEX(Inputs!$K$5:$AJ$190,0,MATCH(AA$2,Inputs!$K$4:$AJ$4,0)))+SUMPRODUCT((Inputs!$C$5:$C$190=$B4)*Inputs!$D$5:$D$190*(((Inputs!$G$5:$G$190="moeda")+(Inputs!$G$5:$G$190="acoes"))*Inputs!$B$1+((Inputs!$G$5:$G$190<>"moeda")*(Inputs!$G$5:$G$190<>"acoes")))*INDEX(Inputs!$K$5:$AJ$190,0,MATCH(AA$2,Inputs!$K$4:$AJ$4,0)))+SUMPRODUCT((Inputs!$E$5:$E$190=$B4)*Inputs!$F$5:$F$190*(((Inputs!$G$5:$G$190="moeda")+(Inputs!$G$5:$G$190="acoes"))*Inputs!$B$1+((Inputs!$G$5:$G$190<>"moeda")*(Inputs!$G$5:$G$190<>"acoes")))*INDEX(Inputs!$K$5:$AJ$190,0,MATCH(AA$2,Inputs!$K$4:$AJ$4,0))))) -> 11119.492 | AB4: =SUM(X4:AA4) -> 42805.846 | AC4: =IF(ISNA(MATCH(AC$2,Inputs!$K$4:$AJ$4,0)),NA(),IF(SUMPRODUCT((Inputs!$A$5:$A$190=$B4)*ISNUMBER(INDEX(Inputs!$K$5:$AJ$190,0,MATCH(AC$2,Inputs!$K$4:$AJ$4,0))))+SUMPRODUCT((Inputs!$C$5:$C$190=$B4)*ISNUMBER(INDEX(Inputs!$K$5:$AJ$190,0,MATCH(AC$2,Inputs!$K$4:$AJ$4,0))))+SUMPRODUCT((Inputs!$E$5:$E$190=$B4)*ISNUMBER(INDEX(Inputs!$K$5:$AJ$190,0,MATCH(AC$2,Inputs!$K$4:$AJ$4,0))))=0,NA(),SUMPRODUCT((Inputs!$A$5:$A$190=$B4)*Inputs!$B$5:$B$190*(((Inputs!$G$5:$G$190="moeda")+(Inputs!$G$5:$G$190="acoes"))*Inputs!$B$1+((Inputs!$G$5:$G$190<>"moeda")*(Inputs!$G$5:$G$190<>"acoes")))*INDEX(Inputs!$K$5:$AJ$190,0,MATCH(AC$2,Inputs!$K$4:$AJ$4,0)))+SUMPRODUCT((Inputs!$C$5:$C$190=$B4)*Inputs!$D$5:$D$190*(((Inputs!$G$5:$G$190="moeda")+(Inputs!$G$5:$G$190="acoes"))*Inputs!$B$1+((Inputs!$G$5:$G$190<>"moeda")*(Inputs!$G$5:$G$190<>"acoes")))*INDEX(Inputs!$K$5:$AJ$190,0,MATCH(AC$2,Inputs!$K$4:$AJ$4,0)))+SUMPRODUCT((Inputs!$E$5:$E$190=$B4)*Inputs!$F$5:$F$190*(((Inputs!$G$5:$G$190="moeda")+(Inputs!$G$5:$G$190="acoes"))*Inputs!$B$1+((Inputs!$G$5:$G$190<>"moeda")*(Inputs!$G$5:$G$190<>"acoes")))*INDEX(Inputs!$K$5:$AJ$190,0,MATCH(AC$2,Inputs!$K$4:$AJ$4,0))))) -> 10924.298 | AD4: =IF(ISNA(MATCH(AD$2,Inputs!$K$4:$AJ$4,0)),NA(),IF(SUMPRODUCT((Inputs!$A$5:$A$190=$B4)*ISNUMBER(INDEX(Inputs!$K$5:$AJ$190,0,MATCH(AD$2,Inputs!$K$4:$AJ$4,0))))+SUMPRODUCT((Inputs!$C$5:$C$190=$B4)*ISNUMBER(INDEX(Inputs!$K$5:$AJ$190,0,MATCH(AD$2,Inputs!$K$4:$AJ$4,0))))+SUMPRODUCT((Inputs!$E$5:$E$190=$B4)*ISNUMBER(INDEX(Inputs!$K$5:$AJ$190,0,MATCH(AD$2,Inputs!$K$4:$AJ$4,0))))=0,NA(),SUMPRODUCT((Inputs!$A$5:$A$190=$B4)*Inputs!$B$5:$B$190*(((Inputs!$G$5:$G$190="moeda")+(Inputs!$G$5:$G$190="acoes"))*Inputs!$B$1+((Inputs!$G$5:$G$190<>"moeda")*(Inputs!$G$5:$G$190<>"acoes")))*INDEX(Inputs!$K$5:$AJ$190,0,MATCH(AD$2,Inputs!$K$4:$AJ$4,0)))+SUMPRODUCT((Inputs!$C$5:$C$190=$B4)*Inputs!$D$5:$D$190*(((Inputs!$G$5:$G$190="moeda")+(Inputs!$G$5:$G$190="acoes"))*Inputs!$B$1+((Inputs!$G$5:$G$190<>"moeda")*(Inputs!$G$5:$G$190<>"acoes")))*INDEX(Inputs!$K$5:$AJ$190,0,MATCH(AD$2,Inputs!$K$4:$AJ$4,0)))+SUMPRODUCT((Inputs!$E$5:$E$190=$B4)*Inputs!$F$5:$F$190*(((Inputs!$G$5:$G$190="moeda")+(Inputs!$G$5:$G$190="acoes"))*Inputs!$B$1+((Inputs!$G$5:$G$190<>"moeda")*(Inputs!$G$5:$G$190<>"acoes")))*INDEX(Inputs!$K$5:$AJ$190,0,MATCH(AD$2,Inputs!$K$4:$AJ$4,0))))) -> 11248.662 | AE4: =IF(ISNA(MATCH(AE$2,Inputs!$K$4:$AJ$4,0)),NA(),IF(SUMPRODUCT((Inputs!$A$5:$A$190=$B4)*ISNUMBER(INDEX(Inputs!$K$5:$AJ$190,0,MATCH(AE$2,Inputs!$K$4:$AJ$4,0))))+SUMPRODUCT((Inputs!$C$5:$C$190=$B4)*ISNUMBER(INDEX(Inputs!$K$5:$AJ$190,0,MATCH(AE$2,Inputs!$K$4:$AJ$4,0))))+SUMPRODUCT((Inputs!$E$5:$E$190=$B4)*ISNUMBER(INDEX(Inputs!$K$5:$AJ$190,0,MATCH(AE$2,Inputs!$K$4:$AJ$4,0))))=0,NA(),SUMPRODUCT((Inputs!$A$5:$A$190=$B4)*Inputs!$B$5:$B$190*(((Inputs!$G$5:$G$190="moeda")+(Inputs!$G$5:$G$190="acoes"))*Inputs!$B$1+((Inputs!$G$5:$G$190<>"moeda")*(Inputs!$G$5:$G$190<>"acoes")))*INDEX(Inputs!$K$5:$AJ$190,0,MATCH(AE$2,Inputs!$K$4:$AJ$4,0)))+SUMPRODUCT((Inputs!$C$5:$C$190=$B4)*Inputs!$D$5:$D$190*(((Inputs!$G$5:$G$190="moeda")+(Inputs!$G$5:$G$190="acoes"))*Inputs!$B$1+((Inputs!$G$5:$G$190<>"moeda")*(Inputs!$G$5:$G$190<>"acoes")))*INDEX(Inputs!$K$5:$AJ$190,0,MATCH(AE$2,Inputs!$K$4:$AJ$4,0)))+SUMPRODUCT((Inputs!$E$5:$E$190=$B4)*Inputs!$F$5:$F$190*(((Inputs!$G$5:$G$190="moeda")+(Inputs!$G$5:$G$190="acoes"))*Inputs!$B$1+((Inputs!$G$5:$G$190<>"moeda")*(Inputs!$G$5:$G$190<>"acoes")))*INDEX(Inputs!$K$5:$AJ$190,0,MATCH(AE$2,Inputs!$K$4:$AJ$4,0))))) -> #N/A | AF4: =IF(ISNA(MATCH(AF$2,Inputs!$K$4:$AJ$4,0)),NA(),IF(SUMPRODUCT((Inputs!$A$5:$A$190=$B4)*ISNUMBER(INDEX(Inputs!$K$5:$AJ$190,0,MATCH(AF$2,Inputs!$K$4:$AJ$4,0))))+SUMPRODUCT((Inputs!$C$5:$C$190=$B4)*ISNUMBER(INDEX(Inputs!$K$5:$AJ$190,0,MATCH(AF$2,Inputs!$K$4:$AJ$4,0))))+SUMPRODUCT((Inputs!$E$5:$E$190=$B4)*ISNUMBER(INDEX(Inputs!$K$5:$AJ$190,0,MATCH(AF$2,Inputs!$K$4:$AJ$4,0))))=0,NA(),SUMPRODUCT((Inputs!$A$5:$A$190=$B4)*Inputs!$B$5:$B$190*(((Inputs!$G$5:$G$190="moeda")+(Inputs!$G$5:$G$190="acoes"))*Inputs!$B$1+((Inputs!$G$5:$G$190<>"moeda")*(Inputs!$G$5:$G$190<>"acoes")))*INDEX(Inputs!$K$5:$AJ$190,0,MATCH(AF$2,Inputs!$K$4:$AJ$4,0)))+SUMPRODUCT((Inputs!$C$5:$C$190=$B4)*Inputs!$D$5:$D$190*(((Inputs!$G$5:$G$190="moeda")+(Inputs!$G$5:$G$190="acoes"))*Inputs!$B$1+((Inputs!$G$5:$G$190<>"moeda")*(Inputs!$G$5:$G$190<>"acoes")))*INDEX(Inputs!$K$5:$AJ$190,0,MATCH(AF$2,Inputs!$K$4:$AJ$4,0)))+SUMPRODUCT((Inputs!$E$5:$E$190=$B4)*Inputs!$F$5:$F$190*(((Inputs!$G$5:$G$190="moeda")+(Inputs!$G$5:$G$190="acoes"))*Inputs!$B$1+((Inputs!$G$5:$G$190<>"moeda")*(Inputs!$G$5:$G$190<>"acoes")))*INDEX(Inputs!$K$5:$AJ$190,0,MATCH(AF$2,Inputs!$K$4:$AJ$4,0))))) -> #N/A | AG4: =SUM(AC4:AF4) -> #N/A | AH4: =IF(ISNA(MATCH(AH$2,Inputs!$K$4:$AJ$4,0)),NA(),IF(SUMPRODUCT((Inputs!$A$5:$A$190=$B4)*ISNUMBER(INDEX(Inputs!$K$5:$AJ$190,0,MATCH(AH$2,Inputs!$K$4:$AJ$4,0))))+SUMPRODUCT((Inputs!$C$5:$C$190=$B4)*ISNUMBER(INDEX(Inputs!$K$5:$AJ$190,0,MATCH(AH$2,Inputs!$K$4:$AJ$4,0))))+SUMPRODUCT((Inputs!$E$5:$E$190=$B4)*ISNUMBER(INDEX(Inputs!$K$5:$AJ$190,0,MATCH(AH$2,Inputs!$K$4:$AJ$4,0))))=0,NA(),SUMPRODUCT((Inputs!$A$5:$A$190=$B4)*Inputs!$B$5:$B$190*(((Inputs!$G$5:$G$190="moeda")+(Inputs!$G$5:$G$190="acoes"))*Inputs!$B$1+((Inputs!$G$5:$G$190<>"moeda")*(Inputs!$G$5:$G$190<>"acoes")))*INDEX(Inputs!$K$5:$AJ$190,0,MATCH(AH$2,Inputs!$K$4:$AJ$4,0)))+SUMPRODUCT((Inputs!$C$5:$C$190=$B4)*Inputs!$D$5:$D$190*(((Inputs!$G$5:$G$190="moeda")+(Inputs!$G$5:$G$190="acoes"))*Inputs!$B$1+((Inputs!$G$5:$G$190<>"moeda")*(Inputs!$G$5:$G$190<>"acoes")))*INDEX(Inputs!$K$5:$AJ$190,0,MATCH(AH$2,Inputs!$K$4:$AJ$4,0)))+SUMPRODUCT((Inputs!$E$5:$E$190=$B4)*Inputs!$F$5:$F$190*(((Inputs!$G$5:$G$190="moeda")+(Inputs!$G$5:$G$190="acoes"))*Inputs!$B$1+((Inputs!$G$5:$G$190<>"moeda")*(Inputs!$G$5:$G$190<>"acoes")))*INDEX(Inputs!$K$5:$AJ$190,0,MATCH(AH$2,Inputs!$K$4:$AJ$4,0))))) -> 2356.8923 | AI4: =IF(ISNA(MATCH(AI$2,Inputs!$K$4:$AJ$4,0)),NA(),IF(SUMPRODUCT((Inputs!$A$5:$A$190=$B4)*ISNUMBER(INDEX(Inputs!$K$5:$AJ$190,0,MATCH(AI$2,Inputs!$K$4:$AJ$4,0))))+SUMPRODUCT((Inputs!$C$5:$C$190=$B4)*ISNUMBER(INDEX(Inputs!$K$5:$AJ$190,0,MATCH(AI$2,Inputs!$K$4:$AJ$4,0))))+SUMPRODUCT((Inputs!$E$5:$E$190=$B4)*ISNUMBER(INDEX(Inputs!$K$5:$AJ$190,0,MATCH(AI$2,Inputs!$K$4:$AJ$4,0))))=0,NA(),SUMPRODUCT((Inputs!$A$5:$A$190=$B4)*Inputs!$B$5:$B$190*(((Inputs!$G$5:$G$190="moeda")+(Inputs!$G$5:$G$190="acoes"))*Inputs!$B$1+((Inputs!$G$5:$G$190<>"moeda")*(Inputs!$G$5:$G$190<>"acoes")))*INDEX(Inputs!$K$5:$AJ$190,0,MATCH(AI$2,Inputs!$K$4:$AJ$4,0)))+SUMPRODUCT((Inputs!$C$5:$C$190=$B4)*Inputs!$D$5:$D$190*(((Inputs!$G$5:$G$190="moeda")+(Inputs!$G$5:$G$190="acoes"))*Inputs!$B$1+((Inputs!$G$5:$G$190<>"moeda")*(Inputs!$G$5:$G$190<>"acoes")))*INDEX(Inputs!$K$5:$AJ$190,0,MATCH(AI$2,Inputs!$K$4:$AJ$4,0)))+SUMPRODUCT((Inputs!$E$5:$E$190=$B4)*Inputs!$F$5:$F$190*(((Inputs!$G$5:$G$190="moeda")+(Inputs!$G$5:$G$190="acoes"))*Inputs!$B$1+((Inputs!$G$5:$G$190<>"moeda")*(Inputs!$G$5:$G$190<>"acoes")))*INDEX(Inputs!$K$5:$AJ$190,0,MATCH(AI$2,Inputs!$K$4:$AJ$4,0))))) -> 2197.2248 | AJ4: =IF(ISNA(MATCH(AJ$2,Inputs!$K$4:$AJ$4,0)),NA(),IF(SUMPRODUCT((Inputs!$A$5:$A$190=$B4)*ISNUMBER(INDEX(Inputs!$K$5:$AJ$190,0,MATCH(AJ$2,Inputs!$K$4:$AJ$4,0))))+SUMPRODUCT((Inputs!$C$5:$C$190=$B4)*ISNUMBER(INDEX(Inputs!$K$5:$AJ$190,0,MATCH(AJ$2,Inputs!$K$4:$AJ$4,0))))+SUMPRODUCT((Inputs!$E$5:$E$190=$B4)*ISNUMBER(INDEX(Inputs!$K$5:$AJ$190,0,MATCH(AJ$2,Inputs!$K$4:$AJ$4,0))))=0,NA(),SUMPRODUCT((Inputs!$A$5:$A$190=$B4)*Inputs!$B$5:$B$190*(((Inputs!$G$5:$G$190="moeda")+(Inputs!$G$5:$G$190="acoes"))*Inputs!$B$1+((Inputs!$G$5:$G$190<>"moeda")*(Inputs!$G$5:$G$190<>"acoes")))*INDEX(Inputs!$K$5:$AJ$190,0,MATCH(AJ$2,Inputs!$K$4:$AJ$4,0)))+SUMPRODUCT((Inputs!$C$5:$C$190=$B4)*Inputs!$D$5:$D$190*(((Inputs!$G$5:$G$190="moeda")+(Inputs!$G$5:$G$190="acoes"))*Inputs!$B$1+((Inputs!$G$5:$G$190<>"moeda")*(Inputs!$G$5:$G$190<>"acoes")))*INDEX(Inputs!$K$5:$AJ$190,0,MATCH(AJ$2,Inputs!$K$4:$AJ$4,0)))+SUMPRODUCT((Inputs!$E$5:$E$190=$B4)*Inputs!$F$5:$F$190*(((Inputs!$G$5:$G$190="moeda")+(Inputs!$G$5:$G$190="acoes"))*Inputs!$B$1+((Inputs!$G$5:$G$190<>"moeda")*(Inputs!$G$5:$G$190<>"acoes")))*INDEX(Inputs!$K$5:$AJ$190,0,MATCH(AJ$2,Inputs!$K$4:$AJ$4,0))))) -> 2603.0449 | AK4: =IF(ISNA(MATCH(AK$2,Inputs!$K$4:$AJ$4,0)),NA(),IF(SUMPRODUCT((Inputs!$A$5:$A$190=$B4)*ISNUMBER(INDEX(Inputs!$K$5:$AJ$190,0,MATCH(AK$2,Inputs!$K$4:$AJ$4,0))))+SUMPRODUCT((Inputs!$C$5:$C$190=$B4)*ISNUMBER(INDEX(Inputs!$K$5:$AJ$190,0,MATCH(AK$2,Inputs!$K$4:$AJ$4,0))))+SUMPRODUCT((Inputs!$E$5:$E$190=$B4)*ISNUMBER(INDEX(Inputs!$K$5:$AJ$190,0,MATCH(AK$2,Inputs!$K$4:$AJ$4,0))))=0,NA(),SUMPRODUCT((Inputs!$A$5:$A$190=$B4)*Inputs!$B$5:$B$190*(((Inputs!$G$5:$G$190="moeda")+(Inputs!$G$5:$G$190="acoes"))*Inputs!$B$1+((Inputs!$G$5:$G$190<>"moeda")*(Inputs!$G$5:$G$190<>"acoes")))*INDEX(Inputs!$K$5:$AJ$190,0,MATCH(AK$2,Inputs!$K$4:$AJ$4,0)))+SUMPRODUCT((Inputs!$C$5:$C$190=$B4)*Inputs!$D$5:$D$190*(((Inputs!$G$5:$G$190="moeda")+(Inputs!$G$5:$G$190="acoes"))*Inputs!$B$1+((Inputs!$G$5:$G$190<>"moeda")*(Inputs!$G$5:$G$190<>"acoes")))*INDEX(Inputs!$K$5:$AJ$190,0,MATCH(AK$2,Inputs!$K$4:$AJ$4,0)))+SUMPRODUCT((Inputs!$E$5:$E$190=$B4)*Inputs!$F$5:$F$190*(((Inputs!$G$5:$G$190="moeda")+(Inputs!$G$5:$G$190="acoes"))*Inputs!$B$1+((Inputs!$G$5:$G$190<>"moeda")*(Inputs!$G$5:$G$190<>"acoes")))*INDEX(Inputs!$K$5:$AJ$190,0,MATCH(AK$2,Inputs!$K$4:$AJ$4,0))))) -> 2649.895 | AL4: =SUM(AH4:AK4) -> 9807.057
