Workbook

Sheet Inputs
A1: Fator p/ milhões: | B1: 1 | D1: Shell plc (SHEL, CIK 1306965) - fonte: Quarterly Databook Q2 2026 do RI (shell.com/investors). Moeda: USD. Brutos já em USD milhões (fator = 1). Trimestre isolado (a soma dos quatro trimestres fecha o ano, arredondamento de US$ 1 mi). Série da fonte: 1T21 a 2T26. 1T20-4T20 ficam vazios: o databook vigente começa em Q1 2021. IFRS: DRE em etapa única, sem lucro operacional divulgado.
J2: Trimestre | K2: 1Q20 | L2: 2Q20 | M2: 3Q20 | N2: 4Q20 | O2: 1Q21 | P2: 2Q21 | Q2: 3Q21 | R2: 4Q21 | S2: 1Q22 | T2: 2Q22 | U2: 3Q22 | V2: 4Q22 | W2: 1Q23 | X2: 2Q23 | Y2: 3Q23 | Z2: 4Q23 | AA2: 1Q24 | AB2: 2Q24 | AC2: 3Q24 | AD2: 4Q24 | AE2: 1Q25 | AF2: 2Q25 | AG2: 3Q25 | AH2: 4Q25 | AI2: 1Q26 | AJ2: 2Q26
A4: COD1 | B4: SINAL1 | C4: COD2 | D4: SINAL2 | E4: COD3 | F4: SINAL3 | G4: UNID | H4: Conta (PT) / origem | I4: Account (EN) | J4: ORIGEM | K4: 1Q20 | L4: 2Q20 | M4: 3Q20 | N4: 4Q20 | O4: 1Q21 | P4: 2Q21 | Q4: 3Q21 | R4: 4Q21 | S4: 1Q22 | T4: 2Q22 | U4: 3Q22 | V4: 4Q22 | W4: 1Q23 | X4: 2Q23 | Y4: 3Q23 | Z4: 4Q23 | AA4: 1Q24 | AB4: 2Q24 | AC4: 3Q24 | AD4: 4Q24 | AE4: 1Q25 | AF4: 2Q25 | AG4: 3Q25 | AH4: 4Q25 | AI4: 1Q26 | AJ4: 2Q26
H5: DRE - trimestre isolado (USD milhões). Fonte: aba Statement of Income do databook
A6: 1 | B6: 1 | G6: moeda | H6: Receita [Revenue] databook Statement of Income | J6: fonte | O6: 55665 | P6: 60515 | Q6: 60044 | R6: 85280 | S6: 84204 | T6: 100059 | U6: 95749 | V6: 101303 | W6: 86959 | X6: 74578 | Y6: 76350 | Z6: 78732 | AA6: 72478 | AB6: 74463 | AC6: 71089 | AD6: 66281 | AE6: 69234 | AF6: 65406 | AG6: 68153 | AH6: 64093 | AI6: 69691 | AJ6: 94664
A7: 2 | B7: -1 | G7: moeda | H7: Compras / custo da receita (divulgado positivo) [Purchases] | J7: fonte | O7: 34369 | P7: 39717 | Q7: 44260 | R7: 56566 | S7: 55657 | T7: 66658 | U7: 70684 | V7: 65489 | W7: 57502 | X7: 51492 | Y7: 49144 | Z7: 54745 | AA7: 46867 | AB7: 49417 | AC7: 48225 | AD7: 43610 | AE7: 45849 | AF7: 44099 | AG7: 45145 | AH7: 42102 | AI7: 44775 | AJ7: 64530
G8: moeda | H8: Despesas de produção e fabricação [Production and manufacturing expenses] (memória; entram nas despesas operacionais) | J8: memoria | O8: 6808 | P8: 5162 | Q8: 5322 | R8: 6530 | S8: 6029 | T8: 6359 | U8: 5910 | V8: 7220 | W8: 6008 | X8: 6041 | Y8: 6384 | Z8: 6807 | AA8: 5810 | AB8: 5593 | AC8: 6138 | AD8: 5839 | AE8: 5549 | AF8: 4909 | AG8: 5609 | AH8: 5830 | AI8: 5745 | AJ8: 5476
G9: moeda | H9: Despesas de vendas, distribuição e administrativas [Selling, distribution and administrative expenses] | J9: memoria | O9: 2462 | P9: 3107 | Q9: 2892 | R9: 2867 | S9: 3239 | T9: 2924 | U9: 3229 | V9: 3491 | W9: 3051 | X9: 3314 | Y9: 3447 | Z9: 3621 | AA9: 2975 | AB9: 3094 | AC9: 3139 | AD9: 3231 | AE9: 2840 | AF9: 3077 | AG9: 3258 | AH9: 3432 | AI9: 2803 | AJ9: 2911
G10: moeda | H10: P&D [Research and development] | J10: memoria | O10: 166 | P10: 201 | Q10: 145 | R10: 304 | S10: 189 | T10: 264 | U10: 220 | V10: 403 | W10: 253 | X10: 297 | Y10: 267 | Z10: 469 | AA10: 212 | AB10: 263 | AC10: 294 | AD10: 331 | AE10: 185 | AF10: 278 | AG10: 409 | AH10: 298 | AI10: 167 | AJ10: 277
G11: moeda | H11: Exploração [Exploration] | J11: memoria | O11: 285 | P11: 332 | Q11: 526 | R11: 280 | S11: 269 | T11: 370 | U11: 424 | V11: 649 | W11: 404 | X11: 444 | Y11: 436 | Z11: 467 | AA11: 750 | AB11: 496 | AC11: 305 | AD11: 861 | AE11: 210 | AF11: 360 | AG11: 175 | AH11: 391 | AI11: 98 | AJ11: 110
G12: moeda | H12: Lucro operacional DERIVADO = receita − compras − produção − vendas/adm − P&D − exploração − D&A. A Shell não divulga EBIT; JV e outras receitas ficam no não operacional. | J12: memoria | O12: 5679 | P12: 3773 | Q12: 541 | R12: 12288 | S12: 12526 | T12: 23832 | U12: 9158 | V12: 17592 | W12: 13456 | X12: 5118 | Y12: 10761 | Z12: 1402 | AA12: 9983 | AB12: 8045 | AC12: 7072 | AD12: 4889 | AE12: 9160 | AF12: 6013 | AG12: 6950 | AH12: 5459 | AI12: 10360 | AJ12: 15177
A13: 3 | B13: -1 | G13: moeda | H13: Despesas operacionais = receita − custo − lucro operacional (produção, vendas/adm, P&D, exploração, D&A) | J13: derivada | O13: =N(O6)-N(O7)-N(O12) -> 15617 | P13: =N(P6)-N(P7)-N(P12) -> 17025 | Q13: =N(Q6)-N(Q7)-N(Q12) -> 15243 | R13: =N(R6)-N(R7)-N(R12) -> 16426 | S13: =N(S6)-N(S7)-N(S12) -> 16021 | T13: =N(T6)-N(T7)-N(T12) -> 9569 | U13: =N(U6)-N(U7)-N(U12) -> 15907 | V13: =N(V6)-N(V7)-N(V12) -> 18222 | ... AJ13: =N(AJ6)-N(AJ7)-N(AJ12) -> 14957
G14: moeda | H14: Lucro antes do IR [Income/(loss) before taxation] | J14: memoria | O14: 8237 | P14: 4130 | Q14: 1193 | R14: 16269 | S14: 10776 | T14: 26160 | U14: 11435 | V14: 16443 | W14: 14354 | X14: 5348 | Y14: 11291 | Z14: 1635 | AA14: 11044 | AB14: 7404 | AC14: 7270 | AD14: 4205 | AE14: 8959 | AF14: 5975 | AG14: 7924 | AH14: 6898 | AI14: 9328 | AJ14: 15754
A15: 6 | B15: 1 | G15: moeda | H15: Resultado não operacional total = lucro antes do IR − lucro operacional (JV + outras receitas − juros) | J15: derivada | O15: =N(O14)-N(O12) -> 2558 | P15: =N(P14)-N(P12) -> 357 | Q15: =N(Q14)-N(Q12) -> 652 | R15: =N(R14)-N(R12) -> 3981 | S15: =N(S14)-N(S12) -> -1750 | T15: =N(T14)-N(T12) -> 2328 | U15: =N(U14)-N(U12) -> 2277 | V15: =N(V14)-N(V12) -> -1149 | ... AJ15: =N(AJ14)-N(AJ12) -> 577
G16: moeda | H16: Equivalência patrimonial [Share of profit/(loss) of joint ventures and associates] (memória; já está no código 6 via não operacional) | J16: memoria | O16: 995 | P16: 1114 | Q16: 1014 | R16: 975 | S16: -303 | T16: 2031 | U16: 2512 | V16: -268 | W16: 1581 | X16: 629 | Y16: 747 | Z16: 768 | AA16: 1318 | AB16: 898 | AC16: 933 | AD16: -156 | AE16: 615 | AF16: 712 | AG16: 507 | AH16: -215 | AI16: -93 | AJ16: 642
G17: moeda | H17: Juros e outras receitas/(despesas) [Interest and other income/(expenses)] (memória; já está no código 6 via não operacional) | J17: memoria | O17: 2455 | P17: 134 | Q17: 497 | R17: 3968 | S17: -737 | T17: 993 | U17: 498 | V17: 160 | W17: 481 | X17: 813 | Y17: 913 | Z17: 631 | AA17: 907 | AB17: -305 | AC17: 440 | AD17: 683 | AE17: 302 | AF17: 326 | AG17: 1751 | AH17: 2848 | AI17: 535 | AJ17: 1048
A18: 5 | B18: -1 | C18: 6 | D18: 1 | G18: moeda | H18: Despesa de juros (divulgado positivo): COD1=5 lança; COD2=6 devolve ao não operacional, que já a contém [Interest expense] | J18: fonte | O18: 892 | P18: 893 | Q18: 859 | R18: 963 | S18: 711 | T18: 695 | U18: 734 | V18: 1040 | W18: 1165 | X18: 1211 | Y18: 1131 | Z18: 1166 | AA18: 1164 | AB18: 1235 | AC18: 1174 | AD18: 1213 | AE18: 1120 | AF18: 1075 | AG18: 1284 | AH18: 1193 | AI18: 1473 | AJ18: 1114
A19: 7 | B19: -1 | G19: moeda | H19: Imposto de renda (charge positivo / credit negativo) [Taxation charge/(credit)] | J19: fonte | O19: 2453 | P19: 571 | Q19: 1510 | R19: 4665 | S19: 3457 | T19: 7922 | U19: 4587 | V19: 5975 | W19: 5582 | X19: 2195 | Y19: 4115 | Z19: 1099 | AA19: 3604 | AB19: 3754 | AC19: 2879 | AD19: 3164 | AE19: 4083 | AF19: 2332 | AG19: 2504 | AH19: 2718 | AI19: 3570 | AJ19: 4949
A20: 9 | B20: -1 | G20: moeda | H20: Lucro atribuído a não controladores [Income/(loss) attributable to non-controlling interest] | J20: fonte | O20: 124 | P20: 131 | Q20: 130 | R20: 144 | S20: 203 | T20: 198 | U20: 104 | V20: 59 | W20: 64 | X20: 20 | Y20: 132 | Z20: 62 | AA20: 82 | AB20: 133 | AC20: 100 | AD20: 113 | AE20: 95 | AF20: 43 | AG20: 98 | AH20: 46 | AI20: 64 | AJ20: -16
G21: moeda | H21: Lucro líquido atribuído à Shell plc [Income/(loss) attributable to Shell plc shareholders] | J21: memoria | O21: 5660 | P21: 3428 | Q21: -447 | R21: 11461 | S21: 7116 | T21: 18040 | U21: 6743 | V21: 10409 | W21: 8709 | X21: 3134 | Y21: 7044 | Z21: 474 | AA21: 7358 | AB21: 3517 | AC21: 4291 | AD21: 928 | AE21: 4780 | AF21: 3601 | AG21: 5322 | AH21: 4134 | AI21: 5694 | AJ21: 10821
A22: 8 | B22: 1 | G22: moeda | H22: Resultado após IR não classificado: lucro − (LAIR − IR − minoritários); absorve arredondamento de US$ 1 mi | J22: derivada | O22: =N(O21)-(N(O14)-N(O19)-N(O20)) -> 0 | P22: =N(P21)-(N(P14)-N(P19)-N(P20)) -> 0 | Q22: =N(Q21)-(N(Q14)-N(Q19)-N(Q20)) -> 0 | R22: =N(R21)-(N(R14)-N(R19)-N(R20)) -> 1 | S22: =N(S21)-(N(S14)-N(S19)-N(S20)) -> 0 | T22: =N(T21)-(N(T14)-N(T19)-N(T20)) -> 0 | U22: =N(U21)-(N(U14)-N(U19)-N(U20)) -> -1 | V22: =N(V21)-(N(V14)-N(V19)-N(V20)) -> 0 | ... AJ22: =N(AJ21)-(N(AJ14)-N(AJ19)-N(AJ20)) -> 0
A23: 44 | B23: 1 | G23: moeda | H23: Lucro líquido (check IS, código 44) | J23: derivada | O23: =N(O21) -> 5660 | P23: =N(P21) -> 3428 | Q23: =N(Q21) -> -447 | R23: =N(R21) -> 11461 | S23: =N(S21) -> 7116 | T23: =N(T21) -> 18040 | U23: =N(U21) -> 6743 | V23: =N(V21) -> 10409 | ... AJ23: =N(AJ21) -> 10821
H24: DFC - trimestre isolado (USD milhões). Dividendos: databook negativo, lançados em valor absoluto
A25: 4 | B25: -1 | C25: 3 | D25: 1 | G25: moeda | H25: D&A da DRE. COD1=4 lança; COD2=3 devolve às despesas operacionais (a D&A vem em linha própria, não no custo) [Depreciation, depletion and amortisation] | J25: fonte | O25: 5896 | P25: 8223 | Q25: 6358 | R25: 6445 | S25: 6295 | T25: -348 | U25: 6124 | V25: 6459 | W25: 6285 | X25: 7872 | Y25: 5911 | Z25: 11221 | AA25: 5881 | AB25: 7555 | AC25: 5916 | AD25: 7520 | AE25: 5441 | AF25: 6670 | AG25: 6607 | AH25: 6581 | AI25: 5743 | AJ25: 6183
A26: 10 | B26: -1 | G26: moeda | H26: Dividendos pagos aos acionistas da Shell plc (valor absoluto do fluxo) [Cash dividends paid to Shell plc shareholders] | J26: fonte | O26: 1292 | P26: 1310 | Q26: 1812 | R26: 1838 | S26: 1950 | T26: 1851 | U26: 1818 | V26: 1785 | W26: 2029 | X26: 1983 | Y26: 2179 | Z26: 2201 | AA26: 2210 | AB26: 2177 | AC26: 2167 | AD26: 2114 | AE26: 2179 | AF26: 2122 | AG26: 2103 | AH26: 2068 | AI26: 2100 | AJ26: 2164
G27: moeda | H27: CFO [Cash flow from operating activities] memória | J27: memoria | O27: 8294 | P27: 12617 | Q27: 16025 | R27: 8170 | S27: 14815 | T27: 18655 | U27: 12539 | V27: 22404 | W27: 14159 | X27: 15130 | Y27: 12332 | Z27: 12575 | AA27: 13330 | AB27: 13508 | AC27: 14684 | AD27: 13162 | AE27: 9281 | AF27: 11937 | AG27: 12207 | AH27: 9438 | AI27: 6062 | AJ27: 21432
G28: moeda | H28: CFI [Cash flow from investing activities] memória | J28: memoria | O28: -590 | P28: -2946 | Q28: -3804 | R28: 2579 | S28: -4273 | T28: -6207 | U28: -5049 | V28: -6918 | W28: -4238 | X28: -3015 | Y28: -4827 | Z28: -5657 | AA28: -3528 | AB28: -3338 | AC28: -3857 | AD28: -4431 | AE28: -3959 | AF28: -5406 | AG28: -2257 | AH28: -5190 | AI28: -3136 | AJ28: -3908
G29: moeda | H29: CFF [Cash flow from financing activities] memória | J29: memoria | O29: -8420 | P29: -6550 | Q29: -7930 | R29: -11764 | S29: -9019 | T29: -11150 | U29: -9707 | V29: -12078 | W29: -8385 | X29: -9003 | Y29: -9147 | Z29: -11703 | AA29: -8248 | AB29: -11846 | AC29: -7452 | AD29: -10889 | AE29: -9183 | AF29: -10106 | AG29: -9473 | AH29: -7049 | AI29: -9820 | AJ29: -9166
G30: moeda | H30: Capex (valor absoluto) [Capital expenditure] memória | J30: memoria | O30: 3885 | P30: 4232 | Q30: 4648 | R30: 6236 | S30: 4237 | T30: 6677 | U30: 5268 | V30: 6417 | W30: 6161 | X30: 4614 | Y30: 5259 | Z30: 6960 | AA30: 3980 | AB30: 4445 | AC30: 4690 | AD30: 6486 | AE30: 3748 | AF30: 5393 | AG30: 4557 | AH30: 5250 | AI30: 3757 | AJ30: 4031
H31: BALANÇO (USD milhões, saldo no fim do trimestre). IFRS: não circulante primeiro. Arrendamentos dentro de PPE e Debt.
A32: 20 | B32: 1 | G32: moeda | H32: Goodwill | J32: fonte | O32: 14086 | P32: 14019 | Q32: 13858 | R32: 14920 | S32: 15200 | T32: 15810 | U32: 15423 | V32: 16039 | W32: 17651 | X32: 17655 | Y32: 17345 | Z32: 16660 | AA32: 16554 | AB32: 16538 | AC32: 16600 | AD32: 16032 | AE32: 16072 | AF32: 16332 | AG32: 16034 | AH32: 15662 | AI32: 15189 | AJ32: 14969
A33: 21 | B33: 1 | G33: moeda | H33: Outros intangíveis [Other intangible assets] | J33: fonte | O33: 8786 | P33: 8443 | Q33: 8486 | R33: 9773 | S33: 9735 | T33: 9730 | U33: 8939 | V33: 9662 | W33: 9751 | X33: 8642 | Y33: 8288 | Z33: 10253 | AA33: 9999 | AB33: 9387 | AC33: 8188 | AD33: 9480 | AE33: 11365 | AF33: 11338 | AG33: 9546 | AH33: 11010 | AI33: 10873 | AJ33: 10449
A34: 18 | B34: 1 | G34: moeda | H34: Imobilizado (inclui direito de uso IFRS 16) [Property, plant and equipment] | J34: fonte | O34: 208298 | P34: 205272 | Q34: 196261 | R34: 194932 | S34: 193301 | T34: 200122 | U34: 193681 | V34: 198642 | W34: 199209 | X34: 197177 | Y34: 197043 | Z34: 194835 | AA34: 191952 | AB34: 189656 | AC34: 191721 | AD34: 185219 | AE34: 183712 | AF34: 186461 | AG34: 183907 | AH34: 185077 | AI34: 185708 | AJ34: 182300
A35: 17 | B35: 1 | G35: moeda | H35: Investimentos em joint ventures e coligadas | J35: fonte | O35: 22537 | P35: 23248 | Q35: 23724 | R35: 23415 | S35: 23289 | T35: 23264 | U35: 24489 | V35: 23864 | W35: 24843 | X35: 24434 | Y35: 24477 | Z35: 24457 | AA35: 25113 | AB35: 25098 | AC35: 25764 | AD35: 23445 | AE35: 24236 | AF35: 23456 | AG35: 23729 | AH35: 27775 | AI35: 27579 | AJ35: 27997
A36: 22 | B36: 1 | G36: moeda | H36: Investimentos em títulos [Investments in securities] | J36: fonte | O36: 3341 | P36: 3554 | Q36: 3662 | R36: 3797 | S36: 3550 | T36: 3507 | U36: 3491 | V36: 3362 | W36: 3357 | X36: 3431 | Y36: 3329 | Z36: 3246 | AA36: 3033 | AB36: 2972 | AC36: 3062 | AD36: 2255 | AE36: 2284 | AF36: 2225 | AG36: 1592 | AH36: 1557 | AI36: 1554 | AJ36: 1479
A37: 14 | B37: 1 | G37: moeda | H37: IR diferido ativo [Deferred tax, não circulante] | J37: fonte | O37: 13871 | P37: 14392 | Q37: 14542 | R37: 12426 | S37: 11420 | T37: 8575 | U37: 7885 | V37: 7815 | W37: 6716 | X37: 6238 | Y37: 5537 | Z37: 6454 | AA37: 6217 | AB37: 5888 | AC37: 6114 | AD37: 6857 | AE37: 6989 | AF37: 7524 | AG37: 8088 | AH37: 8173 | AI37: 7474 | AJ37: 6606
A38: 22 | B38: 1 | G38: moeda | H38: Ativo de benefícios de aposentadoria [Retirement benefits] | J38: fonte | O38: 5845 | P38: 7941 | Q38: 8009 | R38: 8471 | S38: 9548 | T38: 14973 | U38: 13314 | V38: 10200 | W38: 10330 | X38: 10398 | Y38: 9654 | Z38: 9151 | AA38: 9151 | AB38: 9454 | AC38: 10564 | AD38: 10003 | AE38: 10266 | AF38: 10980 | AG38: 5527 | AH38: 5052 | AI38: 5192 | AJ38: 5306
A39: 22 | B39: 1 | G39: moeda | H39: Contas a receber não circulantes [Trade and other receivables] | J39: fonte | O39: 7396 | P39: 7798 | Q39: 7605 | R39: 7065 | S39: 6218 | T39: 5853 | U39: 5841 | V39: 6920 | W39: 6184 | X39: 6031 | Y39: 6049 | Z39: 6298 | AA39: 6548 | AB39: 6808 | AC39: 6883 | AD39: 6018 | AE39: 7269 | AF39: 7315 | AG39: 7472 | AH39: 8252 | AI39: 7294 | AJ39: 8017
A40: 22 | B40: 1 | G40: moeda | H40: Derivativos ativo não circulante | J40: fonte | O40: 1681 | P40: 1508 | Q40: 1052 | R40: 815 | S40: 705 | T40: 839 | U40: 978 | V40: 582 | W40: 540 | X40: 541 | Y40: 524 | Z40: 801 | AA40: 381 | AB40: 348 | AC40: 498 | AD40: 374 | AE40: 400 | AF40: 692 | AG40: 665 | AH40: 619 | AI40: 573 | AJ40: 558
A41: 13 | B41: 1 | G41: moeda | H41: Estoques [Inventories] | J41: fonte | O41: 22680 | P41: 25097 | Q41: 24596 | R41: 25258 | S41: 30008 | T41: 36087 | U41: 34721 | V41: 31894 | W41: 28579 | X41: 26975 | Y41: 30230 | Z41: 26019 | AA41: 26471 | AB41: 26449 | AC41: 24143 | AD41: 23426 | AE41: 22984 | AF41: 23283 | AG41: 22913 | AH41: 22216 | AI41: 28700 | AJ41: 26639
...

Sheet Inputs (2)
A1: =COUNTIF($B$3:$B$1048576,$B$1) -> 1 | B1: =MAX($B$3:$B$1048576) -> 55
D2: 1Q21 | E2: 2Q21 | F2: 3Q21 | G2: 4Q21 | H2: 2021 | I2: 1Q22 | J2: 2Q22 | K2: 3Q22 | L2: 4Q22 | M2: 2022 | N2: 1Q23 | O2: 2Q23 | P2: 3Q23 | Q2: 4Q23 | R2: 2023 | S2: 1Q24 | T2: 2Q24 | U2: 3Q24 | V2: 4Q24 | W2: 2024 | X2: 1Q25 | Y2: 2Q25 | Z2: 3Q25 | AA2: 4Q25 | AB2: 2025 | AC2: 1Q26 | AD2: 2Q26 | AE2: 3Q26 | AF2: 4Q26 | AG2: 2026 | AH2: 1Q20 | AI2: 2Q20 | AJ2: 3Q20 | AK2: 4Q20 | AL2: 2020 | AN2: Sem dado na fonte: 1Q20-4Q20 (databook começa em 1Q21); 3Q26, 4Q26 e 2026 (rotulo em cinza).
B4: 1 | C4: Net Revenues | D4: =IF(ISNA(MATCH(D$2,Inputs!$K$4:$AJ$4,0)),NA(),IF(SUMPRODUCT((Inputs!$A$5:$A$130=$B4)*ISNUMBER(INDEX(Inputs!$K$5:$AJ$130,0,MATCH(D$2,Inputs!$K$4:$AJ$4,0))))+SUMPRODUCT((Inputs!$C$5:$C$130=$B4)*ISNUMBER(INDEX(Inputs!$K$5:$AJ$130,0,MATCH(D$2,Inputs!$K$4:$AJ$4,0))))+SUMPRODUCT((Inputs!$E$5:$E$130=$B4)*ISNUMBER(INDEX(Inputs!$K$5:$AJ$130,0,MATCH(D$2,Inputs!$K$4:$AJ$4,0))))=0,NA(),SUMPRODUCT((Inputs!$A$5:$A$130=$B4)*Inputs!$B$5:$B$130*(((Inputs!$G$5:$G$130="moeda")+(Inputs!$G$5:$G$130="acoes"))*Inputs!$B$1+((Inputs!$G$5:$G$130<>"moeda")*(Inputs!$G$5:$G$130<>"acoes")))*INDEX(Inputs!$K$5:$AJ$130,0,MATCH(D$2,Inputs!$K$4:$AJ$4,0)))+SUMPRODUCT((Inputs!$C$5:$C$130=$B4)*Inputs!$D$5:$D$130*(((Inputs!$G$5:$G$130="moeda")+(Inputs!$G$5:$G$130="acoes"))*Inputs!$B$1+((Inputs!$G$5:$G$130<>"moeda")*(Inputs!$G$5:$G$130<>"acoes")))*INDEX(Inputs!$K$5:$AJ$130,0,MATCH(D$2,Inputs!$K$4:$AJ$4,0)))+SUMPRODUCT((Inputs!$E$5:$E$130=$B4)*Inputs!$F$5:$F$130*(((Inputs!$G$5:$G$130="moeda")+(Inputs!$G$5:$G$130="acoes"))*Inputs!$B$1+((Inputs!$G$5:$G$130<>"moeda")*(Inputs!$G$5:$G$130<>"acoes")))*INDEX(Inputs!$K$5:$AJ$130,0,MATCH(D$2,Inputs!$K$4:$AJ$4,0))))) -> 55665 | E4: =IF(ISNA(MATCH(E$2,Inputs!$K$4:$AJ$4,0)),NA(),IF(SUMPRODUCT((Inputs!$A$5:$A$130=$B4)*ISNUMBER(INDEX(Inputs!$K$5:$AJ$130,0,MATCH(E$2,Inputs!$K$4:$AJ$4,0))))+SUMPRODUCT((Inputs!$C$5:$C$130=$B4)*ISNUMBER(INDEX(Inputs!$K$5:$AJ$130,0,MATCH(E$2,Inputs!$K$4:$AJ$4,0))))+SUMPRODUCT((Inputs!$E$5:$E$130=$B4)*ISNUMBER(INDEX(Inputs!$K$5:$AJ$130,0,MATCH(E$2,Inputs!$K$4:$AJ$4,0))))=0,NA(),SUMPRODUCT((Inputs!$A$5:$A$130=$B4)*Inputs!$B$5:$B$130*(((Inputs!$G$5:$G$130="moeda")+(Inputs!$G$5:$G$130="acoes"))*Inputs!$B$1+((Inputs!$G$5:$G$130<>"moeda")*(Inputs!$G$5:$G$130<>"acoes")))*INDEX(Inputs!$K$5:$AJ$130,0,MATCH(E$2,Inputs!$K$4:$AJ$4,0)))+SUMPRODUCT((Inputs!$C$5:$C$130=$B4)*Inputs!$D$5:$D$130*(((Inputs!$G$5:$G$130="moeda")+(Inputs!$G$5:$G$130="acoes"))*Inputs!$B$1+((Inputs!$G$5:$G$130<>"moeda")*(Inputs!$G$5:$G$130<>"acoes")))*INDEX(Inputs!$K$5:$AJ$130,0,MATCH(E$2,Inputs!$K$4:$AJ$4,0)))+SUMPRODUCT((Inputs!$E$5:$E$130=$B4)*Inputs!$F$5:$F$130*(((Inputs!$G$5:$G$130="moeda")+(Inputs!$G$5:$G$130="acoes"))*Inputs!$B$1+((Inputs!$G$5:$G$130<>"moeda")*(Inputs!$G$5:$G$130<>"acoes")))*INDEX(Inputs!$K$5:$AJ$130,0,MATCH(E$2,Inputs!$K$4:$AJ$4,0))))) -> 60515 | F4: =IF(ISNA(MATCH(F$2,Inputs!$K$4:$AJ$4,0)),NA(),IF(SUMPRODUCT((Inputs!$A$5:$A$130=$B4)*ISNUMBER(INDEX(Inputs!$K$5:$AJ$130,0,MATCH(F$2,Inputs!$K$4:$AJ$4,0))))+SUMPRODUCT((Inputs!$C$5:$C$130=$B4)*ISNUMBER(INDEX(Inputs!$K$5:$AJ$130,0,MATCH(F$2,Inputs!$K$4:$AJ$4,0))))+SUMPRODUCT((Inputs!$E$5:$E$130=$B4)*ISNUMBER(INDEX(Inputs!$K$5:$AJ$130,0,MATCH(F$2,Inputs!$K$4:$AJ$4,0))))=0,NA(),SUMPRODUCT((Inputs!$A$5:$A$130=$B4)*Inputs!$B$5:$B$130*(((Inputs!$G$5:$G$130="moeda")+(Inputs!$G$5:$G$130="acoes"))*Inputs!$B$1+((Inputs!$G$5:$G$130<>"moeda")*(Inputs!$G$5:$G$130<>"acoes")))*INDEX(Inputs!$K$5:$AJ$130,0,MATCH(F$2,Inputs!$K$4:$AJ$4,0)))+SUMPRODUCT((Inputs!$C$5:$C$130=$B4)*Inputs!$D$5:$D$130*(((Inputs!$G$5:$G$130="moeda")+(Inputs!$G$5:$G$130="acoes"))*Inputs!$B$1+((Inputs!$G$5:$G$130<>"moeda")*(Inputs!$G$5:$G$130<>"acoes")))*INDEX(Inputs!$K$5:$AJ$130,0,MATCH(F$2,Inputs!$K$4:$AJ$4,0)))+SUMPRODUCT((Inputs!$E$5:$E$130=$B4)*Inputs!$F$5:$F$130*(((Inputs!$G$5:$G$130="moeda")+(Inputs!$G$5:$G$130="acoes"))*Inputs!$B$1+((Inputs!$G$5:$G$130<>"moeda")*(Inputs!$G$5:$G$130<>"acoes")))*INDEX(Inputs!$K$5:$AJ$130,0,MATCH(F$2,Inputs!$K$4:$AJ$4,0))))) -> 60044 | G4: =IF(ISNA(MATCH(G$2,Inputs!$K$4:$AJ$4,0)),NA(),IF(SUMPRODUCT((Inputs!$A$5:$A$130=$B4)*ISNUMBER(INDEX(Inputs!$K$5:$AJ$130,0,MATCH(G$2,Inputs!$K$4:$AJ$4,0))))+SUMPRODUCT((Inputs!$C$5:$C$130=$B4)*ISNUMBER(INDEX(Inputs!$K$5:$AJ$130,0,MATCH(G$2,Inputs!$K$4:$AJ$4,0))))+SUMPRODUCT((Inputs!$E$5:$E$130=$B4)*ISNUMBER(INDEX(Inputs!$K$5:$AJ$130,0,MATCH(G$2,Inputs!$K$4:$AJ$4,0))))=0,NA(),SUMPRODUCT((Inputs!$A$5:$A$130=$B4)*Inputs!$B$5:$B$130*(((Inputs!$G$5:$G$130="moeda")+(Inputs!$G$5:$G$130="acoes"))*Inputs!$B$1+((Inputs!$G$5:$G$130<>"moeda")*(Inputs!$G$5:$G$130<>"acoes")))*INDEX(Inputs!$K$5:$AJ$130,0,MATCH(G$2,Inputs!$K$4:$AJ$4,0)))+SUMPRODUCT((Inputs!$C$5:$C$130=$B4)*Inputs!$D$5:$D$130*(((Inputs!$G$5:$G$130="moeda")+(Inputs!$G$5:$G$130="acoes"))*Inputs!$B$1+((Inputs!$G$5:$G$130<>"moeda")*(Inputs!$G$5:$G$130<>"acoes")))*INDEX(Inputs!$K$5:$AJ$130,0,MATCH(G$2,Inputs!$K$4:$AJ$4,0)))+SUMPRODUCT((Inputs!$E$5:$E$130=$B4)*Inputs!$F$5:$F$130*(((Inputs!$G$5:$G$130="moeda")+(Inputs!$G$5:$G$130="acoes"))*Inputs!$B$1+((Inputs!$G$5:$G$130<>"moeda")*(Inputs!$G$5:$G$130<>"acoes")))*INDEX(Inputs!$K$5:$AJ$130,0,MATCH(G$2,Inputs!$K$4:$AJ$4,0))))) -> 85280 | H4: =SUM(D4:G4) -> 261504 | I4: =IF(ISNA(MATCH(I$2,Inputs!$K$4:$AJ$4,0)),NA(),IF(SUMPRODUCT((Inputs!$A$5:$A$130=$B4)*ISNUMBER(INDEX(Inputs!$K$5:$AJ$130,0,MATCH(I$2,Inputs!$K$4:$AJ$4,0))))+SUMPRODUCT((Inputs!$C$5:$C$130=$B4)*ISNUMBER(INDEX(Inputs!$K$5:$AJ$130,0,MATCH(I$2,Inputs!$K$4:$AJ$4,0))))+SUMPRODUCT((Inputs!$E$5:$E$130=$B4)*ISNUMBER(INDEX(Inputs!$K$5:$AJ$130,0,MATCH(I$2,Inputs!$K$4:$AJ$4,0))))=0,NA(),SUMPRODUCT((Inputs!$A$5:$A$130=$B4)*Inputs!$B$5:$B$130*(((Inputs!$G$5:$G$130="moeda")+(Inputs!$G$5:$G$130="acoes"))*Inputs!$B$1+((Inputs!$G$5:$G$130<>"moeda")*(Inputs!$G$5:$G$130<>"acoes")))*INDEX(Inputs!$K$5:$AJ$130,0,MATCH(I$2,Inputs!$K$4:$AJ$4,0)))+SUMPRODUCT((Inputs!$C$5:$C$130=$B4)*Inputs!$D$5:$D$130*(((Inputs!$G$5:$G$130="moeda")+(Inputs!$G$5:$G$130="acoes"))*Inputs!$B$1+((Inputs!$G$5:$G$130<>"moeda")*(Inputs!$G$5:$G$130<>"acoes")))*INDEX(Inputs!$K$5:$AJ$130,0,MATCH(I$2,Inputs!$K$4:$AJ$4,0)))+SUMPRODUCT((Inputs!$E$5:$E$130=$B4)*Inputs!$F$5:$F$130*(((Inputs!$G$5:$G$130="moeda")+(Inputs!$G$5:$G$130="acoes"))*Inputs!$B$1+((Inputs!$G$5:$G$130<>"moeda")*(Inputs!$G$5:$G$130<>"acoes")))*INDEX(Inputs!$K$5:$AJ$130,0,MATCH(I$2,Inputs!$K$4:$AJ$4,0))))) -> 84204 | J4: =IF(ISNA(MATCH(J$2,Inputs!$K$4:$AJ$4,0)),NA(),IF(SUMPRODUCT((Inputs!$A$5:$A$130=$B4)*ISNUMBER(INDEX(Inputs!$K$5:$AJ$130,0,MATCH(J$2,Inputs!$K$4:$AJ$4,0))))+SUMPRODUCT((Inputs!$C$5:$C$130=$B4)*ISNUMBER(INDEX(Inputs!$K$5:$AJ$130,0,MATCH(J$2,Inputs!$K$4:$AJ$4,0))))+SUMPRODUCT((Inputs!$E$5:$E$130=$B4)*ISNUMBER(INDEX(Inputs!$K$5:$AJ$130,0,MATCH(J$2,Inputs!$K$4:$AJ$4,0))))=0,NA(),SUMPRODUCT((Inputs!$A$5:$A$130=$B4)*Inputs!$B$5:$B$130*(((Inputs!$G$5:$G$130="moeda")+(Inputs!$G$5:$G$130="acoes"))*Inputs!$B$1+((Inputs!$G$5:$G$130<>"moeda")*(Inputs!$G$5:$G$130<>"acoes")))*INDEX(Inputs!$K$5:$AJ$130,0,MATCH(J$2,Inputs!$K$4:$AJ$4,0)))+SUMPRODUCT((Inputs!$C$5:$C$130=$B4)*Inputs!$D$5:$D$130*(((Inputs!$G$5:$G$130="moeda")+(Inputs!$G$5:$G$130="acoes"))*Inputs!$B$1+((Inputs!$G$5:$G$130<>"moeda")*(Inputs!$G$5:$G$130<>"acoes")))*INDEX(Inputs!$K$5:$AJ$130,0,MATCH(J$2,Inputs!$K$4:$AJ$4,0)))+SUMPRODUCT((Inputs!$E$5:$E$130=$B4)*Inputs!$F$5:$F$130*(((Inputs!$G$5:$G$130="moeda")+(Inputs!$G$5:$G$130="acoes"))*Inputs!$B$1+((Inputs!$G$5:$G$130<>"moeda")*(Inputs!$G$5:$G$130<>"acoes")))*INDEX(Inputs!$K$5:$AJ$130,0,MATCH(J$2,Inputs!$K$4:$AJ$4,0))))) -> 100059 | K4: =IF(ISNA(MATCH(K$2,Inputs!$K$4:$AJ$4,0)),NA(),IF(SUMPRODUCT((Inputs!$A$5:$A$130=$B4)*ISNUMBER(INDEX(Inputs!$K$5:$AJ$130,0,MATCH(K$2,Inputs!$K$4:$AJ$4,0))))+SUMPRODUCT((Inputs!$C$5:$C$130=$B4)*ISNUMBER(INDEX(Inputs!$K$5:$AJ$130,0,MATCH(K$2,Inputs!$K$4:$AJ$4,0))))+SUMPRODUCT((Inputs!$E$5:$E$130=$B4)*ISNUMBER(INDEX(Inputs!$K$5:$AJ$130,0,MATCH(K$2,Inputs!$K$4:$AJ$4,0))))=0,NA(),SUMPRODUCT((Inputs!$A$5:$A$130=$B4)*Inputs!$B$5:$B$130*(((Inputs!$G$5:$G$130="moeda")+(Inputs!$G$5:$G$130="acoes"))*Inputs!$B$1+((Inputs!$G$5:$G$130<>"moeda")*(Inputs!$G$5:$G$130<>"acoes")))*INDEX(Inputs!$K$5:$AJ$130,0,MATCH(K$2,Inputs!$K$4:$AJ$4,0)))+SUMPRODUCT((Inputs!$C$5:$C$130=$B4)*Inputs!$D$5:$D$130*(((Inputs!$G$5:$G$130="moeda")+(Inputs!$G$5:$G$130="acoes"))*Inputs!$B$1+((Inputs!$G$5:$G$130<>"moeda")*(Inputs!$G$5:$G$130<>"acoes")))*INDEX(Inputs!$K$5:$AJ$130,0,MATCH(K$2,Inputs!$K$4:$AJ$4,0)))+SUMPRODUCT((Inputs!$E$5:$E$130=$B4)*Inputs!$F$5:$F$130*(((Inputs!$G$5:$G$130="moeda")+(Inputs!$G$5:$G$130="acoes"))*Inputs!$B$1+((Inputs!$G$5:$G$130<>"moeda")*(Inputs!$G$5:$G$130<>"acoes")))*INDEX(Inputs!$K$5:$AJ$130,0,MATCH(K$2,Inputs!$K$4:$AJ$4,0))))) -> 95749 | L4: =IF(ISNA(MATCH(L$2,Inputs!$K$4:$AJ$4,0)),NA(),IF(SUMPRODUCT((Inputs!$A$5:$A$130=$B4)*ISNUMBER(INDEX(Inputs!$K$5:$AJ$130,0,MATCH(L$2,Inputs!$K$4:$AJ$4,0))))+SUMPRODUCT((Inputs!$C$5:$C$130=$B4)*ISNUMBER(INDEX(Inputs!$K$5:$AJ$130,0,MATCH(L$2,Inputs!$K$4:$AJ$4,0))))+SUMPRODUCT((Inputs!$E$5:$E$130=$B4)*ISNUMBER(INDEX(Inputs!$K$5:$AJ$130,0,MATCH(L$2,Inputs!$K$4:$AJ$4,0))))=0,NA(),SUMPRODUCT((Inputs!$A$5:$A$130=$B4)*Inputs!$B$5:$B$130*(((Inputs!$G$5:$G$130="moeda")+(Inputs!$G$5:$G$130="acoes"))*Inputs!$B$1+((Inputs!$G$5:$G$130<>"moeda")*(Inputs!$G$5:$G$130<>"acoes")))*INDEX(Inputs!$K$5:$AJ$130,0,MATCH(L$2,Inputs!$K$4:$AJ$4,0)))+SUMPRODUCT((Inputs!$C$5:$C$130=$B4)*Inputs!$D$5:$D$130*(((Inputs!$G$5:$G$130="moeda")+(Inputs!$G$5:$G$130="acoes"))*Inputs!$B$1+((Inputs!$G$5:$G$130<>"moeda")*(Inputs!$G$5:$G$130<>"acoes")))*INDEX(Inputs!$K$5:$AJ$130,0,MATCH(L$2,Inputs!$K$4:$AJ$4,0)))+SUMPRODUCT((Inputs!$E$5:$E$130=$B4)*Inputs!$F$5:$F$130*(((Inputs!$G$5:$G$130="moeda")+(Inputs!$G$5:$G$130="acoes"))*Inputs!$B$1+((Inputs!$G$5:$G$130<>"moeda")*(Inputs!$G$5:$G$130<>"acoes")))*INDEX(Inputs!$K$5:$AJ$130,0,MATCH(L$2,Inputs!$K$4:$AJ$4,0))))) -> 101303 | M4: =SUM(I4:L4) -> 381315 | N4: =IF(ISNA(MATCH(N$2,Inputs!$K$4:$AJ$4,0)),NA(),IF(SUMPRODUCT((Inputs!$A$5:$A$130=$B4)*ISNUMBER(INDEX(Inputs!$K$5:$AJ$130,0,MATCH(N$2,Inputs!$K$4:$AJ$4,0))))+SUMPRODUCT((Inputs!$C$5:$C$130=$B4)*ISNUMBER(INDEX(Inputs!$K$5:$AJ$130,0,MATCH(N$2,Inputs!$K$4:$AJ$4,0))))+SUMPRODUCT((Inputs!$E$5:$E$130=$B4)*ISNUMBER(INDEX(Inputs!$K$5:$AJ$130,0,MATCH(N$2,Inputs!$K$4:$AJ$4,0))))=0,NA(),SUMPRODUCT((Inputs!$A$5:$A$130=$B4)*Inputs!$B$5:$B$130*(((Inputs!$G$5:$G$130="moeda")+(Inputs!$G$5:$G$130="acoes"))*Inputs!$B$1+((Inputs!$G$5:$G$130<>"moeda")*(Inputs!$G$5:$G$130<>"acoes")))*INDEX(Inputs!$K$5:$AJ$130,0,MATCH(N$2,Inputs!$K$4:$AJ$4,0)))+SUMPRODUCT((Inputs!$C$5:$C$130=$B4)*Inputs!$D$5:$D$130*(((Inputs!$G$5:$G$130="moeda")+(Inputs!$G$5:$G$130="acoes"))*Inputs!$B$1+((Inputs!$G$5:$G$130<>"moeda")*(Inputs!$G$5:$G$130<>"acoes")))*INDEX(Inputs!$K$5:$AJ$130,0,MATCH(N$2,Inputs!$K$4:$AJ$4,0)))+SUMPRODUCT((Inputs!$E$5:$E$130=$B4)*Inputs!$F$5:$F$130*(((Inputs!$G$5:$G$130="moeda")+(Inputs!$G$5:$G$130="acoes"))*Inputs!$B$1+((Inputs!$G$5:$G$130<>"moeda")*(Inputs!$G$5:$G$130<>"acoes")))*INDEX(Inputs!$K$5:$AJ$130,0,MATCH(N$2,Inputs!$K$4:$AJ$4,0))))) -> 86959 | O4: =IF(ISNA(MATCH(O$2,Inputs!$K$4:$AJ$4,0)),NA(),IF(SUMPRODUCT((Inputs!$A$5:$A$130=$B4)*ISNUMBER(INDEX(Inputs!$K$5:$AJ$130,0,MATCH(O$2,Inputs!$K$4:$AJ$4,0))))+SUMPRODUCT((Inputs!$C$5:$C$130=$B4)*ISNUMBER(INDEX(Inputs!$K$5:$AJ$130,0,MATCH(O$2,Inputs!$K$4:$AJ$4,0))))+SUMPRODUCT((Inputs!$E$5:$E$130=$B4)*ISNUMBER(INDEX(Inputs!$K$5:$AJ$130,0,MATCH(O$2,Inputs!$K$4:$AJ$4,0))))=0,NA(),SUMPRODUCT((Inputs!$A$5:$A$130=$B4)*Inputs!$B$5:$B$130*(((Inputs!$G$5:$G$130="moeda")+(Inputs!$G$5:$G$130="acoes"))*Inputs!$B$1+((Inputs!$G$5:$G$130<>"moeda")*(Inputs!$G$5:$G$130<>"acoes")))*INDEX(Inputs!$K$5:$AJ$130,0,MATCH(O$2,Inputs!$K$4:$AJ$4,0)))+SUMPRODUCT((Inputs!$C$5:$C$130=$B4)*Inputs!$D$5:$D$130*(((Inputs!$G$5:$G$130="moeda")+(Inputs!$G$5:$G$130="acoes"))*Inputs!$B$1+((Inputs!$G$5:$G$130<>"moeda")*(Inputs!$G$5:$G$130<>"acoes")))*INDEX(Inputs!$K$5:$AJ$130,0,MATCH(O$2,Inputs!$K$4:$AJ$4,0)))+SUMPRODUCT((Inputs!$E$5:$E$130=$B4)*Inputs!$F$5:$F$130*(((Inputs!$G$5:$G$130="moeda")+(Inputs!$G$5:$G$130="acoes"))*Inputs!$B$1+((Inputs!$G$5:$G$130<>"moeda")*(Inputs!$G$5:$G$130<>"acoes")))*INDEX(Inputs!$K$5:$AJ$130,0,MATCH(O$2,Inputs!$K$4:$AJ$4,0))))) -> 74578 | P4: =IF(ISNA(MATCH(P$2,Inputs!$K$4:$AJ$4,0)),NA(),IF(SUMPRODUCT((Inputs!$A$5:$A$130=$B4)*ISNUMBER(INDEX(Inputs!$K$5:$AJ$130,0,MATCH(P$2,Inputs!$K$4:$AJ$4,0))))+SUMPRODUCT((Inputs!$C$5:$C$130=$B4)*ISNUMBER(INDEX(Inputs!$K$5:$AJ$130,0,MATCH(P$2,Inputs!$K$4:$AJ$4,0))))+SUMPRODUCT((Inputs!$E$5:$E$130=$B4)*ISNUMBER(INDEX(Inputs!$K$5:$AJ$130,0,MATCH(P$2,Inputs!$K$4:$AJ$4,0))))=0,NA(),SUMPRODUCT((Inputs!$A$5:$A$130=$B4)*Inputs!$B$5:$B$130*(((Inputs!$G$5:$G$130="moeda")+(Inputs!$G$5:$G$130="acoes"))*Inputs!$B$1+((Inputs!$G$5:$G$130<>"moeda")*(Inputs!$G$5:$G$130<>"acoes")))*INDEX(Inputs!$K$5:$AJ$130,0,MATCH(P$2,Inputs!$K$4:$AJ$4,0)))+SUMPRODUCT((Inputs!$C$5:$C$130=$B4)*Inputs!$D$5:$D$130*(((Inputs!$G$5:$G$130="moeda")+(Inputs!$G$5:$G$130="acoes"))*Inputs!$B$1+((Inputs!$G$5:$G$130<>"moeda")*(Inputs!$G$5:$G$130<>"acoes")))*INDEX(Inputs!$K$5:$AJ$130,0,MATCH(P$2,Inputs!$K$4:$AJ$4,0)))+SUMPRODUCT((Inputs!$E$5:$E$130=$B4)*Inputs!$F$5:$F$130*(((Inputs!$G$5:$G$130="moeda")+(Inputs!$G$5:$G$130="acoes"))*Inputs!$B$1+((Inputs!$G$5:$G$130<>"moeda")*(Inputs!$G$5:$G$130<>"acoes")))*INDEX(Inputs!$K$5:$AJ$130,0,MATCH(P$2,Inputs!$K$4:$AJ$4,0))))) -> 76350 | Q4: =IF(ISNA(MATCH(Q$2,Inputs!$K$4:$AJ$4,0)),NA(),IF(SUMPRODUCT((Inputs!$A$5:$A$130=$B4)*ISNUMBER(INDEX(Inputs!$K$5:$AJ$130,0,MATCH(Q$2,Inputs!$K$4:$AJ$4,0))))+SUMPRODUCT((Inputs!$C$5:$C$130=$B4)*ISNUMBER(INDEX(Inputs!$K$5:$AJ$130,0,MATCH(Q$2,Inputs!$K$4:$AJ$4,0))))+SUMPRODUCT((Inputs!$E$5:$E$130=$B4)*ISNUMBER(INDEX(Inputs!$K$5:$AJ$130,0,MATCH(Q$2,Inputs!$K$4:$AJ$4,0))))=0,NA(),SUMPRODUCT((Inputs!$A$5:$A$130=$B4)*Inputs!$B$5:$B$130*(((Inputs!$G$5:$G$130="moeda")+(Inputs!$G$5:$G$130="acoes"))*Inputs!$B$1+((Inputs!$G$5:$G$130<>"moeda")*(Inputs!$G$5:$G$130<>"acoes")))*INDEX(Inputs!$K$5:$AJ$130,0,MATCH(Q$2,Inputs!$K$4:$AJ$4,0)))+SUMPRODUCT((Inputs!$C$5:$C$130=$B4)*Inputs!$D$5:$D$130*(((Inputs!$G$5:$G$130="moeda")+(Inputs!$G$5:$G$130="acoes"))*Inputs!$B$1+((Inputs!$G$5:$G$130<>"moeda")*(Inputs!$G$5:$G$130<>"acoes")))*INDEX(Inputs!$K$5:$AJ$130,0,MATCH(Q$2,Inputs!$K$4:$AJ$4,0)))+SUMPRODUCT((Inputs!$E$5:$E$130=$B4)*Inputs!$F$5:$F$130*(((Inputs!$G$5:$G$130="moeda")+(Inputs!$G$5:$G$130="acoes"))*Inputs!$B$1+((Inputs!$G$5:$G$130<>"moeda")*(Inputs!$G$5:$G$130<>"acoes")))*INDEX(Inputs!$K$5:$AJ$130,0,MATCH(Q$2,Inputs!$K$4:$AJ$4,0))))) -> 78732 | R4: =SUM(N4:Q4) -> 316619 | S4: =IF(ISNA(MATCH(S$2,Inputs!$K$4:$AJ$4,0)),NA(),IF(SUMPRODUCT((Inputs!$A$5:$A$130=$B4)*ISNUMBER(INDEX(Inputs!$K$5:$AJ$130,0,MATCH(S$2,Inputs!$K$4:$AJ$4,0))))+SUMPRODUCT((Inputs!$C$5:$C$130=$B4)*ISNUMBER(INDEX(Inputs!$K$5:$AJ$130,0,MATCH(S$2,Inputs!$K$4:$AJ$4,0))))+SUMPRODUCT((Inputs!$E$5:$E$130=$B4)*ISNUMBER(INDEX(Inputs!$K$5:$AJ$130,0,MATCH(S$2,Inputs!$K$4:$AJ$4,0))))=0,NA(),SUMPRODUCT((Inputs!$A$5:$A$130=$B4)*Inputs!$B$5:$B$130*(((Inputs!$G$5:$G$130="moeda")+(Inputs!$G$5:$G$130="acoes"))*Inputs!$B$1+((Inputs!$G$5:$G$130<>"moeda")*(Inputs!$G$5:$G$130<>"acoes")))*INDEX(Inputs!$K$5:$AJ$130,0,MATCH(S$2,Inputs!$K$4:$AJ$4,0)))+SUMPRODUCT((Inputs!$C$5:$C$130=$B4)*Inputs!$D$5:$D$130*(((Inputs!$G$5:$G$130="moeda")+(Inputs!$G$5:$G$130="acoes"))*Inputs!$B$1+((Inputs!$G$5:$G$130<>"moeda")*(Inputs!$G$5:$G$130<>"acoes")))*INDEX(Inputs!$K$5:$AJ$130,0,MATCH(S$2,Inputs!$K$4:$AJ$4,0)))+SUMPRODUCT((Inputs!$E$5:$E$130=$B4)*Inputs!$F$5:$F$130*(((Inputs!$G$5:$G$130="moeda")+(Inputs!$G$5:$G$130="acoes"))*Inputs!$B$1+((Inputs!$G$5:$G$130<>"moeda")*(Inputs!$G$5:$G$130<>"acoes")))*INDEX(Inputs!$K$5:$AJ$130,0,MATCH(S$2,Inputs!$K$4:$AJ$4,0))))) -> 72478 | T4: =IF(ISNA(MATCH(T$2,Inputs!$K$4:$AJ$4,0)),NA(),IF(SUMPRODUCT((Inputs!$A$5:$A$130=$B4)*ISNUMBER(INDEX(Inputs!$K$5:$AJ$130,0,MATCH(T$2,Inputs!$K$4:$AJ$4,0))))+SUMPRODUCT((Inputs!$C$5:$C$130=$B4)*ISNUMBER(INDEX(Inputs!$K$5:$AJ$130,0,MATCH(T$2,Inputs!$K$4:$AJ$4,0))))+SUMPRODUCT((Inputs!$E$5:$E$130=$B4)*ISNUMBER(INDEX(Inputs!$K$5:$AJ$130,0,MATCH(T$2,Inputs!$K$4:$AJ$4,0))))=0,NA(),SUMPRODUCT((Inputs!$A$5:$A$130=$B4)*Inputs!$B$5:$B$130*(((Inputs!$G$5:$G$130="moeda")+(Inputs!$G$5:$G$130="acoes"))*Inputs!$B$1+((Inputs!$G$5:$G$130<>"moeda")*(Inputs!$G$5:$G$130<>"acoes")))*INDEX(Inputs!$K$5:$AJ$130,0,MATCH(T$2,Inputs!$K$4:$AJ$4,0)))+SUMPRODUCT((Inputs!$C$5:$C$130=$B4)*Inputs!$D$5:$D$130*(((Inputs!$G$5:$G$130="moeda")+(Inputs!$G$5:$G$130="acoes"))*Inputs!$B$1+((Inputs!$G$5:$G$130<>"moeda")*(Inputs!$G$5:$G$130<>"acoes")))*INDEX(Inputs!$K$5:$AJ$130,0,MATCH(T$2,Inputs!$K$4:$AJ$4,0)))+SUMPRODUCT((Inputs!$E$5:$E$130=$B4)*Inputs!$F$5:$F$130*(((Inputs!$G$5:$G$130="moeda")+(Inputs!$G$5:$G$130="acoes"))*Inputs!$B$1+((Inputs!$G$5:$G$130<>"moeda")*(Inputs!$G$5:$G$130<>"acoes")))*INDEX(Inputs!$K$5:$AJ$130,0,MATCH(T$2,Inputs!$K$4:$AJ$4,0))))) -> 74463 | U4: =IF(ISNA(MATCH(U$2,Inputs!$K$4:$AJ$4,0)),NA(),IF(SUMPRODUCT((Inputs!$A$5:$A$130=$B4)*ISNUMBER(INDEX(Inputs!$K$5:$AJ$130,0,MATCH(U$2,Inputs!$K$4:$AJ$4,0))))+SUMPRODUCT((Inputs!$C$5:$C$130=$B4)*ISNUMBER(INDEX(Inputs!$K$5:$AJ$130,0,MATCH(U$2,Inputs!$K$4:$AJ$4,0))))+SUMPRODUCT((Inputs!$E$5:$E$130=$B4)*ISNUMBER(INDEX(Inputs!$K$5:$AJ$130,0,MATCH(U$2,Inputs!$K$4:$AJ$4,0))))=0,NA(),SUMPRODUCT((Inputs!$A$5:$A$130=$B4)*Inputs!$B$5:$B$130*(((Inputs!$G$5:$G$130="moeda")+(Inputs!$G$5:$G$130="acoes"))*Inputs!$B$1+((Inputs!$G$5:$G$130<>"moeda")*(Inputs!$G$5:$G$130<>"acoes")))*INDEX(Inputs!$K$5:$AJ$130,0,MATCH(U$2,Inputs!$K$4:$AJ$4,0)))+SUMPRODUCT((Inputs!$C$5:$C$130=$B4)*Inputs!$D$5:$D$130*(((Inputs!$G$5:$G$130="moeda")+(Inputs!$G$5:$G$130="acoes"))*Inputs!$B$1+((Inputs!$G$5:$G$130<>"moeda")*(Inputs!$G$5:$G$130<>"acoes")))*INDEX(Inputs!$K$5:$AJ$130,0,MATCH(U$2,Inputs!$K$4:$AJ$4,0)))+SUMPRODUCT((Inputs!$E$5:$E$130=$B4)*Inputs!$F$5:$F$130*(((Inputs!$G$5:$G$130="moeda")+(Inputs!$G$5:$G$130="acoes"))*Inputs!$B$1+((Inputs!$G$5:$G$130<>"moeda")*(Inputs!$G$5:$G$130<>"acoes")))*INDEX(Inputs!$K$5:$AJ$130,0,MATCH(U$2,Inputs!$K$4:$AJ$4,0))))) -> 71089 | V4: =IF(ISNA(MATCH(V$2,Inputs!$K$4:$AJ$4,0)),NA(),IF(SUMPRODUCT((Inputs!$A$5:$A$130=$B4)*ISNUMBER(INDEX(Inputs!$K$5:$AJ$130,0,MATCH(V$2,Inputs!$K$4:$AJ$4,0))))+SUMPRODUCT((Inputs!$C$5:$C$130=$B4)*ISNUMBER(INDEX(Inputs!$K$5:$AJ$130,0,MATCH(V$2,Inputs!$K$4:$AJ$4,0))))+SUMPRODUCT((Inputs!$E$5:$E$130=$B4)*ISNUMBER(INDEX(Inputs!$K$5:$AJ$130,0,MATCH(V$2,Inputs!$K$4:$AJ$4,0))))=0,NA(),SUMPRODUCT((Inputs!$A$5:$A$130=$B4)*Inputs!$B$5:$B$130*(((Inputs!$G$5:$G$130="moeda")+(Inputs!$G$5:$G$130="acoes"))*Inputs!$B$1+((Inputs!$G$5:$G$130<>"moeda")*(Inputs!$G$5:$G$130<>"acoes")))*INDEX(Inputs!$K$5:$AJ$130,0,MATCH(V$2,Inputs!$K$4:$AJ$4,0)))+SUMPRODUCT((Inputs!$C$5:$C$130=$B4)*Inputs!$D$5:$D$130*(((Inputs!$G$5:$G$130="moeda")+(Inputs!$G$5:$G$130="acoes"))*Inputs!$B$1+((Inputs!$G$5:$G$130<>"moeda")*(Inputs!$G$5:$G$130<>"acoes")))*INDEX(Inputs!$K$5:$AJ$130,0,MATCH(V$2,Inputs!$K$4:$AJ$4,0)))+SUMPRODUCT((Inputs!$E$5:$E$130=$B4)*Inputs!$F$5:$F$130*(((Inputs!$G$5:$G$130="moeda")+(Inputs!$G$5:$G$130="acoes"))*Inputs!$B$1+((Inputs!$G$5:$G$130<>"moeda")*(Inputs!$G$5:$G$130<>"acoes")))*INDEX(Inputs!$K$5:$AJ$130,0,MATCH(V$2,Inputs!$K$4:$AJ$4,0))))) -> 66281 | W4: =SUM(S4:V4) -> 284311 | X4: =IF(ISNA(MATCH(X$2,Inputs!$K$4:$AJ$4,0)),NA(),IF(SUMPRODUCT((Inputs!$A$5:$A$130=$B4)*ISNUMBER(INDEX(Inputs!$K$5:$AJ$130,0,MATCH(X$2,Inputs!$K$4:$AJ$4,0))))+SUMPRODUCT((Inputs!$C$5:$C$130=$B4)*ISNUMBER(INDEX(Inputs!$K$5:$AJ$130,0,MATCH(X$2,Inputs!$K$4:$AJ$4,0))))+SUMPRODUCT((Inputs!$E$5:$E$130=$B4)*ISNUMBER(INDEX(Inputs!$K$5:$AJ$130,0,MATCH(X$2,Inputs!$K$4:$AJ$4,0))))=0,NA(),SUMPRODUCT((Inputs!$A$5:$A$130=$B4)*Inputs!$B$5:$B$130*(((Inputs!$G$5:$G$130="moeda")+(Inputs!$G$5:$G$130="acoes"))*Inputs!$B$1+((Inputs!$G$5:$G$130<>"moeda")*(Inputs!$G$5:$G$130<>"acoes")))*INDEX(Inputs!$K$5:$AJ$130,0,MATCH(X$2,Inputs!$K$4:$AJ$4,0)))+SUMPRODUCT((Inputs!$C$5:$C$130=$B4)*Inputs!$D$5:$D$130*(((Inputs!$G$5:$G$130="moeda")+(Inputs!$G$5:$G$130="acoes"))*Inputs!$B$1+((Inputs!$G$5:$G$130<>"moeda")*(Inputs!$G$5:$G$130<>"acoes")))*INDEX(Inputs!$K$5:$AJ$130,0,MATCH(X$2,Inputs!$K$4:$AJ$4,0)))+SUMPRODUCT((Inputs!$E$5:$E$130=$B4)*Inputs!$F$5:$F$130*(((Inputs!$G$5:$G$130="moeda")+(Inputs!$G$5:$G$130="acoes"))*Inputs!$B$1+((Inputs!$G$5:$G$130<>"moeda")*(Inputs!$G$5:$G$130<>"acoes")))*INDEX(Inputs!$K$5:$AJ$130,0,MATCH(X$2,Inputs!$K$4:$AJ$4,0))))) -> 69234 | Y4: =IF(ISNA(MATCH(Y$2,Inputs!$K$4:$AJ$4,0)),NA(),IF(SUMPRODUCT((Inputs!$A$5:$A$130=$B4)*ISNUMBER(INDEX(Inputs!$K$5:$AJ$130,0,MATCH(Y$2,Inputs!$K$4:$AJ$4,0))))+SUMPRODUCT((Inputs!$C$5:$C$130=$B4)*ISNUMBER(INDEX(Inputs!$K$5:$AJ$130,0,MATCH(Y$2,Inputs!$K$4:$AJ$4,0))))+SUMPRODUCT((Inputs!$E$5:$E$130=$B4)*ISNUMBER(INDEX(Inputs!$K$5:$AJ$130,0,MATCH(Y$2,Inputs!$K$4:$AJ$4,0))))=0,NA(),SUMPRODUCT((Inputs!$A$5:$A$130=$B4)*Inputs!$B$5:$B$130*(((Inputs!$G$5:$G$130="moeda")+(Inputs!$G$5:$G$130="acoes"))*Inputs!$B$1+((Inputs!$G$5:$G$130<>"moeda")*(Inputs!$G$5:$G$130<>"acoes")))*INDEX(Inputs!$K$5:$AJ$130,0,MATCH(Y$2,Inputs!$K$4:$AJ$4,0)))+SUMPRODUCT((Inputs!$C$5:$C$130=$B4)*Inputs!$D$5:$D$130*(((Inputs!$G$5:$G$130="moeda")+(Inputs!$G$5:$G$130="acoes"))*Inputs!$B$1+((Inputs!$G$5:$G$130<>"moeda")*(Inputs!$G$5:$G$130<>"acoes")))*INDEX(Inputs!$K$5:$AJ$130,0,MATCH(Y$2,Inputs!$K$4:$AJ$4,0)))+SUMPRODUCT((Inputs!$E$5:$E$130=$B4)*Inputs!$F$5:$F$130*(((Inputs!$G$5:$G$130="moeda")+(Inputs!$G$5:$G$130="acoes"))*Inputs!$B$1+((Inputs!$G$5:$G$130<>"moeda")*(Inputs!$G$5:$G$130<>"acoes")))*INDEX(Inputs!$K$5:$AJ$130,0,MATCH(Y$2,Inputs!$K$4:$AJ$4,0))))) -> 65406 | Z4: =IF(ISNA(MATCH(Z$2,Inputs!$K$4:$AJ$4,0)),NA(),IF(SUMPRODUCT((Inputs!$A$5:$A$130=$B4)*ISNUMBER(INDEX(Inputs!$K$5:$AJ$130,0,MATCH(Z$2,Inputs!$K$4:$AJ$4,0))))+SUMPRODUCT((Inputs!$C$5:$C$130=$B4)*ISNUMBER(INDEX(Inputs!$K$5:$AJ$130,0,MATCH(Z$2,Inputs!$K$4:$AJ$4,0))))+SUMPRODUCT((Inputs!$E$5:$E$130=$B4)*ISNUMBER(INDEX(Inputs!$K$5:$AJ$130,0,MATCH(Z$2,Inputs!$K$4:$AJ$4,0))))=0,NA(),SUMPRODUCT((Inputs!$A$5:$A$130=$B4)*Inputs!$B$5:$B$130*(((Inputs!$G$5:$G$130="moeda")+(Inputs!$G$5:$G$130="acoes"))*Inputs!$B$1+((Inputs!$G$5:$G$130<>"moeda")*(Inputs!$G$5:$G$130<>"acoes")))*INDEX(Inputs!$K$5:$AJ$130,0,MATCH(Z$2,Inputs!$K$4:$AJ$4,0)))+SUMPRODUCT((Inputs!$C$5:$C$130=$B4)*Inputs!$D$5:$D$130*(((Inputs!$G$5:$G$130="moeda")+(Inputs!$G$5:$G$130="acoes"))*Inputs!$B$1+((Inputs!$G$5:$G$130<>"moeda")*(Inputs!$G$5:$G$130<>"acoes")))*INDEX(Inputs!$K$5:$AJ$130,0,MATCH(Z$2,Inputs!$K$4:$AJ$4,0)))+SUMPRODUCT((Inputs!$E$5:$E$130=$B4)*Inputs!$F$5:$F$130*(((Inputs!$G$5:$G$130="moeda")+(Inputs!$G$5:$G$130="acoes"))*Inputs!$B$1+((Inputs!$G$5:$G$130<>"moeda")*(Inputs!$G$5:$G$130<>"acoes")))*INDEX(Inputs!$K$5:$AJ$130,0,MATCH(Z$2,Inputs!$K$4:$AJ$4,0))))) -> 68153 | AA4: =IF(ISNA(MATCH(AA$2,Inputs!$K$4:$AJ$4,0)),NA(),IF(SUMPRODUCT((Inputs!$A$5:$A$130=$B4)*ISNUMBER(INDEX(Inputs!$K$5:$AJ$130,0,MATCH(AA$2,Inputs!$K$4:$AJ$4,0))))+SUMPRODUCT((Inputs!$C$5:$C$130=$B4)*ISNUMBER(INDEX(Inputs!$K$5:$AJ$130,0,MATCH(AA$2,Inputs!$K$4:$AJ$4,0))))+SUMPRODUCT((Inputs!$E$5:$E$130=$B4)*ISNUMBER(INDEX(Inputs!$K$5:$AJ$130,0,MATCH(AA$2,Inputs!$K$4:$AJ$4,0))))=0,NA(),SUMPRODUCT((Inputs!$A$5:$A$130=$B4)*Inputs!$B$5:$B$130*(((Inputs!$G$5:$G$130="moeda")+(Inputs!$G$5:$G$130="acoes"))*Inputs!$B$1+((Inputs!$G$5:$G$130<>"moeda")*(Inputs!$G$5:$G$130<>"acoes")))*INDEX(Inputs!$K$5:$AJ$130,0,MATCH(AA$2,Inputs!$K$4:$AJ$4,0)))+SUMPRODUCT((Inputs!$C$5:$C$130=$B4)*Inputs!$D$5:$D$130*(((Inputs!$G$5:$G$130="moeda")+(Inputs!$G$5:$G$130="acoes"))*Inputs!$B$1+((Inputs!$G$5:$G$130<>"moeda")*(Inputs!$G$5:$G$130<>"acoes")))*INDEX(Inputs!$K$5:$AJ$130,0,MATCH(AA$2,Inputs!$K$4:$AJ$4,0)))+SUMPRODUCT((Inputs!$E$5:$E$130=$B4)*Inputs!$F$5:$F$130*(((Inputs!$G$5:$G$130="moeda")+(Inputs!$G$5:$G$130="acoes"))*Inputs!$B$1+((Inputs!$G$5:$G$130<>"moeda")*(Inputs!$G$5:$G$130<>"acoes")))*INDEX(Inputs!$K$5:$AJ$130,0,MATCH(AA$2,Inputs!$K$4:$AJ$4,0))))) -> 64093 | AB4: =SUM(X4:AA4) -> 266886 | AC4: =IF(ISNA(MATCH(AC$2,Inputs!$K$4:$AJ$4,0)),NA(),IF(SUMPRODUCT((Inputs!$A$5:$A$130=$B4)*ISNUMBER(INDEX(Inputs!$K$5:$AJ$130,0,MATCH(AC$2,Inputs!$K$4:$AJ$4,0))))+SUMPRODUCT((Inputs!$C$5:$C$130=$B4)*ISNUMBER(INDEX(Inputs!$K$5:$AJ$130,0,MATCH(AC$2,Inputs!$K$4:$AJ$4,0))))+SUMPRODUCT((Inputs!$E$5:$E$130=$B4)*ISNUMBER(INDEX(Inputs!$K$5:$AJ$130,0,MATCH(AC$2,Inputs!$K$4:$AJ$4,0))))=0,NA(),SUMPRODUCT((Inputs!$A$5:$A$130=$B4)*Inputs!$B$5:$B$130*(((Inputs!$G$5:$G$130="moeda")+(Inputs!$G$5:$G$130="acoes"))*Inputs!$B$1+((Inputs!$G$5:$G$130<>"moeda")*(Inputs!$G$5:$G$130<>"acoes")))*INDEX(Inputs!$K$5:$AJ$130,0,MATCH(AC$2,Inputs!$K$4:$AJ$4,0)))+SUMPRODUCT((Inputs!$C$5:$C$130=$B4)*Inputs!$D$5:$D$130*(((Inputs!$G$5:$G$130="moeda")+(Inputs!$G$5:$G$130="acoes"))*Inputs!$B$1+((Inputs!$G$5:$G$130<>"moeda")*(Inputs!$G$5:$G$130<>"acoes")))*INDEX(Inputs!$K$5:$AJ$130,0,MATCH(AC$2,Inputs!$K$4:$AJ$4,0)))+SUMPRODUCT((Inputs!$E$5:$E$130=$B4)*Inputs!$F$5:$F$130*(((Inputs!$G$5:$G$130="moeda")+(Inputs!$G$5:$G$130="acoes"))*Inputs!$B$1+((Inputs!$G$5:$G$130<>"moeda")*(Inputs!$G$5:$G$130<>"acoes")))*INDEX(Inputs!$K$5:$AJ$130,0,MATCH(AC$2,Inputs!$K$4:$AJ$4,0))))) -> 69691 | AD4: =IF(ISNA(MATCH(AD$2,Inputs!$K$4:$AJ$4,0)),NA(),IF(SUMPRODUCT((Inputs!$A$5:$A$130=$B4)*ISNUMBER(INDEX(Inputs!$K$5:$AJ$130,0,MATCH(AD$2,Inputs!$K$4:$AJ$4,0))))+SUMPRODUCT((Inputs!$C$5:$C$130=$B4)*ISNUMBER(INDEX(Inputs!$K$5:$AJ$130,0,MATCH(AD$2,Inputs!$K$4:$AJ$4,0))))+SUMPRODUCT((Inputs!$E$5:$E$130=$B4)*ISNUMBER(INDEX(Inputs!$K$5:$AJ$130,0,MATCH(AD$2,Inputs!$K$4:$AJ$4,0))))=0,NA(),SUMPRODUCT((Inputs!$A$5:$A$130=$B4)*Inputs!$B$5:$B$130*(((Inputs!$G$5:$G$130="moeda")+(Inputs!$G$5:$G$130="acoes"))*Inputs!$B$1+((Inputs!$G$5:$G$130<>"moeda")*(Inputs!$G$5:$G$130<>"acoes")))*INDEX(Inputs!$K$5:$AJ$130,0,MATCH(AD$2,Inputs!$K$4:$AJ$4,0)))+SUMPRODUCT((Inputs!$C$5:$C$130=$B4)*Inputs!$D$5:$D$130*(((Inputs!$G$5:$G$130="moeda")+(Inputs!$G$5:$G$130="acoes"))*Inputs!$B$1+((Inputs!$G$5:$G$130<>"moeda")*(Inputs!$G$5:$G$130<>"acoes")))*INDEX(Inputs!$K$5:$AJ$130,0,MATCH(AD$2,Inputs!$K$4:$AJ$4,0)))+SUMPRODUCT((Inputs!$E$5:$E$130=$B4)*Inputs!$F$5:$F$130*(((Inputs!$G$5:$G$130="moeda")+(Inputs!$G$5:$G$130="acoes"))*Inputs!$B$1+((Inputs!$G$5:$G$130<>"moeda")*(Inputs!$G$5:$G$130<>"acoes")))*INDEX(Inputs!$K$5:$AJ$130,0,MATCH(AD$2,Inputs!$K$4:$AJ$4,0))))) -> 94664 | AE4: =IF(ISNA(MATCH(AE$2,Inputs!$K$4:$AJ$4,0)),NA(),IF(SUMPRODUCT((Inputs!$A$5:$A$130=$B4)*ISNUMBER(INDEX(Inputs!$K$5:$AJ$130,0,MATCH(AE$2,Inputs!$K$4:$AJ$4,0))))+SUMPRODUCT((Inputs!$C$5:$C$130=$B4)*ISNUMBER(INDEX(Inputs!$K$5:$AJ$130,0,MATCH(AE$2,Inputs!$K$4:$AJ$4,0))))+SUMPRODUCT((Inputs!$E$5:$E$130=$B4)*ISNUMBER(INDEX(Inputs!$K$5:$AJ$130,0,MATCH(AE$2,Inputs!$K$4:$AJ$4,0))))=0,NA(),SUMPRODUCT((Inputs!$A$5:$A$130=$B4)*Inputs!$B$5:$B$130*(((Inputs!$G$5:$G$130="moeda")+(Inputs!$G$5:$G$130="acoes"))*Inputs!$B$1+((Inputs!$G$5:$G$130<>"moeda")*(Inputs!$G$5:$G$130<>"acoes")))*INDEX(Inputs!$K$5:$AJ$130,0,MATCH(AE$2,Inputs!$K$4:$AJ$4,0)))+SUMPRODUCT((Inputs!$C$5:$C$130=$B4)*Inputs!$D$5:$D$130*(((Inputs!$G$5:$G$130="moeda")+(Inputs!$G$5:$G$130="acoes"))*Inputs!$B$1+((Inputs!$G$5:$G$130<>"moeda")*(Inputs!$G$5:$G$130<>"acoes")))*INDEX(Inputs!$K$5:$AJ$130,0,MATCH(AE$2,Inputs!$K$4:$AJ$4,0)))+SUMPRODUCT((Inputs!$E$5:$E$130=$B4)*Inputs!$F$5:$F$130*(((Inputs!$G$5:$G$130="moeda")+(Inputs!$G$5:$G$130="acoes"))*Inputs!$B$1+((Inputs!$G$5:$G$130<>"moeda")*(Inputs!$G$5:$G$130<>"acoes")))*INDEX(Inputs!$K$5:$AJ$130,0,MATCH(AE$2,Inputs!$K$4:$AJ$4,0))))) -> #N/A | AF4: =IF(ISNA(MATCH(AF$2,Inputs!$K$4:$AJ$4,0)),NA(),IF(SUMPRODUCT((Inputs!$A$5:$A$130=$B4)*ISNUMBER(INDEX(Inputs!$K$5:$AJ$130,0,MATCH(AF$2,Inputs!$K$4:$AJ$4,0))))+SUMPRODUCT((Inputs!$C$5:$C$130=$B4)*ISNUMBER(INDEX(Inputs!$K$5:$AJ$130,0,MATCH(AF$2,Inputs!$K$4:$AJ$4,0))))+SUMPRODUCT((Inputs!$E$5:$E$130=$B4)*ISNUMBER(INDEX(Inputs!$K$5:$AJ$130,0,MATCH(AF$2,Inputs!$K$4:$AJ$4,0))))=0,NA(),SUMPRODUCT((Inputs!$A$5:$A$130=$B4)*Inputs!$B$5:$B$130*(((Inputs!$G$5:$G$130="moeda")+(Inputs!$G$5:$G$130="acoes"))*Inputs!$B$1+((Inputs!$G$5:$G$130<>"moeda")*(Inputs!$G$5:$G$130<>"acoes")))*INDEX(Inputs!$K$5:$AJ$130,0,MATCH(AF$2,Inputs!$K$4:$AJ$4,0)))+SUMPRODUCT((Inputs!$C$5:$C$130=$B4)*Inputs!$D$5:$D$130*(((Inputs!$G$5:$G$130="moeda")+(Inputs!$G$5:$G$130="acoes"))*Inputs!$B$1+((Inputs!$G$5:$G$130<>"moeda")*(Inputs!$G$5:$G$130<>"acoes")))*INDEX(Inputs!$K$5:$AJ$130,0,MATCH(AF$2,Inputs!$K$4:$AJ$4,0)))+SUMPRODUCT((Inputs!$E$5:$E$130=$B4)*Inputs!$F$5:$F$130*(((Inputs!$G$5:$G$130="moeda")+(Inputs!$G$5:$G$130="acoes"))*Inputs!$B$1+((Inputs!$G$5:$G$130<>"moeda")*(Inputs!$G$5:$G$130<>"acoes")))*INDEX(Inputs!$K$5:$AJ$130,0,MATCH(AF$2,Inputs!$K$4:$AJ$4,0))))) -> #N/A | AG4: =SUM(AC4:AF4) -> #N/A | AH4: =IF(ISNA(MATCH(AH$2,Inputs!$K$4:$AJ$4,0)),NA(),IF(SUMPRODUCT((Inputs!$A$5:$A$130=$B4)*ISNUMBER(INDEX(Inputs!$K$5:$AJ$130,0,MATCH(AH$2,Inputs!$K$4:$AJ$4,0))))+SUMPRODUCT((Inputs!$C$5:$C$130=$B4)*ISNUMBER(INDEX(Inputs!$K$5:$AJ$130,0,MATCH(AH$2,Inputs!$K$4:$AJ$4,0))))+SUMPRODUCT((Inputs!$E$5:$E$130=$B4)*ISNUMBER(INDEX(Inputs!$K$5:$AJ$130,0,MATCH(AH$2,Inputs!$K$4:$AJ$4,0))))=0,NA(),SUMPRODUCT((Inputs!$A$5:$A$130=$B4)*Inputs!$B$5:$B$130*(((Inputs!$G$5:$G$130="moeda")+(Inputs!$G$5:$G$130="acoes"))*Inputs!$B$1+((Inputs!$G$5:$G$130<>"moeda")*(Inputs!$G$5:$G$130<>"acoes")))*INDEX(Inputs!$K$5:$AJ$130,0,MATCH(AH$2,Inputs!$K$4:$AJ$4,0)))+SUMPRODUCT((Inputs!$C$5:$C$130=$B4)*Inputs!$D$5:$D$130*(((Inputs!$G$5:$G$130="moeda")+(Inputs!$G$5:$G$130="acoes"))*Inputs!$B$1+((Inputs!$G$5:$G$130<>"moeda")*(Inputs!$G$5:$G$130<>"acoes")))*INDEX(Inputs!$K$5:$AJ$130,0,MATCH(AH$2,Inputs!$K$4:$AJ$4,0)))+SUMPRODUCT((Inputs!$E$5:$E$130=$B4)*Inputs!$F$5:$F$130*(((Inputs!$G$5:$G$130="moeda")+(Inputs!$G$5:$G$130="acoes"))*Inputs!$B$1+((Inputs!$G$5:$G$130<>"moeda")*(Inputs!$G$5:$G$130<>"acoes")))*INDEX(Inputs!$K$5:$AJ$130,0,MATCH(AH$2,Inputs!$K$4:$AJ$4,0))))) -> #N/A | AI4: =IF(ISNA(MATCH(AI$2,Inputs!$K$4:$AJ$4,0)),NA(),IF(SUMPRODUCT((Inputs!$A$5:$A$130=$B4)*ISNUMBER(INDEX(Inputs!$K$5:$AJ$130,0,MATCH(AI$2,Inputs!$K$4:$AJ$4,0))))+SUMPRODUCT((Inputs!$C$5:$C$130=$B4)*ISNUMBER(INDEX(Inputs!$K$5:$AJ$130,0,MATCH(AI$2,Inputs!$K$4:$AJ$4,0))))+SUMPRODUCT((Inputs!$E$5:$E$130=$B4)*ISNUMBER(INDEX(Inputs!$K$5:$AJ$130,0,MATCH(AI$2,Inputs!$K$4:$AJ$4,0))))=0,NA(),SUMPRODUCT((Inputs!$A$5:$A$130=$B4)*Inputs!$B$5:$B$130*(((Inputs!$G$5:$G$130="moeda")+(Inputs!$G$5:$G$130="acoes"))*Inputs!$B$1+((Inputs!$G$5:$G$130<>"moeda")*(Inputs!$G$5:$G$130<>"acoes")))*INDEX(Inputs!$K$5:$AJ$130,0,MATCH(AI$2,Inputs!$K$4:$AJ$4,0)))+SUMPRODUCT((Inputs!$C$5:$C$130=$B4)*Inputs!$D$5:$D$130*(((Inputs!$G$5:$G$130="moeda")+(Inputs!$G$5:$G$130="acoes"))*Inputs!$B$1+((Inputs!$G$5:$G$130<>"moeda")*(Inputs!$G$5:$G$130<>"acoes")))*INDEX(Inputs!$K$5:$AJ$130,0,MATCH(AI$2,Inputs!$K$4:$AJ$4,0)))+SUMPRODUCT((Inputs!$E$5:$E$130=$B4)*Inputs!$F$5:$F$130*(((Inputs!$G$5:$G$130="moeda")+(Inputs!$G$5:$G$130="acoes"))*Inputs!$B$1+((Inputs!$G$5:$G$130<>"moeda")*(Inputs!$G$5:$G$130<>"acoes")))*INDEX(Inputs!$K$5:$AJ$130,0,MATCH(AI$2,Inputs!$K$4:$AJ$4,0))))) -> #N/A | AJ4: =IF(ISNA(MATCH(AJ$2,Inputs!$K$4:$AJ$4,0)),NA(),IF(SUMPRODUCT((Inputs!$A$5:$A$130=$B4)*ISNUMBER(INDEX(Inputs!$K$5:$AJ$130,0,MATCH(AJ$2,Inputs!$K$4:$AJ$4,0))))+SUMPRODUCT((Inputs!$C$5:$C$130=$B4)*ISNUMBER(INDEX(Inputs!$K$5:$AJ$130,0,MATCH(AJ$2,Inputs!$K$4:$AJ$4,0))))+SUMPRODUCT((Inputs!$E$5:$E$130=$B4)*ISNUMBER(INDEX(Inputs!$K$5:$AJ$130,0,MATCH(AJ$2,Inputs!$K$4:$AJ$4,0))))=0,NA(),SUMPRODUCT((Inputs!$A$5:$A$130=$B4)*Inputs!$B$5:$B$130*(((Inputs!$G$5:$G$130="moeda")+(Inputs!$G$5:$G$130="acoes"))*Inputs!$B$1+((Inputs!$G$5:$G$130<>"moeda")*(Inputs!$G$5:$G$130<>"acoes")))*INDEX(Inputs!$K$5:$AJ$130,0,MATCH(AJ$2,Inputs!$K$4:$AJ$4,0)))+SUMPRODUCT((Inputs!$C$5:$C$130=$B4)*Inputs!$D$5:$D$130*(((Inputs!$G$5:$G$130="moeda")+(Inputs!$G$5:$G$130="acoes"))*Inputs!$B$1+((Inputs!$G$5:$G$130<>"moeda")*(Inputs!$G$5:$G$130<>"acoes")))*INDEX(Inputs!$K$5:$AJ$130,0,MATCH(AJ$2,Inputs!$K$4:$AJ$4,0)))+SUMPRODUCT((Inputs!$E$5:$E$130=$B4)*Inputs!$F$5:$F$130*(((Inputs!$G$5:$G$130="moeda")+(Inputs!$G$5:$G$130="acoes"))*Inputs!$B$1+((Inputs!$G$5:$G$130<>"moeda")*(Inputs!$G$5:$G$130<>"acoes")))*INDEX(Inputs!$K$5:$AJ$130,0,MATCH(AJ$2,Inputs!$K$4:$AJ$4,0))))) -> #N/A | AK4: =IF(ISNA(MATCH(AK$2,Inputs!$K$4:$AJ$4,0)),NA(),IF(SUMPRODUCT((Inputs!$A$5:$A$130=$B4)*ISNUMBER(INDEX(Inputs!$K$5:$AJ$130,0,MATCH(AK$2,Inputs!$K$4:$AJ$4,0))))+SUMPRODUCT((Inputs!$C$5:$C$130=$B4)*ISNUMBER(INDEX(Inputs!$K$5:$AJ$130,0,MATCH(AK$2,Inputs!$K$4:$AJ$4,0))))+SUMPRODUCT((Inputs!$E$5:$E$130=$B4)*ISNUMBER(INDEX(Inputs!$K$5:$AJ$130,0,MATCH(AK$2,Inputs!$K$4:$AJ$4,0))))=0,NA(),SUMPRODUCT((Inputs!$A$5:$A$130=$B4)*Inputs!$B$5:$B$130*(((Inputs!$G$5:$G$130="moeda")+(Inputs!$G$5:$G$130="acoes"))*Inputs!$B$1+((Inputs!$G$5:$G$130<>"moeda")*(Inputs!$G$5:$G$130<>"acoes")))*INDEX(Inputs!$K$5:$AJ$130,0,MATCH(AK$2,Inputs!$K$4:$AJ$4,0)))+SUMPRODUCT((Inputs!$C$5:$C$130=$B4)*Inputs!$D$5:$D$130*(((Inputs!$G$5:$G$130="moeda")+(Inputs!$G$5:$G$130="acoes"))*Inputs!$B$1+((Inputs!$G$5:$G$130<>"moeda")*(Inputs!$G$5:$G$130<>"acoes")))*INDEX(Inputs!$K$5:$AJ$130,0,MATCH(AK$2,Inputs!$K$4:$AJ$4,0)))+SUMPRODUCT((Inputs!$E$5:$E$130=$B4)*Inputs!$F$5:$F$130*(((Inputs!$G$5:$G$130="moeda")+(Inputs!$G$5:$G$130="acoes"))*Inputs!$B$1+((Inputs!$G$5:$G$130<>"moeda")*(Inputs!$G$5:$G$130<>"acoes")))*INDEX(Inputs!$K$5:$AJ$130,0,MATCH(AK$2,Inputs!$K$4:$AJ$4,0))))) -> #N/A | AL4: =SUM(AH4:AK4) -> #N/A
