Workbook
Name beta_observed: Valuation!$D$93
Name beta_observed_unlevered: #REF!
Name beta_unlev_comps: #REF!
Name cirkbreak: #REF!
Name costdebtfirm: #REF!
Name costequity: #REF!
Name Debt: #REF!
Name debt_weight: #REF!
Name last_close: Valuation!$G$7
Name Market_Equity: #REF!
Name midyear: #REF!
Name Net_Debt: #REF!
Name range: #REF!
Name Stub_year_fraction: #REF!
Name ticker: Valuation!$D$7
Name Useful_Life_of_Depreciable_PP_E: "PPElife"
Name beta_observed: #REF!
Name ticker: #REF!
Name costdebtfirm: Valuation!$D$86
Name costequity: Valuation!$D$94
Name debt: Valuation!$G$88
Name debt_weight: Valuation!$J$88
Name g: Valuation!$D$63
Name market_equity: Valuation!$G$89
Name noplat_t1: Valuation!$D$65
Name relevered_beta: Valuation!$M$102
Name risk_free_rate: Valuation!$D$91
Name risk_premium: Valuation!$D$92
Name ronic: Valuation!$D$64
Name stub_year_fraction: Valuation!$D$11
Name totalcap: Valuation!$G$90
Name wacc: Valuation!$D$12
Name scenario: Valuation!$E$8

Sheet Inputs
A1: Fator p/ milhões: | B1: 0.001 | D1: Cury Construtora (CURY3) - fonte: Planilha Fundamentos do RI (abas Resultados Operacionais, Demonstracoes do Resultado, BP Ativo, BP Passivo, Fluxo de Caixa). Moeda: BRL. Brutos em R$ mil. Consolidado. DRE e DFC trimestrais isolados (soma = ano, conferido).
J2: Trimestre na fonte | K2: 1T20 | L2: 2T20 | M2: 3T20 | N2: 4T20 | O2: 1T21 | P2: 2T21 | Q2: 3T21 | R2: 4T21 | S2: 1T22 | T2: 2T22 | U2: 3T22 | V2: 4T22 | W2: 1T23 | X2: 2T23 | Y2: 3T23 | Z2: 4T23 | AA2: 1T24 | AB2: 2T24 | AC2: 3T24 | AD2: 4T24 | AE2: 1T25 | AF2: 2T25 | AG2: 3T25 | AH2: 4T25 | AI2: 1T26 | AJ2: 2T26
A4: COD1 | B4: SINAL1 | C4: COD2 | D4: SINAL2 | E4: COD3 | F4: SINAL3 | G4: UNID | H4: Conta (PT) / origem | I4: Account (EN) | J4: ORIGEM | K4: 1Q20 | L4: 2Q20 | M4: 3Q20 | N4: 4Q20 | O4: 1Q21 | P4: 2Q21 | Q4: 3Q21 | R4: 4Q21 | S4: 1Q22 | T4: 2Q22 | U4: 3Q22 | V4: 4Q22 | W4: 1Q23 | X4: 2Q23 | Y4: 3Q23 | Z4: 4Q23 | AA4: 1Q24 | AB4: 2Q24 | AC4: 3Q24 | AD4: 4Q24 | AE4: 1Q25 | AF4: 2Q25 | AG4: 3Q25 | AH4: 4Q25 | AI4: 1Q26 | AJ4: 2Q26
H5: DRE - TRIMESTRE ISOLADO (aba Demonstracoes do Resultado; R$ mil)
A6: 1 | B6: 1 | G6: moeda | H6: Receita liquida (DRE l.4) | J6: fonte | K6: 227321 | L6: 246204 | M6: 325898 | N6: 345259 | O6: 339286 | P6: 451337 | Q6: 456449.58 | R6: 491223 | S6: 447374 | T6: 602783 | U6: 626659 | V6: 580478 | W6: 594956 | X6: 727746 | Y6: 751874 | Z6: 811596 | AA6: 837382 | AB6: 998085 | AC6: 1055872 | AD6: 1034971 | AE6: 1216184 | AF6: 1346599 | AG6: 1416926 | AH6: 1419715 | AI6: 1612571 | AJ6: 1690594
A7: 2 | B7: 1 | G7: moeda | H7: Custo das vendas e servicos (DRE l.5; inclui juros capitalizados apropriados ao custo) | J7: fonte | K7: -149181 | L7: -159137 | M7: -202541 | N7: -205433 | O7: -218944 | P7: -288421 | Q7: -281477.74 | R7: -304781 | S7: -281465 | T7: -387286 | U7: -392916 | V7: -358735 | W7: -371794 | X7: -453192 | Y7: -467971 | Z7: -497862 | AA7: -520773 | AB7: -615554 | AC7: -646426 | AD7: -630617 | AE7: -741296 | AF7: -813823 | AG7: -850699 | AH7: -847019 | AI7: -982915 | AJ7: -1022232
A8: 3 | B8: 1 | G8: moeda | H8: Despesas com vendas (DRE l.10; inclui depreciacao de estandes, devolvida abaixo) | J8: fonte | K8: -22046 | L8: -26343 | M8: -27428 | N8: -26987 | O8: -30360 | P8: -38953 | Q8: -47900 | R8: -46959 | S8: -44417 | T8: -53835 | U8: -59384 | V8: -54552 | W8: -62031 | X8: -66728 | Y8: -80995 | Z8: -75476 | AA8: -76092 | AB8: -97945.737 | AC8: -113852 | AD8: -103983 | AE8: -106236 | AF8: -124746.99 | AG8: -134823 | AH8: -129085 | AI8: -119070 | AJ8: -166790
A9: 3 | B9: 1 | G9: moeda | H9: Despesas gerais e administrativas (DRE l.11) | J9: fonte | K9: -28376 | L9: -14508 | M9: -25631 | N9: -28377 | O9: -20615 | P9: -24043 | Q9: -31170 | R9: -26689 | S9: -22810 | T9: -34143 | U9: -49409 | V9: -30206 | W9: -33375 | X9: -42088 | Y9: -54245 | Z9: -36075 | AA9: -41298 | AB9: -62203 | AC9: -68034 | AD9: -52894 | AE9: -50355 | AF9: -64401.683 | AG9: -66007 | AH9: -58575 | AI9: -64932 | AJ9: -78364
A10: 3 | B10: 1 | G10: moeda | H10: Outros resultados operacionais (DRE l.12) | J10: fonte | K10: -3179 | L10: 2365 | M10: -3304 | N10: -1914 | O10: -6524 | P10: -10905 | Q10: -8910 | R10: 23796 | S10: -19298 | T10: -15382 | U10: -11456 | V10: -12938 | W10: -12810 | X10: -18568 | Y10: -12803 | Z10: -19866 | AA10: -21345 | AB10: -23250 | AC10: -19747 | AD10: -21156 | AE10: -39738 | AF10: -30493.826 | AG10: -39204 | AH10: -42251 | AI10: -44791 | AJ10: -45797
A11: 8 | B11: 1 | G11: moeda | H11: Equivalencia patrimonial (DRE l.14) | J11: fonte | K11: 791 | L11: 195 | M11: 336 | N11: 1038 | O11: 1138 | P11: 1726 | Q11: -950 | R11: -991 | S11: -311 | T11: -141 | U11: 976 | V11: -145 | W11: -110 | X11: 696 | Y11: -295 | Z11: 1356 | AA11: 1299 | AB11: 2807 | AC11: 3389 | AD11: 1044 | AE11: 688 | AF11: 1091.0762 | AG11: 2474 | AH11: 3137 | AI11: 2282 | AJ11: 1014
A12: 5 | B12: 1 | G12: moeda | H12: Despesas financeiras (DRE l.18) | J12: fonte | K12: -4959 | L12: -5719 | M12: -6639 | N12: -6166 | O12: -7256 | P12: -9300 | Q12: -11430 | R12: -21731 | S12: -17062 | T12: -22214 | U12: -22860 | V12: -26332 | W12: -25672 | X12: -26026 | Y12: -23214 | Z12: -25215 | AA12: -24806 | AB12: -31099 | AC12: -39673 | AD12: -41587 | AE12: -51332 | AF12: -50846.244 | AG12: -56062 | AH12: -59596 | AI12: -59802 | AJ12: -70288
A13: 6 | B13: 1 | G13: moeda | H13: Receitas financeiras (DRE l.19) | J13: fonte | K13: 2784 | L13: 2827 | M13: 5428 | N13: 3634 | O13: 2222 | P13: 3924 | Q13: 10360 | R13: 8485 | S13: 12977 | T13: 17605 | U13: 18795 | V13: 14654 | W13: 20228 | X13: 20425 | Y13: 19668 | Z13: 25895 | AA13: 19889 | AB13: 25350 | AC13: 32060 | AD13: 28782 | AE13: 36752 | AF13: 35218.012 | AG13: 47368 | AH13: 50684 | AI13: 49093 | AJ13: 48168
A14: 7 | B14: 1 | G14: moeda | H14: IR e CS diferido (DRE l.23) | J14: fonte | K14: -666 | L14: 186 | M14: -1002 | N14: -82 | O14: -1492 | P14: -2193 | Q14: -842 | R14: 89 | S14: -2130 | T14: -2124 | U14: -1635 | V14: 81 | W14: -1627 | X14: -2289 | Y14: -800 | Z14: 133 | AA14: -2957 | AB14: -951 | AC14: -1562 | AD14: 2237 | AE14: -8693 | AF14: -2894 | AG14: 260 | AH14: 136 | AI14: -4003 | AJ14: -3011
A15: 7 | B15: 1 | G15: moeda | H15: IR e CS corrente (DRE l.24) | J15: fonte | K15: -7071 | L15: -5058 | M15: -5901 | N15: -6620 | O15: -5387 | P15: -6221 | Q15: -9490 | R15: -10799 | S15: -9507 | T15: -12324 | U15: -13899 | V15: -15026 | W15: -13709 | X15: -15906 | Y15: -18328 | Z15: -19892 | AA15: -17229 | AB15: -19957 | AC15: -21440 | AD15: -27925 | AE15: -22310 | AF15: -28545 | AG15: -37023 | AH15: -39957 | AI15: -37247 | AJ15: -42103
G16: moeda | H16: Lucro liquido do exercicio - 100% (DRE l.26) - memoria | J16: memoria | K16: 15418 | L16: 41012 | M16: 59216 | N16: 74352 | O16: 52068 | P16: 76951 | Q16: 74639.49 | R16: 111644 | S16: 63351 | T16: 92939 | U16: 94871 | V16: 97279 | W16: 94056 | X16: 124070 | Y16: 112891 | Z16: 164594 | AA16: 154070 | AB16: 175282 | AC16: 180588 | AD16: 188872 | AE16: 233664 | AF16: 267157 | AG16: 283210 | AH16: 297189 | AI16: 351186 | AJ16: 311191
A17: 9 | B17: -1 | G17: moeda | H17: Parcela do lucro atribuida aos nao controladores (DRE l.29; positiva na fonte -> COD 9 com sinal -1) | J17: fonte | K17: 8918 | L17: 4023 | M17: 9861 | N17: 6384 | O17: 2075 | P17: -1652 | Q17: 7241.7259 | R17: 7891 | S17: 1448 | T17: 6614 | U17: 4999 | V17: 5494 | W17: 2207 | X17: 2697 | Y17: 4671 | Z17: 4271 | AA17: 12829 | AB17: 3035 | AC17: 10017 | AD17: 23088 | AE17: 20189 | AF17: 30426.4 | AG17: 27957 | AH17: 27112 | AI17: 48319 | AJ17: 40740
A18: 44 | B18: 1 | G18: moeda | H18: Lucro liquido atribuido aos acionistas da controladora - %Cury (DRE l.30). COD 44 alimenta o check IS do Model (linha 4) | J18: fonte | K18: 6500 | L18: 36989 | M18: 49355 | N18: 67968 | O18: 49993 | P18: 78603 | Q18: 67397.764 | R18: 103753 | S18: 61903 | T18: 86325 | U18: 89872 | V18: 91785 | W18: 91849 | X18: 121373 | Y18: 108220 | Z18: 160323 | AA18: 141241 | AB18: 172247 | AC18: 170571 | AD18: 165784 | AE18: 213475 | AF18: 236730.6 | AG18: 255253 | AH18: 270077 | AI18: 302867 | AJ18: 270451
G19: moeda | H19: EBIT - lucro antes do resultado financeiro (DRE l.16) - memoria | J19: memoria | K19: 25330 | L19: 48776 | M19: 67330 | N19: 83586 | O19: 63981 | P19: 90741 | Q19: 86041.841 | R19: 135600 | S19: 79073 | T19: 111996 | U19: 114470 | V19: 123902 | W19: 114836 | X19: 147866 | Y19: 135565 | Z19: 183673 | AA19: 179173 | AB19: 201938.5 | AC19: 211203 | AD19: 227365 | AE19: 279247 | AF19: 314224 | AG19: 328667 | AH19: 345922 | AI19: 403145 | AJ19: 378425
G20: moeda | H20: EBITDA (DRE l.34, como divulgado) - memoria | J20: memoria | K20: 28255 | L20: 49083 | M20: 67695 | N20: 83849.71 | O20: 64315.653 | P20: 91096.058 | Q20: 86417.801 | R20: 135977.74 | S20: 79997.387 | T20: 117700 | U20: 120185 | V20: 130204 | W20: 121057.08 | X20: 154166 | Y20: 141905.89 | Z20: 190683.02 | AA20: 186290 | AB20: 208950.08 | AC20: 219394.2 | AD20: 236176.19 | AE20: 287780 | AF20: 322978 | AG20: 337188 | AH20: 354992 | AI20: 411494 | AJ20: 386976
G21: moeda | H21: EBITDA ajustado (DRE l.36; soma juros capitalizados) - memoria | J21: memoria | K21: 29620 | L21: 50769 | M21: 68104 | N21: 84604.71 | O21: 64437.653 | P21: 91238.058 | Q21: 86926.401 | R21: 136539.14 | S21: 80604.387 | T21: 118450.94 | U21: 121285.06 | V21: 131030 | W21: 122355.92 | X21: 155581.16 | Y21: 143394.89 | Z21: 192444.02 | AA21: 188146.01 | AB21: 211076 | AC21: 221434.3 | AD21: 238513.69 | AE21: 289491 | AF21: 326435.39 | AG21: 340249 | AH21: 359319 | AI21: 415737 | AJ21: 392251
G22: moeda | H22: Depreciacao e amortizacao (DRE l.33) - memoria | J22: memoria | K22: 2925 | L22: 307 | M22: 365 | N22: 265 | O22: 334.74295 | P22: 355.0585 | Q22: 370.45284 | R22: 378 | S22: 5875 | T22: 5704 | U22: 5715 | V22: 6302 | W22: 6221.0827 | X22: 6300 | Y22: 6340.8939 | Z22: 7010.0235 | AA22: 7117 | AB22: 7009 | AC22: 8191.3272 | AD22: 8811.1873 | AE22: 8533 | AF22: 8754 | AG22: 8521 | AH22: 9070 | AI22: 8349 | AJ22: 8551
H23: DFC - TRIMESTRE ISOLADO (aba Fluxo de Caixa; R$ mil)
A24: 10 | B24: 1 | G24: moeda | H24: Dividendos pagos a acionistas (DFC l.55; ja negativo na fonte) | J24: fonte | K24: 0 | L24: 0 | M24: 0 | N24: -170000 | O24: 0 | P24: 0 | Q24: -115000 | R24: -50000 | S24: 0 | T24: 0 | U24: -150000 | V24: 0 | W24: -60000 | X24: -18348 | Y24: 0 | Z24: -250000 | AA24: 0 | AB24: -118537 | AC24: -265000 | AD24: -100000 | AE24: -175000 | AF24: -154338 | AG24: 0 | AH24: -1023000 | AI24: 0 | AJ24: -270000
G25: moeda | H25: Imobilizado (DFC l.45) - capex - memoria | J25: memoria | K25: -3482 | L25: -3535 | M25: -5230 | N25: -5452 | O25: -10124 | P25: -8154 | Q25: -7054 | R25: -6369 | S25: -3970 | T25: -3383 | U25: 800 | V25: -12210 | W25: -13870 | X25: -8152 | Y25: -6189 | Z25: -7971 | AA25: -9128 | AB25: -7072 | AC25: -10833 | AD25: -10607 | AE25: -8816 | AF25: -7259 | AG25: -8645 | AH25: -9760 | AI25: -13519 | AJ25: -13320
G26: moeda | H26: Fluxo de caixa liquido das atividades operacionais (DFC l.39) - memoria | J26: memoria | K26: 4520.7146 | L26: 67057.593 | M26: 55153.829 | N26: 51347.864 | O26: 14590 | P26: 78624 | Q26: 78369 | R26: 210711 | S26: 27317 | T26: 94261 | U26: 70903 | V26: 154885 | W26: 19409 | X26: 106372 | Y26: 137791 | Z26: 154885 | AA26: 24438 | AB26: 173094 | AC26: 114104 | AD26: 167927.6 | AE26: 57863 | AF26: 105845 | AG26: 271006 | AH26: 312332 | AI26: 81925 | AJ26: 149981
H27: DERIVADAS (formula nesta aba)
A28: 4 | B28: -1 | C28: 3 | D28: 1 | G28: moeda | H28: D&A = EBITDA divulgado - EBIT (DRE l.34 - l.16), para o EBITDA do modelo ser o da Cia. Bate com a D&A da l.33 exceto 1T22 (EBITDA divulgado R$ 80,0 mi = EBIT 79,1 + 0,9; l.33 traz 5,9). COD1=4 lanca; COD2=3 devolve as despesas operacionais | J28: derivada | K28: =K20-K19 -> 2925 | L28: =L20-L19 -> 307 | M28: =M20-M19 -> 365 | N28: =N20-N19 -> 263.71006 | O28: =O20-O19 -> 334.65271 | P28: =P20-P19 -> 355.0585 | Q28: =Q20-Q19 -> 375.96036 | R28: =R20-R19 -> 377.74207 | ... AJ28: =AJ20-AJ19 -> 8551
H29: BALANCO (abas BP Ativo e BP Passivo; R$ mil, fim de trimestre)
A30: 11 | B30: 1 | G30: moeda | H30: Ativo: Caixa e equivalentes (l.6) | J30: fonte | K30: 254528 | L30: 358082 | M30: 529672 | N30: 291125 | O30: 329971 | P30: 390596 | Q30: 414633 | R30: 375963 | S30: 360921 | T30: 454074 | U30: 394522 | V30: 562264 | W30: 470159 | X30: 556696 | Y30: 730072 | Z30: 643630 | AA30: 647595 | AB30: 889522 | AC30: 760259 | AD30: 975224 | AE30: 1031724 | AF30: 1035262 | AG30: 1287134 | AH30: 1355394 | AI30: 1397709 | AJ30: 1375239
A31: 11 | B31: 1 | G31: moeda | H31: Ativo: Títulos e valores mobiliários (l.7) | J31: fonte | K31: 71000 | L31: 67765 | M31: 80177 | N31: 139773 | O31: 106673 | P31: 101391 | Q31: 140294 | R31: 218524 | S31: 241647 | T31: 225903 | U31: 240386 | V31: 227162 | W31: 259664 | X31: 278694 | Y31: 379003 | Z31: 348639 | AA31: 364073 | AB31: 668498 | AC31: 664956 | AD31: 441012 | AE31: 512082 | AF31: 495613 | AG31: 486069 | AH31: 435543 | AI31: 359601 | AJ31: 258467
A32: 12 | B32: 1 | G32: moeda | H32: Ativo: Contas a receber de clientes (l.8) | J32: fonte | K32: 448111 | L32: 528330 | M32: 647241 | N32: 627243 | O32: 770187 | P32: 835343 | Q32: 700282 | R32: 731349 | S32: 996524 | T32: 1004386 | U32: 879561.98 | V32: 681536 | W32: 677724 | X32: 678261 | Y32: 489221 | Z32: 481218 | AA32: 649909 | AB32: 494497 | AC32: 371958 | AD32: 345783 | AE32: 602208 | AF32: 552497 | AG32: 475943.34 | AH32: 286215 | AI32: 536930 | AJ32: 580014
A33: 13 | B33: 1 | G33: moeda | H33: Ativo: Imóveis a comercializar (l.9) | J33: fonte | K33: 210689 | L33: 190026 | M33: 226704 | N33: 270277 | O33: 382697 | P33: 320995 | Q33: 338886 | R33: 486666 | S33: 454883 | T33: 420684 | U33: 477113 | V33: 534993 | W33: 675394 | X33: 602449 | Y33: 626691 | Z33: 641546 | AA33: 683171 | AB33: 699423 | AC33: 683894 | AD33: 808203 | AE33: 742802 | AF33: 744049 | AG33: 960833 | AH33: 919547 | AI33: 1180633 | AJ33: 1185612
A34: 15 | B34: 1 | G34: moeda | H34: Ativo: Adiantamentos a fornecedores (l.10) | J34: fonte | K34: 11718 | L34: 9125 | M34: 8463 | N34: 7748 | O34: 7755 | P34: 5560 | Q34: 9083 | R34: 6611 | S34: 6676 | T34: 6582 | U34: 8343 | V34: 7297 | W34: 7108 | X34: 9562 | Y34: 11558 | Z34: 13547 | AA34: 9839 | AB34: 26070 | AC34: 15022 | AD34: 17033 | AE34: 15238 | AF34: 8316 | AG34: 9581 | AH34: 11708 | AI34: 10253 | AJ34: 9152
A35: 16 | B35: 1 | G35: moeda | H35: Ativo: Outros créditos (l.11) | J35: fonte | K35: 34332 | L35: 36889 | M35: 42749 | N35: 16345 | O35: 15478 | P35: 19254 | Q35: 24330 | R35: 27836 | S35: 30305 | T35: 36248 | U35: 43329 | V35: 50270 | W35: 58214 | X35: 63169 | Y35: 79675 | Z35: 84228 | AA35: 92050 | AB35: 115011 | AC35: 132338 | AD35: 138882 | AE35: 144504 | AF35: 170013 | AG35: 187277 | AH35: 203465 | AI35: 206713 | AJ35: 230579
A36: 12 | B36: 1 | G36: moeda | H36: Ativo: Contas a receber de clientes (l.14) -> cod 12: contas a receber total (CP + LP), padrao de incorporadora; para separar, trocar para cod 22 | J36: fonte | K36: 157343 | L36: 157343 | M36: 183813 | N36: 172079 | O36: 167826 | P36: 213781 | Q36: 406000 | R36: 546316 | S36: 634055 | T36: 552406 | U36: 520139.02 | V36: 497726 | W36: 372912 | X36: 407428 | Y36: 591170 | Z36: 609583 | AA36: 635299 | AB36: 884755 | AC36: 1082272 | AD36: 1091454 | AE36: 1294500 | AF36: 1581210 | AG36: 1722834.7 | AH36: 1871728 | AI36: 2012450 | AJ36: 2142326
A37: 13 | B37: 1 | G37: moeda | H37: Ativo: Imóveis a comercializar (l.15) -> cod 13: imoveis a comercializar total (CP + LP); para separar, trocar para cod 22 | J37: fonte | K37: 0 | L37: 0 | M37: 0 | N37: 25981 | O37: 36788 | P37: 44683 | Q37: 42742 | R37: 46042 | S37: 45908 | T37: 49903 | U37: 51027 | V37: 69096 | W37: 37104 | X37: 55154 | Y37: 62334 | Z37: 76002 | AA37: 128214 | AB37: 66628 | AC37: 107723 | AD37: 384925 | AE37: 392141 | AF37: 439808 | AG37: 356022 | AH37: 429102 | AI37: 340955 | AJ37: 344507
A38: 22 | B38: 1 | G38: moeda | H38: Ativo: Valores a receber entre partes relacionadas (l.16) | J38: fonte | K38: 41381 | L38: 41232 | M38: 32688 | N38: 12206 | O38: 12223 | P38: 4771 | Q38: 4788 | R38: 4321 | S38: 4445 | T38: 4724 | U38: 4355 | V38: 5073 | W38: 4990 | X38: 9220 | Y38: 9055 | Z38: 12877 | AA38: 17035 | AB38: 20868 | AC38: 18436 | AD38: 19811 | AE38: 15765 | AF38: 19451 | AG38: 12336 | AH38: 11893 | AI38: 17865 | AJ38: 18291
A39: 22 | B39: 1 | G39: moeda | H39: Ativo: Outros créditos (l.17) | J39: fonte | K39: 3640 | L39: 3725 | M39: 4441 | N39: 40318 | O39: 39751 | P39: 40488 | Q39: 40920 | R39: 35863 | S39: 36988 | T39: 38934 | U39: 39513 | V39: 37485 | W39: 38625 | X39: 40822 | Y39: 40775 | Z39: 37440 | AA39: 40040 | AB39: 36529 | AC39: 37791 | AD39: 33123 | AE39: 37748 | AF39: 56629 | AG39: 52251 | AH39: 47276 | AI39: 48248 | AJ39: 52709
A40: 17 | B40: 1 | G40: moeda | H40: Ativo: Investimentos (l.18) | J40: fonte | K40: 18857 | L40: 24778 | M40: 25680 | N40: 26948 | O40: 28737 | P40: 32139 | Q40: 29674 | R40: 29770 | S40: 30764 | T40: 33604 | U40: 36393 | V40: 34316 | W40: 32327 | X40: 33598 | Y40: 29692 | Z40: 40875 | AA40: 40803 | AB40: 44707 | AC40: 42837 | AD40: 42244 | AE40: 40372 | AF40: 40727 | AG40: 41203 | AH40: 41321 | AI40: 37757 | AJ40: 30471
A41: 18 | B41: 1 | G41: moeda | H41: Ativo: Imobilizado (l.19) | J41: fonte | K41: 12276 | L41: 12871 | M41: 13604 | N41: 14669 | O41: 20211 | P41: 23569 | Q41: 25579 | R41: 25765 | S41: 24330 | T41: 22509 | U41: 22203 | V41: 22931 | W41: 31101 | X41: 33293 | Y41: 33278 | Z41: 34596 | AA41: 36855 | AB41: 37163 | AC41: 39806 | AD41: 41601 | AE41: 41884 | AF41: 40389 | AG41: 40513 | AH41: 41203 | AI41: 46373 | AJ41: 51142
...

Sheet Inputs (2)
A1: =COUNTIF($B$3:$B$1048576,$B$1) -> 1 | B1: =MAX($B$3:$B$1048576) -> 65
D2: 1Q21 | E2: 2Q21 | F2: 3Q21 | G2: 4Q21 | H2: 2021 | I2: 1Q22 | J2: 2Q22 | K2: 3Q22 | L2: 4Q22 | M2: 2022 | N2: 1Q23 | O2: 2Q23 | P2: 3Q23 | Q2: 4Q23 | R2: 2023 | S2: 1Q24 | T2: 2Q24 | U2: 3Q24 | V2: 4Q24 | W2: 2024 | X2: 1Q25 | Y2: 2Q25 | Z2: 3Q25 | AA2: 4Q25 | AB2: 2025 | AC2: 1Q26 | AD2: 2Q26 | AE2: 3Q26 | AF2: 4Q26 | AG2: 2026 | AH2: 1Q20 | AI2: 2Q20 | AJ2: 3Q20 | AK2: 4Q20 | AL2: 2020 | AN2: Sem dado na fonte: 3Q26, 4Q26 e 2026 (rotulo em cinza). 2020 fica nas colunas AH-AL.
B4: 1 | C4: Net Revenues | D4: =IF(ISNA(MATCH(D$2,Inputs!$K$4:$AJ$4,0)),NA(),IF(SUMPRODUCT((Inputs!$A$5:$A$140=$B4)*ISNUMBER(INDEX(Inputs!$K$5:$AJ$140,0,MATCH(D$2,Inputs!$K$4:$AJ$4,0))))+SUMPRODUCT((Inputs!$C$5:$C$140=$B4)*ISNUMBER(INDEX(Inputs!$K$5:$AJ$140,0,MATCH(D$2,Inputs!$K$4:$AJ$4,0))))+SUMPRODUCT((Inputs!$E$5:$E$140=$B4)*ISNUMBER(INDEX(Inputs!$K$5:$AJ$140,0,MATCH(D$2,Inputs!$K$4:$AJ$4,0))))=0,NA(),SUMPRODUCT((Inputs!$A$5:$A$140=$B4)*Inputs!$B$5:$B$140*(((Inputs!$G$5:$G$140="moeda")+(Inputs!$G$5:$G$140="acoes"))*Inputs!$B$1+((Inputs!$G$5:$G$140<>"moeda")*(Inputs!$G$5:$G$140<>"acoes")))*INDEX(Inputs!$K$5:$AJ$140,0,MATCH(D$2,Inputs!$K$4:$AJ$4,0)))+SUMPRODUCT((Inputs!$C$5:$C$140=$B4)*Inputs!$D$5:$D$140*(((Inputs!$G$5:$G$140="moeda")+(Inputs!$G$5:$G$140="acoes"))*Inputs!$B$1+((Inputs!$G$5:$G$140<>"moeda")*(Inputs!$G$5:$G$140<>"acoes")))*INDEX(Inputs!$K$5:$AJ$140,0,MATCH(D$2,Inputs!$K$4:$AJ$4,0)))+SUMPRODUCT((Inputs!$E$5:$E$140=$B4)*Inputs!$F$5:$F$140*(((Inputs!$G$5:$G$140="moeda")+(Inputs!$G$5:$G$140="acoes"))*Inputs!$B$1+((Inputs!$G$5:$G$140<>"moeda")*(Inputs!$G$5:$G$140<>"acoes")))*INDEX(Inputs!$K$5:$AJ$140,0,MATCH(D$2,Inputs!$K$4:$AJ$4,0))))) -> 339.286 | E4: =IF(ISNA(MATCH(E$2,Inputs!$K$4:$AJ$4,0)),NA(),IF(SUMPRODUCT((Inputs!$A$5:$A$140=$B4)*ISNUMBER(INDEX(Inputs!$K$5:$AJ$140,0,MATCH(E$2,Inputs!$K$4:$AJ$4,0))))+SUMPRODUCT((Inputs!$C$5:$C$140=$B4)*ISNUMBER(INDEX(Inputs!$K$5:$AJ$140,0,MATCH(E$2,Inputs!$K$4:$AJ$4,0))))+SUMPRODUCT((Inputs!$E$5:$E$140=$B4)*ISNUMBER(INDEX(Inputs!$K$5:$AJ$140,0,MATCH(E$2,Inputs!$K$4:$AJ$4,0))))=0,NA(),SUMPRODUCT((Inputs!$A$5:$A$140=$B4)*Inputs!$B$5:$B$140*(((Inputs!$G$5:$G$140="moeda")+(Inputs!$G$5:$G$140="acoes"))*Inputs!$B$1+((Inputs!$G$5:$G$140<>"moeda")*(Inputs!$G$5:$G$140<>"acoes")))*INDEX(Inputs!$K$5:$AJ$140,0,MATCH(E$2,Inputs!$K$4:$AJ$4,0)))+SUMPRODUCT((Inputs!$C$5:$C$140=$B4)*Inputs!$D$5:$D$140*(((Inputs!$G$5:$G$140="moeda")+(Inputs!$G$5:$G$140="acoes"))*Inputs!$B$1+((Inputs!$G$5:$G$140<>"moeda")*(Inputs!$G$5:$G$140<>"acoes")))*INDEX(Inputs!$K$5:$AJ$140,0,MATCH(E$2,Inputs!$K$4:$AJ$4,0)))+SUMPRODUCT((Inputs!$E$5:$E$140=$B4)*Inputs!$F$5:$F$140*(((Inputs!$G$5:$G$140="moeda")+(Inputs!$G$5:$G$140="acoes"))*Inputs!$B$1+((Inputs!$G$5:$G$140<>"moeda")*(Inputs!$G$5:$G$140<>"acoes")))*INDEX(Inputs!$K$5:$AJ$140,0,MATCH(E$2,Inputs!$K$4:$AJ$4,0))))) -> 451.337 | F4: =IF(ISNA(MATCH(F$2,Inputs!$K$4:$AJ$4,0)),NA(),IF(SUMPRODUCT((Inputs!$A$5:$A$140=$B4)*ISNUMBER(INDEX(Inputs!$K$5:$AJ$140,0,MATCH(F$2,Inputs!$K$4:$AJ$4,0))))+SUMPRODUCT((Inputs!$C$5:$C$140=$B4)*ISNUMBER(INDEX(Inputs!$K$5:$AJ$140,0,MATCH(F$2,Inputs!$K$4:$AJ$4,0))))+SUMPRODUCT((Inputs!$E$5:$E$140=$B4)*ISNUMBER(INDEX(Inputs!$K$5:$AJ$140,0,MATCH(F$2,Inputs!$K$4:$AJ$4,0))))=0,NA(),SUMPRODUCT((Inputs!$A$5:$A$140=$B4)*Inputs!$B$5:$B$140*(((Inputs!$G$5:$G$140="moeda")+(Inputs!$G$5:$G$140="acoes"))*Inputs!$B$1+((Inputs!$G$5:$G$140<>"moeda")*(Inputs!$G$5:$G$140<>"acoes")))*INDEX(Inputs!$K$5:$AJ$140,0,MATCH(F$2,Inputs!$K$4:$AJ$4,0)))+SUMPRODUCT((Inputs!$C$5:$C$140=$B4)*Inputs!$D$5:$D$140*(((Inputs!$G$5:$G$140="moeda")+(Inputs!$G$5:$G$140="acoes"))*Inputs!$B$1+((Inputs!$G$5:$G$140<>"moeda")*(Inputs!$G$5:$G$140<>"acoes")))*INDEX(Inputs!$K$5:$AJ$140,0,MATCH(F$2,Inputs!$K$4:$AJ$4,0)))+SUMPRODUCT((Inputs!$E$5:$E$140=$B4)*Inputs!$F$5:$F$140*(((Inputs!$G$5:$G$140="moeda")+(Inputs!$G$5:$G$140="acoes"))*Inputs!$B$1+((Inputs!$G$5:$G$140<>"moeda")*(Inputs!$G$5:$G$140<>"acoes")))*INDEX(Inputs!$K$5:$AJ$140,0,MATCH(F$2,Inputs!$K$4:$AJ$4,0))))) -> 456.44958 | G4: =IF(ISNA(MATCH(G$2,Inputs!$K$4:$AJ$4,0)),NA(),IF(SUMPRODUCT((Inputs!$A$5:$A$140=$B4)*ISNUMBER(INDEX(Inputs!$K$5:$AJ$140,0,MATCH(G$2,Inputs!$K$4:$AJ$4,0))))+SUMPRODUCT((Inputs!$C$5:$C$140=$B4)*ISNUMBER(INDEX(Inputs!$K$5:$AJ$140,0,MATCH(G$2,Inputs!$K$4:$AJ$4,0))))+SUMPRODUCT((Inputs!$E$5:$E$140=$B4)*ISNUMBER(INDEX(Inputs!$K$5:$AJ$140,0,MATCH(G$2,Inputs!$K$4:$AJ$4,0))))=0,NA(),SUMPRODUCT((Inputs!$A$5:$A$140=$B4)*Inputs!$B$5:$B$140*(((Inputs!$G$5:$G$140="moeda")+(Inputs!$G$5:$G$140="acoes"))*Inputs!$B$1+((Inputs!$G$5:$G$140<>"moeda")*(Inputs!$G$5:$G$140<>"acoes")))*INDEX(Inputs!$K$5:$AJ$140,0,MATCH(G$2,Inputs!$K$4:$AJ$4,0)))+SUMPRODUCT((Inputs!$C$5:$C$140=$B4)*Inputs!$D$5:$D$140*(((Inputs!$G$5:$G$140="moeda")+(Inputs!$G$5:$G$140="acoes"))*Inputs!$B$1+((Inputs!$G$5:$G$140<>"moeda")*(Inputs!$G$5:$G$140<>"acoes")))*INDEX(Inputs!$K$5:$AJ$140,0,MATCH(G$2,Inputs!$K$4:$AJ$4,0)))+SUMPRODUCT((Inputs!$E$5:$E$140=$B4)*Inputs!$F$5:$F$140*(((Inputs!$G$5:$G$140="moeda")+(Inputs!$G$5:$G$140="acoes"))*Inputs!$B$1+((Inputs!$G$5:$G$140<>"moeda")*(Inputs!$G$5:$G$140<>"acoes")))*INDEX(Inputs!$K$5:$AJ$140,0,MATCH(G$2,Inputs!$K$4:$AJ$4,0))))) -> 491.223 | H4: =SUM(D4:G4) -> 1738.2956 | I4: =IF(ISNA(MATCH(I$2,Inputs!$K$4:$AJ$4,0)),NA(),IF(SUMPRODUCT((Inputs!$A$5:$A$140=$B4)*ISNUMBER(INDEX(Inputs!$K$5:$AJ$140,0,MATCH(I$2,Inputs!$K$4:$AJ$4,0))))+SUMPRODUCT((Inputs!$C$5:$C$140=$B4)*ISNUMBER(INDEX(Inputs!$K$5:$AJ$140,0,MATCH(I$2,Inputs!$K$4:$AJ$4,0))))+SUMPRODUCT((Inputs!$E$5:$E$140=$B4)*ISNUMBER(INDEX(Inputs!$K$5:$AJ$140,0,MATCH(I$2,Inputs!$K$4:$AJ$4,0))))=0,NA(),SUMPRODUCT((Inputs!$A$5:$A$140=$B4)*Inputs!$B$5:$B$140*(((Inputs!$G$5:$G$140="moeda")+(Inputs!$G$5:$G$140="acoes"))*Inputs!$B$1+((Inputs!$G$5:$G$140<>"moeda")*(Inputs!$G$5:$G$140<>"acoes")))*INDEX(Inputs!$K$5:$AJ$140,0,MATCH(I$2,Inputs!$K$4:$AJ$4,0)))+SUMPRODUCT((Inputs!$C$5:$C$140=$B4)*Inputs!$D$5:$D$140*(((Inputs!$G$5:$G$140="moeda")+(Inputs!$G$5:$G$140="acoes"))*Inputs!$B$1+((Inputs!$G$5:$G$140<>"moeda")*(Inputs!$G$5:$G$140<>"acoes")))*INDEX(Inputs!$K$5:$AJ$140,0,MATCH(I$2,Inputs!$K$4:$AJ$4,0)))+SUMPRODUCT((Inputs!$E$5:$E$140=$B4)*Inputs!$F$5:$F$140*(((Inputs!$G$5:$G$140="moeda")+(Inputs!$G$5:$G$140="acoes"))*Inputs!$B$1+((Inputs!$G$5:$G$140<>"moeda")*(Inputs!$G$5:$G$140<>"acoes")))*INDEX(Inputs!$K$5:$AJ$140,0,MATCH(I$2,Inputs!$K$4:$AJ$4,0))))) -> 447.374 | J4: =IF(ISNA(MATCH(J$2,Inputs!$K$4:$AJ$4,0)),NA(),IF(SUMPRODUCT((Inputs!$A$5:$A$140=$B4)*ISNUMBER(INDEX(Inputs!$K$5:$AJ$140,0,MATCH(J$2,Inputs!$K$4:$AJ$4,0))))+SUMPRODUCT((Inputs!$C$5:$C$140=$B4)*ISNUMBER(INDEX(Inputs!$K$5:$AJ$140,0,MATCH(J$2,Inputs!$K$4:$AJ$4,0))))+SUMPRODUCT((Inputs!$E$5:$E$140=$B4)*ISNUMBER(INDEX(Inputs!$K$5:$AJ$140,0,MATCH(J$2,Inputs!$K$4:$AJ$4,0))))=0,NA(),SUMPRODUCT((Inputs!$A$5:$A$140=$B4)*Inputs!$B$5:$B$140*(((Inputs!$G$5:$G$140="moeda")+(Inputs!$G$5:$G$140="acoes"))*Inputs!$B$1+((Inputs!$G$5:$G$140<>"moeda")*(Inputs!$G$5:$G$140<>"acoes")))*INDEX(Inputs!$K$5:$AJ$140,0,MATCH(J$2,Inputs!$K$4:$AJ$4,0)))+SUMPRODUCT((Inputs!$C$5:$C$140=$B4)*Inputs!$D$5:$D$140*(((Inputs!$G$5:$G$140="moeda")+(Inputs!$G$5:$G$140="acoes"))*Inputs!$B$1+((Inputs!$G$5:$G$140<>"moeda")*(Inputs!$G$5:$G$140<>"acoes")))*INDEX(Inputs!$K$5:$AJ$140,0,MATCH(J$2,Inputs!$K$4:$AJ$4,0)))+SUMPRODUCT((Inputs!$E$5:$E$140=$B4)*Inputs!$F$5:$F$140*(((Inputs!$G$5:$G$140="moeda")+(Inputs!$G$5:$G$140="acoes"))*Inputs!$B$1+((Inputs!$G$5:$G$140<>"moeda")*(Inputs!$G$5:$G$140<>"acoes")))*INDEX(Inputs!$K$5:$AJ$140,0,MATCH(J$2,Inputs!$K$4:$AJ$4,0))))) -> 602.783 | K4: =IF(ISNA(MATCH(K$2,Inputs!$K$4:$AJ$4,0)),NA(),IF(SUMPRODUCT((Inputs!$A$5:$A$140=$B4)*ISNUMBER(INDEX(Inputs!$K$5:$AJ$140,0,MATCH(K$2,Inputs!$K$4:$AJ$4,0))))+SUMPRODUCT((Inputs!$C$5:$C$140=$B4)*ISNUMBER(INDEX(Inputs!$K$5:$AJ$140,0,MATCH(K$2,Inputs!$K$4:$AJ$4,0))))+SUMPRODUCT((Inputs!$E$5:$E$140=$B4)*ISNUMBER(INDEX(Inputs!$K$5:$AJ$140,0,MATCH(K$2,Inputs!$K$4:$AJ$4,0))))=0,NA(),SUMPRODUCT((Inputs!$A$5:$A$140=$B4)*Inputs!$B$5:$B$140*(((Inputs!$G$5:$G$140="moeda")+(Inputs!$G$5:$G$140="acoes"))*Inputs!$B$1+((Inputs!$G$5:$G$140<>"moeda")*(Inputs!$G$5:$G$140<>"acoes")))*INDEX(Inputs!$K$5:$AJ$140,0,MATCH(K$2,Inputs!$K$4:$AJ$4,0)))+SUMPRODUCT((Inputs!$C$5:$C$140=$B4)*Inputs!$D$5:$D$140*(((Inputs!$G$5:$G$140="moeda")+(Inputs!$G$5:$G$140="acoes"))*Inputs!$B$1+((Inputs!$G$5:$G$140<>"moeda")*(Inputs!$G$5:$G$140<>"acoes")))*INDEX(Inputs!$K$5:$AJ$140,0,MATCH(K$2,Inputs!$K$4:$AJ$4,0)))+SUMPRODUCT((Inputs!$E$5:$E$140=$B4)*Inputs!$F$5:$F$140*(((Inputs!$G$5:$G$140="moeda")+(Inputs!$G$5:$G$140="acoes"))*Inputs!$B$1+((Inputs!$G$5:$G$140<>"moeda")*(Inputs!$G$5:$G$140<>"acoes")))*INDEX(Inputs!$K$5:$AJ$140,0,MATCH(K$2,Inputs!$K$4:$AJ$4,0))))) -> 626.659 | L4: =IF(ISNA(MATCH(L$2,Inputs!$K$4:$AJ$4,0)),NA(),IF(SUMPRODUCT((Inputs!$A$5:$A$140=$B4)*ISNUMBER(INDEX(Inputs!$K$5:$AJ$140,0,MATCH(L$2,Inputs!$K$4:$AJ$4,0))))+SUMPRODUCT((Inputs!$C$5:$C$140=$B4)*ISNUMBER(INDEX(Inputs!$K$5:$AJ$140,0,MATCH(L$2,Inputs!$K$4:$AJ$4,0))))+SUMPRODUCT((Inputs!$E$5:$E$140=$B4)*ISNUMBER(INDEX(Inputs!$K$5:$AJ$140,0,MATCH(L$2,Inputs!$K$4:$AJ$4,0))))=0,NA(),SUMPRODUCT((Inputs!$A$5:$A$140=$B4)*Inputs!$B$5:$B$140*(((Inputs!$G$5:$G$140="moeda")+(Inputs!$G$5:$G$140="acoes"))*Inputs!$B$1+((Inputs!$G$5:$G$140<>"moeda")*(Inputs!$G$5:$G$140<>"acoes")))*INDEX(Inputs!$K$5:$AJ$140,0,MATCH(L$2,Inputs!$K$4:$AJ$4,0)))+SUMPRODUCT((Inputs!$C$5:$C$140=$B4)*Inputs!$D$5:$D$140*(((Inputs!$G$5:$G$140="moeda")+(Inputs!$G$5:$G$140="acoes"))*Inputs!$B$1+((Inputs!$G$5:$G$140<>"moeda")*(Inputs!$G$5:$G$140<>"acoes")))*INDEX(Inputs!$K$5:$AJ$140,0,MATCH(L$2,Inputs!$K$4:$AJ$4,0)))+SUMPRODUCT((Inputs!$E$5:$E$140=$B4)*Inputs!$F$5:$F$140*(((Inputs!$G$5:$G$140="moeda")+(Inputs!$G$5:$G$140="acoes"))*Inputs!$B$1+((Inputs!$G$5:$G$140<>"moeda")*(Inputs!$G$5:$G$140<>"acoes")))*INDEX(Inputs!$K$5:$AJ$140,0,MATCH(L$2,Inputs!$K$4:$AJ$4,0))))) -> 580.478 | M4: =SUM(I4:L4) -> 2257.294 | N4: =IF(ISNA(MATCH(N$2,Inputs!$K$4:$AJ$4,0)),NA(),IF(SUMPRODUCT((Inputs!$A$5:$A$140=$B4)*ISNUMBER(INDEX(Inputs!$K$5:$AJ$140,0,MATCH(N$2,Inputs!$K$4:$AJ$4,0))))+SUMPRODUCT((Inputs!$C$5:$C$140=$B4)*ISNUMBER(INDEX(Inputs!$K$5:$AJ$140,0,MATCH(N$2,Inputs!$K$4:$AJ$4,0))))+SUMPRODUCT((Inputs!$E$5:$E$140=$B4)*ISNUMBER(INDEX(Inputs!$K$5:$AJ$140,0,MATCH(N$2,Inputs!$K$4:$AJ$4,0))))=0,NA(),SUMPRODUCT((Inputs!$A$5:$A$140=$B4)*Inputs!$B$5:$B$140*(((Inputs!$G$5:$G$140="moeda")+(Inputs!$G$5:$G$140="acoes"))*Inputs!$B$1+((Inputs!$G$5:$G$140<>"moeda")*(Inputs!$G$5:$G$140<>"acoes")))*INDEX(Inputs!$K$5:$AJ$140,0,MATCH(N$2,Inputs!$K$4:$AJ$4,0)))+SUMPRODUCT((Inputs!$C$5:$C$140=$B4)*Inputs!$D$5:$D$140*(((Inputs!$G$5:$G$140="moeda")+(Inputs!$G$5:$G$140="acoes"))*Inputs!$B$1+((Inputs!$G$5:$G$140<>"moeda")*(Inputs!$G$5:$G$140<>"acoes")))*INDEX(Inputs!$K$5:$AJ$140,0,MATCH(N$2,Inputs!$K$4:$AJ$4,0)))+SUMPRODUCT((Inputs!$E$5:$E$140=$B4)*Inputs!$F$5:$F$140*(((Inputs!$G$5:$G$140="moeda")+(Inputs!$G$5:$G$140="acoes"))*Inputs!$B$1+((Inputs!$G$5:$G$140<>"moeda")*(Inputs!$G$5:$G$140<>"acoes")))*INDEX(Inputs!$K$5:$AJ$140,0,MATCH(N$2,Inputs!$K$4:$AJ$4,0))))) -> 594.956 | O4: =IF(ISNA(MATCH(O$2,Inputs!$K$4:$AJ$4,0)),NA(),IF(SUMPRODUCT((Inputs!$A$5:$A$140=$B4)*ISNUMBER(INDEX(Inputs!$K$5:$AJ$140,0,MATCH(O$2,Inputs!$K$4:$AJ$4,0))))+SUMPRODUCT((Inputs!$C$5:$C$140=$B4)*ISNUMBER(INDEX(Inputs!$K$5:$AJ$140,0,MATCH(O$2,Inputs!$K$4:$AJ$4,0))))+SUMPRODUCT((Inputs!$E$5:$E$140=$B4)*ISNUMBER(INDEX(Inputs!$K$5:$AJ$140,0,MATCH(O$2,Inputs!$K$4:$AJ$4,0))))=0,NA(),SUMPRODUCT((Inputs!$A$5:$A$140=$B4)*Inputs!$B$5:$B$140*(((Inputs!$G$5:$G$140="moeda")+(Inputs!$G$5:$G$140="acoes"))*Inputs!$B$1+((Inputs!$G$5:$G$140<>"moeda")*(Inputs!$G$5:$G$140<>"acoes")))*INDEX(Inputs!$K$5:$AJ$140,0,MATCH(O$2,Inputs!$K$4:$AJ$4,0)))+SUMPRODUCT((Inputs!$C$5:$C$140=$B4)*Inputs!$D$5:$D$140*(((Inputs!$G$5:$G$140="moeda")+(Inputs!$G$5:$G$140="acoes"))*Inputs!$B$1+((Inputs!$G$5:$G$140<>"moeda")*(Inputs!$G$5:$G$140<>"acoes")))*INDEX(Inputs!$K$5:$AJ$140,0,MATCH(O$2,Inputs!$K$4:$AJ$4,0)))+SUMPRODUCT((Inputs!$E$5:$E$140=$B4)*Inputs!$F$5:$F$140*(((Inputs!$G$5:$G$140="moeda")+(Inputs!$G$5:$G$140="acoes"))*Inputs!$B$1+((Inputs!$G$5:$G$140<>"moeda")*(Inputs!$G$5:$G$140<>"acoes")))*INDEX(Inputs!$K$5:$AJ$140,0,MATCH(O$2,Inputs!$K$4:$AJ$4,0))))) -> 727.746 | P4: =IF(ISNA(MATCH(P$2,Inputs!$K$4:$AJ$4,0)),NA(),IF(SUMPRODUCT((Inputs!$A$5:$A$140=$B4)*ISNUMBER(INDEX(Inputs!$K$5:$AJ$140,0,MATCH(P$2,Inputs!$K$4:$AJ$4,0))))+SUMPRODUCT((Inputs!$C$5:$C$140=$B4)*ISNUMBER(INDEX(Inputs!$K$5:$AJ$140,0,MATCH(P$2,Inputs!$K$4:$AJ$4,0))))+SUMPRODUCT((Inputs!$E$5:$E$140=$B4)*ISNUMBER(INDEX(Inputs!$K$5:$AJ$140,0,MATCH(P$2,Inputs!$K$4:$AJ$4,0))))=0,NA(),SUMPRODUCT((Inputs!$A$5:$A$140=$B4)*Inputs!$B$5:$B$140*(((Inputs!$G$5:$G$140="moeda")+(Inputs!$G$5:$G$140="acoes"))*Inputs!$B$1+((Inputs!$G$5:$G$140<>"moeda")*(Inputs!$G$5:$G$140<>"acoes")))*INDEX(Inputs!$K$5:$AJ$140,0,MATCH(P$2,Inputs!$K$4:$AJ$4,0)))+SUMPRODUCT((Inputs!$C$5:$C$140=$B4)*Inputs!$D$5:$D$140*(((Inputs!$G$5:$G$140="moeda")+(Inputs!$G$5:$G$140="acoes"))*Inputs!$B$1+((Inputs!$G$5:$G$140<>"moeda")*(Inputs!$G$5:$G$140<>"acoes")))*INDEX(Inputs!$K$5:$AJ$140,0,MATCH(P$2,Inputs!$K$4:$AJ$4,0)))+SUMPRODUCT((Inputs!$E$5:$E$140=$B4)*Inputs!$F$5:$F$140*(((Inputs!$G$5:$G$140="moeda")+(Inputs!$G$5:$G$140="acoes"))*Inputs!$B$1+((Inputs!$G$5:$G$140<>"moeda")*(Inputs!$G$5:$G$140<>"acoes")))*INDEX(Inputs!$K$5:$AJ$140,0,MATCH(P$2,Inputs!$K$4:$AJ$4,0))))) -> 751.874 | Q4: =IF(ISNA(MATCH(Q$2,Inputs!$K$4:$AJ$4,0)),NA(),IF(SUMPRODUCT((Inputs!$A$5:$A$140=$B4)*ISNUMBER(INDEX(Inputs!$K$5:$AJ$140,0,MATCH(Q$2,Inputs!$K$4:$AJ$4,0))))+SUMPRODUCT((Inputs!$C$5:$C$140=$B4)*ISNUMBER(INDEX(Inputs!$K$5:$AJ$140,0,MATCH(Q$2,Inputs!$K$4:$AJ$4,0))))+SUMPRODUCT((Inputs!$E$5:$E$140=$B4)*ISNUMBER(INDEX(Inputs!$K$5:$AJ$140,0,MATCH(Q$2,Inputs!$K$4:$AJ$4,0))))=0,NA(),SUMPRODUCT((Inputs!$A$5:$A$140=$B4)*Inputs!$B$5:$B$140*(((Inputs!$G$5:$G$140="moeda")+(Inputs!$G$5:$G$140="acoes"))*Inputs!$B$1+((Inputs!$G$5:$G$140<>"moeda")*(Inputs!$G$5:$G$140<>"acoes")))*INDEX(Inputs!$K$5:$AJ$140,0,MATCH(Q$2,Inputs!$K$4:$AJ$4,0)))+SUMPRODUCT((Inputs!$C$5:$C$140=$B4)*Inputs!$D$5:$D$140*(((Inputs!$G$5:$G$140="moeda")+(Inputs!$G$5:$G$140="acoes"))*Inputs!$B$1+((Inputs!$G$5:$G$140<>"moeda")*(Inputs!$G$5:$G$140<>"acoes")))*INDEX(Inputs!$K$5:$AJ$140,0,MATCH(Q$2,Inputs!$K$4:$AJ$4,0)))+SUMPRODUCT((Inputs!$E$5:$E$140=$B4)*Inputs!$F$5:$F$140*(((Inputs!$G$5:$G$140="moeda")+(Inputs!$G$5:$G$140="acoes"))*Inputs!$B$1+((Inputs!$G$5:$G$140<>"moeda")*(Inputs!$G$5:$G$140<>"acoes")))*INDEX(Inputs!$K$5:$AJ$140,0,MATCH(Q$2,Inputs!$K$4:$AJ$4,0))))) -> 811.596 | R4: =SUM(N4:Q4) -> 2886.172 | S4: =IF(ISNA(MATCH(S$2,Inputs!$K$4:$AJ$4,0)),NA(),IF(SUMPRODUCT((Inputs!$A$5:$A$140=$B4)*ISNUMBER(INDEX(Inputs!$K$5:$AJ$140,0,MATCH(S$2,Inputs!$K$4:$AJ$4,0))))+SUMPRODUCT((Inputs!$C$5:$C$140=$B4)*ISNUMBER(INDEX(Inputs!$K$5:$AJ$140,0,MATCH(S$2,Inputs!$K$4:$AJ$4,0))))+SUMPRODUCT((Inputs!$E$5:$E$140=$B4)*ISNUMBER(INDEX(Inputs!$K$5:$AJ$140,0,MATCH(S$2,Inputs!$K$4:$AJ$4,0))))=0,NA(),SUMPRODUCT((Inputs!$A$5:$A$140=$B4)*Inputs!$B$5:$B$140*(((Inputs!$G$5:$G$140="moeda")+(Inputs!$G$5:$G$140="acoes"))*Inputs!$B$1+((Inputs!$G$5:$G$140<>"moeda")*(Inputs!$G$5:$G$140<>"acoes")))*INDEX(Inputs!$K$5:$AJ$140,0,MATCH(S$2,Inputs!$K$4:$AJ$4,0)))+SUMPRODUCT((Inputs!$C$5:$C$140=$B4)*Inputs!$D$5:$D$140*(((Inputs!$G$5:$G$140="moeda")+(Inputs!$G$5:$G$140="acoes"))*Inputs!$B$1+((Inputs!$G$5:$G$140<>"moeda")*(Inputs!$G$5:$G$140<>"acoes")))*INDEX(Inputs!$K$5:$AJ$140,0,MATCH(S$2,Inputs!$K$4:$AJ$4,0)))+SUMPRODUCT((Inputs!$E$5:$E$140=$B4)*Inputs!$F$5:$F$140*(((Inputs!$G$5:$G$140="moeda")+(Inputs!$G$5:$G$140="acoes"))*Inputs!$B$1+((Inputs!$G$5:$G$140<>"moeda")*(Inputs!$G$5:$G$140<>"acoes")))*INDEX(Inputs!$K$5:$AJ$140,0,MATCH(S$2,Inputs!$K$4:$AJ$4,0))))) -> 837.382 | T4: =IF(ISNA(MATCH(T$2,Inputs!$K$4:$AJ$4,0)),NA(),IF(SUMPRODUCT((Inputs!$A$5:$A$140=$B4)*ISNUMBER(INDEX(Inputs!$K$5:$AJ$140,0,MATCH(T$2,Inputs!$K$4:$AJ$4,0))))+SUMPRODUCT((Inputs!$C$5:$C$140=$B4)*ISNUMBER(INDEX(Inputs!$K$5:$AJ$140,0,MATCH(T$2,Inputs!$K$4:$AJ$4,0))))+SUMPRODUCT((Inputs!$E$5:$E$140=$B4)*ISNUMBER(INDEX(Inputs!$K$5:$AJ$140,0,MATCH(T$2,Inputs!$K$4:$AJ$4,0))))=0,NA(),SUMPRODUCT((Inputs!$A$5:$A$140=$B4)*Inputs!$B$5:$B$140*(((Inputs!$G$5:$G$140="moeda")+(Inputs!$G$5:$G$140="acoes"))*Inputs!$B$1+((Inputs!$G$5:$G$140<>"moeda")*(Inputs!$G$5:$G$140<>"acoes")))*INDEX(Inputs!$K$5:$AJ$140,0,MATCH(T$2,Inputs!$K$4:$AJ$4,0)))+SUMPRODUCT((Inputs!$C$5:$C$140=$B4)*Inputs!$D$5:$D$140*(((Inputs!$G$5:$G$140="moeda")+(Inputs!$G$5:$G$140="acoes"))*Inputs!$B$1+((Inputs!$G$5:$G$140<>"moeda")*(Inputs!$G$5:$G$140<>"acoes")))*INDEX(Inputs!$K$5:$AJ$140,0,MATCH(T$2,Inputs!$K$4:$AJ$4,0)))+SUMPRODUCT((Inputs!$E$5:$E$140=$B4)*Inputs!$F$5:$F$140*(((Inputs!$G$5:$G$140="moeda")+(Inputs!$G$5:$G$140="acoes"))*Inputs!$B$1+((Inputs!$G$5:$G$140<>"moeda")*(Inputs!$G$5:$G$140<>"acoes")))*INDEX(Inputs!$K$5:$AJ$140,0,MATCH(T$2,Inputs!$K$4:$AJ$4,0))))) -> 998.085 | U4: =IF(ISNA(MATCH(U$2,Inputs!$K$4:$AJ$4,0)),NA(),IF(SUMPRODUCT((Inputs!$A$5:$A$140=$B4)*ISNUMBER(INDEX(Inputs!$K$5:$AJ$140,0,MATCH(U$2,Inputs!$K$4:$AJ$4,0))))+SUMPRODUCT((Inputs!$C$5:$C$140=$B4)*ISNUMBER(INDEX(Inputs!$K$5:$AJ$140,0,MATCH(U$2,Inputs!$K$4:$AJ$4,0))))+SUMPRODUCT((Inputs!$E$5:$E$140=$B4)*ISNUMBER(INDEX(Inputs!$K$5:$AJ$140,0,MATCH(U$2,Inputs!$K$4:$AJ$4,0))))=0,NA(),SUMPRODUCT((Inputs!$A$5:$A$140=$B4)*Inputs!$B$5:$B$140*(((Inputs!$G$5:$G$140="moeda")+(Inputs!$G$5:$G$140="acoes"))*Inputs!$B$1+((Inputs!$G$5:$G$140<>"moeda")*(Inputs!$G$5:$G$140<>"acoes")))*INDEX(Inputs!$K$5:$AJ$140,0,MATCH(U$2,Inputs!$K$4:$AJ$4,0)))+SUMPRODUCT((Inputs!$C$5:$C$140=$B4)*Inputs!$D$5:$D$140*(((Inputs!$G$5:$G$140="moeda")+(Inputs!$G$5:$G$140="acoes"))*Inputs!$B$1+((Inputs!$G$5:$G$140<>"moeda")*(Inputs!$G$5:$G$140<>"acoes")))*INDEX(Inputs!$K$5:$AJ$140,0,MATCH(U$2,Inputs!$K$4:$AJ$4,0)))+SUMPRODUCT((Inputs!$E$5:$E$140=$B4)*Inputs!$F$5:$F$140*(((Inputs!$G$5:$G$140="moeda")+(Inputs!$G$5:$G$140="acoes"))*Inputs!$B$1+((Inputs!$G$5:$G$140<>"moeda")*(Inputs!$G$5:$G$140<>"acoes")))*INDEX(Inputs!$K$5:$AJ$140,0,MATCH(U$2,Inputs!$K$4:$AJ$4,0))))) -> 1055.872 | V4: =IF(ISNA(MATCH(V$2,Inputs!$K$4:$AJ$4,0)),NA(),IF(SUMPRODUCT((Inputs!$A$5:$A$140=$B4)*ISNUMBER(INDEX(Inputs!$K$5:$AJ$140,0,MATCH(V$2,Inputs!$K$4:$AJ$4,0))))+SUMPRODUCT((Inputs!$C$5:$C$140=$B4)*ISNUMBER(INDEX(Inputs!$K$5:$AJ$140,0,MATCH(V$2,Inputs!$K$4:$AJ$4,0))))+SUMPRODUCT((Inputs!$E$5:$E$140=$B4)*ISNUMBER(INDEX(Inputs!$K$5:$AJ$140,0,MATCH(V$2,Inputs!$K$4:$AJ$4,0))))=0,NA(),SUMPRODUCT((Inputs!$A$5:$A$140=$B4)*Inputs!$B$5:$B$140*(((Inputs!$G$5:$G$140="moeda")+(Inputs!$G$5:$G$140="acoes"))*Inputs!$B$1+((Inputs!$G$5:$G$140<>"moeda")*(Inputs!$G$5:$G$140<>"acoes")))*INDEX(Inputs!$K$5:$AJ$140,0,MATCH(V$2,Inputs!$K$4:$AJ$4,0)))+SUMPRODUCT((Inputs!$C$5:$C$140=$B4)*Inputs!$D$5:$D$140*(((Inputs!$G$5:$G$140="moeda")+(Inputs!$G$5:$G$140="acoes"))*Inputs!$B$1+((Inputs!$G$5:$G$140<>"moeda")*(Inputs!$G$5:$G$140<>"acoes")))*INDEX(Inputs!$K$5:$AJ$140,0,MATCH(V$2,Inputs!$K$4:$AJ$4,0)))+SUMPRODUCT((Inputs!$E$5:$E$140=$B4)*Inputs!$F$5:$F$140*(((Inputs!$G$5:$G$140="moeda")+(Inputs!$G$5:$G$140="acoes"))*Inputs!$B$1+((Inputs!$G$5:$G$140<>"moeda")*(Inputs!$G$5:$G$140<>"acoes")))*INDEX(Inputs!$K$5:$AJ$140,0,MATCH(V$2,Inputs!$K$4:$AJ$4,0))))) -> 1034.971 | W4: =SUM(S4:V4) -> 3926.31 | X4: =IF(ISNA(MATCH(X$2,Inputs!$K$4:$AJ$4,0)),NA(),IF(SUMPRODUCT((Inputs!$A$5:$A$140=$B4)*ISNUMBER(INDEX(Inputs!$K$5:$AJ$140,0,MATCH(X$2,Inputs!$K$4:$AJ$4,0))))+SUMPRODUCT((Inputs!$C$5:$C$140=$B4)*ISNUMBER(INDEX(Inputs!$K$5:$AJ$140,0,MATCH(X$2,Inputs!$K$4:$AJ$4,0))))+SUMPRODUCT((Inputs!$E$5:$E$140=$B4)*ISNUMBER(INDEX(Inputs!$K$5:$AJ$140,0,MATCH(X$2,Inputs!$K$4:$AJ$4,0))))=0,NA(),SUMPRODUCT((Inputs!$A$5:$A$140=$B4)*Inputs!$B$5:$B$140*(((Inputs!$G$5:$G$140="moeda")+(Inputs!$G$5:$G$140="acoes"))*Inputs!$B$1+((Inputs!$G$5:$G$140<>"moeda")*(Inputs!$G$5:$G$140<>"acoes")))*INDEX(Inputs!$K$5:$AJ$140,0,MATCH(X$2,Inputs!$K$4:$AJ$4,0)))+SUMPRODUCT((Inputs!$C$5:$C$140=$B4)*Inputs!$D$5:$D$140*(((Inputs!$G$5:$G$140="moeda")+(Inputs!$G$5:$G$140="acoes"))*Inputs!$B$1+((Inputs!$G$5:$G$140<>"moeda")*(Inputs!$G$5:$G$140<>"acoes")))*INDEX(Inputs!$K$5:$AJ$140,0,MATCH(X$2,Inputs!$K$4:$AJ$4,0)))+SUMPRODUCT((Inputs!$E$5:$E$140=$B4)*Inputs!$F$5:$F$140*(((Inputs!$G$5:$G$140="moeda")+(Inputs!$G$5:$G$140="acoes"))*Inputs!$B$1+((Inputs!$G$5:$G$140<>"moeda")*(Inputs!$G$5:$G$140<>"acoes")))*INDEX(Inputs!$K$5:$AJ$140,0,MATCH(X$2,Inputs!$K$4:$AJ$4,0))))) -> 1216.184 | Y4: =IF(ISNA(MATCH(Y$2,Inputs!$K$4:$AJ$4,0)),NA(),IF(SUMPRODUCT((Inputs!$A$5:$A$140=$B4)*ISNUMBER(INDEX(Inputs!$K$5:$AJ$140,0,MATCH(Y$2,Inputs!$K$4:$AJ$4,0))))+SUMPRODUCT((Inputs!$C$5:$C$140=$B4)*ISNUMBER(INDEX(Inputs!$K$5:$AJ$140,0,MATCH(Y$2,Inputs!$K$4:$AJ$4,0))))+SUMPRODUCT((Inputs!$E$5:$E$140=$B4)*ISNUMBER(INDEX(Inputs!$K$5:$AJ$140,0,MATCH(Y$2,Inputs!$K$4:$AJ$4,0))))=0,NA(),SUMPRODUCT((Inputs!$A$5:$A$140=$B4)*Inputs!$B$5:$B$140*(((Inputs!$G$5:$G$140="moeda")+(Inputs!$G$5:$G$140="acoes"))*Inputs!$B$1+((Inputs!$G$5:$G$140<>"moeda")*(Inputs!$G$5:$G$140<>"acoes")))*INDEX(Inputs!$K$5:$AJ$140,0,MATCH(Y$2,Inputs!$K$4:$AJ$4,0)))+SUMPRODUCT((Inputs!$C$5:$C$140=$B4)*Inputs!$D$5:$D$140*(((Inputs!$G$5:$G$140="moeda")+(Inputs!$G$5:$G$140="acoes"))*Inputs!$B$1+((Inputs!$G$5:$G$140<>"moeda")*(Inputs!$G$5:$G$140<>"acoes")))*INDEX(Inputs!$K$5:$AJ$140,0,MATCH(Y$2,Inputs!$K$4:$AJ$4,0)))+SUMPRODUCT((Inputs!$E$5:$E$140=$B4)*Inputs!$F$5:$F$140*(((Inputs!$G$5:$G$140="moeda")+(Inputs!$G$5:$G$140="acoes"))*Inputs!$B$1+((Inputs!$G$5:$G$140<>"moeda")*(Inputs!$G$5:$G$140<>"acoes")))*INDEX(Inputs!$K$5:$AJ$140,0,MATCH(Y$2,Inputs!$K$4:$AJ$4,0))))) -> 1346.599 | Z4: =IF(ISNA(MATCH(Z$2,Inputs!$K$4:$AJ$4,0)),NA(),IF(SUMPRODUCT((Inputs!$A$5:$A$140=$B4)*ISNUMBER(INDEX(Inputs!$K$5:$AJ$140,0,MATCH(Z$2,Inputs!$K$4:$AJ$4,0))))+SUMPRODUCT((Inputs!$C$5:$C$140=$B4)*ISNUMBER(INDEX(Inputs!$K$5:$AJ$140,0,MATCH(Z$2,Inputs!$K$4:$AJ$4,0))))+SUMPRODUCT((Inputs!$E$5:$E$140=$B4)*ISNUMBER(INDEX(Inputs!$K$5:$AJ$140,0,MATCH(Z$2,Inputs!$K$4:$AJ$4,0))))=0,NA(),SUMPRODUCT((Inputs!$A$5:$A$140=$B4)*Inputs!$B$5:$B$140*(((Inputs!$G$5:$G$140="moeda")+(Inputs!$G$5:$G$140="acoes"))*Inputs!$B$1+((Inputs!$G$5:$G$140<>"moeda")*(Inputs!$G$5:$G$140<>"acoes")))*INDEX(Inputs!$K$5:$AJ$140,0,MATCH(Z$2,Inputs!$K$4:$AJ$4,0)))+SUMPRODUCT((Inputs!$C$5:$C$140=$B4)*Inputs!$D$5:$D$140*(((Inputs!$G$5:$G$140="moeda")+(Inputs!$G$5:$G$140="acoes"))*Inputs!$B$1+((Inputs!$G$5:$G$140<>"moeda")*(Inputs!$G$5:$G$140<>"acoes")))*INDEX(Inputs!$K$5:$AJ$140,0,MATCH(Z$2,Inputs!$K$4:$AJ$4,0)))+SUMPRODUCT((Inputs!$E$5:$E$140=$B4)*Inputs!$F$5:$F$140*(((Inputs!$G$5:$G$140="moeda")+(Inputs!$G$5:$G$140="acoes"))*Inputs!$B$1+((Inputs!$G$5:$G$140<>"moeda")*(Inputs!$G$5:$G$140<>"acoes")))*INDEX(Inputs!$K$5:$AJ$140,0,MATCH(Z$2,Inputs!$K$4:$AJ$4,0))))) -> 1416.926 | AA4: =IF(ISNA(MATCH(AA$2,Inputs!$K$4:$AJ$4,0)),NA(),IF(SUMPRODUCT((Inputs!$A$5:$A$140=$B4)*ISNUMBER(INDEX(Inputs!$K$5:$AJ$140,0,MATCH(AA$2,Inputs!$K$4:$AJ$4,0))))+SUMPRODUCT((Inputs!$C$5:$C$140=$B4)*ISNUMBER(INDEX(Inputs!$K$5:$AJ$140,0,MATCH(AA$2,Inputs!$K$4:$AJ$4,0))))+SUMPRODUCT((Inputs!$E$5:$E$140=$B4)*ISNUMBER(INDEX(Inputs!$K$5:$AJ$140,0,MATCH(AA$2,Inputs!$K$4:$AJ$4,0))))=0,NA(),SUMPRODUCT((Inputs!$A$5:$A$140=$B4)*Inputs!$B$5:$B$140*(((Inputs!$G$5:$G$140="moeda")+(Inputs!$G$5:$G$140="acoes"))*Inputs!$B$1+((Inputs!$G$5:$G$140<>"moeda")*(Inputs!$G$5:$G$140<>"acoes")))*INDEX(Inputs!$K$5:$AJ$140,0,MATCH(AA$2,Inputs!$K$4:$AJ$4,0)))+SUMPRODUCT((Inputs!$C$5:$C$140=$B4)*Inputs!$D$5:$D$140*(((Inputs!$G$5:$G$140="moeda")+(Inputs!$G$5:$G$140="acoes"))*Inputs!$B$1+((Inputs!$G$5:$G$140<>"moeda")*(Inputs!$G$5:$G$140<>"acoes")))*INDEX(Inputs!$K$5:$AJ$140,0,MATCH(AA$2,Inputs!$K$4:$AJ$4,0)))+SUMPRODUCT((Inputs!$E$5:$E$140=$B4)*Inputs!$F$5:$F$140*(((Inputs!$G$5:$G$140="moeda")+(Inputs!$G$5:$G$140="acoes"))*Inputs!$B$1+((Inputs!$G$5:$G$140<>"moeda")*(Inputs!$G$5:$G$140<>"acoes")))*INDEX(Inputs!$K$5:$AJ$140,0,MATCH(AA$2,Inputs!$K$4:$AJ$4,0))))) -> 1419.715 | AB4: =SUM(X4:AA4) -> 5399.424 | AC4: =IF(ISNA(MATCH(AC$2,Inputs!$K$4:$AJ$4,0)),NA(),IF(SUMPRODUCT((Inputs!$A$5:$A$140=$B4)*ISNUMBER(INDEX(Inputs!$K$5:$AJ$140,0,MATCH(AC$2,Inputs!$K$4:$AJ$4,0))))+SUMPRODUCT((Inputs!$C$5:$C$140=$B4)*ISNUMBER(INDEX(Inputs!$K$5:$AJ$140,0,MATCH(AC$2,Inputs!$K$4:$AJ$4,0))))+SUMPRODUCT((Inputs!$E$5:$E$140=$B4)*ISNUMBER(INDEX(Inputs!$K$5:$AJ$140,0,MATCH(AC$2,Inputs!$K$4:$AJ$4,0))))=0,NA(),SUMPRODUCT((Inputs!$A$5:$A$140=$B4)*Inputs!$B$5:$B$140*(((Inputs!$G$5:$G$140="moeda")+(Inputs!$G$5:$G$140="acoes"))*Inputs!$B$1+((Inputs!$G$5:$G$140<>"moeda")*(Inputs!$G$5:$G$140<>"acoes")))*INDEX(Inputs!$K$5:$AJ$140,0,MATCH(AC$2,Inputs!$K$4:$AJ$4,0)))+SUMPRODUCT((Inputs!$C$5:$C$140=$B4)*Inputs!$D$5:$D$140*(((Inputs!$G$5:$G$140="moeda")+(Inputs!$G$5:$G$140="acoes"))*Inputs!$B$1+((Inputs!$G$5:$G$140<>"moeda")*(Inputs!$G$5:$G$140<>"acoes")))*INDEX(Inputs!$K$5:$AJ$140,0,MATCH(AC$2,Inputs!$K$4:$AJ$4,0)))+SUMPRODUCT((Inputs!$E$5:$E$140=$B4)*Inputs!$F$5:$F$140*(((Inputs!$G$5:$G$140="moeda")+(Inputs!$G$5:$G$140="acoes"))*Inputs!$B$1+((Inputs!$G$5:$G$140<>"moeda")*(Inputs!$G$5:$G$140<>"acoes")))*INDEX(Inputs!$K$5:$AJ$140,0,MATCH(AC$2,Inputs!$K$4:$AJ$4,0))))) -> 1612.571 | AD4: =IF(ISNA(MATCH(AD$2,Inputs!$K$4:$AJ$4,0)),NA(),IF(SUMPRODUCT((Inputs!$A$5:$A$140=$B4)*ISNUMBER(INDEX(Inputs!$K$5:$AJ$140,0,MATCH(AD$2,Inputs!$K$4:$AJ$4,0))))+SUMPRODUCT((Inputs!$C$5:$C$140=$B4)*ISNUMBER(INDEX(Inputs!$K$5:$AJ$140,0,MATCH(AD$2,Inputs!$K$4:$AJ$4,0))))+SUMPRODUCT((Inputs!$E$5:$E$140=$B4)*ISNUMBER(INDEX(Inputs!$K$5:$AJ$140,0,MATCH(AD$2,Inputs!$K$4:$AJ$4,0))))=0,NA(),SUMPRODUCT((Inputs!$A$5:$A$140=$B4)*Inputs!$B$5:$B$140*(((Inputs!$G$5:$G$140="moeda")+(Inputs!$G$5:$G$140="acoes"))*Inputs!$B$1+((Inputs!$G$5:$G$140<>"moeda")*(Inputs!$G$5:$G$140<>"acoes")))*INDEX(Inputs!$K$5:$AJ$140,0,MATCH(AD$2,Inputs!$K$4:$AJ$4,0)))+SUMPRODUCT((Inputs!$C$5:$C$140=$B4)*Inputs!$D$5:$D$140*(((Inputs!$G$5:$G$140="moeda")+(Inputs!$G$5:$G$140="acoes"))*Inputs!$B$1+((Inputs!$G$5:$G$140<>"moeda")*(Inputs!$G$5:$G$140<>"acoes")))*INDEX(Inputs!$K$5:$AJ$140,0,MATCH(AD$2,Inputs!$K$4:$AJ$4,0)))+SUMPRODUCT((Inputs!$E$5:$E$140=$B4)*Inputs!$F$5:$F$140*(((Inputs!$G$5:$G$140="moeda")+(Inputs!$G$5:$G$140="acoes"))*Inputs!$B$1+((Inputs!$G$5:$G$140<>"moeda")*(Inputs!$G$5:$G$140<>"acoes")))*INDEX(Inputs!$K$5:$AJ$140,0,MATCH(AD$2,Inputs!$K$4:$AJ$4,0))))) -> 1690.594 | AE4: =IF(ISNA(MATCH(AE$2,Inputs!$K$4:$AJ$4,0)),NA(),IF(SUMPRODUCT((Inputs!$A$5:$A$140=$B4)*ISNUMBER(INDEX(Inputs!$K$5:$AJ$140,0,MATCH(AE$2,Inputs!$K$4:$AJ$4,0))))+SUMPRODUCT((Inputs!$C$5:$C$140=$B4)*ISNUMBER(INDEX(Inputs!$K$5:$AJ$140,0,MATCH(AE$2,Inputs!$K$4:$AJ$4,0))))+SUMPRODUCT((Inputs!$E$5:$E$140=$B4)*ISNUMBER(INDEX(Inputs!$K$5:$AJ$140,0,MATCH(AE$2,Inputs!$K$4:$AJ$4,0))))=0,NA(),SUMPRODUCT((Inputs!$A$5:$A$140=$B4)*Inputs!$B$5:$B$140*(((Inputs!$G$5:$G$140="moeda")+(Inputs!$G$5:$G$140="acoes"))*Inputs!$B$1+((Inputs!$G$5:$G$140<>"moeda")*(Inputs!$G$5:$G$140<>"acoes")))*INDEX(Inputs!$K$5:$AJ$140,0,MATCH(AE$2,Inputs!$K$4:$AJ$4,0)))+SUMPRODUCT((Inputs!$C$5:$C$140=$B4)*Inputs!$D$5:$D$140*(((Inputs!$G$5:$G$140="moeda")+(Inputs!$G$5:$G$140="acoes"))*Inputs!$B$1+((Inputs!$G$5:$G$140<>"moeda")*(Inputs!$G$5:$G$140<>"acoes")))*INDEX(Inputs!$K$5:$AJ$140,0,MATCH(AE$2,Inputs!$K$4:$AJ$4,0)))+SUMPRODUCT((Inputs!$E$5:$E$140=$B4)*Inputs!$F$5:$F$140*(((Inputs!$G$5:$G$140="moeda")+(Inputs!$G$5:$G$140="acoes"))*Inputs!$B$1+((Inputs!$G$5:$G$140<>"moeda")*(Inputs!$G$5:$G$140<>"acoes")))*INDEX(Inputs!$K$5:$AJ$140,0,MATCH(AE$2,Inputs!$K$4:$AJ$4,0))))) -> #N/A | AF4: =IF(ISNA(MATCH(AF$2,Inputs!$K$4:$AJ$4,0)),NA(),IF(SUMPRODUCT((Inputs!$A$5:$A$140=$B4)*ISNUMBER(INDEX(Inputs!$K$5:$AJ$140,0,MATCH(AF$2,Inputs!$K$4:$AJ$4,0))))+SUMPRODUCT((Inputs!$C$5:$C$140=$B4)*ISNUMBER(INDEX(Inputs!$K$5:$AJ$140,0,MATCH(AF$2,Inputs!$K$4:$AJ$4,0))))+SUMPRODUCT((Inputs!$E$5:$E$140=$B4)*ISNUMBER(INDEX(Inputs!$K$5:$AJ$140,0,MATCH(AF$2,Inputs!$K$4:$AJ$4,0))))=0,NA(),SUMPRODUCT((Inputs!$A$5:$A$140=$B4)*Inputs!$B$5:$B$140*(((Inputs!$G$5:$G$140="moeda")+(Inputs!$G$5:$G$140="acoes"))*Inputs!$B$1+((Inputs!$G$5:$G$140<>"moeda")*(Inputs!$G$5:$G$140<>"acoes")))*INDEX(Inputs!$K$5:$AJ$140,0,MATCH(AF$2,Inputs!$K$4:$AJ$4,0)))+SUMPRODUCT((Inputs!$C$5:$C$140=$B4)*Inputs!$D$5:$D$140*(((Inputs!$G$5:$G$140="moeda")+(Inputs!$G$5:$G$140="acoes"))*Inputs!$B$1+((Inputs!$G$5:$G$140<>"moeda")*(Inputs!$G$5:$G$140<>"acoes")))*INDEX(Inputs!$K$5:$AJ$140,0,MATCH(AF$2,Inputs!$K$4:$AJ$4,0)))+SUMPRODUCT((Inputs!$E$5:$E$140=$B4)*Inputs!$F$5:$F$140*(((Inputs!$G$5:$G$140="moeda")+(Inputs!$G$5:$G$140="acoes"))*Inputs!$B$1+((Inputs!$G$5:$G$140<>"moeda")*(Inputs!$G$5:$G$140<>"acoes")))*INDEX(Inputs!$K$5:$AJ$140,0,MATCH(AF$2,Inputs!$K$4:$AJ$4,0))))) -> #N/A | AG4: =SUM(AC4:AF4) -> #N/A | AH4: =IF(ISNA(MATCH(AH$2,Inputs!$K$4:$AJ$4,0)),NA(),IF(SUMPRODUCT((Inputs!$A$5:$A$140=$B4)*ISNUMBER(INDEX(Inputs!$K$5:$AJ$140,0,MATCH(AH$2,Inputs!$K$4:$AJ$4,0))))+SUMPRODUCT((Inputs!$C$5:$C$140=$B4)*ISNUMBER(INDEX(Inputs!$K$5:$AJ$140,0,MATCH(AH$2,Inputs!$K$4:$AJ$4,0))))+SUMPRODUCT((Inputs!$E$5:$E$140=$B4)*ISNUMBER(INDEX(Inputs!$K$5:$AJ$140,0,MATCH(AH$2,Inputs!$K$4:$AJ$4,0))))=0,NA(),SUMPRODUCT((Inputs!$A$5:$A$140=$B4)*Inputs!$B$5:$B$140*(((Inputs!$G$5:$G$140="moeda")+(Inputs!$G$5:$G$140="acoes"))*Inputs!$B$1+((Inputs!$G$5:$G$140<>"moeda")*(Inputs!$G$5:$G$140<>"acoes")))*INDEX(Inputs!$K$5:$AJ$140,0,MATCH(AH$2,Inputs!$K$4:$AJ$4,0)))+SUMPRODUCT((Inputs!$C$5:$C$140=$B4)*Inputs!$D$5:$D$140*(((Inputs!$G$5:$G$140="moeda")+(Inputs!$G$5:$G$140="acoes"))*Inputs!$B$1+((Inputs!$G$5:$G$140<>"moeda")*(Inputs!$G$5:$G$140<>"acoes")))*INDEX(Inputs!$K$5:$AJ$140,0,MATCH(AH$2,Inputs!$K$4:$AJ$4,0)))+SUMPRODUCT((Inputs!$E$5:$E$140=$B4)*Inputs!$F$5:$F$140*(((Inputs!$G$5:$G$140="moeda")+(Inputs!$G$5:$G$140="acoes"))*Inputs!$B$1+((Inputs!$G$5:$G$140<>"moeda")*(Inputs!$G$5:$G$140<>"acoes")))*INDEX(Inputs!$K$5:$AJ$140,0,MATCH(AH$2,Inputs!$K$4:$AJ$4,0))))) -> 227.321 | AI4: =IF(ISNA(MATCH(AI$2,Inputs!$K$4:$AJ$4,0)),NA(),IF(SUMPRODUCT((Inputs!$A$5:$A$140=$B4)*ISNUMBER(INDEX(Inputs!$K$5:$AJ$140,0,MATCH(AI$2,Inputs!$K$4:$AJ$4,0))))+SUMPRODUCT((Inputs!$C$5:$C$140=$B4)*ISNUMBER(INDEX(Inputs!$K$5:$AJ$140,0,MATCH(AI$2,Inputs!$K$4:$AJ$4,0))))+SUMPRODUCT((Inputs!$E$5:$E$140=$B4)*ISNUMBER(INDEX(Inputs!$K$5:$AJ$140,0,MATCH(AI$2,Inputs!$K$4:$AJ$4,0))))=0,NA(),SUMPRODUCT((Inputs!$A$5:$A$140=$B4)*Inputs!$B$5:$B$140*(((Inputs!$G$5:$G$140="moeda")+(Inputs!$G$5:$G$140="acoes"))*Inputs!$B$1+((Inputs!$G$5:$G$140<>"moeda")*(Inputs!$G$5:$G$140<>"acoes")))*INDEX(Inputs!$K$5:$AJ$140,0,MATCH(AI$2,Inputs!$K$4:$AJ$4,0)))+SUMPRODUCT((Inputs!$C$5:$C$140=$B4)*Inputs!$D$5:$D$140*(((Inputs!$G$5:$G$140="moeda")+(Inputs!$G$5:$G$140="acoes"))*Inputs!$B$1+((Inputs!$G$5:$G$140<>"moeda")*(Inputs!$G$5:$G$140<>"acoes")))*INDEX(Inputs!$K$5:$AJ$140,0,MATCH(AI$2,Inputs!$K$4:$AJ$4,0)))+SUMPRODUCT((Inputs!$E$5:$E$140=$B4)*Inputs!$F$5:$F$140*(((Inputs!$G$5:$G$140="moeda")+(Inputs!$G$5:$G$140="acoes"))*Inputs!$B$1+((Inputs!$G$5:$G$140<>"moeda")*(Inputs!$G$5:$G$140<>"acoes")))*INDEX(Inputs!$K$5:$AJ$140,0,MATCH(AI$2,Inputs!$K$4:$AJ$4,0))))) -> 246.204 | AJ4: =IF(ISNA(MATCH(AJ$2,Inputs!$K$4:$AJ$4,0)),NA(),IF(SUMPRODUCT((Inputs!$A$5:$A$140=$B4)*ISNUMBER(INDEX(Inputs!$K$5:$AJ$140,0,MATCH(AJ$2,Inputs!$K$4:$AJ$4,0))))+SUMPRODUCT((Inputs!$C$5:$C$140=$B4)*ISNUMBER(INDEX(Inputs!$K$5:$AJ$140,0,MATCH(AJ$2,Inputs!$K$4:$AJ$4,0))))+SUMPRODUCT((Inputs!$E$5:$E$140=$B4)*ISNUMBER(INDEX(Inputs!$K$5:$AJ$140,0,MATCH(AJ$2,Inputs!$K$4:$AJ$4,0))))=0,NA(),SUMPRODUCT((Inputs!$A$5:$A$140=$B4)*Inputs!$B$5:$B$140*(((Inputs!$G$5:$G$140="moeda")+(Inputs!$G$5:$G$140="acoes"))*Inputs!$B$1+((Inputs!$G$5:$G$140<>"moeda")*(Inputs!$G$5:$G$140<>"acoes")))*INDEX(Inputs!$K$5:$AJ$140,0,MATCH(AJ$2,Inputs!$K$4:$AJ$4,0)))+SUMPRODUCT((Inputs!$C$5:$C$140=$B4)*Inputs!$D$5:$D$140*(((Inputs!$G$5:$G$140="moeda")+(Inputs!$G$5:$G$140="acoes"))*Inputs!$B$1+((Inputs!$G$5:$G$140<>"moeda")*(Inputs!$G$5:$G$140<>"acoes")))*INDEX(Inputs!$K$5:$AJ$140,0,MATCH(AJ$2,Inputs!$K$4:$AJ$4,0)))+SUMPRODUCT((Inputs!$E$5:$E$140=$B4)*Inputs!$F$5:$F$140*(((Inputs!$G$5:$G$140="moeda")+(Inputs!$G$5:$G$140="acoes"))*Inputs!$B$1+((Inputs!$G$5:$G$140<>"moeda")*(Inputs!$G$5:$G$140<>"acoes")))*INDEX(Inputs!$K$5:$AJ$140,0,MATCH(AJ$2,Inputs!$K$4:$AJ$4,0))))) -> 325.898 | AK4: =IF(ISNA(MATCH(AK$2,Inputs!$K$4:$AJ$4,0)),NA(),IF(SUMPRODUCT((Inputs!$A$5:$A$140=$B4)*ISNUMBER(INDEX(Inputs!$K$5:$AJ$140,0,MATCH(AK$2,Inputs!$K$4:$AJ$4,0))))+SUMPRODUCT((Inputs!$C$5:$C$140=$B4)*ISNUMBER(INDEX(Inputs!$K$5:$AJ$140,0,MATCH(AK$2,Inputs!$K$4:$AJ$4,0))))+SUMPRODUCT((Inputs!$E$5:$E$140=$B4)*ISNUMBER(INDEX(Inputs!$K$5:$AJ$140,0,MATCH(AK$2,Inputs!$K$4:$AJ$4,0))))=0,NA(),SUMPRODUCT((Inputs!$A$5:$A$140=$B4)*Inputs!$B$5:$B$140*(((Inputs!$G$5:$G$140="moeda")+(Inputs!$G$5:$G$140="acoes"))*Inputs!$B$1+((Inputs!$G$5:$G$140<>"moeda")*(Inputs!$G$5:$G$140<>"acoes")))*INDEX(Inputs!$K$5:$AJ$140,0,MATCH(AK$2,Inputs!$K$4:$AJ$4,0)))+SUMPRODUCT((Inputs!$C$5:$C$140=$B4)*Inputs!$D$5:$D$140*(((Inputs!$G$5:$G$140="moeda")+(Inputs!$G$5:$G$140="acoes"))*Inputs!$B$1+((Inputs!$G$5:$G$140<>"moeda")*(Inputs!$G$5:$G$140<>"acoes")))*INDEX(Inputs!$K$5:$AJ$140,0,MATCH(AK$2,Inputs!$K$4:$AJ$4,0)))+SUMPRODUCT((Inputs!$E$5:$E$140=$B4)*Inputs!$F$5:$F$140*(((Inputs!$G$5:$G$140="moeda")+(Inputs!$G$5:$G$140="acoes"))*Inputs!$B$1+((Inputs!$G$5:$G$140<>"moeda")*(Inputs!$G$5:$G$140<>"acoes")))*INDEX(Inputs!$K$5:$AJ$140,0,MATCH(AK$2,Inputs!$K$4:$AJ$4,0))))) -> 345.259 | AL4: =SUM(AH4:AK4) -> 1144.682
