Workbook
Name beta_observed: Valuation!$D$93
Name beta_observed_unlevered: #REF!
Name beta_unlev_comps: #REF!
Name cirkbreak: #REF!
Name costdebtfirm: #REF!
Name costequity: #REF!
Name Debt: #REF!
Name debt_weight: #REF!
Name last_close: Valuation!$G$7
Name Market_Equity: #REF!
Name midyear: #REF!
Name Net_Debt: #REF!
Name range: #REF!
Name Stub_year_fraction: #REF!
Name ticker: Valuation!$D$7
Name Useful_Life_of_Depreciable_PP_E: "PPElife"
Name beta_observed: #REF!
Name ticker: #REF!
Name costdebtfirm: Valuation!$D$86
Name costequity: Valuation!$D$94
Name debt: Valuation!$G$88
Name debt_weight: Valuation!$J$88
Name g: Valuation!$D$63
Name market_equity: Valuation!$G$89
Name noplat_t1: Valuation!$D$65
Name relevered_beta: Valuation!$M$102
Name risk_free_rate: Valuation!$D$91
Name risk_premium: Valuation!$D$92
Name ronic: Valuation!$D$64
Name stub_year_fraction: Valuation!$D$11
Name totalcap: Valuation!$G$90
Name wacc: Valuation!$D$12
Name scenario: Valuation!$E$8

Sheet Inputs
A1: Fator p/ milhões: | B1: 0.001 | D1: Alupar Investimento S.A. (ALUP11) - fonte: planilha de fundamentos do RI, aba "Consolidado" (IFRS, consolidado). Moeda: BRL. Unidade dos brutos: R$ mil. Fator converte p/ R$ milhoes.
J2: Rotulo na fonte | K2: 1T20 | L2: 2T20 | M2: 3T20 | N2: 4T20 | O2: 1T21 | P2: 2T21 | Q2: 3T21 | R2: 4T21 | S2: 1T22 | T2: 2T22 | U2: 3T22 | V2: 4T22 | W2: 1T23 | X2: 2T23 | Y2: 3T23 | Z2: 4T23 | AA2: 1T24 | AB2: 2T24 | AC2: 3T24 | AD2: 4T24 | AE2: 1T25 | AF2: 2T25 | AG2: 3T25 | AH2: 4T25 | AI2: 1T26 | AJ2: 2T26
A4: COD1 | B4: SINAL1 | C4: COD2 | D4: SINAL2 | E4: COD3 | F4: SINAL3 | G4: UNID | H4: Conta (PT) / origem | I4: Account (EN) | J4: ORIGEM | K4: 1Q20 | L4: 2Q20 | M4: 3Q20 | N4: 4Q20 | O4: 1Q21 | P4: 2Q21 | Q4: 3Q21 | R4: 4Q21 | S4: 1Q22 | T4: 2Q22 | U4: 3Q22 | V4: 4Q22 | W4: 1Q23 | X4: 2Q23 | Y4: 3Q23 | Z4: 4Q23 | AA4: 1Q24 | AB4: 2Q24 | AC4: 3Q24 | AD4: 4Q24 | AE4: 1Q25 | AF4: 2Q25 | AG4: 3Q25 | AH4: 4Q25 | AI4: 1Q26 | AJ4: 2Q26
H5: DRE (R$ mil, trimestre isolado; aba Consolidado IFRS). Receita = componentes da receita bruta + deducoes (subtotal); custos e despesas negativos na fonte
A6: 1 | B6: 1 | G6: moeda | H6: Receita de transmissão de energia (RAP) / Energy Transmission System (l.104) | J6: fonte | K6: 54546 | L6: 78752 | M6: 80994 | N6: 376909 | O6: 94801 | P6: 101892 | Q6: 121340 | R6: 113606 | S6: 132054 | T6: 133093 | U6: 151165 | V6: 150308 | W6: 151077 | X6: 158369 | Y6: 147167 | Z6: 149544 | AA6: 153460 | AB6: 154759 | AC6: 162723 | AD6: 151746 | AE6: 159716 | AF6: 161370 | AG6: 172356 | AH6: 203391 | AI6: 221177 | AJ6: 213113
A7: 1 | B7: 1 | G7: moeda | H7: Suprimento de energia / Energy Supply (l.105) | J7: fonte | K7: 179039 | L7: 119215 | M7: 152402 | N7: 195219 | O7: 181526 | P7: 171678 | Q7: 237412 | R7: 207020 | S7: 185262 | T7: 160392 | U7: 167156 | V7: 182548 | W7: 199097 | X7: 199602 | Y7: 210009 | Z7: 207475 | AA7: 200808 | AB7: 193980 | AC7: 203699 | AD7: 257183 | AE7: 231888 | AF7: 242027 | AG7: 232259 | AH7: 237413 | AI7: 283621 | AJ7: 240198
A8: 1 | B8: 1 | G8: moeda | H8: Remuneração do ativo contratual da concessão / Remuneration of Contractual Assets (l.106) | J8: fonte | K8: 326415 | L8: 217093 | M8: 423869 | N8: 1298898 | O8: 976410 | P8: 1008846 | Q8: 674156 | R8: 881589 | S8: 985322 | T8: 610789 | U8: 401708 | V8: 354639 | W8: 483941 | X8: 397997 | Y8: 395714 | Z8: 395798 | AA8: 398299 | AB8: 401372 | AC8: 428451 | AD8: 407848 | AE8: 417301 | AF8: 418833 | AG8: 442498 | AH8: 468947 | AI8: 426713 | AJ8: 436556
A9: 1 | B9: 1 | G9: moeda | H9: Remuneração do ativo financeiro da concessão / Remuneration of Financial Assets (l.107) | J9: fonte | K9: 0 | L9: 0 | M9: 0 | N9: 0 | O9: 0 | P9: 0 | Q9: 0 | R9: 0 | S9: 0 | T9: 0 | U9: 0 | V9: 0 | W9: 0 | X9: 0 | Y9: 0 | Z9: 0 | AA9: 0 | AB9: 0 | AC9: 0 | AD9: 0 | AE9: 0 | AF9: 0 | AG9: 0 | AH9: 0 | AI9: 0 | AJ9: 0
A10: 1 | B10: 1 | G10: moeda | H10: Correção monetária do ativo contratual / Monetary Update of Contractual Assets (l.108) | J10: fonte | K10: 0 | L10: 0 | M10: 0 | N10: 0 | O10: 0 | P10: 0 | Q10: 0 | R10: 0 | S10: 0 | T10: 334986 | U10: -25281 | V10: 75383 | W10: 191723 | X10: 39452 | Y10: -61721 | Z10: 154100 | AA10: 243913 | AB10: 168422 | AC10: 128826 | AD10: 310931 | AE10: 359799 | AF10: 160033 | AG10: -5485 | AH10: 136574 | AI10: 187379 | AJ10: 482966
A11: 1 | B11: 1 | G11: moeda | H11: Receita de infraestrutura / Infrastructure Revenue (l.109) | J11: fonte | K11: 778224 | L11: 716276 | M11: 980233 | N11: 766981 | O11: 505633 | P11: 190968 | Q11: 245421 | R11: 90901 | S11: 109284 | T11: 48345 | U11: 28371 | V11: 64481 | W11: 77474 | X11: 46838 | Y11: 33037 | Z11: 50753 | AA11: 103932 | AB11: 134115 | AC11: 102852 | AD11: 99966 | AE11: 168103 | AF11: 176178 | AG11: 228238 | AH11: 237882 | AI11: 266965 | AJ11: 419162
A12: 1 | B12: 1 | G12: moeda | H12: Prestação de serviços de garantia / Consultancy and advisory services in the regulatory area (l.110) | J12: fonte | K12: 0 | L12: 0 | M12: 0 | N12: 0 | O12: 0 | P12: 0 | Q12: 0 | R12: 0 | S12: 0 | T12: 0 | U12: 0 | V12: 0 | W12: 0 | X12: 0 | Y12: 0 | Z12: 0 | AA12: 0 | AB12: 0 | AC12: 0 | AD12: 0 | AE12: 0 | AF12: 0 | AG12: 0 | AH12: 0 | AI12: 0 | AJ12: 0
A13: 1 | B13: 1 | G13: moeda | H13: Outras receitas operacionais / O&M Services (l.111) | J13: fonte | K13: 0 | L13: 0 | M13: 0 | N13: 0 | O13: 0 | P13: 0 | Q13: 0 | R13: 0 | S13: 0 | T13: 0 | U13: 0 | V13: 0 | W13: 8251 | X13: -4736 | Y13: 1442 | Z13: 1502 | AA13: 1350 | AB13: 1437 | AC13: 1132 | AD13: 997 | AE13: 12156 | AF13: 135 | AG13: 132 | AH13: 133 | AI13: 4187 | AJ13: 124
A14: 1 | B14: 1 | G14: moeda | H14: Deduções da receita operacional / Deductions from operating revenues (l.113) | J14: fonte | K14: -121297 | L14: -104360 | M14: -146175 | N14: -232488 | O14: -156896 | P14: -136243 | Q14: -110677 | R14: -165175 | S14: -131402 | T14: -119362 | U14: -70460 | V14: -95073 | W14: -107566 | X14: -57366 | Y14: -76691 | Z14: -80901 | AA14: -105227 | AB14: -100393 | AC14: -99116 | AD14: -105361 | AE14: -125232 | AF14: -111436 | AG14: -106645 | AH14: -120681 | AI14: -134407 | AJ14: -164834
A15: 2 | B15: 1 | G15: moeda | H15: Compra de Energia / Energy purchase (l.130) | J15: fonte | K15: -32699 | L15: -26099 | M15: -35062 | N15: -47912 | O15: -26695 | P15: -33948 | Q15: -50791 | R15: -34731 | S15: -12662 | T15: -6806 | U15: -14184 | V15: -8829 | W15: -12730 | X15: -9126 | Y15: -12693 | Z15: -28433 | AA15: -11597 | AB15: -10327 | AC15: -35334 | AD15: -62038 | AE15: -31340 | AF15: -25294 | AG15: -43664 | AH15: -50722 | AI15: -44591 | AJ15: -38203
A16: 2 | B16: 1 | G16: moeda | H16: Custo dos serviços prestados / Cost of Rendered Services (l.131) | J16: fonte | K16: -44865 | L16: -49574 | M16: -53418 | N16: -77825 | O16: -51089 | P16: -56671 | Q16: -72341 | R16: -5524 | S16: -62463 | T16: -72183 | U16: -79556 | V16: -91088 | W16: -78523 | X16: -70345 | Y16: -85709 | Z16: -82765 | AA16: -81490 | AB16: -89146 | AC16: -89797 | AD16: -109700 | AE16: -99565 | AF16: -95678 | AG16: -95957 | AH16: -114899 | AI16: -94540 | AJ16: -106727
A17: 2 | B17: 1 | G17: moeda | H17: Custo de construção / Construction Costs (l.132) | J17: fonte | K17: -500082 | L17: -500547 | M17: -653799 | N17: -549845 | O17: -393249 | P17: -110635 | Q17: -163915 | R17: -265541 | S17: -59664 | T17: -44643 | U17: -37678 | V17: -61157 | W17: -70465 | X17: -57267 | Y17: -63336 | Z17: -78497 | AA17: -75083 | AB17: -80965 | AC17: -121828 | AD17: -155612 | AE17: -164293 | AF17: -161634 | AG17: -106197 | AH17: -170320 | AI17: -269988 | AJ17: -379246
... A31: 9 | B31: 1 | G31: moeda | H31: Participação de acionistas não controladores / Non-controlling interest (l.163) | J31: fonte | K31: -198384 | L31: -125868 | M31: -265868 | N31: -523297 | O31: -337471 | P31: -344143 | Q31: -188716 | R31: -137085 | S31: -307900 | T31: -187923 | U31: -134594 | V31: -114990 | W31: -156618 | X31: -117395 | Y31: -67187 | Z31: -115723 | AA31: -147894 | AB31: -156347 | AC31: -281625 | AD31: -187950 | AE31: -186523 | AF31: -138966 | AG31: -43206 | AH31: -148939 | AI31: -139779 | AJ31: -295846
H32: DRE - subtotais divulgados (memoria)
G33: moeda | H33: Receita operacional bruta / Gross Operating Revenue (l.103) | J33: memoria | K33: 1338224 | L33: 1131336 | M33: 1637498 | N33: 2638007 | O33: 1758370 | P33: 1473384 | Q33: 1278329 | R33: 1293116 | S33: 1411922 | T33: 1287605 | U33: 723119 | V33: 827359 | W33: 1111563 | X33: 837522 | Y33: 725648 | Z33: 959172 | AA33: 1101762 | AB33: 1054085 | AC33: 1027683 | AD33: 1228671 | AE33: 1348963 | AF33: 1158576 | AG33: 1069998 | AH33: 1284340 | AI33: 1390042 | AJ33: 1792119
G34: moeda | H34: Custos / Costs (l.129) | J34: memoria | K34: -604040 | L34: -623099 | M34: -769661 | N34: -702755 | O34: -498916 | P34: -229551 | Q34: -330583 | R34: -340576 | S34: -170289 | T34: -158203 | U34: -166680 | V34: -197481 | W34: -194916 | X34: -171600 | Y34: -201159 | Z34: -230092 | AA34: -209529 | AB34: -222927 | AC34: -291307 | AD34: -371210 | AE34: -334776 | AF34: -326528 | AG34: -291604 | AH34: -385200 | AI34: -460362 | AJ34: -573656
G35: moeda | H35: Lucro antes do resultado financeiro / Income before financial result (l.143) | J35: memoria | K35: 581800 | L35: 372133 | M35: 699950 | N35: 1664671 | O35: 1078685 | P35: 1100133 | Q35: 858378 | R35: 742816 | S35: 1093036 | T35: 836673 | U35: 450425 | V35: 485821 | W35: 776774 | X35: 599764 | Y35: 414163 | Z35: 566994 | AA35: 768929 | AB35: 741690 | AC35: 646938 | AD35: 735079 | AE35: 891274 | AF35: 555102 | AG35: 936989 | AH35: 731154 | AI35: 755987 | AJ35: 1005418
G36: moeda | H36: Despesas financeiras / Financial Expenses (l.145) | J36: memoria | K36: -110320 | L36: -84432 | M36: -104796 | N36: -213505 | O36: -220925 | P36: -220616 | Q36: -312051 | R36: -269776 | S36: -275120 | T36: -409748 | U36: -255871 | V36: -279287 | W36: -354499 | X36: -264197 | Y36: -286255 | Z36: -254432 | AA36: -326855 | AB36: -314151 | AC36: -275474 | AD36: -353327 | AE36: -379058 | AF36: -320431 | AG36: -311305 | AH36: -319449 | AI36: -398261 | AJ36: -367445
G37: moeda | H37: Receitas financeiras / Financial Revenue (l.149) | J37: memoria | K37: 18050 | L37: 15361 | M37: 7682 | N37: 10221 | O37: 10815 | P37: 19481 | Q37: 24304 | R37: 53223 | S37: 49812 | T37: 68796 | U37: 73153 | V37: 62139 | W37: 69850 | X37: 69451 | Y37: 72068 | Z37: 70582 | AA37: 72974 | AB37: 80069 | AC37: 84033 | AD37: 81612 | AE37: 104321 | AF37: 114439 | AG37: 98737 | AH37: 140909 | AI37: 96147 | AJ37: 129420
G38: moeda | H38: Lucro antes da Contribuição social e Imposto de Renda / Income before social contribution and income tax (l.153) | J38: memoria | K38: 489530 | L38: 303062 | M38: 602836 | N38: 1461387 | O38: 868575 | P38: 898998 | Q38: 570631 | R38: 526263 | S38: 867728 | T38: 495721 | U38: 267707 | V38: 268673 | W38: 492125 | X38: 405018 | Y38: 199976 | Z38: 383144 | AA38: 515048 | AB38: 507608 | AC38: 455497 | AD38: 463364 | AE38: 616537 | AF38: 349110 | AG38: 724421 | AH38: 552614 | AI38: 453873 | AJ38: 767393
G39: moeda | H39: Lucro antes da participação de não controladores / Net Income before the non-controlling interest (l.161) | J39: memoria | K39: 377533 | L39: 197977 | M39: 447082 | N39: 1032913 | O39: 660887 | P39: 676488 | Q39: 429032 | R39: 356409 | S39: 738879 | T39: 367931 | U39: 250270 | V39: 306793 | W39: 387328 | X39: 339581 | Y39: 167192 | Z39: 256885 | AA39: 402838 | AB39: 393417 | AC39: 645379 | AD39: 418272 | AE39: 485300 | AF39: 283833 | AG39: 532596 | AH39: 431464 | AI39: 337846 | AJ39: 712472
A40: 44 | B40: 1 | G40: moeda | H40: Lucro Líquido do Exercício / Net Income (l.165) - COD 44 alimenta o check IS do Model (linha 4) | J40: memoria | K40: 179149 | L40: 72109 | M40: 181214 | N40: 509616 | O40: 323416 | P40: 332345 | Q40: 240316 | R40: 219324 | S40: 430979 | T40: 180008 | U40: 115676 | V40: 191803 | W40: 230710 | X40: 222186 | Y40: 100005 | Z40: 141162 | AA40: 254944 | AB40: 237070 | AC40: 363754 | AD40: 230322 | AE40: 298777 | AF40: 144867 | AG40: 489390 | AH40: 282525 | AI40: 198067 | AJ40: 416626
H41: BALANCO (R$ mil, saldo de fim de trimestre). 3T23: bloco do PL realinhado (ver nota na linha do capital social)
A42: 11 | B42: 1 | G42: moeda | H42: Caixa equivalentes de caixa / Cash and Cash Equivalents (l.10) | J42: fonte | K42: 628105 | L42: 606617 | M42: 632296 | N42: 674609 | O42: 523159 | P42: 438465 | Q42: 409127 | R42: 377119 | S42: 449213 | T42: 545253 | U42: 864019 | V42: 850481 | W42: 1073717 | X42: 812592 | Y42: 935306 | Z42: 823209 | AA42: 949533 | AB42: 1172596 | AC42: 1193159 | AD42: 807229 | AE42: 957628 | AF42: 754650 | AG42: 569032 | AH42: 685881 | AI42: 792531 | AJ42: 759240
A43: 11 | B43: 1 | G43: moeda | H43: Investimento de curto prazo / Short-Term Investments (l.11) | J43: fonte | K43: 2791013 | L43: 2154637 | M43: 1727186 | N43: 1405506 | O43: 1365101 | P43: 1247469 | Q43: 1082196 | R43: 1553503 | S43: 1547125 | T43: 1759164 | U43: 1557031 | V43: 1836607 | W43: 1764906 | X43: 1638665 | Y43: 1621571 | Z43: 1852958 | AA43: 1864486 | AB43: 2427255 | AC43: 2142870 | AD43: 2571896 | AE43: 2537074 | AF43: 2789111 | AG43: 2470434 | AH43: 2387700 | AI43: 4262531 | AJ43: 4456479
A44: 11 | B44: 1 | G44: moeda | H44: Títulos e valores mobiliários / Marketable Securities (l.12) | J44: fonte | K44: 2730 | L44: 753 | M44: 2805 | N44: 767 | O44: 3118 | P44: 1390 | Q44: 3292 | R44: 971 | S44: 3843 | T44: 1000 | U44: 3919 | V44: 1304 | W44: 4726 | X44: 144573 | Y44: 159321 | Z44: 155384 | AA44: 176368 | AB44: 157159 | AC44: 173071 | AD44: 165134 | AE44: 183496 | AF44: 152659 | AG44: 184721 | AH44: 155040 | AI44: 191095 | AJ44: 156202
A45: 12 | B45: 1 | G45: moeda | H45: Contas a receber de clientes / Trade Accounts Receivable (l.13) | J45: fonte | K45: 330399 | L45: 328061 | M45: 365380 | N45: 415353 | O45: 338682 | P45: 345885 | Q45: 378626 | R45: 391698 | S45: 363277 | T45: 377686 | U45: 412736 | V45: 448279 | W45: 476539 | X45: 292699 | Y45: 338637 | Z45: 288702 | AA45: 262889 | AB45: 270403 | AC45: 274293 | AD45: 283923 | AE45: 259685 | AF45: 247846 | AG45: 212361 | AH45: 186798 | AI45: 191285 | AJ45: 349127
A46: 16 | B46: 1 | G46: moeda | H46: Partes relacionadas / Related Parties (l.14) | J46: fonte | K46: 175 | L46: 75 | M46: 75 | N46: 75 | O46: 75 | P46: 75 | Q46: 75 | R46: 75 | S46: 75 | T46: 75 | U46: 75 | V46: 75 | W46: 75 | X46: 75 | Y46: 75 | Z46: 75 | AA46: 75 | AB46: 75 | AC46: 75 | AD46: 75 | AE46: 75 | AF46: 75 | AG46: 75 | AH46: 75 | AI46: 75 | AJ46: 75
A47: 16 | B47: 1 | G47: moeda | H47: Impostos a recuperar / Taxes Recoverable (l.15) | J47: fonte | K47: 149911 | L47: 166766 | M47: 172836 | N47: 141160 | O47: 139170 | P47: 81235 | Q47: 85561 | R47: 98802 | S47: 105997 | T47: 117108 | U47: 121285 | V47: 173299 | W47: 171089 | X47: 189566 | Y47: 194828 | Z47: 178974 | AA47: 181205 | AB47: 207146 | AC47: 213207 | AD47: 208344 | AE47: 220975 | AF47: 239885 | AG47: 254571 | AH47: 251346 | AI47: 270761 | AJ47: 345598
A48: 16 | B48: 1 | G48: moeda | H48: Adiantamento a fornecedores / Advance for Suppliers (l.16) | J48: fonte | K48: 16951 | L48: 29556 | M48: 40329 | N48: 79744 | O48: 80879 | P48: 133118 | Q48: 137094 | R48: 171482 | S48: 86932 | T48: 92680 | U48: 86795 | V48: 87668 | W48: 64542 | X48: 64631 | Y48: 65819 | Z48: 50802 | AA48: 51187 | AB48: 42193 | AC48: 41413 | AD48: 44304 | AE48: 35956 | AF48: 47139 | AG48: 85990 | AH48: 135800 | AI48: 172192 | AJ48: 176510
A49: 13 | B49: 1 | G49: moeda | H49: Estoques / Inventories (l.17) | J49: fonte | K49: 9723 | L49: 8082 | M49: 8244 | N49: 7856 | O49: 7969 | P49: 8386 | Q49: 8389 | R49: 8245 | S49: 8368 | T49: 8455 | U49: 8952 | V49: 9201 | W49: 9061 | X49: 9397 | Y49: 17446 | Z49: 10278 | AA49: 9874 | AB49: 9229 | AC49: 9486 | AD49: 9766 | AE49: 10107 | AF49: 9833 | AG49: 9692 | AH49: 10472 | AI49: 10780 | AJ49: 11141
A50: 16 | B50: 1 | G50: moeda | H50: Cauções e depósitos judiciais / Judicial Deposits (l.18) | J50: fonte | K50: 550 | L50: 384 | M50: 384 | N50: 384 | O50: 384 | P50: 384 | Q50: 384 | R50: 384 | S50: 384 | T50: 384 | U50: 384 | V50: 384 | W50: 384 | X50: 384 | Y50: 384 | Z50: 384 | AA50: 384 | AB50: 384 | AC50: 384 | AD50: 120 | AE50: 120 | AF50: 0 | AG50: 0 | AH50: 0 | AI50: 0 | AJ50: 0
A51: 15 | B51: 1 | G51: moeda | H51: Despesas pagas antecipadamente / Prepaid Expenses (l.19) | J51: fonte | K51: 3616 | L51: 1454 | M51: 6391 | N51: 5828 | O51: 4979 | P51: 10437 | Q51: 9944 | R51: 8251 | S51: 7110 | T51: 11678 | U51: 13120 | V51: 13602 | W51: 7204 | X51: 9983 | Y51: 9189 | Z51: 12141 | AA51: 7964 | AB51: 11090 | AC51: 10329 | AD51: 9961 | AE51: 8499 | AF51: 9341 | AG51: 12455 | AH51: 10900 | AI51: 11131 | AJ51: 12761
A52: 16 | B52: 1 | G52: moeda | H52: Ativo financeiro da concessão / Accounts Receivable - Concession Assets (l.20) | J52: fonte | K52: 0 | L52: 0 | M52: 0 | N52: 0 | O52: 0 | P52: 0 | Q52: 0 | R52: 0 | S52: 0 | T52: 0 | U52: 0 | V52: 0 | W52: 0 | X52: 0 | Y52: 0 | Z52: 0 | AA52: 0 | AB52: 0 | AC52: 0 | AD52: 0 | AE52: 0 | AF52: 0 | AG52: 0 | AH52: 0 | AI52: 0 | AJ52: 0
A53: 16 | B53: 1 | G53: moeda | H53: Contas a receber ativo contratual / Accounts Receivable - Contractual Assets (l.21) | J53: fonte | K53: 977687 | L53: 920963 | M53: 1033622 | N53: 1290362 | O53: 1499674 | P53: 1581795 | Q53: 1596466 | R53: 1701139 | S53: 1869931 | T53: 1911593 | U53: 1897690 | V53: 1909364 | W53: 1980098 | X53: 1969683 | Y53: 1976654 | Z53: 1984827 | AA53: 2034340 | AB53: 2062113 | AC53: 2065735 | AD53: 2098105 | AE53: 2148936 | AF53: 2231278 | AG53: 2246629 | AH53: 2254400 | AI53: 2274328 | AJ53: 2359837
... A114: 35 | B114: 1 | G114: moeda | H114: Participação de acionistas não controladores / Non-controlling interest (l.94) | J114: fonte | K114: 2615278 | L114: 2695718 | M114: 2904541 | N114: 3194564 | O114: 3518758 | P114: 3613423 | Q114: 3681275 | R114: 3450486 | S114: 3649408 | T114: 3594617 | U114: 3476338 | V114: 3413556 | W114: 3560059 | X114: 3384892 | Y114: 3320519 | Z114: 3273249 | AA114: 3423454 | AB114: 3448681 | AC114: 3695059 | AD114: 3483372 | AE114: 3664272 | AF114: 3483293 | AG114: 3360623 | AH114: 3412620 | AI114: 3543062 | AJ114: 3738333
...

Sheet Inputs (2)
A1: =COUNTIF($B$3:$B$1048576,$B$1) -> 1 | B1: =MAX($B$3:$B$1048576) -> 100
D2: 1Q21 | E2: 2Q21 | F2: 3Q21 | G2: 4Q21 | H2: 2021 | I2: 1Q22 | J2: 2Q22 | K2: 3Q22 | L2: 4Q22 | M2: 2022 | N2: 1Q23 | O2: 2Q23 | P2: 3Q23 | Q2: 4Q23 | R2: 2023 | S2: 1Q24 | T2: 2Q24 | U2: 3Q24 | V2: 4Q24 | W2: 2024 | X2: 1Q25 | Y2: 2Q25 | Z2: 3Q25 | AA2: 4Q25 | AB2: 2025 | AC2: 1Q26 | AD2: 2Q26 | AE2: 3Q26 | AF2: 4Q26 | AG2: 2026 | AH2: 1Q20 | AI2: 2Q20 | AJ2: 3Q20 | AK2: 4Q20 | AL2: 2020 | AN2: Sem dado na fonte: 3Q26, 4Q26 e 2026 (rotulo em cinza). 2020 fica nas colunas AH-AL.
B4: 1 | C4: Net Revenues | D4: =IF(ISNA(MATCH(D$2,Inputs!$K$4:$AJ$4,0)),NA(),IF(SUMPRODUCT((Inputs!$A$5:$A$230=$B4)*ISNUMBER(INDEX(Inputs!$K$5:$AJ$230,0,MATCH(D$2,Inputs!$K$4:$AJ$4,0))))+SUMPRODUCT((Inputs!$C$5:$C$230=$B4)*ISNUMBER(INDEX(Inputs!$K$5:$AJ$230,0,MATCH(D$2,Inputs!$K$4:$AJ$4,0))))+SUMPRODUCT((Inputs!$E$5:$E$230=$B4)*ISNUMBER(INDEX(Inputs!$K$5:$AJ$230,0,MATCH(D$2,Inputs!$K$4:$AJ$4,0))))=0,NA(),SUMPRODUCT((Inputs!$A$5:$A$230=$B4)*Inputs!$B$5:$B$230*(((Inputs!$G$5:$G$230="moeda")+(Inputs!$G$5:$G$230="acoes"))*Inputs!$B$1+((Inputs!$G$5:$G$230<>"moeda")*(Inputs!$G$5:$G$230<>"acoes")))*INDEX(Inputs!$K$5:$AJ$230,0,MATCH(D$2,Inputs!$K$4:$AJ$4,0)))+SUMPRODUCT((Inputs!$C$5:$C$230=$B4)*Inputs!$D$5:$D$230*(((Inputs!$G$5:$G$230="moeda")+(Inputs!$G$5:$G$230="acoes"))*Inputs!$B$1+((Inputs!$G$5:$G$230<>"moeda")*(Inputs!$G$5:$G$230<>"acoes")))*INDEX(Inputs!$K$5:$AJ$230,0,MATCH(D$2,Inputs!$K$4:$AJ$4,0)))+SUMPRODUCT((Inputs!$E$5:$E$230=$B4)*Inputs!$F$5:$F$230*(((Inputs!$G$5:$G$230="moeda")+(Inputs!$G$5:$G$230="acoes"))*Inputs!$B$1+((Inputs!$G$5:$G$230<>"moeda")*(Inputs!$G$5:$G$230<>"acoes")))*INDEX(Inputs!$K$5:$AJ$230,0,MATCH(D$2,Inputs!$K$4:$AJ$4,0))))) -> 1601.474 | E4: =IF(ISNA(MATCH(E$2,Inputs!$K$4:$AJ$4,0)),NA(),IF(SUMPRODUCT((Inputs!$A$5:$A$230=$B4)*ISNUMBER(INDEX(Inputs!$K$5:$AJ$230,0,MATCH(E$2,Inputs!$K$4:$AJ$4,0))))+SUMPRODUCT((Inputs!$C$5:$C$230=$B4)*ISNUMBER(INDEX(Inputs!$K$5:$AJ$230,0,MATCH(E$2,Inputs!$K$4:$AJ$4,0))))+SUMPRODUCT((Inputs!$E$5:$E$230=$B4)*ISNUMBER(INDEX(Inputs!$K$5:$AJ$230,0,MATCH(E$2,Inputs!$K$4:$AJ$4,0))))=0,NA(),SUMPRODUCT((Inputs!$A$5:$A$230=$B4)*Inputs!$B$5:$B$230*(((Inputs!$G$5:$G$230="moeda")+(Inputs!$G$5:$G$230="acoes"))*Inputs!$B$1+((Inputs!$G$5:$G$230<>"moeda")*(Inputs!$G$5:$G$230<>"acoes")))*INDEX(Inputs!$K$5:$AJ$230,0,MATCH(E$2,Inputs!$K$4:$AJ$4,0)))+SUMPRODUCT((Inputs!$C$5:$C$230=$B4)*Inputs!$D$5:$D$230*(((Inputs!$G$5:$G$230="moeda")+(Inputs!$G$5:$G$230="acoes"))*Inputs!$B$1+((Inputs!$G$5:$G$230<>"moeda")*(Inputs!$G$5:$G$230<>"acoes")))*INDEX(Inputs!$K$5:$AJ$230,0,MATCH(E$2,Inputs!$K$4:$AJ$4,0)))+SUMPRODUCT((Inputs!$E$5:$E$230=$B4)*Inputs!$F$5:$F$230*(((Inputs!$G$5:$G$230="moeda")+(Inputs!$G$5:$G$230="acoes"))*Inputs!$B$1+((Inputs!$G$5:$G$230<>"moeda")*(Inputs!$G$5:$G$230<>"acoes")))*INDEX(Inputs!$K$5:$AJ$230,0,MATCH(E$2,Inputs!$K$4:$AJ$4,0))))) -> 1337.141 | F4: =IF(ISNA(MATCH(F$2,Inputs!$K$4:$AJ$4,0)),NA(),IF(SUMPRODUCT((Inputs!$A$5:$A$230=$B4)*ISNUMBER(INDEX(Inputs!$K$5:$AJ$230,0,MATCH(F$2,Inputs!$K$4:$AJ$4,0))))+SUMPRODUCT((Inputs!$C$5:$C$230=$B4)*ISNUMBER(INDEX(Inputs!$K$5:$AJ$230,0,MATCH(F$2,Inputs!$K$4:$AJ$4,0))))+SUMPRODUCT((Inputs!$E$5:$E$230=$B4)*ISNUMBER(INDEX(Inputs!$K$5:$AJ$230,0,MATCH(F$2,Inputs!$K$4:$AJ$4,0))))=0,NA(),SUMPRODUCT((Inputs!$A$5:$A$230=$B4)*Inputs!$B$5:$B$230*(((Inputs!$G$5:$G$230="moeda")+(Inputs!$G$5:$G$230="acoes"))*Inputs!$B$1+((Inputs!$G$5:$G$230<>"moeda")*(Inputs!$G$5:$G$230<>"acoes")))*INDEX(Inputs!$K$5:$AJ$230,0,MATCH(F$2,Inputs!$K$4:$AJ$4,0)))+SUMPRODUCT((Inputs!$C$5:$C$230=$B4)*Inputs!$D$5:$D$230*(((Inputs!$G$5:$G$230="moeda")+(Inputs!$G$5:$G$230="acoes"))*Inputs!$B$1+((Inputs!$G$5:$G$230<>"moeda")*(Inputs!$G$5:$G$230<>"acoes")))*INDEX(Inputs!$K$5:$AJ$230,0,MATCH(F$2,Inputs!$K$4:$AJ$4,0)))+SUMPRODUCT((Inputs!$E$5:$E$230=$B4)*Inputs!$F$5:$F$230*(((Inputs!$G$5:$G$230="moeda")+(Inputs!$G$5:$G$230="acoes"))*Inputs!$B$1+((Inputs!$G$5:$G$230<>"moeda")*(Inputs!$G$5:$G$230<>"acoes")))*INDEX(Inputs!$K$5:$AJ$230,0,MATCH(F$2,Inputs!$K$4:$AJ$4,0))))) -> 1167.652 | G4: =IF(ISNA(MATCH(G$2,Inputs!$K$4:$AJ$4,0)),NA(),IF(SUMPRODUCT((Inputs!$A$5:$A$230=$B4)*ISNUMBER(INDEX(Inputs!$K$5:$AJ$230,0,MATCH(G$2,Inputs!$K$4:$AJ$4,0))))+SUMPRODUCT((Inputs!$C$5:$C$230=$B4)*ISNUMBER(INDEX(Inputs!$K$5:$AJ$230,0,MATCH(G$2,Inputs!$K$4:$AJ$4,0))))+SUMPRODUCT((Inputs!$E$5:$E$230=$B4)*ISNUMBER(INDEX(Inputs!$K$5:$AJ$230,0,MATCH(G$2,Inputs!$K$4:$AJ$4,0))))=0,NA(),SUMPRODUCT((Inputs!$A$5:$A$230=$B4)*Inputs!$B$5:$B$230*(((Inputs!$G$5:$G$230="moeda")+(Inputs!$G$5:$G$230="acoes"))*Inputs!$B$1+((Inputs!$G$5:$G$230<>"moeda")*(Inputs!$G$5:$G$230<>"acoes")))*INDEX(Inputs!$K$5:$AJ$230,0,MATCH(G$2,Inputs!$K$4:$AJ$4,0)))+SUMPRODUCT((Inputs!$C$5:$C$230=$B4)*Inputs!$D$5:$D$230*(((Inputs!$G$5:$G$230="moeda")+(Inputs!$G$5:$G$230="acoes"))*Inputs!$B$1+((Inputs!$G$5:$G$230<>"moeda")*(Inputs!$G$5:$G$230<>"acoes")))*INDEX(Inputs!$K$5:$AJ$230,0,MATCH(G$2,Inputs!$K$4:$AJ$4,0)))+SUMPRODUCT((Inputs!$E$5:$E$230=$B4)*Inputs!$F$5:$F$230*(((Inputs!$G$5:$G$230="moeda")+(Inputs!$G$5:$G$230="acoes"))*Inputs!$B$1+((Inputs!$G$5:$G$230<>"moeda")*(Inputs!$G$5:$G$230<>"acoes")))*INDEX(Inputs!$K$5:$AJ$230,0,MATCH(G$2,Inputs!$K$4:$AJ$4,0))))) -> 1127.941 | H4: =SUM(D4:G4) -> 5234.208 | I4: =IF(ISNA(MATCH(I$2,Inputs!$K$4:$AJ$4,0)),NA(),IF(SUMPRODUCT((Inputs!$A$5:$A$230=$B4)*ISNUMBER(INDEX(Inputs!$K$5:$AJ$230,0,MATCH(I$2,Inputs!$K$4:$AJ$4,0))))+SUMPRODUCT((Inputs!$C$5:$C$230=$B4)*ISNUMBER(INDEX(Inputs!$K$5:$AJ$230,0,MATCH(I$2,Inputs!$K$4:$AJ$4,0))))+SUMPRODUCT((Inputs!$E$5:$E$230=$B4)*ISNUMBER(INDEX(Inputs!$K$5:$AJ$230,0,MATCH(I$2,Inputs!$K$4:$AJ$4,0))))=0,NA(),SUMPRODUCT((Inputs!$A$5:$A$230=$B4)*Inputs!$B$5:$B$230*(((Inputs!$G$5:$G$230="moeda")+(Inputs!$G$5:$G$230="acoes"))*Inputs!$B$1+((Inputs!$G$5:$G$230<>"moeda")*(Inputs!$G$5:$G$230<>"acoes")))*INDEX(Inputs!$K$5:$AJ$230,0,MATCH(I$2,Inputs!$K$4:$AJ$4,0)))+SUMPRODUCT((Inputs!$C$5:$C$230=$B4)*Inputs!$D$5:$D$230*(((Inputs!$G$5:$G$230="moeda")+(Inputs!$G$5:$G$230="acoes"))*Inputs!$B$1+((Inputs!$G$5:$G$230<>"moeda")*(Inputs!$G$5:$G$230<>"acoes")))*INDEX(Inputs!$K$5:$AJ$230,0,MATCH(I$2,Inputs!$K$4:$AJ$4,0)))+SUMPRODUCT((Inputs!$E$5:$E$230=$B4)*Inputs!$F$5:$F$230*(((Inputs!$G$5:$G$230="moeda")+(Inputs!$G$5:$G$230="acoes"))*Inputs!$B$1+((Inputs!$G$5:$G$230<>"moeda")*(Inputs!$G$5:$G$230<>"acoes")))*INDEX(Inputs!$K$5:$AJ$230,0,MATCH(I$2,Inputs!$K$4:$AJ$4,0))))) -> 1280.52 | J4: =IF(ISNA(MATCH(J$2,Inputs!$K$4:$AJ$4,0)),NA(),IF(SUMPRODUCT((Inputs!$A$5:$A$230=$B4)*ISNUMBER(INDEX(Inputs!$K$5:$AJ$230,0,MATCH(J$2,Inputs!$K$4:$AJ$4,0))))+SUMPRODUCT((Inputs!$C$5:$C$230=$B4)*ISNUMBER(INDEX(Inputs!$K$5:$AJ$230,0,MATCH(J$2,Inputs!$K$4:$AJ$4,0))))+SUMPRODUCT((Inputs!$E$5:$E$230=$B4)*ISNUMBER(INDEX(Inputs!$K$5:$AJ$230,0,MATCH(J$2,Inputs!$K$4:$AJ$4,0))))=0,NA(),SUMPRODUCT((Inputs!$A$5:$A$230=$B4)*Inputs!$B$5:$B$230*(((Inputs!$G$5:$G$230="moeda")+(Inputs!$G$5:$G$230="acoes"))*Inputs!$B$1+((Inputs!$G$5:$G$230<>"moeda")*(Inputs!$G$5:$G$230<>"acoes")))*INDEX(Inputs!$K$5:$AJ$230,0,MATCH(J$2,Inputs!$K$4:$AJ$4,0)))+SUMPRODUCT((Inputs!$C$5:$C$230=$B4)*Inputs!$D$5:$D$230*(((Inputs!$G$5:$G$230="moeda")+(Inputs!$G$5:$G$230="acoes"))*Inputs!$B$1+((Inputs!$G$5:$G$230<>"moeda")*(Inputs!$G$5:$G$230<>"acoes")))*INDEX(Inputs!$K$5:$AJ$230,0,MATCH(J$2,Inputs!$K$4:$AJ$4,0)))+SUMPRODUCT((Inputs!$E$5:$E$230=$B4)*Inputs!$F$5:$F$230*(((Inputs!$G$5:$G$230="moeda")+(Inputs!$G$5:$G$230="acoes"))*Inputs!$B$1+((Inputs!$G$5:$G$230<>"moeda")*(Inputs!$G$5:$G$230<>"acoes")))*INDEX(Inputs!$K$5:$AJ$230,0,MATCH(J$2,Inputs!$K$4:$AJ$4,0))))) -> 1168.243 | K4: =IF(ISNA(MATCH(K$2,Inputs!$K$4:$AJ$4,0)),NA(),IF(SUMPRODUCT((Inputs!$A$5:$A$230=$B4)*ISNUMBER(INDEX(Inputs!$K$5:$AJ$230,0,MATCH(K$2,Inputs!$K$4:$AJ$4,0))))+SUMPRODUCT((Inputs!$C$5:$C$230=$B4)*ISNUMBER(INDEX(Inputs!$K$5:$AJ$230,0,MATCH(K$2,Inputs!$K$4:$AJ$4,0))))+SUMPRODUCT((Inputs!$E$5:$E$230=$B4)*ISNUMBER(INDEX(Inputs!$K$5:$AJ$230,0,MATCH(K$2,Inputs!$K$4:$AJ$4,0))))=0,NA(),SUMPRODUCT((Inputs!$A$5:$A$230=$B4)*Inputs!$B$5:$B$230*(((Inputs!$G$5:$G$230="moeda")+(Inputs!$G$5:$G$230="acoes"))*Inputs!$B$1+((Inputs!$G$5:$G$230<>"moeda")*(Inputs!$G$5:$G$230<>"acoes")))*INDEX(Inputs!$K$5:$AJ$230,0,MATCH(K$2,Inputs!$K$4:$AJ$4,0)))+SUMPRODUCT((Inputs!$C$5:$C$230=$B4)*Inputs!$D$5:$D$230*(((Inputs!$G$5:$G$230="moeda")+(Inputs!$G$5:$G$230="acoes"))*Inputs!$B$1+((Inputs!$G$5:$G$230<>"moeda")*(Inputs!$G$5:$G$230<>"acoes")))*INDEX(Inputs!$K$5:$AJ$230,0,MATCH(K$2,Inputs!$K$4:$AJ$4,0)))+SUMPRODUCT((Inputs!$E$5:$E$230=$B4)*Inputs!$F$5:$F$230*(((Inputs!$G$5:$G$230="moeda")+(Inputs!$G$5:$G$230="acoes"))*Inputs!$B$1+((Inputs!$G$5:$G$230<>"moeda")*(Inputs!$G$5:$G$230<>"acoes")))*INDEX(Inputs!$K$5:$AJ$230,0,MATCH(K$2,Inputs!$K$4:$AJ$4,0))))) -> 652.659 | L4: =IF(ISNA(MATCH(L$2,Inputs!$K$4:$AJ$4,0)),NA(),IF(SUMPRODUCT((Inputs!$A$5:$A$230=$B4)*ISNUMBER(INDEX(Inputs!$K$5:$AJ$230,0,MATCH(L$2,Inputs!$K$4:$AJ$4,0))))+SUMPRODUCT((Inputs!$C$5:$C$230=$B4)*ISNUMBER(INDEX(Inputs!$K$5:$AJ$230,0,MATCH(L$2,Inputs!$K$4:$AJ$4,0))))+SUMPRODUCT((Inputs!$E$5:$E$230=$B4)*ISNUMBER(INDEX(Inputs!$K$5:$AJ$230,0,MATCH(L$2,Inputs!$K$4:$AJ$4,0))))=0,NA(),SUMPRODUCT((Inputs!$A$5:$A$230=$B4)*Inputs!$B$5:$B$230*(((Inputs!$G$5:$G$230="moeda")+(Inputs!$G$5:$G$230="acoes"))*Inputs!$B$1+((Inputs!$G$5:$G$230<>"moeda")*(Inputs!$G$5:$G$230<>"acoes")))*INDEX(Inputs!$K$5:$AJ$230,0,MATCH(L$2,Inputs!$K$4:$AJ$4,0)))+SUMPRODUCT((Inputs!$C$5:$C$230=$B4)*Inputs!$D$5:$D$230*(((Inputs!$G$5:$G$230="moeda")+(Inputs!$G$5:$G$230="acoes"))*Inputs!$B$1+((Inputs!$G$5:$G$230<>"moeda")*(Inputs!$G$5:$G$230<>"acoes")))*INDEX(Inputs!$K$5:$AJ$230,0,MATCH(L$2,Inputs!$K$4:$AJ$4,0)))+SUMPRODUCT((Inputs!$E$5:$E$230=$B4)*Inputs!$F$5:$F$230*(((Inputs!$G$5:$G$230="moeda")+(Inputs!$G$5:$G$230="acoes"))*Inputs!$B$1+((Inputs!$G$5:$G$230<>"moeda")*(Inputs!$G$5:$G$230<>"acoes")))*INDEX(Inputs!$K$5:$AJ$230,0,MATCH(L$2,Inputs!$K$4:$AJ$4,0))))) -> 732.286 | M4: =SUM(I4:L4) -> 3833.708 | N4: =IF(ISNA(MATCH(N$2,Inputs!$K$4:$AJ$4,0)),NA(),IF(SUMPRODUCT((Inputs!$A$5:$A$230=$B4)*ISNUMBER(INDEX(Inputs!$K$5:$AJ$230,0,MATCH(N$2,Inputs!$K$4:$AJ$4,0))))+SUMPRODUCT((Inputs!$C$5:$C$230=$B4)*ISNUMBER(INDEX(Inputs!$K$5:$AJ$230,0,MATCH(N$2,Inputs!$K$4:$AJ$4,0))))+SUMPRODUCT((Inputs!$E$5:$E$230=$B4)*ISNUMBER(INDEX(Inputs!$K$5:$AJ$230,0,MATCH(N$2,Inputs!$K$4:$AJ$4,0))))=0,NA(),SUMPRODUCT((Inputs!$A$5:$A$230=$B4)*Inputs!$B$5:$B$230*(((Inputs!$G$5:$G$230="moeda")+(Inputs!$G$5:$G$230="acoes"))*Inputs!$B$1+((Inputs!$G$5:$G$230<>"moeda")*(Inputs!$G$5:$G$230<>"acoes")))*INDEX(Inputs!$K$5:$AJ$230,0,MATCH(N$2,Inputs!$K$4:$AJ$4,0)))+SUMPRODUCT((Inputs!$C$5:$C$230=$B4)*Inputs!$D$5:$D$230*(((Inputs!$G$5:$G$230="moeda")+(Inputs!$G$5:$G$230="acoes"))*Inputs!$B$1+((Inputs!$G$5:$G$230<>"moeda")*(Inputs!$G$5:$G$230<>"acoes")))*INDEX(Inputs!$K$5:$AJ$230,0,MATCH(N$2,Inputs!$K$4:$AJ$4,0)))+SUMPRODUCT((Inputs!$E$5:$E$230=$B4)*Inputs!$F$5:$F$230*(((Inputs!$G$5:$G$230="moeda")+(Inputs!$G$5:$G$230="acoes"))*Inputs!$B$1+((Inputs!$G$5:$G$230<>"moeda")*(Inputs!$G$5:$G$230<>"acoes")))*INDEX(Inputs!$K$5:$AJ$230,0,MATCH(N$2,Inputs!$K$4:$AJ$4,0))))) -> 1003.997 | O4: =IF(ISNA(MATCH(O$2,Inputs!$K$4:$AJ$4,0)),NA(),IF(SUMPRODUCT((Inputs!$A$5:$A$230=$B4)*ISNUMBER(INDEX(Inputs!$K$5:$AJ$230,0,MATCH(O$2,Inputs!$K$4:$AJ$4,0))))+SUMPRODUCT((Inputs!$C$5:$C$230=$B4)*ISNUMBER(INDEX(Inputs!$K$5:$AJ$230,0,MATCH(O$2,Inputs!$K$4:$AJ$4,0))))+SUMPRODUCT((Inputs!$E$5:$E$230=$B4)*ISNUMBER(INDEX(Inputs!$K$5:$AJ$230,0,MATCH(O$2,Inputs!$K$4:$AJ$4,0))))=0,NA(),SUMPRODUCT((Inputs!$A$5:$A$230=$B4)*Inputs!$B$5:$B$230*(((Inputs!$G$5:$G$230="moeda")+(Inputs!$G$5:$G$230="acoes"))*Inputs!$B$1+((Inputs!$G$5:$G$230<>"moeda")*(Inputs!$G$5:$G$230<>"acoes")))*INDEX(Inputs!$K$5:$AJ$230,0,MATCH(O$2,Inputs!$K$4:$AJ$4,0)))+SUMPRODUCT((Inputs!$C$5:$C$230=$B4)*Inputs!$D$5:$D$230*(((Inputs!$G$5:$G$230="moeda")+(Inputs!$G$5:$G$230="acoes"))*Inputs!$B$1+((Inputs!$G$5:$G$230<>"moeda")*(Inputs!$G$5:$G$230<>"acoes")))*INDEX(Inputs!$K$5:$AJ$230,0,MATCH(O$2,Inputs!$K$4:$AJ$4,0)))+SUMPRODUCT((Inputs!$E$5:$E$230=$B4)*Inputs!$F$5:$F$230*(((Inputs!$G$5:$G$230="moeda")+(Inputs!$G$5:$G$230="acoes"))*Inputs!$B$1+((Inputs!$G$5:$G$230<>"moeda")*(Inputs!$G$5:$G$230<>"acoes")))*INDEX(Inputs!$K$5:$AJ$230,0,MATCH(O$2,Inputs!$K$4:$AJ$4,0))))) -> 780.156 | P4: =IF(ISNA(MATCH(P$2,Inputs!$K$4:$AJ$4,0)),NA(),IF(SUMPRODUCT((Inputs!$A$5:$A$230=$B4)*ISNUMBER(INDEX(Inputs!$K$5:$AJ$230,0,MATCH(P$2,Inputs!$K$4:$AJ$4,0))))+SUMPRODUCT((Inputs!$C$5:$C$230=$B4)*ISNUMBER(INDEX(Inputs!$K$5:$AJ$230,0,MATCH(P$2,Inputs!$K$4:$AJ$4,0))))+SUMPRODUCT((Inputs!$E$5:$E$230=$B4)*ISNUMBER(INDEX(Inputs!$K$5:$AJ$230,0,MATCH(P$2,Inputs!$K$4:$AJ$4,0))))=0,NA(),SUMPRODUCT((Inputs!$A$5:$A$230=$B4)*Inputs!$B$5:$B$230*(((Inputs!$G$5:$G$230="moeda")+(Inputs!$G$5:$G$230="acoes"))*Inputs!$B$1+((Inputs!$G$5:$G$230<>"moeda")*(Inputs!$G$5:$G$230<>"acoes")))*INDEX(Inputs!$K$5:$AJ$230,0,MATCH(P$2,Inputs!$K$4:$AJ$4,0)))+SUMPRODUCT((Inputs!$C$5:$C$230=$B4)*Inputs!$D$5:$D$230*(((Inputs!$G$5:$G$230="moeda")+(Inputs!$G$5:$G$230="acoes"))*Inputs!$B$1+((Inputs!$G$5:$G$230<>"moeda")*(Inputs!$G$5:$G$230<>"acoes")))*INDEX(Inputs!$K$5:$AJ$230,0,MATCH(P$2,Inputs!$K$4:$AJ$4,0)))+SUMPRODUCT((Inputs!$E$5:$E$230=$B4)*Inputs!$F$5:$F$230*(((Inputs!$G$5:$G$230="moeda")+(Inputs!$G$5:$G$230="acoes"))*Inputs!$B$1+((Inputs!$G$5:$G$230<>"moeda")*(Inputs!$G$5:$G$230<>"acoes")))*INDEX(Inputs!$K$5:$AJ$230,0,MATCH(P$2,Inputs!$K$4:$AJ$4,0))))) -> 648.957 | Q4: =IF(ISNA(MATCH(Q$2,Inputs!$K$4:$AJ$4,0)),NA(),IF(SUMPRODUCT((Inputs!$A$5:$A$230=$B4)*ISNUMBER(INDEX(Inputs!$K$5:$AJ$230,0,MATCH(Q$2,Inputs!$K$4:$AJ$4,0))))+SUMPRODUCT((Inputs!$C$5:$C$230=$B4)*ISNUMBER(INDEX(Inputs!$K$5:$AJ$230,0,MATCH(Q$2,Inputs!$K$4:$AJ$4,0))))+SUMPRODUCT((Inputs!$E$5:$E$230=$B4)*ISNUMBER(INDEX(Inputs!$K$5:$AJ$230,0,MATCH(Q$2,Inputs!$K$4:$AJ$4,0))))=0,NA(),SUMPRODUCT((Inputs!$A$5:$A$230=$B4)*Inputs!$B$5:$B$230*(((Inputs!$G$5:$G$230="moeda")+(Inputs!$G$5:$G$230="acoes"))*Inputs!$B$1+((Inputs!$G$5:$G$230<>"moeda")*(Inputs!$G$5:$G$230<>"acoes")))*INDEX(Inputs!$K$5:$AJ$230,0,MATCH(Q$2,Inputs!$K$4:$AJ$4,0)))+SUMPRODUCT((Inputs!$C$5:$C$230=$B4)*Inputs!$D$5:$D$230*(((Inputs!$G$5:$G$230="moeda")+(Inputs!$G$5:$G$230="acoes"))*Inputs!$B$1+((Inputs!$G$5:$G$230<>"moeda")*(Inputs!$G$5:$G$230<>"acoes")))*INDEX(Inputs!$K$5:$AJ$230,0,MATCH(Q$2,Inputs!$K$4:$AJ$4,0)))+SUMPRODUCT((Inputs!$E$5:$E$230=$B4)*Inputs!$F$5:$F$230*(((Inputs!$G$5:$G$230="moeda")+(Inputs!$G$5:$G$230="acoes"))*Inputs!$B$1+((Inputs!$G$5:$G$230<>"moeda")*(Inputs!$G$5:$G$230<>"acoes")))*INDEX(Inputs!$K$5:$AJ$230,0,MATCH(Q$2,Inputs!$K$4:$AJ$4,0))))) -> 878.271 | R4: =SUM(N4:Q4) -> 3311.381 | S4: =IF(ISNA(MATCH(S$2,Inputs!$K$4:$AJ$4,0)),NA(),IF(SUMPRODUCT((Inputs!$A$5:$A$230=$B4)*ISNUMBER(INDEX(Inputs!$K$5:$AJ$230,0,MATCH(S$2,Inputs!$K$4:$AJ$4,0))))+SUMPRODUCT((Inputs!$C$5:$C$230=$B4)*ISNUMBER(INDEX(Inputs!$K$5:$AJ$230,0,MATCH(S$2,Inputs!$K$4:$AJ$4,0))))+SUMPRODUCT((Inputs!$E$5:$E$230=$B4)*ISNUMBER(INDEX(Inputs!$K$5:$AJ$230,0,MATCH(S$2,Inputs!$K$4:$AJ$4,0))))=0,NA(),SUMPRODUCT((Inputs!$A$5:$A$230=$B4)*Inputs!$B$5:$B$230*(((Inputs!$G$5:$G$230="moeda")+(Inputs!$G$5:$G$230="acoes"))*Inputs!$B$1+((Inputs!$G$5:$G$230<>"moeda")*(Inputs!$G$5:$G$230<>"acoes")))*INDEX(Inputs!$K$5:$AJ$230,0,MATCH(S$2,Inputs!$K$4:$AJ$4,0)))+SUMPRODUCT((Inputs!$C$5:$C$230=$B4)*Inputs!$D$5:$D$230*(((Inputs!$G$5:$G$230="moeda")+(Inputs!$G$5:$G$230="acoes"))*Inputs!$B$1+((Inputs!$G$5:$G$230<>"moeda")*(Inputs!$G$5:$G$230<>"acoes")))*INDEX(Inputs!$K$5:$AJ$230,0,MATCH(S$2,Inputs!$K$4:$AJ$4,0)))+SUMPRODUCT((Inputs!$E$5:$E$230=$B4)*Inputs!$F$5:$F$230*(((Inputs!$G$5:$G$230="moeda")+(Inputs!$G$5:$G$230="acoes"))*Inputs!$B$1+((Inputs!$G$5:$G$230<>"moeda")*(Inputs!$G$5:$G$230<>"acoes")))*INDEX(Inputs!$K$5:$AJ$230,0,MATCH(S$2,Inputs!$K$4:$AJ$4,0))))) -> 996.535 | T4: =IF(ISNA(MATCH(T$2,Inputs!$K$4:$AJ$4,0)),NA(),IF(SUMPRODUCT((Inputs!$A$5:$A$230=$B4)*ISNUMBER(INDEX(Inputs!$K$5:$AJ$230,0,MATCH(T$2,Inputs!$K$4:$AJ$4,0))))+SUMPRODUCT((Inputs!$C$5:$C$230=$B4)*ISNUMBER(INDEX(Inputs!$K$5:$AJ$230,0,MATCH(T$2,Inputs!$K$4:$AJ$4,0))))+SUMPRODUCT((Inputs!$E$5:$E$230=$B4)*ISNUMBER(INDEX(Inputs!$K$5:$AJ$230,0,MATCH(T$2,Inputs!$K$4:$AJ$4,0))))=0,NA(),SUMPRODUCT((Inputs!$A$5:$A$230=$B4)*Inputs!$B$5:$B$230*(((Inputs!$G$5:$G$230="moeda")+(Inputs!$G$5:$G$230="acoes"))*Inputs!$B$1+((Inputs!$G$5:$G$230<>"moeda")*(Inputs!$G$5:$G$230<>"acoes")))*INDEX(Inputs!$K$5:$AJ$230,0,MATCH(T$2,Inputs!$K$4:$AJ$4,0)))+SUMPRODUCT((Inputs!$C$5:$C$230=$B4)*Inputs!$D$5:$D$230*(((Inputs!$G$5:$G$230="moeda")+(Inputs!$G$5:$G$230="acoes"))*Inputs!$B$1+((Inputs!$G$5:$G$230<>"moeda")*(Inputs!$G$5:$G$230<>"acoes")))*INDEX(Inputs!$K$5:$AJ$230,0,MATCH(T$2,Inputs!$K$4:$AJ$4,0)))+SUMPRODUCT((Inputs!$E$5:$E$230=$B4)*Inputs!$F$5:$F$230*(((Inputs!$G$5:$G$230="moeda")+(Inputs!$G$5:$G$230="acoes"))*Inputs!$B$1+((Inputs!$G$5:$G$230<>"moeda")*(Inputs!$G$5:$G$230<>"acoes")))*INDEX(Inputs!$K$5:$AJ$230,0,MATCH(T$2,Inputs!$K$4:$AJ$4,0))))) -> 953.692 | U4: =IF(ISNA(MATCH(U$2,Inputs!$K$4:$AJ$4,0)),NA(),IF(SUMPRODUCT((Inputs!$A$5:$A$230=$B4)*ISNUMBER(INDEX(Inputs!$K$5:$AJ$230,0,MATCH(U$2,Inputs!$K$4:$AJ$4,0))))+SUMPRODUCT((Inputs!$C$5:$C$230=$B4)*ISNUMBER(INDEX(Inputs!$K$5:$AJ$230,0,MATCH(U$2,Inputs!$K$4:$AJ$4,0))))+SUMPRODUCT((Inputs!$E$5:$E$230=$B4)*ISNUMBER(INDEX(Inputs!$K$5:$AJ$230,0,MATCH(U$2,Inputs!$K$4:$AJ$4,0))))=0,NA(),SUMPRODUCT((Inputs!$A$5:$A$230=$B4)*Inputs!$B$5:$B$230*(((Inputs!$G$5:$G$230="moeda")+(Inputs!$G$5:$G$230="acoes"))*Inputs!$B$1+((Inputs!$G$5:$G$230<>"moeda")*(Inputs!$G$5:$G$230<>"acoes")))*INDEX(Inputs!$K$5:$AJ$230,0,MATCH(U$2,Inputs!$K$4:$AJ$4,0)))+SUMPRODUCT((Inputs!$C$5:$C$230=$B4)*Inputs!$D$5:$D$230*(((Inputs!$G$5:$G$230="moeda")+(Inputs!$G$5:$G$230="acoes"))*Inputs!$B$1+((Inputs!$G$5:$G$230<>"moeda")*(Inputs!$G$5:$G$230<>"acoes")))*INDEX(Inputs!$K$5:$AJ$230,0,MATCH(U$2,Inputs!$K$4:$AJ$4,0)))+SUMPRODUCT((Inputs!$E$5:$E$230=$B4)*Inputs!$F$5:$F$230*(((Inputs!$G$5:$G$230="moeda")+(Inputs!$G$5:$G$230="acoes"))*Inputs!$B$1+((Inputs!$G$5:$G$230<>"moeda")*(Inputs!$G$5:$G$230<>"acoes")))*INDEX(Inputs!$K$5:$AJ$230,0,MATCH(U$2,Inputs!$K$4:$AJ$4,0))))) -> 928.567 | V4: =IF(ISNA(MATCH(V$2,Inputs!$K$4:$AJ$4,0)),NA(),IF(SUMPRODUCT((Inputs!$A$5:$A$230=$B4)*ISNUMBER(INDEX(Inputs!$K$5:$AJ$230,0,MATCH(V$2,Inputs!$K$4:$AJ$4,0))))+SUMPRODUCT((Inputs!$C$5:$C$230=$B4)*ISNUMBER(INDEX(Inputs!$K$5:$AJ$230,0,MATCH(V$2,Inputs!$K$4:$AJ$4,0))))+SUMPRODUCT((Inputs!$E$5:$E$230=$B4)*ISNUMBER(INDEX(Inputs!$K$5:$AJ$230,0,MATCH(V$2,Inputs!$K$4:$AJ$4,0))))=0,NA(),SUMPRODUCT((Inputs!$A$5:$A$230=$B4)*Inputs!$B$5:$B$230*(((Inputs!$G$5:$G$230="moeda")+(Inputs!$G$5:$G$230="acoes"))*Inputs!$B$1+((Inputs!$G$5:$G$230<>"moeda")*(Inputs!$G$5:$G$230<>"acoes")))*INDEX(Inputs!$K$5:$AJ$230,0,MATCH(V$2,Inputs!$K$4:$AJ$4,0)))+SUMPRODUCT((Inputs!$C$5:$C$230=$B4)*Inputs!$D$5:$D$230*(((Inputs!$G$5:$G$230="moeda")+(Inputs!$G$5:$G$230="acoes"))*Inputs!$B$1+((Inputs!$G$5:$G$230<>"moeda")*(Inputs!$G$5:$G$230<>"acoes")))*INDEX(Inputs!$K$5:$AJ$230,0,MATCH(V$2,Inputs!$K$4:$AJ$4,0)))+SUMPRODUCT((Inputs!$E$5:$E$230=$B4)*Inputs!$F$5:$F$230*(((Inputs!$G$5:$G$230="moeda")+(Inputs!$G$5:$G$230="acoes"))*Inputs!$B$1+((Inputs!$G$5:$G$230<>"moeda")*(Inputs!$G$5:$G$230<>"acoes")))*INDEX(Inputs!$K$5:$AJ$230,0,MATCH(V$2,Inputs!$K$4:$AJ$4,0))))) -> 1123.31 | W4: =SUM(S4:V4) -> 4002.104 | X4: =IF(ISNA(MATCH(X$2,Inputs!$K$4:$AJ$4,0)),NA(),IF(SUMPRODUCT((Inputs!$A$5:$A$230=$B4)*ISNUMBER(INDEX(Inputs!$K$5:$AJ$230,0,MATCH(X$2,Inputs!$K$4:$AJ$4,0))))+SUMPRODUCT((Inputs!$C$5:$C$230=$B4)*ISNUMBER(INDEX(Inputs!$K$5:$AJ$230,0,MATCH(X$2,Inputs!$K$4:$AJ$4,0))))+SUMPRODUCT((Inputs!$E$5:$E$230=$B4)*ISNUMBER(INDEX(Inputs!$K$5:$AJ$230,0,MATCH(X$2,Inputs!$K$4:$AJ$4,0))))=0,NA(),SUMPRODUCT((Inputs!$A$5:$A$230=$B4)*Inputs!$B$5:$B$230*(((Inputs!$G$5:$G$230="moeda")+(Inputs!$G$5:$G$230="acoes"))*Inputs!$B$1+((Inputs!$G$5:$G$230<>"moeda")*(Inputs!$G$5:$G$230<>"acoes")))*INDEX(Inputs!$K$5:$AJ$230,0,MATCH(X$2,Inputs!$K$4:$AJ$4,0)))+SUMPRODUCT((Inputs!$C$5:$C$230=$B4)*Inputs!$D$5:$D$230*(((Inputs!$G$5:$G$230="moeda")+(Inputs!$G$5:$G$230="acoes"))*Inputs!$B$1+((Inputs!$G$5:$G$230<>"moeda")*(Inputs!$G$5:$G$230<>"acoes")))*INDEX(Inputs!$K$5:$AJ$230,0,MATCH(X$2,Inputs!$K$4:$AJ$4,0)))+SUMPRODUCT((Inputs!$E$5:$E$230=$B4)*Inputs!$F$5:$F$230*(((Inputs!$G$5:$G$230="moeda")+(Inputs!$G$5:$G$230="acoes"))*Inputs!$B$1+((Inputs!$G$5:$G$230<>"moeda")*(Inputs!$G$5:$G$230<>"acoes")))*INDEX(Inputs!$K$5:$AJ$230,0,MATCH(X$2,Inputs!$K$4:$AJ$4,0))))) -> 1223.731 | Y4: =IF(ISNA(MATCH(Y$2,Inputs!$K$4:$AJ$4,0)),NA(),IF(SUMPRODUCT((Inputs!$A$5:$A$230=$B4)*ISNUMBER(INDEX(Inputs!$K$5:$AJ$230,0,MATCH(Y$2,Inputs!$K$4:$AJ$4,0))))+SUMPRODUCT((Inputs!$C$5:$C$230=$B4)*ISNUMBER(INDEX(Inputs!$K$5:$AJ$230,0,MATCH(Y$2,Inputs!$K$4:$AJ$4,0))))+SUMPRODUCT((Inputs!$E$5:$E$230=$B4)*ISNUMBER(INDEX(Inputs!$K$5:$AJ$230,0,MATCH(Y$2,Inputs!$K$4:$AJ$4,0))))=0,NA(),SUMPRODUCT((Inputs!$A$5:$A$230=$B4)*Inputs!$B$5:$B$230*(((Inputs!$G$5:$G$230="moeda")+(Inputs!$G$5:$G$230="acoes"))*Inputs!$B$1+((Inputs!$G$5:$G$230<>"moeda")*(Inputs!$G$5:$G$230<>"acoes")))*INDEX(Inputs!$K$5:$AJ$230,0,MATCH(Y$2,Inputs!$K$4:$AJ$4,0)))+SUMPRODUCT((Inputs!$C$5:$C$230=$B4)*Inputs!$D$5:$D$230*(((Inputs!$G$5:$G$230="moeda")+(Inputs!$G$5:$G$230="acoes"))*Inputs!$B$1+((Inputs!$G$5:$G$230<>"moeda")*(Inputs!$G$5:$G$230<>"acoes")))*INDEX(Inputs!$K$5:$AJ$230,0,MATCH(Y$2,Inputs!$K$4:$AJ$4,0)))+SUMPRODUCT((Inputs!$E$5:$E$230=$B4)*Inputs!$F$5:$F$230*(((Inputs!$G$5:$G$230="moeda")+(Inputs!$G$5:$G$230="acoes"))*Inputs!$B$1+((Inputs!$G$5:$G$230<>"moeda")*(Inputs!$G$5:$G$230<>"acoes")))*INDEX(Inputs!$K$5:$AJ$230,0,MATCH(Y$2,Inputs!$K$4:$AJ$4,0))))) -> 1047.14 | Z4: =IF(ISNA(MATCH(Z$2,Inputs!$K$4:$AJ$4,0)),NA(),IF(SUMPRODUCT((Inputs!$A$5:$A$230=$B4)*ISNUMBER(INDEX(Inputs!$K$5:$AJ$230,0,MATCH(Z$2,Inputs!$K$4:$AJ$4,0))))+SUMPRODUCT((Inputs!$C$5:$C$230=$B4)*ISNUMBER(INDEX(Inputs!$K$5:$AJ$230,0,MATCH(Z$2,Inputs!$K$4:$AJ$4,0))))+SUMPRODUCT((Inputs!$E$5:$E$230=$B4)*ISNUMBER(INDEX(Inputs!$K$5:$AJ$230,0,MATCH(Z$2,Inputs!$K$4:$AJ$4,0))))=0,NA(),SUMPRODUCT((Inputs!$A$5:$A$230=$B4)*Inputs!$B$5:$B$230*(((Inputs!$G$5:$G$230="moeda")+(Inputs!$G$5:$G$230="acoes"))*Inputs!$B$1+((Inputs!$G$5:$G$230<>"moeda")*(Inputs!$G$5:$G$230<>"acoes")))*INDEX(Inputs!$K$5:$AJ$230,0,MATCH(Z$2,Inputs!$K$4:$AJ$4,0)))+SUMPRODUCT((Inputs!$C$5:$C$230=$B4)*Inputs!$D$5:$D$230*(((Inputs!$G$5:$G$230="moeda")+(Inputs!$G$5:$G$230="acoes"))*Inputs!$B$1+((Inputs!$G$5:$G$230<>"moeda")*(Inputs!$G$5:$G$230<>"acoes")))*INDEX(Inputs!$K$5:$AJ$230,0,MATCH(Z$2,Inputs!$K$4:$AJ$4,0)))+SUMPRODUCT((Inputs!$E$5:$E$230=$B4)*Inputs!$F$5:$F$230*(((Inputs!$G$5:$G$230="moeda")+(Inputs!$G$5:$G$230="acoes"))*Inputs!$B$1+((Inputs!$G$5:$G$230<>"moeda")*(Inputs!$G$5:$G$230<>"acoes")))*INDEX(Inputs!$K$5:$AJ$230,0,MATCH(Z$2,Inputs!$K$4:$AJ$4,0))))) -> 963.353 | AA4: =IF(ISNA(MATCH(AA$2,Inputs!$K$4:$AJ$4,0)),NA(),IF(SUMPRODUCT((Inputs!$A$5:$A$230=$B4)*ISNUMBER(INDEX(Inputs!$K$5:$AJ$230,0,MATCH(AA$2,Inputs!$K$4:$AJ$4,0))))+SUMPRODUCT((Inputs!$C$5:$C$230=$B4)*ISNUMBER(INDEX(Inputs!$K$5:$AJ$230,0,MATCH(AA$2,Inputs!$K$4:$AJ$4,0))))+SUMPRODUCT((Inputs!$E$5:$E$230=$B4)*ISNUMBER(INDEX(Inputs!$K$5:$AJ$230,0,MATCH(AA$2,Inputs!$K$4:$AJ$4,0))))=0,NA(),SUMPRODUCT((Inputs!$A$5:$A$230=$B4)*Inputs!$B$5:$B$230*(((Inputs!$G$5:$G$230="moeda")+(Inputs!$G$5:$G$230="acoes"))*Inputs!$B$1+((Inputs!$G$5:$G$230<>"moeda")*(Inputs!$G$5:$G$230<>"acoes")))*INDEX(Inputs!$K$5:$AJ$230,0,MATCH(AA$2,Inputs!$K$4:$AJ$4,0)))+SUMPRODUCT((Inputs!$C$5:$C$230=$B4)*Inputs!$D$5:$D$230*(((Inputs!$G$5:$G$230="moeda")+(Inputs!$G$5:$G$230="acoes"))*Inputs!$B$1+((Inputs!$G$5:$G$230<>"moeda")*(Inputs!$G$5:$G$230<>"acoes")))*INDEX(Inputs!$K$5:$AJ$230,0,MATCH(AA$2,Inputs!$K$4:$AJ$4,0)))+SUMPRODUCT((Inputs!$E$5:$E$230=$B4)*Inputs!$F$5:$F$230*(((Inputs!$G$5:$G$230="moeda")+(Inputs!$G$5:$G$230="acoes"))*Inputs!$B$1+((Inputs!$G$5:$G$230<>"moeda")*(Inputs!$G$5:$G$230<>"acoes")))*INDEX(Inputs!$K$5:$AJ$230,0,MATCH(AA$2,Inputs!$K$4:$AJ$4,0))))) -> 1163.659 | AB4: =SUM(X4:AA4) -> 4397.883 | AC4: =IF(ISNA(MATCH(AC$2,Inputs!$K$4:$AJ$4,0)),NA(),IF(SUMPRODUCT((Inputs!$A$5:$A$230=$B4)*ISNUMBER(INDEX(Inputs!$K$5:$AJ$230,0,MATCH(AC$2,Inputs!$K$4:$AJ$4,0))))+SUMPRODUCT((Inputs!$C$5:$C$230=$B4)*ISNUMBER(INDEX(Inputs!$K$5:$AJ$230,0,MATCH(AC$2,Inputs!$K$4:$AJ$4,0))))+SUMPRODUCT((Inputs!$E$5:$E$230=$B4)*ISNUMBER(INDEX(Inputs!$K$5:$AJ$230,0,MATCH(AC$2,Inputs!$K$4:$AJ$4,0))))=0,NA(),SUMPRODUCT((Inputs!$A$5:$A$230=$B4)*Inputs!$B$5:$B$230*(((Inputs!$G$5:$G$230="moeda")+(Inputs!$G$5:$G$230="acoes"))*Inputs!$B$1+((Inputs!$G$5:$G$230<>"moeda")*(Inputs!$G$5:$G$230<>"acoes")))*INDEX(Inputs!$K$5:$AJ$230,0,MATCH(AC$2,Inputs!$K$4:$AJ$4,0)))+SUMPRODUCT((Inputs!$C$5:$C$230=$B4)*Inputs!$D$5:$D$230*(((Inputs!$G$5:$G$230="moeda")+(Inputs!$G$5:$G$230="acoes"))*Inputs!$B$1+((Inputs!$G$5:$G$230<>"moeda")*(Inputs!$G$5:$G$230<>"acoes")))*INDEX(Inputs!$K$5:$AJ$230,0,MATCH(AC$2,Inputs!$K$4:$AJ$4,0)))+SUMPRODUCT((Inputs!$E$5:$E$230=$B4)*Inputs!$F$5:$F$230*(((Inputs!$G$5:$G$230="moeda")+(Inputs!$G$5:$G$230="acoes"))*Inputs!$B$1+((Inputs!$G$5:$G$230<>"moeda")*(Inputs!$G$5:$G$230<>"acoes")))*INDEX(Inputs!$K$5:$AJ$230,0,MATCH(AC$2,Inputs!$K$4:$AJ$4,0))))) -> 1255.635 | AD4: =IF(ISNA(MATCH(AD$2,Inputs!$K$4:$AJ$4,0)),NA(),IF(SUMPRODUCT((Inputs!$A$5:$A$230=$B4)*ISNUMBER(INDEX(Inputs!$K$5:$AJ$230,0,MATCH(AD$2,Inputs!$K$4:$AJ$4,0))))+SUMPRODUCT((Inputs!$C$5:$C$230=$B4)*ISNUMBER(INDEX(Inputs!$K$5:$AJ$230,0,MATCH(AD$2,Inputs!$K$4:$AJ$4,0))))+SUMPRODUCT((Inputs!$E$5:$E$230=$B4)*ISNUMBER(INDEX(Inputs!$K$5:$AJ$230,0,MATCH(AD$2,Inputs!$K$4:$AJ$4,0))))=0,NA(),SUMPRODUCT((Inputs!$A$5:$A$230=$B4)*Inputs!$B$5:$B$230*(((Inputs!$G$5:$G$230="moeda")+(Inputs!$G$5:$G$230="acoes"))*Inputs!$B$1+((Inputs!$G$5:$G$230<>"moeda")*(Inputs!$G$5:$G$230<>"acoes")))*INDEX(Inputs!$K$5:$AJ$230,0,MATCH(AD$2,Inputs!$K$4:$AJ$4,0)))+SUMPRODUCT((Inputs!$C$5:$C$230=$B4)*Inputs!$D$5:$D$230*(((Inputs!$G$5:$G$230="moeda")+(Inputs!$G$5:$G$230="acoes"))*Inputs!$B$1+((Inputs!$G$5:$G$230<>"moeda")*(Inputs!$G$5:$G$230<>"acoes")))*INDEX(Inputs!$K$5:$AJ$230,0,MATCH(AD$2,Inputs!$K$4:$AJ$4,0)))+SUMPRODUCT((Inputs!$E$5:$E$230=$B4)*Inputs!$F$5:$F$230*(((Inputs!$G$5:$G$230="moeda")+(Inputs!$G$5:$G$230="acoes"))*Inputs!$B$1+((Inputs!$G$5:$G$230<>"moeda")*(Inputs!$G$5:$G$230<>"acoes")))*INDEX(Inputs!$K$5:$AJ$230,0,MATCH(AD$2,Inputs!$K$4:$AJ$4,0))))) -> 1627.285 | AE4: =IF(ISNA(MATCH(AE$2,Inputs!$K$4:$AJ$4,0)),NA(),IF(SUMPRODUCT((Inputs!$A$5:$A$230=$B4)*ISNUMBER(INDEX(Inputs!$K$5:$AJ$230,0,MATCH(AE$2,Inputs!$K$4:$AJ$4,0))))+SUMPRODUCT((Inputs!$C$5:$C$230=$B4)*ISNUMBER(INDEX(Inputs!$K$5:$AJ$230,0,MATCH(AE$2,Inputs!$K$4:$AJ$4,0))))+SUMPRODUCT((Inputs!$E$5:$E$230=$B4)*ISNUMBER(INDEX(Inputs!$K$5:$AJ$230,0,MATCH(AE$2,Inputs!$K$4:$AJ$4,0))))=0,NA(),SUMPRODUCT((Inputs!$A$5:$A$230=$B4)*Inputs!$B$5:$B$230*(((Inputs!$G$5:$G$230="moeda")+(Inputs!$G$5:$G$230="acoes"))*Inputs!$B$1+((Inputs!$G$5:$G$230<>"moeda")*(Inputs!$G$5:$G$230<>"acoes")))*INDEX(Inputs!$K$5:$AJ$230,0,MATCH(AE$2,Inputs!$K$4:$AJ$4,0)))+SUMPRODUCT((Inputs!$C$5:$C$230=$B4)*Inputs!$D$5:$D$230*(((Inputs!$G$5:$G$230="moeda")+(Inputs!$G$5:$G$230="acoes"))*Inputs!$B$1+((Inputs!$G$5:$G$230<>"moeda")*(Inputs!$G$5:$G$230<>"acoes")))*INDEX(Inputs!$K$5:$AJ$230,0,MATCH(AE$2,Inputs!$K$4:$AJ$4,0)))+SUMPRODUCT((Inputs!$E$5:$E$230=$B4)*Inputs!$F$5:$F$230*(((Inputs!$G$5:$G$230="moeda")+(Inputs!$G$5:$G$230="acoes"))*Inputs!$B$1+((Inputs!$G$5:$G$230<>"moeda")*(Inputs!$G$5:$G$230<>"acoes")))*INDEX(Inputs!$K$5:$AJ$230,0,MATCH(AE$2,Inputs!$K$4:$AJ$4,0))))) -> #N/A | AF4: =IF(ISNA(MATCH(AF$2,Inputs!$K$4:$AJ$4,0)),NA(),IF(SUMPRODUCT((Inputs!$A$5:$A$230=$B4)*ISNUMBER(INDEX(Inputs!$K$5:$AJ$230,0,MATCH(AF$2,Inputs!$K$4:$AJ$4,0))))+SUMPRODUCT((Inputs!$C$5:$C$230=$B4)*ISNUMBER(INDEX(Inputs!$K$5:$AJ$230,0,MATCH(AF$2,Inputs!$K$4:$AJ$4,0))))+SUMPRODUCT((Inputs!$E$5:$E$230=$B4)*ISNUMBER(INDEX(Inputs!$K$5:$AJ$230,0,MATCH(AF$2,Inputs!$K$4:$AJ$4,0))))=0,NA(),SUMPRODUCT((Inputs!$A$5:$A$230=$B4)*Inputs!$B$5:$B$230*(((Inputs!$G$5:$G$230="moeda")+(Inputs!$G$5:$G$230="acoes"))*Inputs!$B$1+((Inputs!$G$5:$G$230<>"moeda")*(Inputs!$G$5:$G$230<>"acoes")))*INDEX(Inputs!$K$5:$AJ$230,0,MATCH(AF$2,Inputs!$K$4:$AJ$4,0)))+SUMPRODUCT((Inputs!$C$5:$C$230=$B4)*Inputs!$D$5:$D$230*(((Inputs!$G$5:$G$230="moeda")+(Inputs!$G$5:$G$230="acoes"))*Inputs!$B$1+((Inputs!$G$5:$G$230<>"moeda")*(Inputs!$G$5:$G$230<>"acoes")))*INDEX(Inputs!$K$5:$AJ$230,0,MATCH(AF$2,Inputs!$K$4:$AJ$4,0)))+SUMPRODUCT((Inputs!$E$5:$E$230=$B4)*Inputs!$F$5:$F$230*(((Inputs!$G$5:$G$230="moeda")+(Inputs!$G$5:$G$230="acoes"))*Inputs!$B$1+((Inputs!$G$5:$G$230<>"moeda")*(Inputs!$G$5:$G$230<>"acoes")))*INDEX(Inputs!$K$5:$AJ$230,0,MATCH(AF$2,Inputs!$K$4:$AJ$4,0))))) -> #N/A | AG4: =SUM(AC4:AF4) -> #N/A | AH4: =IF(ISNA(MATCH(AH$2,Inputs!$K$4:$AJ$4,0)),NA(),IF(SUMPRODUCT((Inputs!$A$5:$A$230=$B4)*ISNUMBER(INDEX(Inputs!$K$5:$AJ$230,0,MATCH(AH$2,Inputs!$K$4:$AJ$4,0))))+SUMPRODUCT((Inputs!$C$5:$C$230=$B4)*ISNUMBER(INDEX(Inputs!$K$5:$AJ$230,0,MATCH(AH$2,Inputs!$K$4:$AJ$4,0))))+SUMPRODUCT((Inputs!$E$5:$E$230=$B4)*ISNUMBER(INDEX(Inputs!$K$5:$AJ$230,0,MATCH(AH$2,Inputs!$K$4:$AJ$4,0))))=0,NA(),SUMPRODUCT((Inputs!$A$5:$A$230=$B4)*Inputs!$B$5:$B$230*(((Inputs!$G$5:$G$230="moeda")+(Inputs!$G$5:$G$230="acoes"))*Inputs!$B$1+((Inputs!$G$5:$G$230<>"moeda")*(Inputs!$G$5:$G$230<>"acoes")))*INDEX(Inputs!$K$5:$AJ$230,0,MATCH(AH$2,Inputs!$K$4:$AJ$4,0)))+SUMPRODUCT((Inputs!$C$5:$C$230=$B4)*Inputs!$D$5:$D$230*(((Inputs!$G$5:$G$230="moeda")+(Inputs!$G$5:$G$230="acoes"))*Inputs!$B$1+((Inputs!$G$5:$G$230<>"moeda")*(Inputs!$G$5:$G$230<>"acoes")))*INDEX(Inputs!$K$5:$AJ$230,0,MATCH(AH$2,Inputs!$K$4:$AJ$4,0)))+SUMPRODUCT((Inputs!$E$5:$E$230=$B4)*Inputs!$F$5:$F$230*(((Inputs!$G$5:$G$230="moeda")+(Inputs!$G$5:$G$230="acoes"))*Inputs!$B$1+((Inputs!$G$5:$G$230<>"moeda")*(Inputs!$G$5:$G$230<>"acoes")))*INDEX(Inputs!$K$5:$AJ$230,0,MATCH(AH$2,Inputs!$K$4:$AJ$4,0))))) -> 1216.927 | AI4: =IF(ISNA(MATCH(AI$2,Inputs!$K$4:$AJ$4,0)),NA(),IF(SUMPRODUCT((Inputs!$A$5:$A$230=$B4)*ISNUMBER(INDEX(Inputs!$K$5:$AJ$230,0,MATCH(AI$2,Inputs!$K$4:$AJ$4,0))))+SUMPRODUCT((Inputs!$C$5:$C$230=$B4)*ISNUMBER(INDEX(Inputs!$K$5:$AJ$230,0,MATCH(AI$2,Inputs!$K$4:$AJ$4,0))))+SUMPRODUCT((Inputs!$E$5:$E$230=$B4)*ISNUMBER(INDEX(Inputs!$K$5:$AJ$230,0,MATCH(AI$2,Inputs!$K$4:$AJ$4,0))))=0,NA(),SUMPRODUCT((Inputs!$A$5:$A$230=$B4)*Inputs!$B$5:$B$230*(((Inputs!$G$5:$G$230="moeda")+(Inputs!$G$5:$G$230="acoes"))*Inputs!$B$1+((Inputs!$G$5:$G$230<>"moeda")*(Inputs!$G$5:$G$230<>"acoes")))*INDEX(Inputs!$K$5:$AJ$230,0,MATCH(AI$2,Inputs!$K$4:$AJ$4,0)))+SUMPRODUCT((Inputs!$C$5:$C$230=$B4)*Inputs!$D$5:$D$230*(((Inputs!$G$5:$G$230="moeda")+(Inputs!$G$5:$G$230="acoes"))*Inputs!$B$1+((Inputs!$G$5:$G$230<>"moeda")*(Inputs!$G$5:$G$230<>"acoes")))*INDEX(Inputs!$K$5:$AJ$230,0,MATCH(AI$2,Inputs!$K$4:$AJ$4,0)))+SUMPRODUCT((Inputs!$E$5:$E$230=$B4)*Inputs!$F$5:$F$230*(((Inputs!$G$5:$G$230="moeda")+(Inputs!$G$5:$G$230="acoes"))*Inputs!$B$1+((Inputs!$G$5:$G$230<>"moeda")*(Inputs!$G$5:$G$230<>"acoes")))*INDEX(Inputs!$K$5:$AJ$230,0,MATCH(AI$2,Inputs!$K$4:$AJ$4,0))))) -> 1026.976 | AJ4: =IF(ISNA(MATCH(AJ$2,Inputs!$K$4:$AJ$4,0)),NA(),IF(SUMPRODUCT((Inputs!$A$5:$A$230=$B4)*ISNUMBER(INDEX(Inputs!$K$5:$AJ$230,0,MATCH(AJ$2,Inputs!$K$4:$AJ$4,0))))+SUMPRODUCT((Inputs!$C$5:$C$230=$B4)*ISNUMBER(INDEX(Inputs!$K$5:$AJ$230,0,MATCH(AJ$2,Inputs!$K$4:$AJ$4,0))))+SUMPRODUCT((Inputs!$E$5:$E$230=$B4)*ISNUMBER(INDEX(Inputs!$K$5:$AJ$230,0,MATCH(AJ$2,Inputs!$K$4:$AJ$4,0))))=0,NA(),SUMPRODUCT((Inputs!$A$5:$A$230=$B4)*Inputs!$B$5:$B$230*(((Inputs!$G$5:$G$230="moeda")+(Inputs!$G$5:$G$230="acoes"))*Inputs!$B$1+((Inputs!$G$5:$G$230<>"moeda")*(Inputs!$G$5:$G$230<>"acoes")))*INDEX(Inputs!$K$5:$AJ$230,0,MATCH(AJ$2,Inputs!$K$4:$AJ$4,0)))+SUMPRODUCT((Inputs!$C$5:$C$230=$B4)*Inputs!$D$5:$D$230*(((Inputs!$G$5:$G$230="moeda")+(Inputs!$G$5:$G$230="acoes"))*Inputs!$B$1+((Inputs!$G$5:$G$230<>"moeda")*(Inputs!$G$5:$G$230<>"acoes")))*INDEX(Inputs!$K$5:$AJ$230,0,MATCH(AJ$2,Inputs!$K$4:$AJ$4,0)))+SUMPRODUCT((Inputs!$E$5:$E$230=$B4)*Inputs!$F$5:$F$230*(((Inputs!$G$5:$G$230="moeda")+(Inputs!$G$5:$G$230="acoes"))*Inputs!$B$1+((Inputs!$G$5:$G$230<>"moeda")*(Inputs!$G$5:$G$230<>"acoes")))*INDEX(Inputs!$K$5:$AJ$230,0,MATCH(AJ$2,Inputs!$K$4:$AJ$4,0))))) -> 1491.323 | AK4: =IF(ISNA(MATCH(AK$2,Inputs!$K$4:$AJ$4,0)),NA(),IF(SUMPRODUCT((Inputs!$A$5:$A$230=$B4)*ISNUMBER(INDEX(Inputs!$K$5:$AJ$230,0,MATCH(AK$2,Inputs!$K$4:$AJ$4,0))))+SUMPRODUCT((Inputs!$C$5:$C$230=$B4)*ISNUMBER(INDEX(Inputs!$K$5:$AJ$230,0,MATCH(AK$2,Inputs!$K$4:$AJ$4,0))))+SUMPRODUCT((Inputs!$E$5:$E$230=$B4)*ISNUMBER(INDEX(Inputs!$K$5:$AJ$230,0,MATCH(AK$2,Inputs!$K$4:$AJ$4,0))))=0,NA(),SUMPRODUCT((Inputs!$A$5:$A$230=$B4)*Inputs!$B$5:$B$230*(((Inputs!$G$5:$G$230="moeda")+(Inputs!$G$5:$G$230="acoes"))*Inputs!$B$1+((Inputs!$G$5:$G$230<>"moeda")*(Inputs!$G$5:$G$230<>"acoes")))*INDEX(Inputs!$K$5:$AJ$230,0,MATCH(AK$2,Inputs!$K$4:$AJ$4,0)))+SUMPRODUCT((Inputs!$C$5:$C$230=$B4)*Inputs!$D$5:$D$230*(((Inputs!$G$5:$G$230="moeda")+(Inputs!$G$5:$G$230="acoes"))*Inputs!$B$1+((Inputs!$G$5:$G$230<>"moeda")*(Inputs!$G$5:$G$230<>"acoes")))*INDEX(Inputs!$K$5:$AJ$230,0,MATCH(AK$2,Inputs!$K$4:$AJ$4,0)))+SUMPRODUCT((Inputs!$E$5:$E$230=$B4)*Inputs!$F$5:$F$230*(((Inputs!$G$5:$G$230="moeda")+(Inputs!$G$5:$G$230="acoes"))*Inputs!$B$1+((Inputs!$G$5:$G$230<>"moeda")*(Inputs!$G$5:$G$230<>"acoes")))*INDEX(Inputs!$K$5:$AJ$230,0,MATCH(AK$2,Inputs!$K$4:$AJ$4,0))))) -> 2405.519 | AL4: =SUM(AH4:AK4) -> 6140.745
