Workbook
Name beta_observed: Valuation!$D$93
Name last_close: Valuation!$G$7
Name ticker: Valuation!$D$7
Name Useful_Life_of_Depreciable_PP_E: "PPElife"
Name beta_observed: #REF!
Name ticker: #REF!
Name costdebtfirm: Valuation!$D$86
Name costequity: Valuation!$D$94
Name debt: Valuation!$G$88
Name debt_weight: Valuation!$J$88
Name g: Valuation!$D$63
Name market_equity: Valuation!$G$89
Name noplat_t1: Valuation!$D$65
Name relevered_beta: Valuation!$M$102
Name risk_free_rate: Valuation!$D$91
Name risk_premium: Valuation!$D$92
Name ronic: Valuation!$D$64
Name stub_year_fraction: Valuation!$D$11
Name totalcap: Valuation!$G$90
Name wacc: Valuation!$D$12

Sheet Inputs
A1: Base histórica normalizada (US$ mil) — convertida da máscara anterior; linhas de origem auditáveis
A2: Fonte / conta original | B2: Código | C2: Conta padronizada | D2: 1Q21 | E2: 2Q21 | F2: 3Q21 | G2: 4Q21 | H2: 2021 | I2: 1Q22 | J2: 2Q22 | K2: 3Q22 | L2: 4Q22 | M2: 2022 | N2: 1Q23 | O2: 2Q23 | P2: 3Q23 | Q2: 4Q23 | R2: 2023 | S2: 1Q24 | T2: 2Q24 | U2: 3Q24 | V2: 4Q24 | W2: 2024 | X2: 1Q25 | Y2: 2Q25 | Z2: 3Q25 | AA2: 4Q25 | AB2: 2025 | AC2: 1Q26 | AD2: 2Q26 | AE2: 3Q26 | AF2: 4Q26 | AG2: 2026
A3: Fonte: ver coluna A de cada linha | C3: Unidade: US$ mil (monetário); demais unidades × 1.000
A4: DRE - BRUTO COMO DIVULGADO (USD). 3M = trimestre do 10-Q (FQ1-FQ3 = 4T, 1T, 2T calendário); 12M = ano fiscal do 10-K (na coluna do 3T calendário); 9M = acumulado do 10-Q de jun (coluna do 2T) | C4: [linha bruta, sem código; lançada nas linhas abaixo]
A5: Receita líquida (net sales) - 3M (10-Q) [us-gaap:RevenueFromContractWithCustomerExcludingAssessedTax] · memoria · unid. moeda | C5: [linha bruta, sem código; lançada nas linhas abaixo] | D5: 89584000 | E5: 81434000 | G5: 123945000 | I5: 97278000 | J5: 82959000 | L5: 117154000 | N5: 94836000 | O5: 81797000 | Q5: 119575000 | S5: 90753000 | T5: 85777000 | V5: 124300000 | X5: 95359000 | Y5: 94036000 | AA5: 143756000 | AC5: 111184000 | AD5: 109417000
A6: Receita líquida (net sales) - ano fiscal 12M (10-K; na coluna do 3T) · memoria · unid. moeda | C6: [linha bruta, sem código; lançada nas linhas abaixo] | F6: 365817000 | K6: 394328000 | P6: 383285000 | U6: 391035000 | Z6: 416161000
A7: Receita líquida (net sales) - 9M acumulado (10-Q de jun; na coluna do 2T) · memoria · unid. moeda | C7: [linha bruta, sem código; lançada nas linhas abaixo] | E7: 282457000 | J7: 304182000 | O7: 293787000 | T7: 296105000 | Y7: 313695000 | AD7: 364357000
A8: Custo das vendas (divulgado positivo) - 3M (10-Q) [us-gaap:CostOfGoodsAndServicesSold] · memoria · unid. moeda | C8: [linha bruta, sem código; lançada nas linhas abaixo] | D8: 51505000 | E8: 46179000 | G8: 69702000 | I8: 54719000 | J8: 47074000 | L8: 66822000 | N8: 52860000 | O8: 45384000 | Q8: 64720000 | S8: 48482000 | T8: 46099000 | V8: 66025000 | X8: 50492000 | Y8: 50318000 | AA8: 74525000 | AC8: 56403000 | AD8: 54647000
A9: Custo das vendas (divulgado positivo) - ano fiscal 12M (10-K; na coluna do 3T) · memoria · unid. moeda | C9: [linha bruta, sem código; lançada nas linhas abaixo] | F9: 212981000 | K9: 223546000 | P9: 214137000 | U9: 210352000 | Z9: 220960000
A10: Custo das vendas (divulgado positivo) - 9M acumulado (10-Q de jun; na coluna do 2T) · memoria · unid. moeda | C10: [linha bruta, sem código; lançada nas linhas abaixo] | E10: 164795000 | J10: 171495000 | O10: 165066000 | T10: 159301000 | Y10: 166835000 | AD10: 185575000
A11: Despesas operacionais totais = P&D + SG&A (divulgado positivo) - 3M (10-Q) [us-gaap:OperatingExpenses] · memoria · unid. moeda | C11: [linha bruta, sem código; lançada nas linhas abaixo] | D11: 10576000 | E11: 11129000 | G11: 12755000 | I11: 12580000 | J11: 12809000 | L11: 14316000 | N11: 13658000 | O11: 13415000 | Q11: 14482000 | S11: 14371000 | T11: 14326000 | V11: 15443000 | X11: 15278000 | Y11: 15516000 | AA11: 18379000 | AC11: 18896000 | AD11: 19075000
A12: Despesas operacionais totais = P&D + SG&A (divulgado positivo) - ano fiscal 12M (10-K; na coluna do 3T) · memoria · unid. moeda | C12: [linha bruta, sem código; lançada nas linhas abaixo] | F12: 43887000 | K12: 51345000 | P12: 54847000 | U12: 57467000 | Z12: 62151000
A13: Despesas operacionais totais = P&D + SG&A (divulgado positivo) - 9M acumulado (10-Q de jun; na coluna do 2T) · memoria · unid. moeda | C13: [linha bruta, sem código; lançada nas linhas abaixo] | E13: 32499000 | J13: 38144000 | O13: 41389000 | T13: 43179000 | Y13: 46237000 | AD13: 56350000
A14: Outras receitas/(despesas), líquido (inclui juros) - 3M (10-Q) [us-gaap:NonoperatingIncomeExpense] · memoria · unid. moeda | C14: [linha bruta, sem código; lançada nas linhas abaixo] | D14: 508000 | E14: 243000 | G14: -247000 | I14: 160000 | J14: -10000 | L14: -393000 | N14: 64000 | O14: -265000 | Q14: -50000 | S14: 158000 | T14: 142000 | V14: -248000 | X14: -279000 | Y14: -171000 | AA14: 150000 | AC14: -52000 | AD14: 572000
A15: Outras receitas/(despesas), líquido (inclui juros) - ano fiscal 12M (10-K; na coluna do 3T) · memoria · unid. moeda | C15: [linha bruta, sem código; lançada nas linhas abaixo] | F15: 258000 | K15: -334000 | P15: -565000 | U15: 269000 | Z15: -321000
A16: Outras receitas/(despesas), líquido (inclui juros) - 9M acumulado (10-Q de jun; na coluna do 2T) · memoria · unid. moeda | C16: [linha bruta, sem código; lançada nas linhas abaixo] | E16: 796000 | J16: -97000 | O16: -594000 | T16: 250000 | Y16: -698000 | AD16: 670000
A17: Imposto de renda (divulgado positivo) - 3M (10-Q) [us-gaap:IncomeTaxExpenseBenefit] · memoria · unid. moeda | C17: [linha bruta, sem código; lançada nas linhas abaixo] | D17: 4381000 | E17: 2625000 | G17: 6611000 | I17: 5129000 | J17: 3624000 | L17: 5625000 | N17: 4222000 | O17: 2852000 | Q17: 6407000 | S17: 4422000 | T17: 4046000 | V17: 6254000 | X17: 4530000 | Y17: 4597000 | AA17: 8905000 | AC17: 6255000 | AD17: 6478000
A18: Imposto de renda (divulgado positivo) - ano fiscal 12M (10-K; na coluna do 3T) · memoria · unid. moeda | C18: [linha bruta, sem código; lançada nas linhas abaixo] | F18: 14527000 | K18: 19300000 | P18: 16741000 | U18: 29749000 | Z18: 20719000
A19: Imposto de renda (divulgado positivo) - 9M acumulado (10-Q de jun; na coluna do 2T) · memoria · unid. moeda | C19: [linha bruta, sem código; lançada nas linhas abaixo] | E19: 11830000 | J19: 15364000 | O19: 12699000 | T19: 14875000 | Y19: 15381000 | AD19: 21638000
A20: Lucro líquido - 3M (10-Q) [us-gaap:NetIncomeLoss] · memoria · unid. moeda | C20: [linha bruta, sem código; lançada nas linhas abaixo] | D20: 23630000 | E20: 21744000 | G20: 34630000 | I20: 25010000 | J20: 19442000 | L20: 29998000 | N20: 24160000 | O20: 19881000 | Q20: 33916000 | S20: 23636000 | T20: 21448000 | V20: 36330000 | X20: 24780000 | Y20: 23434000 | AA20: 42097000 | AC20: 29578000 | AD20: 29789000
A21: Lucro líquido - ano fiscal 12M (10-K; na coluna do 3T) · memoria · unid. moeda | C21: [linha bruta, sem código; lançada nas linhas abaixo] | F21: 94680000 | K21: 99803000 | P21: 96995000 | U21: 93736000 | Z21: 112010000
A22: Lucro líquido - 9M acumulado (10-Q de jun; na coluna do 2T) · memoria · unid. moeda | C22: [linha bruta, sem código; lançada nas linhas abaixo] | E22: 74129000 | J22: 79082000 | O22: 74039000 | T22: 79000000 | Y22: 84544000 | AD22: 101464000
A23: DRE TRIMESTRALIZADA (derivada por fórmula): 3T calendário = ano fiscal - 9M | C23: [linha bruta, sem código; lançada nas linhas abaixo]
A24: Receita líquida (net sales) - trimestre · derivada · unid. moeda | B24: 1 | C24: Net Revenues | D24: =D5 -> 89584000 | E24: =E5 -> 81434000 | F24: =N(F6)-N(E7) -> 83360000 | G24: =G5 -> 123945000 | I24: =I5 -> 97278000 | J24: =J5 -> 82959000 | K24: =N(K6)-N(J7) -> 90146000 | L24: =L5 -> 117154000 | N24: =N5 -> 94836000 | O24: =O5 -> 81797000 | P24: =N(P6)-N(O7) -> 89498000 | Q24: =Q5 -> 119575000 | S24: =S5 -> 90753000 | T24: =T5 -> 85777000 | U24: =N(U6)-N(T7) -> 94930000 | V24: =V5 -> 124300000 | X24: =X5 -> 95359000 | Y24: =Y5 -> 94036000 | Z24: =N(Z6)-N(Y7) -> 102466000 | AA24: =AA5 -> 143756000 | AC24: =AC5 -> 111184000 | AD24: =AD5 -> 109417000
A25: Custo das vendas (divulgado positivo) - trimestre · derivada · unid. moeda | C25: [linha bruta, sem código; lançada nas linhas abaixo] | D25: =D8 -> 51505000 | E25: =E8 -> 46179000 | F25: =N(F9)-N(E10) -> 48186000 | G25: =G8 -> 69702000 | I25: =I8 -> 54719000 | J25: =J8 -> 47074000 | K25: =N(K9)-N(J10) -> 52051000 | L25: =L8 -> 66822000 | N25: =N8 -> 52860000 | O25: =O8 -> 45384000 | P25: =N(P9)-N(O10) -> 49071000 | Q25: =Q8 -> 64720000 | S25: =S8 -> 48482000 | T25: =T8 -> 46099000 | U25: =N(U9)-N(T10) -> 51051000 | V25: =V8 -> 66025000 | X25: =X8 -> 50492000 | Y25: =Y8 -> 50318000 | Z25: =N(Z9)-N(Y10) -> 54125000 | AA25: =AA8 -> 74525000 | AC25: =AC8 -> 56403000 | AD25: =AD8 -> 54647000
A26: (lançamento) código 2, sinal -1 sobre a linha bruta 25: Custo das vendas (divulgado positivo) - trimestre | B26: 2 | C26: COGS (cash) | D26: =IF(D25="","",-1*D25) -> -51505000 | E26: =IF(E25="","",-1*E25) -> -46179000 | F26: =IF(F25="","",-1*F25) -> -48186000 | G26: =IF(G25="","",-1*G25) -> -69702000 | I26: =IF(I25="","",-1*I25) -> -54719000 | J26: =IF(J25="","",-1*J25) -> -47074000 | K26: =IF(K25="","",-1*K25) -> -52051000 | L26: =IF(L25="","",-1*L25) -> -66822000 | N26: =IF(N25="","",-1*N25) -> -52860000 | O26: =IF(O25="","",-1*O25) -> -45384000 | P26: =IF(P25="","",-1*P25) -> -49071000 | Q26: =IF(Q25="","",-1*Q25) -> -64720000 | S26: =IF(S25="","",-1*S25) -> -48482000 | T26: =IF(T25="","",-1*T25) -> -46099000 | U26: =IF(U25="","",-1*U25) -> -51051000 | V26: =IF(V25="","",-1*V25) -> -66025000 | X26: =IF(X25="","",-1*X25) -> -50492000 | Y26: =IF(Y25="","",-1*Y25) -> -50318000 | Z26: =IF(Z25="","",-1*Z25) -> -54125000 | AA26: =IF(AA25="","",-1*AA25) -> -74525000 | AC26: =IF(AC25="","",-1*AC25) -> -56403000 | AD26: =IF(AD25="","",-1*AD25) -> -54647000
A27: Despesas operacionais totais = P&D + SG&A (divulgado positivo) - trimestre · derivada · unid. moeda | C27: [linha bruta, sem código; lançada nas linhas abaixo] | D27: =D11 -> 10576000 | E27: =E11 -> 11129000 | F27: =N(F12)-N(E13) -> 11388000 | G27: =G11 -> 12755000 | I27: =I11 -> 12580000 | J27: =J11 -> 12809000 | K27: =N(K12)-N(J13) -> 13201000 | L27: =L11 -> 14316000 | N27: =N11 -> 13658000 | O27: =O11 -> 13415000 | P27: =N(P12)-N(O13) -> 13458000 | Q27: =Q11 -> 14482000 | S27: =S11 -> 14371000 | T27: =T11 -> 14326000 | U27: =N(U12)-N(T13) -> 14288000 | V27: =V11 -> 15443000 | X27: =X11 -> 15278000 | Y27: =Y11 -> 15516000 | Z27: =N(Z12)-N(Y13) -> 15914000 | AA27: =AA11 -> 18379000 | AC27: =AC11 -> 18896000 | AD27: =AD11 -> 19075000
A28: (lançamento) código 3, sinal -1 sobre a linha bruta 27: Despesas operacionais totais = P&D + SG&A (divulgado positivo) - trimestre | B28: 3 | C28: SG&A and Other (cash) | D28: =IF(D27="","",-1*D27) -> -10576000 | E28: =IF(E27="","",-1*E27) -> -11129000 | F28: =IF(F27="","",-1*F27) -> -11388000 | G28: =IF(G27="","",-1*G27) -> -12755000 | I28: =IF(I27="","",-1*I27) -> -12580000 | J28: =IF(J27="","",-1*J27) -> -12809000 | K28: =IF(K27="","",-1*K27) -> -13201000 | L28: =IF(L27="","",-1*L27) -> -14316000 | N28: =IF(N27="","",-1*N27) -> -13658000 | O28: =IF(O27="","",-1*O27) -> -13415000 | P28: =IF(P27="","",-1*P27) -> -13458000 | Q28: =IF(Q27="","",-1*Q27) -> -14482000 | S28: =IF(S27="","",-1*S27) -> -14371000 | T28: =IF(T27="","",-1*T27) -> -14326000 | U28: =IF(U27="","",-1*U27) -> -14288000 | V28: =IF(V27="","",-1*V27) -> -15443000 | X28: =IF(X27="","",-1*X27) -> -15278000 | Y28: =IF(Y27="","",-1*Y27) -> -15516000 | Z28: =IF(Z27="","",-1*Z27) -> -15914000 | AA28: =IF(AA27="","",-1*AA27) -> -18379000 | AC28: =IF(AC27="","",-1*AC27) -> -18896000 | AD28: =IF(AD27="","",-1*AD27) -> -19075000
A29: Outras receitas/(despesas), líquido (inclui juros) - trimestre · derivada · unid. moeda | B29: 6 | C29: Nonoperating Income / (Loss) | D29: =D14 -> 508000 | E29: =E14 -> 243000 | F29: =N(F15)-N(E16) -> -538000 | G29: =G14 -> -247000 | I29: =I14 -> 160000 | J29: =J14 -> -10000 | K29: =N(K15)-N(J16) -> -237000 | L29: =L14 -> -393000 | N29: =N14 -> 64000 | O29: =O14 -> -265000 | P29: =N(P15)-N(O16) -> 29000 | Q29: =Q14 -> -50000 | S29: =S14 -> 158000 | T29: =T14 -> 142000 | U29: =N(U15)-N(T16) -> 19000 | V29: =V14 -> -248000 | X29: =X14 -> -279000 | Y29: =Y14 -> -171000 | Z29: =N(Z15)-N(Y16) -> 377000 | AA29: =AA14 -> 150000 | AC29: =AC14 -> -52000 | AD29: =AD14 -> 572000
A30: Imposto de renda (divulgado positivo) - trimestre · derivada · unid. moeda | C30: [linha bruta, sem código; lançada nas linhas abaixo] | D30: =D17 -> 4381000 | E30: =E17 -> 2625000 | F30: =N(F18)-N(E19) -> 2697000 | G30: =G17 -> 6611000 | I30: =I17 -> 5129000 | J30: =J17 -> 3624000 | K30: =N(K18)-N(J19) -> 3936000 | L30: =L17 -> 5625000 | N30: =N17 -> 4222000 | O30: =O17 -> 2852000 | P30: =N(P18)-N(O19) -> 4042000 | Q30: =Q17 -> 6407000 | S30: =S17 -> 4422000 | T30: =T17 -> 4046000 | U30: =N(U18)-N(T19) -> 14874000 | V30: =V17 -> 6254000 | X30: =X17 -> 4530000 | Y30: =Y17 -> 4597000 | Z30: =N(Z18)-N(Y19) -> 5338000 | AA30: =AA17 -> 8905000 | AC30: =AC17 -> 6255000 | AD30: =AD17 -> 6478000
A31: (lançamento) código 7, sinal -1 sobre a linha bruta 30: Imposto de renda (divulgado positivo) - trimestre | B31: 7 | C31: Taxes | D31: =IF(D30="","",-1*D30) -> -4381000 | E31: =IF(E30="","",-1*E30) -> -2625000 | F31: =IF(F30="","",-1*F30) -> -2697000 | G31: =IF(G30="","",-1*G30) -> -6611000 | I31: =IF(I30="","",-1*I30) -> -5129000 | J31: =IF(J30="","",-1*J30) -> -3624000 | K31: =IF(K30="","",-1*K30) -> -3936000 | L31: =IF(L30="","",-1*L30) -> -5625000 | N31: =IF(N30="","",-1*N30) -> -4222000 | O31: =IF(O30="","",-1*O30) -> -2852000 | P31: =IF(P30="","",-1*P30) -> -4042000 | Q31: =IF(Q30="","",-1*Q30) -> -6407000 | S31: =IF(S30="","",-1*S30) -> -4422000 | T31: =IF(T30="","",-1*T30) -> -4046000 | U31: =IF(U30="","",-1*U30) -> -14874000 | V31: =IF(V30="","",-1*V30) -> -6254000 | X31: =IF(X30="","",-1*X30) -> -4530000 | Y31: =IF(Y30="","",-1*Y30) -> -4597000 | Z31: =IF(Z30="","",-1*Z30) -> -5338000 | AA31: =IF(AA30="","",-1*AA30) -> -8905000 | AC31: =IF(AC30="","",-1*AC30) -> -6255000 | AD31: =IF(AD30="","",-1*AD30) -> -6478000
A32: Lucro líquido - trimestre · derivada · unid. moeda | B32: 44 | C32: Lucro líquido - trimestre | D32: =D20 -> 23630000 | E32: =E20 -> 21744000 | F32: =N(F21)-N(E22) -> 20551000 | G32: =G20 -> 34630000 | I32: =I20 -> 25010000 | J32: =J20 -> 19442000 | K32: =N(K21)-N(J22) -> 20721000 | L32: =L20 -> 29998000 | N32: =N20 -> 24160000 | O32: =O20 -> 19881000 | P32: =N(P21)-N(O22) -> 22956000 | Q32: =Q20 -> 33916000 | S32: =S20 -> 23636000 | T32: =T20 -> 21448000 | U32: =N(U21)-N(T22) -> 14736000 | V32: =V20 -> 36330000 | X32: =X20 -> 24780000 | Y32: =Y20 -> 23434000 | Z32: =N(Z21)-N(Y22) -> 27466000 | AA32: =AA20 -> 42097000 | AC32: =AC20 -> 29578000 | AD32: =AD20 -> 29789000
A33: DFC - ACUMULADO NO ANO FISCAL (USD): 3M (dez), 6M (mar), 9M (jun), 12M (set) | C33: [linha bruta, sem código; lançada nas linhas abaixo]
A34: Depreciação e amortização - acumulado no ano fiscal [us-gaap:DepreciationDepletionAndAmortization] · memoria · unid. moeda | C34: [linha bruta, sem código; lançada nas linhas abaixo] | D34: 5463000 | E34: 8295000 | F34: 11284000 | G34: 2697000 | I34: 5434000 | J34: 8239000 | K34: 11104000 | L34: 2916000 | N34: 5814000 | O34: 8866000 | P34: 11519000 | Q34: 2848000 | S34: 5684000 | T34: 8534000 | U34: 11445000 | V34: 3080000 | X34: 5741000 | Y34: 8571000 | Z34: 11698000 | AA34: 3214000 | AC34: 6653000 | AD34: 9973000
A35: Depreciação e amortização - out-dez/2019 (3M do 10-Q de dez/19), para desacumular o 1T20 · memoria · unid. moeda | C35: [linha bruta, sem código; lançada nas linhas abaixo]
A36: Dividendos pagos - acumulado no ano fiscal [us-gaap:PaymentsOfDividends] · memoria · unid. moeda | C36: [linha bruta, sem código; lançada nas linhas abaixo] | D36: 7060000 | E36: 10827000 | F36: 14467000 | G36: 3732000 | I36: 7327000 | J36: 11138000 | K36: 14841000 | L36: 3768000 | N36: 7418000 | O36: 11267000 | P36: 15025000 | Q36: 3825000 | S36: 7535000 | T36: 11430000 | U36: 15234000 | V36: 3856000 | X36: 7614000 | Y36: 11559000 | Z36: 15421000 | AA36: 3921000 | AC36: 7743000 | AD36: 11778000
A37: Dividendos pagos - out-dez/2019 (3M do 10-Q de dez/19), para desacumular o 1T20 · memoria · unid. moeda | C37: [linha bruta, sem código; lançada nas linhas abaixo]
A38: D&A trimestral (desacumulada). COD1=4 lança (positivo -> -1); COD2=3 devolve às despesas operacionais (a Apple não abre D&A entre custo e despesa) · derivada · unid. moeda | C38: [linha bruta, sem código; lançada nas linhas abaixo] | D38: =N(D34)-N(N34) -> -351000 | E38: =N(E34)-N(D34) -> 2832000 | F38: =N(F34)-N(E34) -> 2989000 | G38: =N(G34) -> 2697000 | I38: =N(I34)-N(G34) -> 2737000 | J38: =N(J34)-N(I34) -> 2805000 | K38: =N(K34)-N(J34) -> 2865000 | L38: =N(L34) -> 2916000 | N38: =N(N34)-N(L34) -> 2898000 | O38: =N(O34)-N(N34) -> 3052000 | P38: =N(P34)-N(O34) -> 2653000 | Q38: =N(Q34) -> 2848000 | S38: =N(S34)-N(Q34) -> 2836000 | T38: =N(T34)-N(S34) -> 2850000 | U38: =N(U34)-N(T34) -> 2911000 | V38: =N(V34) -> 3080000 | X38: =N(X34)-N(V34) -> 2661000 | Y38: =N(Y34)-N(X34) -> 2830000 | Z38: =N(Z34)-N(Y34) -> 3127000 | AA38: =N(AA34) -> 3214000 | AC38: =N(AC34)-N(AA34) -> 3439000 | AD38: =N(AD34)-N(AC34) -> 3320000
A39: (lançamento) código 4, sinal -1 sobre a linha bruta 38: D&A trimestral (desacumulada). COD1=4 lança (positivo -> -1); COD2=3 devolve às despesas o | B39: 4 | C39: D&A | D39: =IF(D38="","",-1*D38) -> 351000 | E39: =IF(E38="","",-1*E38) -> -2832000 | F39: =IF(F38="","",-1*F38) -> -2989000 | G39: =IF(G38="","",-1*G38) -> -2697000 | I39: =IF(I38="","",-1*I38) -> -2737000 | J39: =IF(J38="","",-1*J38) -> -2805000 | K39: =IF(K38="","",-1*K38) -> -2865000 | L39: =IF(L38="","",-1*L38) -> -2916000 | N39: =IF(N38="","",-1*N38) -> -2898000 | O39: =IF(O38="","",-1*O38) -> -3052000 | P39: =IF(P38="","",-1*P38) -> -2653000 | Q39: =IF(Q38="","",-1*Q38) -> -2848000 | S39: =IF(S38="","",-1*S38) -> -2836000 | T39: =IF(T38="","",-1*T38) -> -2850000 | U39: =IF(U38="","",-1*U38) -> -2911000 | V39: =IF(V38="","",-1*V38) -> -3080000 | X39: =IF(X38="","",-1*X38) -> -2661000 | Y39: =IF(Y38="","",-1*Y38) -> -2830000 | Z39: =IF(Z38="","",-1*Z38) -> -3127000 | AA39: =IF(AA38="","",-1*AA38) -> -3214000 | AC39: =IF(AC38="","",-1*AC38) -> -3439000 | AD39: =IF(AD38="","",-1*AD38) -> -3320000
A40: (lançamento) código 3, sinal +1 sobre a linha bruta 38: D&A trimestral (desacumulada). COD1=4 lança (positivo -> -1); COD2=3 devolve às despesas o | B40: 3 | C40: SG&A and Other (cash) | D40: =IF(D38="","",D38) -> -351000 | E40: =IF(E38="","",E38) -> 2832000 | F40: =IF(F38="","",F38) -> 2989000 | G40: =IF(G38="","",G38) -> 2697000 | I40: =IF(I38="","",I38) -> 2737000 | J40: =IF(J38="","",J38) -> 2805000 | K40: =IF(K38="","",K38) -> 2865000 | L40: =IF(L38="","",L38) -> 2916000 | N40: =IF(N38="","",N38) -> 2898000 | O40: =IF(O38="","",O38) -> 3052000 | P40: =IF(P38="","",P38) -> 2653000 | Q40: =IF(Q38="","",Q38) -> 2848000 | S40: =IF(S38="","",S38) -> 2836000 | T40: =IF(T38="","",T38) -> 2850000 | U40: =IF(U38="","",U38) -> 2911000 | V40: =IF(V38="","",V38) -> 3080000 | X40: =IF(X38="","",X38) -> 2661000 | Y40: =IF(Y38="","",Y38) -> 2830000 | Z40: =IF(Z38="","",Z38) -> 3127000 | AA40: =IF(AA38="","",AA38) -> 3214000 | AC40: =IF(AC38="","",AC38) -> 3439000 | AD40: =IF(AD38="","",AD38) -> 3320000
...

Sheet Inputs (2)
A1: =IF(Control!B3="","EMPRESA",Control!B3) -> Apple Inc. | B1: Código | C1: Conta padronizada | D1: 2021 | E1: 2021 | F1: 2021 | G1: 2021 | H1: 2021 | I1: 2022 | J1: 2022 | K1: 2022 | L1: 2022 | M1: 2022 | N1: 2023 | O1: 2023 | P1: 2023 | Q1: 2023 | R1: 2023 | S1: 2024 | T1: 2024 | U1: 2024 | V1: 2024 | W1: 2024 | X1: 2025 | Y1: 2025 | Z1: 2025 | AA1: 2025 | AB1: 2025 | AC1: 2026 | AD1: 2026 | AE1: 2026 | AF1: 2026 | AG1: 2026
A2: US$ milhões | C2: Período | D2: 1Q21 | E2: 2Q21 | F2: 3Q21 | G2: 4Q21 | H2: 2021 | I2: 1Q22 | J2: 2Q22 | K2: 3Q22 | L2: 4Q22 | M2: 2022 | N2: 1Q23 | O2: 2Q23 | P2: 3Q23 | Q2: 4Q23 | R2: 2023 | S2: 1Q24 | T2: 2Q24 | U2: 3Q24 | V2: 4Q24 | W2: 2024 | X2: 1Q25 | Y2: 2Q25 | Z2: 3Q25 | AA2: 4Q25 | AB2: 2025 | AC2: 1Q26 | AD2: 2Q26 | AE2: 3Q26 | AF2: 4Q26 | AG2: 2026
A3: Actual flag | C3: 0 = sem dados / 1 = realizado | D3: 1 | E3: 1 | F3: 1 | G3: 1 | H3: 1 | I3: 1 | J3: 1 | K3: 1 | L3: 1 | M3: 1 | N3: 1 | O3: 1 | P3: 1 | Q3: 1 | R3: 1 | S3: 1 | T3: 1 | U3: 1 | V3: 1 | W3: 1 | X3: 1 | Y3: 1 | Z3: 1 | AA3: 1 | AB3: 1 | AC3: 1 | AD3: 1 | AE3: 0 | AF3: 0 | AG3: 0
B4: 1 | C4: Net Revenues | D4: =IF(D$3=0,"",SUMIFS(INDEX(Inputs!$D$4:$AG$150,0,MATCH(D$2,Inputs!$D$2:$AG$2,0)),Inputs!$B$4:$B$150,$B4)/1000) -> 89584 | E4: =IF(E$3=0,"",SUMIFS(INDEX(Inputs!$D$4:$AG$150,0,MATCH(E$2,Inputs!$D$2:$AG$2,0)),Inputs!$B$4:$B$150,$B4)/1000) -> 81434 | F4: =IF(F$3=0,"",SUMIFS(INDEX(Inputs!$D$4:$AG$150,0,MATCH(F$2,Inputs!$D$2:$AG$2,0)),Inputs!$B$4:$B$150,$B4)/1000) -> 83360 | G4: =IF(G$3=0,"",SUMIFS(INDEX(Inputs!$D$4:$AG$150,0,MATCH(G$2,Inputs!$D$2:$AG$2,0)),Inputs!$B$4:$B$150,$B4)/1000) -> 123945 | H4: =IF(COUNT(D4:G4)=4,SUM(D4:G4),"") -> 378323 | I4: =IF(I$3=0,"",SUMIFS(INDEX(Inputs!$D$4:$AG$150,0,MATCH(I$2,Inputs!$D$2:$AG$2,0)),Inputs!$B$4:$B$150,$B4)/1000) -> 97278 | J4: =IF(J$3=0,"",SUMIFS(INDEX(Inputs!$D$4:$AG$150,0,MATCH(J$2,Inputs!$D$2:$AG$2,0)),Inputs!$B$4:$B$150,$B4)/1000) -> 82959 | K4: =IF(K$3=0,"",SUMIFS(INDEX(Inputs!$D$4:$AG$150,0,MATCH(K$2,Inputs!$D$2:$AG$2,0)),Inputs!$B$4:$B$150,$B4)/1000) -> 90146 | L4: =IF(L$3=0,"",SUMIFS(INDEX(Inputs!$D$4:$AG$150,0,MATCH(L$2,Inputs!$D$2:$AG$2,0)),Inputs!$B$4:$B$150,$B4)/1000) -> 117154 | M4: =IF(COUNT(I4:L4)=4,SUM(I4:L4),"") -> 387537 | N4: =IF(N$3=0,"",SUMIFS(INDEX(Inputs!$D$4:$AG$150,0,MATCH(N$2,Inputs!$D$2:$AG$2,0)),Inputs!$B$4:$B$150,$B4)/1000) -> 94836 | O4: =IF(O$3=0,"",SUMIFS(INDEX(Inputs!$D$4:$AG$150,0,MATCH(O$2,Inputs!$D$2:$AG$2,0)),Inputs!$B$4:$B$150,$B4)/1000) -> 81797 | P4: =IF(P$3=0,"",SUMIFS(INDEX(Inputs!$D$4:$AG$150,0,MATCH(P$2,Inputs!$D$2:$AG$2,0)),Inputs!$B$4:$B$150,$B4)/1000) -> 89498 | Q4: =IF(Q$3=0,"",SUMIFS(INDEX(Inputs!$D$4:$AG$150,0,MATCH(Q$2,Inputs!$D$2:$AG$2,0)),Inputs!$B$4:$B$150,$B4)/1000) -> 119575 | R4: =IF(COUNT(N4:Q4)=4,SUM(N4:Q4),"") -> 385706 | S4: =IF(S$3=0,"",SUMIFS(INDEX(Inputs!$D$4:$AG$150,0,MATCH(S$2,Inputs!$D$2:$AG$2,0)),Inputs!$B$4:$B$150,$B4)/1000) -> 90753 | T4: =IF(T$3=0,"",SUMIFS(INDEX(Inputs!$D$4:$AG$150,0,MATCH(T$2,Inputs!$D$2:$AG$2,0)),Inputs!$B$4:$B$150,$B4)/1000) -> 85777 | U4: =IF(U$3=0,"",SUMIFS(INDEX(Inputs!$D$4:$AG$150,0,MATCH(U$2,Inputs!$D$2:$AG$2,0)),Inputs!$B$4:$B$150,$B4)/1000) -> 94930 | V4: =IF(V$3=0,"",SUMIFS(INDEX(Inputs!$D$4:$AG$150,0,MATCH(V$2,Inputs!$D$2:$AG$2,0)),Inputs!$B$4:$B$150,$B4)/1000) -> 124300 | W4: =IF(COUNT(S4:V4)=4,SUM(S4:V4),"") -> 395760 | X4: =IF(X$3=0,"",SUMIFS(INDEX(Inputs!$D$4:$AG$150,0,MATCH(X$2,Inputs!$D$2:$AG$2,0)),Inputs!$B$4:$B$150,$B4)/1000) -> 95359 | Y4: =IF(Y$3=0,"",SUMIFS(INDEX(Inputs!$D$4:$AG$150,0,MATCH(Y$2,Inputs!$D$2:$AG$2,0)),Inputs!$B$4:$B$150,$B4)/1000) -> 94036 | Z4: =IF(Z$3=0,"",SUMIFS(INDEX(Inputs!$D$4:$AG$150,0,MATCH(Z$2,Inputs!$D$2:$AG$2,0)),Inputs!$B$4:$B$150,$B4)/1000) -> 102466 | AA4: =IF(AA$3=0,"",SUMIFS(INDEX(Inputs!$D$4:$AG$150,0,MATCH(AA$2,Inputs!$D$2:$AG$2,0)),Inputs!$B$4:$B$150,$B4)/1000) -> 143756 | AB4: =IF(COUNT(X4:AA4)=4,SUM(X4:AA4),"") -> 435617 | AC4: =IF(AC$3=0,"",SUMIFS(INDEX(Inputs!$D$4:$AG$150,0,MATCH(AC$2,Inputs!$D$2:$AG$2,0)),Inputs!$B$4:$B$150,$B4)/1000) -> 111184 | AD4: =IF(AD$3=0,"",SUMIFS(INDEX(Inputs!$D$4:$AG$150,0,MATCH(AD$2,Inputs!$D$2:$AG$2,0)),Inputs!$B$4:$B$150,$B4)/1000) -> 109417 | AE4: =IF(AE$3=0,"",SUMIFS(INDEX(Inputs!$D$4:$AG$150,0,MATCH(AE$2,Inputs!$D$2:$AG$2,0)),Inputs!$B$4:$B$150,$B4)/1000) | AF4: =IF(AF$3=0,"",SUMIFS(INDEX(Inputs!$D$4:$AG$150,0,MATCH(AF$2,Inputs!$D$2:$AG$2,0)),Inputs!$B$4:$B$150,$B4)/1000) | AG4: =IF(COUNT(AC4:AF4)=4,SUM(AC4:AF4),"")
B5: 2 | C5: COGS (cash) | D5: =IF(D$3=0,"",SUMIFS(INDEX(Inputs!$D$4:$AG$150,0,MATCH(D$2,Inputs!$D$2:$AG$2,0)),Inputs!$B$4:$B$150,$B5)/1000) -> -51505 | E5: =IF(E$3=0,"",SUMIFS(INDEX(Inputs!$D$4:$AG$150,0,MATCH(E$2,Inputs!$D$2:$AG$2,0)),Inputs!$B$4:$B$150,$B5)/1000) -> -46179 | F5: =IF(F$3=0,"",SUMIFS(INDEX(Inputs!$D$4:$AG$150,0,MATCH(F$2,Inputs!$D$2:$AG$2,0)),Inputs!$B$4:$B$150,$B5)/1000) -> -48186 | G5: =IF(G$3=0,"",SUMIFS(INDEX(Inputs!$D$4:$AG$150,0,MATCH(G$2,Inputs!$D$2:$AG$2,0)),Inputs!$B$4:$B$150,$B5)/1000) -> -69702 | H5: =IF(COUNT(D5:G5)=4,SUM(D5:G5),"") -> -215572 | I5: =IF(I$3=0,"",SUMIFS(INDEX(Inputs!$D$4:$AG$150,0,MATCH(I$2,Inputs!$D$2:$AG$2,0)),Inputs!$B$4:$B$150,$B5)/1000) -> -54719 | J5: =IF(J$3=0,"",SUMIFS(INDEX(Inputs!$D$4:$AG$150,0,MATCH(J$2,Inputs!$D$2:$AG$2,0)),Inputs!$B$4:$B$150,$B5)/1000) -> -47074 | K5: =IF(K$3=0,"",SUMIFS(INDEX(Inputs!$D$4:$AG$150,0,MATCH(K$2,Inputs!$D$2:$AG$2,0)),Inputs!$B$4:$B$150,$B5)/1000) -> -52051 | L5: =IF(L$3=0,"",SUMIFS(INDEX(Inputs!$D$4:$AG$150,0,MATCH(L$2,Inputs!$D$2:$AG$2,0)),Inputs!$B$4:$B$150,$B5)/1000) -> -66822 | M5: =IF(COUNT(I5:L5)=4,SUM(I5:L5),"") -> -220666 | N5: =IF(N$3=0,"",SUMIFS(INDEX(Inputs!$D$4:$AG$150,0,MATCH(N$2,Inputs!$D$2:$AG$2,0)),Inputs!$B$4:$B$150,$B5)/1000) -> -52860 | O5: =IF(O$3=0,"",SUMIFS(INDEX(Inputs!$D$4:$AG$150,0,MATCH(O$2,Inputs!$D$2:$AG$2,0)),Inputs!$B$4:$B$150,$B5)/1000) -> -45384 | P5: =IF(P$3=0,"",SUMIFS(INDEX(Inputs!$D$4:$AG$150,0,MATCH(P$2,Inputs!$D$2:$AG$2,0)),Inputs!$B$4:$B$150,$B5)/1000) -> -49071 | Q5: =IF(Q$3=0,"",SUMIFS(INDEX(Inputs!$D$4:$AG$150,0,MATCH(Q$2,Inputs!$D$2:$AG$2,0)),Inputs!$B$4:$B$150,$B5)/1000) -> -64720 | R5: =IF(COUNT(N5:Q5)=4,SUM(N5:Q5),"") -> -212035 | S5: =IF(S$3=0,"",SUMIFS(INDEX(Inputs!$D$4:$AG$150,0,MATCH(S$2,Inputs!$D$2:$AG$2,0)),Inputs!$B$4:$B$150,$B5)/1000) -> -48482 | T5: =IF(T$3=0,"",SUMIFS(INDEX(Inputs!$D$4:$AG$150,0,MATCH(T$2,Inputs!$D$2:$AG$2,0)),Inputs!$B$4:$B$150,$B5)/1000) -> -46099 | U5: =IF(U$3=0,"",SUMIFS(INDEX(Inputs!$D$4:$AG$150,0,MATCH(U$2,Inputs!$D$2:$AG$2,0)),Inputs!$B$4:$B$150,$B5)/1000) -> -51051 | V5: =IF(V$3=0,"",SUMIFS(INDEX(Inputs!$D$4:$AG$150,0,MATCH(V$2,Inputs!$D$2:$AG$2,0)),Inputs!$B$4:$B$150,$B5)/1000) -> -66025 | W5: =IF(COUNT(S5:V5)=4,SUM(S5:V5),"") -> -211657 | X5: =IF(X$3=0,"",SUMIFS(INDEX(Inputs!$D$4:$AG$150,0,MATCH(X$2,Inputs!$D$2:$AG$2,0)),Inputs!$B$4:$B$150,$B5)/1000) -> -50492 | Y5: =IF(Y$3=0,"",SUMIFS(INDEX(Inputs!$D$4:$AG$150,0,MATCH(Y$2,Inputs!$D$2:$AG$2,0)),Inputs!$B$4:$B$150,$B5)/1000) -> -50318 | Z5: =IF(Z$3=0,"",SUMIFS(INDEX(Inputs!$D$4:$AG$150,0,MATCH(Z$2,Inputs!$D$2:$AG$2,0)),Inputs!$B$4:$B$150,$B5)/1000) -> -54125 | AA5: =IF(AA$3=0,"",SUMIFS(INDEX(Inputs!$D$4:$AG$150,0,MATCH(AA$2,Inputs!$D$2:$AG$2,0)),Inputs!$B$4:$B$150,$B5)/1000) -> -74525 | AB5: =IF(COUNT(X5:AA5)=4,SUM(X5:AA5),"") -> -229460 | AC5: =IF(AC$3=0,"",SUMIFS(INDEX(Inputs!$D$4:$AG$150,0,MATCH(AC$2,Inputs!$D$2:$AG$2,0)),Inputs!$B$4:$B$150,$B5)/1000) -> -56403 | AD5: =IF(AD$3=0,"",SUMIFS(INDEX(Inputs!$D$4:$AG$150,0,MATCH(AD$2,Inputs!$D$2:$AG$2,0)),Inputs!$B$4:$B$150,$B5)/1000) -> -54647 | AE5: =IF(AE$3=0,"",SUMIFS(INDEX(Inputs!$D$4:$AG$150,0,MATCH(AE$2,Inputs!$D$2:$AG$2,0)),Inputs!$B$4:$B$150,$B5)/1000) | AF5: =IF(AF$3=0,"",SUMIFS(INDEX(Inputs!$D$4:$AG$150,0,MATCH(AF$2,Inputs!$D$2:$AG$2,0)),Inputs!$B$4:$B$150,$B5)/1000) | AG5: =IF(COUNT(AC5:AF5)=4,SUM(AC5:AF5),"")
B6: 3 | C6: SG&A and Other (cash) | D6: =IF(D$3=0,"",SUMIFS(INDEX(Inputs!$D$4:$AG$150,0,MATCH(D$2,Inputs!$D$2:$AG$2,0)),Inputs!$B$4:$B$150,$B6)/1000) -> -10927 | E6: =IF(E$3=0,"",SUMIFS(INDEX(Inputs!$D$4:$AG$150,0,MATCH(E$2,Inputs!$D$2:$AG$2,0)),Inputs!$B$4:$B$150,$B6)/1000) -> -8297 | F6: =IF(F$3=0,"",SUMIFS(INDEX(Inputs!$D$4:$AG$150,0,MATCH(F$2,Inputs!$D$2:$AG$2,0)),Inputs!$B$4:$B$150,$B6)/1000) -> -8399 | G6: =IF(G$3=0,"",SUMIFS(INDEX(Inputs!$D$4:$AG$150,0,MATCH(G$2,Inputs!$D$2:$AG$2,0)),Inputs!$B$4:$B$150,$B6)/1000) -> -10058 | H6: =IF(COUNT(D6:G6)=4,SUM(D6:G6),"") -> -37681 | I6: =IF(I$3=0,"",SUMIFS(INDEX(Inputs!$D$4:$AG$150,0,MATCH(I$2,Inputs!$D$2:$AG$2,0)),Inputs!$B$4:$B$150,$B6)/1000) -> -9843 | J6: =IF(J$3=0,"",SUMIFS(INDEX(Inputs!$D$4:$AG$150,0,MATCH(J$2,Inputs!$D$2:$AG$2,0)),Inputs!$B$4:$B$150,$B6)/1000) -> -10004 | K6: =IF(K$3=0,"",SUMIFS(INDEX(Inputs!$D$4:$AG$150,0,MATCH(K$2,Inputs!$D$2:$AG$2,0)),Inputs!$B$4:$B$150,$B6)/1000) -> -10336 | L6: =IF(L$3=0,"",SUMIFS(INDEX(Inputs!$D$4:$AG$150,0,MATCH(L$2,Inputs!$D$2:$AG$2,0)),Inputs!$B$4:$B$150,$B6)/1000) -> -11400 | M6: =IF(COUNT(I6:L6)=4,SUM(I6:L6),"") -> -41583 | N6: =IF(N$3=0,"",SUMIFS(INDEX(Inputs!$D$4:$AG$150,0,MATCH(N$2,Inputs!$D$2:$AG$2,0)),Inputs!$B$4:$B$150,$B6)/1000) -> -10760 | O6: =IF(O$3=0,"",SUMIFS(INDEX(Inputs!$D$4:$AG$150,0,MATCH(O$2,Inputs!$D$2:$AG$2,0)),Inputs!$B$4:$B$150,$B6)/1000) -> -10363 | P6: =IF(P$3=0,"",SUMIFS(INDEX(Inputs!$D$4:$AG$150,0,MATCH(P$2,Inputs!$D$2:$AG$2,0)),Inputs!$B$4:$B$150,$B6)/1000) -> -10805 | Q6: =IF(Q$3=0,"",SUMIFS(INDEX(Inputs!$D$4:$AG$150,0,MATCH(Q$2,Inputs!$D$2:$AG$2,0)),Inputs!$B$4:$B$150,$B6)/1000) -> -11634 | R6: =IF(COUNT(N6:Q6)=4,SUM(N6:Q6),"") -> -43562 | S6: =IF(S$3=0,"",SUMIFS(INDEX(Inputs!$D$4:$AG$150,0,MATCH(S$2,Inputs!$D$2:$AG$2,0)),Inputs!$B$4:$B$150,$B6)/1000) -> -11535 | T6: =IF(T$3=0,"",SUMIFS(INDEX(Inputs!$D$4:$AG$150,0,MATCH(T$2,Inputs!$D$2:$AG$2,0)),Inputs!$B$4:$B$150,$B6)/1000) -> -11476 | U6: =IF(U$3=0,"",SUMIFS(INDEX(Inputs!$D$4:$AG$150,0,MATCH(U$2,Inputs!$D$2:$AG$2,0)),Inputs!$B$4:$B$150,$B6)/1000) -> -11377 | V6: =IF(V$3=0,"",SUMIFS(INDEX(Inputs!$D$4:$AG$150,0,MATCH(V$2,Inputs!$D$2:$AG$2,0)),Inputs!$B$4:$B$150,$B6)/1000) -> -12363 | W6: =IF(COUNT(S6:V6)=4,SUM(S6:V6),"") -> -46751 | X6: =IF(X$3=0,"",SUMIFS(INDEX(Inputs!$D$4:$AG$150,0,MATCH(X$2,Inputs!$D$2:$AG$2,0)),Inputs!$B$4:$B$150,$B6)/1000) -> -12617 | Y6: =IF(Y$3=0,"",SUMIFS(INDEX(Inputs!$D$4:$AG$150,0,MATCH(Y$2,Inputs!$D$2:$AG$2,0)),Inputs!$B$4:$B$150,$B6)/1000) -> -12686 | Z6: =IF(Z$3=0,"",SUMIFS(INDEX(Inputs!$D$4:$AG$150,0,MATCH(Z$2,Inputs!$D$2:$AG$2,0)),Inputs!$B$4:$B$150,$B6)/1000) -> -12787 | AA6: =IF(AA$3=0,"",SUMIFS(INDEX(Inputs!$D$4:$AG$150,0,MATCH(AA$2,Inputs!$D$2:$AG$2,0)),Inputs!$B$4:$B$150,$B6)/1000) -> -15165 | AB6: =IF(COUNT(X6:AA6)=4,SUM(X6:AA6),"") -> -53255 | AC6: =IF(AC$3=0,"",SUMIFS(INDEX(Inputs!$D$4:$AG$150,0,MATCH(AC$2,Inputs!$D$2:$AG$2,0)),Inputs!$B$4:$B$150,$B6)/1000) -> -15457 | AD6: =IF(AD$3=0,"",SUMIFS(INDEX(Inputs!$D$4:$AG$150,0,MATCH(AD$2,Inputs!$D$2:$AG$2,0)),Inputs!$B$4:$B$150,$B6)/1000) -> -15755 | AE6: =IF(AE$3=0,"",SUMIFS(INDEX(Inputs!$D$4:$AG$150,0,MATCH(AE$2,Inputs!$D$2:$AG$2,0)),Inputs!$B$4:$B$150,$B6)/1000) | AF6: =IF(AF$3=0,"",SUMIFS(INDEX(Inputs!$D$4:$AG$150,0,MATCH(AF$2,Inputs!$D$2:$AG$2,0)),Inputs!$B$4:$B$150,$B6)/1000) | AG6: =IF(COUNT(AC6:AF6)=4,SUM(AC6:AF6),"")
B7: 4 | C7: D&A | D7: =IF(D$3=0,"",SUMIFS(INDEX(Inputs!$D$4:$AG$150,0,MATCH(D$2,Inputs!$D$2:$AG$2,0)),Inputs!$B$4:$B$150,$B7)/1000) -> 351 | E7: =IF(E$3=0,"",SUMIFS(INDEX(Inputs!$D$4:$AG$150,0,MATCH(E$2,Inputs!$D$2:$AG$2,0)),Inputs!$B$4:$B$150,$B7)/1000) -> -2832 | F7: =IF(F$3=0,"",SUMIFS(INDEX(Inputs!$D$4:$AG$150,0,MATCH(F$2,Inputs!$D$2:$AG$2,0)),Inputs!$B$4:$B$150,$B7)/1000) -> -2989 | G7: =IF(G$3=0,"",SUMIFS(INDEX(Inputs!$D$4:$AG$150,0,MATCH(G$2,Inputs!$D$2:$AG$2,0)),Inputs!$B$4:$B$150,$B7)/1000) -> -2697 | H7: =IF(COUNT(D7:G7)=4,SUM(D7:G7),"") -> -8167 | I7: =IF(I$3=0,"",SUMIFS(INDEX(Inputs!$D$4:$AG$150,0,MATCH(I$2,Inputs!$D$2:$AG$2,0)),Inputs!$B$4:$B$150,$B7)/1000) -> -2737 | J7: =IF(J$3=0,"",SUMIFS(INDEX(Inputs!$D$4:$AG$150,0,MATCH(J$2,Inputs!$D$2:$AG$2,0)),Inputs!$B$4:$B$150,$B7)/1000) -> -2805 | K7: =IF(K$3=0,"",SUMIFS(INDEX(Inputs!$D$4:$AG$150,0,MATCH(K$2,Inputs!$D$2:$AG$2,0)),Inputs!$B$4:$B$150,$B7)/1000) -> -2865 | L7: =IF(L$3=0,"",SUMIFS(INDEX(Inputs!$D$4:$AG$150,0,MATCH(L$2,Inputs!$D$2:$AG$2,0)),Inputs!$B$4:$B$150,$B7)/1000) -> -2916 | M7: =IF(COUNT(I7:L7)=4,SUM(I7:L7),"") -> -11323 | N7: =IF(N$3=0,"",SUMIFS(INDEX(Inputs!$D$4:$AG$150,0,MATCH(N$2,Inputs!$D$2:$AG$2,0)),Inputs!$B$4:$B$150,$B7)/1000) -> -2898 | O7: =IF(O$3=0,"",SUMIFS(INDEX(Inputs!$D$4:$AG$150,0,MATCH(O$2,Inputs!$D$2:$AG$2,0)),Inputs!$B$4:$B$150,$B7)/1000) -> -3052 | P7: =IF(P$3=0,"",SUMIFS(INDEX(Inputs!$D$4:$AG$150,0,MATCH(P$2,Inputs!$D$2:$AG$2,0)),Inputs!$B$4:$B$150,$B7)/1000) -> -2653 | Q7: =IF(Q$3=0,"",SUMIFS(INDEX(Inputs!$D$4:$AG$150,0,MATCH(Q$2,Inputs!$D$2:$AG$2,0)),Inputs!$B$4:$B$150,$B7)/1000) -> -2848 | R7: =IF(COUNT(N7:Q7)=4,SUM(N7:Q7),"") -> -11451 | S7: =IF(S$3=0,"",SUMIFS(INDEX(Inputs!$D$4:$AG$150,0,MATCH(S$2,Inputs!$D$2:$AG$2,0)),Inputs!$B$4:$B$150,$B7)/1000) -> -2836 | T7: =IF(T$3=0,"",SUMIFS(INDEX(Inputs!$D$4:$AG$150,0,MATCH(T$2,Inputs!$D$2:$AG$2,0)),Inputs!$B$4:$B$150,$B7)/1000) -> -2850 | U7: =IF(U$3=0,"",SUMIFS(INDEX(Inputs!$D$4:$AG$150,0,MATCH(U$2,Inputs!$D$2:$AG$2,0)),Inputs!$B$4:$B$150,$B7)/1000) -> -2911 | V7: =IF(V$3=0,"",SUMIFS(INDEX(Inputs!$D$4:$AG$150,0,MATCH(V$2,Inputs!$D$2:$AG$2,0)),Inputs!$B$4:$B$150,$B7)/1000) -> -3080 | W7: =IF(COUNT(S7:V7)=4,SUM(S7:V7),"") -> -11677 | X7: =IF(X$3=0,"",SUMIFS(INDEX(Inputs!$D$4:$AG$150,0,MATCH(X$2,Inputs!$D$2:$AG$2,0)),Inputs!$B$4:$B$150,$B7)/1000) -> -2661 | Y7: =IF(Y$3=0,"",SUMIFS(INDEX(Inputs!$D$4:$AG$150,0,MATCH(Y$2,Inputs!$D$2:$AG$2,0)),Inputs!$B$4:$B$150,$B7)/1000) -> -2830 | Z7: =IF(Z$3=0,"",SUMIFS(INDEX(Inputs!$D$4:$AG$150,0,MATCH(Z$2,Inputs!$D$2:$AG$2,0)),Inputs!$B$4:$B$150,$B7)/1000) -> -3127 | AA7: =IF(AA$3=0,"",SUMIFS(INDEX(Inputs!$D$4:$AG$150,0,MATCH(AA$2,Inputs!$D$2:$AG$2,0)),Inputs!$B$4:$B$150,$B7)/1000) -> -3214 | AB7: =IF(COUNT(X7:AA7)=4,SUM(X7:AA7),"") -> -11832 | AC7: =IF(AC$3=0,"",SUMIFS(INDEX(Inputs!$D$4:$AG$150,0,MATCH(AC$2,Inputs!$D$2:$AG$2,0)),Inputs!$B$4:$B$150,$B7)/1000) -> -3439 | AD7: =IF(AD$3=0,"",SUMIFS(INDEX(Inputs!$D$4:$AG$150,0,MATCH(AD$2,Inputs!$D$2:$AG$2,0)),Inputs!$B$4:$B$150,$B7)/1000) -> -3320 | AE7: =IF(AE$3=0,"",SUMIFS(INDEX(Inputs!$D$4:$AG$150,0,MATCH(AE$2,Inputs!$D$2:$AG$2,0)),Inputs!$B$4:$B$150,$B7)/1000) | AF7: =IF(AF$3=0,"",SUMIFS(INDEX(Inputs!$D$4:$AG$150,0,MATCH(AF$2,Inputs!$D$2:$AG$2,0)),Inputs!$B$4:$B$150,$B7)/1000) | AG7: =IF(COUNT(AC7:AF7)=4,SUM(AC7:AF7),"")
B8: 5 | C8: Interest Expense | D8: =IF(D$3=0,"",SUMIFS(INDEX(Inputs!$D$4:$AG$150,0,MATCH(D$2,Inputs!$D$2:$AG$2,0)),Inputs!$B$4:$B$150,$B8)/1000) -> 0 | E8: =IF(E$3=0,"",SUMIFS(INDEX(Inputs!$D$4:$AG$150,0,MATCH(E$2,Inputs!$D$2:$AG$2,0)),Inputs!$B$4:$B$150,$B8)/1000) -> 0 | F8: =IF(F$3=0,"",SUMIFS(INDEX(Inputs!$D$4:$AG$150,0,MATCH(F$2,Inputs!$D$2:$AG$2,0)),Inputs!$B$4:$B$150,$B8)/1000) -> 0 | G8: =IF(G$3=0,"",SUMIFS(INDEX(Inputs!$D$4:$AG$150,0,MATCH(G$2,Inputs!$D$2:$AG$2,0)),Inputs!$B$4:$B$150,$B8)/1000) -> 0 | H8: =IF(COUNT(D8:G8)=4,SUM(D8:G8),"") -> 0 | I8: =IF(I$3=0,"",SUMIFS(INDEX(Inputs!$D$4:$AG$150,0,MATCH(I$2,Inputs!$D$2:$AG$2,0)),Inputs!$B$4:$B$150,$B8)/1000) -> 0 | J8: =IF(J$3=0,"",SUMIFS(INDEX(Inputs!$D$4:$AG$150,0,MATCH(J$2,Inputs!$D$2:$AG$2,0)),Inputs!$B$4:$B$150,$B8)/1000) -> 0 | K8: =IF(K$3=0,"",SUMIFS(INDEX(Inputs!$D$4:$AG$150,0,MATCH(K$2,Inputs!$D$2:$AG$2,0)),Inputs!$B$4:$B$150,$B8)/1000) -> 0 | L8: =IF(L$3=0,"",SUMIFS(INDEX(Inputs!$D$4:$AG$150,0,MATCH(L$2,Inputs!$D$2:$AG$2,0)),Inputs!$B$4:$B$150,$B8)/1000) -> 0 | M8: =IF(COUNT(I8:L8)=4,SUM(I8:L8),"") -> 0 | N8: =IF(N$3=0,"",SUMIFS(INDEX(Inputs!$D$4:$AG$150,0,MATCH(N$2,Inputs!$D$2:$AG$2,0)),Inputs!$B$4:$B$150,$B8)/1000) -> 0 | O8: =IF(O$3=0,"",SUMIFS(INDEX(Inputs!$D$4:$AG$150,0,MATCH(O$2,Inputs!$D$2:$AG$2,0)),Inputs!$B$4:$B$150,$B8)/1000) -> 0 | P8: =IF(P$3=0,"",SUMIFS(INDEX(Inputs!$D$4:$AG$150,0,MATCH(P$2,Inputs!$D$2:$AG$2,0)),Inputs!$B$4:$B$150,$B8)/1000) -> 0 | Q8: =IF(Q$3=0,"",SUMIFS(INDEX(Inputs!$D$4:$AG$150,0,MATCH(Q$2,Inputs!$D$2:$AG$2,0)),Inputs!$B$4:$B$150,$B8)/1000) -> 0 | R8: =IF(COUNT(N8:Q8)=4,SUM(N8:Q8),"") -> 0 | S8: =IF(S$3=0,"",SUMIFS(INDEX(Inputs!$D$4:$AG$150,0,MATCH(S$2,Inputs!$D$2:$AG$2,0)),Inputs!$B$4:$B$150,$B8)/1000) -> 0 | T8: =IF(T$3=0,"",SUMIFS(INDEX(Inputs!$D$4:$AG$150,0,MATCH(T$2,Inputs!$D$2:$AG$2,0)),Inputs!$B$4:$B$150,$B8)/1000) -> 0 | U8: =IF(U$3=0,"",SUMIFS(INDEX(Inputs!$D$4:$AG$150,0,MATCH(U$2,Inputs!$D$2:$AG$2,0)),Inputs!$B$4:$B$150,$B8)/1000) -> 0 | V8: =IF(V$3=0,"",SUMIFS(INDEX(Inputs!$D$4:$AG$150,0,MATCH(V$2,Inputs!$D$2:$AG$2,0)),Inputs!$B$4:$B$150,$B8)/1000) -> 0 | W8: =IF(COUNT(S8:V8)=4,SUM(S8:V8),"") -> 0 | X8: =IF(X$3=0,"",SUMIFS(INDEX(Inputs!$D$4:$AG$150,0,MATCH(X$2,Inputs!$D$2:$AG$2,0)),Inputs!$B$4:$B$150,$B8)/1000) -> 0 | Y8: =IF(Y$3=0,"",SUMIFS(INDEX(Inputs!$D$4:$AG$150,0,MATCH(Y$2,Inputs!$D$2:$AG$2,0)),Inputs!$B$4:$B$150,$B8)/1000) -> 0 | Z8: =IF(Z$3=0,"",SUMIFS(INDEX(Inputs!$D$4:$AG$150,0,MATCH(Z$2,Inputs!$D$2:$AG$2,0)),Inputs!$B$4:$B$150,$B8)/1000) -> 0 | AA8: =IF(AA$3=0,"",SUMIFS(INDEX(Inputs!$D$4:$AG$150,0,MATCH(AA$2,Inputs!$D$2:$AG$2,0)),Inputs!$B$4:$B$150,$B8)/1000) -> 0 | AB8: =IF(COUNT(X8:AA8)=4,SUM(X8:AA8),"") -> 0 | AC8: =IF(AC$3=0,"",SUMIFS(INDEX(Inputs!$D$4:$AG$150,0,MATCH(AC$2,Inputs!$D$2:$AG$2,0)),Inputs!$B$4:$B$150,$B8)/1000) -> 0 | AD8: =IF(AD$3=0,"",SUMIFS(INDEX(Inputs!$D$4:$AG$150,0,MATCH(AD$2,Inputs!$D$2:$AG$2,0)),Inputs!$B$4:$B$150,$B8)/1000) -> 0 | AE8: =IF(AE$3=0,"",SUMIFS(INDEX(Inputs!$D$4:$AG$150,0,MATCH(AE$2,Inputs!$D$2:$AG$2,0)),Inputs!$B$4:$B$150,$B8)/1000) | AF8: =IF(AF$3=0,"",SUMIFS(INDEX(Inputs!$D$4:$AG$150,0,MATCH(AF$2,Inputs!$D$2:$AG$2,0)),Inputs!$B$4:$B$150,$B8)/1000) | AG8: =IF(COUNT(AC8:AF8)=4,SUM(AC8:AF8),"")
B9: 6 | C9: Nonoperating Income / (Loss) | D9: =IF(D$3=0,"",SUMIFS(INDEX(Inputs!$D$4:$AG$150,0,MATCH(D$2,Inputs!$D$2:$AG$2,0)),Inputs!$B$4:$B$150,$B9)/1000) -> 508 | E9: =IF(E$3=0,"",SUMIFS(INDEX(Inputs!$D$4:$AG$150,0,MATCH(E$2,Inputs!$D$2:$AG$2,0)),Inputs!$B$4:$B$150,$B9)/1000) -> 243 | F9: =IF(F$3=0,"",SUMIFS(INDEX(Inputs!$D$4:$AG$150,0,MATCH(F$2,Inputs!$D$2:$AG$2,0)),Inputs!$B$4:$B$150,$B9)/1000) -> -538 | G9: =IF(G$3=0,"",SUMIFS(INDEX(Inputs!$D$4:$AG$150,0,MATCH(G$2,Inputs!$D$2:$AG$2,0)),Inputs!$B$4:$B$150,$B9)/1000) -> -247 | H9: =IF(COUNT(D9:G9)=4,SUM(D9:G9),"") -> -34 | I9: =IF(I$3=0,"",SUMIFS(INDEX(Inputs!$D$4:$AG$150,0,MATCH(I$2,Inputs!$D$2:$AG$2,0)),Inputs!$B$4:$B$150,$B9)/1000) -> 160 | J9: =IF(J$3=0,"",SUMIFS(INDEX(Inputs!$D$4:$AG$150,0,MATCH(J$2,Inputs!$D$2:$AG$2,0)),Inputs!$B$4:$B$150,$B9)/1000) -> -10 | K9: =IF(K$3=0,"",SUMIFS(INDEX(Inputs!$D$4:$AG$150,0,MATCH(K$2,Inputs!$D$2:$AG$2,0)),Inputs!$B$4:$B$150,$B9)/1000) -> -237 | L9: =IF(L$3=0,"",SUMIFS(INDEX(Inputs!$D$4:$AG$150,0,MATCH(L$2,Inputs!$D$2:$AG$2,0)),Inputs!$B$4:$B$150,$B9)/1000) -> -393 | M9: =IF(COUNT(I9:L9)=4,SUM(I9:L9),"") -> -480 | N9: =IF(N$3=0,"",SUMIFS(INDEX(Inputs!$D$4:$AG$150,0,MATCH(N$2,Inputs!$D$2:$AG$2,0)),Inputs!$B$4:$B$150,$B9)/1000) -> 64 | O9: =IF(O$3=0,"",SUMIFS(INDEX(Inputs!$D$4:$AG$150,0,MATCH(O$2,Inputs!$D$2:$AG$2,0)),Inputs!$B$4:$B$150,$B9)/1000) -> -265 | P9: =IF(P$3=0,"",SUMIFS(INDEX(Inputs!$D$4:$AG$150,0,MATCH(P$2,Inputs!$D$2:$AG$2,0)),Inputs!$B$4:$B$150,$B9)/1000) -> 29 | Q9: =IF(Q$3=0,"",SUMIFS(INDEX(Inputs!$D$4:$AG$150,0,MATCH(Q$2,Inputs!$D$2:$AG$2,0)),Inputs!$B$4:$B$150,$B9)/1000) -> -50 | R9: =IF(COUNT(N9:Q9)=4,SUM(N9:Q9),"") -> -222 | S9: =IF(S$3=0,"",SUMIFS(INDEX(Inputs!$D$4:$AG$150,0,MATCH(S$2,Inputs!$D$2:$AG$2,0)),Inputs!$B$4:$B$150,$B9)/1000) -> 158 | T9: =IF(T$3=0,"",SUMIFS(INDEX(Inputs!$D$4:$AG$150,0,MATCH(T$2,Inputs!$D$2:$AG$2,0)),Inputs!$B$4:$B$150,$B9)/1000) -> 142 | U9: =IF(U$3=0,"",SUMIFS(INDEX(Inputs!$D$4:$AG$150,0,MATCH(U$2,Inputs!$D$2:$AG$2,0)),Inputs!$B$4:$B$150,$B9)/1000) -> 19 | V9: =IF(V$3=0,"",SUMIFS(INDEX(Inputs!$D$4:$AG$150,0,MATCH(V$2,Inputs!$D$2:$AG$2,0)),Inputs!$B$4:$B$150,$B9)/1000) -> -248 | W9: =IF(COUNT(S9:V9)=4,SUM(S9:V9),"") -> 71 | X9: =IF(X$3=0,"",SUMIFS(INDEX(Inputs!$D$4:$AG$150,0,MATCH(X$2,Inputs!$D$2:$AG$2,0)),Inputs!$B$4:$B$150,$B9)/1000) -> -279 | Y9: =IF(Y$3=0,"",SUMIFS(INDEX(Inputs!$D$4:$AG$150,0,MATCH(Y$2,Inputs!$D$2:$AG$2,0)),Inputs!$B$4:$B$150,$B9)/1000) -> -171 | Z9: =IF(Z$3=0,"",SUMIFS(INDEX(Inputs!$D$4:$AG$150,0,MATCH(Z$2,Inputs!$D$2:$AG$2,0)),Inputs!$B$4:$B$150,$B9)/1000) -> 377 | AA9: =IF(AA$3=0,"",SUMIFS(INDEX(Inputs!$D$4:$AG$150,0,MATCH(AA$2,Inputs!$D$2:$AG$2,0)),Inputs!$B$4:$B$150,$B9)/1000) -> 150 | AB9: =IF(COUNT(X9:AA9)=4,SUM(X9:AA9),"") -> 77 | AC9: =IF(AC$3=0,"",SUMIFS(INDEX(Inputs!$D$4:$AG$150,0,MATCH(AC$2,Inputs!$D$2:$AG$2,0)),Inputs!$B$4:$B$150,$B9)/1000) -> -52 | AD9: =IF(AD$3=0,"",SUMIFS(INDEX(Inputs!$D$4:$AG$150,0,MATCH(AD$2,Inputs!$D$2:$AG$2,0)),Inputs!$B$4:$B$150,$B9)/1000) -> 572 | AE9: =IF(AE$3=0,"",SUMIFS(INDEX(Inputs!$D$4:$AG$150,0,MATCH(AE$2,Inputs!$D$2:$AG$2,0)),Inputs!$B$4:$B$150,$B9)/1000) | AF9: =IF(AF$3=0,"",SUMIFS(INDEX(Inputs!$D$4:$AG$150,0,MATCH(AF$2,Inputs!$D$2:$AG$2,0)),Inputs!$B$4:$B$150,$B9)/1000) | AG9: =IF(COUNT(AC9:AF9)=4,SUM(AC9:AF9),"")
B10: 7 | C10: Taxes | D10: =IF(D$3=0,"",SUMIFS(INDEX(Inputs!$D$4:$AG$150,0,MATCH(D$2,Inputs!$D$2:$AG$2,0)),Inputs!$B$4:$B$150,$B10)/1000) -> -4381 | E10: =IF(E$3=0,"",SUMIFS(INDEX(Inputs!$D$4:$AG$150,0,MATCH(E$2,Inputs!$D$2:$AG$2,0)),Inputs!$B$4:$B$150,$B10)/1000) -> -2625 | F10: =IF(F$3=0,"",SUMIFS(INDEX(Inputs!$D$4:$AG$150,0,MATCH(F$2,Inputs!$D$2:$AG$2,0)),Inputs!$B$4:$B$150,$B10)/1000) -> -2697 | G10: =IF(G$3=0,"",SUMIFS(INDEX(Inputs!$D$4:$AG$150,0,MATCH(G$2,Inputs!$D$2:$AG$2,0)),Inputs!$B$4:$B$150,$B10)/1000) -> -6611 | H10: =IF(COUNT(D10:G10)=4,SUM(D10:G10),"") -> -16314 | I10: =IF(I$3=0,"",SUMIFS(INDEX(Inputs!$D$4:$AG$150,0,MATCH(I$2,Inputs!$D$2:$AG$2,0)),Inputs!$B$4:$B$150,$B10)/1000) -> -5129 | J10: =IF(J$3=0,"",SUMIFS(INDEX(Inputs!$D$4:$AG$150,0,MATCH(J$2,Inputs!$D$2:$AG$2,0)),Inputs!$B$4:$B$150,$B10)/1000) -> -3624 | K10: =IF(K$3=0,"",SUMIFS(INDEX(Inputs!$D$4:$AG$150,0,MATCH(K$2,Inputs!$D$2:$AG$2,0)),Inputs!$B$4:$B$150,$B10)/1000) -> -3936 | L10: =IF(L$3=0,"",SUMIFS(INDEX(Inputs!$D$4:$AG$150,0,MATCH(L$2,Inputs!$D$2:$AG$2,0)),Inputs!$B$4:$B$150,$B10)/1000) -> -5625 | M10: =IF(COUNT(I10:L10)=4,SUM(I10:L10),"") -> -18314 | N10: =IF(N$3=0,"",SUMIFS(INDEX(Inputs!$D$4:$AG$150,0,MATCH(N$2,Inputs!$D$2:$AG$2,0)),Inputs!$B$4:$B$150,$B10)/1000) -> -4222 | O10: =IF(O$3=0,"",SUMIFS(INDEX(Inputs!$D$4:$AG$150,0,MATCH(O$2,Inputs!$D$2:$AG$2,0)),Inputs!$B$4:$B$150,$B10)/1000) -> -2852 | P10: =IF(P$3=0,"",SUMIFS(INDEX(Inputs!$D$4:$AG$150,0,MATCH(P$2,Inputs!$D$2:$AG$2,0)),Inputs!$B$4:$B$150,$B10)/1000) -> -4042 | Q10: =IF(Q$3=0,"",SUMIFS(INDEX(Inputs!$D$4:$AG$150,0,MATCH(Q$2,Inputs!$D$2:$AG$2,0)),Inputs!$B$4:$B$150,$B10)/1000) -> -6407 | R10: =IF(COUNT(N10:Q10)=4,SUM(N10:Q10),"") -> -17523 | S10: =IF(S$3=0,"",SUMIFS(INDEX(Inputs!$D$4:$AG$150,0,MATCH(S$2,Inputs!$D$2:$AG$2,0)),Inputs!$B$4:$B$150,$B10)/1000) -> -4422 | T10: =IF(T$3=0,"",SUMIFS(INDEX(Inputs!$D$4:$AG$150,0,MATCH(T$2,Inputs!$D$2:$AG$2,0)),Inputs!$B$4:$B$150,$B10)/1000) -> -4046 | U10: =IF(U$3=0,"",SUMIFS(INDEX(Inputs!$D$4:$AG$150,0,MATCH(U$2,Inputs!$D$2:$AG$2,0)),Inputs!$B$4:$B$150,$B10)/1000) -> -14874 | V10: =IF(V$3=0,"",SUMIFS(INDEX(Inputs!$D$4:$AG$150,0,MATCH(V$2,Inputs!$D$2:$AG$2,0)),Inputs!$B$4:$B$150,$B10)/1000) -> -6254 | W10: =IF(COUNT(S10:V10)=4,SUM(S10:V10),"") -> -29596 | X10: =IF(X$3=0,"",SUMIFS(INDEX(Inputs!$D$4:$AG$150,0,MATCH(X$2,Inputs!$D$2:$AG$2,0)),Inputs!$B$4:$B$150,$B10)/1000) -> -4530 | Y10: =IF(Y$3=0,"",SUMIFS(INDEX(Inputs!$D$4:$AG$150,0,MATCH(Y$2,Inputs!$D$2:$AG$2,0)),Inputs!$B$4:$B$150,$B10)/1000) -> -4597 | Z10: =IF(Z$3=0,"",SUMIFS(INDEX(Inputs!$D$4:$AG$150,0,MATCH(Z$2,Inputs!$D$2:$AG$2,0)),Inputs!$B$4:$B$150,$B10)/1000) -> -5338 | AA10: =IF(AA$3=0,"",SUMIFS(INDEX(Inputs!$D$4:$AG$150,0,MATCH(AA$2,Inputs!$D$2:$AG$2,0)),Inputs!$B$4:$B$150,$B10)/1000) -> -8905 | AB10: =IF(COUNT(X10:AA10)=4,SUM(X10:AA10),"") -> -23370 | AC10: =IF(AC$3=0,"",SUMIFS(INDEX(Inputs!$D$4:$AG$150,0,MATCH(AC$2,Inputs!$D$2:$AG$2,0)),Inputs!$B$4:$B$150,$B10)/1000) -> -6255 | AD10: =IF(AD$3=0,"",SUMIFS(INDEX(Inputs!$D$4:$AG$150,0,MATCH(AD$2,Inputs!$D$2:$AG$2,0)),Inputs!$B$4:$B$150,$B10)/1000) -> -6478 | AE10: =IF(AE$3=0,"",SUMIFS(INDEX(Inputs!$D$4:$AG$150,0,MATCH(AE$2,Inputs!$D$2:$AG$2,0)),Inputs!$B$4:$B$150,$B10)/1000) | AF10: =IF(AF$3=0,"",SUMIFS(INDEX(Inputs!$D$4:$AG$150,0,MATCH(AF$2,Inputs!$D$2:$AG$2,0)),Inputs!$B$4:$B$150,$B10)/1000) | AG10: =IF(COUNT(AC10:AF10)=4,SUM(AC10:AF10),"")
B11: 8 | C11: Equity in Income of Affiliates, after tax (enter as +) | D11: =IF(D$3=0,"",SUMIFS(INDEX(Inputs!$D$4:$AG$150,0,MATCH(D$2,Inputs!$D$2:$AG$2,0)),Inputs!$B$4:$B$150,$B11)/1000) -> 0 | E11: =IF(E$3=0,"",SUMIFS(INDEX(Inputs!$D$4:$AG$150,0,MATCH(E$2,Inputs!$D$2:$AG$2,0)),Inputs!$B$4:$B$150,$B11)/1000) -> 0 | F11: =IF(F$3=0,"",SUMIFS(INDEX(Inputs!$D$4:$AG$150,0,MATCH(F$2,Inputs!$D$2:$AG$2,0)),Inputs!$B$4:$B$150,$B11)/1000) -> 0 | G11: =IF(G$3=0,"",SUMIFS(INDEX(Inputs!$D$4:$AG$150,0,MATCH(G$2,Inputs!$D$2:$AG$2,0)),Inputs!$B$4:$B$150,$B11)/1000) -> 0 | H11: =IF(COUNT(D11:G11)=4,SUM(D11:G11),"") -> 0 | I11: =IF(I$3=0,"",SUMIFS(INDEX(Inputs!$D$4:$AG$150,0,MATCH(I$2,Inputs!$D$2:$AG$2,0)),Inputs!$B$4:$B$150,$B11)/1000) -> 0 | J11: =IF(J$3=0,"",SUMIFS(INDEX(Inputs!$D$4:$AG$150,0,MATCH(J$2,Inputs!$D$2:$AG$2,0)),Inputs!$B$4:$B$150,$B11)/1000) -> 0 | K11: =IF(K$3=0,"",SUMIFS(INDEX(Inputs!$D$4:$AG$150,0,MATCH(K$2,Inputs!$D$2:$AG$2,0)),Inputs!$B$4:$B$150,$B11)/1000) -> 0 | L11: =IF(L$3=0,"",SUMIFS(INDEX(Inputs!$D$4:$AG$150,0,MATCH(L$2,Inputs!$D$2:$AG$2,0)),Inputs!$B$4:$B$150,$B11)/1000) -> 0 | M11: =IF(COUNT(I11:L11)=4,SUM(I11:L11),"") -> 0 | N11: =IF(N$3=0,"",SUMIFS(INDEX(Inputs!$D$4:$AG$150,0,MATCH(N$2,Inputs!$D$2:$AG$2,0)),Inputs!$B$4:$B$150,$B11)/1000) -> 0 | O11: =IF(O$3=0,"",SUMIFS(INDEX(Inputs!$D$4:$AG$150,0,MATCH(O$2,Inputs!$D$2:$AG$2,0)),Inputs!$B$4:$B$150,$B11)/1000) -> 0 | P11: =IF(P$3=0,"",SUMIFS(INDEX(Inputs!$D$4:$AG$150,0,MATCH(P$2,Inputs!$D$2:$AG$2,0)),Inputs!$B$4:$B$150,$B11)/1000) -> 0 | Q11: =IF(Q$3=0,"",SUMIFS(INDEX(Inputs!$D$4:$AG$150,0,MATCH(Q$2,Inputs!$D$2:$AG$2,0)),Inputs!$B$4:$B$150,$B11)/1000) -> 0 | R11: =IF(COUNT(N11:Q11)=4,SUM(N11:Q11),"") -> 0 | S11: =IF(S$3=0,"",SUMIFS(INDEX(Inputs!$D$4:$AG$150,0,MATCH(S$2,Inputs!$D$2:$AG$2,0)),Inputs!$B$4:$B$150,$B11)/1000) -> 0 | T11: =IF(T$3=0,"",SUMIFS(INDEX(Inputs!$D$4:$AG$150,0,MATCH(T$2,Inputs!$D$2:$AG$2,0)),Inputs!$B$4:$B$150,$B11)/1000) -> 0 | U11: =IF(U$3=0,"",SUMIFS(INDEX(Inputs!$D$4:$AG$150,0,MATCH(U$2,Inputs!$D$2:$AG$2,0)),Inputs!$B$4:$B$150,$B11)/1000) -> 0 | V11: =IF(V$3=0,"",SUMIFS(INDEX(Inputs!$D$4:$AG$150,0,MATCH(V$2,Inputs!$D$2:$AG$2,0)),Inputs!$B$4:$B$150,$B11)/1000) -> 0 | W11: =IF(COUNT(S11:V11)=4,SUM(S11:V11),"") -> 0 | X11: =IF(X$3=0,"",SUMIFS(INDEX(Inputs!$D$4:$AG$150,0,MATCH(X$2,Inputs!$D$2:$AG$2,0)),Inputs!$B$4:$B$150,$B11)/1000) -> 0 | Y11: =IF(Y$3=0,"",SUMIFS(INDEX(Inputs!$D$4:$AG$150,0,MATCH(Y$2,Inputs!$D$2:$AG$2,0)),Inputs!$B$4:$B$150,$B11)/1000) -> 0 | Z11: =IF(Z$3=0,"",SUMIFS(INDEX(Inputs!$D$4:$AG$150,0,MATCH(Z$2,Inputs!$D$2:$AG$2,0)),Inputs!$B$4:$B$150,$B11)/1000) -> 0 | AA11: =IF(AA$3=0,"",SUMIFS(INDEX(Inputs!$D$4:$AG$150,0,MATCH(AA$2,Inputs!$D$2:$AG$2,0)),Inputs!$B$4:$B$150,$B11)/1000) -> 0 | AB11: =IF(COUNT(X11:AA11)=4,SUM(X11:AA11),"") -> 0 | AC11: =IF(AC$3=0,"",SUMIFS(INDEX(Inputs!$D$4:$AG$150,0,MATCH(AC$2,Inputs!$D$2:$AG$2,0)),Inputs!$B$4:$B$150,$B11)/1000) -> 0 | AD11: =IF(AD$3=0,"",SUMIFS(INDEX(Inputs!$D$4:$AG$150,0,MATCH(AD$2,Inputs!$D$2:$AG$2,0)),Inputs!$B$4:$B$150,$B11)/1000) -> 0 | AE11: =IF(AE$3=0,"",SUMIFS(INDEX(Inputs!$D$4:$AG$150,0,MATCH(AE$2,Inputs!$D$2:$AG$2,0)),Inputs!$B$4:$B$150,$B11)/1000) | AF11: =IF(AF$3=0,"",SUMIFS(INDEX(Inputs!$D$4:$AG$150,0,MATCH(AF$2,Inputs!$D$2:$AG$2,0)),Inputs!$B$4:$B$150,$B11)/1000) | AG11: =IF(COUNT(AC11:AF11)=4,SUM(AC11:AF11),"")
B12: 9 | C12: Minority Interest Expense, after tax (enter as - ) | D12: =IF(D$3=0,"",SUMIFS(INDEX(Inputs!$D$4:$AG$150,0,MATCH(D$2,Inputs!$D$2:$AG$2,0)),Inputs!$B$4:$B$150,$B12)/1000) -> 0 | E12: =IF(E$3=0,"",SUMIFS(INDEX(Inputs!$D$4:$AG$150,0,MATCH(E$2,Inputs!$D$2:$AG$2,0)),Inputs!$B$4:$B$150,$B12)/1000) -> 0 | F12: =IF(F$3=0,"",SUMIFS(INDEX(Inputs!$D$4:$AG$150,0,MATCH(F$2,Inputs!$D$2:$AG$2,0)),Inputs!$B$4:$B$150,$B12)/1000) -> 0 | G12: =IF(G$3=0,"",SUMIFS(INDEX(Inputs!$D$4:$AG$150,0,MATCH(G$2,Inputs!$D$2:$AG$2,0)),Inputs!$B$4:$B$150,$B12)/1000) -> 0 | H12: =IF(COUNT(D12:G12)=4,SUM(D12:G12),"") -> 0 | I12: =IF(I$3=0,"",SUMIFS(INDEX(Inputs!$D$4:$AG$150,0,MATCH(I$2,Inputs!$D$2:$AG$2,0)),Inputs!$B$4:$B$150,$B12)/1000) -> 0 | J12: =IF(J$3=0,"",SUMIFS(INDEX(Inputs!$D$4:$AG$150,0,MATCH(J$2,Inputs!$D$2:$AG$2,0)),Inputs!$B$4:$B$150,$B12)/1000) -> 0 | K12: =IF(K$3=0,"",SUMIFS(INDEX(Inputs!$D$4:$AG$150,0,MATCH(K$2,Inputs!$D$2:$AG$2,0)),Inputs!$B$4:$B$150,$B12)/1000) -> 0 | L12: =IF(L$3=0,"",SUMIFS(INDEX(Inputs!$D$4:$AG$150,0,MATCH(L$2,Inputs!$D$2:$AG$2,0)),Inputs!$B$4:$B$150,$B12)/1000) -> 0 | M12: =IF(COUNT(I12:L12)=4,SUM(I12:L12),"") -> 0 | N12: =IF(N$3=0,"",SUMIFS(INDEX(Inputs!$D$4:$AG$150,0,MATCH(N$2,Inputs!$D$2:$AG$2,0)),Inputs!$B$4:$B$150,$B12)/1000) -> 0 | O12: =IF(O$3=0,"",SUMIFS(INDEX(Inputs!$D$4:$AG$150,0,MATCH(O$2,Inputs!$D$2:$AG$2,0)),Inputs!$B$4:$B$150,$B12)/1000) -> 0 | P12: =IF(P$3=0,"",SUMIFS(INDEX(Inputs!$D$4:$AG$150,0,MATCH(P$2,Inputs!$D$2:$AG$2,0)),Inputs!$B$4:$B$150,$B12)/1000) -> 0 | Q12: =IF(Q$3=0,"",SUMIFS(INDEX(Inputs!$D$4:$AG$150,0,MATCH(Q$2,Inputs!$D$2:$AG$2,0)),Inputs!$B$4:$B$150,$B12)/1000) -> 0 | R12: =IF(COUNT(N12:Q12)=4,SUM(N12:Q12),"") -> 0 | S12: =IF(S$3=0,"",SUMIFS(INDEX(Inputs!$D$4:$AG$150,0,MATCH(S$2,Inputs!$D$2:$AG$2,0)),Inputs!$B$4:$B$150,$B12)/1000) -> 0 | T12: =IF(T$3=0,"",SUMIFS(INDEX(Inputs!$D$4:$AG$150,0,MATCH(T$2,Inputs!$D$2:$AG$2,0)),Inputs!$B$4:$B$150,$B12)/1000) -> 0 | U12: =IF(U$3=0,"",SUMIFS(INDEX(Inputs!$D$4:$AG$150,0,MATCH(U$2,Inputs!$D$2:$AG$2,0)),Inputs!$B$4:$B$150,$B12)/1000) -> 0 | V12: =IF(V$3=0,"",SUMIFS(INDEX(Inputs!$D$4:$AG$150,0,MATCH(V$2,Inputs!$D$2:$AG$2,0)),Inputs!$B$4:$B$150,$B12)/1000) -> 0 | W12: =IF(COUNT(S12:V12)=4,SUM(S12:V12),"") -> 0 | X12: =IF(X$3=0,"",SUMIFS(INDEX(Inputs!$D$4:$AG$150,0,MATCH(X$2,Inputs!$D$2:$AG$2,0)),Inputs!$B$4:$B$150,$B12)/1000) -> 0 | Y12: =IF(Y$3=0,"",SUMIFS(INDEX(Inputs!$D$4:$AG$150,0,MATCH(Y$2,Inputs!$D$2:$AG$2,0)),Inputs!$B$4:$B$150,$B12)/1000) -> 0 | Z12: =IF(Z$3=0,"",SUMIFS(INDEX(Inputs!$D$4:$AG$150,0,MATCH(Z$2,Inputs!$D$2:$AG$2,0)),Inputs!$B$4:$B$150,$B12)/1000) -> 0 | AA12: =IF(AA$3=0,"",SUMIFS(INDEX(Inputs!$D$4:$AG$150,0,MATCH(AA$2,Inputs!$D$2:$AG$2,0)),Inputs!$B$4:$B$150,$B12)/1000) -> 0 | AB12: =IF(COUNT(X12:AA12)=4,SUM(X12:AA12),"") -> 0 | AC12: =IF(AC$3=0,"",SUMIFS(INDEX(Inputs!$D$4:$AG$150,0,MATCH(AC$2,Inputs!$D$2:$AG$2,0)),Inputs!$B$4:$B$150,$B12)/1000) -> 0 | AD12: =IF(AD$3=0,"",SUMIFS(INDEX(Inputs!$D$4:$AG$150,0,MATCH(AD$2,Inputs!$D$2:$AG$2,0)),Inputs!$B$4:$B$150,$B12)/1000) -> 0 | AE12: =IF(AE$3=0,"",SUMIFS(INDEX(Inputs!$D$4:$AG$150,0,MATCH(AE$2,Inputs!$D$2:$AG$2,0)),Inputs!$B$4:$B$150,$B12)/1000) | AF12: =IF(AF$3=0,"",SUMIFS(INDEX(Inputs!$D$4:$AG$150,0,MATCH(AF$2,Inputs!$D$2:$AG$2,0)),Inputs!$B$4:$B$150,$B12)/1000) | AG12: =IF(COUNT(AC12:AF12)=4,SUM(AC12:AF12),"")
B13: 10 | C13: Common Dividends | D13: =IF(D$3=0,"",SUMIFS(INDEX(Inputs!$D$4:$AG$150,0,MATCH(D$2,Inputs!$D$2:$AG$2,0)),Inputs!$B$4:$B$150,$B13)/1000) -> 358 | E13: =IF(E$3=0,"",SUMIFS(INDEX(Inputs!$D$4:$AG$150,0,MATCH(E$2,Inputs!$D$2:$AG$2,0)),Inputs!$B$4:$B$150,$B13)/1000) -> -3767 | F13: =IF(F$3=0,"",SUMIFS(INDEX(Inputs!$D$4:$AG$150,0,MATCH(F$2,Inputs!$D$2:$AG$2,0)),Inputs!$B$4:$B$150,$B13)/1000) -> -3640 | G13: =IF(G$3=0,"",SUMIFS(INDEX(Inputs!$D$4:$AG$150,0,MATCH(G$2,Inputs!$D$2:$AG$2,0)),Inputs!$B$4:$B$150,$B13)/1000) -> -3732 | H13: =IF(COUNT(D13:G13)=4,SUM(D13:G13),"") -> -10781 | I13: =IF(I$3=0,"",SUMIFS(INDEX(Inputs!$D$4:$AG$150,0,MATCH(I$2,Inputs!$D$2:$AG$2,0)),Inputs!$B$4:$B$150,$B13)/1000) -> -3595 | J13: =IF(J$3=0,"",SUMIFS(INDEX(Inputs!$D$4:$AG$150,0,MATCH(J$2,Inputs!$D$2:$AG$2,0)),Inputs!$B$4:$B$150,$B13)/1000) -> -3811 | K13: =IF(K$3=0,"",SUMIFS(INDEX(Inputs!$D$4:$AG$150,0,MATCH(K$2,Inputs!$D$2:$AG$2,0)),Inputs!$B$4:$B$150,$B13)/1000) -> -3703 | L13: =IF(L$3=0,"",SUMIFS(INDEX(Inputs!$D$4:$AG$150,0,MATCH(L$2,Inputs!$D$2:$AG$2,0)),Inputs!$B$4:$B$150,$B13)/1000) -> -3768 | M13: =IF(COUNT(I13:L13)=4,SUM(I13:L13),"") -> -14877 | N13: =IF(N$3=0,"",SUMIFS(INDEX(Inputs!$D$4:$AG$150,0,MATCH(N$2,Inputs!$D$2:$AG$2,0)),Inputs!$B$4:$B$150,$B13)/1000) -> -3650 | O13: =IF(O$3=0,"",SUMIFS(INDEX(Inputs!$D$4:$AG$150,0,MATCH(O$2,Inputs!$D$2:$AG$2,0)),Inputs!$B$4:$B$150,$B13)/1000) -> -3849 | P13: =IF(P$3=0,"",SUMIFS(INDEX(Inputs!$D$4:$AG$150,0,MATCH(P$2,Inputs!$D$2:$AG$2,0)),Inputs!$B$4:$B$150,$B13)/1000) -> -3758 | Q13: =IF(Q$3=0,"",SUMIFS(INDEX(Inputs!$D$4:$AG$150,0,MATCH(Q$2,Inputs!$D$2:$AG$2,0)),Inputs!$B$4:$B$150,$B13)/1000) -> -3825 | R13: =IF(COUNT(N13:Q13)=4,SUM(N13:Q13),"") -> -15082 | S13: =IF(S$3=0,"",SUMIFS(INDEX(Inputs!$D$4:$AG$150,0,MATCH(S$2,Inputs!$D$2:$AG$2,0)),Inputs!$B$4:$B$150,$B13)/1000) -> -3710 | T13: =IF(T$3=0,"",SUMIFS(INDEX(Inputs!$D$4:$AG$150,0,MATCH(T$2,Inputs!$D$2:$AG$2,0)),Inputs!$B$4:$B$150,$B13)/1000) -> -3895 | U13: =IF(U$3=0,"",SUMIFS(INDEX(Inputs!$D$4:$AG$150,0,MATCH(U$2,Inputs!$D$2:$AG$2,0)),Inputs!$B$4:$B$150,$B13)/1000) -> -3804 | V13: =IF(V$3=0,"",SUMIFS(INDEX(Inputs!$D$4:$AG$150,0,MATCH(V$2,Inputs!$D$2:$AG$2,0)),Inputs!$B$4:$B$150,$B13)/1000) -> -3856 | W13: =IF(COUNT(S13:V13)=4,SUM(S13:V13),"") -> -15265 | X13: =IF(X$3=0,"",SUMIFS(INDEX(Inputs!$D$4:$AG$150,0,MATCH(X$2,Inputs!$D$2:$AG$2,0)),Inputs!$B$4:$B$150,$B13)/1000) -> -3758 | Y13: =IF(Y$3=0,"",SUMIFS(INDEX(Inputs!$D$4:$AG$150,0,MATCH(Y$2,Inputs!$D$2:$AG$2,0)),Inputs!$B$4:$B$150,$B13)/1000) -> -3945 | Z13: =IF(Z$3=0,"",SUMIFS(INDEX(Inputs!$D$4:$AG$150,0,MATCH(Z$2,Inputs!$D$2:$AG$2,0)),Inputs!$B$4:$B$150,$B13)/1000) -> -3862 | AA13: =IF(AA$3=0,"",SUMIFS(INDEX(Inputs!$D$4:$AG$150,0,MATCH(AA$2,Inputs!$D$2:$AG$2,0)),Inputs!$B$4:$B$150,$B13)/1000) -> -3921 | AB13: =IF(COUNT(X13:AA13)=4,SUM(X13:AA13),"") -> -15486 | AC13: =IF(AC$3=0,"",SUMIFS(INDEX(Inputs!$D$4:$AG$150,0,MATCH(AC$2,Inputs!$D$2:$AG$2,0)),Inputs!$B$4:$B$150,$B13)/1000) -> -3822 | AD13: =IF(AD$3=0,"",SUMIFS(INDEX(Inputs!$D$4:$AG$150,0,MATCH(AD$2,Inputs!$D$2:$AG$2,0)),Inputs!$B$4:$B$150,$B13)/1000) -> -4035 | AE13: =IF(AE$3=0,"",SUMIFS(INDEX(Inputs!$D$4:$AG$150,0,MATCH(AE$2,Inputs!$D$2:$AG$2,0)),Inputs!$B$4:$B$150,$B13)/1000) | AF13: =IF(AF$3=0,"",SUMIFS(INDEX(Inputs!$D$4:$AG$150,0,MATCH(AF$2,Inputs!$D$2:$AG$2,0)),Inputs!$B$4:$B$150,$B13)/1000) | AG13: =IF(COUNT(AC13:AF13)=4,SUM(AC13:AF13),"")
B15: 11 | C15: Cash and equivalents (inc. investment securities) | D15: =IF(D$3=0,"",SUMIFS(INDEX(Inputs!$D$4:$AG$150,0,MATCH(D$2,Inputs!$D$2:$AG$2,0)),Inputs!$B$4:$B$150,$B15)/1000) -> 204373 | E15: =IF(E$3=0,"",SUMIFS(INDEX(Inputs!$D$4:$AG$150,0,MATCH(E$2,Inputs!$D$2:$AG$2,0)),Inputs!$B$4:$B$150,$B15)/1000) -> 193644 | F15: =IF(F$3=0,"",SUMIFS(INDEX(Inputs!$D$4:$AG$150,0,MATCH(F$2,Inputs!$D$2:$AG$2,0)),Inputs!$B$4:$B$150,$B15)/1000) -> 190516 | G15: =IF(G$3=0,"",SUMIFS(INDEX(Inputs!$D$4:$AG$150,0,MATCH(G$2,Inputs!$D$2:$AG$2,0)),Inputs!$B$4:$B$150,$B15)/1000) -> 202596 | H15: =IF(G15="","",G15) -> 202596 | I15: =IF(I$3=0,"",SUMIFS(INDEX(Inputs!$D$4:$AG$150,0,MATCH(I$2,Inputs!$D$2:$AG$2,0)),Inputs!$B$4:$B$150,$B15)/1000) -> 192730 | J15: =IF(J$3=0,"",SUMIFS(INDEX(Inputs!$D$4:$AG$150,0,MATCH(J$2,Inputs!$D$2:$AG$2,0)),Inputs!$B$4:$B$150,$B15)/1000) -> 179308 | K15: =IF(K$3=0,"",SUMIFS(INDEX(Inputs!$D$4:$AG$150,0,MATCH(K$2,Inputs!$D$2:$AG$2,0)),Inputs!$B$4:$B$150,$B15)/1000) -> 169109 | L15: =IF(L$3=0,"",SUMIFS(INDEX(Inputs!$D$4:$AG$150,0,MATCH(L$2,Inputs!$D$2:$AG$2,0)),Inputs!$B$4:$B$150,$B15)/1000) -> 165450 | M15: =IF(L15="","",L15) -> 165450 | N15: =IF(N$3=0,"",SUMIFS(INDEX(Inputs!$D$4:$AG$150,0,MATCH(N$2,Inputs!$D$2:$AG$2,0)),Inputs!$B$4:$B$150,$B15)/1000) -> 166333 | O15: =IF(O$3=0,"",SUMIFS(INDEX(Inputs!$D$4:$AG$150,0,MATCH(O$2,Inputs!$D$2:$AG$2,0)),Inputs!$B$4:$B$150,$B15)/1000) -> 166543 | P15: =IF(P$3=0,"",SUMIFS(INDEX(Inputs!$D$4:$AG$150,0,MATCH(P$2,Inputs!$D$2:$AG$2,0)),Inputs!$B$4:$B$150,$B15)/1000) -> 162099 | Q15: =IF(Q$3=0,"",SUMIFS(INDEX(Inputs!$D$4:$AG$150,0,MATCH(Q$2,Inputs!$D$2:$AG$2,0)),Inputs!$B$4:$B$150,$B15)/1000) -> 172575 | R15: =IF(Q15="","",Q15) -> 172575 | S15: =IF(S$3=0,"",SUMIFS(INDEX(Inputs!$D$4:$AG$150,0,MATCH(S$2,Inputs!$D$2:$AG$2,0)),Inputs!$B$4:$B$150,$B15)/1000) -> 162337 | T15: =IF(T$3=0,"",SUMIFS(INDEX(Inputs!$D$4:$AG$150,0,MATCH(T$2,Inputs!$D$2:$AG$2,0)),Inputs!$B$4:$B$150,$B15)/1000) -> 153041 | U15: =IF(U$3=0,"",SUMIFS(INDEX(Inputs!$D$4:$AG$150,0,MATCH(U$2,Inputs!$D$2:$AG$2,0)),Inputs!$B$4:$B$150,$B15)/1000) -> 156650 | V15: =IF(V$3=0,"",SUMIFS(INDEX(Inputs!$D$4:$AG$150,0,MATCH(V$2,Inputs!$D$2:$AG$2,0)),Inputs!$B$4:$B$150,$B15)/1000) -> 141368 | W15: =IF(V15="","",V15) -> 141368 | X15: =IF(X$3=0,"",SUMIFS(INDEX(Inputs!$D$4:$AG$150,0,MATCH(X$2,Inputs!$D$2:$AG$2,0)),Inputs!$B$4:$B$150,$B15)/1000) -> 132922 | Y15: =IF(Y$3=0,"",SUMIFS(INDEX(Inputs!$D$4:$AG$150,0,MATCH(Y$2,Inputs!$D$2:$AG$2,0)),Inputs!$B$4:$B$150,$B15)/1000) -> 132986 | Z15: =IF(Z$3=0,"",SUMIFS(INDEX(Inputs!$D$4:$AG$150,0,MATCH(Z$2,Inputs!$D$2:$AG$2,0)),Inputs!$B$4:$B$150,$B15)/1000) -> 132420 | AA15: =IF(AA$3=0,"",SUMIFS(INDEX(Inputs!$D$4:$AG$150,0,MATCH(AA$2,Inputs!$D$2:$AG$2,0)),Inputs!$B$4:$B$150,$B15)/1000) -> 144795 | AB15: =IF(AA15="","",AA15) -> 144795 | AC15: =IF(AC$3=0,"",SUMIFS(INDEX(Inputs!$D$4:$AG$150,0,MATCH(AC$2,Inputs!$D$2:$AG$2,0)),Inputs!$B$4:$B$150,$B15)/1000) -> 146595 | AD15: =IF(AD$3=0,"",SUMIFS(INDEX(Inputs!$D$4:$AG$150,0,MATCH(AD$2,Inputs!$D$2:$AG$2,0)),Inputs!$B$4:$B$150,$B15)/1000) -> 146517 | AE15: =IF(AE$3=0,"",SUMIFS(INDEX(Inputs!$D$4:$AG$150,0,MATCH(AE$2,Inputs!$D$2:$AG$2,0)),Inputs!$B$4:$B$150,$B15)/1000) | AF15: =IF(AF$3=0,"",SUMIFS(INDEX(Inputs!$D$4:$AG$150,0,MATCH(AF$2,Inputs!$D$2:$AG$2,0)),Inputs!$B$4:$B$150,$B15)/1000) | AG15: =IF(AF15="","",AF15)
