Workbook
Name beta_observed: Valuation!$D$93
Name last_close: Valuation!$G$7
Name ticker: Valuation!$D$7
Name Useful_Life_of_Depreciable_PP_E: "PPElife"
Name beta_observed: #REF!
Name ticker: #REF!
Name costdebtfirm: Valuation!$D$86
Name costequity: Valuation!$D$94
Name debt: Valuation!$G$88
Name debt_weight: Valuation!$J$88
Name g: Valuation!$D$63
Name market_equity: Valuation!$G$89
Name noplat_t1: Valuation!$D$65
Name relevered_beta: Valuation!$M$102
Name risk_free_rate: Valuation!$D$91
Name risk_premium: Valuation!$D$92
Name ronic: Valuation!$D$64
Name stub_year_fraction: Valuation!$D$11
Name totalcap: Valuation!$G$90
Name wacc: Valuation!$D$12

Sheet Inputs
A1: Base histórica normalizada (US$ mil) — convertida da máscara anterior; linhas de origem auditáveis
A2: Fonte / conta original | B2: Código | C2: Conta padronizada | D2: 1Q21 | E2: 2Q21 | F2: 3Q21 | G2: 4Q21 | H2: 2021 | I2: 1Q22 | J2: 2Q22 | K2: 3Q22 | L2: 4Q22 | M2: 2022 | N2: 1Q23 | O2: 2Q23 | P2: 3Q23 | Q2: 4Q23 | R2: 2023 | S2: 1Q24 | T2: 2Q24 | U2: 3Q24 | V2: 4Q24 | W2: 2024 | X2: 1Q25 | Y2: 2Q25 | Z2: 3Q25 | AA2: 4Q25 | AB2: 2025 | AC2: 1Q26 | AD2: 2Q26 | AE2: 3Q26 | AF2: 4Q26 | AG2: 2026
A3: Fonte: ver coluna A de cada linha | C3: Unidade: US$ mil (monetário); demais unidades × 1.000
A4: DRE - trimestre isolado (USD). Brutos SEC XBRL; linhas "derivada" são fórmulas nesta aba | C4: [linha bruta, sem código; lançada nas linhas abaixo]
A5: Receita [us-gaap:Revenues] · fonte · unid. moeda | B5: 1 | C5: Net Revenues | D5: 59147000 | E5: 67742000 | F5: 73786000 | G5: 84965000 | I5: 90500000 | J5: 115681000 | K5: 112070000 | L5: 95429000 | N5: 86564000 | O5: 82914000 | P5: 90760000 | Q5: 84344000 | S5: 83083000 | T5: 93060000 | U5: 90016000 | V5: 83426000 | X5: 83130000 | Y5: 81506000 | Z5: 85294000 | AA5: 82308000 | AC5: 85138000 | AD5: 116017000
A6: Custo da receita (divulgado positivo) [us-gaap:CrudeOilAndProductPurchases] · fonte · unid. moeda | C6: [linha bruta, sem código; lançada nas linhas abaixo] | D6: 32601000 | E6: 37329000 | F6: 39745000 | G6: 45489000 | I6: 52388000 | J6: 65613000 | K6: 60197000 | L6: 50761000 | N6: 46003000 | O6: 47598000 | P6: 53076000 | Q6: 46352000 | S6: 47601000 | T6: 54199000 | U6: 51261000 | V6: 46393000 | X6: 46788000 | Y6: 45327000 | Z6: 47928000 | AA6: 44205000 | AC6: 51802000 | AD6: 67801000
A7: (lançamento) código 2, sinal -1 sobre a linha bruta 6: Custo da receita (divulgado positivo) [us-gaap:CrudeOilAndProductPurchases] | B7: 2 | C7: COGS (cash) | D7: =IF(D6="","",-1*D6) -> -32601000 | E7: =IF(E6="","",-1*E6) -> -37329000 | F7: =IF(F6="","",-1*F6) -> -39745000 | G7: =IF(G6="","",-1*G6) -> -45489000 | I7: =IF(I6="","",-1*I6) -> -52388000 | J7: =IF(J6="","",-1*J6) -> -65613000 | K7: =IF(K6="","",-1*K6) -> -60197000 | L7: =IF(L6="","",-1*L6) -> -50761000 | N7: =IF(N6="","",-1*N6) -> -46003000 | O7: =IF(O6="","",-1*O6) -> -47598000 | P7: =IF(P6="","",-1*P6) -> -53076000 | Q7: =IF(Q6="","",-1*Q6) -> -46352000 | S7: =IF(S6="","",-1*S6) -> -47601000 | T7: =IF(T6="","",-1*T6) -> -54199000 | U7: =IF(U6="","",-1*U6) -> -51261000 | V7: =IF(V6="","",-1*V6) -> -46393000 | X7: =IF(X6="","",-1*X6) -> -46788000 | Y7: =IF(Y6="","",-1*Y6) -> -45327000 | Z7: =IF(Z6="","",-1*Z6) -> -47928000 | AA7: =IF(AA6="","",-1*AA6) -> -44205000 | AC7: =IF(AC6="","",-1*AC6) -> -51802000 | AD7: =IF(AD6="","",-1*AD6) -> -67801000
A8: Lucro operacional DERIVADO = receita - custos e despesas totais [us-gaap:CostsAndExpenses] + despesa de juros (a companhia não divulga lucro operacional) · memoria · unid. moeda | C8: [linha bruta, sem código; lançada nas linhas abaixo] | D8: 3850000 | E8: 6561000 | F8: 9820000 | G8: 11950000 | I8: 8744000 | J8: 25127000 | K8: 25631000 | L8: 19049000 | N8: 16962000 | O8: 11905000 | P8: 13868000 | Q8: 10897000 | S8: 12590000 | T8: 13936000 | U8: 13233000 | V8: 10110000 | X8: 11805000 | Y8: 10850000 | Z8: 11022000 | AA8: 8194000 | AC8: 7262000 | AD8: 19651000
A9: Despesas operacionais = receita - custo - lucro operacional (P&D + SG&A + outras operacionais) · derivada · unid. moeda | C9: [linha bruta, sem código; lançada nas linhas abaixo] | D9: =N(D5)-N(D6)-N(D8) -> 22696000 | E9: =N(E5)-N(E6)-N(E8) -> 23852000 | F9: =N(F5)-N(F6)-N(F8) -> 24221000 | G9: =N(G5)-N(G6)-N(G8) -> 27526000 | I9: =N(I5)-N(I6)-N(I8) -> 29368000 | J9: =N(J5)-N(J6)-N(J8) -> 24941000 | K9: =N(K5)-N(K6)-N(K8) -> 26242000 | L9: =N(L5)-N(L6)-N(L8) -> 25619000 | N9: =N(N5)-N(N6)-N(N8) -> 23599000 | O9: =N(O5)-N(O6)-N(O8) -> 23411000 | P9: =N(P5)-N(P6)-N(P8) -> 23816000 | Q9: =N(Q5)-N(Q6)-N(Q8) -> 27095000 | S9: =N(S5)-N(S6)-N(S8) -> 22892000 | T9: =N(T5)-N(T6)-N(T8) -> 24925000 | U9: =N(U5)-N(U6)-N(U8) -> 25522000 | V9: =N(V5)-N(V6)-N(V8) -> 26923000 | X9: =N(X5)-N(X6)-N(X8) -> 24537000 | Y9: =N(Y5)-N(Y6)-N(Y8) -> 25329000 | Z9: =N(Z5)-N(Z6)-N(Z8) -> 26344000 | AA9: =N(AA5)-N(AA6)-N(AA8) -> 29909000 | AC9: =N(AC5)-N(AC6)-N(AC8) -> 26074000 | AD9: =N(AD5)-N(AD6)-N(AD8) -> 28565000
A10: (lançamento) código 3, sinal -1 sobre a linha bruta 9: Despesas operacionais = receita - custo - lucro operacional (P&D + SG&A + outras operacion | B10: 3 | C10: SG&A and Other (cash) | D10: =IF(D9="","",-1*D9) -> -22696000 | E10: =IF(E9="","",-1*E9) -> -23852000 | F10: =IF(F9="","",-1*F9) -> -24221000 | G10: =IF(G9="","",-1*G9) -> -27526000 | I10: =IF(I9="","",-1*I9) -> -29368000 | J10: =IF(J9="","",-1*J9) -> -24941000 | K10: =IF(K9="","",-1*K9) -> -26242000 | L10: =IF(L9="","",-1*L9) -> -25619000 | N10: =IF(N9="","",-1*N9) -> -23599000 | O10: =IF(O9="","",-1*O9) -> -23411000 | P10: =IF(P9="","",-1*P9) -> -23816000 | Q10: =IF(Q9="","",-1*Q9) -> -27095000 | S10: =IF(S9="","",-1*S9) -> -22892000 | T10: =IF(T9="","",-1*T9) -> -24925000 | U10: =IF(U9="","",-1*U9) -> -25522000 | V10: =IF(V9="","",-1*V9) -> -26923000 | X10: =IF(X9="","",-1*X9) -> -24537000 | Y10: =IF(Y9="","",-1*Y9) -> -25329000 | Z10: =IF(Z9="","",-1*Z9) -> -26344000 | AA10: =IF(AA9="","",-1*AA9) -> -29909000 | AC10: =IF(AC9="","",-1*AC9) -> -26074000 | AD10: =IF(AD9="","",-1*AD9) -> -28565000
A11: Lucro antes do IR [us-gaap:IncomeLossFromContinuingOperationsBeforeIncomeTaxesExtraordi] · memoria · unid. moeda | C11: [linha bruta, sem código; lançada nas linhas abaixo] | D11: 3592000 | E11: 6307000 | F11: 9606000 | G11: 11729000 | I11: 8556000 | J11: 24933000 | K11: 25422000 | L11: 18842000 | N11: 16803000 | O11: 11656000 | P11: 13699000 | Q11: 10625000 | S11: 12369000 | T11: 13665000 | U11: 13026000 | V11: 9813000 | X11: 11600000 | Y11: 10705000 | Z11: 10932000 | AA11: 8031000 | AC11: 6967000 | AD11: 19424000
A12: Resultado não operacional total = lucro antes do IR - lucro operacional · derivada · unid. moeda | B12: 6 | C12: Nonoperating Income / (Loss) | D12: =N(D11)-N(D8) -> -258000 | E12: =N(E11)-N(E8) -> -254000 | F12: =N(F11)-N(F8) -> -214000 | G12: =N(G11)-N(G8) -> -221000 | I12: =N(I11)-N(I8) -> -188000 | J12: =N(J11)-N(J8) -> -194000 | K12: =N(K11)-N(K8) -> -209000 | L12: =N(L11)-N(L8) -> -207000 | N12: =N(N11)-N(N8) -> -159000 | O12: =N(O11)-N(O8) -> -249000 | P12: =N(P11)-N(P8) -> -169000 | Q12: =N(Q11)-N(Q8) -> -272000 | S12: =N(S11)-N(S8) -> -221000 | T12: =N(T11)-N(T8) -> -271000 | U12: =N(U11)-N(U8) -> -207000 | V12: =N(V11)-N(V8) -> -297000 | X12: =N(X11)-N(X8) -> -205000 | Y12: =N(Y11)-N(Y8) -> -145000 | Z12: =N(Z11)-N(Z8) -> -90000 | AA12: =N(AA11)-N(AA8) -> -163000 | AC12: =N(AC11)-N(AC8) -> -295000 | AD12: =N(AD11)-N(AD8) -> -227000
A13: Despesa de juros (divulgado positivo): COD1=5 lança; COD2=6 devolve ao não operacional, que já a contém [us-gaap:InterestExpense/InterestExpenseNonoperating] · fonte · unid. moeda | C13: [linha bruta, sem código; lançada nas linhas abaixo] | D13: 258000 | E13: 254000 | F13: 214000 | G13: 221000 | I13: 188000 | J13: 194000 | K13: 209000 | L13: 207000 | N13: 159000 | O13: 249000 | P13: 169000 | Q13: 272000 | S13: 221000 | T13: 271000 | U13: 207000 | V13: 297000 | X13: 205000 | Y13: 145000 | Z13: 90000 | AA13: 163000 | AC13: 295000 | AD13: 227000
A14: (lançamento) código 5, sinal -1 sobre a linha bruta 13: Despesa de juros (divulgado positivo): COD1=5 lança; COD2=6 devolve ao não operacional, qu | B14: 5 | C14: Interest Expense | D14: =IF(D13="","",-1*D13) -> -258000 | E14: =IF(E13="","",-1*E13) -> -254000 | F14: =IF(F13="","",-1*F13) -> -214000 | G14: =IF(G13="","",-1*G13) -> -221000 | I14: =IF(I13="","",-1*I13) -> -188000 | J14: =IF(J13="","",-1*J13) -> -194000 | K14: =IF(K13="","",-1*K13) -> -209000 | L14: =IF(L13="","",-1*L13) -> -207000 | N14: =IF(N13="","",-1*N13) -> -159000 | O14: =IF(O13="","",-1*O13) -> -249000 | P14: =IF(P13="","",-1*P13) -> -169000 | Q14: =IF(Q13="","",-1*Q13) -> -272000 | S14: =IF(S13="","",-1*S13) -> -221000 | T14: =IF(T13="","",-1*T13) -> -271000 | U14: =IF(U13="","",-1*U13) -> -207000 | V14: =IF(V13="","",-1*V13) -> -297000 | X14: =IF(X13="","",-1*X13) -> -205000 | Y14: =IF(Y13="","",-1*Y13) -> -145000 | Z14: =IF(Z13="","",-1*Z13) -> -90000 | AA14: =IF(AA13="","",-1*AA13) -> -163000 | AC14: =IF(AC13="","",-1*AC13) -> -295000 | AD14: =IF(AD13="","",-1*AD13) -> -227000
A15: (lançamento) código 6, sinal +1 sobre a linha bruta 13: Despesa de juros (divulgado positivo): COD1=5 lança; COD2=6 devolve ao não operacional, qu | B15: 6 | C15: Nonoperating Income / (Loss) | D15: =IF(D13="","",D13) -> 258000 | E15: =IF(E13="","",E13) -> 254000 | F15: =IF(F13="","",F13) -> 214000 | G15: =IF(G13="","",G13) -> 221000 | I15: =IF(I13="","",I13) -> 188000 | J15: =IF(J13="","",J13) -> 194000 | K15: =IF(K13="","",K13) -> 209000 | L15: =IF(L13="","",L13) -> 207000 | N15: =IF(N13="","",N13) -> 159000 | O15: =IF(O13="","",O13) -> 249000 | P15: =IF(P13="","",P13) -> 169000 | Q15: =IF(Q13="","",Q13) -> 272000 | S15: =IF(S13="","",S13) -> 221000 | T15: =IF(T13="","",T13) -> 271000 | U15: =IF(U13="","",U13) -> 207000 | V15: =IF(V13="","",V13) -> 297000 | X15: =IF(X13="","",X13) -> 205000 | Y15: =IF(Y13="","",Y13) -> 145000 | Z15: =IF(Z13="","",Z13) -> 90000 | AA15: =IF(AA13="","",AA13) -> 163000 | AC15: =IF(AC13="","",AC13) -> 295000 | AD15: =IF(AD13="","",AD13) -> 227000
A16: Imposto de renda (divulgado positivo) [us-gaap:IncomeTaxExpenseBenefit] · fonte · unid. moeda | C16: [linha bruta, sem código; lançada nas linhas abaixo] | D16: 796000 | E16: 1526000 | F16: 2664000 | G16: 2650000 | I16: 2806000 | J16: 6359000 | K16: 5224000 | L16: 5787000 | N16: 4960000 | O16: 3503000 | P16: 4353000 | Q16: 2613000 | S16: 3803000 | T16: 4094000 | U16: 4055000 | V16: 1858000 | X16: 3567000 | Y16: 3351000 | Z16: 3164000 | AA16: 1422000 | AC16: 2495000 | AD16: 4543000
A17: (lançamento) código 7, sinal -1 sobre a linha bruta 16: Imposto de renda (divulgado positivo) [us-gaap:IncomeTaxExpenseBenefit] | B17: 7 | C17: Taxes | D17: =IF(D16="","",-1*D16) -> -796000 | E17: =IF(E16="","",-1*E16) -> -1526000 | F17: =IF(F16="","",-1*F16) -> -2664000 | G17: =IF(G16="","",-1*G16) -> -2650000 | I17: =IF(I16="","",-1*I16) -> -2806000 | J17: =IF(J16="","",-1*J16) -> -6359000 | K17: =IF(K16="","",-1*K16) -> -5224000 | L17: =IF(L16="","",-1*L16) -> -5787000 | N17: =IF(N16="","",-1*N16) -> -4960000 | O17: =IF(O16="","",-1*O16) -> -3503000 | P17: =IF(P16="","",-1*P16) -> -4353000 | Q17: =IF(Q16="","",-1*Q16) -> -2613000 | S17: =IF(S16="","",-1*S16) -> -3803000 | T17: =IF(T16="","",-1*T16) -> -4094000 | U17: =IF(U16="","",-1*U16) -> -4055000 | V17: =IF(V16="","",-1*V16) -> -1858000 | X17: =IF(X16="","",-1*X16) -> -3567000 | Y17: =IF(Y16="","",-1*Y16) -> -3351000 | Z17: =IF(Z16="","",-1*Z16) -> -3164000 | AA17: =IF(AA16="","",-1*AA16) -> -1422000 | AC17: =IF(AC16="","",-1*AC16) -> -2495000 | AD17: =IF(AD16="","",-1*AD16) -> -4543000
A18: Lucro atribuído a não controladores (divulgado positivo) [us-gaap:NetIncomeLossAttributableToNoncontrollingInterest] · fonte · unid. moeda | C18: [linha bruta, sem código; lançada nas linhas abaixo] | D18: 66000 | E18: 91000 | F18: 192000 | G18: 209000 | I18: 270000 | J18: 724000 | K18: 538000 | L18: 305000 | N18: 413000 | O18: 273000 | P18: 276000 | Q18: 382000 | S18: 346000 | T18: 331000 | U18: 361000 | V18: 345000 | X18: 320000 | Y18: 272000 | Z18: 220000 | AA18: 108000 | AC18: 289000 | AD18: 356000
A19: (lançamento) código 9, sinal -1 sobre a linha bruta 18: Lucro atribuído a não controladores (divulgado positivo) [us-gaap:NetIncomeLossAttributabl | B19: 9 | C19: Minority Interest Expense, after tax (enter as - ) | D19: =IF(D18="","",-1*D18) -> -66000 | E19: =IF(E18="","",-1*E18) -> -91000 | F19: =IF(F18="","",-1*F18) -> -192000 | G19: =IF(G18="","",-1*G18) -> -209000 | I19: =IF(I18="","",-1*I18) -> -270000 | J19: =IF(J18="","",-1*J18) -> -724000 | K19: =IF(K18="","",-1*K18) -> -538000 | L19: =IF(L18="","",-1*L18) -> -305000 | N19: =IF(N18="","",-1*N18) -> -413000 | O19: =IF(O18="","",-1*O18) -> -273000 | P19: =IF(P18="","",-1*P18) -> -276000 | Q19: =IF(Q18="","",-1*Q18) -> -382000 | S19: =IF(S18="","",-1*S18) -> -346000 | T19: =IF(T18="","",-1*T18) -> -331000 | U19: =IF(U18="","",-1*U18) -> -361000 | V19: =IF(V18="","",-1*V18) -> -345000 | X19: =IF(X18="","",-1*X18) -> -320000 | Y19: =IF(Y18="","",-1*Y18) -> -272000 | Z19: =IF(Z18="","",-1*Z18) -> -220000 | AA19: =IF(AA18="","",-1*AA18) -> -108000 | AC19: =IF(AC18="","",-1*AC18) -> -289000 | AD19: =IF(AD18="","",-1*AD18) -> -356000
A20: Lucro líquido atribuído à companhia [us-gaap:NetIncomeLoss] · memoria · unid. moeda | C20: [linha bruta, sem código; lançada nas linhas abaixo] | D20: 2730000 | E20: 4690000 | F20: 6750000 | G20: 8870000 | I20: 5480000 | J20: 17850000 | K20: 19660000 | L20: 12750000 | N20: 11430000 | O20: 7880000 | P20: 9070000 | Q20: 7630000 | S20: 8220000 | T20: 9240000 | U20: 8610000 | V20: 7610000 | X20: 7713000 | Y20: 7082000 | Z20: 7548000 | AA20: 6501000 | AC20: 4183000 | AD20: 14525000
A21: Resultado após IR não classificado acima (equivalência patrimonial, operações descontinuadas): lucro - (LAIR - IR - minoritários); zero quando não há · derivada · unid. moeda | B21: 8 | C21: Equity in Income of Affiliates, after tax (enter as +) | D21: =N(D20)-(N(D11)-N(D16)-N(D18)) -> 0 | E21: =N(E20)-(N(E11)-N(E16)-N(E18)) -> 0 | F21: =N(F20)-(N(F11)-N(F16)-N(F18)) -> 0 | G21: =N(G20)-(N(G11)-N(G16)-N(G18)) -> 0 | I21: =N(I20)-(N(I11)-N(I16)-N(I18)) -> 0 | J21: =N(J20)-(N(J11)-N(J16)-N(J18)) -> 0 | K21: =N(K20)-(N(K11)-N(K16)-N(K18)) -> 0 | L21: =N(L20)-(N(L11)-N(L16)-N(L18)) -> 0 | N21: =N(N20)-(N(N11)-N(N16)-N(N18)) -> 0 | O21: =N(O20)-(N(O11)-N(O16)-N(O18)) -> 0 | P21: =N(P20)-(N(P11)-N(P16)-N(P18)) -> 0 | Q21: =N(Q20)-(N(Q11)-N(Q16)-N(Q18)) -> 0 | S21: =N(S20)-(N(S11)-N(S16)-N(S18)) -> 0 | T21: =N(T20)-(N(T11)-N(T16)-N(T18)) -> 0 | U21: =N(U20)-(N(U11)-N(U16)-N(U18)) -> 0 | V21: =N(V20)-(N(V11)-N(V16)-N(V18)) -> 0 | X21: =N(X20)-(N(X11)-N(X16)-N(X18)) -> 0 | Y21: =N(Y20)-(N(Y11)-N(Y16)-N(Y18)) -> 0 | Z21: =N(Z20)-(N(Z11)-N(Z16)-N(Z18)) -> 0 | AA21: =N(AA20)-(N(AA11)-N(AA16)-N(AA18)) -> 0 | AC21: =N(AC20)-(N(AC11)-N(AC16)-N(AC18)) -> 0 | AD21: =N(AD20)-(N(AD11)-N(AD16)-N(AD18)) -> 0
A22: Lucro líquido (check IS, código 44) · derivada · unid. moeda | B22: 44 | C22: Lucro líquido (check IS, código 44) | D22: =N(D20) -> 2730000 | E22: =N(E20) -> 4690000 | F22: =N(F20) -> 6750000 | G22: =N(G20) -> 8870000 | I22: =N(I20) -> 5480000 | J22: =N(J20) -> 17850000 | K22: =N(K20) -> 19660000 | L22: =N(L20) -> 12750000 | N22: =N(N20) -> 11430000 | O22: =N(O20) -> 7880000 | P22: =N(P20) -> 9070000 | Q22: =N(Q20) -> 7630000 | S22: =N(S20) -> 8220000 | T22: =N(T20) -> 9240000 | U22: =N(U20) -> 8610000 | V22: =N(V20) -> 7610000 | X22: =N(X20) -> 7713000 | Y22: =N(Y20) -> 7082000 | Z22: =N(Z20) -> 7548000 | AA22: =N(AA20) -> 6501000 | AC22: =N(AC20) -> 4183000 | AD22: =N(AD20) -> 14525000
A23: DFC - trimestre isolado (desacumulado na extração) | C23: [linha bruta, sem código; lançada nas linhas abaixo]
A24: D&A (fluxo de caixa). COD1=4 lança (positivo -> -1); COD2=3 devolve às despesas operacionais (a companhia não abre D&A entre custo e despesa) [us-gaap:DepreciationDepletionAndAmortization/DepreciationAmortizationAndImpairment] · fonte · unid. moeda | C24: [linha bruta, sem código; lançada nas linhas abaixo] | D24: 5004000 | E24: 4952000 | F24: 4990000 | G24: 5661000 | I24: 8883000 | J24: 4451000 | K24: 5642000 | L24: 5064000 | N24: 4244000 | O24: 4242000 | P24: 4415000 | Q24: 7740000 | S24: 4812000 | T24: 5787000 | U24: 6258000 | V24: 6585000 | X24: 5702000 | Y24: 6101000 | Z24: 6475000 | AA24: 7715000 | AC24: 6771000 | AD24: 8689000
A25: (lançamento) código 4, sinal -1 sobre a linha bruta 24: D&A (fluxo de caixa). COD1=4 lança (positivo -> -1); COD2=3 devolve às despesas operaciona | B25: 4 | C25: D&A | D25: =IF(D24="","",-1*D24) -> -5004000 | E25: =IF(E24="","",-1*E24) -> -4952000 | F25: =IF(F24="","",-1*F24) -> -4990000 | G25: =IF(G24="","",-1*G24) -> -5661000 | I25: =IF(I24="","",-1*I24) -> -8883000 | J25: =IF(J24="","",-1*J24) -> -4451000 | K25: =IF(K24="","",-1*K24) -> -5642000 | L25: =IF(L24="","",-1*L24) -> -5064000 | N25: =IF(N24="","",-1*N24) -> -4244000 | O25: =IF(O24="","",-1*O24) -> -4242000 | P25: =IF(P24="","",-1*P24) -> -4415000 | Q25: =IF(Q24="","",-1*Q24) -> -7740000 | S25: =IF(S24="","",-1*S24) -> -4812000 | T25: =IF(T24="","",-1*T24) -> -5787000 | U25: =IF(U24="","",-1*U24) -> -6258000 | V25: =IF(V24="","",-1*V24) -> -6585000 | X25: =IF(X24="","",-1*X24) -> -5702000 | Y25: =IF(Y24="","",-1*Y24) -> -6101000 | Z25: =IF(Z24="","",-1*Z24) -> -6475000 | AA25: =IF(AA24="","",-1*AA24) -> -7715000 | AC25: =IF(AC24="","",-1*AC24) -> -6771000 | AD25: =IF(AD24="","",-1*AD24) -> -8689000
A26: (lançamento) código 3, sinal +1 sobre a linha bruta 24: D&A (fluxo de caixa). COD1=4 lança (positivo -> -1); COD2=3 devolve às despesas operaciona | B26: 3 | C26: SG&A and Other (cash) | D26: =IF(D24="","",D24) -> 5004000 | E26: =IF(E24="","",E24) -> 4952000 | F26: =IF(F24="","",F24) -> 4990000 | G26: =IF(G24="","",G24) -> 5661000 | I26: =IF(I24="","",I24) -> 8883000 | J26: =IF(J24="","",J24) -> 4451000 | K26: =IF(K24="","",K24) -> 5642000 | L26: =IF(L24="","",L24) -> 5064000 | N26: =IF(N24="","",N24) -> 4244000 | O26: =IF(O24="","",O24) -> 4242000 | P26: =IF(P24="","",P24) -> 4415000 | Q26: =IF(Q24="","",Q24) -> 7740000 | S26: =IF(S24="","",S24) -> 4812000 | T26: =IF(T24="","",T24) -> 5787000 | U26: =IF(U24="","",U24) -> 6258000 | V26: =IF(V24="","",V24) -> 6585000 | X26: =IF(X24="","",X24) -> 5702000 | Y26: =IF(Y24="","",Y24) -> 6101000 | Z26: =IF(Z24="","",Z24) -> 6475000 | AA26: =IF(AA24="","",AA24) -> 7715000 | AC26: =IF(AC24="","",AC24) -> 6771000 | AD26: =IF(AD24="","",AD24) -> 8689000
A27: Dividendos pagos [us-gaap:PaymentsOfDividends] · fonte · unid. moeda | C27: [linha bruta, sem código; lançada nas linhas abaixo] | D27: 3720000 | E27: 3721000 | F27: 3720000 | G27: 3763000 | I27: 3760000 | J27: 3727000 | K27: 3685000 | L27: 3767000 | N27: 3738000 | O27: 3701000 | P27: 3663000 | Q27: 3839000 | S27: 3808000 | T27: 4285000 | U27: 4240000 | V27: 4371000 | X27: 4335000 | Y27: 4288000 | Z27: 4242000 | AA27: 4366000 | AC27: 4334000 | AD27: 4299000
A28: (lançamento) código 10, sinal -1 sobre a linha bruta 27: Dividendos pagos [us-gaap:PaymentsOfDividends] | B28: 10 | C28: Common Dividends | D28: =IF(D27="","",-1*D27) -> -3720000 | E28: =IF(E27="","",-1*E27) -> -3721000 | F28: =IF(F27="","",-1*F27) -> -3720000 | G28: =IF(G27="","",-1*G27) -> -3763000 | I28: =IF(I27="","",-1*I27) -> -3760000 | J28: =IF(J27="","",-1*J27) -> -3727000 | K28: =IF(K27="","",-1*K27) -> -3685000 | L28: =IF(L27="","",-1*L27) -> -3767000 | N28: =IF(N27="","",-1*N27) -> -3738000 | O28: =IF(O27="","",-1*O27) -> -3701000 | P28: =IF(P27="","",-1*P27) -> -3663000 | Q28: =IF(Q27="","",-1*Q27) -> -3839000 | S28: =IF(S27="","",-1*S27) -> -3808000 | T28: =IF(T27="","",-1*T27) -> -4285000 | U28: =IF(U27="","",-1*U27) -> -4240000 | V28: =IF(V27="","",-1*V27) -> -4371000 | X28: =IF(X27="","",-1*X27) -> -4335000 | Y28: =IF(Y27="","",-1*Y27) -> -4288000 | Z28: =IF(Z27="","",-1*Z27) -> -4242000 | AA28: =IF(AA27="","",-1*AA27) -> -4366000 | AC28: =IF(AC27="","",-1*AC27) -> -4334000 | AD28: =IF(AD27="","",-1*AD27) -> -4299000
A29: BALANÇO DE FACE (USD, saldo no fim do trimestre; cada trimestre lido da instância do próprio 10-Q/10-K) | C29: [linha bruta, sem código; lançada nas linhas abaixo]
A30: CashAndCashEquivalentsAtCarryingValue · fonte · unid. moeda | B30: 11 | C30: Cash and equivalents (inc. investment securities) | D30: 3515000 | E30: 3465000 | F30: 4768000 | G30: 6802000 | I30: 11074000 | J30: 18861000 | K30: 30407000 | L30: 29640000 | N30: 32651000 | O30: 29528000 | P30: 32944000 | Q30: 31539000 | S30: 33320000 | T30: 26460000 | U30: 26926000 | V30: 23029000 | X30: 17036000 | Y30: 14352000 | Z30: 13814000 | AA30: 10681000 | AC30: 8435000 | AD30: 10588000
A31: ReceivablesNetCurrent · fonte · unid. moeda | B31: 12 | C31: Accounts receivable | D31: 24755000 | E31: 28540000 | F31: 29516000 | G31: 32383000 | I31: 42142000 | J31: 48063000 | K31: 42411000 | L31: 41749000 | N31: 38808000 | O31: 35915000 | P31: 41814000 | Q31: 38015000 | S31: 40366000 | T31: 43071000 | U31: 41505000 | V31: 43681000 | X31: 46303000 | Y31: 41792000 | Z31: 45285000 | AA31: 44562000 | AC31: 61783000 | AD31: 60558000
A32: EnergyRelatedInventory · fonte · unid. moeda | B32: 16 | C32: Other current assets | D32: 13740000 | E32: 14711000 | F32: 15087000 | G32: 14519000 | I32: 18074000 | J32: 19580000 | K32: 20078000 | L32: 20434000 | N32: 19458000 | O32: 20006000 | P32: 20052000 | Q32: 20528000 | S32: 18891000 | T32: 19685000 | U32: 19183000 | V32: 19444000 | X32: 20502000 | Y32: 21364000 | Z32: 23174000 | AA32: 22979000 | AC32: 21838000 | AD32: 22363000
A33: InventoryPartsAndComponentsNetOfReserves · fonte · unid. moeda | B33: 16 | C33: Other current assets | D33: 4617000 | E33: 4564000 | F33: 4520000 | G33: 4261000 | I33: 4103000 | J33: 4005000 | K33: 4018000 | L33: 4001000 | N33: 4184000 | O33: 4243000 | P33: 4398000 | Q33: 4592000 | S33: 4600000 | T33: 4818000 | U33: 4692000 | V33: 4080000 | X33: 3976000 | Y33: 4007000 | Z33: 4064000 | AA33: 3323000 | AC33: 3137000 | AD33: 3200000
A34: OtherAssetsCurrent · fonte · unid. moeda | B34: 16 | C34: Other current assets | D34: 1568000 | E34: 1562000 | F34: 1664000 | G34: 1189000 | I34: 1862000 | J34: 2654000 | K34: 2318000 | L34: 1782000 | N34: 2098000 | O34: 2039000 | P34: 1905000 | Q34: 1906000 | S34: 2171000 | T34: 2176000 | U34: 1997000 | V34: 1598000 | X34: 1940000 | Y34: 2234000 | Z34: 2113000 | AA34: 1837000 | AC34: 2594000 | AD34: 4084000
A35: RestrictedCashAndCashEquivalents · fonte · unid. moeda | B35: 16 | C35: Other current assets | D35: 0 | E35: 0 | F35: 0 | G35: 0 | I35: 0 | J35: 0 | K35: 57000 | L35: 0 | N35: 0 | O35: 0 | P35: 0 | Q35: 0 | S35: 0 | T35: 0 | U35: 0 | V35: 0 | X35: 0 | Y35: 0 | Z35: 0 | AA35: 0 | AC35: 0 | AD35: 0
A36: RestrictedCashAndCashEquivalentsAtCarryingValue · fonte · unid. moeda | B36: 16 | C36: Other current assets | D36: 0 | E36: 0 | F36: 0 | G36: 0 | I36: 0 | J36: 0 | K36: 0 | L36: 25000 | N36: 25000 | O36: 29000 | P36: 29000 | Q36: 29000 | S36: 29000 | T36: 28000 | U36: 46000 | V36: 158000 | X36: 1476000 | Y36: 1359000 | Z36: 55000 | AA36: 0 | AC36: 0 | AD36: 0
A37: PropertyPlantAndEquipmentNet · fonte · unid. moeda | B37: 18 | C37: PP&E | D37: 224641000 | E37: 223012000 | F37: 218795000 | G37: 216552000 | I37: 212773000 | J37: 209159000 | K37: 203102000 | L37: 204692000 | N37: 206023000 | O37: 206736000 | P37: 205862000 | Q37: 214940000 | S37: 213723000 | T37: 298283000 | U37: 299543000 | V37: 294318000 | X37: 292646000 | Y37: 295356000 | Z37: 298388000 | AA37: 299373000 | AC37: 298781000 | AD37: 296298000
A38: LongTermInvestmentsAndReceivablesNet · fonte · unid. moeda | B38: 22 | C38: Other non-current assets | D38: 44181000 | E38: 44774000 | F38: 45641000 | G38: 45195000 | I38: 46329000 | J38: 46820000 | K38: 50235000 | L38: 49793000 | N38: 49044000 | O38: 47273000 | P38: 48066000 | Q38: 47630000 | S38: 47608000 | T38: 47948000 | U38: 48869000 | V38: 47200000 | X38: 47853000 | Y38: 46092000 | Z38: 46138000 | AA38: 45317000 | AC38: 46125000 | AD38: 45605000
A39: OtherAssetsNoncurrent · fonte · unid. moeda | B39: 22 | C39: Other non-current assets | D39: 16753000 | E39: 16661000 | F39: 16697000 | G39: 18022000 | I39: 18414000 | J39: 18632000 | K39: 17526000 | L39: 16951000 | N39: 17080000 | O39: 17479000 | P39: 17189000 | Q39: 17138000 | S39: 17210000 | T39: 18238000 | U39: 19155000 | V39: 19967000 | X39: 20176000 | Y39: 21041000 | Z39: 21309000 | AA39: 20908000 | AC39: 21717000 | AD39: 21786000
A40: AccountsPayableAndAccruedLiabilitiesCurrent · fonte · unid. moeda | B40: 23 | C40: Accounts payable | D40: 41017000 | E40: 45780000 | F40: 47257000 | G40: 50766000 | I40: 63501000 | J40: 67958000 | K40: 62550000 | L40: 63197000 | N40: 59935000 | O40: 54404000 | P40: 62257000 | Q40: 58037000 | S40: 59531000 | T40: 60107000 | U40: 60518000 | V40: 61297000 | X40: 63987000 | Y40: 59725000 | Z40: 65382000 | AA40: 60911000 | AC40: 77088000 | AD40: 74491000
...

Sheet Inputs (2)
A1: =IF(Control!B3="","EMPRESA",Control!B3) -> Exxon Mobil Corporation | B1: Código | C1: Conta padronizada | D1: 2021 | E1: 2021 | F1: 2021 | G1: 2021 | H1: 2021 | I1: 2022 | J1: 2022 | K1: 2022 | L1: 2022 | M1: 2022 | N1: 2023 | O1: 2023 | P1: 2023 | Q1: 2023 | R1: 2023 | S1: 2024 | T1: 2024 | U1: 2024 | V1: 2024 | W1: 2024 | X1: 2025 | Y1: 2025 | Z1: 2025 | AA1: 2025 | AB1: 2025 | AC1: 2026 | AD1: 2026 | AE1: 2026 | AF1: 2026 | AG1: 2026
A2: US$ milhões | C2: Período | D2: 1Q21 | E2: 2Q21 | F2: 3Q21 | G2: 4Q21 | H2: 2021 | I2: 1Q22 | J2: 2Q22 | K2: 3Q22 | L2: 4Q22 | M2: 2022 | N2: 1Q23 | O2: 2Q23 | P2: 3Q23 | Q2: 4Q23 | R2: 2023 | S2: 1Q24 | T2: 2Q24 | U2: 3Q24 | V2: 4Q24 | W2: 2024 | X2: 1Q25 | Y2: 2Q25 | Z2: 3Q25 | AA2: 4Q25 | AB2: 2025 | AC2: 1Q26 | AD2: 2Q26 | AE2: 3Q26 | AF2: 4Q26 | AG2: 2026
A3: Actual flag | C3: 0 = sem dados / 1 = realizado | D3: 1 | E3: 1 | F3: 1 | G3: 1 | H3: 1 | I3: 1 | J3: 1 | K3: 1 | L3: 1 | M3: 1 | N3: 1 | O3: 1 | P3: 1 | Q3: 1 | R3: 1 | S3: 1 | T3: 1 | U3: 1 | V3: 1 | W3: 1 | X3: 1 | Y3: 1 | Z3: 1 | AA3: 1 | AB3: 1 | AC3: 1 | AD3: 1 | AE3: 0 | AF3: 0 | AG3: 0
B4: 1 | C4: Net Revenues | D4: =IF(D$3=0,"",SUMIFS(INDEX(Inputs!$D$4:$AG$150,0,MATCH(D$2,Inputs!$D$2:$AG$2,0)),Inputs!$B$4:$B$150,$B4)/1000) -> 59147 | E4: =IF(E$3=0,"",SUMIFS(INDEX(Inputs!$D$4:$AG$150,0,MATCH(E$2,Inputs!$D$2:$AG$2,0)),Inputs!$B$4:$B$150,$B4)/1000) -> 67742 | F4: =IF(F$3=0,"",SUMIFS(INDEX(Inputs!$D$4:$AG$150,0,MATCH(F$2,Inputs!$D$2:$AG$2,0)),Inputs!$B$4:$B$150,$B4)/1000) -> 73786 | G4: =IF(G$3=0,"",SUMIFS(INDEX(Inputs!$D$4:$AG$150,0,MATCH(G$2,Inputs!$D$2:$AG$2,0)),Inputs!$B$4:$B$150,$B4)/1000) -> 84965 | H4: =IF(COUNT(D4:G4)=4,SUM(D4:G4),"") -> 285640 | I4: =IF(I$3=0,"",SUMIFS(INDEX(Inputs!$D$4:$AG$150,0,MATCH(I$2,Inputs!$D$2:$AG$2,0)),Inputs!$B$4:$B$150,$B4)/1000) -> 90500 | J4: =IF(J$3=0,"",SUMIFS(INDEX(Inputs!$D$4:$AG$150,0,MATCH(J$2,Inputs!$D$2:$AG$2,0)),Inputs!$B$4:$B$150,$B4)/1000) -> 115681 | K4: =IF(K$3=0,"",SUMIFS(INDEX(Inputs!$D$4:$AG$150,0,MATCH(K$2,Inputs!$D$2:$AG$2,0)),Inputs!$B$4:$B$150,$B4)/1000) -> 112070 | L4: =IF(L$3=0,"",SUMIFS(INDEX(Inputs!$D$4:$AG$150,0,MATCH(L$2,Inputs!$D$2:$AG$2,0)),Inputs!$B$4:$B$150,$B4)/1000) -> 95429 | M4: =IF(COUNT(I4:L4)=4,SUM(I4:L4),"") -> 413680 | N4: =IF(N$3=0,"",SUMIFS(INDEX(Inputs!$D$4:$AG$150,0,MATCH(N$2,Inputs!$D$2:$AG$2,0)),Inputs!$B$4:$B$150,$B4)/1000) -> 86564 | O4: =IF(O$3=0,"",SUMIFS(INDEX(Inputs!$D$4:$AG$150,0,MATCH(O$2,Inputs!$D$2:$AG$2,0)),Inputs!$B$4:$B$150,$B4)/1000) -> 82914 | P4: =IF(P$3=0,"",SUMIFS(INDEX(Inputs!$D$4:$AG$150,0,MATCH(P$2,Inputs!$D$2:$AG$2,0)),Inputs!$B$4:$B$150,$B4)/1000) -> 90760 | Q4: =IF(Q$3=0,"",SUMIFS(INDEX(Inputs!$D$4:$AG$150,0,MATCH(Q$2,Inputs!$D$2:$AG$2,0)),Inputs!$B$4:$B$150,$B4)/1000) -> 84344 | R4: =IF(COUNT(N4:Q4)=4,SUM(N4:Q4),"") -> 344582 | S4: =IF(S$3=0,"",SUMIFS(INDEX(Inputs!$D$4:$AG$150,0,MATCH(S$2,Inputs!$D$2:$AG$2,0)),Inputs!$B$4:$B$150,$B4)/1000) -> 83083 | T4: =IF(T$3=0,"",SUMIFS(INDEX(Inputs!$D$4:$AG$150,0,MATCH(T$2,Inputs!$D$2:$AG$2,0)),Inputs!$B$4:$B$150,$B4)/1000) -> 93060 | U4: =IF(U$3=0,"",SUMIFS(INDEX(Inputs!$D$4:$AG$150,0,MATCH(U$2,Inputs!$D$2:$AG$2,0)),Inputs!$B$4:$B$150,$B4)/1000) -> 90016 | V4: =IF(V$3=0,"",SUMIFS(INDEX(Inputs!$D$4:$AG$150,0,MATCH(V$2,Inputs!$D$2:$AG$2,0)),Inputs!$B$4:$B$150,$B4)/1000) -> 83426 | W4: =IF(COUNT(S4:V4)=4,SUM(S4:V4),"") -> 349585 | X4: =IF(X$3=0,"",SUMIFS(INDEX(Inputs!$D$4:$AG$150,0,MATCH(X$2,Inputs!$D$2:$AG$2,0)),Inputs!$B$4:$B$150,$B4)/1000) -> 83130 | Y4: =IF(Y$3=0,"",SUMIFS(INDEX(Inputs!$D$4:$AG$150,0,MATCH(Y$2,Inputs!$D$2:$AG$2,0)),Inputs!$B$4:$B$150,$B4)/1000) -> 81506 | Z4: =IF(Z$3=0,"",SUMIFS(INDEX(Inputs!$D$4:$AG$150,0,MATCH(Z$2,Inputs!$D$2:$AG$2,0)),Inputs!$B$4:$B$150,$B4)/1000) -> 85294 | AA4: =IF(AA$3=0,"",SUMIFS(INDEX(Inputs!$D$4:$AG$150,0,MATCH(AA$2,Inputs!$D$2:$AG$2,0)),Inputs!$B$4:$B$150,$B4)/1000) -> 82308 | AB4: =IF(COUNT(X4:AA4)=4,SUM(X4:AA4),"") -> 332238 | AC4: =IF(AC$3=0,"",SUMIFS(INDEX(Inputs!$D$4:$AG$150,0,MATCH(AC$2,Inputs!$D$2:$AG$2,0)),Inputs!$B$4:$B$150,$B4)/1000) -> 85138 | AD4: =IF(AD$3=0,"",SUMIFS(INDEX(Inputs!$D$4:$AG$150,0,MATCH(AD$2,Inputs!$D$2:$AG$2,0)),Inputs!$B$4:$B$150,$B4)/1000) -> 116017 | AE4: =IF(AE$3=0,"",SUMIFS(INDEX(Inputs!$D$4:$AG$150,0,MATCH(AE$2,Inputs!$D$2:$AG$2,0)),Inputs!$B$4:$B$150,$B4)/1000) | AF4: =IF(AF$3=0,"",SUMIFS(INDEX(Inputs!$D$4:$AG$150,0,MATCH(AF$2,Inputs!$D$2:$AG$2,0)),Inputs!$B$4:$B$150,$B4)/1000) | AG4: =IF(COUNT(AC4:AF4)=4,SUM(AC4:AF4),"")
B5: 2 | C5: COGS (cash) | D5: =IF(D$3=0,"",SUMIFS(INDEX(Inputs!$D$4:$AG$150,0,MATCH(D$2,Inputs!$D$2:$AG$2,0)),Inputs!$B$4:$B$150,$B5)/1000) -> -32601 | E5: =IF(E$3=0,"",SUMIFS(INDEX(Inputs!$D$4:$AG$150,0,MATCH(E$2,Inputs!$D$2:$AG$2,0)),Inputs!$B$4:$B$150,$B5)/1000) -> -37329 | F5: =IF(F$3=0,"",SUMIFS(INDEX(Inputs!$D$4:$AG$150,0,MATCH(F$2,Inputs!$D$2:$AG$2,0)),Inputs!$B$4:$B$150,$B5)/1000) -> -39745 | G5: =IF(G$3=0,"",SUMIFS(INDEX(Inputs!$D$4:$AG$150,0,MATCH(G$2,Inputs!$D$2:$AG$2,0)),Inputs!$B$4:$B$150,$B5)/1000) -> -45489 | H5: =IF(COUNT(D5:G5)=4,SUM(D5:G5),"") -> -155164 | I5: =IF(I$3=0,"",SUMIFS(INDEX(Inputs!$D$4:$AG$150,0,MATCH(I$2,Inputs!$D$2:$AG$2,0)),Inputs!$B$4:$B$150,$B5)/1000) -> -52388 | J5: =IF(J$3=0,"",SUMIFS(INDEX(Inputs!$D$4:$AG$150,0,MATCH(J$2,Inputs!$D$2:$AG$2,0)),Inputs!$B$4:$B$150,$B5)/1000) -> -65613 | K5: =IF(K$3=0,"",SUMIFS(INDEX(Inputs!$D$4:$AG$150,0,MATCH(K$2,Inputs!$D$2:$AG$2,0)),Inputs!$B$4:$B$150,$B5)/1000) -> -60197 | L5: =IF(L$3=0,"",SUMIFS(INDEX(Inputs!$D$4:$AG$150,0,MATCH(L$2,Inputs!$D$2:$AG$2,0)),Inputs!$B$4:$B$150,$B5)/1000) -> -50761 | M5: =IF(COUNT(I5:L5)=4,SUM(I5:L5),"") -> -228959 | N5: =IF(N$3=0,"",SUMIFS(INDEX(Inputs!$D$4:$AG$150,0,MATCH(N$2,Inputs!$D$2:$AG$2,0)),Inputs!$B$4:$B$150,$B5)/1000) -> -46003 | O5: =IF(O$3=0,"",SUMIFS(INDEX(Inputs!$D$4:$AG$150,0,MATCH(O$2,Inputs!$D$2:$AG$2,0)),Inputs!$B$4:$B$150,$B5)/1000) -> -47598 | P5: =IF(P$3=0,"",SUMIFS(INDEX(Inputs!$D$4:$AG$150,0,MATCH(P$2,Inputs!$D$2:$AG$2,0)),Inputs!$B$4:$B$150,$B5)/1000) -> -53076 | Q5: =IF(Q$3=0,"",SUMIFS(INDEX(Inputs!$D$4:$AG$150,0,MATCH(Q$2,Inputs!$D$2:$AG$2,0)),Inputs!$B$4:$B$150,$B5)/1000) -> -46352 | R5: =IF(COUNT(N5:Q5)=4,SUM(N5:Q5),"") -> -193029 | S5: =IF(S$3=0,"",SUMIFS(INDEX(Inputs!$D$4:$AG$150,0,MATCH(S$2,Inputs!$D$2:$AG$2,0)),Inputs!$B$4:$B$150,$B5)/1000) -> -47601 | T5: =IF(T$3=0,"",SUMIFS(INDEX(Inputs!$D$4:$AG$150,0,MATCH(T$2,Inputs!$D$2:$AG$2,0)),Inputs!$B$4:$B$150,$B5)/1000) -> -54199 | U5: =IF(U$3=0,"",SUMIFS(INDEX(Inputs!$D$4:$AG$150,0,MATCH(U$2,Inputs!$D$2:$AG$2,0)),Inputs!$B$4:$B$150,$B5)/1000) -> -51261 | V5: =IF(V$3=0,"",SUMIFS(INDEX(Inputs!$D$4:$AG$150,0,MATCH(V$2,Inputs!$D$2:$AG$2,0)),Inputs!$B$4:$B$150,$B5)/1000) -> -46393 | W5: =IF(COUNT(S5:V5)=4,SUM(S5:V5),"") -> -199454 | X5: =IF(X$3=0,"",SUMIFS(INDEX(Inputs!$D$4:$AG$150,0,MATCH(X$2,Inputs!$D$2:$AG$2,0)),Inputs!$B$4:$B$150,$B5)/1000) -> -46788 | Y5: =IF(Y$3=0,"",SUMIFS(INDEX(Inputs!$D$4:$AG$150,0,MATCH(Y$2,Inputs!$D$2:$AG$2,0)),Inputs!$B$4:$B$150,$B5)/1000) -> -45327 | Z5: =IF(Z$3=0,"",SUMIFS(INDEX(Inputs!$D$4:$AG$150,0,MATCH(Z$2,Inputs!$D$2:$AG$2,0)),Inputs!$B$4:$B$150,$B5)/1000) -> -47928 | AA5: =IF(AA$3=0,"",SUMIFS(INDEX(Inputs!$D$4:$AG$150,0,MATCH(AA$2,Inputs!$D$2:$AG$2,0)),Inputs!$B$4:$B$150,$B5)/1000) -> -44205 | AB5: =IF(COUNT(X5:AA5)=4,SUM(X5:AA5),"") -> -184248 | AC5: =IF(AC$3=0,"",SUMIFS(INDEX(Inputs!$D$4:$AG$150,0,MATCH(AC$2,Inputs!$D$2:$AG$2,0)),Inputs!$B$4:$B$150,$B5)/1000) -> -51802 | AD5: =IF(AD$3=0,"",SUMIFS(INDEX(Inputs!$D$4:$AG$150,0,MATCH(AD$2,Inputs!$D$2:$AG$2,0)),Inputs!$B$4:$B$150,$B5)/1000) -> -67801 | AE5: =IF(AE$3=0,"",SUMIFS(INDEX(Inputs!$D$4:$AG$150,0,MATCH(AE$2,Inputs!$D$2:$AG$2,0)),Inputs!$B$4:$B$150,$B5)/1000) | AF5: =IF(AF$3=0,"",SUMIFS(INDEX(Inputs!$D$4:$AG$150,0,MATCH(AF$2,Inputs!$D$2:$AG$2,0)),Inputs!$B$4:$B$150,$B5)/1000) | AG5: =IF(COUNT(AC5:AF5)=4,SUM(AC5:AF5),"")
B6: 3 | C6: SG&A and Other (cash) | D6: =IF(D$3=0,"",SUMIFS(INDEX(Inputs!$D$4:$AG$150,0,MATCH(D$2,Inputs!$D$2:$AG$2,0)),Inputs!$B$4:$B$150,$B6)/1000) -> -17692 | E6: =IF(E$3=0,"",SUMIFS(INDEX(Inputs!$D$4:$AG$150,0,MATCH(E$2,Inputs!$D$2:$AG$2,0)),Inputs!$B$4:$B$150,$B6)/1000) -> -18900 | F6: =IF(F$3=0,"",SUMIFS(INDEX(Inputs!$D$4:$AG$150,0,MATCH(F$2,Inputs!$D$2:$AG$2,0)),Inputs!$B$4:$B$150,$B6)/1000) -> -19231 | G6: =IF(G$3=0,"",SUMIFS(INDEX(Inputs!$D$4:$AG$150,0,MATCH(G$2,Inputs!$D$2:$AG$2,0)),Inputs!$B$4:$B$150,$B6)/1000) -> -21865 | H6: =IF(COUNT(D6:G6)=4,SUM(D6:G6),"") -> -77688 | I6: =IF(I$3=0,"",SUMIFS(INDEX(Inputs!$D$4:$AG$150,0,MATCH(I$2,Inputs!$D$2:$AG$2,0)),Inputs!$B$4:$B$150,$B6)/1000) -> -20485 | J6: =IF(J$3=0,"",SUMIFS(INDEX(Inputs!$D$4:$AG$150,0,MATCH(J$2,Inputs!$D$2:$AG$2,0)),Inputs!$B$4:$B$150,$B6)/1000) -> -20490 | K6: =IF(K$3=0,"",SUMIFS(INDEX(Inputs!$D$4:$AG$150,0,MATCH(K$2,Inputs!$D$2:$AG$2,0)),Inputs!$B$4:$B$150,$B6)/1000) -> -20600 | L6: =IF(L$3=0,"",SUMIFS(INDEX(Inputs!$D$4:$AG$150,0,MATCH(L$2,Inputs!$D$2:$AG$2,0)),Inputs!$B$4:$B$150,$B6)/1000) -> -20555 | M6: =IF(COUNT(I6:L6)=4,SUM(I6:L6),"") -> -82130 | N6: =IF(N$3=0,"",SUMIFS(INDEX(Inputs!$D$4:$AG$150,0,MATCH(N$2,Inputs!$D$2:$AG$2,0)),Inputs!$B$4:$B$150,$B6)/1000) -> -19355 | O6: =IF(O$3=0,"",SUMIFS(INDEX(Inputs!$D$4:$AG$150,0,MATCH(O$2,Inputs!$D$2:$AG$2,0)),Inputs!$B$4:$B$150,$B6)/1000) -> -19169 | P6: =IF(P$3=0,"",SUMIFS(INDEX(Inputs!$D$4:$AG$150,0,MATCH(P$2,Inputs!$D$2:$AG$2,0)),Inputs!$B$4:$B$150,$B6)/1000) -> -19401 | Q6: =IF(Q$3=0,"",SUMIFS(INDEX(Inputs!$D$4:$AG$150,0,MATCH(Q$2,Inputs!$D$2:$AG$2,0)),Inputs!$B$4:$B$150,$B6)/1000) -> -19355 | R6: =IF(COUNT(N6:Q6)=4,SUM(N6:Q6),"") -> -77280 | S6: =IF(S$3=0,"",SUMIFS(INDEX(Inputs!$D$4:$AG$150,0,MATCH(S$2,Inputs!$D$2:$AG$2,0)),Inputs!$B$4:$B$150,$B6)/1000) -> -18080 | T6: =IF(T$3=0,"",SUMIFS(INDEX(Inputs!$D$4:$AG$150,0,MATCH(T$2,Inputs!$D$2:$AG$2,0)),Inputs!$B$4:$B$150,$B6)/1000) -> -19138 | U6: =IF(U$3=0,"",SUMIFS(INDEX(Inputs!$D$4:$AG$150,0,MATCH(U$2,Inputs!$D$2:$AG$2,0)),Inputs!$B$4:$B$150,$B6)/1000) -> -19264 | V6: =IF(V$3=0,"",SUMIFS(INDEX(Inputs!$D$4:$AG$150,0,MATCH(V$2,Inputs!$D$2:$AG$2,0)),Inputs!$B$4:$B$150,$B6)/1000) -> -20338 | W6: =IF(COUNT(S6:V6)=4,SUM(S6:V6),"") -> -76820 | X6: =IF(X$3=0,"",SUMIFS(INDEX(Inputs!$D$4:$AG$150,0,MATCH(X$2,Inputs!$D$2:$AG$2,0)),Inputs!$B$4:$B$150,$B6)/1000) -> -18835 | Y6: =IF(Y$3=0,"",SUMIFS(INDEX(Inputs!$D$4:$AG$150,0,MATCH(Y$2,Inputs!$D$2:$AG$2,0)),Inputs!$B$4:$B$150,$B6)/1000) -> -19228 | Z6: =IF(Z$3=0,"",SUMIFS(INDEX(Inputs!$D$4:$AG$150,0,MATCH(Z$2,Inputs!$D$2:$AG$2,0)),Inputs!$B$4:$B$150,$B6)/1000) -> -19869 | AA6: =IF(AA$3=0,"",SUMIFS(INDEX(Inputs!$D$4:$AG$150,0,MATCH(AA$2,Inputs!$D$2:$AG$2,0)),Inputs!$B$4:$B$150,$B6)/1000) -> -22194 | AB6: =IF(COUNT(X6:AA6)=4,SUM(X6:AA6),"") -> -80126 | AC6: =IF(AC$3=0,"",SUMIFS(INDEX(Inputs!$D$4:$AG$150,0,MATCH(AC$2,Inputs!$D$2:$AG$2,0)),Inputs!$B$4:$B$150,$B6)/1000) -> -19303 | AD6: =IF(AD$3=0,"",SUMIFS(INDEX(Inputs!$D$4:$AG$150,0,MATCH(AD$2,Inputs!$D$2:$AG$2,0)),Inputs!$B$4:$B$150,$B6)/1000) -> -19876 | AE6: =IF(AE$3=0,"",SUMIFS(INDEX(Inputs!$D$4:$AG$150,0,MATCH(AE$2,Inputs!$D$2:$AG$2,0)),Inputs!$B$4:$B$150,$B6)/1000) | AF6: =IF(AF$3=0,"",SUMIFS(INDEX(Inputs!$D$4:$AG$150,0,MATCH(AF$2,Inputs!$D$2:$AG$2,0)),Inputs!$B$4:$B$150,$B6)/1000) | AG6: =IF(COUNT(AC6:AF6)=4,SUM(AC6:AF6),"")
B7: 4 | C7: D&A | D7: =IF(D$3=0,"",SUMIFS(INDEX(Inputs!$D$4:$AG$150,0,MATCH(D$2,Inputs!$D$2:$AG$2,0)),Inputs!$B$4:$B$150,$B7)/1000) -> -5004 | E7: =IF(E$3=0,"",SUMIFS(INDEX(Inputs!$D$4:$AG$150,0,MATCH(E$2,Inputs!$D$2:$AG$2,0)),Inputs!$B$4:$B$150,$B7)/1000) -> -4952 | F7: =IF(F$3=0,"",SUMIFS(INDEX(Inputs!$D$4:$AG$150,0,MATCH(F$2,Inputs!$D$2:$AG$2,0)),Inputs!$B$4:$B$150,$B7)/1000) -> -4990 | G7: =IF(G$3=0,"",SUMIFS(INDEX(Inputs!$D$4:$AG$150,0,MATCH(G$2,Inputs!$D$2:$AG$2,0)),Inputs!$B$4:$B$150,$B7)/1000) -> -5661 | H7: =IF(COUNT(D7:G7)=4,SUM(D7:G7),"") -> -20607 | I7: =IF(I$3=0,"",SUMIFS(INDEX(Inputs!$D$4:$AG$150,0,MATCH(I$2,Inputs!$D$2:$AG$2,0)),Inputs!$B$4:$B$150,$B7)/1000) -> -8883 | J7: =IF(J$3=0,"",SUMIFS(INDEX(Inputs!$D$4:$AG$150,0,MATCH(J$2,Inputs!$D$2:$AG$2,0)),Inputs!$B$4:$B$150,$B7)/1000) -> -4451 | K7: =IF(K$3=0,"",SUMIFS(INDEX(Inputs!$D$4:$AG$150,0,MATCH(K$2,Inputs!$D$2:$AG$2,0)),Inputs!$B$4:$B$150,$B7)/1000) -> -5642 | L7: =IF(L$3=0,"",SUMIFS(INDEX(Inputs!$D$4:$AG$150,0,MATCH(L$2,Inputs!$D$2:$AG$2,0)),Inputs!$B$4:$B$150,$B7)/1000) -> -5064 | M7: =IF(COUNT(I7:L7)=4,SUM(I7:L7),"") -> -24040 | N7: =IF(N$3=0,"",SUMIFS(INDEX(Inputs!$D$4:$AG$150,0,MATCH(N$2,Inputs!$D$2:$AG$2,0)),Inputs!$B$4:$B$150,$B7)/1000) -> -4244 | O7: =IF(O$3=0,"",SUMIFS(INDEX(Inputs!$D$4:$AG$150,0,MATCH(O$2,Inputs!$D$2:$AG$2,0)),Inputs!$B$4:$B$150,$B7)/1000) -> -4242 | P7: =IF(P$3=0,"",SUMIFS(INDEX(Inputs!$D$4:$AG$150,0,MATCH(P$2,Inputs!$D$2:$AG$2,0)),Inputs!$B$4:$B$150,$B7)/1000) -> -4415 | Q7: =IF(Q$3=0,"",SUMIFS(INDEX(Inputs!$D$4:$AG$150,0,MATCH(Q$2,Inputs!$D$2:$AG$2,0)),Inputs!$B$4:$B$150,$B7)/1000) -> -7740 | R7: =IF(COUNT(N7:Q7)=4,SUM(N7:Q7),"") -> -20641 | S7: =IF(S$3=0,"",SUMIFS(INDEX(Inputs!$D$4:$AG$150,0,MATCH(S$2,Inputs!$D$2:$AG$2,0)),Inputs!$B$4:$B$150,$B7)/1000) -> -4812 | T7: =IF(T$3=0,"",SUMIFS(INDEX(Inputs!$D$4:$AG$150,0,MATCH(T$2,Inputs!$D$2:$AG$2,0)),Inputs!$B$4:$B$150,$B7)/1000) -> -5787 | U7: =IF(U$3=0,"",SUMIFS(INDEX(Inputs!$D$4:$AG$150,0,MATCH(U$2,Inputs!$D$2:$AG$2,0)),Inputs!$B$4:$B$150,$B7)/1000) -> -6258 | V7: =IF(V$3=0,"",SUMIFS(INDEX(Inputs!$D$4:$AG$150,0,MATCH(V$2,Inputs!$D$2:$AG$2,0)),Inputs!$B$4:$B$150,$B7)/1000) -> -6585 | W7: =IF(COUNT(S7:V7)=4,SUM(S7:V7),"") -> -23442 | X7: =IF(X$3=0,"",SUMIFS(INDEX(Inputs!$D$4:$AG$150,0,MATCH(X$2,Inputs!$D$2:$AG$2,0)),Inputs!$B$4:$B$150,$B7)/1000) -> -5702 | Y7: =IF(Y$3=0,"",SUMIFS(INDEX(Inputs!$D$4:$AG$150,0,MATCH(Y$2,Inputs!$D$2:$AG$2,0)),Inputs!$B$4:$B$150,$B7)/1000) -> -6101 | Z7: =IF(Z$3=0,"",SUMIFS(INDEX(Inputs!$D$4:$AG$150,0,MATCH(Z$2,Inputs!$D$2:$AG$2,0)),Inputs!$B$4:$B$150,$B7)/1000) -> -6475 | AA7: =IF(AA$3=0,"",SUMIFS(INDEX(Inputs!$D$4:$AG$150,0,MATCH(AA$2,Inputs!$D$2:$AG$2,0)),Inputs!$B$4:$B$150,$B7)/1000) -> -7715 | AB7: =IF(COUNT(X7:AA7)=4,SUM(X7:AA7),"") -> -25993 | AC7: =IF(AC$3=0,"",SUMIFS(INDEX(Inputs!$D$4:$AG$150,0,MATCH(AC$2,Inputs!$D$2:$AG$2,0)),Inputs!$B$4:$B$150,$B7)/1000) -> -6771 | AD7: =IF(AD$3=0,"",SUMIFS(INDEX(Inputs!$D$4:$AG$150,0,MATCH(AD$2,Inputs!$D$2:$AG$2,0)),Inputs!$B$4:$B$150,$B7)/1000) -> -8689 | AE7: =IF(AE$3=0,"",SUMIFS(INDEX(Inputs!$D$4:$AG$150,0,MATCH(AE$2,Inputs!$D$2:$AG$2,0)),Inputs!$B$4:$B$150,$B7)/1000) | AF7: =IF(AF$3=0,"",SUMIFS(INDEX(Inputs!$D$4:$AG$150,0,MATCH(AF$2,Inputs!$D$2:$AG$2,0)),Inputs!$B$4:$B$150,$B7)/1000) | AG7: =IF(COUNT(AC7:AF7)=4,SUM(AC7:AF7),"")
B8: 5 | C8: Interest Expense | D8: =IF(D$3=0,"",SUMIFS(INDEX(Inputs!$D$4:$AG$150,0,MATCH(D$2,Inputs!$D$2:$AG$2,0)),Inputs!$B$4:$B$150,$B8)/1000) -> -258 | E8: =IF(E$3=0,"",SUMIFS(INDEX(Inputs!$D$4:$AG$150,0,MATCH(E$2,Inputs!$D$2:$AG$2,0)),Inputs!$B$4:$B$150,$B8)/1000) -> -254 | F8: =IF(F$3=0,"",SUMIFS(INDEX(Inputs!$D$4:$AG$150,0,MATCH(F$2,Inputs!$D$2:$AG$2,0)),Inputs!$B$4:$B$150,$B8)/1000) -> -214 | G8: =IF(G$3=0,"",SUMIFS(INDEX(Inputs!$D$4:$AG$150,0,MATCH(G$2,Inputs!$D$2:$AG$2,0)),Inputs!$B$4:$B$150,$B8)/1000) -> -221 | H8: =IF(COUNT(D8:G8)=4,SUM(D8:G8),"") -> -947 | I8: =IF(I$3=0,"",SUMIFS(INDEX(Inputs!$D$4:$AG$150,0,MATCH(I$2,Inputs!$D$2:$AG$2,0)),Inputs!$B$4:$B$150,$B8)/1000) -> -188 | J8: =IF(J$3=0,"",SUMIFS(INDEX(Inputs!$D$4:$AG$150,0,MATCH(J$2,Inputs!$D$2:$AG$2,0)),Inputs!$B$4:$B$150,$B8)/1000) -> -194 | K8: =IF(K$3=0,"",SUMIFS(INDEX(Inputs!$D$4:$AG$150,0,MATCH(K$2,Inputs!$D$2:$AG$2,0)),Inputs!$B$4:$B$150,$B8)/1000) -> -209 | L8: =IF(L$3=0,"",SUMIFS(INDEX(Inputs!$D$4:$AG$150,0,MATCH(L$2,Inputs!$D$2:$AG$2,0)),Inputs!$B$4:$B$150,$B8)/1000) -> -207 | M8: =IF(COUNT(I8:L8)=4,SUM(I8:L8),"") -> -798 | N8: =IF(N$3=0,"",SUMIFS(INDEX(Inputs!$D$4:$AG$150,0,MATCH(N$2,Inputs!$D$2:$AG$2,0)),Inputs!$B$4:$B$150,$B8)/1000) -> -159 | O8: =IF(O$3=0,"",SUMIFS(INDEX(Inputs!$D$4:$AG$150,0,MATCH(O$2,Inputs!$D$2:$AG$2,0)),Inputs!$B$4:$B$150,$B8)/1000) -> -249 | P8: =IF(P$3=0,"",SUMIFS(INDEX(Inputs!$D$4:$AG$150,0,MATCH(P$2,Inputs!$D$2:$AG$2,0)),Inputs!$B$4:$B$150,$B8)/1000) -> -169 | Q8: =IF(Q$3=0,"",SUMIFS(INDEX(Inputs!$D$4:$AG$150,0,MATCH(Q$2,Inputs!$D$2:$AG$2,0)),Inputs!$B$4:$B$150,$B8)/1000) -> -272 | R8: =IF(COUNT(N8:Q8)=4,SUM(N8:Q8),"") -> -849 | S8: =IF(S$3=0,"",SUMIFS(INDEX(Inputs!$D$4:$AG$150,0,MATCH(S$2,Inputs!$D$2:$AG$2,0)),Inputs!$B$4:$B$150,$B8)/1000) -> -221 | T8: =IF(T$3=0,"",SUMIFS(INDEX(Inputs!$D$4:$AG$150,0,MATCH(T$2,Inputs!$D$2:$AG$2,0)),Inputs!$B$4:$B$150,$B8)/1000) -> -271 | U8: =IF(U$3=0,"",SUMIFS(INDEX(Inputs!$D$4:$AG$150,0,MATCH(U$2,Inputs!$D$2:$AG$2,0)),Inputs!$B$4:$B$150,$B8)/1000) -> -207 | V8: =IF(V$3=0,"",SUMIFS(INDEX(Inputs!$D$4:$AG$150,0,MATCH(V$2,Inputs!$D$2:$AG$2,0)),Inputs!$B$4:$B$150,$B8)/1000) -> -297 | W8: =IF(COUNT(S8:V8)=4,SUM(S8:V8),"") -> -996 | X8: =IF(X$3=0,"",SUMIFS(INDEX(Inputs!$D$4:$AG$150,0,MATCH(X$2,Inputs!$D$2:$AG$2,0)),Inputs!$B$4:$B$150,$B8)/1000) -> -205 | Y8: =IF(Y$3=0,"",SUMIFS(INDEX(Inputs!$D$4:$AG$150,0,MATCH(Y$2,Inputs!$D$2:$AG$2,0)),Inputs!$B$4:$B$150,$B8)/1000) -> -145 | Z8: =IF(Z$3=0,"",SUMIFS(INDEX(Inputs!$D$4:$AG$150,0,MATCH(Z$2,Inputs!$D$2:$AG$2,0)),Inputs!$B$4:$B$150,$B8)/1000) -> -90 | AA8: =IF(AA$3=0,"",SUMIFS(INDEX(Inputs!$D$4:$AG$150,0,MATCH(AA$2,Inputs!$D$2:$AG$2,0)),Inputs!$B$4:$B$150,$B8)/1000) -> -163 | AB8: =IF(COUNT(X8:AA8)=4,SUM(X8:AA8),"") -> -603 | AC8: =IF(AC$3=0,"",SUMIFS(INDEX(Inputs!$D$4:$AG$150,0,MATCH(AC$2,Inputs!$D$2:$AG$2,0)),Inputs!$B$4:$B$150,$B8)/1000) -> -295 | AD8: =IF(AD$3=0,"",SUMIFS(INDEX(Inputs!$D$4:$AG$150,0,MATCH(AD$2,Inputs!$D$2:$AG$2,0)),Inputs!$B$4:$B$150,$B8)/1000) -> -227 | AE8: =IF(AE$3=0,"",SUMIFS(INDEX(Inputs!$D$4:$AG$150,0,MATCH(AE$2,Inputs!$D$2:$AG$2,0)),Inputs!$B$4:$B$150,$B8)/1000) | AF8: =IF(AF$3=0,"",SUMIFS(INDEX(Inputs!$D$4:$AG$150,0,MATCH(AF$2,Inputs!$D$2:$AG$2,0)),Inputs!$B$4:$B$150,$B8)/1000) | AG8: =IF(COUNT(AC8:AF8)=4,SUM(AC8:AF8),"")
B9: 6 | C9: Nonoperating Income / (Loss) | D9: =IF(D$3=0,"",SUMIFS(INDEX(Inputs!$D$4:$AG$150,0,MATCH(D$2,Inputs!$D$2:$AG$2,0)),Inputs!$B$4:$B$150,$B9)/1000) -> 0 | E9: =IF(E$3=0,"",SUMIFS(INDEX(Inputs!$D$4:$AG$150,0,MATCH(E$2,Inputs!$D$2:$AG$2,0)),Inputs!$B$4:$B$150,$B9)/1000) -> 0 | F9: =IF(F$3=0,"",SUMIFS(INDEX(Inputs!$D$4:$AG$150,0,MATCH(F$2,Inputs!$D$2:$AG$2,0)),Inputs!$B$4:$B$150,$B9)/1000) -> 0 | G9: =IF(G$3=0,"",SUMIFS(INDEX(Inputs!$D$4:$AG$150,0,MATCH(G$2,Inputs!$D$2:$AG$2,0)),Inputs!$B$4:$B$150,$B9)/1000) -> 0 | H9: =IF(COUNT(D9:G9)=4,SUM(D9:G9),"") -> 0 | I9: =IF(I$3=0,"",SUMIFS(INDEX(Inputs!$D$4:$AG$150,0,MATCH(I$2,Inputs!$D$2:$AG$2,0)),Inputs!$B$4:$B$150,$B9)/1000) -> 0 | J9: =IF(J$3=0,"",SUMIFS(INDEX(Inputs!$D$4:$AG$150,0,MATCH(J$2,Inputs!$D$2:$AG$2,0)),Inputs!$B$4:$B$150,$B9)/1000) -> 0 | K9: =IF(K$3=0,"",SUMIFS(INDEX(Inputs!$D$4:$AG$150,0,MATCH(K$2,Inputs!$D$2:$AG$2,0)),Inputs!$B$4:$B$150,$B9)/1000) -> 0 | L9: =IF(L$3=0,"",SUMIFS(INDEX(Inputs!$D$4:$AG$150,0,MATCH(L$2,Inputs!$D$2:$AG$2,0)),Inputs!$B$4:$B$150,$B9)/1000) -> 0 | M9: =IF(COUNT(I9:L9)=4,SUM(I9:L9),"") -> 0 | N9: =IF(N$3=0,"",SUMIFS(INDEX(Inputs!$D$4:$AG$150,0,MATCH(N$2,Inputs!$D$2:$AG$2,0)),Inputs!$B$4:$B$150,$B9)/1000) -> 0 | O9: =IF(O$3=0,"",SUMIFS(INDEX(Inputs!$D$4:$AG$150,0,MATCH(O$2,Inputs!$D$2:$AG$2,0)),Inputs!$B$4:$B$150,$B9)/1000) -> 0 | P9: =IF(P$3=0,"",SUMIFS(INDEX(Inputs!$D$4:$AG$150,0,MATCH(P$2,Inputs!$D$2:$AG$2,0)),Inputs!$B$4:$B$150,$B9)/1000) -> 0 | Q9: =IF(Q$3=0,"",SUMIFS(INDEX(Inputs!$D$4:$AG$150,0,MATCH(Q$2,Inputs!$D$2:$AG$2,0)),Inputs!$B$4:$B$150,$B9)/1000) -> 0 | R9: =IF(COUNT(N9:Q9)=4,SUM(N9:Q9),"") -> 0 | S9: =IF(S$3=0,"",SUMIFS(INDEX(Inputs!$D$4:$AG$150,0,MATCH(S$2,Inputs!$D$2:$AG$2,0)),Inputs!$B$4:$B$150,$B9)/1000) -> 0 | T9: =IF(T$3=0,"",SUMIFS(INDEX(Inputs!$D$4:$AG$150,0,MATCH(T$2,Inputs!$D$2:$AG$2,0)),Inputs!$B$4:$B$150,$B9)/1000) -> 0 | U9: =IF(U$3=0,"",SUMIFS(INDEX(Inputs!$D$4:$AG$150,0,MATCH(U$2,Inputs!$D$2:$AG$2,0)),Inputs!$B$4:$B$150,$B9)/1000) -> 0 | V9: =IF(V$3=0,"",SUMIFS(INDEX(Inputs!$D$4:$AG$150,0,MATCH(V$2,Inputs!$D$2:$AG$2,0)),Inputs!$B$4:$B$150,$B9)/1000) -> 0 | W9: =IF(COUNT(S9:V9)=4,SUM(S9:V9),"") -> 0 | X9: =IF(X$3=0,"",SUMIFS(INDEX(Inputs!$D$4:$AG$150,0,MATCH(X$2,Inputs!$D$2:$AG$2,0)),Inputs!$B$4:$B$150,$B9)/1000) -> 0 | Y9: =IF(Y$3=0,"",SUMIFS(INDEX(Inputs!$D$4:$AG$150,0,MATCH(Y$2,Inputs!$D$2:$AG$2,0)),Inputs!$B$4:$B$150,$B9)/1000) -> 0 | Z9: =IF(Z$3=0,"",SUMIFS(INDEX(Inputs!$D$4:$AG$150,0,MATCH(Z$2,Inputs!$D$2:$AG$2,0)),Inputs!$B$4:$B$150,$B9)/1000) -> 0 | AA9: =IF(AA$3=0,"",SUMIFS(INDEX(Inputs!$D$4:$AG$150,0,MATCH(AA$2,Inputs!$D$2:$AG$2,0)),Inputs!$B$4:$B$150,$B9)/1000) -> 0 | AB9: =IF(COUNT(X9:AA9)=4,SUM(X9:AA9),"") -> 0 | AC9: =IF(AC$3=0,"",SUMIFS(INDEX(Inputs!$D$4:$AG$150,0,MATCH(AC$2,Inputs!$D$2:$AG$2,0)),Inputs!$B$4:$B$150,$B9)/1000) -> 0 | AD9: =IF(AD$3=0,"",SUMIFS(INDEX(Inputs!$D$4:$AG$150,0,MATCH(AD$2,Inputs!$D$2:$AG$2,0)),Inputs!$B$4:$B$150,$B9)/1000) -> 0 | AE9: =IF(AE$3=0,"",SUMIFS(INDEX(Inputs!$D$4:$AG$150,0,MATCH(AE$2,Inputs!$D$2:$AG$2,0)),Inputs!$B$4:$B$150,$B9)/1000) | AF9: =IF(AF$3=0,"",SUMIFS(INDEX(Inputs!$D$4:$AG$150,0,MATCH(AF$2,Inputs!$D$2:$AG$2,0)),Inputs!$B$4:$B$150,$B9)/1000) | AG9: =IF(COUNT(AC9:AF9)=4,SUM(AC9:AF9),"")
B10: 7 | C10: Taxes | D10: =IF(D$3=0,"",SUMIFS(INDEX(Inputs!$D$4:$AG$150,0,MATCH(D$2,Inputs!$D$2:$AG$2,0)),Inputs!$B$4:$B$150,$B10)/1000) -> -796 | E10: =IF(E$3=0,"",SUMIFS(INDEX(Inputs!$D$4:$AG$150,0,MATCH(E$2,Inputs!$D$2:$AG$2,0)),Inputs!$B$4:$B$150,$B10)/1000) -> -1526 | F10: =IF(F$3=0,"",SUMIFS(INDEX(Inputs!$D$4:$AG$150,0,MATCH(F$2,Inputs!$D$2:$AG$2,0)),Inputs!$B$4:$B$150,$B10)/1000) -> -2664 | G10: =IF(G$3=0,"",SUMIFS(INDEX(Inputs!$D$4:$AG$150,0,MATCH(G$2,Inputs!$D$2:$AG$2,0)),Inputs!$B$4:$B$150,$B10)/1000) -> -2650 | H10: =IF(COUNT(D10:G10)=4,SUM(D10:G10),"") -> -7636 | I10: =IF(I$3=0,"",SUMIFS(INDEX(Inputs!$D$4:$AG$150,0,MATCH(I$2,Inputs!$D$2:$AG$2,0)),Inputs!$B$4:$B$150,$B10)/1000) -> -2806 | J10: =IF(J$3=0,"",SUMIFS(INDEX(Inputs!$D$4:$AG$150,0,MATCH(J$2,Inputs!$D$2:$AG$2,0)),Inputs!$B$4:$B$150,$B10)/1000) -> -6359 | K10: =IF(K$3=0,"",SUMIFS(INDEX(Inputs!$D$4:$AG$150,0,MATCH(K$2,Inputs!$D$2:$AG$2,0)),Inputs!$B$4:$B$150,$B10)/1000) -> -5224 | L10: =IF(L$3=0,"",SUMIFS(INDEX(Inputs!$D$4:$AG$150,0,MATCH(L$2,Inputs!$D$2:$AG$2,0)),Inputs!$B$4:$B$150,$B10)/1000) -> -5787 | M10: =IF(COUNT(I10:L10)=4,SUM(I10:L10),"") -> -20176 | N10: =IF(N$3=0,"",SUMIFS(INDEX(Inputs!$D$4:$AG$150,0,MATCH(N$2,Inputs!$D$2:$AG$2,0)),Inputs!$B$4:$B$150,$B10)/1000) -> -4960 | O10: =IF(O$3=0,"",SUMIFS(INDEX(Inputs!$D$4:$AG$150,0,MATCH(O$2,Inputs!$D$2:$AG$2,0)),Inputs!$B$4:$B$150,$B10)/1000) -> -3503 | P10: =IF(P$3=0,"",SUMIFS(INDEX(Inputs!$D$4:$AG$150,0,MATCH(P$2,Inputs!$D$2:$AG$2,0)),Inputs!$B$4:$B$150,$B10)/1000) -> -4353 | Q10: =IF(Q$3=0,"",SUMIFS(INDEX(Inputs!$D$4:$AG$150,0,MATCH(Q$2,Inputs!$D$2:$AG$2,0)),Inputs!$B$4:$B$150,$B10)/1000) -> -2613 | R10: =IF(COUNT(N10:Q10)=4,SUM(N10:Q10),"") -> -15429 | S10: =IF(S$3=0,"",SUMIFS(INDEX(Inputs!$D$4:$AG$150,0,MATCH(S$2,Inputs!$D$2:$AG$2,0)),Inputs!$B$4:$B$150,$B10)/1000) -> -3803 | T10: =IF(T$3=0,"",SUMIFS(INDEX(Inputs!$D$4:$AG$150,0,MATCH(T$2,Inputs!$D$2:$AG$2,0)),Inputs!$B$4:$B$150,$B10)/1000) -> -4094 | U10: =IF(U$3=0,"",SUMIFS(INDEX(Inputs!$D$4:$AG$150,0,MATCH(U$2,Inputs!$D$2:$AG$2,0)),Inputs!$B$4:$B$150,$B10)/1000) -> -4055 | V10: =IF(V$3=0,"",SUMIFS(INDEX(Inputs!$D$4:$AG$150,0,MATCH(V$2,Inputs!$D$2:$AG$2,0)),Inputs!$B$4:$B$150,$B10)/1000) -> -1858 | W10: =IF(COUNT(S10:V10)=4,SUM(S10:V10),"") -> -13810 | X10: =IF(X$3=0,"",SUMIFS(INDEX(Inputs!$D$4:$AG$150,0,MATCH(X$2,Inputs!$D$2:$AG$2,0)),Inputs!$B$4:$B$150,$B10)/1000) -> -3567 | Y10: =IF(Y$3=0,"",SUMIFS(INDEX(Inputs!$D$4:$AG$150,0,MATCH(Y$2,Inputs!$D$2:$AG$2,0)),Inputs!$B$4:$B$150,$B10)/1000) -> -3351 | Z10: =IF(Z$3=0,"",SUMIFS(INDEX(Inputs!$D$4:$AG$150,0,MATCH(Z$2,Inputs!$D$2:$AG$2,0)),Inputs!$B$4:$B$150,$B10)/1000) -> -3164 | AA10: =IF(AA$3=0,"",SUMIFS(INDEX(Inputs!$D$4:$AG$150,0,MATCH(AA$2,Inputs!$D$2:$AG$2,0)),Inputs!$B$4:$B$150,$B10)/1000) -> -1422 | AB10: =IF(COUNT(X10:AA10)=4,SUM(X10:AA10),"") -> -11504 | AC10: =IF(AC$3=0,"",SUMIFS(INDEX(Inputs!$D$4:$AG$150,0,MATCH(AC$2,Inputs!$D$2:$AG$2,0)),Inputs!$B$4:$B$150,$B10)/1000) -> -2495 | AD10: =IF(AD$3=0,"",SUMIFS(INDEX(Inputs!$D$4:$AG$150,0,MATCH(AD$2,Inputs!$D$2:$AG$2,0)),Inputs!$B$4:$B$150,$B10)/1000) -> -4543 | AE10: =IF(AE$3=0,"",SUMIFS(INDEX(Inputs!$D$4:$AG$150,0,MATCH(AE$2,Inputs!$D$2:$AG$2,0)),Inputs!$B$4:$B$150,$B10)/1000) | AF10: =IF(AF$3=0,"",SUMIFS(INDEX(Inputs!$D$4:$AG$150,0,MATCH(AF$2,Inputs!$D$2:$AG$2,0)),Inputs!$B$4:$B$150,$B10)/1000) | AG10: =IF(COUNT(AC10:AF10)=4,SUM(AC10:AF10),"")
B11: 8 | C11: Equity in Income of Affiliates, after tax (enter as +) | D11: =IF(D$3=0,"",SUMIFS(INDEX(Inputs!$D$4:$AG$150,0,MATCH(D$2,Inputs!$D$2:$AG$2,0)),Inputs!$B$4:$B$150,$B11)/1000) -> 0 | E11: =IF(E$3=0,"",SUMIFS(INDEX(Inputs!$D$4:$AG$150,0,MATCH(E$2,Inputs!$D$2:$AG$2,0)),Inputs!$B$4:$B$150,$B11)/1000) -> 0 | F11: =IF(F$3=0,"",SUMIFS(INDEX(Inputs!$D$4:$AG$150,0,MATCH(F$2,Inputs!$D$2:$AG$2,0)),Inputs!$B$4:$B$150,$B11)/1000) -> 0 | G11: =IF(G$3=0,"",SUMIFS(INDEX(Inputs!$D$4:$AG$150,0,MATCH(G$2,Inputs!$D$2:$AG$2,0)),Inputs!$B$4:$B$150,$B11)/1000) -> 0 | H11: =IF(COUNT(D11:G11)=4,SUM(D11:G11),"") -> 0 | I11: =IF(I$3=0,"",SUMIFS(INDEX(Inputs!$D$4:$AG$150,0,MATCH(I$2,Inputs!$D$2:$AG$2,0)),Inputs!$B$4:$B$150,$B11)/1000) -> 0 | J11: =IF(J$3=0,"",SUMIFS(INDEX(Inputs!$D$4:$AG$150,0,MATCH(J$2,Inputs!$D$2:$AG$2,0)),Inputs!$B$4:$B$150,$B11)/1000) -> 0 | K11: =IF(K$3=0,"",SUMIFS(INDEX(Inputs!$D$4:$AG$150,0,MATCH(K$2,Inputs!$D$2:$AG$2,0)),Inputs!$B$4:$B$150,$B11)/1000) -> 0 | L11: =IF(L$3=0,"",SUMIFS(INDEX(Inputs!$D$4:$AG$150,0,MATCH(L$2,Inputs!$D$2:$AG$2,0)),Inputs!$B$4:$B$150,$B11)/1000) -> 0 | M11: =IF(COUNT(I11:L11)=4,SUM(I11:L11),"") -> 0 | N11: =IF(N$3=0,"",SUMIFS(INDEX(Inputs!$D$4:$AG$150,0,MATCH(N$2,Inputs!$D$2:$AG$2,0)),Inputs!$B$4:$B$150,$B11)/1000) -> 0 | O11: =IF(O$3=0,"",SUMIFS(INDEX(Inputs!$D$4:$AG$150,0,MATCH(O$2,Inputs!$D$2:$AG$2,0)),Inputs!$B$4:$B$150,$B11)/1000) -> 0 | P11: =IF(P$3=0,"",SUMIFS(INDEX(Inputs!$D$4:$AG$150,0,MATCH(P$2,Inputs!$D$2:$AG$2,0)),Inputs!$B$4:$B$150,$B11)/1000) -> 0 | Q11: =IF(Q$3=0,"",SUMIFS(INDEX(Inputs!$D$4:$AG$150,0,MATCH(Q$2,Inputs!$D$2:$AG$2,0)),Inputs!$B$4:$B$150,$B11)/1000) -> 0 | R11: =IF(COUNT(N11:Q11)=4,SUM(N11:Q11),"") -> 0 | S11: =IF(S$3=0,"",SUMIFS(INDEX(Inputs!$D$4:$AG$150,0,MATCH(S$2,Inputs!$D$2:$AG$2,0)),Inputs!$B$4:$B$150,$B11)/1000) -> 0 | T11: =IF(T$3=0,"",SUMIFS(INDEX(Inputs!$D$4:$AG$150,0,MATCH(T$2,Inputs!$D$2:$AG$2,0)),Inputs!$B$4:$B$150,$B11)/1000) -> 0 | U11: =IF(U$3=0,"",SUMIFS(INDEX(Inputs!$D$4:$AG$150,0,MATCH(U$2,Inputs!$D$2:$AG$2,0)),Inputs!$B$4:$B$150,$B11)/1000) -> 0 | V11: =IF(V$3=0,"",SUMIFS(INDEX(Inputs!$D$4:$AG$150,0,MATCH(V$2,Inputs!$D$2:$AG$2,0)),Inputs!$B$4:$B$150,$B11)/1000) -> 0 | W11: =IF(COUNT(S11:V11)=4,SUM(S11:V11),"") -> 0 | X11: =IF(X$3=0,"",SUMIFS(INDEX(Inputs!$D$4:$AG$150,0,MATCH(X$2,Inputs!$D$2:$AG$2,0)),Inputs!$B$4:$B$150,$B11)/1000) -> 0 | Y11: =IF(Y$3=0,"",SUMIFS(INDEX(Inputs!$D$4:$AG$150,0,MATCH(Y$2,Inputs!$D$2:$AG$2,0)),Inputs!$B$4:$B$150,$B11)/1000) -> 0 | Z11: =IF(Z$3=0,"",SUMIFS(INDEX(Inputs!$D$4:$AG$150,0,MATCH(Z$2,Inputs!$D$2:$AG$2,0)),Inputs!$B$4:$B$150,$B11)/1000) -> 0 | AA11: =IF(AA$3=0,"",SUMIFS(INDEX(Inputs!$D$4:$AG$150,0,MATCH(AA$2,Inputs!$D$2:$AG$2,0)),Inputs!$B$4:$B$150,$B11)/1000) -> 0 | AB11: =IF(COUNT(X11:AA11)=4,SUM(X11:AA11),"") -> 0 | AC11: =IF(AC$3=0,"",SUMIFS(INDEX(Inputs!$D$4:$AG$150,0,MATCH(AC$2,Inputs!$D$2:$AG$2,0)),Inputs!$B$4:$B$150,$B11)/1000) -> 0 | AD11: =IF(AD$3=0,"",SUMIFS(INDEX(Inputs!$D$4:$AG$150,0,MATCH(AD$2,Inputs!$D$2:$AG$2,0)),Inputs!$B$4:$B$150,$B11)/1000) -> 0 | AE11: =IF(AE$3=0,"",SUMIFS(INDEX(Inputs!$D$4:$AG$150,0,MATCH(AE$2,Inputs!$D$2:$AG$2,0)),Inputs!$B$4:$B$150,$B11)/1000) | AF11: =IF(AF$3=0,"",SUMIFS(INDEX(Inputs!$D$4:$AG$150,0,MATCH(AF$2,Inputs!$D$2:$AG$2,0)),Inputs!$B$4:$B$150,$B11)/1000) | AG11: =IF(COUNT(AC11:AF11)=4,SUM(AC11:AF11),"")
B12: 9 | C12: Minority Interest Expense, after tax (enter as - ) | D12: =IF(D$3=0,"",SUMIFS(INDEX(Inputs!$D$4:$AG$150,0,MATCH(D$2,Inputs!$D$2:$AG$2,0)),Inputs!$B$4:$B$150,$B12)/1000) -> -66 | E12: =IF(E$3=0,"",SUMIFS(INDEX(Inputs!$D$4:$AG$150,0,MATCH(E$2,Inputs!$D$2:$AG$2,0)),Inputs!$B$4:$B$150,$B12)/1000) -> -91 | F12: =IF(F$3=0,"",SUMIFS(INDEX(Inputs!$D$4:$AG$150,0,MATCH(F$2,Inputs!$D$2:$AG$2,0)),Inputs!$B$4:$B$150,$B12)/1000) -> -192 | G12: =IF(G$3=0,"",SUMIFS(INDEX(Inputs!$D$4:$AG$150,0,MATCH(G$2,Inputs!$D$2:$AG$2,0)),Inputs!$B$4:$B$150,$B12)/1000) -> -209 | H12: =IF(COUNT(D12:G12)=4,SUM(D12:G12),"") -> -558 | I12: =IF(I$3=0,"",SUMIFS(INDEX(Inputs!$D$4:$AG$150,0,MATCH(I$2,Inputs!$D$2:$AG$2,0)),Inputs!$B$4:$B$150,$B12)/1000) -> -270 | J12: =IF(J$3=0,"",SUMIFS(INDEX(Inputs!$D$4:$AG$150,0,MATCH(J$2,Inputs!$D$2:$AG$2,0)),Inputs!$B$4:$B$150,$B12)/1000) -> -724 | K12: =IF(K$3=0,"",SUMIFS(INDEX(Inputs!$D$4:$AG$150,0,MATCH(K$2,Inputs!$D$2:$AG$2,0)),Inputs!$B$4:$B$150,$B12)/1000) -> -538 | L12: =IF(L$3=0,"",SUMIFS(INDEX(Inputs!$D$4:$AG$150,0,MATCH(L$2,Inputs!$D$2:$AG$2,0)),Inputs!$B$4:$B$150,$B12)/1000) -> -305 | M12: =IF(COUNT(I12:L12)=4,SUM(I12:L12),"") -> -1837 | N12: =IF(N$3=0,"",SUMIFS(INDEX(Inputs!$D$4:$AG$150,0,MATCH(N$2,Inputs!$D$2:$AG$2,0)),Inputs!$B$4:$B$150,$B12)/1000) -> -413 | O12: =IF(O$3=0,"",SUMIFS(INDEX(Inputs!$D$4:$AG$150,0,MATCH(O$2,Inputs!$D$2:$AG$2,0)),Inputs!$B$4:$B$150,$B12)/1000) -> -273 | P12: =IF(P$3=0,"",SUMIFS(INDEX(Inputs!$D$4:$AG$150,0,MATCH(P$2,Inputs!$D$2:$AG$2,0)),Inputs!$B$4:$B$150,$B12)/1000) -> -276 | Q12: =IF(Q$3=0,"",SUMIFS(INDEX(Inputs!$D$4:$AG$150,0,MATCH(Q$2,Inputs!$D$2:$AG$2,0)),Inputs!$B$4:$B$150,$B12)/1000) -> -382 | R12: =IF(COUNT(N12:Q12)=4,SUM(N12:Q12),"") -> -1344 | S12: =IF(S$3=0,"",SUMIFS(INDEX(Inputs!$D$4:$AG$150,0,MATCH(S$2,Inputs!$D$2:$AG$2,0)),Inputs!$B$4:$B$150,$B12)/1000) -> -346 | T12: =IF(T$3=0,"",SUMIFS(INDEX(Inputs!$D$4:$AG$150,0,MATCH(T$2,Inputs!$D$2:$AG$2,0)),Inputs!$B$4:$B$150,$B12)/1000) -> -331 | U12: =IF(U$3=0,"",SUMIFS(INDEX(Inputs!$D$4:$AG$150,0,MATCH(U$2,Inputs!$D$2:$AG$2,0)),Inputs!$B$4:$B$150,$B12)/1000) -> -361 | V12: =IF(V$3=0,"",SUMIFS(INDEX(Inputs!$D$4:$AG$150,0,MATCH(V$2,Inputs!$D$2:$AG$2,0)),Inputs!$B$4:$B$150,$B12)/1000) -> -345 | W12: =IF(COUNT(S12:V12)=4,SUM(S12:V12),"") -> -1383 | X12: =IF(X$3=0,"",SUMIFS(INDEX(Inputs!$D$4:$AG$150,0,MATCH(X$2,Inputs!$D$2:$AG$2,0)),Inputs!$B$4:$B$150,$B12)/1000) -> -320 | Y12: =IF(Y$3=0,"",SUMIFS(INDEX(Inputs!$D$4:$AG$150,0,MATCH(Y$2,Inputs!$D$2:$AG$2,0)),Inputs!$B$4:$B$150,$B12)/1000) -> -272 | Z12: =IF(Z$3=0,"",SUMIFS(INDEX(Inputs!$D$4:$AG$150,0,MATCH(Z$2,Inputs!$D$2:$AG$2,0)),Inputs!$B$4:$B$150,$B12)/1000) -> -220 | AA12: =IF(AA$3=0,"",SUMIFS(INDEX(Inputs!$D$4:$AG$150,0,MATCH(AA$2,Inputs!$D$2:$AG$2,0)),Inputs!$B$4:$B$150,$B12)/1000) -> -108 | AB12: =IF(COUNT(X12:AA12)=4,SUM(X12:AA12),"") -> -920 | AC12: =IF(AC$3=0,"",SUMIFS(INDEX(Inputs!$D$4:$AG$150,0,MATCH(AC$2,Inputs!$D$2:$AG$2,0)),Inputs!$B$4:$B$150,$B12)/1000) -> -289 | AD12: =IF(AD$3=0,"",SUMIFS(INDEX(Inputs!$D$4:$AG$150,0,MATCH(AD$2,Inputs!$D$2:$AG$2,0)),Inputs!$B$4:$B$150,$B12)/1000) -> -356 | AE12: =IF(AE$3=0,"",SUMIFS(INDEX(Inputs!$D$4:$AG$150,0,MATCH(AE$2,Inputs!$D$2:$AG$2,0)),Inputs!$B$4:$B$150,$B12)/1000) | AF12: =IF(AF$3=0,"",SUMIFS(INDEX(Inputs!$D$4:$AG$150,0,MATCH(AF$2,Inputs!$D$2:$AG$2,0)),Inputs!$B$4:$B$150,$B12)/1000) | AG12: =IF(COUNT(AC12:AF12)=4,SUM(AC12:AF12),"")
B13: 10 | C13: Common Dividends | D13: =IF(D$3=0,"",SUMIFS(INDEX(Inputs!$D$4:$AG$150,0,MATCH(D$2,Inputs!$D$2:$AG$2,0)),Inputs!$B$4:$B$150,$B13)/1000) -> -3720 | E13: =IF(E$3=0,"",SUMIFS(INDEX(Inputs!$D$4:$AG$150,0,MATCH(E$2,Inputs!$D$2:$AG$2,0)),Inputs!$B$4:$B$150,$B13)/1000) -> -3721 | F13: =IF(F$3=0,"",SUMIFS(INDEX(Inputs!$D$4:$AG$150,0,MATCH(F$2,Inputs!$D$2:$AG$2,0)),Inputs!$B$4:$B$150,$B13)/1000) -> -3720 | G13: =IF(G$3=0,"",SUMIFS(INDEX(Inputs!$D$4:$AG$150,0,MATCH(G$2,Inputs!$D$2:$AG$2,0)),Inputs!$B$4:$B$150,$B13)/1000) -> -3763 | H13: =IF(COUNT(D13:G13)=4,SUM(D13:G13),"") -> -14924 | I13: =IF(I$3=0,"",SUMIFS(INDEX(Inputs!$D$4:$AG$150,0,MATCH(I$2,Inputs!$D$2:$AG$2,0)),Inputs!$B$4:$B$150,$B13)/1000) -> -3760 | J13: =IF(J$3=0,"",SUMIFS(INDEX(Inputs!$D$4:$AG$150,0,MATCH(J$2,Inputs!$D$2:$AG$2,0)),Inputs!$B$4:$B$150,$B13)/1000) -> -3727 | K13: =IF(K$3=0,"",SUMIFS(INDEX(Inputs!$D$4:$AG$150,0,MATCH(K$2,Inputs!$D$2:$AG$2,0)),Inputs!$B$4:$B$150,$B13)/1000) -> -3685 | L13: =IF(L$3=0,"",SUMIFS(INDEX(Inputs!$D$4:$AG$150,0,MATCH(L$2,Inputs!$D$2:$AG$2,0)),Inputs!$B$4:$B$150,$B13)/1000) -> -3767 | M13: =IF(COUNT(I13:L13)=4,SUM(I13:L13),"") -> -14939 | N13: =IF(N$3=0,"",SUMIFS(INDEX(Inputs!$D$4:$AG$150,0,MATCH(N$2,Inputs!$D$2:$AG$2,0)),Inputs!$B$4:$B$150,$B13)/1000) -> -3738 | O13: =IF(O$3=0,"",SUMIFS(INDEX(Inputs!$D$4:$AG$150,0,MATCH(O$2,Inputs!$D$2:$AG$2,0)),Inputs!$B$4:$B$150,$B13)/1000) -> -3701 | P13: =IF(P$3=0,"",SUMIFS(INDEX(Inputs!$D$4:$AG$150,0,MATCH(P$2,Inputs!$D$2:$AG$2,0)),Inputs!$B$4:$B$150,$B13)/1000) -> -3663 | Q13: =IF(Q$3=0,"",SUMIFS(INDEX(Inputs!$D$4:$AG$150,0,MATCH(Q$2,Inputs!$D$2:$AG$2,0)),Inputs!$B$4:$B$150,$B13)/1000) -> -3839 | R13: =IF(COUNT(N13:Q13)=4,SUM(N13:Q13),"") -> -14941 | S13: =IF(S$3=0,"",SUMIFS(INDEX(Inputs!$D$4:$AG$150,0,MATCH(S$2,Inputs!$D$2:$AG$2,0)),Inputs!$B$4:$B$150,$B13)/1000) -> -3808 | T13: =IF(T$3=0,"",SUMIFS(INDEX(Inputs!$D$4:$AG$150,0,MATCH(T$2,Inputs!$D$2:$AG$2,0)),Inputs!$B$4:$B$150,$B13)/1000) -> -4285 | U13: =IF(U$3=0,"",SUMIFS(INDEX(Inputs!$D$4:$AG$150,0,MATCH(U$2,Inputs!$D$2:$AG$2,0)),Inputs!$B$4:$B$150,$B13)/1000) -> -4240 | V13: =IF(V$3=0,"",SUMIFS(INDEX(Inputs!$D$4:$AG$150,0,MATCH(V$2,Inputs!$D$2:$AG$2,0)),Inputs!$B$4:$B$150,$B13)/1000) -> -4371 | W13: =IF(COUNT(S13:V13)=4,SUM(S13:V13),"") -> -16704 | X13: =IF(X$3=0,"",SUMIFS(INDEX(Inputs!$D$4:$AG$150,0,MATCH(X$2,Inputs!$D$2:$AG$2,0)),Inputs!$B$4:$B$150,$B13)/1000) -> -4335 | Y13: =IF(Y$3=0,"",SUMIFS(INDEX(Inputs!$D$4:$AG$150,0,MATCH(Y$2,Inputs!$D$2:$AG$2,0)),Inputs!$B$4:$B$150,$B13)/1000) -> -4288 | Z13: =IF(Z$3=0,"",SUMIFS(INDEX(Inputs!$D$4:$AG$150,0,MATCH(Z$2,Inputs!$D$2:$AG$2,0)),Inputs!$B$4:$B$150,$B13)/1000) -> -4242 | AA13: =IF(AA$3=0,"",SUMIFS(INDEX(Inputs!$D$4:$AG$150,0,MATCH(AA$2,Inputs!$D$2:$AG$2,0)),Inputs!$B$4:$B$150,$B13)/1000) -> -4366 | AB13: =IF(COUNT(X13:AA13)=4,SUM(X13:AA13),"") -> -17231 | AC13: =IF(AC$3=0,"",SUMIFS(INDEX(Inputs!$D$4:$AG$150,0,MATCH(AC$2,Inputs!$D$2:$AG$2,0)),Inputs!$B$4:$B$150,$B13)/1000) -> -4334 | AD13: =IF(AD$3=0,"",SUMIFS(INDEX(Inputs!$D$4:$AG$150,0,MATCH(AD$2,Inputs!$D$2:$AG$2,0)),Inputs!$B$4:$B$150,$B13)/1000) -> -4299 | AE13: =IF(AE$3=0,"",SUMIFS(INDEX(Inputs!$D$4:$AG$150,0,MATCH(AE$2,Inputs!$D$2:$AG$2,0)),Inputs!$B$4:$B$150,$B13)/1000) | AF13: =IF(AF$3=0,"",SUMIFS(INDEX(Inputs!$D$4:$AG$150,0,MATCH(AF$2,Inputs!$D$2:$AG$2,0)),Inputs!$B$4:$B$150,$B13)/1000) | AG13: =IF(COUNT(AC13:AF13)=4,SUM(AC13:AF13),"")
