Workbook

Sheet Inputs
B1: Fator de escala | C1: Fonte já na unidade final = 1 · fonte em milhares = 0,001 | D1: 1 | F1: MODELO-BASE VAZIO — preencha os valores nas linhas abaixo e as datas de primeiro e último trimestre no painel de premissas
B2: COD | C2: Conta (como divulgada) | D2: Fonte · ORIGEM · unidade | E2: 1T20 | F2: 2T20 | G2: 3T20 | H2: 4T20 | I2: 1T21 | J2: 2T21 | K2: 3T21 | L2: 4T21 | M2: 1T22 | N2: 2T22 | O2: 3T22 | P2: 4T22 | Q2: 1T23 | R2: 2T23 | S2: 3T23 | T2: 4T23 | U2: 1T24 | V2: 2T24 | W2: 3T24 | X2: 4T24 | Y2: 1T25 | Z2: 2T25 | AA2: 3T25 | AB2: 4T25 | AC2: 1T26 | AD2: 2T26 | AE2: 3T26 | AF2: 4T26 | AG2: 1T27 | AH2: 2T27 | AI2: 3T27 | AJ2: 4T27 | AK2: 1T28 | AL2: 2T28 | AM2: 3T28 | AN2: 4T28 | AO2: 1T29 | AP2: 2T29 | AQ2: 3T29 | AR2: 4T29 | AS2: 1T30 | AT2: 2T30 | AU2: 3T30 | AV2: 4T30
C5: ATIVO
B6: disp | C6: Disponibilidades | D6: preencher: aba e linha da fonte · fonte · moeda
B7: aplic_mo | C7: Aplicações no Mercado Aberto | D7: preencher: aba e linha da fonte · fonte · moeda
B8: aplic_di | C8: Aplicações em Depósitos Interfinanceiros | D8: preencher: aba e linha da fonte · fonte · moeda
B9: aplic_rg | C9: Recursos Garantidores das Provisões Técnicas | D9: preencher: aba e linha da fonte · fonte · moeda
B10: aplic_pdd | C10: (Provisão para Perda de Crédito Esperada) | D10: preencher: aba e linha da fonte · fonte · moeda
B11: tvm_prop | C11: Carteira própria | D11: preencher: aba e linha da fonte · fonte · moeda
B12: tvm_vinc | C12: Vinculados | D12: preencher: aba e linha da fonte · fonte · moeda
B13: tvm_rg | C13: Recursos Garantidores das Provisões Técnicas | D13: preencher: aba e linha da fonte · fonte · moeda
B14: tvm_pdd | C14: (Provisão para Perda de Crédito Esperada) | D14: preencher: aba e linha da fonte · fonte · moeda
B15: deriv_a | C15: Derivativos | D15: preencher: aba e linha da fonte · fonte · moeda
B16: cred_op | C16: Operações de Crédito, Arrendamentos e Outros Créditos | D16: preencher: aba e linha da fonte · fonte · moeda
B17: cred_tvm | C17: Títulos e Valores Mobiliários | D17: preencher: aba e linha da fonte · fonte · moeda
... B25: intang | C25: Ágio e Intangível | D25: preencher: aba e linha da fonte · fonte · moeda
C27: PASSIVO
B28: dep_vista | C28: Depósitos à Vista | D28: preencher: aba e linha da fonte · fonte · moeda
B29: dep_poup | C29: Depósitos de Poupança | D29: preencher: aba e linha da fonte · fonte · moeda
B30: dep_inter | C30: Depósitos Interfinanceiros | D30: preencher: aba e linha da fonte · fonte · moeda
B31: dep_prazo | C31: Depósitos a Prazo | D31: preencher: aba e linha da fonte · fonte · moeda
B32: dep_out | C32: Outros Depósitos | D32: preencher: aba e linha da fonte · fonte · moeda
B33: mo_prop | C33: Carteira Própria | D33: preencher: aba e linha da fonte · fonte · moeda
B34: mo_terc | C34: Carteira de Terceiros | D34: preencher: aba e linha da fonte · fonte · moeda
B35: mo_livre | C35: Carteira de Livre Movimentação | D35: preencher: aba e linha da fonte · fonte · moeda
B36: div_emis | C36: Recursos de Emissões (LF, LCI, LCA, LIG) | D36: preencher: aba e linha da fonte · fonte · moeda
B37: div_ext | C37: Obrigações por TVM no Exterior | D37: preencher: aba e linha da fonte · fonte · moeda
B38: div_coe | C38: Captação por Certificados de Operações Estruturadas | D38: preencher: aba e linha da fonte · fonte · moeda
B39: div_sub | C39: Instrumentos de Dívida Subordinada | D39: preencher: aba e linha da fonte · fonte · moeda
... B48: out_p | C48: Outros Passivos | D48: preencher: aba e linha da fonte · fonte · moeda
C50: PATRIMÔNIO LÍQUIDO
B51: cap_social | C51: Capital Social | D51: preencher: aba e linha da fonte · fonte · moeda
B52: res_cap | C52: Reservas de Capital | D52: preencher: aba e linha da fonte · fonte · moeda
B53: res_luc | C53: Reservas de Lucros | D53: preencher: aba e linha da fonte · fonte · moeda
B54: ora | C54: Outros Resultados Abrangentes | D54: preencher: aba e linha da fonte · fonte · moeda
B55: tesour | C55: (Ações em Tesouraria) | D55: preencher: aba e linha da fonte · fonte · moeda
B56: minor | C56: Participação de Acionistas Não Controladores | D56: preencher: aba e linha da fonte · fonte · moeda
C58: DEMONSTRAÇÃO DO RESULTADO
B59: rec_cred | C59: Resultado com Operações de Concessão de Crédito | D59: preencher: aba e linha da fonte · fonte · moeda
B60: rec_tvm | C60: Resultado de TVM, Derivativos e Outros | D60: preencher: aba e linha da fonte · fonte · moeda
...

Sheet Inputs (2)
C1: ="Demonstrações reportadas — valores em "&Inputs!$E$202 -> Demonstrações reportadas — valores em R$ milhões | D1: Reported financials | E1: =DATE(2020,4,1)-1 -> 43921 | F1: =DATE(2020,7,1)-1 -> 44012 | G1: =DATE(2020,10,1)-1 -> 44104 | H1: =DATE(2020,13,1)-1 -> 44196 | I1: =H1 -> 44196 | J1: =DATE(2021,4,1)-1 -> 44286 | K1: =DATE(2021,7,1)-1 -> 44377 | L1: =DATE(2021,10,1)-1 -> 44469 | M1: =DATE(2021,13,1)-1 -> 44561 | N1: =M1 -> 44561 | O1: =DATE(2022,4,1)-1 -> 44651 | P1: =DATE(2022,7,1)-1 -> 44742 | Q1: =DATE(2022,10,1)-1 -> 44834 | R1: =DATE(2022,13,1)-1 -> 44926 | S1: =R1 -> 44926 | T1: =DATE(2023,4,1)-1 -> 45016 | U1: =DATE(2023,7,1)-1 -> 45107 | V1: =DATE(2023,10,1)-1 -> 45199 | W1: =DATE(2023,13,1)-1 -> 45291 | X1: =W1 -> 45291 | Y1: =DATE(2024,4,1)-1 -> 45382 | Z1: =DATE(2024,7,1)-1 -> 45473 | AA1: =DATE(2024,10,1)-1 -> 45565 | AB1: =DATE(2024,13,1)-1 -> 45657 | AC1: =AB1 -> 45657 | AD1: =DATE(2025,4,1)-1 -> 45747 | AE1: =DATE(2025,7,1)-1 -> 45838 | AF1: =DATE(2025,10,1)-1 -> 45930 | AG1: =DATE(2025,13,1)-1 -> 46022 | AH1: =AG1 -> 46022 | AI1: =DATE(2026,4,1)-1 -> 46112 | AJ1: =DATE(2026,7,1)-1 -> 46203 | AK1: =DATE(2026,10,1)-1 -> 46295 | AL1: =DATE(2026,13,1)-1 -> 46387 | AM1: =AL1 -> 46387 | AN1: =DATE(2027,4,1)-1 -> 46477 | AO1: =DATE(2027,7,1)-1 -> 46568 | AP1: =DATE(2027,10,1)-1 -> 46660 | AQ1: =DATE(2027,13,1)-1 -> 46752 | AR1: =AQ1 -> 46752 | AS1: =DATE(2028,4,1)-1 -> 46843 | AT1: =DATE(2028,7,1)-1 -> 46934 | AU1: =DATE(2028,10,1)-1 -> 47026 | AV1: =DATE(2028,13,1)-1 -> 47118 | AW1: =AV1 -> 47118 | AX1: =DATE(2029,4,1)-1 -> 47208 | AY1: =DATE(2029,7,1)-1 -> 47299 | AZ1: =DATE(2029,10,1)-1 -> 47391 | BA1: =DATE(2029,13,1)-1 -> 47483 | BB1: =BA1 -> 47483 | BC1: =DATE(2030,4,1)-1 -> 47573 | BD1: =DATE(2030,7,1)-1 -> 47664 | BE1: =DATE(2030,10,1)-1 -> 47756 | BF1: =DATE(2030,13,1)-1 -> 47848 | BG1: =BF1 -> 47848
B2: COD | E2: 2020 | F2: 2020 | G2: 2020 | H2: 2020 | I2: 2020 | J2: 2021 | K2: 2021 | L2: 2021 | M2: 2021 | N2: 2021 | O2: 2022 | P2: 2022 | Q2: 2022 | R2: 2022 | S2: 2022 | T2: 2023 | U2: 2023 | V2: 2023 | W2: 2023 | X2: 2023 | Y2: 2024 | Z2: 2024 | AA2: 2024 | AB2: 2024 | AC2: 2024 | AD2: 2025 | AE2: 2025 | AF2: 2025 | AG2: 2025 | AH2: 2025 | AI2: 2026 | AJ2: 2026 | AK2: 2026 | AL2: 2026 | AM2: 2026 | AN2: 2027 | AO2: 2027 | AP2: 2027 | AQ2: 2027 | AR2: 2027 | AS2: 2028 | AT2: 2028 | AU2: 2028 | AV2: 2028 | AW2: 2028 | AX2: 2029 | AY2: 2029 | AZ2: 2029 | BA2: 2029 | BB2: 2029 | BC2: 2030 | BD2: 2030 | BE2: 2030 | BF2: 2030 | BG2: 2030
C3: Período | D3: Period | E3: ="1Q"&RIGHT(E2,2) -> 1Q20 | F3: ="2Q"&RIGHT(F2,2) -> 2Q20 | G3: ="3Q"&RIGHT(G2,2) -> 3Q20 | H3: ="4Q"&RIGHT(H2,2) -> 4Q20 | I3: ="FY"&RIGHT(I2,2) -> FY20 | J3: ="1Q"&RIGHT(J2,2) -> 1Q21 | K3: ="2Q"&RIGHT(K2,2) -> 2Q21 | L3: ="3Q"&RIGHT(L2,2) -> 3Q21 | M3: ="4Q"&RIGHT(M2,2) -> 4Q21 | N3: ="FY"&RIGHT(N2,2) -> FY21 | O3: ="1Q"&RIGHT(O2,2) -> 1Q22 | P3: ="2Q"&RIGHT(P2,2) -> 2Q22 | Q3: ="3Q"&RIGHT(Q2,2) -> 3Q22 | R3: ="4Q"&RIGHT(R2,2) -> 4Q22 | S3: ="FY"&RIGHT(S2,2) -> FY22 | T3: ="1Q"&RIGHT(T2,2) -> 1Q23 | U3: ="2Q"&RIGHT(U2,2) -> 2Q23 | V3: ="3Q"&RIGHT(V2,2) -> 3Q23 | W3: ="4Q"&RIGHT(W2,2) -> 4Q23 | X3: ="FY"&RIGHT(X2,2) -> FY23 | Y3: ="1Q"&RIGHT(Y2,2) -> 1Q24 | Z3: ="2Q"&RIGHT(Z2,2) -> 2Q24 | AA3: ="3Q"&RIGHT(AA2,2) -> 3Q24 | AB3: ="4Q"&RIGHT(AB2,2) -> 4Q24 | AC3: ="FY"&RIGHT(AC2,2) -> FY24 | AD3: ="1Q"&RIGHT(AD2,2) -> 1Q25 | AE3: ="2Q"&RIGHT(AE2,2) -> 2Q25 | AF3: ="3Q"&RIGHT(AF2,2) -> 3Q25 | AG3: ="4Q"&RIGHT(AG2,2) -> 4Q25 | AH3: ="FY"&RIGHT(AH2,2) -> FY25 | AI3: ="1Q"&RIGHT(AI2,2) -> 1Q26 | AJ3: ="2Q"&RIGHT(AJ2,2) -> 2Q26 | AK3: ="3Q"&RIGHT(AK2,2) -> 3Q26 | AL3: ="4Q"&RIGHT(AL2,2) -> 4Q26 | AM3: ="FY"&RIGHT(AM2,2) -> FY26 | AN3: ="1Q"&RIGHT(AN2,2) -> 1Q27 | AO3: ="2Q"&RIGHT(AO2,2) -> 2Q27 | AP3: ="3Q"&RIGHT(AP2,2) -> 3Q27 | AQ3: ="4Q"&RIGHT(AQ2,2) -> 4Q27 | AR3: ="FY"&RIGHT(AR2,2) -> FY27 | AS3: ="1Q"&RIGHT(AS2,2) -> 1Q28 | AT3: ="2Q"&RIGHT(AT2,2) -> 2Q28 | AU3: ="3Q"&RIGHT(AU2,2) -> 3Q28 | AV3: ="4Q"&RIGHT(AV2,2) -> 4Q28 | AW3: ="FY"&RIGHT(AW2,2) -> FY28 | AX3: ="1Q"&RIGHT(AX2,2) -> 1Q29 | AY3: ="2Q"&RIGHT(AY2,2) -> 2Q29 | AZ3: ="3Q"&RIGHT(AZ2,2) -> 3Q29 | BA3: ="4Q"&RIGHT(BA2,2) -> 4Q29 | BB3: ="FY"&RIGHT(BB2,2) -> FY29 | BC3: ="1Q"&RIGHT(BC2,2) -> 1Q30 | BD3: ="2Q"&RIGHT(BD2,2) -> 2Q30 | BE3: ="3Q"&RIGHT(BE2,2) -> 3Q30 | BF3: ="4Q"&RIGHT(BF2,2) -> 4Q30 | BG3: ="FY"&RIGHT(BG2,2) -> FY30
C4: ATIVO | D4: ASSETS
B5: disp | C5: Disponibilidades | D5: Cash and Cash Equivalents | E5: =IF(ISNA(SUMIFS(INDEX(Inputs!$B$2:$AZ$190,,MATCH(SUBSTITUTE(E$3,"Q","T"),Inputs!$B$2:$AZ$2,0)),Inputs!$B$2:$B$190,$B5)*Inputs!$D$1),"",SUMIFS(INDEX(Inputs!$B$2:$AZ$190,,MATCH(SUBSTITUTE(E$3,"Q","T"),Inputs!$B$2:$AZ$2,0)),Inputs!$B$2:$B$190,$B5)*Inputs!$D$1) -> 0 | F5: =IF(ISNA(SUMIFS(INDEX(Inputs!$B$2:$AZ$190,,MATCH(SUBSTITUTE(F$3,"Q","T"),Inputs!$B$2:$AZ$2,0)),Inputs!$B$2:$B$190,$B5)*Inputs!$D$1),"",SUMIFS(INDEX(Inputs!$B$2:$AZ$190,,MATCH(SUBSTITUTE(F$3,"Q","T"),Inputs!$B$2:$AZ$2,0)),Inputs!$B$2:$B$190,$B5)*Inputs!$D$1) -> 0 | G5: =IF(ISNA(SUMIFS(INDEX(Inputs!$B$2:$AZ$190,,MATCH(SUBSTITUTE(G$3,"Q","T"),Inputs!$B$2:$AZ$2,0)),Inputs!$B$2:$B$190,$B5)*Inputs!$D$1),"",SUMIFS(INDEX(Inputs!$B$2:$AZ$190,,MATCH(SUBSTITUTE(G$3,"Q","T"),Inputs!$B$2:$AZ$2,0)),Inputs!$B$2:$B$190,$B5)*Inputs!$D$1) -> 0 | H5: =IF(ISNA(SUMIFS(INDEX(Inputs!$B$2:$AZ$190,,MATCH(SUBSTITUTE(H$3,"Q","T"),Inputs!$B$2:$AZ$2,0)),Inputs!$B$2:$B$190,$B5)*Inputs!$D$1),"",SUMIFS(INDEX(Inputs!$B$2:$AZ$190,,MATCH(SUBSTITUTE(H$3,"Q","T"),Inputs!$B$2:$AZ$2,0)),Inputs!$B$2:$B$190,$B5)*Inputs!$D$1) -> 0 | I5: =H5 -> 0 | J5: =IF(ISNA(SUMIFS(INDEX(Inputs!$B$2:$AZ$190,,MATCH(SUBSTITUTE(J$3,"Q","T"),Inputs!$B$2:$AZ$2,0)),Inputs!$B$2:$B$190,$B5)*Inputs!$D$1),"",SUMIFS(INDEX(Inputs!$B$2:$AZ$190,,MATCH(SUBSTITUTE(J$3,"Q","T"),Inputs!$B$2:$AZ$2,0)),Inputs!$B$2:$B$190,$B5)*Inputs!$D$1) -> 0 | K5: =IF(ISNA(SUMIFS(INDEX(Inputs!$B$2:$AZ$190,,MATCH(SUBSTITUTE(K$3,"Q","T"),Inputs!$B$2:$AZ$2,0)),Inputs!$B$2:$B$190,$B5)*Inputs!$D$1),"",SUMIFS(INDEX(Inputs!$B$2:$AZ$190,,MATCH(SUBSTITUTE(K$3,"Q","T"),Inputs!$B$2:$AZ$2,0)),Inputs!$B$2:$B$190,$B5)*Inputs!$D$1) -> 0 | L5: =IF(ISNA(SUMIFS(INDEX(Inputs!$B$2:$AZ$190,,MATCH(SUBSTITUTE(L$3,"Q","T"),Inputs!$B$2:$AZ$2,0)),Inputs!$B$2:$B$190,$B5)*Inputs!$D$1),"",SUMIFS(INDEX(Inputs!$B$2:$AZ$190,,MATCH(SUBSTITUTE(L$3,"Q","T"),Inputs!$B$2:$AZ$2,0)),Inputs!$B$2:$B$190,$B5)*Inputs!$D$1) -> 0 | M5: =IF(ISNA(SUMIFS(INDEX(Inputs!$B$2:$AZ$190,,MATCH(SUBSTITUTE(M$3,"Q","T"),Inputs!$B$2:$AZ$2,0)),Inputs!$B$2:$B$190,$B5)*Inputs!$D$1),"",SUMIFS(INDEX(Inputs!$B$2:$AZ$190,,MATCH(SUBSTITUTE(M$3,"Q","T"),Inputs!$B$2:$AZ$2,0)),Inputs!$B$2:$B$190,$B5)*Inputs!$D$1) -> 0 | N5: =M5 -> 0 | O5: =IF(ISNA(SUMIFS(INDEX(Inputs!$B$2:$AZ$190,,MATCH(SUBSTITUTE(O$3,"Q","T"),Inputs!$B$2:$AZ$2,0)),Inputs!$B$2:$B$190,$B5)*Inputs!$D$1),"",SUMIFS(INDEX(Inputs!$B$2:$AZ$190,,MATCH(SUBSTITUTE(O$3,"Q","T"),Inputs!$B$2:$AZ$2,0)),Inputs!$B$2:$B$190,$B5)*Inputs!$D$1) -> 0 | P5: =IF(ISNA(SUMIFS(INDEX(Inputs!$B$2:$AZ$190,,MATCH(SUBSTITUTE(P$3,"Q","T"),Inputs!$B$2:$AZ$2,0)),Inputs!$B$2:$B$190,$B5)*Inputs!$D$1),"",SUMIFS(INDEX(Inputs!$B$2:$AZ$190,,MATCH(SUBSTITUTE(P$3,"Q","T"),Inputs!$B$2:$AZ$2,0)),Inputs!$B$2:$B$190,$B5)*Inputs!$D$1) -> 0 | Q5: =IF(ISNA(SUMIFS(INDEX(Inputs!$B$2:$AZ$190,,MATCH(SUBSTITUTE(Q$3,"Q","T"),Inputs!$B$2:$AZ$2,0)),Inputs!$B$2:$B$190,$B5)*Inputs!$D$1),"",SUMIFS(INDEX(Inputs!$B$2:$AZ$190,,MATCH(SUBSTITUTE(Q$3,"Q","T"),Inputs!$B$2:$AZ$2,0)),Inputs!$B$2:$B$190,$B5)*Inputs!$D$1) -> 0 | R5: =IF(ISNA(SUMIFS(INDEX(Inputs!$B$2:$AZ$190,,MATCH(SUBSTITUTE(R$3,"Q","T"),Inputs!$B$2:$AZ$2,0)),Inputs!$B$2:$B$190,$B5)*Inputs!$D$1),"",SUMIFS(INDEX(Inputs!$B$2:$AZ$190,,MATCH(SUBSTITUTE(R$3,"Q","T"),Inputs!$B$2:$AZ$2,0)),Inputs!$B$2:$B$190,$B5)*Inputs!$D$1) -> 0 | S5: =R5 -> 0 | T5: =IF(ISNA(SUMIFS(INDEX(Inputs!$B$2:$AZ$190,,MATCH(SUBSTITUTE(T$3,"Q","T"),Inputs!$B$2:$AZ$2,0)),Inputs!$B$2:$B$190,$B5)*Inputs!$D$1),"",SUMIFS(INDEX(Inputs!$B$2:$AZ$190,,MATCH(SUBSTITUTE(T$3,"Q","T"),Inputs!$B$2:$AZ$2,0)),Inputs!$B$2:$B$190,$B5)*Inputs!$D$1) -> 0 | U5: =IF(ISNA(SUMIFS(INDEX(Inputs!$B$2:$AZ$190,,MATCH(SUBSTITUTE(U$3,"Q","T"),Inputs!$B$2:$AZ$2,0)),Inputs!$B$2:$B$190,$B5)*Inputs!$D$1),"",SUMIFS(INDEX(Inputs!$B$2:$AZ$190,,MATCH(SUBSTITUTE(U$3,"Q","T"),Inputs!$B$2:$AZ$2,0)),Inputs!$B$2:$B$190,$B5)*Inputs!$D$1) -> 0 | V5: =IF(ISNA(SUMIFS(INDEX(Inputs!$B$2:$AZ$190,,MATCH(SUBSTITUTE(V$3,"Q","T"),Inputs!$B$2:$AZ$2,0)),Inputs!$B$2:$B$190,$B5)*Inputs!$D$1),"",SUMIFS(INDEX(Inputs!$B$2:$AZ$190,,MATCH(SUBSTITUTE(V$3,"Q","T"),Inputs!$B$2:$AZ$2,0)),Inputs!$B$2:$B$190,$B5)*Inputs!$D$1) -> 0 | W5: =IF(ISNA(SUMIFS(INDEX(Inputs!$B$2:$AZ$190,,MATCH(SUBSTITUTE(W$3,"Q","T"),Inputs!$B$2:$AZ$2,0)),Inputs!$B$2:$B$190,$B5)*Inputs!$D$1),"",SUMIFS(INDEX(Inputs!$B$2:$AZ$190,,MATCH(SUBSTITUTE(W$3,"Q","T"),Inputs!$B$2:$AZ$2,0)),Inputs!$B$2:$B$190,$B5)*Inputs!$D$1) -> 0 | X5: =W5 -> 0 | Y5: =IF(ISNA(SUMIFS(INDEX(Inputs!$B$2:$AZ$190,,MATCH(SUBSTITUTE(Y$3,"Q","T"),Inputs!$B$2:$AZ$2,0)),Inputs!$B$2:$B$190,$B5)*Inputs!$D$1),"",SUMIFS(INDEX(Inputs!$B$2:$AZ$190,,MATCH(SUBSTITUTE(Y$3,"Q","T"),Inputs!$B$2:$AZ$2,0)),Inputs!$B$2:$B$190,$B5)*Inputs!$D$1) -> 0 | Z5: =IF(ISNA(SUMIFS(INDEX(Inputs!$B$2:$AZ$190,,MATCH(SUBSTITUTE(Z$3,"Q","T"),Inputs!$B$2:$AZ$2,0)),Inputs!$B$2:$B$190,$B5)*Inputs!$D$1),"",SUMIFS(INDEX(Inputs!$B$2:$AZ$190,,MATCH(SUBSTITUTE(Z$3,"Q","T"),Inputs!$B$2:$AZ$2,0)),Inputs!$B$2:$B$190,$B5)*Inputs!$D$1) -> 0 | AA5: =IF(ISNA(SUMIFS(INDEX(Inputs!$B$2:$AZ$190,,MATCH(SUBSTITUTE(AA$3,"Q","T"),Inputs!$B$2:$AZ$2,0)),Inputs!$B$2:$B$190,$B5)*Inputs!$D$1),"",SUMIFS(INDEX(Inputs!$B$2:$AZ$190,,MATCH(SUBSTITUTE(AA$3,"Q","T"),Inputs!$B$2:$AZ$2,0)),Inputs!$B$2:$B$190,$B5)*Inputs!$D$1) -> 0 | AB5: =IF(ISNA(SUMIFS(INDEX(Inputs!$B$2:$AZ$190,,MATCH(SUBSTITUTE(AB$3,"Q","T"),Inputs!$B$2:$AZ$2,0)),Inputs!$B$2:$B$190,$B5)*Inputs!$D$1),"",SUMIFS(INDEX(Inputs!$B$2:$AZ$190,,MATCH(SUBSTITUTE(AB$3,"Q","T"),Inputs!$B$2:$AZ$2,0)),Inputs!$B$2:$B$190,$B5)*Inputs!$D$1) -> 0 | AC5: =AB5 -> 0 | AD5: =IF(ISNA(SUMIFS(INDEX(Inputs!$B$2:$AZ$190,,MATCH(SUBSTITUTE(AD$3,"Q","T"),Inputs!$B$2:$AZ$2,0)),Inputs!$B$2:$B$190,$B5)*Inputs!$D$1),"",SUMIFS(INDEX(Inputs!$B$2:$AZ$190,,MATCH(SUBSTITUTE(AD$3,"Q","T"),Inputs!$B$2:$AZ$2,0)),Inputs!$B$2:$B$190,$B5)*Inputs!$D$1) -> 0 | AE5: =IF(ISNA(SUMIFS(INDEX(Inputs!$B$2:$AZ$190,,MATCH(SUBSTITUTE(AE$3,"Q","T"),Inputs!$B$2:$AZ$2,0)),Inputs!$B$2:$B$190,$B5)*Inputs!$D$1),"",SUMIFS(INDEX(Inputs!$B$2:$AZ$190,,MATCH(SUBSTITUTE(AE$3,"Q","T"),Inputs!$B$2:$AZ$2,0)),Inputs!$B$2:$B$190,$B5)*Inputs!$D$1) -> 0 | AF5: =IF(ISNA(SUMIFS(INDEX(Inputs!$B$2:$AZ$190,,MATCH(SUBSTITUTE(AF$3,"Q","T"),Inputs!$B$2:$AZ$2,0)),Inputs!$B$2:$B$190,$B5)*Inputs!$D$1),"",SUMIFS(INDEX(Inputs!$B$2:$AZ$190,,MATCH(SUBSTITUTE(AF$3,"Q","T"),Inputs!$B$2:$AZ$2,0)),Inputs!$B$2:$B$190,$B5)*Inputs!$D$1) -> 0 | AG5: =IF(ISNA(SUMIFS(INDEX(Inputs!$B$2:$AZ$190,,MATCH(SUBSTITUTE(AG$3,"Q","T"),Inputs!$B$2:$AZ$2,0)),Inputs!$B$2:$B$190,$B5)*Inputs!$D$1),"",SUMIFS(INDEX(Inputs!$B$2:$AZ$190,,MATCH(SUBSTITUTE(AG$3,"Q","T"),Inputs!$B$2:$AZ$2,0)),Inputs!$B$2:$B$190,$B5)*Inputs!$D$1) -> 0 | AH5: =AG5 -> 0 | AI5: =IF(ISNA(SUMIFS(INDEX(Inputs!$B$2:$AZ$190,,MATCH(SUBSTITUTE(AI$3,"Q","T"),Inputs!$B$2:$AZ$2,0)),Inputs!$B$2:$B$190,$B5)*Inputs!$D$1),"",SUMIFS(INDEX(Inputs!$B$2:$AZ$190,,MATCH(SUBSTITUTE(AI$3,"Q","T"),Inputs!$B$2:$AZ$2,0)),Inputs!$B$2:$B$190,$B5)*Inputs!$D$1) -> 0 | AJ5: =IF(ISNA(SUMIFS(INDEX(Inputs!$B$2:$AZ$190,,MATCH(SUBSTITUTE(AJ$3,"Q","T"),Inputs!$B$2:$AZ$2,0)),Inputs!$B$2:$B$190,$B5)*Inputs!$D$1),"",SUMIFS(INDEX(Inputs!$B$2:$AZ$190,,MATCH(SUBSTITUTE(AJ$3,"Q","T"),Inputs!$B$2:$AZ$2,0)),Inputs!$B$2:$B$190,$B5)*Inputs!$D$1) -> 0 | AK5: =IF(ISNA(SUMIFS(INDEX(Inputs!$B$2:$AZ$190,,MATCH(SUBSTITUTE(AK$3,"Q","T"),Inputs!$B$2:$AZ$2,0)),Inputs!$B$2:$B$190,$B5)*Inputs!$D$1),"",SUMIFS(INDEX(Inputs!$B$2:$AZ$190,,MATCH(SUBSTITUTE(AK$3,"Q","T"),Inputs!$B$2:$AZ$2,0)),Inputs!$B$2:$B$190,$B5)*Inputs!$D$1) -> 0 | AL5: =IF(ISNA(SUMIFS(INDEX(Inputs!$B$2:$AZ$190,,MATCH(SUBSTITUTE(AL$3,"Q","T"),Inputs!$B$2:$AZ$2,0)),Inputs!$B$2:$B$190,$B5)*Inputs!$D$1),"",SUMIFS(INDEX(Inputs!$B$2:$AZ$190,,MATCH(SUBSTITUTE(AL$3,"Q","T"),Inputs!$B$2:$AZ$2,0)),Inputs!$B$2:$B$190,$B5)*Inputs!$D$1) -> 0 | AM5: =AL5 -> 0 | AN5: =IF(ISNA(SUMIFS(INDEX(Inputs!$B$2:$AZ$190,,MATCH(SUBSTITUTE(AN$3,"Q","T"),Inputs!$B$2:$AZ$2,0)),Inputs!$B$2:$B$190,$B5)*Inputs!$D$1),"",SUMIFS(INDEX(Inputs!$B$2:$AZ$190,,MATCH(SUBSTITUTE(AN$3,"Q","T"),Inputs!$B$2:$AZ$2,0)),Inputs!$B$2:$B$190,$B5)*Inputs!$D$1) -> 0 | AO5: =IF(ISNA(SUMIFS(INDEX(Inputs!$B$2:$AZ$190,,MATCH(SUBSTITUTE(AO$3,"Q","T"),Inputs!$B$2:$AZ$2,0)),Inputs!$B$2:$B$190,$B5)*Inputs!$D$1),"",SUMIFS(INDEX(Inputs!$B$2:$AZ$190,,MATCH(SUBSTITUTE(AO$3,"Q","T"),Inputs!$B$2:$AZ$2,0)),Inputs!$B$2:$B$190,$B5)*Inputs!$D$1) -> 0 | AP5: =IF(ISNA(SUMIFS(INDEX(Inputs!$B$2:$AZ$190,,MATCH(SUBSTITUTE(AP$3,"Q","T"),Inputs!$B$2:$AZ$2,0)),Inputs!$B$2:$B$190,$B5)*Inputs!$D$1),"",SUMIFS(INDEX(Inputs!$B$2:$AZ$190,,MATCH(SUBSTITUTE(AP$3,"Q","T"),Inputs!$B$2:$AZ$2,0)),Inputs!$B$2:$B$190,$B5)*Inputs!$D$1) -> 0 | AQ5: =IF(ISNA(SUMIFS(INDEX(Inputs!$B$2:$AZ$190,,MATCH(SUBSTITUTE(AQ$3,"Q","T"),Inputs!$B$2:$AZ$2,0)),Inputs!$B$2:$B$190,$B5)*Inputs!$D$1),"",SUMIFS(INDEX(Inputs!$B$2:$AZ$190,,MATCH(SUBSTITUTE(AQ$3,"Q","T"),Inputs!$B$2:$AZ$2,0)),Inputs!$B$2:$B$190,$B5)*Inputs!$D$1) -> 0 | AR5: =AQ5 -> 0 | AS5: =IF(ISNA(SUMIFS(INDEX(Inputs!$B$2:$AZ$190,,MATCH(SUBSTITUTE(AS$3,"Q","T"),Inputs!$B$2:$AZ$2,0)),Inputs!$B$2:$B$190,$B5)*Inputs!$D$1),"",SUMIFS(INDEX(Inputs!$B$2:$AZ$190,,MATCH(SUBSTITUTE(AS$3,"Q","T"),Inputs!$B$2:$AZ$2,0)),Inputs!$B$2:$B$190,$B5)*Inputs!$D$1) -> 0 | AT5: =IF(ISNA(SUMIFS(INDEX(Inputs!$B$2:$AZ$190,,MATCH(SUBSTITUTE(AT$3,"Q","T"),Inputs!$B$2:$AZ$2,0)),Inputs!$B$2:$B$190,$B5)*Inputs!$D$1),"",SUMIFS(INDEX(Inputs!$B$2:$AZ$190,,MATCH(SUBSTITUTE(AT$3,"Q","T"),Inputs!$B$2:$AZ$2,0)),Inputs!$B$2:$B$190,$B5)*Inputs!$D$1) -> 0 | AU5: =IF(ISNA(SUMIFS(INDEX(Inputs!$B$2:$AZ$190,,MATCH(SUBSTITUTE(AU$3,"Q","T"),Inputs!$B$2:$AZ$2,0)),Inputs!$B$2:$B$190,$B5)*Inputs!$D$1),"",SUMIFS(INDEX(Inputs!$B$2:$AZ$190,,MATCH(SUBSTITUTE(AU$3,"Q","T"),Inputs!$B$2:$AZ$2,0)),Inputs!$B$2:$B$190,$B5)*Inputs!$D$1) -> 0 | AV5: =IF(ISNA(SUMIFS(INDEX(Inputs!$B$2:$AZ$190,,MATCH(SUBSTITUTE(AV$3,"Q","T"),Inputs!$B$2:$AZ$2,0)),Inputs!$B$2:$B$190,$B5)*Inputs!$D$1),"",SUMIFS(INDEX(Inputs!$B$2:$AZ$190,,MATCH(SUBSTITUTE(AV$3,"Q","T"),Inputs!$B$2:$AZ$2,0)),Inputs!$B$2:$B$190,$B5)*Inputs!$D$1) -> 0 | AW5: =AV5 -> 0 | AX5: =IF(ISNA(SUMIFS(INDEX(Inputs!$B$2:$AZ$190,,MATCH(SUBSTITUTE(AX$3,"Q","T"),Inputs!$B$2:$AZ$2,0)),Inputs!$B$2:$B$190,$B5)*Inputs!$D$1),"",SUMIFS(INDEX(Inputs!$B$2:$AZ$190,,MATCH(SUBSTITUTE(AX$3,"Q","T"),Inputs!$B$2:$AZ$2,0)),Inputs!$B$2:$B$190,$B5)*Inputs!$D$1) -> 0 | AY5: =IF(ISNA(SUMIFS(INDEX(Inputs!$B$2:$AZ$190,,MATCH(SUBSTITUTE(AY$3,"Q","T"),Inputs!$B$2:$AZ$2,0)),Inputs!$B$2:$B$190,$B5)*Inputs!$D$1),"",SUMIFS(INDEX(Inputs!$B$2:$AZ$190,,MATCH(SUBSTITUTE(AY$3,"Q","T"),Inputs!$B$2:$AZ$2,0)),Inputs!$B$2:$B$190,$B5)*Inputs!$D$1) -> 0 | AZ5: =IF(ISNA(SUMIFS(INDEX(Inputs!$B$2:$AZ$190,,MATCH(SUBSTITUTE(AZ$3,"Q","T"),Inputs!$B$2:$AZ$2,0)),Inputs!$B$2:$B$190,$B5)*Inputs!$D$1),"",SUMIFS(INDEX(Inputs!$B$2:$AZ$190,,MATCH(SUBSTITUTE(AZ$3,"Q","T"),Inputs!$B$2:$AZ$2,0)),Inputs!$B$2:$B$190,$B5)*Inputs!$D$1) -> 0 | BA5: =IF(ISNA(SUMIFS(INDEX(Inputs!$B$2:$AZ$190,,MATCH(SUBSTITUTE(BA$3,"Q","T"),Inputs!$B$2:$AZ$2,0)),Inputs!$B$2:$B$190,$B5)*Inputs!$D$1),"",SUMIFS(INDEX(Inputs!$B$2:$AZ$190,,MATCH(SUBSTITUTE(BA$3,"Q","T"),Inputs!$B$2:$AZ$2,0)),Inputs!$B$2:$B$190,$B5)*Inputs!$D$1) -> 0 | BB5: =BA5 -> 0 | BC5: =IF(ISNA(SUMIFS(INDEX(Inputs!$B$2:$AZ$190,,MATCH(SUBSTITUTE(BC$3,"Q","T"),Inputs!$B$2:$AZ$2,0)),Inputs!$B$2:$B$190,$B5)*Inputs!$D$1),"",SUMIFS(INDEX(Inputs!$B$2:$AZ$190,,MATCH(SUBSTITUTE(BC$3,"Q","T"),Inputs!$B$2:$AZ$2,0)),Inputs!$B$2:$B$190,$B5)*Inputs!$D$1) -> 0 | BD5: =IF(ISNA(SUMIFS(INDEX(Inputs!$B$2:$AZ$190,,MATCH(SUBSTITUTE(BD$3,"Q","T"),Inputs!$B$2:$AZ$2,0)),Inputs!$B$2:$B$190,$B5)*Inputs!$D$1),"",SUMIFS(INDEX(Inputs!$B$2:$AZ$190,,MATCH(SUBSTITUTE(BD$3,"Q","T"),Inputs!$B$2:$AZ$2,0)),Inputs!$B$2:$B$190,$B5)*Inputs!$D$1) -> 0 | BE5: =IF(ISNA(SUMIFS(INDEX(Inputs!$B$2:$AZ$190,,MATCH(SUBSTITUTE(BE$3,"Q","T"),Inputs!$B$2:$AZ$2,0)),Inputs!$B$2:$B$190,$B5)*Inputs!$D$1),"",SUMIFS(INDEX(Inputs!$B$2:$AZ$190,,MATCH(SUBSTITUTE(BE$3,"Q","T"),Inputs!$B$2:$AZ$2,0)),Inputs!$B$2:$B$190,$B5)*Inputs!$D$1) -> 0 | BF5: =IF(ISNA(SUMIFS(INDEX(Inputs!$B$2:$AZ$190,,MATCH(SUBSTITUTE(BF$3,"Q","T"),Inputs!$B$2:$AZ$2,0)),Inputs!$B$2:$B$190,$B5)*Inputs!$D$1),"",SUMIFS(INDEX(Inputs!$B$2:$AZ$190,,MATCH(SUBSTITUTE(BF$3,"Q","T"),Inputs!$B$2:$AZ$2,0)),Inputs!$B$2:$B$190,$B5)*Inputs!$D$1) -> 0 | BG5: =BF5 -> 0
C6: Aplicações Interfinanceiras de Liquidez | D6: Interbank Investments | E6: =IFERROR(E7+E8+E9+E10,"") -> 0 | F6: =IFERROR(F7+F8+F9+F10,"") -> 0 | G6: =IFERROR(G7+G8+G9+G10,"") -> 0 | H6: =IFERROR(H7+H8+H9+H10,"") -> 0 | I6: =H6 -> 0 | J6: =IFERROR(J7+J8+J9+J10,"") -> 0 | K6: =IFERROR(K7+K8+K9+K10,"") -> 0 | L6: =IFERROR(L7+L8+L9+L10,"") -> 0 | M6: =IFERROR(M7+M8+M9+M10,"") -> 0 | N6: =M6 -> 0 | O6: =IFERROR(O7+O8+O9+O10,"") -> 0 | P6: =IFERROR(P7+P8+P9+P10,"") -> 0 | Q6: =IFERROR(Q7+Q8+Q9+Q10,"") -> 0 | R6: =IFERROR(R7+R8+R9+R10,"") -> 0 | S6: =R6 -> 0 | T6: =IFERROR(T7+T8+T9+T10,"") -> 0 | U6: =IFERROR(U7+U8+U9+U10,"") -> 0 | V6: =IFERROR(V7+V8+V9+V10,"") -> 0 | W6: =IFERROR(W7+W8+W9+W10,"") -> 0 | X6: =W6 -> 0 | Y6: =IFERROR(Y7+Y8+Y9+Y10,"") -> 0 | Z6: =IFERROR(Z7+Z8+Z9+Z10,"") -> 0 | AA6: =IFERROR(AA7+AA8+AA9+AA10,"") -> 0 | AB6: =IFERROR(AB7+AB8+AB9+AB10,"") -> 0 | AC6: =AB6 -> 0 | AD6: =IFERROR(AD7+AD8+AD9+AD10,"") -> 0 | AE6: =IFERROR(AE7+AE8+AE9+AE10,"") -> 0 | AF6: =IFERROR(AF7+AF8+AF9+AF10,"") -> 0 | AG6: =IFERROR(AG7+AG8+AG9+AG10,"") -> 0 | AH6: =AG6 -> 0 | AI6: =IFERROR(AI7+AI8+AI9+AI10,"") -> 0 | AJ6: =IFERROR(AJ7+AJ8+AJ9+AJ10,"") -> 0 | AK6: =IFERROR(AK7+AK8+AK9+AK10,"") -> 0 | AL6: =IFERROR(AL7+AL8+AL9+AL10,"") -> 0 | AM6: =AL6 -> 0 | AN6: =IFERROR(AN7+AN8+AN9+AN10,"") -> 0 | AO6: =IFERROR(AO7+AO8+AO9+AO10,"") -> 0 | AP6: =IFERROR(AP7+AP8+AP9+AP10,"") -> 0 | AQ6: =IFERROR(AQ7+AQ8+AQ9+AQ10,"") -> 0 | AR6: =AQ6 -> 0 | AS6: =IFERROR(AS7+AS8+AS9+AS10,"") -> 0 | AT6: =IFERROR(AT7+AT8+AT9+AT10,"") -> 0 | AU6: =IFERROR(AU7+AU8+AU9+AU10,"") -> 0 | AV6: =IFERROR(AV7+AV8+AV9+AV10,"") -> 0 | AW6: =AV6 -> 0 | AX6: =IFERROR(AX7+AX8+AX9+AX10,"") -> 0 | AY6: =IFERROR(AY7+AY8+AY9+AY10,"") -> 0 | AZ6: =IFERROR(AZ7+AZ8+AZ9+AZ10,"") -> 0 | BA6: =IFERROR(BA7+BA8+BA9+BA10,"") -> 0 | BB6: =BA6 -> 0 | BC6: =IFERROR(BC7+BC8+BC9+BC10,"") -> 0 | BD6: =IFERROR(BD7+BD8+BD9+BD10,"") -> 0 | BE6: =IFERROR(BE7+BE8+BE9+BE10,"") -> 0 | BF6: =IFERROR(BF7+BF8+BF9+BF10,"") -> 0 | BG6: =BF6 -> 0
B7: aplic_mo | C7: Aplicações no Mercado Aberto | D7: Open Market Investments | E7: =IF(ISNA(SUMIFS(INDEX(Inputs!$B$2:$AZ$190,,MATCH(SUBSTITUTE(E$3,"Q","T"),Inputs!$B$2:$AZ$2,0)),Inputs!$B$2:$B$190,$B7)*Inputs!$D$1),"",SUMIFS(INDEX(Inputs!$B$2:$AZ$190,,MATCH(SUBSTITUTE(E$3,"Q","T"),Inputs!$B$2:$AZ$2,0)),Inputs!$B$2:$B$190,$B7)*Inputs!$D$1) -> 0 | F7: =IF(ISNA(SUMIFS(INDEX(Inputs!$B$2:$AZ$190,,MATCH(SUBSTITUTE(F$3,"Q","T"),Inputs!$B$2:$AZ$2,0)),Inputs!$B$2:$B$190,$B7)*Inputs!$D$1),"",SUMIFS(INDEX(Inputs!$B$2:$AZ$190,,MATCH(SUBSTITUTE(F$3,"Q","T"),Inputs!$B$2:$AZ$2,0)),Inputs!$B$2:$B$190,$B7)*Inputs!$D$1) -> 0 | G7: =IF(ISNA(SUMIFS(INDEX(Inputs!$B$2:$AZ$190,,MATCH(SUBSTITUTE(G$3,"Q","T"),Inputs!$B$2:$AZ$2,0)),Inputs!$B$2:$B$190,$B7)*Inputs!$D$1),"",SUMIFS(INDEX(Inputs!$B$2:$AZ$190,,MATCH(SUBSTITUTE(G$3,"Q","T"),Inputs!$B$2:$AZ$2,0)),Inputs!$B$2:$B$190,$B7)*Inputs!$D$1) -> 0 | H7: =IF(ISNA(SUMIFS(INDEX(Inputs!$B$2:$AZ$190,,MATCH(SUBSTITUTE(H$3,"Q","T"),Inputs!$B$2:$AZ$2,0)),Inputs!$B$2:$B$190,$B7)*Inputs!$D$1),"",SUMIFS(INDEX(Inputs!$B$2:$AZ$190,,MATCH(SUBSTITUTE(H$3,"Q","T"),Inputs!$B$2:$AZ$2,0)),Inputs!$B$2:$B$190,$B7)*Inputs!$D$1) -> 0 | I7: =H7 -> 0 | J7: =IF(ISNA(SUMIFS(INDEX(Inputs!$B$2:$AZ$190,,MATCH(SUBSTITUTE(J$3,"Q","T"),Inputs!$B$2:$AZ$2,0)),Inputs!$B$2:$B$190,$B7)*Inputs!$D$1),"",SUMIFS(INDEX(Inputs!$B$2:$AZ$190,,MATCH(SUBSTITUTE(J$3,"Q","T"),Inputs!$B$2:$AZ$2,0)),Inputs!$B$2:$B$190,$B7)*Inputs!$D$1) -> 0 | K7: =IF(ISNA(SUMIFS(INDEX(Inputs!$B$2:$AZ$190,,MATCH(SUBSTITUTE(K$3,"Q","T"),Inputs!$B$2:$AZ$2,0)),Inputs!$B$2:$B$190,$B7)*Inputs!$D$1),"",SUMIFS(INDEX(Inputs!$B$2:$AZ$190,,MATCH(SUBSTITUTE(K$3,"Q","T"),Inputs!$B$2:$AZ$2,0)),Inputs!$B$2:$B$190,$B7)*Inputs!$D$1) -> 0 | L7: =IF(ISNA(SUMIFS(INDEX(Inputs!$B$2:$AZ$190,,MATCH(SUBSTITUTE(L$3,"Q","T"),Inputs!$B$2:$AZ$2,0)),Inputs!$B$2:$B$190,$B7)*Inputs!$D$1),"",SUMIFS(INDEX(Inputs!$B$2:$AZ$190,,MATCH(SUBSTITUTE(L$3,"Q","T"),Inputs!$B$2:$AZ$2,0)),Inputs!$B$2:$B$190,$B7)*Inputs!$D$1) -> 0 | M7: =IF(ISNA(SUMIFS(INDEX(Inputs!$B$2:$AZ$190,,MATCH(SUBSTITUTE(M$3,"Q","T"),Inputs!$B$2:$AZ$2,0)),Inputs!$B$2:$B$190,$B7)*Inputs!$D$1),"",SUMIFS(INDEX(Inputs!$B$2:$AZ$190,,MATCH(SUBSTITUTE(M$3,"Q","T"),Inputs!$B$2:$AZ$2,0)),Inputs!$B$2:$B$190,$B7)*Inputs!$D$1) -> 0 | N7: =M7 -> 0 | O7: =IF(ISNA(SUMIFS(INDEX(Inputs!$B$2:$AZ$190,,MATCH(SUBSTITUTE(O$3,"Q","T"),Inputs!$B$2:$AZ$2,0)),Inputs!$B$2:$B$190,$B7)*Inputs!$D$1),"",SUMIFS(INDEX(Inputs!$B$2:$AZ$190,,MATCH(SUBSTITUTE(O$3,"Q","T"),Inputs!$B$2:$AZ$2,0)),Inputs!$B$2:$B$190,$B7)*Inputs!$D$1) -> 0 | P7: =IF(ISNA(SUMIFS(INDEX(Inputs!$B$2:$AZ$190,,MATCH(SUBSTITUTE(P$3,"Q","T"),Inputs!$B$2:$AZ$2,0)),Inputs!$B$2:$B$190,$B7)*Inputs!$D$1),"",SUMIFS(INDEX(Inputs!$B$2:$AZ$190,,MATCH(SUBSTITUTE(P$3,"Q","T"),Inputs!$B$2:$AZ$2,0)),Inputs!$B$2:$B$190,$B7)*Inputs!$D$1) -> 0 | Q7: =IF(ISNA(SUMIFS(INDEX(Inputs!$B$2:$AZ$190,,MATCH(SUBSTITUTE(Q$3,"Q","T"),Inputs!$B$2:$AZ$2,0)),Inputs!$B$2:$B$190,$B7)*Inputs!$D$1),"",SUMIFS(INDEX(Inputs!$B$2:$AZ$190,,MATCH(SUBSTITUTE(Q$3,"Q","T"),Inputs!$B$2:$AZ$2,0)),Inputs!$B$2:$B$190,$B7)*Inputs!$D$1) -> 0 | R7: =IF(ISNA(SUMIFS(INDEX(Inputs!$B$2:$AZ$190,,MATCH(SUBSTITUTE(R$3,"Q","T"),Inputs!$B$2:$AZ$2,0)),Inputs!$B$2:$B$190,$B7)*Inputs!$D$1),"",SUMIFS(INDEX(Inputs!$B$2:$AZ$190,,MATCH(SUBSTITUTE(R$3,"Q","T"),Inputs!$B$2:$AZ$2,0)),Inputs!$B$2:$B$190,$B7)*Inputs!$D$1) -> 0 | S7: =R7 -> 0 | T7: =IF(ISNA(SUMIFS(INDEX(Inputs!$B$2:$AZ$190,,MATCH(SUBSTITUTE(T$3,"Q","T"),Inputs!$B$2:$AZ$2,0)),Inputs!$B$2:$B$190,$B7)*Inputs!$D$1),"",SUMIFS(INDEX(Inputs!$B$2:$AZ$190,,MATCH(SUBSTITUTE(T$3,"Q","T"),Inputs!$B$2:$AZ$2,0)),Inputs!$B$2:$B$190,$B7)*Inputs!$D$1) -> 0 | U7: =IF(ISNA(SUMIFS(INDEX(Inputs!$B$2:$AZ$190,,MATCH(SUBSTITUTE(U$3,"Q","T"),Inputs!$B$2:$AZ$2,0)),Inputs!$B$2:$B$190,$B7)*Inputs!$D$1),"",SUMIFS(INDEX(Inputs!$B$2:$AZ$190,,MATCH(SUBSTITUTE(U$3,"Q","T"),Inputs!$B$2:$AZ$2,0)),Inputs!$B$2:$B$190,$B7)*Inputs!$D$1) -> 0 | V7: =IF(ISNA(SUMIFS(INDEX(Inputs!$B$2:$AZ$190,,MATCH(SUBSTITUTE(V$3,"Q","T"),Inputs!$B$2:$AZ$2,0)),Inputs!$B$2:$B$190,$B7)*Inputs!$D$1),"",SUMIFS(INDEX(Inputs!$B$2:$AZ$190,,MATCH(SUBSTITUTE(V$3,"Q","T"),Inputs!$B$2:$AZ$2,0)),Inputs!$B$2:$B$190,$B7)*Inputs!$D$1) -> 0 | W7: =IF(ISNA(SUMIFS(INDEX(Inputs!$B$2:$AZ$190,,MATCH(SUBSTITUTE(W$3,"Q","T"),Inputs!$B$2:$AZ$2,0)),Inputs!$B$2:$B$190,$B7)*Inputs!$D$1),"",SUMIFS(INDEX(Inputs!$B$2:$AZ$190,,MATCH(SUBSTITUTE(W$3,"Q","T"),Inputs!$B$2:$AZ$2,0)),Inputs!$B$2:$B$190,$B7)*Inputs!$D$1) -> 0 | X7: =W7 -> 0 | Y7: =IF(ISNA(SUMIFS(INDEX(Inputs!$B$2:$AZ$190,,MATCH(SUBSTITUTE(Y$3,"Q","T"),Inputs!$B$2:$AZ$2,0)),Inputs!$B$2:$B$190,$B7)*Inputs!$D$1),"",SUMIFS(INDEX(Inputs!$B$2:$AZ$190,,MATCH(SUBSTITUTE(Y$3,"Q","T"),Inputs!$B$2:$AZ$2,0)),Inputs!$B$2:$B$190,$B7)*Inputs!$D$1) -> 0 | Z7: =IF(ISNA(SUMIFS(INDEX(Inputs!$B$2:$AZ$190,,MATCH(SUBSTITUTE(Z$3,"Q","T"),Inputs!$B$2:$AZ$2,0)),Inputs!$B$2:$B$190,$B7)*Inputs!$D$1),"",SUMIFS(INDEX(Inputs!$B$2:$AZ$190,,MATCH(SUBSTITUTE(Z$3,"Q","T"),Inputs!$B$2:$AZ$2,0)),Inputs!$B$2:$B$190,$B7)*Inputs!$D$1) -> 0 | AA7: =IF(ISNA(SUMIFS(INDEX(Inputs!$B$2:$AZ$190,,MATCH(SUBSTITUTE(AA$3,"Q","T"),Inputs!$B$2:$AZ$2,0)),Inputs!$B$2:$B$190,$B7)*Inputs!$D$1),"",SUMIFS(INDEX(Inputs!$B$2:$AZ$190,,MATCH(SUBSTITUTE(AA$3,"Q","T"),Inputs!$B$2:$AZ$2,0)),Inputs!$B$2:$B$190,$B7)*Inputs!$D$1) -> 0 | AB7: =IF(ISNA(SUMIFS(INDEX(Inputs!$B$2:$AZ$190,,MATCH(SUBSTITUTE(AB$3,"Q","T"),Inputs!$B$2:$AZ$2,0)),Inputs!$B$2:$B$190,$B7)*Inputs!$D$1),"",SUMIFS(INDEX(Inputs!$B$2:$AZ$190,,MATCH(SUBSTITUTE(AB$3,"Q","T"),Inputs!$B$2:$AZ$2,0)),Inputs!$B$2:$B$190,$B7)*Inputs!$D$1) -> 0 | AC7: =AB7 -> 0 | AD7: =IF(ISNA(SUMIFS(INDEX(Inputs!$B$2:$AZ$190,,MATCH(SUBSTITUTE(AD$3,"Q","T"),Inputs!$B$2:$AZ$2,0)),Inputs!$B$2:$B$190,$B7)*Inputs!$D$1),"",SUMIFS(INDEX(Inputs!$B$2:$AZ$190,,MATCH(SUBSTITUTE(AD$3,"Q","T"),Inputs!$B$2:$AZ$2,0)),Inputs!$B$2:$B$190,$B7)*Inputs!$D$1) -> 0 | AE7: =IF(ISNA(SUMIFS(INDEX(Inputs!$B$2:$AZ$190,,MATCH(SUBSTITUTE(AE$3,"Q","T"),Inputs!$B$2:$AZ$2,0)),Inputs!$B$2:$B$190,$B7)*Inputs!$D$1),"",SUMIFS(INDEX(Inputs!$B$2:$AZ$190,,MATCH(SUBSTITUTE(AE$3,"Q","T"),Inputs!$B$2:$AZ$2,0)),Inputs!$B$2:$B$190,$B7)*Inputs!$D$1) -> 0 | AF7: =IF(ISNA(SUMIFS(INDEX(Inputs!$B$2:$AZ$190,,MATCH(SUBSTITUTE(AF$3,"Q","T"),Inputs!$B$2:$AZ$2,0)),Inputs!$B$2:$B$190,$B7)*Inputs!$D$1),"",SUMIFS(INDEX(Inputs!$B$2:$AZ$190,,MATCH(SUBSTITUTE(AF$3,"Q","T"),Inputs!$B$2:$AZ$2,0)),Inputs!$B$2:$B$190,$B7)*Inputs!$D$1) -> 0 | AG7: =IF(ISNA(SUMIFS(INDEX(Inputs!$B$2:$AZ$190,,MATCH(SUBSTITUTE(AG$3,"Q","T"),Inputs!$B$2:$AZ$2,0)),Inputs!$B$2:$B$190,$B7)*Inputs!$D$1),"",SUMIFS(INDEX(Inputs!$B$2:$AZ$190,,MATCH(SUBSTITUTE(AG$3,"Q","T"),Inputs!$B$2:$AZ$2,0)),Inputs!$B$2:$B$190,$B7)*Inputs!$D$1) -> 0 | AH7: =AG7 -> 0 | AI7: =IF(ISNA(SUMIFS(INDEX(Inputs!$B$2:$AZ$190,,MATCH(SUBSTITUTE(AI$3,"Q","T"),Inputs!$B$2:$AZ$2,0)),Inputs!$B$2:$B$190,$B7)*Inputs!$D$1),"",SUMIFS(INDEX(Inputs!$B$2:$AZ$190,,MATCH(SUBSTITUTE(AI$3,"Q","T"),Inputs!$B$2:$AZ$2,0)),Inputs!$B$2:$B$190,$B7)*Inputs!$D$1) -> 0 | AJ7: =IF(ISNA(SUMIFS(INDEX(Inputs!$B$2:$AZ$190,,MATCH(SUBSTITUTE(AJ$3,"Q","T"),Inputs!$B$2:$AZ$2,0)),Inputs!$B$2:$B$190,$B7)*Inputs!$D$1),"",SUMIFS(INDEX(Inputs!$B$2:$AZ$190,,MATCH(SUBSTITUTE(AJ$3,"Q","T"),Inputs!$B$2:$AZ$2,0)),Inputs!$B$2:$B$190,$B7)*Inputs!$D$1) -> 0 | AK7: =IF(ISNA(SUMIFS(INDEX(Inputs!$B$2:$AZ$190,,MATCH(SUBSTITUTE(AK$3,"Q","T"),Inputs!$B$2:$AZ$2,0)),Inputs!$B$2:$B$190,$B7)*Inputs!$D$1),"",SUMIFS(INDEX(Inputs!$B$2:$AZ$190,,MATCH(SUBSTITUTE(AK$3,"Q","T"),Inputs!$B$2:$AZ$2,0)),Inputs!$B$2:$B$190,$B7)*Inputs!$D$1) -> 0 | AL7: =IF(ISNA(SUMIFS(INDEX(Inputs!$B$2:$AZ$190,,MATCH(SUBSTITUTE(AL$3,"Q","T"),Inputs!$B$2:$AZ$2,0)),Inputs!$B$2:$B$190,$B7)*Inputs!$D$1),"",SUMIFS(INDEX(Inputs!$B$2:$AZ$190,,MATCH(SUBSTITUTE(AL$3,"Q","T"),Inputs!$B$2:$AZ$2,0)),Inputs!$B$2:$B$190,$B7)*Inputs!$D$1) -> 0 | AM7: =AL7 -> 0 | AN7: =IF(ISNA(SUMIFS(INDEX(Inputs!$B$2:$AZ$190,,MATCH(SUBSTITUTE(AN$3,"Q","T"),Inputs!$B$2:$AZ$2,0)),Inputs!$B$2:$B$190,$B7)*Inputs!$D$1),"",SUMIFS(INDEX(Inputs!$B$2:$AZ$190,,MATCH(SUBSTITUTE(AN$3,"Q","T"),Inputs!$B$2:$AZ$2,0)),Inputs!$B$2:$B$190,$B7)*Inputs!$D$1) -> 0 | AO7: =IF(ISNA(SUMIFS(INDEX(Inputs!$B$2:$AZ$190,,MATCH(SUBSTITUTE(AO$3,"Q","T"),Inputs!$B$2:$AZ$2,0)),Inputs!$B$2:$B$190,$B7)*Inputs!$D$1),"",SUMIFS(INDEX(Inputs!$B$2:$AZ$190,,MATCH(SUBSTITUTE(AO$3,"Q","T"),Inputs!$B$2:$AZ$2,0)),Inputs!$B$2:$B$190,$B7)*Inputs!$D$1) -> 0 | AP7: =IF(ISNA(SUMIFS(INDEX(Inputs!$B$2:$AZ$190,,MATCH(SUBSTITUTE(AP$3,"Q","T"),Inputs!$B$2:$AZ$2,0)),Inputs!$B$2:$B$190,$B7)*Inputs!$D$1),"",SUMIFS(INDEX(Inputs!$B$2:$AZ$190,,MATCH(SUBSTITUTE(AP$3,"Q","T"),Inputs!$B$2:$AZ$2,0)),Inputs!$B$2:$B$190,$B7)*Inputs!$D$1) -> 0 | AQ7: =IF(ISNA(SUMIFS(INDEX(Inputs!$B$2:$AZ$190,,MATCH(SUBSTITUTE(AQ$3,"Q","T"),Inputs!$B$2:$AZ$2,0)),Inputs!$B$2:$B$190,$B7)*Inputs!$D$1),"",SUMIFS(INDEX(Inputs!$B$2:$AZ$190,,MATCH(SUBSTITUTE(AQ$3,"Q","T"),Inputs!$B$2:$AZ$2,0)),Inputs!$B$2:$B$190,$B7)*Inputs!$D$1) -> 0 | AR7: =AQ7 -> 0 | AS7: =IF(ISNA(SUMIFS(INDEX(Inputs!$B$2:$AZ$190,,MATCH(SUBSTITUTE(AS$3,"Q","T"),Inputs!$B$2:$AZ$2,0)),Inputs!$B$2:$B$190,$B7)*Inputs!$D$1),"",SUMIFS(INDEX(Inputs!$B$2:$AZ$190,,MATCH(SUBSTITUTE(AS$3,"Q","T"),Inputs!$B$2:$AZ$2,0)),Inputs!$B$2:$B$190,$B7)*Inputs!$D$1) -> 0 | AT7: =IF(ISNA(SUMIFS(INDEX(Inputs!$B$2:$AZ$190,,MATCH(SUBSTITUTE(AT$3,"Q","T"),Inputs!$B$2:$AZ$2,0)),Inputs!$B$2:$B$190,$B7)*Inputs!$D$1),"",SUMIFS(INDEX(Inputs!$B$2:$AZ$190,,MATCH(SUBSTITUTE(AT$3,"Q","T"),Inputs!$B$2:$AZ$2,0)),Inputs!$B$2:$B$190,$B7)*Inputs!$D$1) -> 0 | AU7: =IF(ISNA(SUMIFS(INDEX(Inputs!$B$2:$AZ$190,,MATCH(SUBSTITUTE(AU$3,"Q","T"),Inputs!$B$2:$AZ$2,0)),Inputs!$B$2:$B$190,$B7)*Inputs!$D$1),"",SUMIFS(INDEX(Inputs!$B$2:$AZ$190,,MATCH(SUBSTITUTE(AU$3,"Q","T"),Inputs!$B$2:$AZ$2,0)),Inputs!$B$2:$B$190,$B7)*Inputs!$D$1) -> 0 | AV7: =IF(ISNA(SUMIFS(INDEX(Inputs!$B$2:$AZ$190,,MATCH(SUBSTITUTE(AV$3,"Q","T"),Inputs!$B$2:$AZ$2,0)),Inputs!$B$2:$B$190,$B7)*Inputs!$D$1),"",SUMIFS(INDEX(Inputs!$B$2:$AZ$190,,MATCH(SUBSTITUTE(AV$3,"Q","T"),Inputs!$B$2:$AZ$2,0)),Inputs!$B$2:$B$190,$B7)*Inputs!$D$1) -> 0 | AW7: =AV7 -> 0 | AX7: =IF(ISNA(SUMIFS(INDEX(Inputs!$B$2:$AZ$190,,MATCH(SUBSTITUTE(AX$3,"Q","T"),Inputs!$B$2:$AZ$2,0)),Inputs!$B$2:$B$190,$B7)*Inputs!$D$1),"",SUMIFS(INDEX(Inputs!$B$2:$AZ$190,,MATCH(SUBSTITUTE(AX$3,"Q","T"),Inputs!$B$2:$AZ$2,0)),Inputs!$B$2:$B$190,$B7)*Inputs!$D$1) -> 0 | AY7: =IF(ISNA(SUMIFS(INDEX(Inputs!$B$2:$AZ$190,,MATCH(SUBSTITUTE(AY$3,"Q","T"),Inputs!$B$2:$AZ$2,0)),Inputs!$B$2:$B$190,$B7)*Inputs!$D$1),"",SUMIFS(INDEX(Inputs!$B$2:$AZ$190,,MATCH(SUBSTITUTE(AY$3,"Q","T"),Inputs!$B$2:$AZ$2,0)),Inputs!$B$2:$B$190,$B7)*Inputs!$D$1) -> 0 | AZ7: =IF(ISNA(SUMIFS(INDEX(Inputs!$B$2:$AZ$190,,MATCH(SUBSTITUTE(AZ$3,"Q","T"),Inputs!$B$2:$AZ$2,0)),Inputs!$B$2:$B$190,$B7)*Inputs!$D$1),"",SUMIFS(INDEX(Inputs!$B$2:$AZ$190,,MATCH(SUBSTITUTE(AZ$3,"Q","T"),Inputs!$B$2:$AZ$2,0)),Inputs!$B$2:$B$190,$B7)*Inputs!$D$1) -> 0 | BA7: =IF(ISNA(SUMIFS(INDEX(Inputs!$B$2:$AZ$190,,MATCH(SUBSTITUTE(BA$3,"Q","T"),Inputs!$B$2:$AZ$2,0)),Inputs!$B$2:$B$190,$B7)*Inputs!$D$1),"",SUMIFS(INDEX(Inputs!$B$2:$AZ$190,,MATCH(SUBSTITUTE(BA$3,"Q","T"),Inputs!$B$2:$AZ$2,0)),Inputs!$B$2:$B$190,$B7)*Inputs!$D$1) -> 0 | BB7: =BA7 -> 0 | BC7: =IF(ISNA(SUMIFS(INDEX(Inputs!$B$2:$AZ$190,,MATCH(SUBSTITUTE(BC$3,"Q","T"),Inputs!$B$2:$AZ$2,0)),Inputs!$B$2:$B$190,$B7)*Inputs!$D$1),"",SUMIFS(INDEX(Inputs!$B$2:$AZ$190,,MATCH(SUBSTITUTE(BC$3,"Q","T"),Inputs!$B$2:$AZ$2,0)),Inputs!$B$2:$B$190,$B7)*Inputs!$D$1) -> 0 | BD7: =IF(ISNA(SUMIFS(INDEX(Inputs!$B$2:$AZ$190,,MATCH(SUBSTITUTE(BD$3,"Q","T"),Inputs!$B$2:$AZ$2,0)),Inputs!$B$2:$B$190,$B7)*Inputs!$D$1),"",SUMIFS(INDEX(Inputs!$B$2:$AZ$190,,MATCH(SUBSTITUTE(BD$3,"Q","T"),Inputs!$B$2:$AZ$2,0)),Inputs!$B$2:$B$190,$B7)*Inputs!$D$1) -> 0 | BE7: =IF(ISNA(SUMIFS(INDEX(Inputs!$B$2:$AZ$190,,MATCH(SUBSTITUTE(BE$3,"Q","T"),Inputs!$B$2:$AZ$2,0)),Inputs!$B$2:$B$190,$B7)*Inputs!$D$1),"",SUMIFS(INDEX(Inputs!$B$2:$AZ$190,,MATCH(SUBSTITUTE(BE$3,"Q","T"),Inputs!$B$2:$AZ$2,0)),Inputs!$B$2:$B$190,$B7)*Inputs!$D$1) -> 0 | BF7: =IF(ISNA(SUMIFS(INDEX(Inputs!$B$2:$AZ$190,,MATCH(SUBSTITUTE(BF$3,"Q","T"),Inputs!$B$2:$AZ$2,0)),Inputs!$B$2:$B$190,$B7)*Inputs!$D$1),"",SUMIFS(INDEX(Inputs!$B$2:$AZ$190,,MATCH(SUBSTITUTE(BF$3,"Q","T"),Inputs!$B$2:$AZ$2,0)),Inputs!$B$2:$B$190,$B7)*Inputs!$D$1) -> 0 | BG7: =BF7 -> 0
B8: aplic_di | C8: Aplicações em Depósitos Interfinanceiros | D8: Interbank Deposits | E8: =IF(ISNA(SUMIFS(INDEX(Inputs!$B$2:$AZ$190,,MATCH(SUBSTITUTE(E$3,"Q","T"),Inputs!$B$2:$AZ$2,0)),Inputs!$B$2:$B$190,$B8)*Inputs!$D$1),"",SUMIFS(INDEX(Inputs!$B$2:$AZ$190,,MATCH(SUBSTITUTE(E$3,"Q","T"),Inputs!$B$2:$AZ$2,0)),Inputs!$B$2:$B$190,$B8)*Inputs!$D$1) -> 0 | F8: =IF(ISNA(SUMIFS(INDEX(Inputs!$B$2:$AZ$190,,MATCH(SUBSTITUTE(F$3,"Q","T"),Inputs!$B$2:$AZ$2,0)),Inputs!$B$2:$B$190,$B8)*Inputs!$D$1),"",SUMIFS(INDEX(Inputs!$B$2:$AZ$190,,MATCH(SUBSTITUTE(F$3,"Q","T"),Inputs!$B$2:$AZ$2,0)),Inputs!$B$2:$B$190,$B8)*Inputs!$D$1) -> 0 | G8: =IF(ISNA(SUMIFS(INDEX(Inputs!$B$2:$AZ$190,,MATCH(SUBSTITUTE(G$3,"Q","T"),Inputs!$B$2:$AZ$2,0)),Inputs!$B$2:$B$190,$B8)*Inputs!$D$1),"",SUMIFS(INDEX(Inputs!$B$2:$AZ$190,,MATCH(SUBSTITUTE(G$3,"Q","T"),Inputs!$B$2:$AZ$2,0)),Inputs!$B$2:$B$190,$B8)*Inputs!$D$1) -> 0 | H8: =IF(ISNA(SUMIFS(INDEX(Inputs!$B$2:$AZ$190,,MATCH(SUBSTITUTE(H$3,"Q","T"),Inputs!$B$2:$AZ$2,0)),Inputs!$B$2:$B$190,$B8)*Inputs!$D$1),"",SUMIFS(INDEX(Inputs!$B$2:$AZ$190,,MATCH(SUBSTITUTE(H$3,"Q","T"),Inputs!$B$2:$AZ$2,0)),Inputs!$B$2:$B$190,$B8)*Inputs!$D$1) -> 0 | I8: =H8 -> 0 | J8: =IF(ISNA(SUMIFS(INDEX(Inputs!$B$2:$AZ$190,,MATCH(SUBSTITUTE(J$3,"Q","T"),Inputs!$B$2:$AZ$2,0)),Inputs!$B$2:$B$190,$B8)*Inputs!$D$1),"",SUMIFS(INDEX(Inputs!$B$2:$AZ$190,,MATCH(SUBSTITUTE(J$3,"Q","T"),Inputs!$B$2:$AZ$2,0)),Inputs!$B$2:$B$190,$B8)*Inputs!$D$1) -> 0 | K8: =IF(ISNA(SUMIFS(INDEX(Inputs!$B$2:$AZ$190,,MATCH(SUBSTITUTE(K$3,"Q","T"),Inputs!$B$2:$AZ$2,0)),Inputs!$B$2:$B$190,$B8)*Inputs!$D$1),"",SUMIFS(INDEX(Inputs!$B$2:$AZ$190,,MATCH(SUBSTITUTE(K$3,"Q","T"),Inputs!$B$2:$AZ$2,0)),Inputs!$B$2:$B$190,$B8)*Inputs!$D$1) -> 0 | L8: =IF(ISNA(SUMIFS(INDEX(Inputs!$B$2:$AZ$190,,MATCH(SUBSTITUTE(L$3,"Q","T"),Inputs!$B$2:$AZ$2,0)),Inputs!$B$2:$B$190,$B8)*Inputs!$D$1),"",SUMIFS(INDEX(Inputs!$B$2:$AZ$190,,MATCH(SUBSTITUTE(L$3,"Q","T"),Inputs!$B$2:$AZ$2,0)),Inputs!$B$2:$B$190,$B8)*Inputs!$D$1) -> 0 | M8: =IF(ISNA(SUMIFS(INDEX(Inputs!$B$2:$AZ$190,,MATCH(SUBSTITUTE(M$3,"Q","T"),Inputs!$B$2:$AZ$2,0)),Inputs!$B$2:$B$190,$B8)*Inputs!$D$1),"",SUMIFS(INDEX(Inputs!$B$2:$AZ$190,,MATCH(SUBSTITUTE(M$3,"Q","T"),Inputs!$B$2:$AZ$2,0)),Inputs!$B$2:$B$190,$B8)*Inputs!$D$1) -> 0 | N8: =M8 -> 0 | O8: =IF(ISNA(SUMIFS(INDEX(Inputs!$B$2:$AZ$190,,MATCH(SUBSTITUTE(O$3,"Q","T"),Inputs!$B$2:$AZ$2,0)),Inputs!$B$2:$B$190,$B8)*Inputs!$D$1),"",SUMIFS(INDEX(Inputs!$B$2:$AZ$190,,MATCH(SUBSTITUTE(O$3,"Q","T"),Inputs!$B$2:$AZ$2,0)),Inputs!$B$2:$B$190,$B8)*Inputs!$D$1) -> 0 | P8: =IF(ISNA(SUMIFS(INDEX(Inputs!$B$2:$AZ$190,,MATCH(SUBSTITUTE(P$3,"Q","T"),Inputs!$B$2:$AZ$2,0)),Inputs!$B$2:$B$190,$B8)*Inputs!$D$1),"",SUMIFS(INDEX(Inputs!$B$2:$AZ$190,,MATCH(SUBSTITUTE(P$3,"Q","T"),Inputs!$B$2:$AZ$2,0)),Inputs!$B$2:$B$190,$B8)*Inputs!$D$1) -> 0 | Q8: =IF(ISNA(SUMIFS(INDEX(Inputs!$B$2:$AZ$190,,MATCH(SUBSTITUTE(Q$3,"Q","T"),Inputs!$B$2:$AZ$2,0)),Inputs!$B$2:$B$190,$B8)*Inputs!$D$1),"",SUMIFS(INDEX(Inputs!$B$2:$AZ$190,,MATCH(SUBSTITUTE(Q$3,"Q","T"),Inputs!$B$2:$AZ$2,0)),Inputs!$B$2:$B$190,$B8)*Inputs!$D$1) -> 0 | R8: =IF(ISNA(SUMIFS(INDEX(Inputs!$B$2:$AZ$190,,MATCH(SUBSTITUTE(R$3,"Q","T"),Inputs!$B$2:$AZ$2,0)),Inputs!$B$2:$B$190,$B8)*Inputs!$D$1),"",SUMIFS(INDEX(Inputs!$B$2:$AZ$190,,MATCH(SUBSTITUTE(R$3,"Q","T"),Inputs!$B$2:$AZ$2,0)),Inputs!$B$2:$B$190,$B8)*Inputs!$D$1) -> 0 | S8: =R8 -> 0 | T8: =IF(ISNA(SUMIFS(INDEX(Inputs!$B$2:$AZ$190,,MATCH(SUBSTITUTE(T$3,"Q","T"),Inputs!$B$2:$AZ$2,0)),Inputs!$B$2:$B$190,$B8)*Inputs!$D$1),"",SUMIFS(INDEX(Inputs!$B$2:$AZ$190,,MATCH(SUBSTITUTE(T$3,"Q","T"),Inputs!$B$2:$AZ$2,0)),Inputs!$B$2:$B$190,$B8)*Inputs!$D$1) -> 0 | U8: =IF(ISNA(SUMIFS(INDEX(Inputs!$B$2:$AZ$190,,MATCH(SUBSTITUTE(U$3,"Q","T"),Inputs!$B$2:$AZ$2,0)),Inputs!$B$2:$B$190,$B8)*Inputs!$D$1),"",SUMIFS(INDEX(Inputs!$B$2:$AZ$190,,MATCH(SUBSTITUTE(U$3,"Q","T"),Inputs!$B$2:$AZ$2,0)),Inputs!$B$2:$B$190,$B8)*Inputs!$D$1) -> 0 | V8: =IF(ISNA(SUMIFS(INDEX(Inputs!$B$2:$AZ$190,,MATCH(SUBSTITUTE(V$3,"Q","T"),Inputs!$B$2:$AZ$2,0)),Inputs!$B$2:$B$190,$B8)*Inputs!$D$1),"",SUMIFS(INDEX(Inputs!$B$2:$AZ$190,,MATCH(SUBSTITUTE(V$3,"Q","T"),Inputs!$B$2:$AZ$2,0)),Inputs!$B$2:$B$190,$B8)*Inputs!$D$1) -> 0 | W8: =IF(ISNA(SUMIFS(INDEX(Inputs!$B$2:$AZ$190,,MATCH(SUBSTITUTE(W$3,"Q","T"),Inputs!$B$2:$AZ$2,0)),Inputs!$B$2:$B$190,$B8)*Inputs!$D$1),"",SUMIFS(INDEX(Inputs!$B$2:$AZ$190,,MATCH(SUBSTITUTE(W$3,"Q","T"),Inputs!$B$2:$AZ$2,0)),Inputs!$B$2:$B$190,$B8)*Inputs!$D$1) -> 0 | X8: =W8 -> 0 | Y8: =IF(ISNA(SUMIFS(INDEX(Inputs!$B$2:$AZ$190,,MATCH(SUBSTITUTE(Y$3,"Q","T"),Inputs!$B$2:$AZ$2,0)),Inputs!$B$2:$B$190,$B8)*Inputs!$D$1),"",SUMIFS(INDEX(Inputs!$B$2:$AZ$190,,MATCH(SUBSTITUTE(Y$3,"Q","T"),Inputs!$B$2:$AZ$2,0)),Inputs!$B$2:$B$190,$B8)*Inputs!$D$1) -> 0 | Z8: =IF(ISNA(SUMIFS(INDEX(Inputs!$B$2:$AZ$190,,MATCH(SUBSTITUTE(Z$3,"Q","T"),Inputs!$B$2:$AZ$2,0)),Inputs!$B$2:$B$190,$B8)*Inputs!$D$1),"",SUMIFS(INDEX(Inputs!$B$2:$AZ$190,,MATCH(SUBSTITUTE(Z$3,"Q","T"),Inputs!$B$2:$AZ$2,0)),Inputs!$B$2:$B$190,$B8)*Inputs!$D$1) -> 0 | AA8: =IF(ISNA(SUMIFS(INDEX(Inputs!$B$2:$AZ$190,,MATCH(SUBSTITUTE(AA$3,"Q","T"),Inputs!$B$2:$AZ$2,0)),Inputs!$B$2:$B$190,$B8)*Inputs!$D$1),"",SUMIFS(INDEX(Inputs!$B$2:$AZ$190,,MATCH(SUBSTITUTE(AA$3,"Q","T"),Inputs!$B$2:$AZ$2,0)),Inputs!$B$2:$B$190,$B8)*Inputs!$D$1) -> 0 | AB8: =IF(ISNA(SUMIFS(INDEX(Inputs!$B$2:$AZ$190,,MATCH(SUBSTITUTE(AB$3,"Q","T"),Inputs!$B$2:$AZ$2,0)),Inputs!$B$2:$B$190,$B8)*Inputs!$D$1),"",SUMIFS(INDEX(Inputs!$B$2:$AZ$190,,MATCH(SUBSTITUTE(AB$3,"Q","T"),Inputs!$B$2:$AZ$2,0)),Inputs!$B$2:$B$190,$B8)*Inputs!$D$1) -> 0 | AC8: =AB8 -> 0 | AD8: =IF(ISNA(SUMIFS(INDEX(Inputs!$B$2:$AZ$190,,MATCH(SUBSTITUTE(AD$3,"Q","T"),Inputs!$B$2:$AZ$2,0)),Inputs!$B$2:$B$190,$B8)*Inputs!$D$1),"",SUMIFS(INDEX(Inputs!$B$2:$AZ$190,,MATCH(SUBSTITUTE(AD$3,"Q","T"),Inputs!$B$2:$AZ$2,0)),Inputs!$B$2:$B$190,$B8)*Inputs!$D$1) -> 0 | AE8: =IF(ISNA(SUMIFS(INDEX(Inputs!$B$2:$AZ$190,,MATCH(SUBSTITUTE(AE$3,"Q","T"),Inputs!$B$2:$AZ$2,0)),Inputs!$B$2:$B$190,$B8)*Inputs!$D$1),"",SUMIFS(INDEX(Inputs!$B$2:$AZ$190,,MATCH(SUBSTITUTE(AE$3,"Q","T"),Inputs!$B$2:$AZ$2,0)),Inputs!$B$2:$B$190,$B8)*Inputs!$D$1) -> 0 | AF8: =IF(ISNA(SUMIFS(INDEX(Inputs!$B$2:$AZ$190,,MATCH(SUBSTITUTE(AF$3,"Q","T"),Inputs!$B$2:$AZ$2,0)),Inputs!$B$2:$B$190,$B8)*Inputs!$D$1),"",SUMIFS(INDEX(Inputs!$B$2:$AZ$190,,MATCH(SUBSTITUTE(AF$3,"Q","T"),Inputs!$B$2:$AZ$2,0)),Inputs!$B$2:$B$190,$B8)*Inputs!$D$1) -> 0 | AG8: =IF(ISNA(SUMIFS(INDEX(Inputs!$B$2:$AZ$190,,MATCH(SUBSTITUTE(AG$3,"Q","T"),Inputs!$B$2:$AZ$2,0)),Inputs!$B$2:$B$190,$B8)*Inputs!$D$1),"",SUMIFS(INDEX(Inputs!$B$2:$AZ$190,,MATCH(SUBSTITUTE(AG$3,"Q","T"),Inputs!$B$2:$AZ$2,0)),Inputs!$B$2:$B$190,$B8)*Inputs!$D$1) -> 0 | AH8: =AG8 -> 0 | AI8: =IF(ISNA(SUMIFS(INDEX(Inputs!$B$2:$AZ$190,,MATCH(SUBSTITUTE(AI$3,"Q","T"),Inputs!$B$2:$AZ$2,0)),Inputs!$B$2:$B$190,$B8)*Inputs!$D$1),"",SUMIFS(INDEX(Inputs!$B$2:$AZ$190,,MATCH(SUBSTITUTE(AI$3,"Q","T"),Inputs!$B$2:$AZ$2,0)),Inputs!$B$2:$B$190,$B8)*Inputs!$D$1) -> 0 | AJ8: =IF(ISNA(SUMIFS(INDEX(Inputs!$B$2:$AZ$190,,MATCH(SUBSTITUTE(AJ$3,"Q","T"),Inputs!$B$2:$AZ$2,0)),Inputs!$B$2:$B$190,$B8)*Inputs!$D$1),"",SUMIFS(INDEX(Inputs!$B$2:$AZ$190,,MATCH(SUBSTITUTE(AJ$3,"Q","T"),Inputs!$B$2:$AZ$2,0)),Inputs!$B$2:$B$190,$B8)*Inputs!$D$1) -> 0 | AK8: =IF(ISNA(SUMIFS(INDEX(Inputs!$B$2:$AZ$190,,MATCH(SUBSTITUTE(AK$3,"Q","T"),Inputs!$B$2:$AZ$2,0)),Inputs!$B$2:$B$190,$B8)*Inputs!$D$1),"",SUMIFS(INDEX(Inputs!$B$2:$AZ$190,,MATCH(SUBSTITUTE(AK$3,"Q","T"),Inputs!$B$2:$AZ$2,0)),Inputs!$B$2:$B$190,$B8)*Inputs!$D$1) -> 0 | AL8: =IF(ISNA(SUMIFS(INDEX(Inputs!$B$2:$AZ$190,,MATCH(SUBSTITUTE(AL$3,"Q","T"),Inputs!$B$2:$AZ$2,0)),Inputs!$B$2:$B$190,$B8)*Inputs!$D$1),"",SUMIFS(INDEX(Inputs!$B$2:$AZ$190,,MATCH(SUBSTITUTE(AL$3,"Q","T"),Inputs!$B$2:$AZ$2,0)),Inputs!$B$2:$B$190,$B8)*Inputs!$D$1) -> 0 | AM8: =AL8 -> 0 | AN8: =IF(ISNA(SUMIFS(INDEX(Inputs!$B$2:$AZ$190,,MATCH(SUBSTITUTE(AN$3,"Q","T"),Inputs!$B$2:$AZ$2,0)),Inputs!$B$2:$B$190,$B8)*Inputs!$D$1),"",SUMIFS(INDEX(Inputs!$B$2:$AZ$190,,MATCH(SUBSTITUTE(AN$3,"Q","T"),Inputs!$B$2:$AZ$2,0)),Inputs!$B$2:$B$190,$B8)*Inputs!$D$1) -> 0 | AO8: =IF(ISNA(SUMIFS(INDEX(Inputs!$B$2:$AZ$190,,MATCH(SUBSTITUTE(AO$3,"Q","T"),Inputs!$B$2:$AZ$2,0)),Inputs!$B$2:$B$190,$B8)*Inputs!$D$1),"",SUMIFS(INDEX(Inputs!$B$2:$AZ$190,,MATCH(SUBSTITUTE(AO$3,"Q","T"),Inputs!$B$2:$AZ$2,0)),Inputs!$B$2:$B$190,$B8)*Inputs!$D$1) -> 0 | AP8: =IF(ISNA(SUMIFS(INDEX(Inputs!$B$2:$AZ$190,,MATCH(SUBSTITUTE(AP$3,"Q","T"),Inputs!$B$2:$AZ$2,0)),Inputs!$B$2:$B$190,$B8)*Inputs!$D$1),"",SUMIFS(INDEX(Inputs!$B$2:$AZ$190,,MATCH(SUBSTITUTE(AP$3,"Q","T"),Inputs!$B$2:$AZ$2,0)),Inputs!$B$2:$B$190,$B8)*Inputs!$D$1) -> 0 | AQ8: =IF(ISNA(SUMIFS(INDEX(Inputs!$B$2:$AZ$190,,MATCH(SUBSTITUTE(AQ$3,"Q","T"),Inputs!$B$2:$AZ$2,0)),Inputs!$B$2:$B$190,$B8)*Inputs!$D$1),"",SUMIFS(INDEX(Inputs!$B$2:$AZ$190,,MATCH(SUBSTITUTE(AQ$3,"Q","T"),Inputs!$B$2:$AZ$2,0)),Inputs!$B$2:$B$190,$B8)*Inputs!$D$1) -> 0 | AR8: =AQ8 -> 0 | AS8: =IF(ISNA(SUMIFS(INDEX(Inputs!$B$2:$AZ$190,,MATCH(SUBSTITUTE(AS$3,"Q","T"),Inputs!$B$2:$AZ$2,0)),Inputs!$B$2:$B$190,$B8)*Inputs!$D$1),"",SUMIFS(INDEX(Inputs!$B$2:$AZ$190,,MATCH(SUBSTITUTE(AS$3,"Q","T"),Inputs!$B$2:$AZ$2,0)),Inputs!$B$2:$B$190,$B8)*Inputs!$D$1) -> 0 | AT8: =IF(ISNA(SUMIFS(INDEX(Inputs!$B$2:$AZ$190,,MATCH(SUBSTITUTE(AT$3,"Q","T"),Inputs!$B$2:$AZ$2,0)),Inputs!$B$2:$B$190,$B8)*Inputs!$D$1),"",SUMIFS(INDEX(Inputs!$B$2:$AZ$190,,MATCH(SUBSTITUTE(AT$3,"Q","T"),Inputs!$B$2:$AZ$2,0)),Inputs!$B$2:$B$190,$B8)*Inputs!$D$1) -> 0 | AU8: =IF(ISNA(SUMIFS(INDEX(Inputs!$B$2:$AZ$190,,MATCH(SUBSTITUTE(AU$3,"Q","T"),Inputs!$B$2:$AZ$2,0)),Inputs!$B$2:$B$190,$B8)*Inputs!$D$1),"",SUMIFS(INDEX(Inputs!$B$2:$AZ$190,,MATCH(SUBSTITUTE(AU$3,"Q","T"),Inputs!$B$2:$AZ$2,0)),Inputs!$B$2:$B$190,$B8)*Inputs!$D$1) -> 0 | AV8: =IF(ISNA(SUMIFS(INDEX(Inputs!$B$2:$AZ$190,,MATCH(SUBSTITUTE(AV$3,"Q","T"),Inputs!$B$2:$AZ$2,0)),Inputs!$B$2:$B$190,$B8)*Inputs!$D$1),"",SUMIFS(INDEX(Inputs!$B$2:$AZ$190,,MATCH(SUBSTITUTE(AV$3,"Q","T"),Inputs!$B$2:$AZ$2,0)),Inputs!$B$2:$B$190,$B8)*Inputs!$D$1) -> 0 | AW8: =AV8 -> 0 | AX8: =IF(ISNA(SUMIFS(INDEX(Inputs!$B$2:$AZ$190,,MATCH(SUBSTITUTE(AX$3,"Q","T"),Inputs!$B$2:$AZ$2,0)),Inputs!$B$2:$B$190,$B8)*Inputs!$D$1),"",SUMIFS(INDEX(Inputs!$B$2:$AZ$190,,MATCH(SUBSTITUTE(AX$3,"Q","T"),Inputs!$B$2:$AZ$2,0)),Inputs!$B$2:$B$190,$B8)*Inputs!$D$1) -> 0 | AY8: =IF(ISNA(SUMIFS(INDEX(Inputs!$B$2:$AZ$190,,MATCH(SUBSTITUTE(AY$3,"Q","T"),Inputs!$B$2:$AZ$2,0)),Inputs!$B$2:$B$190,$B8)*Inputs!$D$1),"",SUMIFS(INDEX(Inputs!$B$2:$AZ$190,,MATCH(SUBSTITUTE(AY$3,"Q","T"),Inputs!$B$2:$AZ$2,0)),Inputs!$B$2:$B$190,$B8)*Inputs!$D$1) -> 0 | AZ8: =IF(ISNA(SUMIFS(INDEX(Inputs!$B$2:$AZ$190,,MATCH(SUBSTITUTE(AZ$3,"Q","T"),Inputs!$B$2:$AZ$2,0)),Inputs!$B$2:$B$190,$B8)*Inputs!$D$1),"",SUMIFS(INDEX(Inputs!$B$2:$AZ$190,,MATCH(SUBSTITUTE(AZ$3,"Q","T"),Inputs!$B$2:$AZ$2,0)),Inputs!$B$2:$B$190,$B8)*Inputs!$D$1) -> 0 | BA8: =IF(ISNA(SUMIFS(INDEX(Inputs!$B$2:$AZ$190,,MATCH(SUBSTITUTE(BA$3,"Q","T"),Inputs!$B$2:$AZ$2,0)),Inputs!$B$2:$B$190,$B8)*Inputs!$D$1),"",SUMIFS(INDEX(Inputs!$B$2:$AZ$190,,MATCH(SUBSTITUTE(BA$3,"Q","T"),Inputs!$B$2:$AZ$2,0)),Inputs!$B$2:$B$190,$B8)*Inputs!$D$1) -> 0 | BB8: =BA8 -> 0 | BC8: =IF(ISNA(SUMIFS(INDEX(Inputs!$B$2:$AZ$190,,MATCH(SUBSTITUTE(BC$3,"Q","T"),Inputs!$B$2:$AZ$2,0)),Inputs!$B$2:$B$190,$B8)*Inputs!$D$1),"",SUMIFS(INDEX(Inputs!$B$2:$AZ$190,,MATCH(SUBSTITUTE(BC$3,"Q","T"),Inputs!$B$2:$AZ$2,0)),Inputs!$B$2:$B$190,$B8)*Inputs!$D$1) -> 0 | BD8: =IF(ISNA(SUMIFS(INDEX(Inputs!$B$2:$AZ$190,,MATCH(SUBSTITUTE(BD$3,"Q","T"),Inputs!$B$2:$AZ$2,0)),Inputs!$B$2:$B$190,$B8)*Inputs!$D$1),"",SUMIFS(INDEX(Inputs!$B$2:$AZ$190,,MATCH(SUBSTITUTE(BD$3,"Q","T"),Inputs!$B$2:$AZ$2,0)),Inputs!$B$2:$B$190,$B8)*Inputs!$D$1) -> 0 | BE8: =IF(ISNA(SUMIFS(INDEX(Inputs!$B$2:$AZ$190,,MATCH(SUBSTITUTE(BE$3,"Q","T"),Inputs!$B$2:$AZ$2,0)),Inputs!$B$2:$B$190,$B8)*Inputs!$D$1),"",SUMIFS(INDEX(Inputs!$B$2:$AZ$190,,MATCH(SUBSTITUTE(BE$3,"Q","T"),Inputs!$B$2:$AZ$2,0)),Inputs!$B$2:$B$190,$B8)*Inputs!$D$1) -> 0 | BF8: =IF(ISNA(SUMIFS(INDEX(Inputs!$B$2:$AZ$190,,MATCH(SUBSTITUTE(BF$3,"Q","T"),Inputs!$B$2:$AZ$2,0)),Inputs!$B$2:$B$190,$B8)*Inputs!$D$1),"",SUMIFS(INDEX(Inputs!$B$2:$AZ$190,,MATCH(SUBSTITUTE(BF$3,"Q","T"),Inputs!$B$2:$AZ$2,0)),Inputs!$B$2:$B$190,$B8)*Inputs!$D$1) -> 0 | BG8: =BF8 -> 0
B9: aplic_rg | C9: Recursos Garantidores das Provisões Técnicas | D9: Assets Guaranteeing Technical Provisions | E9: =IF(ISNA(SUMIFS(INDEX(Inputs!$B$2:$AZ$190,,MATCH(SUBSTITUTE(E$3,"Q","T"),Inputs!$B$2:$AZ$2,0)),Inputs!$B$2:$B$190,$B9)*Inputs!$D$1),"",SUMIFS(INDEX(Inputs!$B$2:$AZ$190,,MATCH(SUBSTITUTE(E$3,"Q","T"),Inputs!$B$2:$AZ$2,0)),Inputs!$B$2:$B$190,$B9)*Inputs!$D$1) -> 0 | F9: =IF(ISNA(SUMIFS(INDEX(Inputs!$B$2:$AZ$190,,MATCH(SUBSTITUTE(F$3,"Q","T"),Inputs!$B$2:$AZ$2,0)),Inputs!$B$2:$B$190,$B9)*Inputs!$D$1),"",SUMIFS(INDEX(Inputs!$B$2:$AZ$190,,MATCH(SUBSTITUTE(F$3,"Q","T"),Inputs!$B$2:$AZ$2,0)),Inputs!$B$2:$B$190,$B9)*Inputs!$D$1) -> 0 | G9: =IF(ISNA(SUMIFS(INDEX(Inputs!$B$2:$AZ$190,,MATCH(SUBSTITUTE(G$3,"Q","T"),Inputs!$B$2:$AZ$2,0)),Inputs!$B$2:$B$190,$B9)*Inputs!$D$1),"",SUMIFS(INDEX(Inputs!$B$2:$AZ$190,,MATCH(SUBSTITUTE(G$3,"Q","T"),Inputs!$B$2:$AZ$2,0)),Inputs!$B$2:$B$190,$B9)*Inputs!$D$1) -> 0 | H9: =IF(ISNA(SUMIFS(INDEX(Inputs!$B$2:$AZ$190,,MATCH(SUBSTITUTE(H$3,"Q","T"),Inputs!$B$2:$AZ$2,0)),Inputs!$B$2:$B$190,$B9)*Inputs!$D$1),"",SUMIFS(INDEX(Inputs!$B$2:$AZ$190,,MATCH(SUBSTITUTE(H$3,"Q","T"),Inputs!$B$2:$AZ$2,0)),Inputs!$B$2:$B$190,$B9)*Inputs!$D$1) -> 0 | I9: =H9 -> 0 | J9: =IF(ISNA(SUMIFS(INDEX(Inputs!$B$2:$AZ$190,,MATCH(SUBSTITUTE(J$3,"Q","T"),Inputs!$B$2:$AZ$2,0)),Inputs!$B$2:$B$190,$B9)*Inputs!$D$1),"",SUMIFS(INDEX(Inputs!$B$2:$AZ$190,,MATCH(SUBSTITUTE(J$3,"Q","T"),Inputs!$B$2:$AZ$2,0)),Inputs!$B$2:$B$190,$B9)*Inputs!$D$1) -> 0 | K9: =IF(ISNA(SUMIFS(INDEX(Inputs!$B$2:$AZ$190,,MATCH(SUBSTITUTE(K$3,"Q","T"),Inputs!$B$2:$AZ$2,0)),Inputs!$B$2:$B$190,$B9)*Inputs!$D$1),"",SUMIFS(INDEX(Inputs!$B$2:$AZ$190,,MATCH(SUBSTITUTE(K$3,"Q","T"),Inputs!$B$2:$AZ$2,0)),Inputs!$B$2:$B$190,$B9)*Inputs!$D$1) -> 0 | L9: =IF(ISNA(SUMIFS(INDEX(Inputs!$B$2:$AZ$190,,MATCH(SUBSTITUTE(L$3,"Q","T"),Inputs!$B$2:$AZ$2,0)),Inputs!$B$2:$B$190,$B9)*Inputs!$D$1),"",SUMIFS(INDEX(Inputs!$B$2:$AZ$190,,MATCH(SUBSTITUTE(L$3,"Q","T"),Inputs!$B$2:$AZ$2,0)),Inputs!$B$2:$B$190,$B9)*Inputs!$D$1) -> 0 | M9: =IF(ISNA(SUMIFS(INDEX(Inputs!$B$2:$AZ$190,,MATCH(SUBSTITUTE(M$3,"Q","T"),Inputs!$B$2:$AZ$2,0)),Inputs!$B$2:$B$190,$B9)*Inputs!$D$1),"",SUMIFS(INDEX(Inputs!$B$2:$AZ$190,,MATCH(SUBSTITUTE(M$3,"Q","T"),Inputs!$B$2:$AZ$2,0)),Inputs!$B$2:$B$190,$B9)*Inputs!$D$1) -> 0 | N9: =M9 -> 0 | O9: =IF(ISNA(SUMIFS(INDEX(Inputs!$B$2:$AZ$190,,MATCH(SUBSTITUTE(O$3,"Q","T"),Inputs!$B$2:$AZ$2,0)),Inputs!$B$2:$B$190,$B9)*Inputs!$D$1),"",SUMIFS(INDEX(Inputs!$B$2:$AZ$190,,MATCH(SUBSTITUTE(O$3,"Q","T"),Inputs!$B$2:$AZ$2,0)),Inputs!$B$2:$B$190,$B9)*Inputs!$D$1) -> 0 | P9: =IF(ISNA(SUMIFS(INDEX(Inputs!$B$2:$AZ$190,,MATCH(SUBSTITUTE(P$3,"Q","T"),Inputs!$B$2:$AZ$2,0)),Inputs!$B$2:$B$190,$B9)*Inputs!$D$1),"",SUMIFS(INDEX(Inputs!$B$2:$AZ$190,,MATCH(SUBSTITUTE(P$3,"Q","T"),Inputs!$B$2:$AZ$2,0)),Inputs!$B$2:$B$190,$B9)*Inputs!$D$1) -> 0 | Q9: =IF(ISNA(SUMIFS(INDEX(Inputs!$B$2:$AZ$190,,MATCH(SUBSTITUTE(Q$3,"Q","T"),Inputs!$B$2:$AZ$2,0)),Inputs!$B$2:$B$190,$B9)*Inputs!$D$1),"",SUMIFS(INDEX(Inputs!$B$2:$AZ$190,,MATCH(SUBSTITUTE(Q$3,"Q","T"),Inputs!$B$2:$AZ$2,0)),Inputs!$B$2:$B$190,$B9)*Inputs!$D$1) -> 0 | R9: =IF(ISNA(SUMIFS(INDEX(Inputs!$B$2:$AZ$190,,MATCH(SUBSTITUTE(R$3,"Q","T"),Inputs!$B$2:$AZ$2,0)),Inputs!$B$2:$B$190,$B9)*Inputs!$D$1),"",SUMIFS(INDEX(Inputs!$B$2:$AZ$190,,MATCH(SUBSTITUTE(R$3,"Q","T"),Inputs!$B$2:$AZ$2,0)),Inputs!$B$2:$B$190,$B9)*Inputs!$D$1) -> 0 | S9: =R9 -> 0 | T9: =IF(ISNA(SUMIFS(INDEX(Inputs!$B$2:$AZ$190,,MATCH(SUBSTITUTE(T$3,"Q","T"),Inputs!$B$2:$AZ$2,0)),Inputs!$B$2:$B$190,$B9)*Inputs!$D$1),"",SUMIFS(INDEX(Inputs!$B$2:$AZ$190,,MATCH(SUBSTITUTE(T$3,"Q","T"),Inputs!$B$2:$AZ$2,0)),Inputs!$B$2:$B$190,$B9)*Inputs!$D$1) -> 0 | U9: =IF(ISNA(SUMIFS(INDEX(Inputs!$B$2:$AZ$190,,MATCH(SUBSTITUTE(U$3,"Q","T"),Inputs!$B$2:$AZ$2,0)),Inputs!$B$2:$B$190,$B9)*Inputs!$D$1),"",SUMIFS(INDEX(Inputs!$B$2:$AZ$190,,MATCH(SUBSTITUTE(U$3,"Q","T"),Inputs!$B$2:$AZ$2,0)),Inputs!$B$2:$B$190,$B9)*Inputs!$D$1) -> 0 | V9: =IF(ISNA(SUMIFS(INDEX(Inputs!$B$2:$AZ$190,,MATCH(SUBSTITUTE(V$3,"Q","T"),Inputs!$B$2:$AZ$2,0)),Inputs!$B$2:$B$190,$B9)*Inputs!$D$1),"",SUMIFS(INDEX(Inputs!$B$2:$AZ$190,,MATCH(SUBSTITUTE(V$3,"Q","T"),Inputs!$B$2:$AZ$2,0)),Inputs!$B$2:$B$190,$B9)*Inputs!$D$1) -> 0 | W9: =IF(ISNA(SUMIFS(INDEX(Inputs!$B$2:$AZ$190,,MATCH(SUBSTITUTE(W$3,"Q","T"),Inputs!$B$2:$AZ$2,0)),Inputs!$B$2:$B$190,$B9)*Inputs!$D$1),"",SUMIFS(INDEX(Inputs!$B$2:$AZ$190,,MATCH(SUBSTITUTE(W$3,"Q","T"),Inputs!$B$2:$AZ$2,0)),Inputs!$B$2:$B$190,$B9)*Inputs!$D$1) -> 0 | X9: =W9 -> 0 | Y9: =IF(ISNA(SUMIFS(INDEX(Inputs!$B$2:$AZ$190,,MATCH(SUBSTITUTE(Y$3,"Q","T"),Inputs!$B$2:$AZ$2,0)),Inputs!$B$2:$B$190,$B9)*Inputs!$D$1),"",SUMIFS(INDEX(Inputs!$B$2:$AZ$190,,MATCH(SUBSTITUTE(Y$3,"Q","T"),Inputs!$B$2:$AZ$2,0)),Inputs!$B$2:$B$190,$B9)*Inputs!$D$1) -> 0 | Z9: =IF(ISNA(SUMIFS(INDEX(Inputs!$B$2:$AZ$190,,MATCH(SUBSTITUTE(Z$3,"Q","T"),Inputs!$B$2:$AZ$2,0)),Inputs!$B$2:$B$190,$B9)*Inputs!$D$1),"",SUMIFS(INDEX(Inputs!$B$2:$AZ$190,,MATCH(SUBSTITUTE(Z$3,"Q","T"),Inputs!$B$2:$AZ$2,0)),Inputs!$B$2:$B$190,$B9)*Inputs!$D$1) -> 0 | AA9: =IF(ISNA(SUMIFS(INDEX(Inputs!$B$2:$AZ$190,,MATCH(SUBSTITUTE(AA$3,"Q","T"),Inputs!$B$2:$AZ$2,0)),Inputs!$B$2:$B$190,$B9)*Inputs!$D$1),"",SUMIFS(INDEX(Inputs!$B$2:$AZ$190,,MATCH(SUBSTITUTE(AA$3,"Q","T"),Inputs!$B$2:$AZ$2,0)),Inputs!$B$2:$B$190,$B9)*Inputs!$D$1) -> 0 | AB9: =IF(ISNA(SUMIFS(INDEX(Inputs!$B$2:$AZ$190,,MATCH(SUBSTITUTE(AB$3,"Q","T"),Inputs!$B$2:$AZ$2,0)),Inputs!$B$2:$B$190,$B9)*Inputs!$D$1),"",SUMIFS(INDEX(Inputs!$B$2:$AZ$190,,MATCH(SUBSTITUTE(AB$3,"Q","T"),Inputs!$B$2:$AZ$2,0)),Inputs!$B$2:$B$190,$B9)*Inputs!$D$1) -> 0 | AC9: =AB9 -> 0 | AD9: =IF(ISNA(SUMIFS(INDEX(Inputs!$B$2:$AZ$190,,MATCH(SUBSTITUTE(AD$3,"Q","T"),Inputs!$B$2:$AZ$2,0)),Inputs!$B$2:$B$190,$B9)*Inputs!$D$1),"",SUMIFS(INDEX(Inputs!$B$2:$AZ$190,,MATCH(SUBSTITUTE(AD$3,"Q","T"),Inputs!$B$2:$AZ$2,0)),Inputs!$B$2:$B$190,$B9)*Inputs!$D$1) -> 0 | AE9: =IF(ISNA(SUMIFS(INDEX(Inputs!$B$2:$AZ$190,,MATCH(SUBSTITUTE(AE$3,"Q","T"),Inputs!$B$2:$AZ$2,0)),Inputs!$B$2:$B$190,$B9)*Inputs!$D$1),"",SUMIFS(INDEX(Inputs!$B$2:$AZ$190,,MATCH(SUBSTITUTE(AE$3,"Q","T"),Inputs!$B$2:$AZ$2,0)),Inputs!$B$2:$B$190,$B9)*Inputs!$D$1) -> 0 | AF9: =IF(ISNA(SUMIFS(INDEX(Inputs!$B$2:$AZ$190,,MATCH(SUBSTITUTE(AF$3,"Q","T"),Inputs!$B$2:$AZ$2,0)),Inputs!$B$2:$B$190,$B9)*Inputs!$D$1),"",SUMIFS(INDEX(Inputs!$B$2:$AZ$190,,MATCH(SUBSTITUTE(AF$3,"Q","T"),Inputs!$B$2:$AZ$2,0)),Inputs!$B$2:$B$190,$B9)*Inputs!$D$1) -> 0 | AG9: =IF(ISNA(SUMIFS(INDEX(Inputs!$B$2:$AZ$190,,MATCH(SUBSTITUTE(AG$3,"Q","T"),Inputs!$B$2:$AZ$2,0)),Inputs!$B$2:$B$190,$B9)*Inputs!$D$1),"",SUMIFS(INDEX(Inputs!$B$2:$AZ$190,,MATCH(SUBSTITUTE(AG$3,"Q","T"),Inputs!$B$2:$AZ$2,0)),Inputs!$B$2:$B$190,$B9)*Inputs!$D$1) -> 0 | AH9: =AG9 -> 0 | AI9: =IF(ISNA(SUMIFS(INDEX(Inputs!$B$2:$AZ$190,,MATCH(SUBSTITUTE(AI$3,"Q","T"),Inputs!$B$2:$AZ$2,0)),Inputs!$B$2:$B$190,$B9)*Inputs!$D$1),"",SUMIFS(INDEX(Inputs!$B$2:$AZ$190,,MATCH(SUBSTITUTE(AI$3,"Q","T"),Inputs!$B$2:$AZ$2,0)),Inputs!$B$2:$B$190,$B9)*Inputs!$D$1) -> 0 | AJ9: =IF(ISNA(SUMIFS(INDEX(Inputs!$B$2:$AZ$190,,MATCH(SUBSTITUTE(AJ$3,"Q","T"),Inputs!$B$2:$AZ$2,0)),Inputs!$B$2:$B$190,$B9)*Inputs!$D$1),"",SUMIFS(INDEX(Inputs!$B$2:$AZ$190,,MATCH(SUBSTITUTE(AJ$3,"Q","T"),Inputs!$B$2:$AZ$2,0)),Inputs!$B$2:$B$190,$B9)*Inputs!$D$1) -> 0 | AK9: =IF(ISNA(SUMIFS(INDEX(Inputs!$B$2:$AZ$190,,MATCH(SUBSTITUTE(AK$3,"Q","T"),Inputs!$B$2:$AZ$2,0)),Inputs!$B$2:$B$190,$B9)*Inputs!$D$1),"",SUMIFS(INDEX(Inputs!$B$2:$AZ$190,,MATCH(SUBSTITUTE(AK$3,"Q","T"),Inputs!$B$2:$AZ$2,0)),Inputs!$B$2:$B$190,$B9)*Inputs!$D$1) -> 0 | AL9: =IF(ISNA(SUMIFS(INDEX(Inputs!$B$2:$AZ$190,,MATCH(SUBSTITUTE(AL$3,"Q","T"),Inputs!$B$2:$AZ$2,0)),Inputs!$B$2:$B$190,$B9)*Inputs!$D$1),"",SUMIFS(INDEX(Inputs!$B$2:$AZ$190,,MATCH(SUBSTITUTE(AL$3,"Q","T"),Inputs!$B$2:$AZ$2,0)),Inputs!$B$2:$B$190,$B9)*Inputs!$D$1) -> 0 | AM9: =AL9 -> 0 | AN9: =IF(ISNA(SUMIFS(INDEX(Inputs!$B$2:$AZ$190,,MATCH(SUBSTITUTE(AN$3,"Q","T"),Inputs!$B$2:$AZ$2,0)),Inputs!$B$2:$B$190,$B9)*Inputs!$D$1),"",SUMIFS(INDEX(Inputs!$B$2:$AZ$190,,MATCH(SUBSTITUTE(AN$3,"Q","T"),Inputs!$B$2:$AZ$2,0)),Inputs!$B$2:$B$190,$B9)*Inputs!$D$1) -> 0 | AO9: =IF(ISNA(SUMIFS(INDEX(Inputs!$B$2:$AZ$190,,MATCH(SUBSTITUTE(AO$3,"Q","T"),Inputs!$B$2:$AZ$2,0)),Inputs!$B$2:$B$190,$B9)*Inputs!$D$1),"",SUMIFS(INDEX(Inputs!$B$2:$AZ$190,,MATCH(SUBSTITUTE(AO$3,"Q","T"),Inputs!$B$2:$AZ$2,0)),Inputs!$B$2:$B$190,$B9)*Inputs!$D$1) -> 0 | AP9: =IF(ISNA(SUMIFS(INDEX(Inputs!$B$2:$AZ$190,,MATCH(SUBSTITUTE(AP$3,"Q","T"),Inputs!$B$2:$AZ$2,0)),Inputs!$B$2:$B$190,$B9)*Inputs!$D$1),"",SUMIFS(INDEX(Inputs!$B$2:$AZ$190,,MATCH(SUBSTITUTE(AP$3,"Q","T"),Inputs!$B$2:$AZ$2,0)),Inputs!$B$2:$B$190,$B9)*Inputs!$D$1) -> 0 | AQ9: =IF(ISNA(SUMIFS(INDEX(Inputs!$B$2:$AZ$190,,MATCH(SUBSTITUTE(AQ$3,"Q","T"),Inputs!$B$2:$AZ$2,0)),Inputs!$B$2:$B$190,$B9)*Inputs!$D$1),"",SUMIFS(INDEX(Inputs!$B$2:$AZ$190,,MATCH(SUBSTITUTE(AQ$3,"Q","T"),Inputs!$B$2:$AZ$2,0)),Inputs!$B$2:$B$190,$B9)*Inputs!$D$1) -> 0 | AR9: =AQ9 -> 0 | AS9: =IF(ISNA(SUMIFS(INDEX(Inputs!$B$2:$AZ$190,,MATCH(SUBSTITUTE(AS$3,"Q","T"),Inputs!$B$2:$AZ$2,0)),Inputs!$B$2:$B$190,$B9)*Inputs!$D$1),"",SUMIFS(INDEX(Inputs!$B$2:$AZ$190,,MATCH(SUBSTITUTE(AS$3,"Q","T"),Inputs!$B$2:$AZ$2,0)),Inputs!$B$2:$B$190,$B9)*Inputs!$D$1) -> 0 | AT9: =IF(ISNA(SUMIFS(INDEX(Inputs!$B$2:$AZ$190,,MATCH(SUBSTITUTE(AT$3,"Q","T"),Inputs!$B$2:$AZ$2,0)),Inputs!$B$2:$B$190,$B9)*Inputs!$D$1),"",SUMIFS(INDEX(Inputs!$B$2:$AZ$190,,MATCH(SUBSTITUTE(AT$3,"Q","T"),Inputs!$B$2:$AZ$2,0)),Inputs!$B$2:$B$190,$B9)*Inputs!$D$1) -> 0 | AU9: =IF(ISNA(SUMIFS(INDEX(Inputs!$B$2:$AZ$190,,MATCH(SUBSTITUTE(AU$3,"Q","T"),Inputs!$B$2:$AZ$2,0)),Inputs!$B$2:$B$190,$B9)*Inputs!$D$1),"",SUMIFS(INDEX(Inputs!$B$2:$AZ$190,,MATCH(SUBSTITUTE(AU$3,"Q","T"),Inputs!$B$2:$AZ$2,0)),Inputs!$B$2:$B$190,$B9)*Inputs!$D$1) -> 0 | AV9: =IF(ISNA(SUMIFS(INDEX(Inputs!$B$2:$AZ$190,,MATCH(SUBSTITUTE(AV$3,"Q","T"),Inputs!$B$2:$AZ$2,0)),Inputs!$B$2:$B$190,$B9)*Inputs!$D$1),"",SUMIFS(INDEX(Inputs!$B$2:$AZ$190,,MATCH(SUBSTITUTE(AV$3,"Q","T"),Inputs!$B$2:$AZ$2,0)),Inputs!$B$2:$B$190,$B9)*Inputs!$D$1) -> 0 | AW9: =AV9 -> 0 | AX9: =IF(ISNA(SUMIFS(INDEX(Inputs!$B$2:$AZ$190,,MATCH(SUBSTITUTE(AX$3,"Q","T"),Inputs!$B$2:$AZ$2,0)),Inputs!$B$2:$B$190,$B9)*Inputs!$D$1),"",SUMIFS(INDEX(Inputs!$B$2:$AZ$190,,MATCH(SUBSTITUTE(AX$3,"Q","T"),Inputs!$B$2:$AZ$2,0)),Inputs!$B$2:$B$190,$B9)*Inputs!$D$1) -> 0 | AY9: =IF(ISNA(SUMIFS(INDEX(Inputs!$B$2:$AZ$190,,MATCH(SUBSTITUTE(AY$3,"Q","T"),Inputs!$B$2:$AZ$2,0)),Inputs!$B$2:$B$190,$B9)*Inputs!$D$1),"",SUMIFS(INDEX(Inputs!$B$2:$AZ$190,,MATCH(SUBSTITUTE(AY$3,"Q","T"),Inputs!$B$2:$AZ$2,0)),Inputs!$B$2:$B$190,$B9)*Inputs!$D$1) -> 0 | AZ9: =IF(ISNA(SUMIFS(INDEX(Inputs!$B$2:$AZ$190,,MATCH(SUBSTITUTE(AZ$3,"Q","T"),Inputs!$B$2:$AZ$2,0)),Inputs!$B$2:$B$190,$B9)*Inputs!$D$1),"",SUMIFS(INDEX(Inputs!$B$2:$AZ$190,,MATCH(SUBSTITUTE(AZ$3,"Q","T"),Inputs!$B$2:$AZ$2,0)),Inputs!$B$2:$B$190,$B9)*Inputs!$D$1) -> 0 | BA9: =IF(ISNA(SUMIFS(INDEX(Inputs!$B$2:$AZ$190,,MATCH(SUBSTITUTE(BA$3,"Q","T"),Inputs!$B$2:$AZ$2,0)),Inputs!$B$2:$B$190,$B9)*Inputs!$D$1),"",SUMIFS(INDEX(Inputs!$B$2:$AZ$190,,MATCH(SUBSTITUTE(BA$3,"Q","T"),Inputs!$B$2:$AZ$2,0)),Inputs!$B$2:$B$190,$B9)*Inputs!$D$1) -> 0 | BB9: =BA9 -> 0 | BC9: =IF(ISNA(SUMIFS(INDEX(Inputs!$B$2:$AZ$190,,MATCH(SUBSTITUTE(BC$3,"Q","T"),Inputs!$B$2:$AZ$2,0)),Inputs!$B$2:$B$190,$B9)*Inputs!$D$1),"",SUMIFS(INDEX(Inputs!$B$2:$AZ$190,,MATCH(SUBSTITUTE(BC$3,"Q","T"),Inputs!$B$2:$AZ$2,0)),Inputs!$B$2:$B$190,$B9)*Inputs!$D$1) -> 0 | BD9: =IF(ISNA(SUMIFS(INDEX(Inputs!$B$2:$AZ$190,,MATCH(SUBSTITUTE(BD$3,"Q","T"),Inputs!$B$2:$AZ$2,0)),Inputs!$B$2:$B$190,$B9)*Inputs!$D$1),"",SUMIFS(INDEX(Inputs!$B$2:$AZ$190,,MATCH(SUBSTITUTE(BD$3,"Q","T"),Inputs!$B$2:$AZ$2,0)),Inputs!$B$2:$B$190,$B9)*Inputs!$D$1) -> 0 | BE9: =IF(ISNA(SUMIFS(INDEX(Inputs!$B$2:$AZ$190,,MATCH(SUBSTITUTE(BE$3,"Q","T"),Inputs!$B$2:$AZ$2,0)),Inputs!$B$2:$B$190,$B9)*Inputs!$D$1),"",SUMIFS(INDEX(Inputs!$B$2:$AZ$190,,MATCH(SUBSTITUTE(BE$3,"Q","T"),Inputs!$B$2:$AZ$2,0)),Inputs!$B$2:$B$190,$B9)*Inputs!$D$1) -> 0 | BF9: =IF(ISNA(SUMIFS(INDEX(Inputs!$B$2:$AZ$190,,MATCH(SUBSTITUTE(BF$3,"Q","T"),Inputs!$B$2:$AZ$2,0)),Inputs!$B$2:$B$190,$B9)*Inputs!$D$1),"",SUMIFS(INDEX(Inputs!$B$2:$AZ$190,,MATCH(SUBSTITUTE(BF$3,"Q","T"),Inputs!$B$2:$AZ$2,0)),Inputs!$B$2:$B$190,$B9)*Inputs!$D$1) -> 0 | BG9: =BF9 -> 0
